Workbook
Name الحد_الأدنى: المدخلات!$N$3
Name فرق_المباراة: المدخلات!$AD$3
Name قائمة_المدن: المدخلات!$AA$3:$AA$98
Name ملاعب_الفئات: المدخلات!$AC$6:$AI$12

Sheet عدد الملاعب
B2: ملخص الملاعب لكل يوم (المجموعات المكتملة فقط)
B3: الفئة | C3: اليوم | D3: نوع الملعب | E3: المجموعات | F3: عدد الفرق | G3: ملاعب قانونية
B4: =المدخلات!$AC$6 | C4: =المدخلات!$AD$6 | D4: =المدخلات!$AE$6 | E4: =COUNTIFS($C$14:$C$197,المدخلات!$AC$6,$G$14:$G$197,">="&الحد_الأدنى) | F4: =SUMIFS($G$14:$G$197,$C$14:$C$197,المدخلات!$AC$6,$G$14:$G$197,">="&الحد_الأدنى) | G4: =SUMIFS($K$14:$K$197,$C$14:$C$197,المدخلات!$AC$6)
B5: =المدخلات!$AC$7 | C5: =المدخلات!$AD$7 | D5: =المدخلات!$AE$7 | E5: =COUNTIFS($C$14:$C$197,المدخلات!$AC$7,$G$14:$G$197,">="&الحد_الأدنى) | F5: =SUMIFS($G$14:$G$197,$C$14:$C$197,المدخلات!$AC$7,$G$14:$G$197,">="&الحد_الأدنى) | G5: =SUMIFS($K$14:$K$197,$C$14:$C$197,المدخلات!$AC$7)
B6: =المدخلات!$AC$8 | C6: =المدخلات!$AD$8 | D6: =المدخلات!$AE$8 | E6: =COUNTIFS($C$14:$C$197,المدخلات!$AC$8,$G$14:$G$197,">="&الحد_الأدنى) | F6: =SUMIFS($G$14:$G$197,$C$14:$C$197,المدخلات!$AC$8,$G$14:$G$197,">="&الحد_الأدنى) | G6: =SUMIFS($K$14:$K$197,$C$14:$C$197,المدخلات!$AC$8)
B7: =المدخلات!$AC$9 | C7: =المدخلات!$AD$9 | D7: =المدخلات!$AE$9 | E7: =COUNTIFS($C$14:$C$197,المدخلات!$AC$9,$G$14:$G$197,">="&الحد_الأدنى) | F7: =SUMIFS($G$14:$G$197,$C$14:$C$197,المدخلات!$AC$9,$G$14:$G$197,">="&الحد_الأدنى) | G7: =SUMIFS($K$14:$K$197,$C$14:$C$197,المدخلات!$AC$9)
B8: =المدخلات!$AC$10 | C8: =المدخلات!$AD$10 | D8: =المدخلات!$AE$10 | E8: =COUNTIFS($C$14:$C$197,المدخلات!$AC$10,$G$14:$G$197,">="&الحد_الأدنى) | F8: =SUMIFS($G$14:$G$197,$C$14:$C$197,المدخلات!$AC$10,$G$14:$G$197,">="&الحد_الأدنى) | G8: =SUMIFS($K$14:$K$197,$C$14:$C$197,المدخلات!$AC$10)
B9: =المدخلات!$AC$11 | C9: =المدخلات!$AD$11 | D9: =المدخلات!$AE$11 | E9: =COUNTIFS($C$14:$C$197,المدخلات!$AC$11,$G$14:$G$197,">="&الحد_الأدنى) | F9: =SUMIFS($G$14:$G$197,$C$14:$C$197,المدخلات!$AC$11,$G$14:$G$197,">="&الحد_الأدنى) | G9: =SUMIFS($K$14:$K$197,$C$14:$C$197,المدخلات!$AC$11)
B10: =المدخلات!$AC$12 | C10: =المدخلات!$AD$12 | D10: =المدخلات!$AE$12 | E10: =COUNTIFS($C$14:$C$197,المدخلات!$AC$12,$G$14:$G$197,">="&الحد_الأدنى) | F10: =SUMIFS($G$14:$G$197,$C$14:$C$197,المدخلات!$AC$12,$G$14:$G$197,">="&الحد_الأدنى) | G10: =SUMIFS($K$14:$K$197,$C$14:$C$197,المدخلات!$AC$12)
B11: الإجمالي | E11: =SUM(E4:E10) | F11: =SUM(F4:F10) | G11: =SUM(G4:G10)
B13: المنطقة | C13: الفئة | D13: اليوم | E13: المجموعة | F13: المدن | G13: عدد الفرق | H13: نوع الملعب | I13: عدد المباريات في اليوم | J13: ملاعب اللعب المطلوبة | K13: ملاعب قانونية معادلة
B14: ='عدد اللاعبين'!B3 | C14: ='عدد اللاعبين'!C3 | D14: =IFERROR(INDEX(المدخلات!$AD$6:$AD$12,MATCH($C14,المدخلات!$AC$6:$AC$12,0)),"") | E14: ='عدد اللاعبين'!D3 | F14: ='عدد اللاعبين'!F3 | G14: ='عدد اللاعبين'!G3 | H14: =IFERROR(INDEX(المدخلات!$AE$6:$AE$12,MATCH($C14,المدخلات!$AC$6:$AC$12,0)),"") | I14: =IF($G14<الحد_الأدنى,0,ROUNDDOWN($G14/فرق_المباراة,0)) | J14: =ROUNDUP($I14/IFERROR(INDEX(المدخلات!$AJ$6:$AJ$12,MATCH($C14,المدخلات!$AC$6:$AC$12,0)),1),0) | K14: =ROUNDUP($J14/IFERROR(INDEX(المدخلات!$AF$6:$AF$12,MATCH($C14,المدخلات!$AC$6:$AC$12,0)),1),0)
B15: ='عدد اللاعبين'!B4 | C15: ='عدد اللاعبين'!C4 | D15: =IFERROR(INDEX(المدخلات!$AD$6:$AD$12,MATCH($C15,المدخلات!$AC$6:$AC$12,0)),"") | E15: ='عدد اللاعبين'!D4 | F15: ='عدد اللاعبين'!F4 | G15: ='عدد اللاعبين'!G4 | H15: =IFERROR(INDEX(المدخلات!$AE$6:$AE$12,MATCH($C15,المدخلات!$AC$6:$AC$12,0)),"") | I15: =IF($G15<الحد_الأدنى,0,ROUNDDOWN($G15/فرق_المباراة,0)) | J15: =ROUNDUP($I15/IFERROR(INDEX(المدخلات!$AJ$6:$AJ$12,MATCH($C15,المدخلات!$AC$6:$AC$12,0)),1),0) | K15: =ROUNDUP($J15/IFERROR(INDEX(المدخلات!$AF$6:$AF$12,MATCH($C15,المدخلات!$AC$6:$AC$12,0)),1),0)
B16: ='عدد اللاعبين'!B5 | C16: ='عدد اللاعبين'!C5 | D16: =IFERROR(INDEX(المدخلات!$AD$6:$AD$12,MATCH($C16,المدخلات!$AC$6:$AC$12,0)),"") | E16: ='عدد اللاعبين'!D5 | F16: ='عدد اللاعبين'!F5 | G16: ='عدد اللاعبين'!G5 | H16: =IFERROR(INDEX(المدخلات!$AE$6:$AE$12,MATCH($C16,المدخلات!$AC$6:$AC$12,0)),"") | I16: =IF($G16<الحد_الأدنى,0,ROUNDDOWN($G16/فرق_المباراة,0)) | J16: =ROUNDUP($I16/IFERROR(INDEX(المدخلات!$AJ$6:$AJ$12,MATCH($C16,المدخلات!$AC$6:$AC$12,0)),1),0) | K16: =ROUNDUP($J16/IFERROR(INDEX(المدخلات!$AF$6:$AF$12,MATCH($C16,المدخلات!$AC$6:$AC$12,0)),1),0)
B17: ='عدد اللاعبين'!B6 | C17: ='عدد اللاعبين'!C6 | D17: =IFERROR(INDEX(المدخلات!$AD$6:$AD$12,MATCH($C17,المدخلات!$AC$6:$AC$12,0)),"") | E17: ='عدد اللاعبين'!D6 | F17: ='عدد اللاعبين'!F6 | G17: ='عدد اللاعبين'!G6 | H17: =IFERROR(INDEX(المدخلات!$AE$6:$AE$12,MATCH($C17,المدخلات!$AC$6:$AC$12,0)),"") | I17: =IF($G17<الحد_الأدنى,0,ROUNDDOWN($G17/فرق_المباراة,0)) | J17: =ROUNDUP($I17/IFERROR(INDEX(المدخلات!$AJ$6:$AJ$12,MATCH($C17,المدخلات!$AC$6:$AC$12,0)),1),0) | K17: =ROUNDUP($J17/IFERROR(INDEX(المدخلات!$AF$6:$AF$12,MATCH($C17,المدخلات!$AC$6:$AC$12,0)),1),0)
B18: ='عدد اللاعبين'!B7 | C18: ='عدد اللاعبين'!C7 | D18: =IFERROR(INDEX(المدخلات!$AD$6:$AD$12,MATCH($C18,المدخلات!$AC$6:$AC$12,0)),"") | E18: ='عدد اللاعبين'!D7 | F18: ='عدد اللاعبين'!F7 | G18: ='عدد اللاعبين'!G7 | H18: =IFERROR(INDEX(المدخلات!$AE$6:$AE$12,MATCH($C18,المدخلات!$AC$6:$AC$12,0)),"") | I18: =IF($G18<الحد_الأدنى,0,ROUNDDOWN($G18/فرق_المباراة,0)) | J18: =ROUNDUP($I18/IFERROR(INDEX(المدخلات!$AJ$6:$AJ$12,MATCH($C18,المدخلات!$AC$6:$AC$12,0)),1),0) | K18: =ROUNDUP($J18/IFERROR(INDEX(المدخلات!$AF$6:$AF$12,MATCH($C18,المدخلات!$AC$6:$AC$12,0)),1),0)
B19: ='عدد اللاعبين'!B8 | C19: ='عدد اللاعبين'!C8 | D19: =IFERROR(INDEX(المدخلات!$AD$6:$AD$12,MATCH($C19,المدخلات!$AC$6:$AC$12,0)),"") | E19: ='عدد اللاعبين'!D8 | F19: ='عدد اللاعبين'!F8 | G19: ='عدد اللاعبين'!G8 | H19: =IFERROR(INDEX(المدخلات!$AE$6:$AE$12,MATCH($C19,المدخلات!$AC$6:$AC$12,0)),"") | I19: =IF($G19<الحد_الأدنى,0,ROUNDDOWN($G19/فرق_المباراة,0)) | J19: =ROUNDUP($I19/IFERROR(INDEX(المدخلات!$AJ$6:$AJ$12,MATCH($C19,المدخلات!$AC$6:$AC$12,0)),1),0) | K19: =ROUNDUP($J19/IFERROR(INDEX(المدخلات!$AF$6:$AF$12,MATCH($C19,المدخلات!$AC$6:$AC$12,0)),1),0)
B20: ='عدد اللاعبين'!B9 | C20: ='عدد اللاعبين'!C9 | D20: =IFERROR(INDEX(المدخلات!$AD$6:$AD$12,MATCH($C20,المدخلات!$AC$6:$AC$12,0)),"") | E20: ='عدد اللاعبين'!D9 | F20: ='عدد اللاعبين'!F9 | G20: ='عدد اللاعبين'!G9 | H20: =IFERROR(INDEX(المدخلات!$AE$6:$AE$12,MATCH($C20,المدخلات!$AC$6:$AC$12,0)),"") | I20: =IF($G20<الحد_الأدنى,0,ROUNDDOWN($G20/فرق_المباراة,0)) | J20: =ROUNDUP($I20/IFERROR(INDEX(المدخلات!$AJ$6:$AJ$12,MATCH($C20,المدخلات!$AC$6:$AC$12,0)),1),0) | K20: =ROUNDUP($J20/IFERROR(INDEX(المدخلات!$AF$6:$AF$12,MATCH($C20,المدخلات!$AC$6:$AC$12,0)),1),0)
B21: ='عدد اللاعبين'!B10 | C21: ='عدد اللاعبين'!C10 | D21: =IFERROR(INDEX(المدخلات!$AD$6:$AD$12,MATCH($C21,المدخلات!$AC$6:$AC$12,0)),"") | E21: ='عدد اللاعبين'!D10 | F21: ='عدد اللاعبين'!F10 | G21: ='عدد اللاعبين'!G10 | H21: =IFERROR(INDEX(المدخلات!$AE$6:$AE$12,MATCH($C21,المدخلات!$AC$6:$AC$12,0)),"") | I21: =IF($G21<الحد_الأدنى,0,ROUNDDOWN($G21/فرق_المباراة,0)) | J21: =ROUNDUP($I21/IFERROR(INDEX(المدخلات!$AJ$6:$AJ$12,MATCH($C21,المدخلات!$AC$6:$AC$12,0)),1),0) | K21: =ROUNDUP($J21/IFERROR(INDEX(المدخلات!$AF$6:$AF$12,MATCH($C21,المدخلات!$AC$6:$AC$12,0)),1),0)
B22: ='عدد اللاعبين'!B11 | C22: ='عدد اللاعبين'!C11 | D22: =IFERROR(INDEX(المدخلات!$AD$6:$AD$12,MATCH($C22,المدخلات!$AC$6:$AC$12,0)),"") | E22: ='عدد اللاعبين'!D11 | F22: ='عدد اللاعبين'!F11 | G22: ='عدد اللاعبين'!G11 | H22: =IFERROR(INDEX(المدخلات!$AE$6:$AE$12,MATCH($C22,المدخلات!$AC$6:$AC$12,0)),"") | I22: =IF($G22<الحد_الأدنى,0,ROUNDDOWN($G22/فرق_المباراة,0)) | J22: =ROUNDUP($I22/IFERROR(INDEX(المدخلات!$AJ$6:$AJ$12,MATCH($C22,المدخلات!$AC$6:$AC$12,0)),1),0) | K22: =ROUNDUP($J22/IFERROR(INDEX(المدخلات!$AF$6:$AF$12,MATCH($C22,المدخلات!$AC$6:$AC$12,0)),1),0)
B23: ='عدد اللاعبين'!B12 | C23: ='عدد اللاعبين'!C12 | D23: =IFERROR(INDEX(المدخلات!$AD$6:$AD$12,MATCH($C23,المدخلات!$AC$6:$AC$12,0)),"") | E23: ='عدد اللاعبين'!D12 | F23: ='عدد اللاعبين'!F12 | G23: ='عدد اللاعبين'!G12 | H23: =IFERROR(INDEX(المدخلات!$AE$6:$AE$12,MATCH($C23,المدخلات!$AC$6:$AC$12,0)),"") | I23: =IF($G23<الحد_الأدنى,0,ROUNDDOWN($G23/فرق_المباراة,0)) | J23: =ROUNDUP($I23/IFERROR(INDEX(المدخلات!$AJ$6:$AJ$12,MATCH($C23,المدخلات!$AC$6:$AC$12,0)),1),0) | K23: =ROUNDUP($J23/IFERROR(INDEX(المدخلات!$AF$6:$AF$12,MATCH($C23,المدخلات!$AC$6:$AC$12,0)),1),0)
B24: ='عدد اللاعبين'!B13 | C24: ='عدد اللاعبين'!C13 | D24: =IFERROR(INDEX(المدخلات!$AD$6:$AD$12,MATCH($C24,المدخلات!$AC$6:$AC$12,0)),"") | E24: ='عدد اللاعبين'!D13 | F24: ='عدد اللاعبين'!F13 | G24: ='عدد اللاعبين'!G13 | H24: =IFERROR(INDEX(المدخلات!$AE$6:$AE$12,MATCH($C24,المدخلات!$AC$6:$AC$12,0)),"") | I24: =IF($G24<الحد_الأدنى,0,ROUNDDOWN($G24/فرق_المباراة,0)) | J24: =ROUNDUP($I24/IFERROR(INDEX(المدخلات!$AJ$6:$AJ$12,MATCH($C24,المدخلات!$AC$6:$AC$12,0)),1),0) | K24: =ROUNDUP($J24/IFERROR(INDEX(المدخلات!$AF$6:$AF$12,MATCH($C24,المدخلات!$AC$6:$AC$12,0)),1),0)
B25: ='عدد اللاعبين'!B14 | C25: ='عدد اللاعبين'!C14 | D25: =IFERROR(INDEX(المدخلات!$AD$6:$AD$12,MATCH($C25,المدخلات!$AC$6:$AC$12,0)),"") | E25: ='عدد اللاعبين'!D14 | F25: ='عدد اللاعبين'!F14 | G25: ='عدد اللاعبين'!G14 | H25: =IFERROR(INDEX(المدخلات!$AE$6:$AE$12,MATCH($C25,المدخلات!$AC$6:$AC$12,0)),"") | I25: =IF($G25<الحد_الأدنى,0,ROUNDDOWN($G25/فرق_المباراة,0)) | J25: =ROUNDUP($I25/IFERROR(INDEX(المدخلات!$AJ$6:$AJ$12,MATCH($C25,المدخلات!$AC$6:$AC$12,0)),1),0) | K25: =ROUNDUP($J25/IFERROR(INDEX(المدخلات!$AF$6:$AF$12,MATCH($C25,المدخلات!$AC$6:$AC$12,0)),1),0)
... B197: ='عدد اللاعبين'!B186 | C197: ='عدد اللاعبين'!C186 | D197: =IFERROR(INDEX(المدخلات!$AD$6:$AD$12,MATCH($C197,المدخلات!$AC$6:$AC$12,0)),"") | E197: ='عدد اللاعبين'!D186 | F197: ='عدد اللاعبين'!F186 | G197: ='عدد اللاعبين'!G186 | H197: =IFERROR(INDEX(المدخلات!$AE$6:$AE$12,MATCH($C197,المدخلات!$AC$6:$AC$12,0)),"") | I197: =IF($G197<الحد_الأدنى,0,ROUNDDOWN($G197/فرق_المباراة,0)) | J197: =ROUNDUP($I197/IFERROR(INDEX(المدخلات!$AJ$6:$AJ$12,MATCH($C197,المدخلات!$AC$6:$AC$12,0)),1),0) | K197: =ROUNDUP($J197/IFERROR(INDEX(المدخلات!$AF$6:$AF$12,MATCH($C197,المدخلات!$AC$6:$AC$12,0)),1),0)
B202: الطلب لكل مجموعة — الملاعب القانونية المطلوبة
B203: المنطقة | C203: المجموعة | D203: المدن | E203: تحت 5 / 7 / 9 (الأعلى) | F203: =المدخلات!$AC$9 | G203: =المدخلات!$AC$10 | H203: =المدخلات!$AC$11 | I203: =المدخلات!$AC$12 | J203: أقصى ملاعب في يوم واحد | K203: إجمالي الفرق | L203: الحالة
B204: — | C204: — | D204: — | E204: =المدخلات!$AD$6 | F204: =المدخلات!$AD$9 | G204: =المدخلات!$AD$10 | H204: =المدخلات!$AD$11 | I204: =المدخلات!$AD$12 | J204: — | K204: — | L204: —
B205: الباحة | C205: مجموعة الباحة | D205: =IFERROR(INDEX('عدد اللاعبين'!$F$3:$F$186,MATCH($C205,'عدد اللاعبين'!$D$3:$D$186,0)),"") | E205: =MAX(SUMIFS($K$14:$K$197,$E$14:$E$197,$C205,$C$14:$C$197,المدخلات!$AC$6),SUMIFS($K$14:$K$197,$E$14:$E$197,$C205,$C$14:$C$197,المدخلات!$AC$7),SUMIFS($K$14:$K$197,$E$14:$E$197,$C205,$C$14:$C$197,المدخلات!$AC$8)) | F205: =SUMIFS($K$14:$K$197,$E$14:$E$197,$C205,$C$14:$C$197,المدخلات!$AC$9) | G205: =SUMIFS($K$14:$K$197,$E$14:$E$197,$C205,$C$14:$C$197,المدخلات!$AC$10) | H205: =SUMIFS($K$14:$K$197,$E$14:$E$197,$C205,$C$14:$C$197,المدخلات!$AC$11) | I205: =SUMIFS($K$14:$K$197,$E$14:$E$197,$C205,$C$14:$C$197,المدخلات!$AC$12) | J205: =MAX($E205:$I205) | K205: =SUMIFS($G$14:$G$197,$E$14:$E$197,$C205,$G$14:$G$197,">="&الحد_الأدنى) | L205: =IF($K205=0,"غير مكتملة","مكتملة")
B206: الجوف | C206: مجموعة القريات | D206: =IFERROR(INDEX('عدد اللاعبين'!$F$3:$F$186,MATCH($C206,'عدد اللاعبين'!$D$3:$D$186,0)),"") | E206: =MAX(SUMIFS($K$14:$K$197,$E$14:$E$197,$C206,$C$14:$C$197,المدخلات!$AC$6),SUMIFS($K$14:$K$197,$E$14:$E$197,$C206,$C$14:$C$197,المدخلات!$AC$7),SUMIFS($K$14:$K$197,$E$14:$E$197,$C206,$C$14:$C$197,المدخلات!$AC$8)) | F206: =SUMIFS($K$14:$K$197,$E$14:$E$197,$C206,$C$14:$C$197,المدخلات!$AC$9) | G206: =SUMIFS($K$14:$K$197,$E$14:$E$197,$C206,$C$14:$C$197,المدخلات!$AC$10) | H206: =SUMIFS($K$14:$K$197,$E$14:$E$197,$C206,$C$14:$C$197,المدخلات!$AC$11) | I206: =SUMIFS($K$14:$K$197,$E$14:$E$197,$C206,$C$14:$C$197,المدخلات!$AC$12) | J206: =MAX($E206:$I206) | K206: =SUMIFS($G$14:$G$197,$E$14:$E$197,$C206,$G$14:$G$197,">="&الحد_الأدنى) | L206: =IF($K206=0,"غير مكتملة","مكتملة")
B207: الجوف | C207: مجموعة سكاكا | D207: =IFERROR(INDEX('عدد اللاعبين'!$F$3:$F$186,MATCH($C207,'عدد اللاعبين'!$D$3:$D$186,0)),"") | E207: =MAX(SUMIFS($K$14:$K$197,$E$14:$E$197,$C207,$C$14:$C$197,المدخلات!$AC$6),SUMIFS($K$14:$K$197,$E$14:$E$197,$C207,$C$14:$C$197,المدخلات!$AC$7),SUMIFS($K$14:$K$197,$E$14:$E$197,$C207,$C$14:$C$197,المدخلات!$AC$8)) | F207: =SUMIFS($K$14:$K$197,$E$14:$E$197,$C207,$C$14:$C$197,المدخلات!$AC$9) | G207: =SUMIFS($K$14:$K$197,$E$14:$E$197,$C207,$C$14:$C$197,المدخلات!$AC$10) | H207: =SUMIFS($K$14:$K$197,$E$14:$E$197,$C207,$C$14:$C$197,المدخلات!$AC$11) | I207: =SUMIFS($K$14:$K$197,$E$14:$E$197,$C207,$C$14:$C$197,المدخلات!$AC$12) | J207: =MAX($E207:$I207) | K207: =SUMIFS($G$14:$G$197,$E$14:$E$197,$C207,$G$14:$G$197,">="&الحد_الأدنى) | L207: =IF($K207=0,"غير مكتملة","مكتملة")
B208: الجوف | C208: مجموعة طبرجل | D208: =IFERROR(INDEX('عدد اللاعبين'!$F$3:$F$186,MATCH($C208,'عدد اللاعبين'!$D$3:$D$186,0)),"") | E208: =MAX(SUMIFS($K$14:$K$197,$E$14:$E$197,$C208,$C$14:$C$197,المدخلات!$AC$6),SUMIFS($K$14:$K$197,$E$14:$E$197,$C208,$C$14:$C$197,المدخلات!$AC$7),SUMIFS($K$14:$K$197,$E$14:$E$197,$C208,$C$14:$C$197,المدخلات!$AC$8)) | F208: =SUMIFS($K$14:$K$197,$E$14:$E$197,$C208,$C$14:$C$197,المدخلات!$AC$9) | G208: =SUMIFS($K$14:$K$197,$E$14:$E$197,$C208,$C$14:$C$197,المدخلات!$AC$10) | H208: =SUMIFS($K$14:$K$197,$E$14:$E$197,$C208,$C$14:$C$197,المدخلات!$AC$11) | I208: =SUMIFS($K$14:$K$197,$E$14:$E$197,$C208,$C$14:$C$197,المدخلات!$AC$12) | J208: =MAX($E208:$I208) | K208: =SUMIFS($G$14:$G$197,$E$14:$E$197,$C208,$G$14:$G$197,">="&الحد_الأدنى) | L208: =IF($K208=0,"غير مكتملة","مكتملة")
B209: الرياض | C209: مجموعة الخرج | D209: =IFERROR(INDEX('عدد اللاعبين'!$F$3:$F$186,MATCH($C209,'عدد اللاعبين'!$D$3:$D$186,0)),"") | E209: =MAX(SUMIFS($K$14:$K$197,$E$14:$E$197,$C209,$C$14:$C$197,المدخلات!$AC$6),SUMIFS($K$14:$K$197,$E$14:$E$197,$C209,$C$14:$C$197,المدخلات!$AC$7),SUMIFS($K$14:$K$197,$E$14:$E$197,$C209,$C$14:$C$197,المدخلات!$AC$8)) | F209: =SUMIFS($K$14:$K$197,$E$14:$E$197,$C209,$C$14:$C$197,المدخلات!$AC$9) | G209: =SUMIFS($K$14:$K$197,$E$14:$E$197,$C209,$C$14:$C$197,المدخلات!$AC$10) | H209: =SUMIFS($K$14:$K$197,$E$14:$E$197,$C209,$C$14:$C$197,المدخلات!$AC$11) | I209: =SUMIFS($K$14:$K$197,$E$14:$E$197,$C209,$C$14:$C$197,المدخلات!$AC$12) | J209: =MAX($E209:$I209) | K209: =SUMIFS($G$14:$G$197,$E$14:$E$197,$C209,$G$14:$G$197,">="&الحد_الأدنى) | L209: =IF($K209=0,"غير مكتملة","مكتملة")
B210: الرياض | C210: مجموعة الدوادمي | D210: =IFERROR(INDEX('عدد اللاعبين'!$F$3:$F$186,MATCH($C210,'عدد اللاعبين'!$D$3:$D$186,0)),"") | E210: =MAX(SUMIFS($K$14:$K$197,$E$14:$E$197,$C210,$C$14:$C$197,المدخلات!$AC$6),SUMIFS($K$14:$K$197,$E$14:$E$197,$C210,$C$14:$C$197,المدخلات!$AC$7),SUMIFS($K$14:$K$197,$E$14:$E$197,$C210,$C$14:$C$197,المدخلات!$AC$8)) | F210: =SUMIFS($K$14:$K$197,$E$14:$E$197,$C210,$C$14:$C$197,المدخلات!$AC$9) | G210: =SUMIFS($K$14:$K$197,$E$14:$E$197,$C210,$C$14:$C$197,المدخلات!$AC$10) | H210: =SUMIFS($K$14:$K$197,$E$14:$E$197,$C210,$C$14:$C$197,المدخلات!$AC$11) | I210: =SUMIFS($K$14:$K$197,$E$14:$E$197,$C210,$C$14:$C$197,المدخلات!$AC$12) | J210: =MAX($E210:$I210) | K210: =SUMIFS($G$14:$G$197,$E$14:$E$197,$C210,$G$14:$G$197,">="&الحد_الأدنى) | L210: =IF($K210=0,"غير مكتملة","مكتملة")
B211: الرياض | C211: مجموعة الرياض | D211: =IFERROR(INDEX('عدد اللاعبين'!$F$3:$F$186,MATCH($C211,'عدد اللاعبين'!$D$3:$D$186,0)),"") | E211: =MAX(SUMIFS($K$14:$K$197,$E$14:$E$197,$C211,$C$14:$C$197,المدخلات!$AC$6),SUMIFS($K$14:$K$197,$E$14:$E$197,$C211,$C$14:$C$197,المدخلات!$AC$7),SUMIFS($K$14:$K$197,$E$14:$E$197,$C211,$C$14:$C$197,المدخلات!$AC$8)) | F211: =SUMIFS($K$14:$K$197,$E$14:$E$197,$C211,$C$14:$C$197,المدخلات!$AC$9) | G211: =SUMIFS($K$14:$K$197,$E$14:$E$197,$C211,$C$14:$C$197,المدخلات!$AC$10) | H211: =SUMIFS($K$14:$K$197,$E$14:$E$197,$C211,$C$14:$C$197,المدخلات!$AC$11) | I211: =SUMIFS($K$14:$K$197,$E$14:$E$197,$C211,$C$14:$C$197,المدخلات!$AC$12) | J211: =MAX($E211:$I211) | K211: =SUMIFS($G$14:$G$197,$E$14:$E$197,$C211,$G$14:$G$197,">="&الحد_الأدنى) | L211: =IF($K211=0,"غير مكتملة","مكتملة")
B212: الشرقية | C212: مجموعة الأحساء | D212: =IFERROR(INDEX('عدد اللاعبين'!$F$3:$F$186,MATCH($C212,'عدد اللاعبين'!$D$3:$D$186,0)),"") | E212: =MAX(SUMIFS($K$14:$K$197,$E$14:$E$197,$C212,$C$14:$C$197,المدخلات!$AC$6),SUMIFS($K$14:$K$197,$E$14:$E$197,$C212,$C$14:$C$197,المدخلات!$AC$7),SUMIFS($K$14:$K$197,$E$14:$E$197,$C212,$C$14:$C$197,المدخلات!$AC$8)) | F212: =SUMIFS($K$14:$K$197,$E$14:$E$197,$C212,$C$14:$C$197,المدخلات!$AC$9) | G212: =SUMIFS($K$14:$K$197,$E$14:$E$197,$C212,$C$14:$C$197,المدخلات!$AC$10) | H212: =SUMIFS($K$14:$K$197,$E$14:$E$197,$C212,$C$14:$C$197,المدخلات!$AC$11) | I212: =SUMIFS($K$14:$K$197,$E$14:$E$197,$C212,$C$14:$C$197,المدخلات!$AC$12) | J212: =MAX($E212:$I212) | K212: =SUMIFS($G$14:$G$197,$E$14:$E$197,$C212,$G$14:$G$197,">="&الحد_الأدنى) | L212: =IF($K212=0,"غير مكتملة","مكتملة")
B213: الشرقية | C213: مجموعة الخبر | D213: =IFERROR(INDEX('عدد اللاعبين'!$F$3:$F$186,MATCH($C213,'عدد اللاعبين'!$D$3:$D$186,0)),"") | E213: =MAX(SUMIFS($K$14:$K$197,$E$14:$E$197,$C213,$C$14:$C$197,المدخلات!$AC$6),SUMIFS($K$14:$K$197,$E$14:$E$197,$C213,$C$14:$C$197,المدخلات!$AC$7),SUMIFS($K$14:$K$197,$E$14:$E$197,$C213,$C$14:$C$197,المدخلات!$AC$8)) | F213: =SUMIFS($K$14:$K$197,$E$14:$E$197,$C213,$C$14:$C$197,المدخلات!$AC$9) | G213: =SUMIFS($K$14:$K$197,$E$14:$E$197,$C213,$C$14:$C$197,المدخلات!$AC$10) | H213: =SUMIFS($K$14:$K$197,$E$14:$E$197,$C213,$C$14:$C$197,المدخلات!$AC$11) | I213: =SUMIFS($K$14:$K$197,$E$14:$E$197,$C213,$C$14:$C$197,المدخلات!$AC$12) | J213: =MAX($E213:$I213) | K213: =SUMIFS($G$14:$G$197,$E$14:$E$197,$C213,$G$14:$G$197,">="&الحد_الأدنى) | L213: =IF($K213=0,"غير مكتملة","مكتملة")
B214: الشرقية | C214: مجموعة الخفجي | D214: =IFERROR(INDEX('عدد اللاعبين'!$F$3:$F$186,MATCH($C214,'عدد اللاعبين'!$D$3:$D$186,0)),"") | E214: =MAX(SUMIFS($K$14:$K$197,$E$14:$E$197,$C214,$C$14:$C$197,المدخلات!$AC$6),SUMIFS($K$14:$K$197,$E$14:$E$197,$C214,$C$14:$C$197,المدخلات!$AC$7),SUMIFS($K$14:$K$197,$E$14:$E$197,$C214,$C$14:$C$197,المدخلات!$AC$8)) | F214: =SUMIFS($K$14:$K$197,$E$14:$E$197,$C214,$C$14:$C$197,المدخلات!$AC$9) | G214: =SUMIFS($K$14:$K$197,$E$14:$E$197,$C214,$C$14:$C$197,المدخلات!$AC$10) | H214: =SUMIFS($K$14:$K$197,$E$14:$E$197,$C214,$C$14:$C$197,المدخلات!$AC$11) | I214: =SUMIFS($K$14:$K$197,$E$14:$E$197,$C214,$C$14:$C$197,المدخلات!$AC$12) | J214: =MAX($E214:$I214) | K214: =SUMIFS($G$14:$G$197,$E$14:$E$197,$C214,$G$14:$G$197,">="&الحد_الأدنى) | L214: =IF($K214=0,"غير مكتملة","مكتملة")
B215: الشرقية | C215: مجموعة الدمام | D215: =IFERROR(INDEX('عدد اللاعبين'!$F$3:$F$186,MATCH($C215,'عدد اللاعبين'!$D$3:$D$186,0)),"") | E215: =MAX(SUMIFS($K$14:$K$197,$E$14:$E$197,$C215,$C$14:$C$197,المدخلات!$AC$6),SUMIFS($K$14:$K$197,$E$14:$E$197,$C215,$C$14:$C$197,المدخلات!$AC$7),SUMIFS($K$14:$K$197,$E$14:$E$197,$C215,$C$14:$C$197,المدخلات!$AC$8)) | F215: =SUMIFS($K$14:$K$197,$E$14:$E$197,$C215,$C$14:$C$197,المدخلات!$AC$9) | G215: =SUMIFS($K$14:$K$197,$E$14:$E$197,$C215,$C$14:$C$197,المدخلات!$AC$10) | H215: =SUMIFS($K$14:$K$197,$E$14:$E$197,$C215,$C$14:$C$197,المدخلات!$AC$11) | I215: =SUMIFS($K$14:$K$197,$E$14:$E$197,$C215,$C$14:$C$197,المدخلات!$AC$12) | J215: =MAX($E215:$I215) | K215: =SUMIFS($G$14:$G$197,$E$14:$E$197,$C215,$G$14:$G$197,">="&الحد_الأدنى) | L215: =IF($K215=0,"غير مكتملة","مكتملة")
B216: الشرقية | C216: مجموعة القطيف | D216: =IFERROR(INDEX('عدد اللاعبين'!$F$3:$F$186,MATCH($C216,'عدد اللاعبين'!$D$3:$D$186,0)),"") | E216: =MAX(SUMIFS($K$14:$K$197,$E$14:$E$197,$C216,$C$14:$C$197,المدخلات!$AC$6),SUMIFS($K$14:$K$197,$E$14:$E$197,$C216,$C$14:$C$197,المدخلات!$AC$7),SUMIFS($K$14:$K$197,$E$14:$E$197,$C216,$C$14:$C$197,المدخلات!$AC$8)) | F216: =SUMIFS($K$14:$K$197,$E$14:$E$197,$C216,$C$14:$C$197,المدخلات!$AC$9) | G216: =SUMIFS($K$14:$K$197,$E$14:$E$197,$C216,$C$14:$C$197,المدخلات!$AC$10) | H216: =SUMIFS($K$14:$K$197,$E$14:$E$197,$C216,$C$14:$C$197,المدخلات!$AC$11) | I216: =SUMIFS($K$14:$K$197,$E$14:$E$197,$C216,$C$14:$C$197,المدخلات!$AC$12) | J216: =MAX($E216:$I216) | K216: =SUMIFS($G$14:$G$197,$E$14:$E$197,$C216,$G$14:$G$197,">="&الحد_الأدنى) | L216: =IF($K216=0,"غير مكتملة","مكتملة")
... B236: نجران | C236: مجموعة نجران | D236: =IFERROR(INDEX('عدد اللاعبين'!$F$3:$F$186,MATCH($C236,'عدد اللاعبين'!$D$3:$D$186,0)),"") | E236: =MAX(SUMIFS($K$14:$K$197,$E$14:$E$197,$C236,$C$14:$C$197,المدخلات!$AC$6),SUMIFS($K$14:$K$197,$E$14:$E$197,$C236,$C$14:$C$197,المدخلات!$AC$7),SUMIFS($K$14:$K$197,$E$14:$E$197,$C236,$C$14:$C$197,المدخلات!$AC$8)) | F236: =SUMIFS($K$14:$K$197,$E$14:$E$197,$C236,$C$14:$C$197,المدخلات!$AC$9) | G236: =SUMIFS($K$14:$K$197,$E$14:$E$197,$C236,$C$14:$C$197,المدخلات!$AC$10) | H236: =SUMIFS($K$14:$K$197,$E$14:$E$197,$C236,$C$14:$C$197,المدخلات!$AC$11) | I236: =SUMIFS($K$14:$K$197,$E$14:$E$197,$C236,$C$14:$C$197,المدخلات!$AC$12) | J236: =MAX($E236:$I236) | K236: =SUMIFS($G$14:$G$197,$E$14:$E$197,$C236,$G$14:$G$197,">="&الحد_الأدنى) | L236: =IF($K236=0,"غير مكتملة","مكتملة")
...

Sheet عدد المباريات
B2: المنطقة | C2: الفئة | D2: المجموعة | E2: عدد المدن | F2: المدن | G2: عدد الفرق | H2: مجموع مباريات المجموعة
B3: =IFERROR(INDEX(المكاتب_المصدر[المنطقة],MATCH(Table10[[#This Row],[المجموعة]],المكاتب_المصدر[المجموعة],0)),"") | C3: ='ملخص المجموعات'!B3 | D3: ='ملخص المجموعات'!C3 | E3: ='ملخص المجموعات'!D3 | F3: ='ملخص المجموعات'!E3 | G3: ='ملخص المجموعات'!F3 | H3: =IF(Table10[[#This Row],[عدد الفرق]]<الحد_الأدنى,0,Table10[[#This Row],[عدد الفرق]]*IF(OR(Table10[[#This Row],[الفئة]]="تحت 5",Table10[[#This Row],[الفئة]]="تحت 7",Table10[[#This Row],[الفئة]]="تحت 9"),المدخلات!$T$3,المدخلات!$V$3)/2)
B4: =IFERROR(INDEX(المكاتب_المصدر[المنطقة],MATCH(Table10[[#This Row],[المجموعة]],المكاتب_المصدر[المجموعة],0)),"") | C4: ='ملخص المجموعات'!B4 | D4: ='ملخص المجموعات'!C4 | E4: ='ملخص المجموعات'!D4 | F4: ='ملخص المجموعات'!E4 | G4: ='ملخص المجموعات'!F4 | H4: =IF(Table10[[#This Row],[عدد الفرق]]<الحد_الأدنى,0,Table10[[#This Row],[عدد الفرق]]*IF(OR(Table10[[#This Row],[الفئة]]="تحت 5",Table10[[#This Row],[الفئة]]="تحت 7",Table10[[#This Row],[الفئة]]="تحت 9"),المدخلات!$T$3,المدخلات!$V$3)/2)
B5: =IFERROR(INDEX(المكاتب_المصدر[المنطقة],MATCH(Table10[[#This Row],[المجموعة]],المكاتب_المصدر[المجموعة],0)),"") | C5: ='ملخص المجموعات'!B5 | D5: ='ملخص المجموعات'!C5 | E5: ='ملخص المجموعات'!D5 | F5: ='ملخص المجموعات'!E5 | G5: ='ملخص المجموعات'!F5 | H5: =IF(Table10[[#This Row],[عدد الفرق]]<الحد_الأدنى,0,Table10[[#This Row],[عدد الفرق]]*IF(OR(Table10[[#This Row],[الفئة]]="تحت 5",Table10[[#This Row],[الفئة]]="تحت 7",Table10[[#This Row],[الفئة]]="تحت 9"),المدخلات!$T$3,المدخلات!$V$3)/2)
B6: =IFERROR(INDEX(المكاتب_المصدر[المنطقة],MATCH(Table10[[#This Row],[المجموعة]],المكاتب_المصدر[المجموعة],0)),"") | C6: ='ملخص المجموعات'!B6 | D6: ='ملخص المجموعات'!C6 | E6: ='ملخص المجموعات'!D6 | F6: ='ملخص المجموعات'!E6 | G6: ='ملخص المجموعات'!F6 | H6: =IF(Table10[[#This Row],[عدد الفرق]]<الحد_الأدنى,0,Table10[[#This Row],[عدد الفرق]]*IF(OR(Table10[[#This Row],[الفئة]]="تحت 5",Table10[[#This Row],[الفئة]]="تحت 7",Table10[[#This Row],[الفئة]]="تحت 9"),المدخلات!$T$3,المدخلات!$V$3)/2)
B7: =IFERROR(INDEX(المكاتب_المصدر[المنطقة],MATCH(Table10[[#This Row],[المجموعة]],المكاتب_المصدر[المجموعة],0)),"") | C7: ='ملخص المجموعات'!B7 | D7: ='ملخص المجموعات'!C7 | E7: ='ملخص المجموعات'!D7 | F7: ='ملخص المجموعات'!E7 | G7: ='ملخص المجموعات'!F7 | H7: =IF(Table10[[#This Row],[عدد الفرق]]<الحد_الأدنى,0,Table10[[#This Row],[عدد الفرق]]*IF(OR(Table10[[#This Row],[الفئة]]="تحت 5",Table10[[#This Row],[الفئة]]="تحت 7",Table10[[#This Row],[الفئة]]="تحت 9"),المدخلات!$T$3,المدخلات!$V$3)/2)
B8: =IFERROR(INDEX(المكاتب_المصدر[المنطقة],MATCH(Table10[[#This Row],[المجموعة]],المكاتب_المصدر[المجموعة],0)),"") | C8: ='ملخص المجموعات'!B8 | D8: ='ملخص المجموعات'!C8 | E8: ='ملخص المجموعات'!D8 | F8: ='ملخص المجموعات'!E8 | G8: ='ملخص المجموعات'!F8 | H8: =IF(Table10[[#This Row],[عدد الفرق]]<الحد_الأدنى,0,Table10[[#This Row],[عدد الفرق]]*IF(OR(Table10[[#This Row],[الفئة]]="تحت 5",Table10[[#This Row],[الفئة]]="تحت 7",Table10[[#This Row],[الفئة]]="تحت 9"),المدخلات!$T$3,المدخلات!$V$3)/2)
B9: =IFERROR(INDEX(المكاتب_المصدر[المنطقة],MATCH(Table10[[#This Row],[المجموعة]],المكاتب_المصدر[المجموعة],0)),"") | C9: ='ملخص المجموعات'!B9 | D9: ='ملخص المجموعات'!C9 | E9: ='ملخص المجموعات'!D9 | F9: ='ملخص المجموعات'!E9 | G9: ='ملخص المجموعات'!F9 | H9: =IF(Table10[[#This Row],[عدد الفرق]]<الحد_الأدنى,0,Table10[[#This Row],[عدد الفرق]]*IF(OR(Table10[[#This Row],[الفئة]]="تحت 5",Table10[[#This Row],[الفئة]]="تحت 7",Table10[[#This Row],[الفئة]]="تحت 9"),المدخلات!$T$3,المدخلات!$V$3)/2)
B10: =IFERROR(INDEX(المكاتب_المصدر[المنطقة],MATCH(Table10[[#This Row],[المجموعة]],المكاتب_المصدر[المجموعة],0)),"") | C10: ='ملخص المجموعات'!B10 | D10: ='ملخص المجموعات'!C10 | E10: ='ملخص المجموعات'!D10 | F10: ='ملخص المجموعات'!E10 | G10: ='ملخص المجموعات'!F10 | H10: =IF(Table10[[#This Row],[عدد الفرق]]<الحد_الأدنى,0,Table10[[#This Row],[عدد الفرق]]*IF(OR(Table10[[#This Row],[الفئة]]="تحت 5",Table10[[#This Row],[الفئة]]="تحت 7",Table10[[#This Row],[الفئة]]="تحت 9"),المدخلات!$T$3,المدخلات!$V$3)/2)
B11: =IFERROR(INDEX(المكاتب_المصدر[المنطقة],MATCH(Table10[[#This Row],[المجموعة]],المكاتب_المصدر[المجموعة],0)),"") | C11: ='ملخص المجموعات'!B11 | D11: ='ملخص المجموعات'!C11 | E11: ='ملخص المجموعات'!D11 | F11: ='ملخص المجموعات'!E11 | G11: ='ملخص المجموعات'!F11 | H11: =IF(Table10[[#This Row],[عدد الفرق]]<الحد_الأدنى,0,Table10[[#This Row],[عدد الفرق]]*IF(OR(Table10[[#This Row],[الفئة]]="تحت 5",Table10[[#This Row],[الفئة]]="تحت 7",Table10[[#This Row],[الفئة]]="تحت 9"),المدخلات!$T$3,المدخلات!$V$3)/2)
B12: =IFERROR(INDEX(المكاتب_المصدر[المنطقة],MATCH(Table10[[#This Row],[المجموعة]],المكاتب_المصدر[المجموعة],0)),"") | C12: ='ملخص المجموعات'!B12 | D12: ='ملخص المجموعات'!C12 | E12: ='ملخص المجموعات'!D12 | F12: ='ملخص المجموعات'!E12 | G12: ='ملخص المجموعات'!F12 | H12: =IF(Table10[[#This Row],[عدد الفرق]]<الحد_الأدنى,0,Table10[[#This Row],[عدد الفرق]]*IF(OR(Table10[[#This Row],[الفئة]]="تحت 5",Table10[[#This Row],[الفئة]]="تحت 7",Table10[[#This Row],[الفئة]]="تحت 9"),المدخلات!$T$3,المدخلات!$V$3)/2)
B13: =IFERROR(INDEX(المكاتب_المصدر[المنطقة],MATCH(Table10[[#This Row],[المجموعة]],المكاتب_المصدر[المجموعة],0)),"") | C13: ='ملخص المجموعات'!B13 | D13: ='ملخص المجموعات'!C13 | E13: ='ملخص المجموعات'!D13 | F13: ='ملخص المجموعات'!E13 | G13: ='ملخص المجموعات'!F13 | H13: =IF(Table10[[#This Row],[عدد الفرق]]<الحد_الأدنى,0,Table10[[#This Row],[عدد الفرق]]*IF(OR(Table10[[#This Row],[الفئة]]="تحت 5",Table10[[#This Row],[الفئة]]="تحت 7",Table10[[#This Row],[الفئة]]="تحت 9"),المدخلات!$T$3,المدخلات!$V$3)/2)
B14: =IFERROR(INDEX(المكاتب_المصدر[المنطقة],MATCH(Table10[[#This Row],[المجموعة]],المكاتب_المصدر[المجموعة],0)),"") | C14: ='ملخص المجموعات'!B14 | D14: ='ملخص المجموعات'!C14 | E14: ='ملخص المجموعات'!D14 | F14: ='ملخص المجموعات'!E14 | G14: ='ملخص المجموعات'!F14 | H14: =IF(Table10[[#This Row],[عدد الفرق]]<الحد_الأدنى,0,Table10[[#This Row],[عدد الفرق]]*IF(OR(Table10[[#This Row],[الفئة]]="تحت 5",Table10[[#This Row],[الفئة]]="تحت 7",Table10[[#This Row],[الفئة]]="تحت 9"),المدخلات!$T$3,المدخلات!$V$3)/2)
... B186: =IFERROR(INDEX(المكاتب_المصدر[المنطقة],MATCH(Table10[[#This Row],[المجموعة]],المكاتب_المصدر[المجموعة],0)),"") | C186: ='ملخص المجموعات'!B186 | D186: ='ملخص المجموعات'!C186 | E186: ='ملخص المجموعات'!D186 | F186: ='ملخص المجموعات'!E186 | G186: ='ملخص المجموعات'!F186 | H186: =IF(Table10[[#This Row],[عدد الفرق]]<الحد_الأدنى,0,Table10[[#This Row],[عدد الفرق]]*IF(OR(Table10[[#This Row],[الفئة]]="تحت 5",Table10[[#This Row],[الفئة]]="تحت 7",Table10[[#This Row],[الفئة]]="تحت 9"),المدخلات!$T$3,المدخلات!$V$3)/2)

Sheet عدد اللاعبين
B2: المنطقة | C2: الفئة | D2: المجموعة | E2: عدد المدن | F2: المدن | G2: عدد الفرق | H2: عدد اللاعبين
B3: =IFERROR(INDEX(المكاتب_المصدر[المنطقة],MATCH('عدد اللاعبين'!$D3,المكاتب_المصدر[المجموعة],0)),"") | C3: ='ملخص المجموعات'!B3 | D3: ='ملخص المجموعات'!C3 | E3: ='ملخص المجموعات'!D3 | F3: ='ملخص المجموعات'!E3 | G3: ='ملخص المجموعات'!F3 | H3: =IF('عدد اللاعبين'!$G3<الحد_الأدنى,0,'عدد اللاعبين'!$G3*IFERROR(INDEX(المدخلات!$Y$3:$Y$9,MATCH('عدد اللاعبين'!$C3,المدخلات!$X$3:$X$9,0)),0))
B4: =IFERROR(INDEX(المكاتب_المصدر[المنطقة],MATCH('عدد اللاعبين'!$D4,المكاتب_المصدر[المجموعة],0)),"") | C4: ='ملخص المجموعات'!B4 | D4: ='ملخص المجموعات'!C4 | E4: ='ملخص المجموعات'!D4 | F4: ='ملخص المجموعات'!E4 | G4: ='ملخص المجموعات'!F4 | H4: =IF('عدد اللاعبين'!$G4<الحد_الأدنى,0,'عدد اللاعبين'!$G4*IFERROR(INDEX(المدخلات!$Y$3:$Y$9,MATCH('عدد اللاعبين'!$C4,المدخلات!$X$3:$X$9,0)),0))
B5: =IFERROR(INDEX(المكاتب_المصدر[المنطقة],MATCH('عدد اللاعبين'!$D5,المكاتب_المصدر[المجموعة],0)),"") | C5: ='ملخص المجموعات'!B5 | D5: ='ملخص المجموعات'!C5 | E5: ='ملخص المجموعات'!D5 | F5: ='ملخص المجموعات'!E5 | G5: ='ملخص المجموعات'!F5 | H5: =IF('عدد اللاعبين'!$G5<الحد_الأدنى,0,'عدد اللاعبين'!$G5*IFERROR(INDEX(المدخلات!$Y$3:$Y$9,MATCH('عدد اللاعبين'!$C5,المدخلات!$X$3:$X$9,0)),0))
B6: =IFERROR(INDEX(المكاتب_المصدر[المنطقة],MATCH('عدد اللاعبين'!$D6,المكاتب_المصدر[المجموعة],0)),"") | C6: ='ملخص المجموعات'!B6 | D6: ='ملخص المجموعات'!C6 | E6: ='ملخص المجموعات'!D6 | F6: ='ملخص المجموعات'!E6 | G6: ='ملخص المجموعات'!F6 | H6: =IF('عدد اللاعبين'!$G6<الحد_الأدنى,0,'عدد اللاعبين'!$G6*IFERROR(INDEX(المدخلات!$Y$3:$Y$9,MATCH('عدد اللاعبين'!$C6,المدخلات!$X$3:$X$9,0)),0))
B7: =IFERROR(INDEX(المكاتب_المصدر[المنطقة],MATCH('عدد اللاعبين'!$D7,المكاتب_المصدر[المجموعة],0)),"") | C7: ='ملخص المجموعات'!B7 | D7: ='ملخص المجموعات'!C7 | E7: ='ملخص المجموعات'!D7 | F7: ='ملخص المجموعات'!E7 | G7: ='ملخص المجموعات'!F7 | H7: =IF('عدد اللاعبين'!$G7<الحد_الأدنى,0,'عدد اللاعبين'!$G7*IFERROR(INDEX(المدخلات!$Y$3:$Y$9,MATCH('عدد اللاعبين'!$C7,المدخلات!$X$3:$X$9,0)),0))
B8: =IFERROR(INDEX(المكاتب_المصدر[المنطقة],MATCH('عدد اللاعبين'!$D8,المكاتب_المصدر[المجموعة],0)),"") | C8: ='ملخص المجموعات'!B8 | D8: ='ملخص المجموعات'!C8 | E8: ='ملخص المجموعات'!D8 | F8: ='ملخص المجموعات'!E8 | G8: ='ملخص المجموعات'!F8 | H8: =IF('عدد اللاعبين'!$G8<الحد_الأدنى,0,'عدد اللاعبين'!$G8*IFERROR(INDEX(المدخلات!$Y$3:$Y$9,MATCH('عدد اللاعبين'!$C8,المدخلات!$X$3:$X$9,0)),0))
B9: =IFERROR(INDEX(المكاتب_المصدر[المنطقة],MATCH('عدد اللاعبين'!$D9,المكاتب_المصدر[المجموعة],0)),"") | C9: ='ملخص المجموعات'!B9 | D9: ='ملخص المجموعات'!C9 | E9: ='ملخص المجموعات'!D9 | F9: ='ملخص المجموعات'!E9 | G9: ='ملخص المجموعات'!F9 | H9: =IF('عدد اللاعبين'!$G9<الحد_الأدنى,0,'عدد اللاعبين'!$G9*IFERROR(INDEX(المدخلات!$Y$3:$Y$9,MATCH('عدد اللاعبين'!$C9,المدخلات!$X$3:$X$9,0)),0))
B10: =IFERROR(INDEX(المكاتب_المصدر[المنطقة],MATCH('عدد اللاعبين'!$D10,المكاتب_المصدر[المجموعة],0)),"") | C10: ='ملخص المجموعات'!B10 | D10: ='ملخص المجموعات'!C10 | E10: ='ملخص المجموعات'!D10 | F10: ='ملخص المجموعات'!E10 | G10: ='ملخص المجموعات'!F10 | H10: =IF('عدد اللاعبين'!$G10<الحد_الأدنى,0,'عدد اللاعبين'!$G10*IFERROR(INDEX(المدخلات!$Y$3:$Y$9,MATCH('عدد اللاعبين'!$C10,المدخلات!$X$3:$X$9,0)),0))
B11: =IFERROR(INDEX(المكاتب_المصدر[المنطقة],MATCH('عدد اللاعبين'!$D11,المكاتب_المصدر[المجموعة],0)),"") | C11: ='ملخص المجموعات'!B11 | D11: ='ملخص المجموعات'!C11 | E11: ='ملخص المجموعات'!D11 | F11: ='ملخص المجموعات'!E11 | G11: ='ملخص المجموعات'!F11 | H11: =IF('عدد اللاعبين'!$G11<الحد_الأدنى,0,'عدد اللاعبين'!$G11*IFERROR(INDEX(المدخلات!$Y$3:$Y$9,MATCH('عدد اللاعبين'!$C11,المدخلات!$X$3:$X$9,0)),0))
B12: =IFERROR(INDEX(المكاتب_المصدر[المنطقة],MATCH('عدد اللاعبين'!$D12,المكاتب_المصدر[المجموعة],0)),"") | C12: ='ملخص المجموعات'!B12 | D12: ='ملخص المجموعات'!C12 | E12: ='ملخص المجموعات'!D12 | F12: ='ملخص المجموعات'!E12 | G12: ='ملخص المجموعات'!F12 | H12: =IF('عدد اللاعبين'!$G12<الحد_الأدنى,0,'عدد اللاعبين'!$G12*IFERROR(INDEX(المدخلات!$Y$3:$Y$9,MATCH('عدد اللاعبين'!$C12,المدخلات!$X$3:$X$9,0)),0))
B13: =IFERROR(INDEX(المكاتب_المصدر[المنطقة],MATCH('عدد اللاعبين'!$D13,المكاتب_المصدر[المجموعة],0)),"") | C13: ='ملخص المجموعات'!B13 | D13: ='ملخص المجموعات'!C13 | E13: ='ملخص المجموعات'!D13 | F13: ='ملخص المجموعات'!E13 | G13: ='ملخص المجموعات'!F13 | H13: =IF('عدد اللاعبين'!$G13<الحد_الأدنى,0,'عدد اللاعبين'!$G13*IFERROR(INDEX(المدخلات!$Y$3:$Y$9,MATCH('عدد اللاعبين'!$C13,المدخلات!$X$3:$X$9,0)),0))
B14: =IFERROR(INDEX(المكاتب_المصدر[المنطقة],MATCH('عدد اللاعبين'!$D14,المكاتب_المصدر[المجموعة],0)),"") | C14: ='ملخص المجموعات'!B14 | D14: ='ملخص المجموعات'!C14 | E14: ='ملخص المجموعات'!D14 | F14: ='ملخص المجموعات'!E14 | G14: ='ملخص المجموعات'!F14 | H14: =IF('عدد اللاعبين'!$G14<الحد_الأدنى,0,'عدد اللاعبين'!$G14*IFERROR(INDEX(المدخلات!$Y$3:$Y$9,MATCH('عدد اللاعبين'!$C14,المدخلات!$X$3:$X$9,0)),0))
... B186: =IFERROR(INDEX(المكاتب_المصدر[المنطقة],MATCH('عدد اللاعبين'!$D186,المكاتب_المصدر[المجموعة],0)),"") | C186: ='ملخص المجموعات'!B186 | D186: ='ملخص المجموعات'!C186 | E186: ='ملخص المجموعات'!D186 | F186: ='ملخص المجموعات'!E186 | G186: ='ملخص المجموعات'!F186 | H186: =IF('عدد اللاعبين'!$G186<الحد_الأدنى,0,'عدد اللاعبين'!$G186*IFERROR(INDEX(المدخلات!$Y$3:$Y$9,MATCH('عدد اللاعبين'!$C186,المدخلات!$X$3:$X$9,0)),0))

Sheet ملخص المجموعات
B2: الفئة | C2: المجموعة | D2: عدد المدن | E2: المدن | F2: مجموع الفرق | G2: المتبقي | I2: المدن في مجموعات مكتملة (بها نادي واحد على الأقل)
B3: تحت 14 | C3: مجموعة نجران | D3: =COUNTIFS(تفاصيل_الفرق[الفئة العمرية],ملخص_المجموعات[[#This Row],[الفئة]],تفاصيل_الفرق[المجموعة],ملخص_المجموعات[[#This Row],[المجموعة]],تفاصيل_الفرق[عدد الفرق],">0") | E3: {=_xlfn.TEXTJOIN("، ",TRUE,IF((تفاصيل_الفرق[الفئة العمرية]=ملخص_المجموعات[[#This Row],[الفئة]])*(تفاصيل_الفرق[المجموعة]=ملخص_المجموعات[[#This Row],[المجموعة]])*(تفاصيل_الفرق[عدد الفرق]>0),تفاصيل_الفرق[المدينة/المحافظة],""))} | F3: =SUMIFS(تفاصيل_الفرق[عدد الفرق],تفاصيل_الفرق[الفئة العمرية],ملخص_المجموعات[[#This Row],[الفئة]],تفاصيل_الفرق[المجموعة],ملخص_المجموعات[[#This Row],[المجموعة]]) | G3: =MAX(0,الحد_الأدنى-ملخص_المجموعات[[#This Row],[مجموع الفرق]]) | I3: {=_xlfn.LET(_xlpm.t,ملخص_المجموعات[المدن],_xlpm.r,ملخص_المجموعات[المتبقي],_xlpm.f,ملخص_المجموعات[مجموع الفرق],_xlpm.s,_xlfn.TEXTJOIN("، ",TRUE,IF((_xlpm.r=0)*(_xlpm.f>=1),_xlpm.t,"")),COUNTA(_xlfn.UNIQUE(TRIM(_xlfn.TEXTSPLIT(_xlpm.s,"، ")),TRUE)))} | J3: عدد المدن (بدون تكرار)
B4: تحت 5 | C4: مجموعة طبرجل | D4: =COUNTIFS(تفاصيل_الفرق[الفئة العمرية],ملخص_المجموعات[[#This Row],[الفئة]],تفاصيل_الفرق[المجموعة],ملخص_المجموعات[[#This Row],[المجموعة]],تفاصيل_الفرق[عدد الفرق],">0") | E4: {=_xlfn.TEXTJOIN("، ",TRUE,IF((تفاصيل_الفرق[الفئة العمرية]=ملخص_المجموعات[[#This Row],[الفئة]])*(تفاصيل_الفرق[المجموعة]=ملخص_المجموعات[[#This Row],[المجموعة]])*(تفاصيل_الفرق[عدد الفرق]>0),تفاصيل_الفرق[المدينة/المحافظة],""))} | F4: =SUMIFS(تفاصيل_الفرق[عدد الفرق],تفاصيل_الفرق[الفئة العمرية],ملخص_المجموعات[[#This Row],[الفئة]],تفاصيل_الفرق[المجموعة],ملخص_المجموعات[[#This Row],[المجموعة]]) | G4: =MAX(0,الحد_الأدنى-ملخص_المجموعات[[#This Row],[مجموع الفرق]]) | I4: {=SUMPRODUCT((ملخص_المجموعات[المتبقي]=0)*(ملخص_المجموعات[مجموع الفرق]>=1))} | J4: عدد المجموعات المكتملة
B5: تحت 7 | C5: مجموعة طبرجل | D5: =COUNTIFS(تفاصيل_الفرق[الفئة العمرية],ملخص_المجموعات[[#This Row],[الفئة]],تفاصيل_الفرق[المجموعة],ملخص_المجموعات[[#This Row],[المجموعة]],تفاصيل_الفرق[عدد الفرق],">0") | E5: {=_xlfn.TEXTJOIN("، ",TRUE,IF((تفاصيل_الفرق[الفئة العمرية]=ملخص_المجموعات[[#This Row],[الفئة]])*(تفاصيل_الفرق[المجموعة]=ملخص_المجموعات[[#This Row],[المجموعة]])*(تفاصيل_الفرق[عدد الفرق]>0),تفاصيل_الفرق[المدينة/المحافظة],""))} | F5: =SUMIFS(تفاصيل_الفرق[عدد الفرق],تفاصيل_الفرق[الفئة العمرية],ملخص_المجموعات[[#This Row],[الفئة]],تفاصيل_الفرق[المجموعة],ملخص_المجموعات[[#This Row],[المجموعة]]) | G5: =MAX(0,الحد_الأدنى-ملخص_المجموعات[[#This Row],[مجموع الفرق]]) | I5: {=SUMPRODUCT((تفاصيل_الفرق[عدد الفرق]>=1)*(تفاصيل_الفرق[مجموعة مكتملة]=1))} | J5: عدد (مدينة × فئة) في مجموعات مكتملة ولها فرق
B6: تحت 9 | C6: مجموعة الخرج | D6: =COUNTIFS(تفاصيل_الفرق[الفئة العمرية],ملخص_المجموعات[[#This Row],[الفئة]],تفاصيل_الفرق[المجموعة],ملخص_المجموعات[[#This Row],[المجموعة]],تفاصيل_الفرق[عدد الفرق],">0") | E6: {=_xlfn.TEXTJOIN("، ",TRUE,IF((تفاصيل_الفرق[الفئة العمرية]=ملخص_المجموعات[[#This Row],[الفئة]])*(تفاصيل_الفرق[المجموعة]=ملخص_المجموعات[[#This Row],[المجموعة]])*(تفاصيل_الفرق[عدد الفرق]>0),تفاصيل_الفرق[المدينة/المحافظة],""))} | F6: =SUMIFS(تفاصيل_الفرق[عدد الفرق],تفاصيل_الفرق[الفئة العمرية],ملخص_المجموعات[[#This Row],[الفئة]],تفاصيل_الفرق[المجموعة],ملخص_المجموعات[[#This Row],[المجموعة]]) | G6: =MAX(0,الحد_الأدنى-ملخص_المجموعات[[#This Row],[مجموع الفرق]]) | I6: {=COUNTA(_xlfn.UNIQUE(_xlfn._xlws.FILTER(تفاصيل_الفرق[المدينة/المحافظة],(تفاصيل_الفرق[عدد الفرق]>=1)*(تفاصيل_الفرق[مجموعة مكتملة]=1))))} | J6: عدد المدن الفريدة (بنفس الشرط)
B7: تحت 12 | C7: مجموعة طبرجل | D7: =COUNTIFS(تفاصيل_الفرق[الفئة العمرية],ملخص_المجموعات[[#This Row],[الفئة]],تفاصيل_الفرق[المجموعة],ملخص_المجموعات[[#This Row],[المجموعة]],تفاصيل_الفرق[عدد الفرق],">0") | E7: {=_xlfn.TEXTJOIN("، ",TRUE,IF((تفاصيل_الفرق[الفئة العمرية]=ملخص_المجموعات[[#This Row],[الفئة]])*(تفاصيل_الفرق[المجموعة]=ملخص_المجموعات[[#This Row],[المجموعة]])*(تفاصيل_الفرق[عدد الفرق]>0),تفاصيل_الفرق[المدينة/المحافظة],""))} | F7: =SUMIFS(تفاصيل_الفرق[عدد الفرق],تفاصيل_الفرق[الفئة العمرية],ملخص_المجموعات[[#This Row],[الفئة]],تفاصيل_الفرق[المجموعة],ملخص_المجموعات[[#This Row],[المجموعة]]) | G7: =MAX(0,الحد_الأدنى-ملخص_المجموعات[[#This Row],[مجموع الفرق]])
B8: تحت 14 | C8: مجموعة طبرجل | D8: =COUNTIFS(تفاصيل_الفرق[الفئة العمرية],ملخص_المجموعات[[#This Row],[الفئة]],تفاصيل_الفرق[المجموعة],ملخص_المجموعات[[#This Row],[المجموعة]],تفاصيل_الفرق[عدد الفرق],">0") | E8: {=_xlfn.TEXTJOIN("، ",TRUE,IF((تفاصيل_الفرق[الفئة العمرية]=ملخص_المجموعات[[#This Row],[الفئة]])*(تفاصيل_الفرق[المجموعة]=ملخص_المجموعات[[#This Row],[المجموعة]])*(تفاصيل_الفرق[عدد الفرق]>0),تفاصيل_الفرق[المدينة/المحافظة],""))} | F8: =SUMIFS(تفاصيل_الفرق[عدد الفرق],تفاصيل_الفرق[الفئة العمرية],ملخص_المجموعات[[#This Row],[الفئة]],تفاصيل_الفرق[المجموعة],ملخص_المجموعات[[#This Row],[المجموعة]]) | G8: =MAX(0,الحد_الأدنى-ملخص_المجموعات[[#This Row],[مجموع الفرق]])
B9: تحت 7 | C9: مجموعة شرورة | D9: =COUNTIFS(تفاصيل_الفرق[الفئة العمرية],ملخص_المجموعات[[#This Row],[الفئة]],تفاصيل_الفرق[المجموعة],ملخص_المجموعات[[#This Row],[المجموعة]],تفاصيل_الفرق[عدد الفرق],">0") | E9: {=_xlfn.TEXTJOIN("، ",TRUE,IF((تفاصيل_الفرق[الفئة العمرية]=ملخص_المجموعات[[#This Row],[الفئة]])*(تفاصيل_الفرق[المجموعة]=ملخص_المجموعات[[#This Row],[المجموعة]])*(تفاصيل_الفرق[عدد الفرق]>0),تفاصيل_الفرق[المدينة/المحافظة],""))} | F9: =SUMIFS(تفاصيل_الفرق[عدد الفرق],تفاصيل_الفرق[الفئة العمرية],ملخص_المجموعات[[#This Row],[الفئة]],تفاصيل_الفرق[المجموعة],ملخص_المجموعات[[#This Row],[المجموعة]]) | G9: =MAX(0,الحد_الأدنى-ملخص_المجموعات[[#This Row],[مجموع الفرق]]) | I9: مجموعات فيها 5 فرق بالضبط
B10: تحت 9 | C10: مجموعة شرورة | D10: =COUNTIFS(تفاصيل_الفرق[الفئة العمرية],ملخص_المجموعات[[#This Row],[الفئة]],تفاصيل_الفرق[المجموعة],ملخص_المجموعات[[#This Row],[المجموعة]],تفاصيل_الفرق[عدد الفرق],">0") | E10: {=_xlfn.TEXTJOIN("، ",TRUE,IF((تفاصيل_الفرق[الفئة العمرية]=ملخص_المجموعات[[#This Row],[الفئة]])*(تفاصيل_الفرق[المجموعة]=ملخص_المجموعات[[#This Row],[المجموعة]])*(تفاصيل_الفرق[عدد الفرق]>0),تفاصيل_الفرق[المدينة/المحافظة],""))} | F10: =SUMIFS(تفاصيل_الفرق[عدد الفرق],تفاصيل_الفرق[الفئة العمرية],ملخص_المجموعات[[#This Row],[الفئة]],تفاصيل_الفرق[المجموعة],ملخص_المجموعات[[#This Row],[المجموعة]]) | G10: =MAX(0,الحد_الأدنى-ملخص_المجموعات[[#This Row],[مجموع الفرق]]) | I10: الفئة | J10: المجموعة | K10: مجموع الفرق
B11: تحت 9 | C11: مجموعة الدوادمي | D11: =COUNTIFS(تفاصيل_الفرق[الفئة العمرية],ملخص_المجموعات[[#This Row],[الفئة]],تفاصيل_الفرق[المجموعة],ملخص_المجموعات[[#This Row],[المجموعة]],تفاصيل_الفرق[عدد الفرق],">0") | E11: {=_xlfn.TEXTJOIN("، ",TRUE,IF((تفاصيل_الفرق[الفئة العمرية]=ملخص_المجموعات[[#This Row],[الفئة]])*(تفاصيل_الفرق[المجموعة]=ملخص_المجموعات[[#This Row],[المجموعة]])*(تفاصيل_الفرق[عدد الفرق]>0),تفاصيل_الفرق[المدينة/المحافظة],""))} | F11: =SUMIFS(تفاصيل_الفرق[عدد الفرق],تفاصيل_الفرق[الفئة العمرية],ملخص_المجموعات[[#This Row],[الفئة]],تفاصيل_الفرق[المجموعة],ملخص_المجموعات[[#This Row],[المجموعة]]) | G11: =MAX(0,الحد_الأدنى-ملخص_المجموعات[[#This Row],[مجموع الفرق]]) | I11: {=_xlfn._xlws.FILTER(ملخص_المجموعات[الفئة],ملخص_المجموعات[مجموع الفرق]=5,"لا يوجد")} | J11: {=_xlfn._xlws.FILTER(ملخص_المجموعات[المجموعة],ملخص_المجموعات[مجموع الفرق]=5,"")} | K11: {=_xlfn._xlws.FILTER(ملخص_المجموعات[مجموع الفرق],ملخص_المجموعات[مجموع الفرق]=5,"")}
B12: تحت 11 | C12: مجموعة القريات | D12: =COUNTIFS(تفاصيل_الفرق[الفئة العمرية],ملخص_المجموعات[[#This Row],[الفئة]],تفاصيل_الفرق[المجموعة],ملخص_المجموعات[[#This Row],[المجموعة]],تفاصيل_الفرق[عدد الفرق],">0") | E12: {=_xlfn.TEXTJOIN("، ",TRUE,IF((تفاصيل_الفرق[الفئة العمرية]=ملخص_المجموعات[[#This Row],[الفئة]])*(تفاصيل_الفرق[المجموعة]=ملخص_المجموعات[[#This Row],[المجموعة]])*(تفاصيل_الفرق[عدد الفرق]>0),تفاصيل_الفرق[المدينة/المحافظة],""))} | F12: =SUMIFS(تفاصيل_الفرق[عدد الفرق],تفاصيل_الفرق[الفئة العمرية],ملخص_المجموعات[[#This Row],[الفئة]],تفاصيل_الفرق[المجموعة],ملخص_المجموعات[[#This Row],[المجموعة]]) | G12: =MAX(0,الحد_الأدنى-ملخص_المجموعات[[#This Row],[مجموع الفرق]]) | I12: تحت 5 | J12: مجموعة طبرجل | K12: 5
B13: تحت 12 | C13: مجموعة القريات | D13: =COUNTIFS(تفاصيل_الفرق[الفئة العمرية],ملخص_المجموعات[[#This Row],[الفئة]],تفاصيل_الفرق[المجموعة],ملخص_المجموعات[[#This Row],[المجموعة]],تفاصيل_الفرق[عدد الفرق],">0") | E13: {=_xlfn.TEXTJOIN("، ",TRUE,IF((تفاصيل_الفرق[الفئة العمرية]=ملخص_المجموعات[[#This Row],[الفئة]])*(تفاصيل_الفرق[المجموعة]=ملخص_المجموعات[[#This Row],[المجموعة]])*(تفاصيل_الفرق[عدد الفرق]>0),تفاصيل_الفرق[المدينة/المحافظة],""))} | F13: =SUMIFS(تفاصيل_الفرق[عدد الفرق],تفاصيل_الفرق[الفئة العمرية],ملخص_المجموعات[[#This Row],[الفئة]],تفاصيل_الفرق[المجموعة],ملخص_المجموعات[[#This Row],[المجموعة]]) | G13: =MAX(0,الحد_الأدنى-ملخص_المجموعات[[#This Row],[مجموع الفرق]]) | I13: تحت 7 | J13: مجموعة طبرجل | K13: 5
B14: تحت 13 | C14: مجموعة القريات | D14: =COUNTIFS(تفاصيل_الفرق[الفئة العمرية],ملخص_المجموعات[[#This Row],[الفئة]],تفاصيل_الفرق[المجموعة],ملخص_المجموعات[[#This Row],[المجموعة]],تفاصيل_الفرق[عدد الفرق],">0") | E14: {=_xlfn.TEXTJOIN("، ",TRUE,IF((تفاصيل_الفرق[الفئة العمرية]=ملخص_المجموعات[[#This Row],[الفئة]])*(تفاصيل_الفرق[المجموعة]=ملخص_المجموعات[[#This Row],[المجموعة]])*(تفاصيل_الفرق[عدد الفرق]>0),تفاصيل_الفرق[المدينة/المحافظة],""))} | F14: =SUMIFS(تفاصيل_الفرق[عدد الفرق],تفاصيل_الفرق[الفئة العمرية],ملخص_المجموعات[[#This Row],[الفئة]],تفاصيل_الفرق[المجموعة],ملخص_المجموعات[[#This Row],[المجموعة]]) | G14: =MAX(0,الحد_الأدنى-ملخص_المجموعات[[#This Row],[مجموع الفرق]]) | I14: تحت 9 | J14: مجموعة الخرج | K14: 5
B15: تحت 14 | C15: مجموعة القريات | D15: =COUNTIFS(تفاصيل_الفرق[الفئة العمرية],ملخص_المجموعات[[#This Row],[الفئة]],تفاصيل_الفرق[المجموعة],ملخص_المجموعات[[#This Row],[المجموعة]],تفاصيل_الفرق[عدد الفرق],">0") | E15: {=_xlfn.TEXTJOIN("، ",TRUE,IF((تفاصيل_الفرق[الفئة العمرية]=ملخص_المجموعات[[#This Row],[الفئة]])*(تفاصيل_الفرق[المجموعة]=ملخص_المجموعات[[#This Row],[المجموعة]])*(تفاصيل_الفرق[عدد الفرق]>0),تفاصيل_الفرق[المدينة/المحافظة],""))} | F15: =SUMIFS(تفاصيل_الفرق[عدد الفرق],تفاصيل_الفرق[الفئة العمرية],ملخص_المجموعات[[#This Row],[الفئة]],تفاصيل_الفرق[المجموعة],ملخص_المجموعات[[#This Row],[المجموعة]]) | G15: =MAX(0,الحد_الأدنى-ملخص_المجموعات[[#This Row],[مجموع الفرق]]) | I15: تحت 12 | J15: مجموعة طبرجل | K15: 5
B16: تحت 12 | C16: مجموعة الباحة | D16: =COUNTIFS(تفاصيل_الفرق[الفئة العمرية],ملخص_المجموعات[[#This Row],[الفئة]],تفاصيل_الفرق[المجموعة],ملخص_المجموعات[[#This Row],[المجموعة]],تفاصيل_الفرق[عدد الفرق],">0") | E16: {=_xlfn.TEXTJOIN("، ",TRUE,IF((تفاصيل_الفرق[الفئة العمرية]=ملخص_المجموعات[[#This Row],[الفئة]])*(تفاصيل_الفرق[المجموعة]=ملخص_المجموعات[[#This Row],[المجموعة]])*(تفاصيل_الفرق[عدد الفرق]>0),تفاصيل_الفرق[المدينة/المحافظة],""))} | F16: =SUMIFS(تفاصيل_الفرق[عدد الفرق],تفاصيل_الفرق[الفئة العمرية],ملخص_المجموعات[[#This Row],[الفئة]],تفاصيل_الفرق[المجموعة],ملخص_المجموعات[[#This Row],[المجموعة]]) | G16: =MAX(0,الحد_الأدنى-ملخص_المجموعات[[#This Row],[مجموع الفرق]]) | I16: تحت 14 | J16: مجموعة طبرجل | K16: 5
B17: تحت 13 | C17: مجموعة نجران | D17: =COUNTIFS(تفاصيل_الفرق[الفئة العمرية],ملخص_المجموعات[[#This Row],[الفئة]],تفاصيل_الفرق[المجموعة],ملخص_المجموعات[[#This Row],[المجموعة]],تفاصيل_الفرق[عدد الفرق],">0") | E17: {=_xlfn.TEXTJOIN("، ",TRUE,IF((تفاصيل_الفرق[الفئة العمرية]=ملخص_المجموعات[[#This Row],[الفئة]])*(تفاصيل_الفرق[المجموعة]=ملخص_المجموعات[[#This Row],[المجموعة]])*(تفاصيل_الفرق[عدد الفرق]>0),تفاصيل_الفرق[المدينة/المحافظة],""))} | F17: =SUMIFS(تفاصيل_الفرق[عدد الفرق],تفاصيل_الفرق[الفئة العمرية],ملخص_المجموعات[[#This Row],[الفئة]],تفاصيل_الفرق[المجموعة],ملخص_المجموعات[[#This Row],[المجموعة]]) | G17: =MAX(0,الحد_الأدنى-ملخص_المجموعات[[#This Row],[مجموع الفرق]]) | I17: تحت 9 | J17: مجموعة الدوادمي | K17: 5
B18: تحت 13 | C18: مجموعة الباحة | D18: =COUNTIFS(تفاصيل_الفرق[الفئة العمرية],ملخص_المجموعات[[#This Row],[الفئة]],تفاصيل_الفرق[المجموعة],ملخص_المجموعات[[#This Row],[المجموعة]],تفاصيل_الفرق[عدد الفرق],">0") | E18: {=_xlfn.TEXTJOIN("، ",TRUE,IF((تفاصيل_الفرق[الفئة العمرية]=ملخص_المجموعات[[#This Row],[الفئة]])*(تفاصيل_الفرق[المجموعة]=ملخص_المجموعات[[#This Row],[المجموعة]])*(تفاصيل_الفرق[عدد الفرق]>0),تفاصيل_الفرق[المدينة/المحافظة],""))} | F18: =SUMIFS(تفاصيل_الفرق[عدد الفرق],تفاصيل_الفرق[الفئة العمرية],ملخص_المجموعات[[#This Row],[الفئة]],تفاصيل_الفرق[المجموعة],ملخص_المجموعات[[#This Row],[المجموعة]]) | G18: =MAX(0,الحد_الأدنى-ملخص_المجموعات[[#This Row],[مجموع الفرق]]) | I18: تحت 5 | J18: مجموعة القريات | K18: 5
B19: تحت 14 | C19: مجموعة الباحة | D19: =COUNTIFS(تفاصيل_الفرق[الفئة العمرية],ملخص_المجموعات[[#This Row],[الفئة]],تفاصيل_الفرق[المجموعة],ملخص_المجموعات[[#This Row],[المجموعة]],تفاصيل_الفرق[عدد الفرق],">0") | E19: {=_xlfn.TEXTJOIN("، ",TRUE,IF((تفاصيل_الفرق[الفئة العمرية]=ملخص_المجموعات[[#This Row],[الفئة]])*(تفاصيل_الفرق[المجموعة]=ملخص_المجموعات[[#This Row],[المجموعة]])*(تفاصيل_الفرق[عدد الفرق]>0),تفاصيل_الفرق[المدينة/المحافظة],""))} | F19: =SUMIFS(تفاصيل_الفرق[عدد الفرق],تفاصيل_الفرق[الفئة العمرية],ملخص_المجموعات[[#This Row],[الفئة]],تفاصيل_الفرق[المجموعة],ملخص_المجموعات[[#This Row],[المجموعة]]) | G19: =MAX(0,الحد_الأدنى-ملخص_المجموعات[[#This Row],[مجموع الفرق]]) | I19: تحت 5 | J19: مجموعة شرورة | K19: 5
B20: تحت 5 | C20: مجموعة حائل | D20: =COUNTIFS(تفاصيل_الفرق[الفئة العمرية],ملخص_المجموعات[[#This Row],[الفئة]],تفاصيل_الفرق[المجموعة],ملخص_المجموعات[[#This Row],[المجموعة]],تفاصيل_الفرق[عدد الفرق],">0") | E20: {=_xlfn.TEXTJOIN("، ",TRUE,IF((تفاصيل_الفرق[الفئة العمرية]=ملخص_المجموعات[[#This Row],[الفئة]])*(تفاصيل_الفرق[المجموعة]=ملخص_المجموعات[[#This Row],[المجموعة]])*(تفاصيل_الفرق[عدد الفرق]>0),تفاصيل_الفرق[المدينة/المحافظة],""))} | F20: =SUMIFS(تفاصيل_الفرق[عدد الفرق],تفاصيل_الفرق[الفئة العمرية],ملخص_المجموعات[[#This Row],[الفئة]],تفاصيل_الفرق[المجموعة],ملخص_المجموعات[[#This Row],[المجموعة]]) | G20: =MAX(0,الحد_الأدنى-ملخص_المجموعات[[#This Row],[مجموع الفرق]]) | I20: تحت 9 | J20: مجموعة القريات | K20: 5
B21: تحت 5 | C21: مجموعة القريات | D21: =COUNTIFS(تفاصيل_الفرق[الفئة العمرية],ملخص_المجموعات[[#This Row],[الفئة]],تفاصيل_الفرق[المجموعة],ملخص_المجموعات[[#This Row],[المجموعة]],تفاصيل_الفرق[عدد الفرق],">0") | E21: {=_xlfn.TEXTJOIN("، ",TRUE,IF((تفاصيل_الفرق[الفئة العمرية]=ملخص_المجموعات[[#This Row],[الفئة]])*(تفاصيل_الفرق[المجموعة]=ملخص_المجموعات[[#This Row],[المجموعة]])*(تفاصيل_الفرق[عدد الفرق]>0),تفاصيل_الفرق[المدينة/المحافظة],""))} | F21: =SUMIFS(تفاصيل_الفرق[عدد الفرق],تفاصيل_الفرق[الفئة العمرية],ملخص_المجموعات[[#This Row],[الفئة]],تفاصيل_الفرق[المجموعة],ملخص_المجموعات[[#This Row],[المجموعة]]) | G21: =MAX(0,الحد_الأدنى-ملخص_المجموعات[[#This Row],[مجموع الفرق]])
B22: تحت 5 | C22: مجموعة شرورة | D22: =COUNTIFS(تفاصيل_الفرق[الفئة العمرية],ملخص_المجموعات[[#This Row],[الفئة]],تفاصيل_الفرق[المجموعة],ملخص_المجموعات[[#This Row],[المجموعة]],تفاصيل_الفرق[عدد الفرق],">0") | E22: {=_xlfn.TEXTJOIN("، ",TRUE,IF((تفاصيل_الفرق[الفئة العمرية]=ملخص_المجموعات[[#This Row],[الفئة]])*(تفاصيل_الفرق[المجموعة]=ملخص_المجموعات[[#This Row],[المجموعة]])*(تفاصيل_الفرق[عدد الفرق]>0),تفاصيل_الفرق[المدينة/المحافظة],""))} | F22: =SUMIFS(تفاصيل_الفرق[عدد الفرق],تفاصيل_الفرق[الفئة العمرية],ملخص_المجموعات[[#This Row],[الفئة]],تفاصيل_الفرق[المجموعة],ملخص_المجموعات[[#This Row],[المجموعة]]) | G22: =MAX(0,الحد_الأدنى-ملخص_المجموعات[[#This Row],[مجموع الفرق]])
B23: تحت 7 | C23: مجموعة الباحة | D23: =COUNTIFS(تفاصيل_الفرق[الفئة العمرية],ملخص_المجموعات[[#This Row],[الفئة]],تفاصيل_الفرق[المجموعة],ملخص_المجموعات[[#This Row],[المجموعة]],تفاصيل_الفرق[عدد الفرق],">0") | E23: {=_xlfn.TEXTJOIN("، ",TRUE,IF((تفاصيل_الفرق[الفئة العمرية]=ملخص_المجموعات[[#This Row],[الفئة]])*(تفاصيل_الفرق[المجموعة]=ملخص_المجموعات[[#This Row],[المجموعة]])*(تفاصيل_الفرق[عدد الفرق]>0),تفاصيل_الفرق[المدينة/المحافظة],""))} | F23: =SUMIFS(تفاصيل_الفرق[عدد الفرق],تفاصيل_الفرق[الفئة العمرية],ملخص_المجموعات[[#This Row],[الفئة]],تفاصيل_الفرق[المجموعة],ملخص_المجموعات[[#This Row],[المجموعة]]) | G23: =MAX(0,الحد_الأدنى-ملخص_المجموعات[[#This Row],[مجموع الفرق]])
B24: تحت 7 | C24: مجموعة أبها | D24: =COUNTIFS(تفاصيل_الفرق[الفئة العمرية],ملخص_المجموعات[[#This Row],[الفئة]],تفاصيل_الفرق[المجموعة],ملخص_المجموعات[[#This Row],[المجموعة]],تفاصيل_الفرق[عدد الفرق],">0") | E24: {=_xlfn.TEXTJOIN("، ",TRUE,IF((تفاصيل_الفرق[الفئة العمرية]=ملخص_المجموعات[[#This Row],[الفئة]])*(تفاصيل_الفرق[المجموعة]=ملخص_المجموعات[[#This Row],[المجموعة]])*(تفاصيل_الفرق[عدد الفرق]>0),تفاصيل_الفرق[المدينة/المحافظة],""))} | F24: =SUMIFS(تفاصيل_الفرق[عدد الفرق],تفاصيل_الفرق[الفئة العمرية],ملخص_المجموعات[[#This Row],[الفئة]],تفاصيل_الفرق[المجموعة],ملخص_المجموعات[[#This Row],[المجموعة]]) | G24: =MAX(0,الحد_الأدنى-ملخص_المجموعات[[#This Row],[مجموع الفرق]])
B25: تحت 9 | C25: مجموعة القريات | D25: =COUNTIFS(تفاصيل_الفرق[الفئة العمرية],ملخص_المجموعات[[#This Row],[الفئة]],تفاصيل_الفرق[المجموعة],ملخص_المجموعات[[#This Row],[المجموعة]],تفاصيل_الفرق[عدد الفرق],">0") | E25: {=_xlfn.TEXTJOIN("، ",TRUE,IF((تفاصيل_الفرق[الفئة العمرية]=ملخص_المجموعات[[#This Row],[الفئة]])*(تفاصيل_الفرق[المجموعة]=ملخص_المجموعات[[#This Row],[المجموعة]])*(تفاصيل_الفرق[عدد الفرق]>0),تفاصيل_الفرق[المدينة/المحافظة],""))} | F25: =SUMIFS(تفاصيل_الفرق[عدد الفرق],تفاصيل_الفرق[الفئة العمرية],ملخص_المجموعات[[#This Row],[الفئة]],تفاصيل_الفرق[المجموعة],ملخص_المجموعات[[#This Row],[المجموعة]]) | G25: =MAX(0,الحد_الأدنى-ملخص_المجموعات[[#This Row],[مجموع الفرق]])
B26: تحت 9 | C26: مجموعة طبرجل | D26: =COUNTIFS(تفاصيل_الفرق[الفئة العمرية],ملخص_المجموعات[[#This Row],[الفئة]],تفاصيل_الفرق[المجموعة],ملخص_المجموعات[[#This Row],[المجموعة]],تفاصيل_الفرق[عدد الفرق],">0") | E26: {=_xlfn.TEXTJOIN("، ",TRUE,IF((تفاصيل_الفرق[الفئة العمرية]=ملخص_المجموعات[[#This Row],[الفئة]])*(تفاصيل_الفرق[المجموعة]=ملخص_المجموعات[[#This Row],[المجموعة]])*(تفاصيل_الفرق[عدد الفرق]>0),تفاصيل_الفرق[المدينة/المحافظة],""))} | F26: =SUMIFS(تفاصيل_الفرق[عدد الفرق],تفاصيل_الفرق[الفئة العمرية],ملخص_المجموعات[[#This Row],[الفئة]],تفاصيل_الفرق[المجموعة],ملخص_المجموعات[[#This Row],[المجموعة]]) | G26: =MAX(0,الحد_الأدنى-ملخص_المجموعات[[#This Row],[مجموع الفرق]])
B27: تحت 13 | C27: مجموعة الرس | D27: =COUNTIFS(تفاصيل_الفرق[الفئة العمرية],ملخص_المجموعات[[#This Row],[الفئة]],تفاصيل_الفرق[المجموعة],ملخص_المجموعات[[#This Row],[المجموعة]],تفاصيل_الفرق[عدد الفرق],">0") | E27: {=_xlfn.TEXTJOIN("، ",TRUE,IF((تفاصيل_الفرق[الفئة العمرية]=ملخص_المجموعات[[#This Row],[الفئة]])*(تفاصيل_الفرق[المجموعة]=ملخص_المجموعات[[#This Row],[المجموعة]])*(تفاصيل_الفرق[عدد الفرق]>0),تفاصيل_الفرق[المدينة/المحافظة],""))} | F27: =SUMIFS(تفاصيل_الفرق[عدد الفرق],تفاصيل_الفرق[الفئة العمرية],ملخص_المجموعات[[#This Row],[الفئة]],تفاصيل_الفرق[المجموعة],ملخص_المجموعات[[#This Row],[المجموعة]]) | G27: =MAX(0,الحد_الأدنى-ملخص_المجموعات[[#This Row],[مجموع الفرق]])
B28: تحت 13 | C28: مجموعة جازان | D28: =COUNTIFS(تفاصيل_الفرق[الفئة العمرية],ملخص_المجموعات[[#This Row],[الفئة]],تفاصيل_الفرق[المجموعة],ملخص_المجموعات[[#This Row],[المجموعة]],تفاصيل_الفرق[عدد الفرق],">0") | E28: {=_xlfn.TEXTJOIN("، ",TRUE,IF((تفاصيل_الفرق[الفئة العمرية]=ملخص_المجموعات[[#This Row],[الفئة]])*(تفاصيل_الفرق[المجموعة]=ملخص_المجموعات[[#This Row],[المجموعة]])*(تفاصيل_الفرق[عدد الفرق]>0),تفاصيل_الفرق[المدينة/المحافظة],""))} | F28: =SUMIFS(تفاصيل_الفرق[عدد الفرق],تفاصيل_الفرق[الفئة العمرية],ملخص_المجموعات[[#This Row],[الفئة]],تفاصيل_الفرق[المجموعة],ملخص_المجموعات[[#This Row],[المجموعة]]) | G28: =MAX(0,الحد_الأدنى-ملخص_المجموعات[[#This Row],[مجموع الفرق]])
B29: تحت 14 | C29: مجموعة حائل | D29: =COUNTIFS(تفاصيل_الفرق[الفئة العمرية],ملخص_المجموعات[[#This Row],[الفئة]],تفاصيل_الفرق[المجموعة],ملخص_المجموعات[[#This Row],[المجموعة]],تفاصيل_الفرق[عدد الفرق],">0") | E29: {=_xlfn.TEXTJOIN("، ",TRUE,IF((تفاصيل_الفرق[الفئة العمرية]=ملخص_المجموعات[[#This Row],[الفئة]])*(تفاصيل_الفرق[المجموعة]=ملخص_المجموعات[[#This Row],[المجموعة]])*(تفاصيل_الفرق[عدد الفرق]>0),تفاصيل_الفرق[المدينة/المحافظة],""))} | F29: =SUMIFS(تفاصيل_الفرق[عدد الفرق],تفاصيل_الفرق[الفئة العمرية],ملخص_المجموعات[[#This Row],[الفئة]],تفاصيل_الفرق[المجموعة],ملخص_المجموعات[[#This Row],[المجموعة]]) | G29: =MAX(0,الحد_الأدنى-ملخص_المجموعات[[#This Row],[مجموع الفرق]])
B30: تحت 14 | C30: مجموعة الخرج | D30: =COUNTIFS(تفاصيل_الفرق[الفئة العمرية],ملخص_المجموعات[[#This Row],[الفئة]],تفاصيل_الفرق[المجموعة],ملخص_المجموعات[[#This Row],[المجموعة]],تفاصيل_الفرق[عدد الفرق],">0") | E30: {=_xlfn.TEXTJOIN("، ",TRUE,IF((تفاصيل_الفرق[الفئة العمرية]=ملخص_المجموعات[[#This Row],[الفئة]])*(تفاصيل_الفرق[المجموعة]=ملخص_المجموعات[[#This Row],[المجموعة]])*(تفاصيل_الفرق[عدد الفرق]>0),تفاصيل_الفرق[المدينة/المحافظة],""))} | F30: =SUMIFS(تفاصيل_الفرق[عدد الفرق],تفاصيل_الفرق[الفئة العمرية],ملخص_المجموعات[[#This Row],[الفئة]],تفاصيل_الفرق[المجموعة],ملخص_المجموعات[[#This Row],[المجموعة]]) | G30: =MAX(0,الحد_الأدنى-ملخص_المجموعات[[#This Row],[مجموع الفرق]])
B31: تحت 5 | C31: مجموعة مركز الرفيعة | D31: =COUNTIFS(تفاصيل_الفرق[الفئة العمرية],ملخص_المجموعات[[#This Row],[الفئة]],تفاصيل_الفرق[المجموعة],ملخص_المجموعات[[#This Row],[المجموعة]],تفاصيل_الفرق[عدد الفرق],">0") | E31: {=_xlfn.TEXTJOIN("، ",TRUE,IF((تفاصيل_الفرق[الفئة العمرية]=ملخص_المجموعات[[#This Row],[الفئة]])*(تفاصيل_الفرق[المجموعة]=ملخص_المجموعات[[#This Row],[المجموعة]])*(تفاصيل_الفرق[عدد الفرق]>0),تفاصيل_الفرق[المدينة/المحافظة],""))} | F31: =SUMIFS(تفاصيل_الفرق[عدد الفرق],تفاصيل_الفرق[الفئة العمرية],ملخص_المجموعات[[#This Row],[الفئة]],تفاصيل_الفرق[المجموعة],ملخص_المجموعات[[#This Row],[المجموعة]]) | G31: =MAX(0,الحد_الأدنى-ملخص_المجموعات[[#This Row],[مجموع الفرق]])
B32: تحت 5 | C32: مجموعة القطيف | D32: =COUNTIFS(تفاصيل_الفرق[الفئة العمرية],ملخص_المجموعات[[#This Row],[الفئة]],تفاصيل_الفرق[المجموعة],ملخص_المجموعات[[#This Row],[المجموعة]],تفاصيل_الفرق[عدد الفرق],">0") | E32: {=_xlfn.TEXTJOIN("، ",TRUE,IF((تفاصيل_الفرق[الفئة العمرية]=ملخص_المجموعات[[#This Row],[الفئة]])*(تفاصيل_الفرق[المجموعة]=ملخص_المجموعات[[#This Row],[المجموعة]])*(تفاصيل_الفرق[عدد الفرق]>0),تفاصيل_الفرق[المدينة/المحافظة],""))} | F32: =SUMIFS(تفاصيل_الفرق[عدد الفرق],تفاصيل_الفرق[الفئة العمرية],ملخص_المجموعات[[#This Row],[الفئة]],تفاصيل_الفرق[المجموعة],ملخص_المجموعات[[#This Row],[المجموعة]]) | G32: =MAX(0,الحد_الأدنى-ملخص_المجموعات[[#This Row],[مجموع الفرق]])
... B186: تحت 12 | C186: مجموعة جدة | D186: =COUNTIFS(تفاصيل_الفرق[الفئة العمرية],ملخص_المجموعات[[#This Row],[الفئة]],تفاصيل_الفرق[المجموعة],ملخص_المجموعات[[#This Row],[المجموعة]],تفاصيل_الفرق[عدد الفرق],">0") | E186: {=_xlfn.TEXTJOIN("، ",TRUE,IF((تفاصيل_الفرق[الفئة العمرية]=ملخص_المجموعات[[#This Row],[الفئة]])*(تفاصيل_الفرق[المجموعة]=ملخص_المجموعات[[#This Row],[المجموعة]])*(تفاصيل_الفرق[عدد الفرق]>0),تفاصيل_الفرق[المدينة/المحافظة],""))} | F186: =SUMIFS(تفاصيل_الفرق[عدد الفرق],تفاصيل_الفرق[الفئة العمرية],ملخص_المجموعات[[#This Row],[الفئة]],تفاصيل_الفرق[المجموعة],ملخص_المجموعات[[#This Row],[المجموعة]]) | G186: =MAX(0,الحد_الأدنى-ملخص_المجموعات[[#This Row],[مجموع الفرق]])

Sheet بيانات التسجيل
A2: Entry Id | B2: اسم الفريق | C2: الاسم | D2: رقم الجوال | E2: اسم الملعب | F2: الصفة | G2: المنطقة | H2: المدينة | I2: مكتب الوزارة | J2: المشاركة تحت 14 | K2: المشاركة تحت 13 | L2: المشاركة تحت 12 | M2: المشاركة تحت 11 | N2: المشاركة تحت 9 | O2: المشاركة تحت 7 | P2: المشاركة تحت 5 | Q2: ليس في أي مجموعة مكتملة | R2: حالة السداد | S2: فتح حساب لتسجيل اللاعبين
A3: 1 | B3: الزوري | C3: سالم محمد الدوسري | D3: 562311110 | E3: ملاعب المنافسة | F3: أكاديمية | G3: الشرقية | H3: الدمام | I3: الشرقية | J3: 0 | K3: 0 | L3: 1 | M3: 1 | N3: 1 | O3: 0 | P3: 0 | Q3: =IF(SUM([1]!التسجيل[[#This Row],[المشاركة تحت 14]],[1]!التسجيل[[#This Row],[المشاركة تحت 13]],[1]!التسجيل[[#This Row],[المشاركة تحت 12]],[1]!التسجيل[[#This Row],[المشاركة تحت 11]],[1]!التسجيل[[#This Row],[المشاركة تحت 9]],[1]!التسجيل[[#This Row],[المشاركة تحت 7 ]],[1]!التسجيل[[#This Row],[المشاركة تحت 5]])=0,"لا يوجد تسجيل",IF((([1]!التسجيل[[#This Row],[المشاركة تحت 14]]>=1)*(COUNTIFS([1]!تفاصيل_الفرق[الفئة العمرية],"تحت 14",[1]!تفاصيل_الفرق[مدينة منظفة],TRIM([1]!التسجيل[[#This Row],[المدينة]]),[1]!تفاصيل_الفرق[مجموعة مكتملة],1)>0))+(([1]!التسجيل[[#This Row],[المشاركة تحت 13]]>=1)*(COUNTIFS([1]!تفاصيل_الفرق[الفئة العمرية],"تحت 13",[1]!تفاصيل_الفرق[مدينة منظفة],TRIM([1]!التسجيل[[#This Row],[المدينة]]),[1]!تفاصيل_الفرق[مجموعة مكتملة],1)>0))+(([1]!التسجيل[[#This Row],[المشاركة تحت 12]]>=1)*(COUNTIFS([1]!تفاصيل_الفرق[الفئة العمرية],"تحت 12",[1]!تفاصيل_الفرق[مدينة منظفة],TRIM([1]!التسجيل[[#This Row],[المدينة]]),[1]!تفاصيل_الفرق[مجموعة مكتملة],1)>0))+(([1]!التسجيل[[#This Row],[المشاركة تحت 11]]>=1)*(COUNTIFS([1]!تفاصيل_الفرق[الفئة العمرية],"تحت 11",[1]!تفاصيل_الفرق[مدينة منظفة],TRIM([1]!التسجيل[[#This Row],[المدينة]]),[1]!تفاصيل_الفرق[مجموعة مكتملة],1)>0))+(([1]!التسجيل[[#This Row],[المشاركة تحت 9]]>=1)*(COUNTIFS([1]!تفاصيل_الفرق[الفئة العمرية],"تحت 9",[1]!تفاصيل_الفرق[مدينة منظفة],TRIM([1]!التسجيل[[#This Row],[المدينة]]),[1]!تفاصيل_الفرق[مجموعة مكتملة],1)>0))+(([1]!التسجيل[[#This Row],[المشاركة تحت 7 ]]>=1)*(COUNTIFS([1]!تفاصيل_الفرق[الفئة العمرية],"تحت 7",[1]!تفاصيل_الفرق[مدينة منظفة],TRIM([1]!التسجيل[[#This Row],[المدينة]]),[1]!تفاصيل_الفرق[مجموعة مكتملة],1)>0))+(([1]!التسجيل[[#This Row],[المشاركة تحت 5]]>=1)*(COUNTIFS([1]!تفاصيل_الفرق[الفئة العمرية],"تحت 5",[1]!تفاصيل_الفرق[مدينة منظفة],TRIM([1]!التسجيل[[#This Row],[المدينة]]),[1]!تفاصيل_الفرق[مجموعة مكتملة],1)>0))=0,"نعم","لا"))
A4: =1+A3 | B4: المطوع | C4: محمد عساف العتيبي | D4: 539099199 | E4: المطوع بارك | F4: نادي | G4: الرياض | H4: الرياض | I4: الرياض | J4: 1 | K4: 1 | L4: 1 | M4: 1 | N4: 0 | O4: 0 | P4: 0 | Q4: =IF(SUM([1]!التسجيل[[#This Row],[المشاركة تحت 14]],[1]!التسجيل[[#This Row],[المشاركة تحت 13]],[1]!التسجيل[[#This Row],[المشاركة تحت 12]],[1]!التسجيل[[#This Row],[المشاركة تحت 11]],[1]!التسجيل[[#This Row],[المشاركة تحت 9]],[1]!التسجيل[[#This Row],[المشاركة تحت 7 ]],[1]!التسجيل[[#This Row],[المشاركة تحت 5]])=0,"لا يوجد تسجيل",IF((([1]!التسجيل[[#This Row],[المشاركة تحت 14]]>=1)*(COUNTIFS([1]!تفاصيل_الفرق[الفئة العمرية],"تحت 14",[1]!تفاصيل_الفرق[مدينة منظفة],TRIM([1]!التسجيل[[#This Row],[المدينة]]),[1]!تفاصيل_الفرق[مجموعة مكتملة],1)>0))+(([1]!التسجيل[[#This Row],[المشاركة تحت 13]]>=1)*(COUNTIFS([1]!تفاصيل_الفرق[الفئة العمرية],"تحت 13",[1]!تفاصيل_الفرق[مدينة منظفة],TRIM([1]!التسجيل[[#This Row],[المدينة]]),[1]!تفاصيل_الفرق[مجموعة مكتملة],1)>0))+(([1]!التسجيل[[#This Row],[المشاركة تحت 12]]>=1)*(COUNTIFS([1]!تفاصيل_الفرق[الفئة العمرية],"تحت 12",[1]!تفاصيل_الفرق[مدينة منظفة],TRIM([1]!التسجيل[[#This Row],[المدينة]]),[1]!تفاصيل_الفرق[مجموعة مكتملة],1)>0))+(([1]!التسجيل[[#This Row],[المشاركة تحت 11]]>=1)*(COUNTIFS([1]!تفاصيل_الفرق[الفئة العمرية],"تحت 11",[1]!تفاصيل_الفرق[مدينة منظفة],TRIM([1]!التسجيل[[#This Row],[المدينة]]),[1]!تفاصيل_الفرق[مجموعة مكتملة],1)>0))+(([1]!التسجيل[[#This Row],[المشاركة تحت 9]]>=1)*(COUNTIFS([1]!تفاصيل_الفرق[الفئة العمرية],"تحت 9",[1]!تفاصيل_الفرق[مدينة منظفة],TRIM([1]!التسجيل[[#This Row],[المدينة]]),[1]!تفاصيل_الفرق[مجموعة مكتملة],1)>0))+(([1]!التسجيل[[#This Row],[المشاركة تحت 7 ]]>=1)*(COUNTIFS([1]!تفاصيل_الفرق[الفئة العمرية],"تحت 7",[1]!تفاصيل_الفرق[مدينة منظفة],TRIM([1]!التسجيل[[#This Row],[المدينة]]),[1]!تفاصيل_الفرق[مجموعة مكتملة],1)>0))+(([1]!التسجيل[[#This Row],[المشاركة تحت 5]]>=1)*(COUNTIFS([1]!تفاصيل_الفرق[الفئة العمرية],"تحت 5",[1]!تفاصيل_الفرق[مدينة منظفة],TRIM([1]!التسجيل[[#This Row],[المدينة]]),[1]!تفاصيل_الفرق[مجموعة مكتملة],1)>0))=0,"نعم","لا"))
