Workbook
Name الحد_الأدنى: المدخلات!$N$3
Name فرق_المباراة: المدخلات!$AD$3
Name قائمة_المدن: المدخلات!$AA$3:$AA$98
Name ملاعب_الفئات: المدخلات!$AC$6:$AI$12

Sheet Sheet1
B2: الفئة | C2: عدد الفرق | D2: عدد الملاعب القانونية | F2: الفئة | G2: مجموعة الجداول
B3: تحت 5 | C3: 6 | D3: 1 | F3: تحت 5 | G3: تحت 5
B4: تحت 5 | C4: 7 | D4: 1 | F4: تحت 7 | G4: تحت 7 و تحت 9
B5: تحت 5 | C5: 8 | D5: 1 | F5: تحت 9 | G5: تحت 7 و تحت 9
B6: تحت 5 | C6: 9 | D6: 1 | F6: تحت 11 | G6: تحت 11 و تحت 12
B7: تحت 5 | C7: 12 | D7: 2 | F7: تحت 12 | G7: تحت 11 و تحت 12
B8: تحت 5 | C8: 13 | D8: 2 | F8: تحت 13 | G8: تحت 13
B9: تحت 5 | C9: 17 | D9: 2 | F9: تحت 14 | G9: تحت 14
B10: تحت 5 | C10: 18 | D10: 3
B11: تحت 5 | C11: 19 | D11: 3
B12: تحت 5 | C12: 22 | D12: 3
B13: تحت 5 | C13: 30 | D13: 4
B14: تحت 7 و تحت 9 | C14: 6 | D14: 1
B15: تحت 7 و تحت 9 | C15: 7 | D15: 1
B16: تحت 7 و تحت 9 | C16: 8 | D16: 1
B17: تحت 7 و تحت 9 | C17: 9 | D17: 1
B18: تحت 7 و تحت 9 | C18: 10 | D18: 1
B19: تحت 7 و تحت 9 | C19: 11 | D19: 1
B20: تحت 7 و تحت 9 | C20: 12 | D20: 2
B21: تحت 7 و تحت 9 | C21: 13 | D21: 1
... B97: تحت 14 | C97: 48 | D97: 8

Sheet عدد الملاعب_بناء على الجداول
B2: ملخص الملاعب لكل يوم (المجموعات المكتملة فقط)
B3: الفئة | C3: اليوم | D3: نوع الملعب | E3: المجموعات | F3: عدد الفرق | G3: ملاعب قانونية
B4: =المدخلات!$AC$6 -> تحت 5 | C4: =المدخلات!$AD$6 -> السبت | D4: =المدخلات!$AE$6 -> 5 ضد 5 | E4: =COUNTIFS($C$14:$C$204,المدخلات!$AC$6,$G$14:$G$204,">="&الحد_الأدنى) -> 20 | F4: =SUMIFS($G$14:$G$204,$C$14:$C$204,المدخلات!$AC$6,$G$14:$G$204,">="&الحد_الأدنى) -> 240 | G4: =SUMIFS($K$14:$K$204,$C$14:$C$204,المدخلات!$AC$6) -> 16
B5: =المدخلات!$AC$7 -> تحت 7 | C5: =المدخلات!$AD$7 -> السبت | D5: =المدخلات!$AE$7 -> 7 ضد 7 | E5: =COUNTIFS($C$14:$C$204,المدخلات!$AC$7,$G$14:$G$204,">="&الحد_الأدنى) -> 23 | F5: =SUMIFS($G$14:$G$204,$C$14:$C$204,المدخلات!$AC$7,$G$14:$G$204,">="&الحد_الأدنى) -> 347 | G5: =SUMIFS($K$14:$K$204,$C$14:$C$204,المدخلات!$AC$7) -> 21
B6: =المدخلات!$AC$8 -> تحت 9 | C6: =المدخلات!$AD$8 -> السبت | D6: =المدخلات!$AE$8 -> 7 ضد 7 | E6: =COUNTIFS($C$14:$C$204,المدخلات!$AC$8,$G$14:$G$204,">="&الحد_الأدنى) -> 25 | F6: =SUMIFS($G$14:$G$204,$C$14:$C$204,المدخلات!$AC$8,$G$14:$G$204,">="&الحد_الأدنى) -> 398 | G6: =SUMIFS($K$14:$K$204,$C$14:$C$204,المدخلات!$AC$8) -> 31
B7: =المدخلات!$AC$9 -> تحت 11 | C7: =المدخلات!$AD$9 -> الأحد | D7: =المدخلات!$AE$9 -> 7 ضد 7 | E7: =COUNTIFS($C$14:$C$204,المدخلات!$AC$9,$G$14:$G$204,">="&الحد_الأدنى) -> 24 | F7: =SUMIFS($G$14:$G$204,$C$14:$C$204,المدخلات!$AC$9,$G$14:$G$204,">="&الحد_الأدنى) -> 369 | G7: =SUMIFS($K$14:$K$204,$C$14:$C$204,المدخلات!$AC$9) -> 21
B8: =المدخلات!$AC$10 -> تحت 12 | C8: =المدخلات!$AD$10 -> الاثنين | D8: =المدخلات!$AE$10 -> 7 ضد 7 | E8: =COUNTIFS($C$14:$C$204,المدخلات!$AC$10,$G$14:$G$204,">="&الحد_الأدنى) -> 27 | F8: =SUMIFS($G$14:$G$204,$C$14:$C$204,المدخلات!$AC$10,$G$14:$G$204,">="&الحد_الأدنى) -> 392 | G8: =SUMIFS($K$14:$K$204,$C$14:$C$204,المدخلات!$AC$10) -> 33
B9: =المدخلات!$AC$11 -> تحت 13 | C9: =المدخلات!$AD$11 -> الخميس | D9: =المدخلات!$AE$11 -> قانوني | E9: =COUNTIFS($C$14:$C$204,المدخلات!$AC$11,$G$14:$G$204,">="&الحد_الأدنى) -> 27 | F9: =SUMIFS($G$14:$G$204,$C$14:$C$204,المدخلات!$AC$11,$G$14:$G$204,">="&الحد_الأدنى) -> 403 | G9: =SUMIFS($K$14:$K$204,$C$14:$C$204,المدخلات!$AC$11) -> 35
B10: =المدخلات!$AC$12 -> تحت 14 | C10: =المدخلات!$AD$12 -> الأربعاء | D10: =المدخلات!$AE$12 -> قانوني | E10: =COUNTIFS($C$14:$C$204,المدخلات!$AC$12,$G$14:$G$204,">="&الحد_الأدنى) -> 25 | F10: =SUMIFS($G$14:$G$204,$C$14:$C$204,المدخلات!$AC$12,$G$14:$G$204,">="&الحد_الأدنى) -> 376 | G10: =SUMIFS($K$14:$K$204,$C$14:$C$204,المدخلات!$AC$12) -> 36
B11: الإجمالي | E11: =SUM(E4:E10) -> 171 | F11: =SUM(F4:F10) -> 2525 | G11: =SUM(G4:G10) -> 193
B13: المنطقة | C13: الفئة | D13: اليوم | E13: المجموعة | F13: المدن | G13: عدد الفرق | H13: نوع الملعب | I13: عدد المباريات في اليوم | J13: ملاعب اللعب المطلوبة | K13: ملاعب قانونية معادلة
B14: ='عدد اللاعبين'!B3 | C14: ='عدد اللاعبين'!C3 -> #REF! | D14: =IFERROR(INDEX(المدخلات!$AD$6:$AD$12,MATCH($C14,المدخلات!$AC$6:$AC$12,0)),"") | E14: ='عدد اللاعبين'!D3 -> #REF! | F14: ='عدد اللاعبين'!F3 -> نجران | G14: ='عدد اللاعبين'!G3 -> 5 | H14: =IFERROR(INDEX(المدخلات!$AE$6:$AE$12,MATCH($C14,المدخلات!$AC$6:$AC$12,0)),"") | I14: =IF($G14<الحد_الأدنى,0,ROUNDDOWN($G14/فرق_المباراة,0)) -> 0 | J14: =ROUNDUP($I14/IFERROR(INDEX(المدخلات!$AJ$6:$AJ$12,MATCH($C14,المدخلات!$AC$6:$AC$12,0)),1),0) -> 0 | K14: =IF($G14<الحد_الأدنى,0,IFERROR(SUMIFS(Sheet1!$D$3:$D$97,Sheet1!$B$3:$B$97,INDEX(Sheet1!$G$3:$G$9,MATCH($C14,Sheet1!$F$3:$F$9,0)),Sheet1!$C$3:$C$97,$G14),0)) -> 0
B15: ='عدد اللاعبين'!B4 | C15: ='عدد اللاعبين'!C4 -> #REF! | D15: =IFERROR(INDEX(المدخلات!$AD$6:$AD$12,MATCH($C15,المدخلات!$AC$6:$AC$12,0)),"") | E15: ='عدد اللاعبين'!D4 -> #REF! | F15: ='عدد اللاعبين'!F4 -> طبرجل | G15: ='عدد اللاعبين'!G4 -> 5 | H15: =IFERROR(INDEX(المدخلات!$AE$6:$AE$12,MATCH($C15,المدخلات!$AC$6:$AC$12,0)),"") | I15: =IF($G15<الحد_الأدنى,0,ROUNDDOWN($G15/فرق_المباراة,0)) -> 0 | J15: =ROUNDUP($I15/IFERROR(INDEX(المدخلات!$AJ$6:$AJ$12,MATCH($C15,المدخلات!$AC$6:$AC$12,0)),1),0) -> 0 | K15: =IF($G15<الحد_الأدنى,0,IFERROR(SUMIFS(Sheet1!$D$3:$D$97,Sheet1!$B$3:$B$97,INDEX(Sheet1!$G$3:$G$9,MATCH($C15,Sheet1!$F$3:$F$9,0)),Sheet1!$C$3:$C$97,$G15),0)) -> 0
B16: ='عدد اللاعبين'!B5 | C16: ='عدد اللاعبين'!C5 -> #REF! | D16: =IFERROR(INDEX(المدخلات!$AD$6:$AD$12,MATCH($C16,المدخلات!$AC$6:$AC$12,0)),"") | E16: ='عدد اللاعبين'!D5 -> #REF! | F16: ='عدد اللاعبين'!F5 -> طبرجل | G16: ='عدد اللاعبين'!G5 -> 5 | H16: =IFERROR(INDEX(المدخلات!$AE$6:$AE$12,MATCH($C16,المدخلات!$AC$6:$AC$12,0)),"") | I16: =IF($G16<الحد_الأدنى,0,ROUNDDOWN($G16/فرق_المباراة,0)) -> 0 | J16: =ROUNDUP($I16/IFERROR(INDEX(المدخلات!$AJ$6:$AJ$12,MATCH($C16,المدخلات!$AC$6:$AC$12,0)),1),0) -> 0 | K16: =IF($G16<الحد_الأدنى,0,IFERROR(SUMIFS(Sheet1!$D$3:$D$97,Sheet1!$B$3:$B$97,INDEX(Sheet1!$G$3:$G$9,MATCH($C16,Sheet1!$F$3:$F$9,0)),Sheet1!$C$3:$C$97,$G16),0)) -> 0
B17: ='عدد اللاعبين'!B6 | C17: ='عدد اللاعبين'!C6 -> #REF! | D17: =IFERROR(INDEX(المدخلات!$AD$6:$AD$12,MATCH($C17,المدخلات!$AC$6:$AC$12,0)),"") | E17: ='عدد اللاعبين'!D6 -> #REF! | F17: ='عدد اللاعبين'!F6 -> الخرج | G17: ='عدد اللاعبين'!G6 -> 5 | H17: =IFERROR(INDEX(المدخلات!$AE$6:$AE$12,MATCH($C17,المدخلات!$AC$6:$AC$12,0)),"") | I17: =IF($G17<الحد_الأدنى,0,ROUNDDOWN($G17/فرق_المباراة,0)) -> 0 | J17: =ROUNDUP($I17/IFERROR(INDEX(المدخلات!$AJ$6:$AJ$12,MATCH($C17,المدخلات!$AC$6:$AC$12,0)),1),0) -> 0 | K17: =IF($G17<الحد_الأدنى,0,IFERROR(SUMIFS(Sheet1!$D$3:$D$97,Sheet1!$B$3:$B$97,INDEX(Sheet1!$G$3:$G$9,MATCH($C17,Sheet1!$F$3:$F$9,0)),Sheet1!$C$3:$C$97,$G17),0)) -> 0
B18: ='عدد اللاعبين'!B7 | C18: ='عدد اللاعبين'!C7 -> #REF! | D18: =IFERROR(INDEX(المدخلات!$AD$6:$AD$12,MATCH($C18,المدخلات!$AC$6:$AC$12,0)),"") | E18: ='عدد اللاعبين'!D7 -> #REF! | F18: ='عدد اللاعبين'!F7 -> طبرجل | G18: ='عدد اللاعبين'!G7 -> 5 | H18: =IFERROR(INDEX(المدخلات!$AE$6:$AE$12,MATCH($C18,المدخلات!$AC$6:$AC$12,0)),"") | I18: =IF($G18<الحد_الأدنى,0,ROUNDDOWN($G18/فرق_المباراة,0)) -> 0 | J18: =ROUNDUP($I18/IFERROR(INDEX(المدخلات!$AJ$6:$AJ$12,MATCH($C18,المدخلات!$AC$6:$AC$12,0)),1),0) -> 0 | K18: =IF($G18<الحد_الأدنى,0,IFERROR(SUMIFS(Sheet1!$D$3:$D$97,Sheet1!$B$3:$B$97,INDEX(Sheet1!$G$3:$G$9,MATCH($C18,Sheet1!$F$3:$F$9,0)),Sheet1!$C$3:$C$97,$G18),0)) -> 0
B19: ='عدد اللاعبين'!B8 | C19: ='عدد اللاعبين'!C8 -> #REF! | D19: =IFERROR(INDEX(المدخلات!$AD$6:$AD$12,MATCH($C19,المدخلات!$AC$6:$AC$12,0)),"") | E19: ='عدد اللاعبين'!D8 -> #REF! | F19: ='عدد اللاعبين'!F8 -> طبرجل | G19: ='عدد اللاعبين'!G8 -> 5 | H19: =IFERROR(INDEX(المدخلات!$AE$6:$AE$12,MATCH($C19,المدخلات!$AC$6:$AC$12,0)),"") | I19: =IF($G19<الحد_الأدنى,0,ROUNDDOWN($G19/فرق_المباراة,0)) -> 0 | J19: =ROUNDUP($I19/IFERROR(INDEX(المدخلات!$AJ$6:$AJ$12,MATCH($C19,المدخلات!$AC$6:$AC$12,0)),1),0) -> 0 | K19: =IF($G19<الحد_الأدنى,0,IFERROR(SUMIFS(Sheet1!$D$3:$D$97,Sheet1!$B$3:$B$97,INDEX(Sheet1!$G$3:$G$9,MATCH($C19,Sheet1!$F$3:$F$9,0)),Sheet1!$C$3:$C$97,$G19),0)) -> 0
B20: ='عدد اللاعبين'!B9 | C20: ='عدد اللاعبين'!C9 -> #REF! | D20: =IFERROR(INDEX(المدخلات!$AD$6:$AD$12,MATCH($C20,المدخلات!$AC$6:$AC$12,0)),"") | E20: ='عدد اللاعبين'!D9 -> #REF! | F20: ='عدد اللاعبين'!F9 -> شرورة | G20: ='عدد اللاعبين'!G9 -> 5 | H20: =IFERROR(INDEX(المدخلات!$AE$6:$AE$12,MATCH($C20,المدخلات!$AC$6:$AC$12,0)),"") | I20: =IF($G20<الحد_الأدنى,0,ROUNDDOWN($G20/فرق_المباراة,0)) -> 0 | J20: =ROUNDUP($I20/IFERROR(INDEX(المدخلات!$AJ$6:$AJ$12,MATCH($C20,المدخلات!$AC$6:$AC$12,0)),1),0) -> 0 | K20: =IF($G20<الحد_الأدنى,0,IFERROR(SUMIFS(Sheet1!$D$3:$D$97,Sheet1!$B$3:$B$97,INDEX(Sheet1!$G$3:$G$9,MATCH($C20,Sheet1!$F$3:$F$9,0)),Sheet1!$C$3:$C$97,$G20),0)) -> 0
B21: ='عدد اللاعبين'!B10 -> نجران | C21: ='عدد اللاعبين'!C10 -> تحت 14 | D21: =IFERROR(INDEX(المدخلات!$AD$6:$AD$12,MATCH($C21,المدخلات!$AC$6:$AC$12,0)),"") -> الأربعاء | E21: ='عدد اللاعبين'!D10 -> مجموعة نجران | F21: ='عدد اللاعبين'!F10 -> شرورة | G21: ='عدد اللاعبين'!G10 -> 5 | H21: =IFERROR(INDEX(المدخلات!$AE$6:$AE$12,MATCH($C21,المدخلات!$AC$6:$AC$12,0)),"") -> قانوني | I21: =IF($G21<الحد_الأدنى,0,ROUNDDOWN($G21/فرق_المباراة,0)) -> 0 | J21: =ROUNDUP($I21/IFERROR(INDEX(المدخلات!$AJ$6:$AJ$12,MATCH($C21,المدخلات!$AC$6:$AC$12,0)),1),0) -> 0 | K21: =IF($G21<الحد_الأدنى,0,IFERROR(SUMIFS(Sheet1!$D$3:$D$97,Sheet1!$B$3:$B$97,INDEX(Sheet1!$G$3:$G$9,MATCH($C21,Sheet1!$F$3:$F$9,0)),Sheet1!$C$3:$C$97,$G21),0)) -> 0
B22: ='عدد اللاعبين'!B11 -> الجوف | C22: ='عدد اللاعبين'!C11 -> تحت 5 | D22: =IFERROR(INDEX(المدخلات!$AD$6:$AD$12,MATCH($C22,المدخلات!$AC$6:$AC$12,0)),"") -> السبت | E22: ='عدد اللاعبين'!D11 -> مجموعة طبرجل | F22: ='عدد اللاعبين'!F11 -> الدوادمي | G22: ='عدد اللاعبين'!G11 -> 5 | H22: =IFERROR(INDEX(المدخلات!$AE$6:$AE$12,MATCH($C22,المدخلات!$AC$6:$AC$12,0)),"") -> 5 ضد 5 | I22: =IF($G22<الحد_الأدنى,0,ROUNDDOWN($G22/فرق_المباراة,0)) -> 0 | J22: =ROUNDUP($I22/IFERROR(INDEX(المدخلات!$AJ$6:$AJ$12,MATCH($C22,المدخلات!$AC$6:$AC$12,0)),1),0) -> 0 | K22: =IF($G22<الحد_الأدنى,0,IFERROR(SUMIFS(Sheet1!$D$3:$D$97,Sheet1!$B$3:$B$97,INDEX(Sheet1!$G$3:$G$9,MATCH($C22,Sheet1!$F$3:$F$9,0)),Sheet1!$C$3:$C$97,$G22),0)) -> 0
B23: ='عدد اللاعبين'!B12 -> الجوف | C23: ='عدد اللاعبين'!C12 -> تحت 7 | D23: =IFERROR(INDEX(المدخلات!$AD$6:$AD$12,MATCH($C23,المدخلات!$AC$6:$AC$12,0)),"") -> السبت | E23: ='عدد اللاعبين'!D12 -> مجموعة طبرجل | F23: ='عدد اللاعبين'!F12 -> القريات | G23: ='عدد اللاعبين'!G12 -> 5 | H23: =IFERROR(INDEX(المدخلات!$AE$6:$AE$12,MATCH($C23,المدخلات!$AC$6:$AC$12,0)),"") -> 7 ضد 7 | I23: =IF($G23<الحد_الأدنى,0,ROUNDDOWN($G23/فرق_المباراة,0)) -> 0 | J23: =ROUNDUP($I23/IFERROR(INDEX(المدخلات!$AJ$6:$AJ$12,MATCH($C23,المدخلات!$AC$6:$AC$12,0)),1),0) -> 0 | K23: =IF($G23<الحد_الأدنى,0,IFERROR(SUMIFS(Sheet1!$D$3:$D$97,Sheet1!$B$3:$B$97,INDEX(Sheet1!$G$3:$G$9,MATCH($C23,Sheet1!$F$3:$F$9,0)),Sheet1!$C$3:$C$97,$G23),0)) -> 0
B24: ='عدد اللاعبين'!B13 -> الرياض | C24: ='عدد اللاعبين'!C13 -> تحت 9 | D24: =IFERROR(INDEX(المدخلات!$AD$6:$AD$12,MATCH($C24,المدخلات!$AC$6:$AC$12,0)),"") -> السبت | E24: ='عدد اللاعبين'!D13 -> مجموعة الخرج | F24: ='عدد اللاعبين'!F13 -> القريات | G24: ='عدد اللاعبين'!G13 -> 5 | H24: =IFERROR(INDEX(المدخلات!$AE$6:$AE$12,MATCH($C24,المدخلات!$AC$6:$AC$12,0)),"") -> 7 ضد 7 | I24: =IF($G24<الحد_الأدنى,0,ROUNDDOWN($G24/فرق_المباراة,0)) -> 0 | J24: =ROUNDUP($I24/IFERROR(INDEX(المدخلات!$AJ$6:$AJ$12,MATCH($C24,المدخلات!$AC$6:$AC$12,0)),1),0) -> 0 | K24: =IF($G24<الحد_الأدنى,0,IFERROR(SUMIFS(Sheet1!$D$3:$D$97,Sheet1!$B$3:$B$97,INDEX(Sheet1!$G$3:$G$9,MATCH($C24,Sheet1!$F$3:$F$9,0)),Sheet1!$C$3:$C$97,$G24),0)) -> 0
B25: ='عدد اللاعبين'!B14 -> الجوف | C25: ='عدد اللاعبين'!C14 -> تحت 12 | D25: =IFERROR(INDEX(المدخلات!$AD$6:$AD$12,MATCH($C25,المدخلات!$AC$6:$AC$12,0)),"") -> الاثنين | E25: ='عدد اللاعبين'!D14 -> مجموعة طبرجل | F25: ='عدد اللاعبين'!F14 -> القريات | G25: ='عدد اللاعبين'!G14 -> 5 | H25: =IFERROR(INDEX(المدخلات!$AE$6:$AE$12,MATCH($C25,المدخلات!$AC$6:$AC$12,0)),"") -> 7 ضد 7 | I25: =IF($G25<الحد_الأدنى,0,ROUNDDOWN($G25/فرق_المباراة,0)) -> 0 | J25: =ROUNDUP($I25/IFERROR(INDEX(المدخلات!$AJ$6:$AJ$12,MATCH($C25,المدخلات!$AC$6:$AC$12,0)),1),0) -> 0 | K25: =IF($G25<الحد_الأدنى,0,IFERROR(SUMIFS(Sheet1!$D$3:$D$97,Sheet1!$B$3:$B$97,INDEX(Sheet1!$G$3:$G$9,MATCH($C25,Sheet1!$F$3:$F$9,0)),Sheet1!$C$3:$C$97,$G25),0)) -> 0
... B204: ='عدد اللاعبين'!B193 -> مكة المكرمة | C204: ='عدد اللاعبين'!C193 -> تحت 12 | D204: =IFERROR(INDEX(المدخلات!$AD$6:$AD$12,MATCH($C204,المدخلات!$AC$6:$AC$12,0)),"") -> الاثنين | E204: ='عدد اللاعبين'!D193 -> مجموعة جدة | F204: ='عدد اللاعبين'!F193 -> #VALUE! | G204: ='عدد اللاعبين'!G193 -> 0 | H204: =IFERROR(INDEX(المدخلات!$AE$6:$AE$12,MATCH($C204,المدخلات!$AC$6:$AC$12,0)),"") -> 7 ضد 7 | I204: =IF($G204<الحد_الأدنى,0,ROUNDDOWN($G204/فرق_المباراة,0)) -> 0 | J204: =ROUNDUP($I204/IFERROR(INDEX(المدخلات!$AJ$6:$AJ$12,MATCH($C204,المدخلات!$AC$6:$AC$12,0)),1),0) -> 0 | K204: =IF($G204<الحد_الأدنى,0,IFERROR(SUMIFS(Sheet1!$D$3:$D$97,Sheet1!$B$3:$B$97,INDEX(Sheet1!$G$3:$G$9,MATCH($C204,Sheet1!$F$3:$F$9,0)),Sheet1!$C$3:$C$97,$G204),0)) -> 0
B209: الطلب لكل مجموعة — الملاعب القانونية المطلوبة
B210: المنطقة | C210: المجموعة | D210: المدن | E210: تحت 5 / 7 / 9 (الأعلى) | F210: =المدخلات!$AC$9 -> تحت 11 | G210: =المدخلات!$AC$10 -> تحت 12 | H210: =المدخلات!$AC$11 -> تحت 13 | I210: =المدخلات!$AC$12 -> تحت 14 | J210: أقصى ملاعب في يوم واحد | K210: إجمالي الفرق | L210: الحالة
B211: — | C211: — | D211: — | E211: =المدخلات!$AD$6 -> السبت | F211: =المدخلات!$AD$9 -> الأحد | G211: =المدخلات!$AD$10 -> الاثنين | H211: =المدخلات!$AD$11 -> الخميس | I211: =المدخلات!$AD$12 -> الأربعاء | J211: — | K211: — | L211: —
B212: الباحة | C212: مجموعة الباحة | D212: =IFERROR(INDEX('عدد اللاعبين'!$F$3:$F$193,MATCH($C212,'عدد اللاعبين'!$D$3:$D$193,0)),"") -> الباحة، بلقرن | E212: =MAX(SUMIFS($K$14:$K$204,$E$14:$E$204,$C212,$C$14:$C$204,المدخلات!$AC$6),SUMIFS($K$14:$K$204,$E$14:$E$204,$C212,$C$14:$C$204,المدخلات!$AC$7),SUMIFS($K$14:$K$204,$E$14:$E$204,$C212,$C$14:$C$204,المدخلات!$AC$8)) -> 1 | F212: =SUMIFS($K$14:$K$204,$E$14:$E$204,$C212,$C$14:$C$204,المدخلات!$AC$9) -> 0 | G212: =SUMIFS($K$14:$K$204,$E$14:$E$204,$C212,$C$14:$C$204,المدخلات!$AC$10) -> 1 | H212: =SUMIFS($K$14:$K$204,$E$14:$E$204,$C212,$C$14:$C$204,المدخلات!$AC$11) -> 1 | I212: =SUMIFS($K$14:$K$204,$E$14:$E$204,$C212,$C$14:$C$204,المدخلات!$AC$12) -> 1 | J212: =MAX($E212:$I212) -> 1 | K212: =SUMIFS($G$14:$G$204,$E$14:$E$204,$C212,$G$14:$G$204,">="&الحد_الأدنى) -> 33 | L212: =IF($K212=0,"غير مكتملة","مكتملة") -> مكتملة
B213: الجوف | C213: مجموعة القريات | D213: =IFERROR(INDEX('عدد اللاعبين'!$F$3:$F$193,MATCH($C213,'عدد اللاعبين'!$D$3:$D$193,0)),"") -> الباحة | E213: =MAX(SUMIFS($K$14:$K$204,$E$14:$E$204,$C213,$C$14:$C$204,المدخلات!$AC$6),SUMIFS($K$14:$K$204,$E$14:$E$204,$C213,$C$14:$C$204,المدخلات!$AC$7),SUMIFS($K$14:$K$204,$E$14:$E$204,$C213,$C$14:$C$204,المدخلات!$AC$8)) -> 1 | F213: =SUMIFS($K$14:$K$204,$E$14:$E$204,$C213,$C$14:$C$204,المدخلات!$AC$9) -> 1 | G213: =SUMIFS($K$14:$K$204,$E$14:$E$204,$C213,$C$14:$C$204,المدخلات!$AC$10) -> 1 | H213: =SUMIFS($K$14:$K$204,$E$14:$E$204,$C213,$C$14:$C$204,المدخلات!$AC$11) -> 1 | I213: =SUMIFS($K$14:$K$204,$E$14:$E$204,$C213,$C$14:$C$204,المدخلات!$AC$12) -> 1 | J213: =MAX($E213:$I213) -> 1 | K213: =SUMIFS($G$14:$G$204,$E$14:$E$204,$C213,$G$14:$G$204,">="&الحد_الأدنى) -> 46 | L213: =IF($K213=0,"غير مكتملة","مكتملة") -> مكتملة
B214: الجوف | C214: مجموعة سكاكا | D214: =IFERROR(INDEX('عدد اللاعبين'!$F$3:$F$193,MATCH($C214,'عدد اللاعبين'!$D$3:$D$193,0)),"") -> أحد المسارحة | E214: =MAX(SUMIFS($K$14:$K$204,$E$14:$E$204,$C214,$C$14:$C$204,المدخلات!$AC$6),SUMIFS($K$14:$K$204,$E$14:$E$204,$C214,$C$14:$C$204,المدخلات!$AC$7),SUMIFS($K$14:$K$204,$E$14:$E$204,$C214,$C$14:$C$204,المدخلات!$AC$8)) -> 2 | F214: =SUMIFS($K$14:$K$204,$E$14:$E$204,$C214,$C$14:$C$204,المدخلات!$AC$9) -> 0 | G214: =SUMIFS($K$14:$K$204,$E$14:$E$204,$C214,$C$14:$C$204,المدخلات!$AC$10) -> 1 | H214: =SUMIFS($K$14:$K$204,$E$14:$E$204,$C214,$C$14:$C$204,المدخلات!$AC$11) -> 2 | I214: =SUMIFS($K$14:$K$204,$E$14:$E$204,$C214,$C$14:$C$204,المدخلات!$AC$12) -> 0 | J214: =MAX($E214:$I214) -> 2 | K214: =SUMIFS($G$14:$G$204,$E$14:$E$204,$C214,$G$14:$G$204,">="&الحد_الأدنى) -> 81 | L214: =IF($K214=0,"غير مكتملة","مكتملة") -> مكتملة
B215: الجوف | C215: مجموعة طبرجل | D215: =IFERROR(INDEX('عدد اللاعبين'!$F$3:$F$193,MATCH($C215,'عدد اللاعبين'!$D$3:$D$193,0)),"") -> الدوادمي | E215: =MAX(SUMIFS($K$14:$K$204,$E$14:$E$204,$C215,$C$14:$C$204,المدخلات!$AC$6),SUMIFS($K$14:$K$204,$E$14:$E$204,$C215,$C$14:$C$204,المدخلات!$AC$7),SUMIFS($K$14:$K$204,$E$14:$E$204,$C215,$C$14:$C$204,المدخلات!$AC$8)) -> 1 | F215: =SUMIFS($K$14:$K$204,$E$14:$E$204,$C215,$C$14:$C$204,المدخلات!$AC$9) -> 0 | G215: =SUMIFS($K$14:$K$204,$E$14:$E$204,$C215,$C$14:$C$204,المدخلات!$AC$10) -> 0 | H215: =SUMIFS($K$14:$K$204,$E$14:$E$204,$C215,$C$14:$C$204,المدخلات!$AC$11) -> 0 | I215: =SUMIFS($K$14:$K$204,$E$14:$E$204,$C215,$C$14:$C$204,المدخلات!$AC$12) -> 0 | J215: =MAX($E215:$I215) -> 1 | K215: =SUMIFS($G$14:$G$204,$E$14:$E$204,$C215,$G$14:$G$204,">="&الحد_الأدنى) -> 7 | L215: =IF($K215=0,"غير مكتملة","مكتملة") -> مكتملة
B216: الحدود الشمالية | C216: مجموعة الحدود الشمالية | D216: =IFERROR(INDEX('عدد اللاعبين'!$F$3:$F$193,MATCH($C216,'عدد اللاعبين'!$D$3:$D$193,0)),"") | E216: =MAX(SUMIFS($K$14:$K$204,$E$14:$E$204,$C216,$C$14:$C$204,المدخلات!$AC$6),SUMIFS($K$14:$K$204,$E$14:$E$204,$C216,$C$14:$C$204,المدخلات!$AC$7),SUMIFS($K$14:$K$204,$E$14:$E$204,$C216,$C$14:$C$204,المدخلات!$AC$8)) -> 0 | F216: =SUMIFS($K$14:$K$204,$E$14:$E$204,$C216,$C$14:$C$204,المدخلات!$AC$9) -> 0 | G216: =SUMIFS($K$14:$K$204,$E$14:$E$204,$C216,$C$14:$C$204,المدخلات!$AC$10) -> 0 | H216: =SUMIFS($K$14:$K$204,$E$14:$E$204,$C216,$C$14:$C$204,المدخلات!$AC$11) -> 0 | I216: =SUMIFS($K$14:$K$204,$E$14:$E$204,$C216,$C$14:$C$204,المدخلات!$AC$12) -> 0 | J216: =MAX($E216:$I216) -> 0 | K216: =SUMIFS($G$14:$G$204,$E$14:$E$204,$C216,$G$14:$G$204,">="&الحد_الأدنى) -> 0 | L216: =IF($K216=0,"غير مكتملة","مكتملة") -> غير مكتملة
B217: الرياض | C217: مجموعة الخرج | D217: =IFERROR(INDEX('عدد اللاعبين'!$F$3:$F$193,MATCH($C217,'عدد اللاعبين'!$D$3:$D$193,0)),"") -> القريات | E217: =MAX(SUMIFS($K$14:$K$204,$E$14:$E$204,$C217,$C$14:$C$204,المدخلات!$AC$6),SUMIFS($K$14:$K$204,$E$14:$E$204,$C217,$C$14:$C$204,المدخلات!$AC$7),SUMIFS($K$14:$K$204,$E$14:$E$204,$C217,$C$14:$C$204,المدخلات!$AC$8)) -> 0 | F217: =SUMIFS($K$14:$K$204,$E$14:$E$204,$C217,$C$14:$C$204,المدخلات!$AC$9) -> 0 | G217: =SUMIFS($K$14:$K$204,$E$14:$E$204,$C217,$C$14:$C$204,المدخلات!$AC$10) -> 2 | H217: =SUMIFS($K$14:$K$204,$E$14:$E$204,$C217,$C$14:$C$204,المدخلات!$AC$11) -> 2 | I217: =SUMIFS($K$14:$K$204,$E$14:$E$204,$C217,$C$14:$C$204,المدخلات!$AC$12) -> 1 | J217: =MAX($E217:$I217) -> 2 | K217: =SUMIFS($G$14:$G$204,$E$14:$E$204,$C217,$G$14:$G$204,">="&الحد_الأدنى) -> 40 | L217: =IF($K217=0,"غير مكتملة","مكتملة") -> مكتملة
B218: الرياض | C218: مجموعة الدوادمي | D218: =IFERROR(INDEX('عدد اللاعبين'!$F$3:$F$193,MATCH($C218,'عدد اللاعبين'!$D$3:$D$193,0)),"") -> الباحة، بلقرن، العقيق | E218: =MAX(SUMIFS($K$14:$K$204,$E$14:$E$204,$C218,$C$14:$C$204,المدخلات!$AC$6),SUMIFS($K$14:$K$204,$E$14:$E$204,$C218,$C$14:$C$204,المدخلات!$AC$7),SUMIFS($K$14:$K$204,$E$14:$E$204,$C218,$C$14:$C$204,المدخلات!$AC$8)) -> 1 | F218: =SUMIFS($K$14:$K$204,$E$14:$E$204,$C218,$C$14:$C$204,المدخلات!$AC$9) -> 0 | G218: =SUMIFS($K$14:$K$204,$E$14:$E$204,$C218,$C$14:$C$204,المدخلات!$AC$10) -> 0 | H218: =SUMIFS($K$14:$K$204,$E$14:$E$204,$C218,$C$14:$C$204,المدخلات!$AC$11) -> 0 | I218: =SUMIFS($K$14:$K$204,$E$14:$E$204,$C218,$C$14:$C$204,المدخلات!$AC$12) -> 0 | J218: =MAX($E218:$I218) -> 1 | K218: =SUMIFS($G$14:$G$204,$E$14:$E$204,$C218,$G$14:$G$204,">="&الحد_الأدنى) -> 6 | L218: =IF($K218=0,"غير مكتملة","مكتملة") -> مكتملة
B219: الرياض | C219: مجموعة الرياض | D219: =IFERROR(INDEX('عدد اللاعبين'!$F$3:$F$193,MATCH($C219,'عدد اللاعبين'!$D$3:$D$193,0)),"") -> مكة المكرمة | E219: =MAX(SUMIFS($K$14:$K$204,$E$14:$E$204,$C219,$C$14:$C$204,المدخلات!$AC$6),SUMIFS($K$14:$K$204,$E$14:$E$204,$C219,$C$14:$C$204,المدخلات!$AC$7),SUMIFS($K$14:$K$204,$E$14:$E$204,$C219,$C$14:$C$204,المدخلات!$AC$8)) -> 0 | F219: =SUMIFS($K$14:$K$204,$E$14:$E$204,$C219,$C$14:$C$204,المدخلات!$AC$9) -> 0 | G219: =SUMIFS($K$14:$K$204,$E$14:$E$204,$C219,$C$14:$C$204,المدخلات!$AC$10) -> 0 | H219: =SUMIFS($K$14:$K$204,$E$14:$E$204,$C219,$C$14:$C$204,المدخلات!$AC$11) -> 0 | I219: =SUMIFS($K$14:$K$204,$E$14:$E$204,$C219,$C$14:$C$204,المدخلات!$AC$12) -> 0 | J219: =MAX($E219:$I219) -> 0 | K219: =SUMIFS($G$14:$G$204,$E$14:$E$204,$C219,$G$14:$G$204,">="&الحد_الأدنى) -> 151 | L219: =IF($K219=0,"غير مكتملة","مكتملة") -> مكتملة
B220: الرياض | C220: مجموعة الزلفي | D220: =IFERROR(INDEX('عدد اللاعبين'!$F$3:$F$193,MATCH($C220,'عدد اللاعبين'!$D$3:$D$193,0)),"") | E220: =MAX(SUMIFS($K$14:$K$204,$E$14:$E$204,$C220,$C$14:$C$204,المدخلات!$AC$6),SUMIFS($K$14:$K$204,$E$14:$E$204,$C220,$C$14:$C$204,المدخلات!$AC$7),SUMIFS($K$14:$K$204,$E$14:$E$204,$C220,$C$14:$C$204,المدخلات!$AC$8)) -> 0 | F220: =SUMIFS($K$14:$K$204,$E$14:$E$204,$C220,$C$14:$C$204,المدخلات!$AC$9) -> 0 | G220: =SUMIFS($K$14:$K$204,$E$14:$E$204,$C220,$C$14:$C$204,المدخلات!$AC$10) -> 0 | H220: =SUMIFS($K$14:$K$204,$E$14:$E$204,$C220,$C$14:$C$204,المدخلات!$AC$11) -> 0 | I220: =SUMIFS($K$14:$K$204,$E$14:$E$204,$C220,$C$14:$C$204,المدخلات!$AC$12) -> 0 | J220: =MAX($E220:$I220) -> 0 | K220: =SUMIFS($G$14:$G$204,$E$14:$E$204,$C220,$G$14:$G$204,">="&الحد_الأدنى) -> 0 | L220: =IF($K220=0,"غير مكتملة","مكتملة") -> غير مكتملة
B221: الرياض | C221: مجموعة المجمعة | D221: =IFERROR(INDEX('عدد اللاعبين'!$F$3:$F$193,MATCH($C221,'عدد اللاعبين'!$D$3:$D$193,0)),"") | E221: =MAX(SUMIFS($K$14:$K$204,$E$14:$E$204,$C221,$C$14:$C$204,المدخلات!$AC$6),SUMIFS($K$14:$K$204,$E$14:$E$204,$C221,$C$14:$C$204,المدخلات!$AC$7),SUMIFS($K$14:$K$204,$E$14:$E$204,$C221,$C$14:$C$204,المدخلات!$AC$8)) -> 0 | F221: =SUMIFS($K$14:$K$204,$E$14:$E$204,$C221,$C$14:$C$204,المدخلات!$AC$9) -> 0 | G221: =SUMIFS($K$14:$K$204,$E$14:$E$204,$C221,$C$14:$C$204,المدخلات!$AC$10) -> 0 | H221: =SUMIFS($K$14:$K$204,$E$14:$E$204,$C221,$C$14:$C$204,المدخلات!$AC$11) -> 0 | I221: =SUMIFS($K$14:$K$204,$E$14:$E$204,$C221,$C$14:$C$204,المدخلات!$AC$12) -> 0 | J221: =MAX($E221:$I221) -> 0 | K221: =SUMIFS($G$14:$G$204,$E$14:$E$204,$C221,$G$14:$G$204,">="&الحد_الأدنى) -> 0 | L221: =IF($K221=0,"غير مكتملة","مكتملة") -> غير مكتملة
B222: الرياض | C222: مجموعة عفيف | D222: =IFERROR(INDEX('عدد اللاعبين'!$F$3:$F$193,MATCH($C222,'عدد اللاعبين'!$D$3:$D$193,0)),"") | E222: =MAX(SUMIFS($K$14:$K$204,$E$14:$E$204,$C222,$C$14:$C$204,المدخلات!$AC$6),SUMIFS($K$14:$K$204,$E$14:$E$204,$C222,$C$14:$C$204,المدخلات!$AC$7),SUMIFS($K$14:$K$204,$E$14:$E$204,$C222,$C$14:$C$204,المدخلات!$AC$8)) -> 0 | F222: =SUMIFS($K$14:$K$204,$E$14:$E$204,$C222,$C$14:$C$204,المدخلات!$AC$9) -> 0 | G222: =SUMIFS($K$14:$K$204,$E$14:$E$204,$C222,$C$14:$C$204,المدخلات!$AC$10) -> 0 | H222: =SUMIFS($K$14:$K$204,$E$14:$E$204,$C222,$C$14:$C$204,المدخلات!$AC$11) -> 0 | I222: =SUMIFS($K$14:$K$204,$E$14:$E$204,$C222,$C$14:$C$204,المدخلات!$AC$12) -> 0 | J222: =MAX($E222:$I222) -> 0 | K222: =SUMIFS($G$14:$G$204,$E$14:$E$204,$C222,$G$14:$G$204,">="&الحد_الأدنى) -> 0 | L222: =IF($K222=0,"غير مكتملة","مكتملة") -> غير مكتملة
B223: الرياض | C223: مجموعة وادي الدواسر | D223: =IFERROR(INDEX('عدد اللاعبين'!$F$3:$F$193,MATCH($C223,'عدد اللاعبين'!$D$3:$D$193,0)),"") | E223: =MAX(SUMIFS($K$14:$K$204,$E$14:$E$204,$C223,$C$14:$C$204,المدخلات!$AC$6),SUMIFS($K$14:$K$204,$E$14:$E$204,$C223,$C$14:$C$204,المدخلات!$AC$7),SUMIFS($K$14:$K$204,$E$14:$E$204,$C223,$C$14:$C$204,المدخلات!$AC$8)) -> 0 | F223: =SUMIFS($K$14:$K$204,$E$14:$E$204,$C223,$C$14:$C$204,المدخلات!$AC$9) -> 0 | G223: =SUMIFS($K$14:$K$204,$E$14:$E$204,$C223,$C$14:$C$204,المدخلات!$AC$10) -> 0 | H223: =SUMIFS($K$14:$K$204,$E$14:$E$204,$C223,$C$14:$C$204,المدخلات!$AC$11) -> 0 | I223: =SUMIFS($K$14:$K$204,$E$14:$E$204,$C223,$C$14:$C$204,المدخلات!$AC$12) -> 0 | J223: =MAX($E223:$I223) -> 0 | K223: =SUMIFS($G$14:$G$204,$E$14:$E$204,$C223,$G$14:$G$204,">="&الحد_الأدنى) -> 0 | L223: =IF($K223=0,"غير مكتملة","مكتملة") -> غير مكتملة
... B260: نجران | C260: مجموعة نجران | D260: =IFERROR(INDEX('عدد اللاعبين'!$F$3:$F$193,MATCH($C260,'عدد اللاعبين'!$D$3:$D$193,0)),"") -> شرورة | E260: =MAX(SUMIFS($K$14:$K$204,$E$14:$E$204,$C260,$C$14:$C$204,المدخلات!$AC$6),SUMIFS($K$14:$K$204,$E$14:$E$204,$C260,$C$14:$C$204,المدخلات!$AC$7),SUMIFS($K$14:$K$204,$E$14:$E$204,$C260,$C$14:$C$204,المدخلات!$AC$8)) -> 0 | F260: =SUMIFS($K$14:$K$204,$E$14:$E$204,$C260,$C$14:$C$204,المدخلات!$AC$9) -> 0 | G260: =SUMIFS($K$14:$K$204,$E$14:$E$204,$C260,$C$14:$C$204,المدخلات!$AC$10) -> 1 | H260: =SUMIFS($K$14:$K$204,$E$14:$E$204,$C260,$C$14:$C$204,المدخلات!$AC$11) -> 1 | I260: =SUMIFS($K$14:$K$204,$E$14:$E$204,$C260,$C$14:$C$204,المدخلات!$AC$12) -> 0 | J260: =MAX($E260:$I260) -> 1 | K260: =SUMIFS($G$14:$G$204,$E$14:$E$204,$C260,$G$14:$G$204,">="&الحد_الأدنى) -> 14 | L260: =IF($K260=0,"غير مكتملة","مكتملة") -> مكتملة
...

Sheet عدد الملاعب
B2: ملخص الملاعب لكل يوم (المجموعات المكتملة فقط)
B3: الفئة | C3: اليوم | D3: نوع الملعب | E3: المجموعات | F3: عدد الفرق | G3: ملاعب قانونية
B4: =المدخلات!$AC$6 -> تحت 5 | C4: =المدخلات!$AD$6 -> السبت | D4: =المدخلات!$AE$6 -> 5 ضد 5 | E4: =COUNTIFS($C$14:$C$204,المدخلات!$AC$6,$G$14:$G$204,">="&الحد_الأدنى) -> 20 | F4: =SUMIFS($G$14:$G$204,$C$14:$C$204,المدخلات!$AC$6,$G$14:$G$204,">="&الحد_الأدنى) -> 240 | G4: =SUMIFS($K$14:$K$204,$C$14:$C$204,المدخلات!$AC$6) -> 21
B5: =المدخلات!$AC$7 -> تحت 7 | C5: =المدخلات!$AD$7 -> السبت | D5: =المدخلات!$AE$7 -> 7 ضد 7 | E5: =COUNTIFS($C$14:$C$204,المدخلات!$AC$7,$G$14:$G$204,">="&الحد_الأدنى) -> 23 | F5: =SUMIFS($G$14:$G$204,$C$14:$C$204,المدخلات!$AC$7,$G$14:$G$204,">="&الحد_الأدنى) -> 347 | G5: =SUMIFS($K$14:$K$204,$C$14:$C$204,المدخلات!$AC$7) -> 38
B6: =المدخلات!$AC$8 -> تحت 9 | C6: =المدخلات!$AD$8 -> السبت | D6: =المدخلات!$AE$8 -> 7 ضد 7 | E6: =COUNTIFS($C$14:$C$204,المدخلات!$AC$8,$G$14:$G$204,">="&الحد_الأدنى) -> 25 | F6: =SUMIFS($G$14:$G$204,$C$14:$C$204,المدخلات!$AC$8,$G$14:$G$204,">="&الحد_الأدنى) -> 398 | G6: =SUMIFS($K$14:$K$204,$C$14:$C$204,المدخلات!$AC$8) -> 42
B7: =المدخلات!$AC$9 -> تحت 11 | C7: =المدخلات!$AD$9 -> الأحد | D7: =المدخلات!$AE$9 -> 7 ضد 7 | E7: =COUNTIFS($C$14:$C$204,المدخلات!$AC$9,$G$14:$G$204,">="&الحد_الأدنى) -> 24 | F7: =SUMIFS($G$14:$G$204,$C$14:$C$204,المدخلات!$AC$9,$G$14:$G$204,">="&الحد_الأدنى) -> 369 | G7: =SUMIFS($K$14:$K$204,$C$14:$C$204,المدخلات!$AC$9) -> 30
B8: =المدخلات!$AC$10 -> تحت 12 | C8: =المدخلات!$AD$10 -> الاثنين | D8: =المدخلات!$AE$10 -> 7 ضد 7 | E8: =COUNTIFS($C$14:$C$204,المدخلات!$AC$10,$G$14:$G$204,">="&الحد_الأدنى) -> 27 | F8: =SUMIFS($G$14:$G$204,$C$14:$C$204,المدخلات!$AC$10,$G$14:$G$204,">="&الحد_الأدنى) -> 392 | G8: =SUMIFS($K$14:$K$204,$C$14:$C$204,المدخلات!$AC$10) -> 33
B9: =المدخلات!$AC$11 -> تحت 13 | C9: =المدخلات!$AD$11 -> الخميس | D9: =المدخلات!$AE$11 -> قانوني | E9: =COUNTIFS($C$14:$C$204,المدخلات!$AC$11,$G$14:$G$204,">="&الحد_الأدنى) -> 27 | F9: =SUMIFS($G$14:$G$204,$C$14:$C$204,المدخلات!$AC$11,$G$14:$G$204,">="&الحد_الأدنى) -> 403 | G9: =SUMIFS($K$14:$K$204,$C$14:$C$204,المدخلات!$AC$11) -> 75
B10: =المدخلات!$AC$12 -> تحت 14 | C10: =المدخلات!$AD$12 -> الأربعاء | D10: =المدخلات!$AE$12 -> قانوني | E10: =COUNTIFS($C$14:$C$204,المدخلات!$AC$12,$G$14:$G$204,">="&الحد_الأدنى) -> 25 | F10: =SUMIFS($G$14:$G$204,$C$14:$C$204,المدخلات!$AC$12,$G$14:$G$204,">="&الحد_الأدنى) -> 376 | G10: =SUMIFS($K$14:$K$204,$C$14:$C$204,المدخلات!$AC$12) -> 68
B11: الإجمالي | E11: =SUM(E4:E10) -> 171 | F11: =SUM(F4:F10) -> 2525 | G11: =SUM(G4:G10) -> 307
B13: المنطقة | C13: الفئة | D13: اليوم | E13: المجموعة | F13: المدن | G13: عدد الفرق | H13: نوع الملعب | I13: عدد المباريات في اليوم | J13: ملاعب اللعب المطلوبة | K13: ملاعب قانونية معادلة
B14: ='عدد اللاعبين'!B3 | C14: ='عدد اللاعبين'!C3 -> #REF! | D14: =IFERROR(INDEX(المدخلات!$AD$6:$AD$12,MATCH($C14,المدخلات!$AC$6:$AC$12,0)),"") | E14: ='عدد اللاعبين'!D3 -> #REF! | F14: ='عدد اللاعبين'!F3 -> نجران | G14: ='عدد اللاعبين'!G3 -> 5 | H14: =IFERROR(INDEX(المدخلات!$AE$6:$AE$12,MATCH($C14,المدخلات!$AC$6:$AC$12,0)),"") | I14: =IF($G14<الحد_الأدنى,0,ROUNDDOWN($G14/فرق_المباراة,0)) -> 0 | J14: =ROUNDUP($I14/IFERROR(INDEX(المدخلات!$AJ$6:$AJ$12,MATCH($C14,المدخلات!$AC$6:$AC$12,0)),1),0) -> 0 | K14: =ROUNDUP($J14/IFERROR(INDEX(المدخلات!$AF$6:$AF$12,MATCH($C14,المدخلات!$AC$6:$AC$12,0)),1),0) -> 0
B15: ='عدد اللاعبين'!B4 | C15: ='عدد اللاعبين'!C4 -> #REF! | D15: =IFERROR(INDEX(المدخلات!$AD$6:$AD$12,MATCH($C15,المدخلات!$AC$6:$AC$12,0)),"") | E15: ='عدد اللاعبين'!D4 -> #REF! | F15: ='عدد اللاعبين'!F4 -> طبرجل | G15: ='عدد اللاعبين'!G4 -> 5 | H15: =IFERROR(INDEX(المدخلات!$AE$6:$AE$12,MATCH($C15,المدخلات!$AC$6:$AC$12,0)),"") | I15: =IF($G15<الحد_الأدنى,0,ROUNDDOWN($G15/فرق_المباراة,0)) -> 0 | J15: =ROUNDUP($I15/IFERROR(INDEX(المدخلات!$AJ$6:$AJ$12,MATCH($C15,المدخلات!$AC$6:$AC$12,0)),1),0) -> 0 | K15: =ROUNDUP($J15/IFERROR(INDEX(المدخلات!$AF$6:$AF$12,MATCH($C15,المدخلات!$AC$6:$AC$12,0)),1),0) -> 0
B16: ='عدد اللاعبين'!B5 | C16: ='عدد اللاعبين'!C5 -> #REF! | D16: =IFERROR(INDEX(المدخلات!$AD$6:$AD$12,MATCH($C16,المدخلات!$AC$6:$AC$12,0)),"") | E16: ='عدد اللاعبين'!D5 -> #REF! | F16: ='عدد اللاعبين'!F5 -> طبرجل | G16: ='عدد اللاعبين'!G5 -> 5 | H16: =IFERROR(INDEX(المدخلات!$AE$6:$AE$12,MATCH($C16,المدخلات!$AC$6:$AC$12,0)),"") | I16: =IF($G16<الحد_الأدنى,0,ROUNDDOWN($G16/فرق_المباراة,0)) -> 0 | J16: =ROUNDUP($I16/IFERROR(INDEX(المدخلات!$AJ$6:$AJ$12,MATCH($C16,المدخلات!$AC$6:$AC$12,0)),1),0) -> 0 | K16: =ROUNDUP($J16/IFERROR(INDEX(المدخلات!$AF$6:$AF$12,MATCH($C16,المدخلات!$AC$6:$AC$12,0)),1),0) -> 0
B17: ='عدد اللاعبين'!B6 | C17: ='عدد اللاعبين'!C6 -> #REF! | D17: =IFERROR(INDEX(المدخلات!$AD$6:$AD$12,MATCH($C17,المدخلات!$AC$6:$AC$12,0)),"") | E17: ='عدد اللاعبين'!D6 -> #REF! | F17: ='عدد اللاعبين'!F6 -> الخرج | G17: ='عدد اللاعبين'!G6 -> 5 | H17: =IFERROR(INDEX(المدخلات!$AE$6:$AE$12,MATCH($C17,المدخلات!$AC$6:$AC$12,0)),"") | I17: =IF($G17<الحد_الأدنى,0,ROUNDDOWN($G17/فرق_المباراة,0)) -> 0 | J17: =ROUNDUP($I17/IFERROR(INDEX(المدخلات!$AJ$6:$AJ$12,MATCH($C17,المدخلات!$AC$6:$AC$12,0)),1),0) -> 0 | K17: =ROUNDUP($J17/IFERROR(INDEX(المدخلات!$AF$6:$AF$12,MATCH($C17,المدخلات!$AC$6:$AC$12,0)),1),0) -> 0
B18: ='عدد اللاعبين'!B7 | C18: ='عدد اللاعبين'!C7 -> #REF! | D18: =IFERROR(INDEX(المدخلات!$AD$6:$AD$12,MATCH($C18,المدخلات!$AC$6:$AC$12,0)),"") | E18: ='عدد اللاعبين'!D7 -> #REF! | F18: ='عدد اللاعبين'!F7 -> طبرجل | G18: ='عدد اللاعبين'!G7 -> 5 | H18: =IFERROR(INDEX(المدخلات!$AE$6:$AE$12,MATCH($C18,المدخلات!$AC$6:$AC$12,0)),"") | I18: =IF($G18<الحد_الأدنى,0,ROUNDDOWN($G18/فرق_المباراة,0)) -> 0 | J18: =ROUNDUP($I18/IFERROR(INDEX(المدخلات!$AJ$6:$AJ$12,MATCH($C18,المدخلات!$AC$6:$AC$12,0)),1),0) -> 0 | K18: =ROUNDUP($J18/IFERROR(INDEX(المدخلات!$AF$6:$AF$12,MATCH($C18,المدخلات!$AC$6:$AC$12,0)),1),0) -> 0
B19: ='عدد اللاعبين'!B8 | C19: ='عدد اللاعبين'!C8 -> #REF! | D19: =IFERROR(INDEX(المدخلات!$AD$6:$AD$12,MATCH($C19,المدخلات!$AC$6:$AC$12,0)),"") | E19: ='عدد اللاعبين'!D8 -> #REF! | F19: ='عدد اللاعبين'!F8 -> طبرجل | G19: ='عدد اللاعبين'!G8 -> 5 | H19: =IFERROR(INDEX(المدخلات!$AE$6:$AE$12,MATCH($C19,المدخلات!$AC$6:$AC$12,0)),"") | I19: =IF($G19<الحد_الأدنى,0,ROUNDDOWN($G19/فرق_المباراة,0)) -> 0 | J19: =ROUNDUP($I19/IFERROR(INDEX(المدخلات!$AJ$6:$AJ$12,MATCH($C19,المدخلات!$AC$6:$AC$12,0)),1),0) -> 0 | K19: =ROUNDUP($J19/IFERROR(INDEX(المدخلات!$AF$6:$AF$12,MATCH($C19,المدخلات!$AC$6:$AC$12,0)),1),0) -> 0
B20: ='عدد اللاعبين'!B9 | C20: ='عدد اللاعبين'!C9 -> #REF! | D20: =IFERROR(INDEX(المدخلات!$AD$6:$AD$12,MATCH($C20,المدخلات!$AC$6:$AC$12,0)),"") | E20: ='عدد اللاعبين'!D9 -> #REF! | F20: ='عدد اللاعبين'!F9 -> شرورة | G20: ='عدد اللاعبين'!G9 -> 5 | H20: =IFERROR(INDEX(المدخلات!$AE$6:$AE$12,MATCH($C20,المدخلات!$AC$6:$AC$12,0)),"") | I20: =IF($G20<الحد_الأدنى,0,ROUNDDOWN($G20/فرق_المباراة,0)) -> 0 | J20: =ROUNDUP($I20/IFERROR(INDEX(المدخلات!$AJ$6:$AJ$12,MATCH($C20,المدخلات!$AC$6:$AC$12,0)),1),0) -> 0 | K20: =ROUNDUP($J20/IFERROR(INDEX(المدخلات!$AF$6:$AF$12,MATCH($C20,المدخلات!$AC$6:$AC$12,0)),1),0) -> 0
B21: ='عدد اللاعبين'!B10 -> نجران | C21: ='عدد اللاعبين'!C10 -> تحت 14 | D21: =IFERROR(INDEX(المدخلات!$AD$6:$AD$12,MATCH($C21,المدخلات!$AC$6:$AC$12,0)),"") -> الأربعاء | E21: ='عدد اللاعبين'!D10 -> مجموعة نجران | F21: ='عدد اللاعبين'!F10 -> شرورة | G21: ='عدد اللاعبين'!G10 -> 5 | H21: =IFERROR(INDEX(المدخلات!$AE$6:$AE$12,MATCH($C21,المدخلات!$AC$6:$AC$12,0)),"") -> قانوني | I21: =IF($G21<الحد_الأدنى,0,ROUNDDOWN($G21/فرق_المباراة,0)) -> 0 | J21: =ROUNDUP($I21/IFERROR(INDEX(المدخلات!$AJ$6:$AJ$12,MATCH($C21,المدخلات!$AC$6:$AC$12,0)),1),0) -> 0 | K21: =ROUNDUP($J21/IFERROR(INDEX(المدخلات!$AF$6:$AF$12,MATCH($C21,المدخلات!$AC$6:$AC$12,0)),1),0) -> 0
B22: ='عدد اللاعبين'!B11 -> الجوف | C22: ='عدد اللاعبين'!C11 -> تحت 5 | D22: =IFERROR(INDEX(المدخلات!$AD$6:$AD$12,MATCH($C22,المدخلات!$AC$6:$AC$12,0)),"") -> السبت | E22: ='عدد اللاعبين'!D11 -> مجموعة طبرجل | F22: ='عدد اللاعبين'!F11 -> الدوادمي | G22: ='عدد اللاعبين'!G11 -> 5 | H22: =IFERROR(INDEX(المدخلات!$AE$6:$AE$12,MATCH($C22,المدخلات!$AC$6:$AC$12,0)),"") -> 5 ضد 5 | I22: =IF($G22<الحد_الأدنى,0,ROUNDDOWN($G22/فرق_المباراة,0)) -> 0 | J22: =ROUNDUP($I22/IFERROR(INDEX(المدخلات!$AJ$6:$AJ$12,MATCH($C22,المدخلات!$AC$6:$AC$12,0)),1),0) -> 0 | K22: =ROUNDUP($J22/IFERROR(INDEX(المدخلات!$AF$6:$AF$12,MATCH($C22,المدخلات!$AC$6:$AC$12,0)),1),0) -> 0
B23: ='عدد اللاعبين'!B12 -> الجوف | C23: ='عدد اللاعبين'!C12 -> تحت 7 | D23: =IFERROR(INDEX(المدخلات!$AD$6:$AD$12,MATCH($C23,المدخلات!$AC$6:$AC$12,0)),"") -> السبت | E23: ='عدد اللاعبين'!D12 -> مجموعة طبرجل | F23: ='عدد اللاعبين'!F12 -> القريات | G23: ='عدد اللاعبين'!G12 -> 5 | H23: =IFERROR(INDEX(المدخلات!$AE$6:$AE$12,MATCH($C23,المدخلات!$AC$6:$AC$12,0)),"") -> 7 ضد 7 | I23: =IF($G23<الحد_الأدنى,0,ROUNDDOWN($G23/فرق_المباراة,0)) -> 0 | J23: =ROUNDUP($I23/IFERROR(INDEX(المدخلات!$AJ$6:$AJ$12,MATCH($C23,المدخلات!$AC$6:$AC$12,0)),1),0) -> 0 | K23: =ROUNDUP($J23/IFERROR(INDEX(المدخلات!$AF$6:$AF$12,MATCH($C23,المدخلات!$AC$6:$AC$12,0)),1),0) -> 0
B24: ='عدد اللاعبين'!B13 -> الرياض | C24: ='عدد اللاعبين'!C13 -> تحت 9 | D24: =IFERROR(INDEX(المدخلات!$AD$6:$AD$12,MATCH($C24,المدخلات!$AC$6:$AC$12,0)),"") -> السبت | E24: ='عدد اللاعبين'!D13 -> مجموعة الخرج | F24: ='عدد اللاعبين'!F13 -> القريات | G24: ='عدد اللاعبين'!G13 -> 5 | H24: =IFERROR(INDEX(المدخلات!$AE$6:$AE$12,MATCH($C24,المدخلات!$AC$6:$AC$12,0)),"") -> 7 ضد 7 | I24: =IF($G24<الحد_الأدنى,0,ROUNDDOWN($G24/فرق_المباراة,0)) -> 0 | J24: =ROUNDUP($I24/IFERROR(INDEX(المدخلات!$AJ$6:$AJ$12,MATCH($C24,المدخلات!$AC$6:$AC$12,0)),1),0) -> 0 | K24: =ROUNDUP($J24/IFERROR(INDEX(المدخلات!$AF$6:$AF$12,MATCH($C24,المدخلات!$AC$6:$AC$12,0)),1),0) -> 0
B25: ='عدد اللاعبين'!B14 -> الجوف | C25: ='عدد اللاعبين'!C14 -> تحت 12 | D25: =IFERROR(INDEX(المدخلات!$AD$6:$AD$12,MATCH($C25,المدخلات!$AC$6:$AC$12,0)),"") -> الاثنين | E25: ='عدد اللاعبين'!D14 -> مجموعة طبرجل | F25: ='عدد اللاعبين'!F14 -> القريات | G25: ='عدد اللاعبين'!G14 -> 5 | H25: =IFERROR(INDEX(المدخلات!$AE$6:$AE$12,MATCH($C25,المدخلات!$AC$6:$AC$12,0)),"") -> 7 ضد 7 | I25: =IF($G25<الحد_الأدنى,0,ROUNDDOWN($G25/فرق_المباراة,0)) -> 0 | J25: =ROUNDUP($I25/IFERROR(INDEX(المدخلات!$AJ$6:$AJ$12,MATCH($C25,المدخلات!$AC$6:$AC$12,0)),1),0) -> 0 | K25: =ROUNDUP($J25/IFERROR(INDEX(المدخلات!$AF$6:$AF$12,MATCH($C25,المدخلات!$AC$6:$AC$12,0)),1),0) -> 0
... B204: ='عدد اللاعبين'!B193 -> مكة المكرمة | C204: ='عدد اللاعبين'!C193 -> تحت 12 | D204: =IFERROR(INDEX(المدخلات!$AD$6:$AD$12,MATCH($C204,المدخلات!$AC$6:$AC$12,0)),"") -> الاثنين | E204: ='عدد اللاعبين'!D193 -> مجموعة جدة | F204: ='عدد اللاعبين'!F193 -> #VALUE! | G204: ='عدد اللاعبين'!G193 -> 0 | H204: =IFERROR(INDEX(المدخلات!$AE$6:$AE$12,MATCH($C204,المدخلات!$AC$6:$AC$12,0)),"") -> 7 ضد 7 | I204: =IF($G204<الحد_الأدنى,0,ROUNDDOWN($G204/فرق_المباراة,0)) -> 0 | J204: =ROUNDUP($I204/IFERROR(INDEX(المدخلات!$AJ$6:$AJ$12,MATCH($C204,المدخلات!$AC$6:$AC$12,0)),1),0) -> 0 | K204: =ROUNDUP($J204/IFERROR(INDEX(المدخلات!$AF$6:$AF$12,MATCH($C204,المدخلات!$AC$6:$AC$12,0)),1),0) -> 0
B209: الطلب لكل مجموعة — الملاعب القانونية المطلوبة
B210: المنطقة | C210: المجموعة | D210: المدن | E210: تحت 5 / 7 / 9 (الأعلى) | F210: =المدخلات!$AC$9 -> تحت 11 | G210: =المدخلات!$AC$10 -> تحت 12 | H210: =المدخلات!$AC$11 -> تحت 13 | I210: =المدخلات!$AC$12 -> تحت 14 | J210: أقصى ملاعب في يوم واحد | K210: إجمالي الفرق | L210: الحالة
B211: — | C211: — | D211: — | E211: =المدخلات!$AD$6 -> السبت | F211: =المدخلات!$AD$9 -> الأحد | G211: =المدخلات!$AD$10 -> الاثنين | H211: =المدخلات!$AD$11 -> الخميس | I211: =المدخلات!$AD$12 -> الأربعاء | J211: — | K211: — | L211: —
B212: الباحة | C212: مجموعة الباحة | D212: =IFERROR(INDEX('عدد اللاعبين'!$F$3:$F$193,MATCH($C212,'عدد اللاعبين'!$D$3:$D$193,0)),"") -> الباحة، بلقرن | E212: =MAX(SUMIFS($K$14:$K$204,$E$14:$E$204,$C212,$C$14:$C$204,المدخلات!$AC$6),SUMIFS($K$14:$K$204,$E$14:$E$204,$C212,$C$14:$C$204,المدخلات!$AC$7),SUMIFS($K$14:$K$204,$E$14:$E$204,$C212,$C$14:$C$204,المدخلات!$AC$8)) -> 1 | F212: =SUMIFS($K$14:$K$204,$E$14:$E$204,$C212,$C$14:$C$204,المدخلات!$AC$9) -> 0 | G212: =SUMIFS($K$14:$K$204,$E$14:$E$204,$C212,$C$14:$C$204,المدخلات!$AC$10) -> 1 | H212: =SUMIFS($K$14:$K$204,$E$14:$E$204,$C212,$C$14:$C$204,المدخلات!$AC$11) -> 1 | I212: =SUMIFS($K$14:$K$204,$E$14:$E$204,$C212,$C$14:$C$204,المدخلات!$AC$12) -> 1 | J212: =MAX($E212:$I212) -> 1 | K212: =SUMIFS($G$14:$G$204,$E$14:$E$204,$C212,$G$14:$G$204,">="&الحد_الأدنى) -> 33 | L212: =IF($K212=0,"غير مكتملة","مكتملة") -> مكتملة
B213: الجوف | C213: مجموعة القريات | D213: =IFERROR(INDEX('عدد اللاعبين'!$F$3:$F$193,MATCH($C213,'عدد اللاعبين'!$D$3:$D$193,0)),"") -> الباحة | E213: =MAX(SUMIFS($K$14:$K$204,$E$14:$E$204,$C213,$C$14:$C$204,المدخلات!$AC$6),SUMIFS($K$14:$K$204,$E$14:$E$204,$C213,$C$14:$C$204,المدخلات!$AC$7),SUMIFS($K$14:$K$204,$E$14:$E$204,$C213,$C$14:$C$204,المدخلات!$AC$8)) -> 1 | F213: =SUMIFS($K$14:$K$204,$E$14:$E$204,$C213,$C$14:$C$204,المدخلات!$AC$9) -> 1 | G213: =SUMIFS($K$14:$K$204,$E$14:$E$204,$C213,$C$14:$C$204,المدخلات!$AC$10) -> 1 | H213: =SUMIFS($K$14:$K$204,$E$14:$E$204,$C213,$C$14:$C$204,المدخلات!$AC$11) -> 1 | I213: =SUMIFS($K$14:$K$204,$E$14:$E$204,$C213,$C$14:$C$204,المدخلات!$AC$12) -> 1 | J213: =MAX($E213:$I213) -> 1 | K213: =SUMIFS($G$14:$G$204,$E$14:$E$204,$C213,$G$14:$G$204,">="&الحد_الأدنى) -> 46 | L213: =IF($K213=0,"غير مكتملة","مكتملة") -> مكتملة
B214: الجوف | C214: مجموعة سكاكا | D214: =IFERROR(INDEX('عدد اللاعبين'!$F$3:$F$193,MATCH($C214,'عدد اللاعبين'!$D$3:$D$193,0)),"") -> أحد المسارحة | E214: =MAX(SUMIFS($K$14:$K$204,$E$14:$E$204,$C214,$C$14:$C$204,المدخلات!$AC$6),SUMIFS($K$14:$K$204,$E$14:$E$204,$C214,$C$14:$C$204,المدخلات!$AC$7),SUMIFS($K$14:$K$204,$E$14:$E$204,$C214,$C$14:$C$204,المدخلات!$AC$8)) -> 2 | F214: =SUMIFS($K$14:$K$204,$E$14:$E$204,$C214,$C$14:$C$204,المدخلات!$AC$9) -> 1 | G214: =SUMIFS($K$14:$K$204,$E$14:$E$204,$C214,$C$14:$C$204,المدخلات!$AC$10) -> 1 | H214: =SUMIFS($K$14:$K$204,$E$14:$E$204,$C214,$C$14:$C$204,المدخلات!$AC$11) -> 2 | I214: =SUMIFS($K$14:$K$204,$E$14:$E$204,$C214,$C$14:$C$204,المدخلات!$AC$12) -> 2 | J214: =MAX($E214:$I214) -> 2 | K214: =SUMIFS($G$14:$G$204,$E$14:$E$204,$C214,$G$14:$G$204,">="&الحد_الأدنى) -> 81 | L214: =IF($K214=0,"غير مكتملة","مكتملة") -> مكتملة
B215: الجوف | C215: مجموعة طبرجل | D215: =IFERROR(INDEX('عدد اللاعبين'!$F$3:$F$193,MATCH($C215,'عدد اللاعبين'!$D$3:$D$193,0)),"") -> الدوادمي | E215: =MAX(SUMIFS($K$14:$K$204,$E$14:$E$204,$C215,$C$14:$C$204,المدخلات!$AC$6),SUMIFS($K$14:$K$204,$E$14:$E$204,$C215,$C$14:$C$204,المدخلات!$AC$7),SUMIFS($K$14:$K$204,$E$14:$E$204,$C215,$C$14:$C$204,المدخلات!$AC$8)) -> 1 | F215: =SUMIFS($K$14:$K$204,$E$14:$E$204,$C215,$C$14:$C$204,المدخلات!$AC$9) -> 0 | G215: =SUMIFS($K$14:$K$204,$E$14:$E$204,$C215,$C$14:$C$204,المدخلات!$AC$10) -> 0 | H215: =SUMIFS($K$14:$K$204,$E$14:$E$204,$C215,$C$14:$C$204,المدخلات!$AC$11) -> 0 | I215: =SUMIFS($K$14:$K$204,$E$14:$E$204,$C215,$C$14:$C$204,المدخلات!$AC$12) -> 0 | J215: =MAX($E215:$I215) -> 1 | K215: =SUMIFS($G$14:$G$204,$E$14:$E$204,$C215,$G$14:$G$204,">="&الحد_الأدنى) -> 7 | L215: =IF($K215=0,"غير مكتملة","مكتملة") -> مكتملة
B216: الحدود الشمالية | C216: مجموعة الحدود الشمالية | D216: =IFERROR(INDEX('عدد اللاعبين'!$F$3:$F$193,MATCH($C216,'عدد اللاعبين'!$D$3:$D$193,0)),"") | E216: =MAX(SUMIFS($K$14:$K$204,$E$14:$E$204,$C216,$C$14:$C$204,المدخلات!$AC$6),SUMIFS($K$14:$K$204,$E$14:$E$204,$C216,$C$14:$C$204,المدخلات!$AC$7),SUMIFS($K$14:$K$204,$E$14:$E$204,$C216,$C$14:$C$204,المدخلات!$AC$8)) -> 0 | F216: =SUMIFS($K$14:$K$204,$E$14:$E$204,$C216,$C$14:$C$204,المدخلات!$AC$9) -> 0 | G216: =SUMIFS($K$14:$K$204,$E$14:$E$204,$C216,$C$14:$C$204,المدخلات!$AC$10) -> 0 | H216: =SUMIFS($K$14:$K$204,$E$14:$E$204,$C216,$C$14:$C$204,المدخلات!$AC$11) -> 0 | I216: =SUMIFS($K$14:$K$204,$E$14:$E$204,$C216,$C$14:$C$204,المدخلات!$AC$12) -> 0 | J216: =MAX($E216:$I216) -> 0 | K216: =SUMIFS($G$14:$G$204,$E$14:$E$204,$C216,$G$14:$G$204,">="&الحد_الأدنى) -> 0 | L216: =IF($K216=0,"غير مكتملة","مكتملة") -> غير مكتملة
B217: الرياض | C217: مجموعة الخرج | D217: =IFERROR(INDEX('عدد اللاعبين'!$F$3:$F$193,MATCH($C217,'عدد اللاعبين'!$D$3:$D$193,0)),"") -> القريات | E217: =MAX(SUMIFS($K$14:$K$204,$E$14:$E$204,$C217,$C$14:$C$204,المدخلات!$AC$6),SUMIFS($K$14:$K$204,$E$14:$E$204,$C217,$C$14:$C$204,المدخلات!$AC$7),SUMIFS($K$14:$K$204,$E$14:$E$204,$C217,$C$14:$C$204,المدخلات!$AC$8)) -> 0 | F217: =SUMIFS($K$14:$K$204,$E$14:$E$204,$C217,$C$14:$C$204,المدخلات!$AC$9) -> 1 | G217: =SUMIFS($K$14:$K$204,$E$14:$E$204,$C217,$C$14:$C$204,المدخلات!$AC$10) -> 1 | H217: =SUMIFS($K$14:$K$204,$E$14:$E$204,$C217,$C$14:$C$204,المدخلات!$AC$11) -> 2 | I217: =SUMIFS($K$14:$K$204,$E$14:$E$204,$C217,$C$14:$C$204,المدخلات!$AC$12) -> 1 | J217: =MAX($E217:$I217) -> 2 | K217: =SUMIFS($G$14:$G$204,$E$14:$E$204,$C217,$G$14:$G$204,">="&الحد_الأدنى) -> 40 | L217: =IF($K217=0,"غير مكتملة","مكتملة") -> مكتملة
B218: الرياض | C218: مجموعة الدوادمي | D218: =IFERROR(INDEX('عدد اللاعبين'!$F$3:$F$193,MATCH($C218,'عدد اللاعبين'!$D$3:$D$193,0)),"") -> الباحة، بلقرن، العقيق | E218: =MAX(SUMIFS($K$14:$K$204,$E$14:$E$204,$C218,$C$14:$C$204,المدخلات!$AC$6),SUMIFS($K$14:$K$204,$E$14:$E$204,$C218,$C$14:$C$204,المدخلات!$AC$7),SUMIFS($K$14:$K$204,$E$14:$E$204,$C218,$C$14:$C$204,المدخلات!$AC$8)) -> 1 | F218: =SUMIFS($K$14:$K$204,$E$14:$E$204,$C218,$C$14:$C$204,المدخلات!$AC$9) -> 0 | G218: =SUMIFS($K$14:$K$204,$E$14:$E$204,$C218,$C$14:$C$204,المدخلات!$AC$10) -> 0 | H218: =SUMIFS($K$14:$K$204,$E$14:$E$204,$C218,$C$14:$C$204,المدخلات!$AC$11) -> 0 | I218: =SUMIFS($K$14:$K$204,$E$14:$E$204,$C218,$C$14:$C$204,المدخلات!$AC$12) -> 0 | J218: =MAX($E218:$I218) -> 1 | K218: =SUMIFS($G$14:$G$204,$E$14:$E$204,$C218,$G$14:$G$204,">="&الحد_الأدنى) -> 6 | L218: =IF($K218=0,"غير مكتملة","مكتملة") -> مكتملة
B219: الرياض | C219: مجموعة الرياض | D219: =IFERROR(INDEX('عدد اللاعبين'!$F$3:$F$193,MATCH($C219,'عدد اللاعبين'!$D$3:$D$193,0)),"") -> مكة المكرمة | E219: =MAX(SUMIFS($K$14:$K$204,$E$14:$E$204,$C219,$C$14:$C$204,المدخلات!$AC$6),SUMIFS($K$14:$K$204,$E$14:$E$204,$C219,$C$14:$C$204,المدخلات!$AC$7),SUMIFS($K$14:$K$204,$E$14:$E$204,$C219,$C$14:$C$204,المدخلات!$AC$8)) -> 4 | F219: =SUMIFS($K$14:$K$204,$E$14:$E$204,$C219,$C$14:$C$204,المدخلات!$AC$9) -> 0 | G219: =SUMIFS($K$14:$K$204,$E$14:$E$204,$C219,$C$14:$C$204,المدخلات!$AC$10) -> 0 | H219: =SUMIFS($K$14:$K$204,$E$14:$E$204,$C219,$C$14:$C$204,المدخلات!$AC$11) -> 6 | I219: =SUMIFS($K$14:$K$204,$E$14:$E$204,$C219,$C$14:$C$204,المدخلات!$AC$12) -> 10 | J219: =MAX($E219:$I219) -> 10 | K219: =SUMIFS($G$14:$G$204,$E$14:$E$204,$C219,$G$14:$G$204,">="&الحد_الأدنى) -> 151 | L219: =IF($K219=0,"غير مكتملة","مكتملة") -> مكتملة
B220: الرياض | C220: مجموعة الزلفي | D220: =IFERROR(INDEX('عدد اللاعبين'!$F$3:$F$193,MATCH($C220,'عدد اللاعبين'!$D$3:$D$193,0)),"") | E220: =MAX(SUMIFS($K$14:$K$204,$E$14:$E$204,$C220,$C$14:$C$204,المدخلات!$AC$6),SUMIFS($K$14:$K$204,$E$14:$E$204,$C220,$C$14:$C$204,المدخلات!$AC$7),SUMIFS($K$14:$K$204,$E$14:$E$204,$C220,$C$14:$C$204,المدخلات!$AC$8)) -> 0 | F220: =SUMIFS($K$14:$K$204,$E$14:$E$204,$C220,$C$14:$C$204,المدخلات!$AC$9) -> 0 | G220: =SUMIFS($K$14:$K$204,$E$14:$E$204,$C220,$C$14:$C$204,المدخلات!$AC$10) -> 0 | H220: =SUMIFS($K$14:$K$204,$E$14:$E$204,$C220,$C$14:$C$204,المدخلات!$AC$11) -> 0 | I220: =SUMIFS($K$14:$K$204,$E$14:$E$204,$C220,$C$14:$C$204,المدخلات!$AC$12) -> 0 | J220: =MAX($E220:$I220) -> 0 | K220: =SUMIFS($G$14:$G$204,$E$14:$E$204,$C220,$G$14:$G$204,">="&الحد_الأدنى) -> 0 | L220: =IF($K220=0,"غير مكتملة","مكتملة") -> غير مكتملة
B221: الرياض | C221: مجموعة المجمعة | D221: =IFERROR(INDEX('عدد اللاعبين'!$F$3:$F$193,MATCH($C221,'عدد اللاعبين'!$D$3:$D$193,0)),"") | E221: =MAX(SUMIFS($K$14:$K$204,$E$14:$E$204,$C221,$C$14:$C$204,المدخلات!$AC$6),SUMIFS($K$14:$K$204,$E$14:$E$204,$C221,$C$14:$C$204,المدخلات!$AC$7),SUMIFS($K$14:$K$204,$E$14:$E$204,$C221,$C$14:$C$204,المدخلات!$AC$8)) -> 0 | F221: =SUMIFS($K$14:$K$204,$E$14:$E$204,$C221,$C$14:$C$204,المدخلات!$AC$9) -> 0 | G221: =SUMIFS($K$14:$K$204,$E$14:$E$204,$C221,$C$14:$C$204,المدخلات!$AC$10) -> 0 | H221: =SUMIFS($K$14:$K$204,$E$14:$E$204,$C221,$C$14:$C$204,المدخلات!$AC$11) -> 0 | I221: =SUMIFS($K$14:$K$204,$E$14:$E$204,$C221,$C$14:$C$204,المدخلات!$AC$12) -> 0 | J221: =MAX($E221:$I221) -> 0 | K221: =SUMIFS($G$14:$G$204,$E$14:$E$204,$C221,$G$14:$G$204,">="&الحد_الأدنى) -> 0 | L221: =IF($K221=0,"غير مكتملة","مكتملة") -> غير مكتملة
B222: الرياض | C222: مجموعة عفيف | D222: =IFERROR(INDEX('عدد اللاعبين'!$F$3:$F$193,MATCH($C222,'عدد اللاعبين'!$D$3:$D$193,0)),"") | E222: =MAX(SUMIFS($K$14:$K$204,$E$14:$E$204,$C222,$C$14:$C$204,المدخلات!$AC$6),SUMIFS($K$14:$K$204,$E$14:$E$204,$C222,$C$14:$C$204,المدخلات!$AC$7),SUMIFS($K$14:$K$204,$E$14:$E$204,$C222,$C$14:$C$204,المدخلات!$AC$8)) -> 0 | F222: =SUMIFS($K$14:$K$204,$E$14:$E$204,$C222,$C$14:$C$204,المدخلات!$AC$9) -> 0 | G222: =SUMIFS($K$14:$K$204,$E$14:$E$204,$C222,$C$14:$C$204,المدخلات!$AC$10) -> 0 | H222: =SUMIFS($K$14:$K$204,$E$14:$E$204,$C222,$C$14:$C$204,المدخلات!$AC$11) -> 0 | I222: =SUMIFS($K$14:$K$204,$E$14:$E$204,$C222,$C$14:$C$204,المدخلات!$AC$12) -> 0 | J222: =MAX($E222:$I222) -> 0 | K222: =SUMIFS($G$14:$G$204,$E$14:$E$204,$C222,$G$14:$G$204,">="&الحد_الأدنى) -> 0 | L222: =IF($K222=0,"غير مكتملة","مكتملة") -> غير مكتملة
B223: الرياض | C223: مجموعة وادي الدواسر | D223: =IFERROR(INDEX('عدد اللاعبين'!$F$3:$F$193,MATCH($C223,'عدد اللاعبين'!$D$3:$D$193,0)),"") | E223: =MAX(SUMIFS($K$14:$K$204,$E$14:$E$204,$C223,$C$14:$C$204,المدخلات!$AC$6),SUMIFS($K$14:$K$204,$E$14:$E$204,$C223,$C$14:$C$204,المدخلات!$AC$7),SUMIFS($K$14:$K$204,$E$14:$E$204,$C223,$C$14:$C$204,المدخلات!$AC$8)) -> 0 | F223: =SUMIFS($K$14:$K$204,$E$14:$E$204,$C223,$C$14:$C$204,المدخلات!$AC$9) -> 0 | G223: =SUMIFS($K$14:$K$204,$E$14:$E$204,$C223,$C$14:$C$204,المدخلات!$AC$10) -> 0 | H223: =SUMIFS($K$14:$K$204,$E$14:$E$204,$C223,$C$14:$C$204,المدخلات!$AC$11) -> 0 | I223: =SUMIFS($K$14:$K$204,$E$14:$E$204,$C223,$C$14:$C$204,المدخلات!$AC$12) -> 0 | J223: =MAX($E223:$I223) -> 0 | K223: =SUMIFS($G$14:$G$204,$E$14:$E$204,$C223,$G$14:$G$204,">="&الحد_الأدنى) -> 0 | L223: =IF($K223=0,"غير مكتملة","مكتملة") -> غير مكتملة
... B260: نجران | C260: مجموعة نجران | D260: =IFERROR(INDEX('عدد اللاعبين'!$F$3:$F$193,MATCH($C260,'عدد اللاعبين'!$D$3:$D$193,0)),"") -> شرورة | E260: =MAX(SUMIFS($K$14:$K$204,$E$14:$E$204,$C260,$C$14:$C$204,المدخلات!$AC$6),SUMIFS($K$14:$K$204,$E$14:$E$204,$C260,$C$14:$C$204,المدخلات!$AC$7),SUMIFS($K$14:$K$204,$E$14:$E$204,$C260,$C$14:$C$204,المدخلات!$AC$8)) -> 0 | F260: =SUMIFS($K$14:$K$204,$E$14:$E$204,$C260,$C$14:$C$204,المدخلات!$AC$9) -> 0 | G260: =SUMIFS($K$14:$K$204,$E$14:$E$204,$C260,$C$14:$C$204,المدخلات!$AC$10) -> 1 | H260: =SUMIFS($K$14:$K$204,$E$14:$E$204,$C260,$C$14:$C$204,المدخلات!$AC$11) -> 1 | I260: =SUMIFS($K$14:$K$204,$E$14:$E$204,$C260,$C$14:$C$204,المدخلات!$AC$12) -> 0 | J260: =MAX($E260:$I260) -> 1 | K260: =SUMIFS($G$14:$G$204,$E$14:$E$204,$C260,$G$14:$G$204,">="&الحد_الأدنى) -> 14 | L260: =IF($K260=0,"غير مكتملة","مكتملة") -> مكتملة
...

Sheet عدد المباريات
B2: المنطقة | C2: الفئة | D2: المجموعة | E2: عدد المدن | F2: المدن | G2: عدد الفرق | H2: مجموع مباريات المجموعة
B3: =IFERROR(INDEX(المكاتب_المصدر[المنطقة],MATCH(Table10[[#This Row],[المجموعة]],المكاتب_المصدر[المجموعة],0)),"") | C3: ='ملخص المجموعات'!#REF! -> #REF! | D3: ='ملخص المجموعات'!#REF! -> #REF! | E3: =COUNTIFS(تفاصيل_الفرق[الفئة العمرية],ملخص_المجموعات[[#This Row],[الفئة]],تفاصيل_الفرق[المجموعة],ملخص_المجموعات[[#This Row],[المجموعة]],تفاصيل_الفرق[عدد الفرق],">0") -> 1 | F3: {=_xlfn.TEXTJOIN("، ",TRUE,IF((تفاصيل_الفرق[الفئة العمرية]=ملخص_المجموعات[[#This Row],[الفئة]])*(تفاصيل_الفرق[المجموعة]=ملخص_المجموعات[[#This Row],[المجموعة]])*(تفاصيل_الفرق[عدد الفرق]>0),تفاصيل_الفرق[المدينة/المحافظة],""))} -> نجران | G3: =SUMIFS(تفاصيل_الفرق[عدد الفرق],تفاصيل_الفرق[الفئة العمرية],ملخص_المجموعات[[#This Row],[الفئة]],تفاصيل_الفرق[المجموعة],ملخص_المجموعات[[#This Row],[المجموعة]]) -> 5 | H3: =IF(Table10[[#This Row],[عدد الفرق]]<الحد_الأدنى,0,Table10[[#This Row],[عدد الفرق]]*IF(OR(Table10[[#This Row],[الفئة]]="تحت 5",Table10[[#This Row],[الفئة]]="تحت 7",Table10[[#This Row],[الفئة]]="تحت 9"),المدخلات!$T$3,المدخلات!$V$3)/2) -> 0
B4: =IFERROR(INDEX(المكاتب_المصدر[المنطقة],MATCH(Table10[[#This Row],[المجموعة]],المكاتب_المصدر[المجموعة],0)),"") | C4: ='ملخص المجموعات'!#REF! -> #REF! | D4: ='ملخص المجموعات'!#REF! -> #REF! | E4: =COUNTIFS(تفاصيل_الفرق[الفئة العمرية],ملخص_المجموعات[[#This Row],[الفئة]],تفاصيل_الفرق[المجموعة],ملخص_المجموعات[[#This Row],[المجموعة]],تفاصيل_الفرق[عدد الفرق],">0") -> 1 | F4: {=_xlfn.TEXTJOIN("، ",TRUE,IF((تفاصيل_الفرق[الفئة العمرية]=ملخص_المجموعات[[#This Row],[الفئة]])*(تفاصيل_الفرق[المجموعة]=ملخص_المجموعات[[#This Row],[المجموعة]])*(تفاصيل_الفرق[عدد الفرق]>0),تفاصيل_الفرق[المدينة/المحافظة],""))} -> طبرجل | G4: =SUMIFS(تفاصيل_الفرق[عدد الفرق],تفاصيل_الفرق[الفئة العمرية],ملخص_المجموعات[[#This Row],[الفئة]],تفاصيل_الفرق[المجموعة],ملخص_المجموعات[[#This Row],[المجموعة]]) -> 5 | H4: =IF(Table10[[#This Row],[عدد الفرق]]<الحد_الأدنى,0,Table10[[#This Row],[عدد الفرق]]*IF(OR(Table10[[#This Row],[الفئة]]="تحت 5",Table10[[#This Row],[الفئة]]="تحت 7",Table10[[#This Row],[الفئة]]="تحت 9"),المدخلات!$T$3,المدخلات!$V$3)/2) -> 0
B5: =IFERROR(INDEX(المكاتب_المصدر[المنطقة],MATCH(Table10[[#This Row],[المجموعة]],المكاتب_المصدر[المجموعة],0)),"") | C5: ='ملخص المجموعات'!#REF! -> #REF! | D5: ='ملخص المجموعات'!#REF! -> #REF! | E5: =COUNTIFS(تفاصيل_الفرق[الفئة العمرية],ملخص_المجموعات[[#This Row],[الفئة]],تفاصيل_الفرق[المجموعة],ملخص_المجموعات[[#This Row],[المجموعة]],تفاصيل_الفرق[عدد الفرق],">0") -> 1 | F5: {=_xlfn.TEXTJOIN("، ",TRUE,IF((تفاصيل_الفرق[الفئة العمرية]=ملخص_المجموعات[[#This Row],[الفئة]])*(تفاصيل_الفرق[المجموعة]=ملخص_المجموعات[[#This Row],[المجموعة]])*(تفاصيل_الفرق[عدد الفرق]>0),تفاصيل_الفرق[المدينة/المحافظة],""))} -> طبرجل | G5: =SUMIFS(تفاصيل_الفرق[عدد الفرق],تفاصيل_الفرق[الفئة العمرية],ملخص_المجموعات[[#This Row],[الفئة]],تفاصيل_الفرق[المجموعة],ملخص_المجموعات[[#This Row],[المجموعة]]) -> 5 | H5: =IF(Table10[[#This Row],[عدد الفرق]]<الحد_الأدنى,0,Table10[[#This Row],[عدد الفرق]]*IF(OR(Table10[[#This Row],[الفئة]]="تحت 5",Table10[[#This Row],[الفئة]]="تحت 7",Table10[[#This Row],[الفئة]]="تحت 9"),المدخلات!$T$3,المدخلات!$V$3)/2) -> 0
B6: =IFERROR(INDEX(المكاتب_المصدر[المنطقة],MATCH(Table10[[#This Row],[المجموعة]],المكاتب_المصدر[المجموعة],0)),"") | C6: ='ملخص المجموعات'!#REF! -> #REF! | D6: ='ملخص المجموعات'!#REF! -> #REF! | E6: =COUNTIFS(تفاصيل_الفرق[الفئة العمرية],ملخص_المجموعات[[#This Row],[الفئة]],تفاصيل_الفرق[المجموعة],ملخص_المجموعات[[#This Row],[المجموعة]],تفاصيل_الفرق[عدد الفرق],">0") -> 1 | F6: {=_xlfn.TEXTJOIN("، ",TRUE,IF((تفاصيل_الفرق[الفئة العمرية]=ملخص_المجموعات[[#This Row],[الفئة]])*(تفاصيل_الفرق[المجموعة]=ملخص_المجموعات[[#This Row],[المجموعة]])*(تفاصيل_الفرق[عدد الفرق]>0),تفاصيل_الفرق[المدينة/المحافظة],""))} -> الخرج | G6: =SUMIFS(تفاصيل_الفرق[عدد الفرق],تفاصيل_الفرق[الفئة العمرية],ملخص_المجموعات[[#This Row],[الفئة]],تفاصيل_الفرق[المجموعة],ملخص_المجموعات[[#This Row],[المجموعة]]) -> 5 | H6: =IF(Table10[[#This Row],[عدد الفرق]]<الحد_الأدنى,0,Table10[[#This Row],[عدد الفرق]]*IF(OR(Table10[[#This Row],[الفئة]]="تحت 5",Table10[[#This Row],[الفئة]]="تحت 7",Table10[[#This Row],[الفئة]]="تحت 9"),المدخلات!$T$3,المدخلات!$V$3)/2) -> 0
B7: =IFERROR(INDEX(المكاتب_المصدر[المنطقة],MATCH(Table10[[#This Row],[المجموعة]],المكاتب_المصدر[المجموعة],0)),"") | C7: ='ملخص المجموعات'!#REF! -> #REF! | D7: ='ملخص المجموعات'!#REF! -> #REF! | E7: =COUNTIFS(تفاصيل_الفرق[الفئة العمرية],ملخص_المجموعات[[#This Row],[الفئة]],تفاصيل_الفرق[المجموعة],ملخص_المجموعات[[#This Row],[المجموعة]],تفاصيل_الفرق[عدد الفرق],">0") -> 1 | F7: {=_xlfn.TEXTJOIN("، ",TRUE,IF((تفاصيل_الفرق[الفئة العمرية]=ملخص_المجموعات[[#This Row],[الفئة]])*(تفاصيل_الفرق[المجموعة]=ملخص_المجموعات[[#This Row],[المجموعة]])*(تفاصيل_الفرق[عدد الفرق]>0),تفاصيل_الفرق[المدينة/المحافظة],""))} -> طبرجل | G7: =SUMIFS(تفاصيل_الفرق[عدد الفرق],تفاصيل_الفرق[الفئة العمرية],ملخص_المجموعات[[#This Row],[الفئة]],تفاصيل_الفرق[المجموعة],ملخص_المجموعات[[#This Row],[المجموعة]]) -> 5 | H7: =IF(Table10[[#This Row],[عدد الفرق]]<الحد_الأدنى,0,Table10[[#This Row],[عدد الفرق]]*IF(OR(Table10[[#This Row],[الفئة]]="تحت 5",Table10[[#This Row],[الفئة]]="تحت 7",Table10[[#This Row],[الفئة]]="تحت 9"),المدخلات!$T$3,المدخلات!$V$3)/2) -> 0
B8: =IFERROR(INDEX(المكاتب_المصدر[المنطقة],MATCH(Table10[[#This Row],[المجموعة]],المكاتب_المصدر[المجموعة],0)),"") | C8: ='ملخص المجموعات'!#REF! -> #REF! | D8: ='ملخص المجموعات'!#REF! -> #REF! | E8: =COUNTIFS(تفاصيل_الفرق[الفئة العمرية],ملخص_المجموعات[[#This Row],[الفئة]],تفاصيل_الفرق[المجموعة],ملخص_المجموعات[[#This Row],[المجموعة]],تفاصيل_الفرق[عدد الفرق],">0") -> 1 | F8: {=_xlfn.TEXTJOIN("، ",TRUE,IF((تفاصيل_الفرق[الفئة العمرية]=ملخص_المجموعات[[#This Row],[الفئة]])*(تفاصيل_الفرق[المجموعة]=ملخص_المجموعات[[#This Row],[المجموعة]])*(تفاصيل_الفرق[عدد الفرق]>0),تفاصيل_الفرق[المدينة/المحافظة],""))} -> طبرجل | G8: =SUMIFS(تفاصيل_الفرق[عدد الفرق],تفاصيل_الفرق[الفئة العمرية],ملخص_المجموعات[[#This Row],[الفئة]],تفاصيل_الفرق[المجموعة],ملخص_المجموعات[[#This Row],[المجموعة]]) -> 5 | H8: =IF(Table10[[#This Row],[عدد الفرق]]<الحد_الأدنى,0,Table10[[#This Row],[عدد الفرق]]*IF(OR(Table10[[#This Row],[الفئة]]="تحت 5",Table10[[#This Row],[الفئة]]="تحت 7",Table10[[#This Row],[الفئة]]="تحت 9"),المدخلات!$T$3,المدخلات!$V$3)/2) -> 0
B9: =IFERROR(INDEX(المكاتب_المصدر[المنطقة],MATCH(Table10[[#This Row],[المجموعة]],المكاتب_المصدر[المجموعة],0)),"") | C9: ='ملخص المجموعات'!#REF! -> #REF! | D9: ='ملخص المجموعات'!#REF! -> #REF! | E9: =COUNTIFS(تفاصيل_الفرق[الفئة العمرية],ملخص_المجموعات[[#This Row],[الفئة]],تفاصيل_الفرق[المجموعة],ملخص_المجموعات[[#This Row],[المجموعة]],تفاصيل_الفرق[عدد الفرق],">0") -> 1 | F9: {=_xlfn.TEXTJOIN("، ",TRUE,IF((تفاصيل_الفرق[الفئة العمرية]=ملخص_المجموعات[[#This Row],[الفئة]])*(تفاصيل_الفرق[المجموعة]=ملخص_المجموعات[[#This Row],[المجموعة]])*(تفاصيل_الفرق[عدد الفرق]>0),تفاصيل_الفرق[المدينة/المحافظة],""))} -> شرورة | G9: =SUMIFS(تفاصيل_الفرق[عدد الفرق],تفاصيل_الفرق[الفئة العمرية],ملخص_المجموعات[[#This Row],[الفئة]],تفاصيل_الفرق[المجموعة],ملخص_المجموعات[[#This Row],[المجموعة]]) -> 5 | H9: =IF(Table10[[#This Row],[عدد الفرق]]<الحد_الأدنى,0,Table10[[#This Row],[عدد الفرق]]*IF(OR(Table10[[#This Row],[الفئة]]="تحت 5",Table10[[#This Row],[الفئة]]="تحت 7",Table10[[#This Row],[الفئة]]="تحت 9"),المدخلات!$T$3,المدخلات!$V$3)/2) -> 0
B10: =IFERROR(INDEX(المكاتب_المصدر[المنطقة],MATCH(Table10[[#This Row],[المجموعة]],المكاتب_المصدر[المجموعة],0)),"") -> نجران | C10: ='ملخص المجموعات'!B3 -> تحت 14 | D10: ='ملخص المجموعات'!C3 -> مجموعة نجران | E10: =COUNTIFS(تفاصيل_الفرق[الفئة العمرية],ملخص_المجموعات[[#This Row],[الفئة]],تفاصيل_الفرق[المجموعة],ملخص_المجموعات[[#This Row],[المجموعة]],تفاصيل_الفرق[عدد الفرق],">0") -> 1 | F10: {=_xlfn.TEXTJOIN("، ",TRUE,IF((تفاصيل_الفرق[الفئة العمرية]=ملخص_المجموعات[[#This Row],[الفئة]])*(تفاصيل_الفرق[المجموعة]=ملخص_المجموعات[[#This Row],[المجموعة]])*(تفاصيل_الفرق[عدد الفرق]>0),تفاصيل_الفرق[المدينة/المحافظة],""))} -> شرورة | G10: =SUMIFS(تفاصيل_الفرق[عدد الفرق],تفاصيل_الفرق[الفئة العمرية],ملخص_المجموعات[[#This Row],[الفئة]],تفاصيل_الفرق[المجموعة],ملخص_المجموعات[[#This Row],[المجموعة]]) -> 5 | H10: =IF(Table10[[#This Row],[عدد الفرق]]<الحد_الأدنى,0,Table10[[#This Row],[عدد الفرق]]*IF(OR(Table10[[#This Row],[الفئة]]="تحت 5",Table10[[#This Row],[الفئة]]="تحت 7",Table10[[#This Row],[الفئة]]="تحت 9"),المدخلات!$T$3,المدخلات!$V$3)/2) -> 0
B11: =IFERROR(INDEX(المكاتب_المصدر[المنطقة],MATCH(Table10[[#This Row],[المجموعة]],المكاتب_المصدر[المجموعة],0)),"") -> الجوف | C11: ='ملخص المجموعات'!B4 -> تحت 5 | D11: ='ملخص المجموعات'!C4 -> مجموعة طبرجل | E11: =COUNTIFS(تفاصيل_الفرق[الفئة العمرية],ملخص_المجموعات[[#This Row],[الفئة]],تفاصيل_الفرق[المجموعة],ملخص_المجموعات[[#This Row],[المجموعة]],تفاصيل_الفرق[عدد الفرق],">0") -> 1 | F11: {=_xlfn.TEXTJOIN("، ",TRUE,IF((تفاصيل_الفرق[الفئة العمرية]=ملخص_المجموعات[[#This Row],[الفئة]])*(تفاصيل_الفرق[المجموعة]=ملخص_المجموعات[[#This Row],[المجموعة]])*(تفاصيل_الفرق[عدد الفرق]>0),تفاصيل_الفرق[المدينة/المحافظة],""))} -> الدوادمي | G11: =SUMIFS(تفاصيل_الفرق[عدد الفرق],تفاصيل_الفرق[الفئة العمرية],ملخص_المجموعات[[#This Row],[الفئة]],تفاصيل_الفرق[المجموعة],ملخص_المجموعات[[#This Row],[المجموعة]]) -> 5 | H11: =IF(Table10[[#This Row],[عدد الفرق]]<الحد_الأدنى,0,Table10[[#This Row],[عدد الفرق]]*IF(OR(Table10[[#This Row],[الفئة]]="تحت 5",Table10[[#This Row],[الفئة]]="تحت 7",Table10[[#This Row],[الفئة]]="تحت 9"),المدخلات!$T$3,المدخلات!$V$3)/2) -> 0
B12: =IFERROR(INDEX(المكاتب_المصدر[المنطقة],MATCH(Table10[[#This Row],[المجموعة]],المكاتب_المصدر[المجموعة],0)),"") -> الجوف | C12: ='ملخص المجموعات'!B5 -> تحت 7 | D12: ='ملخص المجموعات'!C5 -> مجموعة طبرجل | E12: =COUNTIFS(تفاصيل_الفرق[الفئة العمرية],ملخص_المجموعات[[#This Row],[الفئة]],تفاصيل_الفرق[المجموعة],ملخص_المجموعات[[#This Row],[المجموعة]],تفاصيل_الفرق[عدد الفرق],">0") -> 1 | F12: {=_xlfn.TEXTJOIN("، ",TRUE,IF((تفاصيل_الفرق[الفئة العمرية]=ملخص_المجموعات[[#This Row],[الفئة]])*(تفاصيل_الفرق[المجموعة]=ملخص_المجموعات[[#This Row],[المجموعة]])*(تفاصيل_الفرق[عدد الفرق]>0),تفاصيل_الفرق[المدينة/المحافظة],""))} -> القريات | G12: =SUMIFS(تفاصيل_الفرق[عدد الفرق],تفاصيل_الفرق[الفئة العمرية],ملخص_المجموعات[[#This Row],[الفئة]],تفاصيل_الفرق[المجموعة],ملخص_المجموعات[[#This Row],[المجموعة]]) -> 5 | H12: =IF(Table10[[#This Row],[عدد الفرق]]<الحد_الأدنى,0,Table10[[#This Row],[عدد الفرق]]*IF(OR(Table10[[#This Row],[الفئة]]="تحت 5",Table10[[#This Row],[الفئة]]="تحت 7",Table10[[#This Row],[الفئة]]="تحت 9"),المدخلات!$T$3,المدخلات!$V$3)/2) -> 0
B13: =IFERROR(INDEX(المكاتب_المصدر[المنطقة],MATCH(Table10[[#This Row],[المجموعة]],المكاتب_المصدر[المجموعة],0)),"") -> الرياض | C13: ='ملخص المجموعات'!B6 -> تحت 9 | D13: ='ملخص المجموعات'!C6 -> مجموعة الخرج | E13: =COUNTIFS(تفاصيل_الفرق[الفئة العمرية],ملخص_المجموعات[[#This Row],[الفئة]],تفاصيل_الفرق[المجموعة],ملخص_المجموعات[[#This Row],[المجموعة]],تفاصيل_الفرق[عدد الفرق],">0") -> 1 | F13: {=_xlfn.TEXTJOIN("، ",TRUE,IF((تفاصيل_الفرق[الفئة العمرية]=ملخص_المجموعات[[#This Row],[الفئة]])*(تفاصيل_الفرق[المجموعة]=ملخص_المجموعات[[#This Row],[المجموعة]])*(تفاصيل_الفرق[عدد الفرق]>0),تفاصيل_الفرق[المدينة/المحافظة],""))} -> القريات | G13: =SUMIFS(تفاصيل_الفرق[عدد الفرق],تفاصيل_الفرق[الفئة العمرية],ملخص_المجموعات[[#This Row],[الفئة]],تفاصيل_الفرق[المجموعة],ملخص_المجموعات[[#This Row],[المجموعة]]) -> 5 | H13: =IF(Table10[[#This Row],[عدد الفرق]]<الحد_الأدنى,0,Table10[[#This Row],[عدد الفرق]]*IF(OR(Table10[[#This Row],[الفئة]]="تحت 5",Table10[[#This Row],[الفئة]]="تحت 7",Table10[[#This Row],[الفئة]]="تحت 9"),المدخلات!$T$3,المدخلات!$V$3)/2) -> 0
