Workbook

Sheet المدخلات
A1: المدخلات
A3: البند | B3: القيمة
A4: وقت بداية اليوم | B4: 0.70833333
A5: مدة المباراة (دقيقة) — ثابت | B5: 15
A6: عدد المهرجانات في الموسم — ثابت | B6: 7
A7: ملاعب مصغّرة داخل الملعب القانوني — ثابت | B7: 4

Sheet المبادئ
A1: مبادئ بناء جداول المجموعات (من 6 إلى 30 فريقاً)
A3: # | B3: المبدأ | C3: الشرح
A4: 1 | B4: لا يلعب الفريق مباراتين ورا بعض | C4: القاعدة الأهم في التصميم: يحصل كل فريق على فترة راحة كاملة (15 دقيقة) بين مباراتيه على الأقل. ويُحقّق ذلك إما بحجز فترات استراحة كاملة (في الأعداد الصغيرة مثل 6 و‏7 و‏8 و‏9) أو بتوزيع الفرق على فترات أكثر (في الأعداد الكبيرة).
A5: 2 | B5: لا يوجد تتابع إطلاقاً | C5: التتابع صفر في جميع البطولات بلا استثناء، وتحقق ذلك بإطالة اليوم بحسب الحاجة: 7 فترات (6 و‏8 فرق)، و‏9 فترات (7 و‏9 و‏13 و‏17 و‏22 و‏30)، و‏10 فترات (19)، و‏11 فترة (12 و‏18). القاعدة: إذا ضاقت الفترات عن عدد المباريات المطلوبة، يُطال اليوم ولا يُضحّى براحة اللاعبين.
A6: 3 | B6: عدالة عدد المباريات | C6: كل الفرق تلعب العدد نفسه في اليوم الواحد وفي البطولة ككل — لا فريق يلعب أكثر من آخر.
A7: 4 | B7: عدالة المواجهات | C7: المقصود أن تُوزّع فرص اللقاء على الجميع لا أن تتكرر بين فرق معيّنة. يُقسم إجمالي المباريات على عدد الأزواج الممكنة، والناتج غالباً ليس عدداً صحيحاً، فيُسمح بمستويين فقط وفرقهما مباراة واحدة. مثال: في 6 فرق الأزواج الممكنة 15 زوجاً والمباريات 84، أي 5.6 لقاء للزوج ← بعض الأزواج يلتقي 5 مرات وبعضها 6، ولا يجوز أن يلتقي زوج 8 مرات وآخر مرتين. وكلما زاد عدد الفرق قلّ التكرار الطبيعي (في 13 فريقاً: 2–3 لقاءات للزوج)، وتبقى القاعدة نفسها. ملاحظة: العدالة محسوبة على مستوى الموسم ككل، ولا يتكرر لقاء الزوج نفسه داخل المهرجان الواحد إطلاقاً.
A8: 5 | B8: تقسيم المجموعات عند الأعداد الكبيرة | C8: إذا كبر عدد الفرق حتى لم تكفِ مباريات الموسم للقاء الجميع بعدل، يُقسم العدد إلى مجموعات تلعب كل منها على ملاعبها الخاصة في نفس الوقت. مثال: 30 فريقًا في مجموعة واحدة = 0.97 دورة (بعض الفرق لا تتقابل أبدًا)، أما التقسيم المعتمد هنا (13 + 9 + 8 على 12 ملعبًا مصغّرًا) فيُعطي داخل كل مجموعة توزيعًا عادلًا في الحد الأمثل: 2–3 لقاءات للزوج في أ (13 فريقًا)، و‏3–4 في ب (9)، و‏4 في ج (8). ومثله في 17 فريقًا (9 + 8) و‏18 (9 + 9) و‏19 (13 + 6).
A9: 6 | B9: اكتمال الدورة قبل التكرار | C9: يلتقي كل فريق بجميع خصومه في مجموعته مرة واحدة قبل أن يتكرر أي لقاء. الترتيب مبني على دورات كاملة متتالية: تُستوفى كل أزواج المجموعة، ثم تبدأ الدورة التالية. مثال: في 9 فرق تكتمل الدورة الأولى (36 لقاءً) بنهاية المهرجان الثاني، وأول تكرار في المهرجان الثالث. وفي 22 فريقاً تكتمل الدورة (231 لقاءً) بنهاية المهرجان السادس. والدورة الأخيرة قد تكون جزئية، فينتج الفارق المسموح (لقاء واحد) بين الأزواج. استثناء: في 7 فرق تُقدَّم راحة اللاعبين على هذا الشرط، فتكتمل الدورة داخل المهرجان الثاني نفسه لكن قد يبدأ التكرار في وقت أبكر من اليوم — لأن الالتزام الصارم بالترتيب كان سيفرض فترات انتظار 45 دقيقة.

Sheet ملخص البطولات
A1: ملخص جداول المجموعات
A3: عدد الفرق | B3: عدد المجموعات | C3: توزيع الفرق في المجموعات | D3: لقاءات كل خصم | E3: مباريات كل فريق في الموسم | F3: مباريات كل فريق في المهرجان | G3: وقت البداية | H3: وقت النهاية | I3: مدة اليوم | J3: عدد الملاعب (5 ضد 5) | K3: عدد الملاعب القانونية
A4: 6 | B4: 1 | C4: 6 | D4: =IF('6 فرق'!$B$63='6 فرق'!$B$64,'6 فرق'!$B$63&"",'6 فرق'!$B$63&_xlfn.UNICHAR(8206)&"–"&_xlfn.UNICHAR(8206)&'6 فرق'!$B$64) -> 5‎–‎6 | E4: =SUM('6 فرق'!F4:F52)*2/A4 -> 28 | F4: =E4/المدخلات!$B$6 -> 4 | G4: =المدخلات!$B$4 -> 0.70833333 | H4: =G4+I4 -> 0.78125 | I4: =COUNTA('6 فرق'!B4:'6 فرق'!B10)*المدخلات!$B$5/1440 -> 0.072916667 | J4: =COUNTIF('6 فرق'!C3:H3,"ملعب *") -> 3 | K4: =ROUNDUP(J4/المدخلات!$B$7,0) -> 1
A5: 7 | B5: 1 | C5: 7 | D5: =IF('7 فرق'!$B$78='7 فرق'!$B$79,'7 فرق'!$B$78&"",'7 فرق'!$B$78&_xlfn.UNICHAR(8206)&"–"&_xlfn.UNICHAR(8206)&'7 فرق'!$B$79) -> 4‎–‎5 | E5: =SUM('7 فرق'!F4:'7 فرق'!F66)*2/A5 -> 28 | F5: =E5/المدخلات!$B$6 -> 4 | G5: =المدخلات!$B$4 -> 0.70833333 | H5: =G5+I5 -> 0.80208333 | I5: =COUNTA('7 فرق'!B4:'7 فرق'!B12)*المدخلات!$B$5/1440 -> 0.09375 | J5: =COUNTIF('7 فرق'!C3:E3,"ملعب *") -> 3 | K5: =ROUNDUP(J5/المدخلات!$B$7,0) -> 1
A6: 8 | B6: 1 | C6: 8 | D6: =IF('8 فرق'!$B$65='8 فرق'!$B$66,'8 فرق'!$B$65&"",'8 فرق'!$B$65&_xlfn.UNICHAR(8206)&"–"&_xlfn.UNICHAR(8206)&'8 فرق'!$B$66) -> 4 | E6: =SUM('8 فرق'!G4:G52)*2/A6 -> 28 | F6: =E6/المدخلات!$B$6 -> 4 | G6: =المدخلات!$B$4 -> 0.70833333 | H6: =G6+I6 -> 0.78125 | I6: =COUNTA('8 فرق'!B4:'8 فرق'!B10)*المدخلات!$B$5/1440 -> 0.072916667 | J6: =COUNTIF('8 فرق'!C3:H3,"ملعب *") -> 4 | K6: =ROUNDUP(J6/المدخلات!$B$7,0) -> 1
A7: 9 | B7: 1 | C7: 9 | D7: =IF('9 فرق'!$B$80='9 فرق'!$B$81,'9 فرق'!$B$80&"",'9 فرق'!$B$80&_xlfn.UNICHAR(8206)&"–"&_xlfn.UNICHAR(8206)&'9 فرق'!$B$81) -> 3‎–‎4 | E7: =SUM('9 فرق'!G4:'9 فرق'!G66)*2/A7 -> 28 | F7: =E7/المدخلات!$B$6 -> 4 | G7: =المدخلات!$B$4 -> 0.70833333 | H7: =G7+I7 -> 0.80208333 | I7: =COUNTA('9 فرق'!B4:'9 فرق'!B12)*المدخلات!$B$5/1440 -> 0.09375 | J7: =COUNTIF('9 فرق'!C3:F3,"ملعب *") -> 4 | K7: =ROUNDUP(J7/المدخلات!$B$7,0) -> 1
A8: 12 | B8: 1 | C8: 12 | D8: =IF('12 فريقًا'!$B$97='12 فريقًا'!$B$98,'12 فريقًا'!$B$97&"",'12 فريقًا'!$B$97&_xlfn.UNICHAR(8206)&"–"&_xlfn.UNICHAR(8206)&'12 فريقًا'!$B$98) -> 2‎–‎3 | E8: =SUM('12 فريقًا'!F4:'12 فريقًا'!F80)*2/A8 -> 28 | F8: =E8/المدخلات!$B$6 -> 4 | G8: =المدخلات!$B$4 -> 0.70833333 | H8: =G8+I8 -> 0.82291667 | I8: =COUNTA('12 فريقًا'!B4:'12 فريقًا'!B14)*المدخلات!$B$5/1440 -> 0.11458333 | J8: =COUNTIF('12 فريقًا'!C3:E3,"ملعب *") -> 3 | K8: =ROUNDUP(J8/المدخلات!$B$7,0) -> 1
A9: 13 | B9: 1 | C9: 13 | D9: =IF('13 فريقًا'!$B$84='13 فريقًا'!$B$85,'13 فريقًا'!$B$84&"",'13 فريقًا'!$B$84&_xlfn.UNICHAR(8206)&"–"&_xlfn.UNICHAR(8206)&'13 فريقًا'!$B$85) -> 2‎–‎3 | E9: =SUM('13 فريقًا'!G4:'13 فريقًا'!G66)*2/A9 -> 28 | F9: =E9/المدخلات!$B$6 -> 4 | G9: =المدخلات!$B$4 -> 0.70833333 | H9: =G9+I9 -> 0.80208333 | I9: =COUNTA('13 فريقًا'!B4:'13 فريقًا'!B12)*المدخلات!$B$5/1440 -> 0.09375 | J9: =COUNTIF('13 فريقًا'!C3:F3,"ملعب *") -> 4 | K9: =ROUNDUP(J9/المدخلات!$B$7,0) -> 1
A10: 17 | B10: 2 | C10: 9‎ + ‎8 | D10: ='17 فريقًا'!$B$88&_xlfn.UNICHAR(8206)&" + "&_xlfn.UNICHAR(8206)&'17 فريقًا'!$B$89 -> 3‎–‎4‎ + ‎4 | E10: =SUM('17 فريقًا'!K4:'17 فريقًا'!K66)*2/A10 -> 28 | F10: =E10/المدخلات!$B$6 -> 4 | G10: =المدخلات!$B$4 -> 0.70833333 | H10: =G10+I10 -> 0.80208333 | I10: =COUNTA('17 فريقًا'!B4:'17 فريقًا'!B12)*المدخلات!$B$5/1440 -> 0.09375 | J10: =COUNTIF('17 فريقًا'!C3:J3,"ملعب *") -> 8 | K10: =ROUNDUP(J10/المدخلات!$B$7,0) -> 2
A11: 18 | B11: 2 | C11: 9‎ + ‎9 | D11: =IF('18 فريقًا'!$B$103='18 فريقًا'!$B$104,'18 فريقًا'!$B$103&"",'18 فريقًا'!$B$103&_xlfn.UNICHAR(8206)&"–"&_xlfn.UNICHAR(8206)&'18 فريقًا'!$B$104) -> 3‎–‎4 | E11: =SUM('18 فريقًا'!G4:'18 فريقًا'!G80)*2/A11 -> 28 | F11: =E11/المدخلات!$B$6 -> 4 | G11: =المدخلات!$B$4 -> 0.70833333 | H11: =G11+I11 -> 0.82291667 | I11: =COUNTA('18 فريقًا'!B4:'18 فريقًا'!B14)*المدخلات!$B$5/1440 -> 0.11458333 | J11: =COUNTIF('18 فريقًا'!C3:F3,"ملعب *") -> 4 | K11: =ROUNDUP(J11/المدخلات!$B$7,0) -> 1
A12: 19 | B12: 2 | C12: 13‎ + ‎6 | D12: ='19 فريقًا'!$B$97&_xlfn.UNICHAR(8206)&" + "&_xlfn.UNICHAR(8206)&'19 فريقًا'!$B$98 -> 2‎–‎3‎ + ‎5‎–‎6 | E12: =SUM('19 فريقًا'!I4:'19 فريقًا'!I73)*2/A12 -> 28 | F12: =E12/المدخلات!$B$6 -> 4 | G12: =المدخلات!$B$4 -> 0.70833333 | H12: =G12+I12 -> 0.8125 | I12: =COUNTA('19 فريقًا'!B4:'19 فريقًا'!B13)*المدخلات!$B$5/1440 -> 0.10416667 | J12: =COUNTIF('19 فريقًا'!C3:H3,"ملعب *") -> 6 | K12: =ROUNDUP(J12/المدخلات!$B$7,0) -> 2
A13: 22 | B13: 1 | C13: 22 | D13: =IF('22 فريقًا'!$B$93='22 فريقًا'!$B$94,'22 فريقًا'!$B$93&"",'22 فريقًا'!$B$93&_xlfn.UNICHAR(8206)&"–"&_xlfn.UNICHAR(8206)&'22 فريقًا'!$B$94) -> 1‎–‎2 | E13: =SUM('22 فريقًا'!K4:'22 فريقًا'!K66)*2/A13 -> 28 | F13: =E13/المدخلات!$B$6 -> 4 | G13: =المدخلات!$B$4 -> 0.70833333 | H13: =G13+I13 -> 0.80208333 | I13: =COUNTA('22 فريقًا'!B4:'22 فريقًا'!B12)*المدخلات!$B$5/1440 -> 0.09375 | J13: =COUNTIF('22 فريقًا'!C3:J3,"ملعب *") -> 8 | K13: =ROUNDUP(J13/المدخلات!$B$7,0) -> 2
A14: 30 | B14: 3 | C14: 13‎ + ‎9‎ + ‎8 | D14: ='30 فريقًا'!$B$101&_xlfn.UNICHAR(8206)&" + "&_xlfn.UNICHAR(8206)&'30 فريقًا'!$B$102&_xlfn.UNICHAR(8206)&" + "&_xlfn.UNICHAR(8206)&'30 فريقًا'!$B$103 -> 2‎–‎3‎ + ‎3‎–‎4‎ + ‎4 | E14: =SUM('30 فريقًا'!O4:'30 فريقًا'!O66)*2/A14 -> 28 | F14: =E14/المدخلات!$B$6 -> 4 | G14: =المدخلات!$B$4 -> 0.70833333 | H14: =G14+I14 -> 0.80208333 | I14: =COUNTA('30 فريقًا'!B4:'30 فريقًا'!B12)*المدخلات!$B$5/1440 -> 0.09375 | J14: =COUNTIF('30 فريقًا'!C3:N3,"ملعب *") -> 12 | K14: =ROUNDUP(J14/المدخلات!$B$7,0) -> 3
A17: توزيع فترات الراحة بين مباراتي الفريق في المهرجان الواحد
A18: عدد الفرق | B18: راحة 15 دقيقة | C18: راحة 30 دقيقة | D18: راحة 45 دقيقة | E18: إجمالي فترات الراحة | F18: نسبة الراحة القصيرة | G18: إجمالي متوقع (تحقق) | H18: المطابقة
A19: 6 | B19: 126 | C19: 0 | D19: 0 | E19: =B19+C19+D19 -> 126 | F19: =B19/E19 -> 1 | G19: =A19*(F4-1)*المدخلات!$B$6 -> 126 | H19: =IF(E19=G19,"مطابق","غير مطابق") -> مطابق
A20: 7 | B20: 105 | C20: 42 | D20: 0 | E20: =B20+C20+D20 -> 147 | F20: =B20/E20 -> 0.71428571 | G20: =A20*(F5-1)*المدخلات!$B$6 -> 147 | H20: =IF(E20=G20,"مطابق","غير مطابق") -> مطابق
A21: 8 | B21: 168 | C21: 0 | D21: 0 | E21: =B21+C21+D21 -> 168 | F21: =B21/E21 -> 1 | G21: =A21*(F6-1)*المدخلات!$B$6 -> 168 | H21: =IF(E21=G21,"مطابق","غير مطابق") -> مطابق
A22: 9 | B22: 141 | C22: 48 | D22: 0 | E22: =B22+C22+D22 -> 189 | F22: =B22/E22 -> 0.74603175 | G22: =A22*(F7-1)*المدخلات!$B$6 -> 189 | H22: =IF(E22=G22,"مطابق","غير مطابق") -> مطابق
A23: 12 | B23: 168 | C23: 84 | D23: 0 | E23: =B23+C23+D23 -> 252 | F23: =B23/E23 -> 0.66666667 | G23: =A23*(F8-1)*المدخلات!$B$6 -> 252 | H23: =IF(E23=G23,"مطابق","غير مطابق") -> مطابق
A24: 13 | B24: 183 | C24: 90 | D24: 0 | E24: =B24+C24+D24 -> 273 | F24: =B24/E24 -> 0.67032967 | G24: =A24*(F9-1)*المدخلات!$B$6 -> 273 | H24: =IF(E24=G24,"مطابق","غير مطابق") -> مطابق
A25: 17 | B25: 309 | C25: 48 | D25: 0 | E25: =B25+C25+D25 -> 357 | F25: =B25/E25 -> 0.86554622 | G25: =A25*(F10-1)*المدخلات!$B$6 -> 357 | H25: =IF(E25=G25,"مطابق","غير مطابق") -> مطابق
A26: 18 | B26: 272 | C26: 106 | D26: 0 | E26: =B26+C26+D26 -> 378 | F26: =B26/E26 -> 0.71957672 | G26: =A26*(F11-1)*المدخلات!$B$6 -> 378 | H26: =IF(E26=G26,"مطابق","غير مطابق") -> مطابق
A27: 19 | B27: 323 | C27: 76 | D27: 0 | E27: =B27+C27+D27 -> 399 | F27: =B27/E27 -> 0.80952381 | G27: =A27*(F12-1)*المدخلات!$B$6 -> 399 | H27: =IF(E27=G27,"مطابق","غير مطابق") -> مطابق
A28: 22 | B28: 420 | C28: 42 | D28: 0 | E28: =B28+C28+D28 -> 462 | F28: =B28/E28 -> 0.90909091 | G28: =A28*(F13-1)*المدخلات!$B$6 -> 462 | H28: =IF(E28=G28,"مطابق","غير مطابق") -> مطابق
A29: 30 | B29: 492 | C29: 138 | D29: 0 | E29: =B29+C29+D29 -> 630 | F29: =B29/E29 -> 0.78095238 | G29: =A29*(F14-1)*المدخلات!$B$6 -> 630 | H29: =IF(E29=G29,"مطابق","غير مطابق") -> مطابق

Sheet 6 فرق
A1: جدول مباريات المجموعات التي فيها 6 فرق
A3: اليوم | B3: الوقت | C3: ملعب 1 | D3: ملعب 2 | E3: ملعب 3 | F3: مجموع مباريات اليوم | G3: مباريات كل فريق في اليوم
A4: اليوم 1 | B4: =MOD(HOUR((المدخلات!$B$4+0*المدخلات!$B$5/1440))-1,12)+1&":"&TEXT(MINUTE((المدخلات!$B$4+0*المدخلات!$B$5/1440)),"00")&"–"&MOD(HOUR((المدخلات!$B$4+0*المدخلات!$B$5/1440+المدخلات!$B$5/1440))-1,12)+1&":"&TEXT(MINUTE((المدخلات!$B$4+0*المدخلات!$B$5/1440+المدخلات!$B$5/1440)),"00")&IF(HOUR((المدخلات!$B$4+0*المدخلات!$B$5/1440))<12," ص"," م") -> 5:00–5:15 م | C4: 1 ضد 6 | D4: 2 ضد 5 | E4: 3 ضد 4 | F4: =COUNTIF(C4:E10,"* ضد *") -> 12 | G4: =F4*2/'ملخص البطولات'!$A$4 -> 4
B5: =MOD(HOUR((المدخلات!$B$4+1*المدخلات!$B$5/1440))-1,12)+1&":"&TEXT(MINUTE((المدخلات!$B$4+1*المدخلات!$B$5/1440)),"00")&"–"&MOD(HOUR((المدخلات!$B$4+1*المدخلات!$B$5/1440+المدخلات!$B$5/1440))-1,12)+1&":"&TEXT(MINUTE((المدخلات!$B$4+1*المدخلات!$B$5/1440+المدخلات!$B$5/1440)),"00")&IF(HOUR((المدخلات!$B$4+1*المدخلات!$B$5/1440))<12," ص"," م") -> 5:15–5:30 م | C5: استراحة (لا توجد مباريات)
B6: =MOD(HOUR((المدخلات!$B$4+2*المدخلات!$B$5/1440))-1,12)+1&":"&TEXT(MINUTE((المدخلات!$B$4+2*المدخلات!$B$5/1440)),"00")&"–"&MOD(HOUR((المدخلات!$B$4+2*المدخلات!$B$5/1440+المدخلات!$B$5/1440))-1,12)+1&":"&TEXT(MINUTE((المدخلات!$B$4+2*المدخلات!$B$5/1440+المدخلات!$B$5/1440)),"00")&IF(HOUR((المدخلات!$B$4+2*المدخلات!$B$5/1440))<12," ص"," م") -> 5:30–5:45 م | C6: 2 ضد 6 | D6: 1 ضد 3 | E6: 4 ضد 5
B7: =MOD(HOUR((المدخلات!$B$4+3*المدخلات!$B$5/1440))-1,12)+1&":"&TEXT(MINUTE((المدخلات!$B$4+3*المدخلات!$B$5/1440)),"00")&"–"&MOD(HOUR((المدخلات!$B$4+3*المدخلات!$B$5/1440+المدخلات!$B$5/1440))-1,12)+1&":"&TEXT(MINUTE((المدخلات!$B$4+3*المدخلات!$B$5/1440+المدخلات!$B$5/1440)),"00")&IF(HOUR((المدخلات!$B$4+3*المدخلات!$B$5/1440))<12," ص"," م") -> 5:45–6:00 م | C7: استراحة (لا توجد مباريات)
B8: =MOD(HOUR((المدخلات!$B$4+4*المدخلات!$B$5/1440))-1,12)+1&":"&TEXT(MINUTE((المدخلات!$B$4+4*المدخلات!$B$5/1440)),"00")&"–"&MOD(HOUR((المدخلات!$B$4+4*المدخلات!$B$5/1440+المدخلات!$B$5/1440))-1,12)+1&":"&TEXT(MINUTE((المدخلات!$B$4+4*المدخلات!$B$5/1440+المدخلات!$B$5/1440)),"00")&IF(HOUR((المدخلات!$B$4+4*المدخلات!$B$5/1440))<12," ص"," م") -> 6:00–6:15 م | C8: 3 ضد 6 | D8: 2 ضد 4 | E8: 1 ضد 5
B9: =MOD(HOUR((المدخلات!$B$4+5*المدخلات!$B$5/1440))-1,12)+1&":"&TEXT(MINUTE((المدخلات!$B$4+5*المدخلات!$B$5/1440)),"00")&"–"&MOD(HOUR((المدخلات!$B$4+5*المدخلات!$B$5/1440+المدخلات!$B$5/1440))-1,12)+1&":"&TEXT(MINUTE((المدخلات!$B$4+5*المدخلات!$B$5/1440+المدخلات!$B$5/1440)),"00")&IF(HOUR((المدخلات!$B$4+5*المدخلات!$B$5/1440))<12," ص"," م") -> 6:15–6:30 م | C9: استراحة (لا توجد مباريات)
B10: =MOD(HOUR((المدخلات!$B$4+6*المدخلات!$B$5/1440))-1,12)+1&":"&TEXT(MINUTE((المدخلات!$B$4+6*المدخلات!$B$5/1440)),"00")&"–"&MOD(HOUR((المدخلات!$B$4+6*المدخلات!$B$5/1440+المدخلات!$B$5/1440))-1,12)+1&":"&TEXT(MINUTE((المدخلات!$B$4+6*المدخلات!$B$5/1440+المدخلات!$B$5/1440)),"00")&IF(HOUR((المدخلات!$B$4+6*المدخلات!$B$5/1440))<12," ص"," م") -> 6:30–6:45 م | C10: 4 ضد 6 | D10: 3 ضد 5 | E10: 1 ضد 2
A11: اليوم 2 | B11: =MOD(HOUR((المدخلات!$B$4+0*المدخلات!$B$5/1440))-1,12)+1&":"&TEXT(MINUTE((المدخلات!$B$4+0*المدخلات!$B$5/1440)),"00")&"–"&MOD(HOUR((المدخلات!$B$4+0*المدخلات!$B$5/1440+المدخلات!$B$5/1440))-1,12)+1&":"&TEXT(MINUTE((المدخلات!$B$4+0*المدخلات!$B$5/1440+المدخلات!$B$5/1440)),"00")&IF(HOUR((المدخلات!$B$4+0*المدخلات!$B$5/1440))<12," ص"," م") -> 5:00–5:15 م | C11: 5 ضد 6 | D11: 1 ضد 4 | E11: 2 ضد 3 | F11: =COUNTIF(C11:E17,"* ضد *") -> 12 | G11: =F11*2/'ملخص البطولات'!$A$4 -> 4
B12: =MOD(HOUR((المدخلات!$B$4+1*المدخلات!$B$5/1440))-1,12)+1&":"&TEXT(MINUTE((المدخلات!$B$4+1*المدخلات!$B$5/1440)),"00")&"–"&MOD(HOUR((المدخلات!$B$4+1*المدخلات!$B$5/1440+المدخلات!$B$5/1440))-1,12)+1&":"&TEXT(MINUTE((المدخلات!$B$4+1*المدخلات!$B$5/1440+المدخلات!$B$5/1440)),"00")&IF(HOUR((المدخلات!$B$4+1*المدخلات!$B$5/1440))<12," ص"," م") -> 5:15–5:30 م | C12: استراحة (لا توجد مباريات)
B13: =MOD(HOUR((المدخلات!$B$4+2*المدخلات!$B$5/1440))-1,12)+1&":"&TEXT(MINUTE((المدخلات!$B$4+2*المدخلات!$B$5/1440)),"00")&"–"&MOD(HOUR((المدخلات!$B$4+2*المدخلات!$B$5/1440+المدخلات!$B$5/1440))-1,12)+1&":"&TEXT(MINUTE((المدخلات!$B$4+2*المدخلات!$B$5/1440+المدخلات!$B$5/1440)),"00")&IF(HOUR((المدخلات!$B$4+2*المدخلات!$B$5/1440))<12," ص"," م") -> 5:30–5:45 م | C13: 1 ضد 6 | D13: 2 ضد 5 | E13: 3 ضد 4
B14: =MOD(HOUR((المدخلات!$B$4+3*المدخلات!$B$5/1440))-1,12)+1&":"&TEXT(MINUTE((المدخلات!$B$4+3*المدخلات!$B$5/1440)),"00")&"–"&MOD(HOUR((المدخلات!$B$4+3*المدخلات!$B$5/1440+المدخلات!$B$5/1440))-1,12)+1&":"&TEXT(MINUTE((المدخلات!$B$4+3*المدخلات!$B$5/1440+المدخلات!$B$5/1440)),"00")&IF(HOUR((المدخلات!$B$4+3*المدخلات!$B$5/1440))<12," ص"," م") -> 5:45–6:00 م | C14: استراحة (لا توجد مباريات)
B15: =MOD(HOUR((المدخلات!$B$4+4*المدخلات!$B$5/1440))-1,12)+1&":"&TEXT(MINUTE((المدخلات!$B$4+4*المدخلات!$B$5/1440)),"00")&"–"&MOD(HOUR((المدخلات!$B$4+4*المدخلات!$B$5/1440+المدخلات!$B$5/1440))-1,12)+1&":"&TEXT(MINUTE((المدخلات!$B$4+4*المدخلات!$B$5/1440+المدخلات!$B$5/1440)),"00")&IF(HOUR((المدخلات!$B$4+4*المدخلات!$B$5/1440))<12," ص"," م") -> 6:00–6:15 م | C15: 2 ضد 6 | D15: 1 ضد 3 | E15: 4 ضد 5
B16: =MOD(HOUR((المدخلات!$B$4+5*المدخلات!$B$5/1440))-1,12)+1&":"&TEXT(MINUTE((المدخلات!$B$4+5*المدخلات!$B$5/1440)),"00")&"–"&MOD(HOUR((المدخلات!$B$4+5*المدخلات!$B$5/1440+المدخلات!$B$5/1440))-1,12)+1&":"&TEXT(MINUTE((المدخلات!$B$4+5*المدخلات!$B$5/1440+المدخلات!$B$5/1440)),"00")&IF(HOUR((المدخلات!$B$4+5*المدخلات!$B$5/1440))<12," ص"," م") -> 6:15–6:30 م | C16: استراحة (لا توجد مباريات)
B17: =MOD(HOUR((المدخلات!$B$4+6*المدخلات!$B$5/1440))-1,12)+1&":"&TEXT(MINUTE((المدخلات!$B$4+6*المدخلات!$B$5/1440)),"00")&"–"&MOD(HOUR((المدخلات!$B$4+6*المدخلات!$B$5/1440+المدخلات!$B$5/1440))-1,12)+1&":"&TEXT(MINUTE((المدخلات!$B$4+6*المدخلات!$B$5/1440+المدخلات!$B$5/1440)),"00")&IF(HOUR((المدخلات!$B$4+6*المدخلات!$B$5/1440))<12," ص"," م") -> 6:30–6:45 م | C17: 3 ضد 6 | D17: 2 ضد 4 | E17: 1 ضد 5
A18: اليوم 3 | B18: =MOD(HOUR((المدخلات!$B$4+0*المدخلات!$B$5/1440))-1,12)+1&":"&TEXT(MINUTE((المدخلات!$B$4+0*المدخلات!$B$5/1440)),"00")&"–"&MOD(HOUR((المدخلات!$B$4+0*المدخلات!$B$5/1440+المدخلات!$B$5/1440))-1,12)+1&":"&TEXT(MINUTE((المدخلات!$B$4+0*المدخلات!$B$5/1440+المدخلات!$B$5/1440)),"00")&IF(HOUR((المدخلات!$B$4+0*المدخلات!$B$5/1440))<12," ص"," م") -> 5:00–5:15 م | C18: 4 ضد 6 | D18: 3 ضد 5 | E18: 1 ضد 2 | F18: =COUNTIF(C18:E24,"* ضد *") -> 12 | G18: =F18*2/'ملخص البطولات'!$A$4 -> 4
B19: =MOD(HOUR((المدخلات!$B$4+1*المدخلات!$B$5/1440))-1,12)+1&":"&TEXT(MINUTE((المدخلات!$B$4+1*المدخلات!$B$5/1440)),"00")&"–"&MOD(HOUR((المدخلات!$B$4+1*المدخلات!$B$5/1440+المدخلات!$B$5/1440))-1,12)+1&":"&TEXT(MINUTE((المدخلات!$B$4+1*المدخلات!$B$5/1440+المدخلات!$B$5/1440)),"00")&IF(HOUR((المدخلات!$B$4+1*المدخلات!$B$5/1440))<12," ص"," م") -> 5:15–5:30 م | C19: استراحة (لا توجد مباريات)
B20: =MOD(HOUR((المدخلات!$B$4+2*المدخلات!$B$5/1440))-1,12)+1&":"&TEXT(MINUTE((المدخلات!$B$4+2*المدخلات!$B$5/1440)),"00")&"–"&MOD(HOUR((المدخلات!$B$4+2*المدخلات!$B$5/1440+المدخلات!$B$5/1440))-1,12)+1&":"&TEXT(MINUTE((المدخلات!$B$4+2*المدخلات!$B$5/1440+المدخلات!$B$5/1440)),"00")&IF(HOUR((المدخلات!$B$4+2*المدخلات!$B$5/1440))<12," ص"," م") -> 5:30–5:45 م | C20: 5 ضد 6 | D20: 1 ضد 4 | E20: 2 ضد 3
B21: =MOD(HOUR((المدخلات!$B$4+3*المدخلات!$B$5/1440))-1,12)+1&":"&TEXT(MINUTE((المدخلات!$B$4+3*المدخلات!$B$5/1440)),"00")&"–"&MOD(HOUR((المدخلات!$B$4+3*المدخلات!$B$5/1440+المدخلات!$B$5/1440))-1,12)+1&":"&TEXT(MINUTE((المدخلات!$B$4+3*المدخلات!$B$5/1440+المدخلات!$B$5/1440)),"00")&IF(HOUR((المدخلات!$B$4+3*المدخلات!$B$5/1440))<12," ص"," م") -> 5:45–6:00 م | C21: استراحة (لا توجد مباريات)
B22: =MOD(HOUR((المدخلات!$B$4+4*المدخلات!$B$5/1440))-1,12)+1&":"&TEXT(MINUTE((المدخلات!$B$4+4*المدخلات!$B$5/1440)),"00")&"–"&MOD(HOUR((المدخلات!$B$4+4*المدخلات!$B$5/1440+المدخلات!$B$5/1440))-1,12)+1&":"&TEXT(MINUTE((المدخلات!$B$4+4*المدخلات!$B$5/1440+المدخلات!$B$5/1440)),"00")&IF(HOUR((المدخلات!$B$4+4*المدخلات!$B$5/1440))<12," ص"," م") -> 6:00–6:15 م | C22: 1 ضد 6 | D22: 2 ضد 5 | E22: 3 ضد 4
B23: =MOD(HOUR((المدخلات!$B$4+5*المدخلات!$B$5/1440))-1,12)+1&":"&TEXT(MINUTE((المدخلات!$B$4+5*المدخلات!$B$5/1440)),"00")&"–"&MOD(HOUR((المدخلات!$B$4+5*المدخلات!$B$5/1440+المدخلات!$B$5/1440))-1,12)+1&":"&TEXT(MINUTE((المدخلات!$B$4+5*المدخلات!$B$5/1440+المدخلات!$B$5/1440)),"00")&IF(HOUR((المدخلات!$B$4+5*المدخلات!$B$5/1440))<12," ص"," م") -> 6:15–6:30 م | C23: استراحة (لا توجد مباريات)
B24: =MOD(HOUR((المدخلات!$B$4+6*المدخلات!$B$5/1440))-1,12)+1&":"&TEXT(MINUTE((المدخلات!$B$4+6*المدخلات!$B$5/1440)),"00")&"–"&MOD(HOUR((المدخلات!$B$4+6*المدخلات!$B$5/1440+المدخلات!$B$5/1440))-1,12)+1&":"&TEXT(MINUTE((المدخلات!$B$4+6*المدخلات!$B$5/1440+المدخلات!$B$5/1440)),"00")&IF(HOUR((المدخلات!$B$4+6*المدخلات!$B$5/1440))<12," ص"," م") -> 6:30–6:45 م | C24: 2 ضد 6 | D24: 1 ضد 3 | E24: 4 ضد 5
A25: اليوم 4 | B25: =MOD(HOUR((المدخلات!$B$4+0*المدخلات!$B$5/1440))-1,12)+1&":"&TEXT(MINUTE((المدخلات!$B$4+0*المدخلات!$B$5/1440)),"00")&"–"&MOD(HOUR((المدخلات!$B$4+0*المدخلات!$B$5/1440+المدخلات!$B$5/1440))-1,12)+1&":"&TEXT(MINUTE((المدخلات!$B$4+0*المدخلات!$B$5/1440+المدخلات!$B$5/1440)),"00")&IF(HOUR((المدخلات!$B$4+0*المدخلات!$B$5/1440))<12," ص"," م") -> 5:00–5:15 م | C25: 3 ضد 6 | D25: 2 ضد 4 | E25: 1 ضد 5 | F25: =COUNTIF(C25:E31,"* ضد *") -> 12 | G25: =F25*2/'ملخص البطولات'!$A$4 -> 4
B26: =MOD(HOUR((المدخلات!$B$4+1*المدخلات!$B$5/1440))-1,12)+1&":"&TEXT(MINUTE((المدخلات!$B$4+1*المدخلات!$B$5/1440)),"00")&"–"&MOD(HOUR((المدخلات!$B$4+1*المدخلات!$B$5/1440+المدخلات!$B$5/1440))-1,12)+1&":"&TEXT(MINUTE((المدخلات!$B$4+1*المدخلات!$B$5/1440+المدخلات!$B$5/1440)),"00")&IF(HOUR((المدخلات!$B$4+1*المدخلات!$B$5/1440))<12," ص"," م") -> 5:15–5:30 م | C26: استراحة (لا توجد مباريات)
B27: =MOD(HOUR((المدخلات!$B$4+2*المدخلات!$B$5/1440))-1,12)+1&":"&TEXT(MINUTE((المدخلات!$B$4+2*المدخلات!$B$5/1440)),"00")&"–"&MOD(HOUR((المدخلات!$B$4+2*المدخلات!$B$5/1440+المدخلات!$B$5/1440))-1,12)+1&":"&TEXT(MINUTE((المدخلات!$B$4+2*المدخلات!$B$5/1440+المدخلات!$B$5/1440)),"00")&IF(HOUR((المدخلات!$B$4+2*المدخلات!$B$5/1440))<12," ص"," م") -> 5:30–5:45 م | C27: 4 ضد 6 | D27: 3 ضد 5 | E27: 1 ضد 2
B28: =MOD(HOUR((المدخلات!$B$4+3*المدخلات!$B$5/1440))-1,12)+1&":"&TEXT(MINUTE((المدخلات!$B$4+3*المدخلات!$B$5/1440)),"00")&"–"&MOD(HOUR((المدخلات!$B$4+3*المدخلات!$B$5/1440+المدخلات!$B$5/1440))-1,12)+1&":"&TEXT(MINUTE((المدخلات!$B$4+3*المدخلات!$B$5/1440+المدخلات!$B$5/1440)),"00")&IF(HOUR((المدخلات!$B$4+3*المدخلات!$B$5/1440))<12," ص"," م") -> 5:45–6:00 م | C28: استراحة (لا توجد مباريات)
B29: =MOD(HOUR((المدخلات!$B$4+4*المدخلات!$B$5/1440))-1,12)+1&":"&TEXT(MINUTE((المدخلات!$B$4+4*المدخلات!$B$5/1440)),"00")&"–"&MOD(HOUR((المدخلات!$B$4+4*المدخلات!$B$5/1440+المدخلات!$B$5/1440))-1,12)+1&":"&TEXT(MINUTE((المدخلات!$B$4+4*المدخلات!$B$5/1440+المدخلات!$B$5/1440)),"00")&IF(HOUR((المدخلات!$B$4+4*المدخلات!$B$5/1440))<12," ص"," م") -> 6:00–6:15 م | C29: 5 ضد 6 | D29: 1 ضد 4 | E29: 2 ضد 3
B30: =MOD(HOUR((المدخلات!$B$4+5*المدخلات!$B$5/1440))-1,12)+1&":"&TEXT(MINUTE((المدخلات!$B$4+5*المدخلات!$B$5/1440)),"00")&"–"&MOD(HOUR((المدخلات!$B$4+5*المدخلات!$B$5/1440+المدخلات!$B$5/1440))-1,12)+1&":"&TEXT(MINUTE((المدخلات!$B$4+5*المدخلات!$B$5/1440+المدخلات!$B$5/1440)),"00")&IF(HOUR((المدخلات!$B$4+5*المدخلات!$B$5/1440))<12," ص"," م") -> 6:15–6:30 م | C30: استراحة (لا توجد مباريات)
B31: =MOD(HOUR((المدخلات!$B$4+6*المدخلات!$B$5/1440))-1,12)+1&":"&TEXT(MINUTE((المدخلات!$B$4+6*المدخلات!$B$5/1440)),"00")&"–"&MOD(HOUR((المدخلات!$B$4+6*المدخلات!$B$5/1440+المدخلات!$B$5/1440))-1,12)+1&":"&TEXT(MINUTE((المدخلات!$B$4+6*المدخلات!$B$5/1440+المدخلات!$B$5/1440)),"00")&IF(HOUR((المدخلات!$B$4+6*المدخلات!$B$5/1440))<12," ص"," م") -> 6:30–6:45 م | C31: 1 ضد 6 | D31: 2 ضد 5 | E31: 3 ضد 4
A32: اليوم 5 | B32: =MOD(HOUR((المدخلات!$B$4+0*المدخلات!$B$5/1440))-1,12)+1&":"&TEXT(MINUTE((المدخلات!$B$4+0*المدخلات!$B$5/1440)),"00")&"–"&MOD(HOUR((المدخلات!$B$4+0*المدخلات!$B$5/1440+المدخلات!$B$5/1440))-1,12)+1&":"&TEXT(MINUTE((المدخلات!$B$4+0*المدخلات!$B$5/1440+المدخلات!$B$5/1440)),"00")&IF(HOUR((المدخلات!$B$4+0*المدخلات!$B$5/1440))<12," ص"," م") -> 5:00–5:15 م | C32: 2 ضد 6 | D32: 1 ضد 3 | E32: 4 ضد 5 | F32: =COUNTIF(C32:E38,"* ضد *") -> 12 | G32: =F32*2/'ملخص البطولات'!$A$4 -> 4
B33: =MOD(HOUR((المدخلات!$B$4+1*المدخلات!$B$5/1440))-1,12)+1&":"&TEXT(MINUTE((المدخلات!$B$4+1*المدخلات!$B$5/1440)),"00")&"–"&MOD(HOUR((المدخلات!$B$4+1*المدخلات!$B$5/1440+المدخلات!$B$5/1440))-1,12)+1&":"&TEXT(MINUTE((المدخلات!$B$4+1*المدخلات!$B$5/1440+المدخلات!$B$5/1440)),"00")&IF(HOUR((المدخلات!$B$4+1*المدخلات!$B$5/1440))<12," ص"," م") -> 5:15–5:30 م | C33: استراحة (لا توجد مباريات)
B34: =MOD(HOUR((المدخلات!$B$4+2*المدخلات!$B$5/1440))-1,12)+1&":"&TEXT(MINUTE((المدخلات!$B$4+2*المدخلات!$B$5/1440)),"00")&"–"&MOD(HOUR((المدخلات!$B$4+2*المدخلات!$B$5/1440+المدخلات!$B$5/1440))-1,12)+1&":"&TEXT(MINUTE((المدخلات!$B$4+2*المدخلات!$B$5/1440+المدخلات!$B$5/1440)),"00")&IF(HOUR((المدخلات!$B$4+2*المدخلات!$B$5/1440))<12," ص"," م") -> 5:30–5:45 م | C34: 3 ضد 6 | D34: 2 ضد 4 | E34: 1 ضد 5
B35: =MOD(HOUR((المدخلات!$B$4+3*المدخلات!$B$5/1440))-1,12)+1&":"&TEXT(MINUTE((المدخلات!$B$4+3*المدخلات!$B$5/1440)),"00")&"–"&MOD(HOUR((المدخلات!$B$4+3*المدخلات!$B$5/1440+المدخلات!$B$5/1440))-1,12)+1&":"&TEXT(MINUTE((المدخلات!$B$4+3*المدخلات!$B$5/1440+المدخلات!$B$5/1440)),"00")&IF(HOUR((المدخلات!$B$4+3*المدخلات!$B$5/1440))<12," ص"," م") -> 5:45–6:00 م | C35: استراحة (لا توجد مباريات)
B36: =MOD(HOUR((المدخلات!$B$4+4*المدخلات!$B$5/1440))-1,12)+1&":"&TEXT(MINUTE((المدخلات!$B$4+4*المدخلات!$B$5/1440)),"00")&"–"&MOD(HOUR((المدخلات!$B$4+4*المدخلات!$B$5/1440+المدخلات!$B$5/1440))-1,12)+1&":"&TEXT(MINUTE((المدخلات!$B$4+4*المدخلات!$B$5/1440+المدخلات!$B$5/1440)),"00")&IF(HOUR((المدخلات!$B$4+4*المدخلات!$B$5/1440))<12," ص"," م") -> 6:00–6:15 م | C36: 4 ضد 6 | D36: 3 ضد 5 | E36: 1 ضد 2
B37: =MOD(HOUR((المدخلات!$B$4+5*المدخلات!$B$5/1440))-1,12)+1&":"&TEXT(MINUTE((المدخلات!$B$4+5*المدخلات!$B$5/1440)),"00")&"–"&MOD(HOUR((المدخلات!$B$4+5*المدخلات!$B$5/1440+المدخلات!$B$5/1440))-1,12)+1&":"&TEXT(MINUTE((المدخلات!$B$4+5*المدخلات!$B$5/1440+المدخلات!$B$5/1440)),"00")&IF(HOUR((المدخلات!$B$4+5*المدخلات!$B$5/1440))<12," ص"," م") -> 6:15–6:30 م | C37: استراحة (لا توجد مباريات)
B38: =MOD(HOUR((المدخلات!$B$4+6*المدخلات!$B$5/1440))-1,12)+1&":"&TEXT(MINUTE((المدخلات!$B$4+6*المدخلات!$B$5/1440)),"00")&"–"&MOD(HOUR((المدخلات!$B$4+6*المدخلات!$B$5/1440+المدخلات!$B$5/1440))-1,12)+1&":"&TEXT(MINUTE((المدخلات!$B$4+6*المدخلات!$B$5/1440+المدخلات!$B$5/1440)),"00")&IF(HOUR((المدخلات!$B$4+6*المدخلات!$B$5/1440))<12," ص"," م") -> 6:30–6:45 م | C38: 5 ضد 6 | D38: 1 ضد 4 | E38: 2 ضد 3
A39: اليوم 6 | B39: =MOD(HOUR((المدخلات!$B$4+0*المدخلات!$B$5/1440))-1,12)+1&":"&TEXT(MINUTE((المدخلات!$B$4+0*المدخلات!$B$5/1440)),"00")&"–"&MOD(HOUR((المدخلات!$B$4+0*المدخلات!$B$5/1440+المدخلات!$B$5/1440))-1,12)+1&":"&TEXT(MINUTE((المدخلات!$B$4+0*المدخلات!$B$5/1440+المدخلات!$B$5/1440)),"00")&IF(HOUR((المدخلات!$B$4+0*المدخلات!$B$5/1440))<12," ص"," م") -> 5:00–5:15 م | C39: 1 ضد 6 | D39: 2 ضد 5 | E39: 3 ضد 4 | F39: =COUNTIF(C39:E45,"* ضد *") -> 12 | G39: =F39*2/'ملخص البطولات'!$A$4 -> 4
B40: =MOD(HOUR((المدخلات!$B$4+1*المدخلات!$B$5/1440))-1,12)+1&":"&TEXT(MINUTE((المدخلات!$B$4+1*المدخلات!$B$5/1440)),"00")&"–"&MOD(HOUR((المدخلات!$B$4+1*المدخلات!$B$5/1440+المدخلات!$B$5/1440))-1,12)+1&":"&TEXT(MINUTE((المدخلات!$B$4+1*المدخلات!$B$5/1440+المدخلات!$B$5/1440)),"00")&IF(HOUR((المدخلات!$B$4+1*المدخلات!$B$5/1440))<12," ص"," م") -> 5:15–5:30 م | C40: استراحة (لا توجد مباريات)
B41: =MOD(HOUR((المدخلات!$B$4+2*المدخلات!$B$5/1440))-1,12)+1&":"&TEXT(MINUTE((المدخلات!$B$4+2*المدخلات!$B$5/1440)),"00")&"–"&MOD(HOUR((المدخلات!$B$4+2*المدخلات!$B$5/1440+المدخلات!$B$5/1440))-1,12)+1&":"&TEXT(MINUTE((المدخلات!$B$4+2*المدخلات!$B$5/1440+المدخلات!$B$5/1440)),"00")&IF(HOUR((المدخلات!$B$4+2*المدخلات!$B$5/1440))<12," ص"," م") -> 5:30–5:45 م | C41: 2 ضد 6 | D41: 1 ضد 3 | E41: 4 ضد 5
...

Sheet 7 فرق
A1: جدول مباريات المجموعات التي فيها 7 فرق
A3: اليوم | B3: الوقت | C3: ملعب 1 | D3: ملعب 2 | E3: ملعب 3 | F3: مجموع مباريات اليوم | G3: مباريات كل فريق في اليوم
A4: اليوم 1 | B4: =MOD(HOUR((المدخلات!$B$4+0*المدخلات!$B$5/1440))-1,12)+1&":"&TEXT(MINUTE((المدخلات!$B$4+0*المدخلات!$B$5/1440)),"00")&"–"&MOD(HOUR((المدخلات!$B$4+0*المدخلات!$B$5/1440+المدخلات!$B$5/1440))-1,12)+1&":"&TEXT(MINUTE((المدخلات!$B$4+0*المدخلات!$B$5/1440+المدخلات!$B$5/1440)),"00")&IF(HOUR((المدخلات!$B$4+0*المدخلات!$B$5/1440))<12," ص"," م") -> 5:00–5:15 م | C4: 5 ضد 6 | D4: 1 ضد 3 | F4: =COUNTIF(C4:E12,"* ضد *") -> 14 | G4: =F4*2/'ملخص البطولات'!$A$5 -> 4
B5: =MOD(HOUR((المدخلات!$B$4+1*المدخلات!$B$5/1440))-1,12)+1&":"&TEXT(MINUTE((المدخلات!$B$4+1*المدخلات!$B$5/1440)),"00")&"–"&MOD(HOUR((المدخلات!$B$4+1*المدخلات!$B$5/1440+المدخلات!$B$5/1440))-1,12)+1&":"&TEXT(MINUTE((المدخلات!$B$4+1*المدخلات!$B$5/1440+المدخلات!$B$5/1440)),"00")&IF(HOUR((المدخلات!$B$4+1*المدخلات!$B$5/1440))<12," ص"," م") -> 5:15–5:30 م | C5: 2 ضد 4
B6: =MOD(HOUR((المدخلات!$B$4+2*المدخلات!$B$5/1440))-1,12)+1&":"&TEXT(MINUTE((المدخلات!$B$4+2*المدخلات!$B$5/1440)),"00")&"–"&MOD(HOUR((المدخلات!$B$4+2*المدخلات!$B$5/1440+المدخلات!$B$5/1440))-1,12)+1&":"&TEXT(MINUTE((المدخلات!$B$4+2*المدخلات!$B$5/1440+المدخلات!$B$5/1440)),"00")&IF(HOUR((المدخلات!$B$4+2*المدخلات!$B$5/1440))<12," ص"," م") -> 5:30–5:45 م | C6: 1 ضد 7 | D6: 3 ضد 5
B7: =MOD(HOUR((المدخلات!$B$4+3*المدخلات!$B$5/1440))-1,12)+1&":"&TEXT(MINUTE((المدخلات!$B$4+3*المدخلات!$B$5/1440)),"00")&"–"&MOD(HOUR((المدخلات!$B$4+3*المدخلات!$B$5/1440+المدخلات!$B$5/1440))-1,12)+1&":"&TEXT(MINUTE((المدخلات!$B$4+3*المدخلات!$B$5/1440+المدخلات!$B$5/1440)),"00")&IF(HOUR((المدخلات!$B$4+3*المدخلات!$B$5/1440))<12," ص"," م") -> 5:45–6:00 م | C7: 4 ضد 6
B8: =MOD(HOUR((المدخلات!$B$4+4*المدخلات!$B$5/1440))-1,12)+1&":"&TEXT(MINUTE((المدخلات!$B$4+4*المدخلات!$B$5/1440)),"00")&"–"&MOD(HOUR((المدخلات!$B$4+4*المدخلات!$B$5/1440+المدخلات!$B$5/1440))-1,12)+1&":"&TEXT(MINUTE((المدخلات!$B$4+4*المدخلات!$B$5/1440+المدخلات!$B$5/1440)),"00")&IF(HOUR((المدخلات!$B$4+4*المدخلات!$B$5/1440))<12," ص"," م") -> 6:00–6:15 م | C8: 1 ضد 2 | D8: 5 ضد 7
B9: =MOD(HOUR((المدخلات!$B$4+5*المدخلات!$B$5/1440))-1,12)+1&":"&TEXT(MINUTE((المدخلات!$B$4+5*المدخلات!$B$5/1440)),"00")&"–"&MOD(HOUR((المدخلات!$B$4+5*المدخلات!$B$5/1440+المدخلات!$B$5/1440))-1,12)+1&":"&TEXT(MINUTE((المدخلات!$B$4+5*المدخلات!$B$5/1440+المدخلات!$B$5/1440)),"00")&IF(HOUR((المدخلات!$B$4+5*المدخلات!$B$5/1440))<12," ص"," م") -> 6:15–6:30 م | C9: 3 ضد 4
B10: =MOD(HOUR((المدخلات!$B$4+6*المدخلات!$B$5/1440))-1,12)+1&":"&TEXT(MINUTE((المدخلات!$B$4+6*المدخلات!$B$5/1440)),"00")&"–"&MOD(HOUR((المدخلات!$B$4+6*المدخلات!$B$5/1440+المدخلات!$B$5/1440))-1,12)+1&":"&TEXT(MINUTE((المدخلات!$B$4+6*المدخلات!$B$5/1440+المدخلات!$B$5/1440)),"00")&IF(HOUR((المدخلات!$B$4+6*المدخلات!$B$5/1440))<12," ص"," م") -> 6:30–6:45 م | C10: 2 ضد 7 | D10: 1 ضد 6
B11: =MOD(HOUR((المدخلات!$B$4+7*المدخلات!$B$5/1440))-1,12)+1&":"&TEXT(MINUTE((المدخلات!$B$4+7*المدخلات!$B$5/1440)),"00")&"–"&MOD(HOUR((المدخلات!$B$4+7*المدخلات!$B$5/1440+المدخلات!$B$5/1440))-1,12)+1&":"&TEXT(MINUTE((المدخلات!$B$4+7*المدخلات!$B$5/1440+المدخلات!$B$5/1440)),"00")&IF(HOUR((المدخلات!$B$4+7*المدخلات!$B$5/1440))<12," ص"," م") -> 6:45–7:00 م | C11: 4 ضد 5
B12: =MOD(HOUR((المدخلات!$B$4+8*المدخلات!$B$5/1440))-1,12)+1&":"&TEXT(MINUTE((المدخلات!$B$4+8*المدخلات!$B$5/1440)),"00")&"–"&MOD(HOUR((المدخلات!$B$4+8*المدخلات!$B$5/1440+المدخلات!$B$5/1440))-1,12)+1&":"&TEXT(MINUTE((المدخلات!$B$4+8*المدخلات!$B$5/1440+المدخلات!$B$5/1440)),"00")&IF(HOUR((المدخلات!$B$4+8*المدخلات!$B$5/1440))<12," ص"," م") -> 7:00–7:15 م | C12: 2 ضد 3 | D12: 6 ضد 7
A13: اليوم 2 | B13: =MOD(HOUR((المدخلات!$B$4+0*المدخلات!$B$5/1440))-1,12)+1&":"&TEXT(MINUTE((المدخلات!$B$4+0*المدخلات!$B$5/1440)),"00")&"–"&MOD(HOUR((المدخلات!$B$4+0*المدخلات!$B$5/1440+المدخلات!$B$5/1440))-1,12)+1&":"&TEXT(MINUTE((المدخلات!$B$4+0*المدخلات!$B$5/1440+المدخلات!$B$5/1440)),"00")&IF(HOUR((المدخلات!$B$4+0*المدخلات!$B$5/1440))<12," ص"," م") -> 5:00–5:15 م | C13: 1 ضد 4 | D13: 2 ضد 6 | F13: =COUNTIF(C13:E21,"* ضد *") -> 14 | G13: =F13*2/'ملخص البطولات'!$A$5 -> 4
B14: =MOD(HOUR((المدخلات!$B$4+1*المدخلات!$B$5/1440))-1,12)+1&":"&TEXT(MINUTE((المدخلات!$B$4+1*المدخلات!$B$5/1440)),"00")&"–"&MOD(HOUR((المدخلات!$B$4+1*المدخلات!$B$5/1440+المدخلات!$B$5/1440))-1,12)+1&":"&TEXT(MINUTE((المدخلات!$B$4+1*المدخلات!$B$5/1440+المدخلات!$B$5/1440)),"00")&IF(HOUR((المدخلات!$B$4+1*المدخلات!$B$5/1440))<12," ص"," م") -> 5:15–5:30 م | C14: 3 ضد 7
B15: =MOD(HOUR((المدخلات!$B$4+2*المدخلات!$B$5/1440))-1,12)+1&":"&TEXT(MINUTE((المدخلات!$B$4+2*المدخلات!$B$5/1440)),"00")&"–"&MOD(HOUR((المدخلات!$B$4+2*المدخلات!$B$5/1440+المدخلات!$B$5/1440))-1,12)+1&":"&TEXT(MINUTE((المدخلات!$B$4+2*المدخلات!$B$5/1440+المدخلات!$B$5/1440)),"00")&IF(HOUR((المدخلات!$B$4+2*المدخلات!$B$5/1440))<12," ص"," م") -> 5:30–5:45 م | C15: 1 ضد 2 | D15: 4 ضد 5
B16: =MOD(HOUR((المدخلات!$B$4+3*المدخلات!$B$5/1440))-1,12)+1&":"&TEXT(MINUTE((المدخلات!$B$4+3*المدخلات!$B$5/1440)),"00")&"–"&MOD(HOUR((المدخلات!$B$4+3*المدخلات!$B$5/1440+المدخلات!$B$5/1440))-1,12)+1&":"&TEXT(MINUTE((المدخلات!$B$4+3*المدخلات!$B$5/1440+المدخلات!$B$5/1440)),"00")&IF(HOUR((المدخلات!$B$4+3*المدخلات!$B$5/1440))<12," ص"," م") -> 5:45–6:00 م | C16: 6 ضد 7
B17: =MOD(HOUR((المدخلات!$B$4+4*المدخلات!$B$5/1440))-1,12)+1&":"&TEXT(MINUTE((المدخلات!$B$4+4*المدخلات!$B$5/1440)),"00")&"–"&MOD(HOUR((المدخلات!$B$4+4*المدخلات!$B$5/1440+المدخلات!$B$5/1440))-1,12)+1&":"&TEXT(MINUTE((المدخلات!$B$4+4*المدخلات!$B$5/1440+المدخلات!$B$5/1440)),"00")&IF(HOUR((المدخلات!$B$4+4*المدخلات!$B$5/1440))<12," ص"," م") -> 6:00–6:15 م | C17: 2 ضد 5 | D17: 3 ضد 4
B18: =MOD(HOUR((المدخلات!$B$4+5*المدخلات!$B$5/1440))-1,12)+1&":"&TEXT(MINUTE((المدخلات!$B$4+5*المدخلات!$B$5/1440)),"00")&"–"&MOD(HOUR((المدخلات!$B$4+5*المدخلات!$B$5/1440+المدخلات!$B$5/1440))-1,12)+1&":"&TEXT(MINUTE((المدخلات!$B$4+5*المدخلات!$B$5/1440+المدخلات!$B$5/1440)),"00")&IF(HOUR((المدخلات!$B$4+5*المدخلات!$B$5/1440))<12," ص"," م") -> 6:15–6:30 م | C18: 1 ضد 7
B19: =MOD(HOUR((المدخلات!$B$4+6*المدخلات!$B$5/1440))-1,12)+1&":"&TEXT(MINUTE((المدخلات!$B$4+6*المدخلات!$B$5/1440)),"00")&"–"&MOD(HOUR((المدخلات!$B$4+6*المدخلات!$B$5/1440+المدخلات!$B$5/1440))-1,12)+1&":"&TEXT(MINUTE((المدخلات!$B$4+6*المدخلات!$B$5/1440+المدخلات!$B$5/1440)),"00")&IF(HOUR((المدخلات!$B$4+6*المدخلات!$B$5/1440))<12," ص"," م") -> 6:30–6:45 م | C19: 5 ضد 6 | D19: 2 ضد 3
B20: =MOD(HOUR((المدخلات!$B$4+7*المدخلات!$B$5/1440))-1,12)+1&":"&TEXT(MINUTE((المدخلات!$B$4+7*المدخلات!$B$5/1440)),"00")&"–"&MOD(HOUR((المدخلات!$B$4+7*المدخلات!$B$5/1440+المدخلات!$B$5/1440))-1,12)+1&":"&TEXT(MINUTE((المدخلات!$B$4+7*المدخلات!$B$5/1440+المدخلات!$B$5/1440)),"00")&IF(HOUR((المدخلات!$B$4+7*المدخلات!$B$5/1440))<12," ص"," م") -> 6:45–7:00 م | C20: 4 ضد 7
B21: =MOD(HOUR((المدخلات!$B$4+8*المدخلات!$B$5/1440))-1,12)+1&":"&TEXT(MINUTE((المدخلات!$B$4+8*المدخلات!$B$5/1440)),"00")&"–"&MOD(HOUR((المدخلات!$B$4+8*المدخلات!$B$5/1440+المدخلات!$B$5/1440))-1,12)+1&":"&TEXT(MINUTE((المدخلات!$B$4+8*المدخلات!$B$5/1440+المدخلات!$B$5/1440)),"00")&IF(HOUR((المدخلات!$B$4+8*المدخلات!$B$5/1440))<12," ص"," م") -> 7:00–7:15 م | C21: 1 ضد 5 | D21: 3 ضد 6
A22: اليوم 3 | B22: =MOD(HOUR((المدخلات!$B$4+0*المدخلات!$B$5/1440))-1,12)+1&":"&TEXT(MINUTE((المدخلات!$B$4+0*المدخلات!$B$5/1440)),"00")&"–"&MOD(HOUR((المدخلات!$B$4+0*المدخلات!$B$5/1440+المدخلات!$B$5/1440))-1,12)+1&":"&TEXT(MINUTE((المدخلات!$B$4+0*المدخلات!$B$5/1440+المدخلات!$B$5/1440)),"00")&IF(HOUR((المدخلات!$B$4+0*المدخلات!$B$5/1440))<12," ص"," م") -> 5:00–5:15 م | C22: 2 ضد 6 | D22: 3 ضد 5 | F22: =COUNTIF(C22:E30,"* ضد *") -> 14 | G22: =F22*2/'ملخص البطولات'!$A$5 -> 4
B23: =MOD(HOUR((المدخلات!$B$4+1*المدخلات!$B$5/1440))-1,12)+1&":"&TEXT(MINUTE((المدخلات!$B$4+1*المدخلات!$B$5/1440)),"00")&"–"&MOD(HOUR((المدخلات!$B$4+1*المدخلات!$B$5/1440+المدخلات!$B$5/1440))-1,12)+1&":"&TEXT(MINUTE((المدخلات!$B$4+1*المدخلات!$B$5/1440+المدخلات!$B$5/1440)),"00")&IF(HOUR((المدخلات!$B$4+1*المدخلات!$B$5/1440))<12," ص"," م") -> 5:15–5:30 م | C23: 1 ضد 4
B24: =MOD(HOUR((المدخلات!$B$4+2*المدخلات!$B$5/1440))-1,12)+1&":"&TEXT(MINUTE((المدخلات!$B$4+2*المدخلات!$B$5/1440)),"00")&"–"&MOD(HOUR((المدخلات!$B$4+2*المدخلات!$B$5/1440+المدخلات!$B$5/1440))-1,12)+1&":"&TEXT(MINUTE((المدخلات!$B$4+2*المدخلات!$B$5/1440+المدخلات!$B$5/1440)),"00")&IF(HOUR((المدخلات!$B$4+2*المدخلات!$B$5/1440))<12," ص"," م") -> 5:30–5:45 م | C24: 2 ضد 7 | D24: 3 ضد 6
B25: =MOD(HOUR((المدخلات!$B$4+3*المدخلات!$B$5/1440))-1,12)+1&":"&TEXT(MINUTE((المدخلات!$B$4+3*المدخلات!$B$5/1440)),"00")&"–"&MOD(HOUR((المدخلات!$B$4+3*المدخلات!$B$5/1440+المدخلات!$B$5/1440))-1,12)+1&":"&TEXT(MINUTE((المدخلات!$B$4+3*المدخلات!$B$5/1440+المدخلات!$B$5/1440)),"00")&IF(HOUR((المدخلات!$B$4+3*المدخلات!$B$5/1440))<12," ص"," م") -> 5:45–6:00 م | C25: 1 ضد 5
B26: =MOD(HOUR((المدخلات!$B$4+4*المدخلات!$B$5/1440))-1,12)+1&":"&TEXT(MINUTE((المدخلات!$B$4+4*المدخلات!$B$5/1440)),"00")&"–"&MOD(HOUR((المدخلات!$B$4+4*المدخلات!$B$5/1440+المدخلات!$B$5/1440))-1,12)+1&":"&TEXT(MINUTE((المدخلات!$B$4+4*المدخلات!$B$5/1440+المدخلات!$B$5/1440)),"00")&IF(HOUR((المدخلات!$B$4+4*المدخلات!$B$5/1440))<12," ص"," م") -> 6:00–6:15 م | C26: 2 ضد 4 | D26: 3 ضد 7
B27: =MOD(HOUR((المدخلات!$B$4+5*المدخلات!$B$5/1440))-1,12)+1&":"&TEXT(MINUTE((المدخلات!$B$4+5*المدخلات!$B$5/1440)),"00")&"–"&MOD(HOUR((المدخلات!$B$4+5*المدخلات!$B$5/1440+المدخلات!$B$5/1440))-1,12)+1&":"&TEXT(MINUTE((المدخلات!$B$4+5*المدخلات!$B$5/1440+المدخلات!$B$5/1440)),"00")&IF(HOUR((المدخلات!$B$4+5*المدخلات!$B$5/1440))<12," ص"," م") -> 6:15–6:30 م | C27: 1 ضد 6
B28: =MOD(HOUR((المدخلات!$B$4+6*المدخلات!$B$5/1440))-1,12)+1&":"&TEXT(MINUTE((المدخلات!$B$4+6*المدخلات!$B$5/1440)),"00")&"–"&MOD(HOUR((المدخلات!$B$4+6*المدخلات!$B$5/1440+المدخلات!$B$5/1440))-1,12)+1&":"&TEXT(MINUTE((المدخلات!$B$4+6*المدخلات!$B$5/1440+المدخلات!$B$5/1440)),"00")&IF(HOUR((المدخلات!$B$4+6*المدخلات!$B$5/1440))<12," ص"," م") -> 6:30–6:45 م | C28: 4 ضد 7 | D28: 2 ضد 5
B29: =MOD(HOUR((المدخلات!$B$4+7*المدخلات!$B$5/1440))-1,12)+1&":"&TEXT(MINUTE((المدخلات!$B$4+7*المدخلات!$B$5/1440)),"00")&"–"&MOD(HOUR((المدخلات!$B$4+7*المدخلات!$B$5/1440+المدخلات!$B$5/1440))-1,12)+1&":"&TEXT(MINUTE((المدخلات!$B$4+7*المدخلات!$B$5/1440+المدخلات!$B$5/1440)),"00")&IF(HOUR((المدخلات!$B$4+7*المدخلات!$B$5/1440))<12," ص"," م") -> 6:45–7:00 م | C29: 1 ضد 3
B30: =MOD(HOUR((المدخلات!$B$4+8*المدخلات!$B$5/1440))-1,12)+1&":"&TEXT(MINUTE((المدخلات!$B$4+8*المدخلات!$B$5/1440)),"00")&"–"&MOD(HOUR((المدخلات!$B$4+8*المدخلات!$B$5/1440+المدخلات!$B$5/1440))-1,12)+1&":"&TEXT(MINUTE((المدخلات!$B$4+8*المدخلات!$B$5/1440+المدخلات!$B$5/1440)),"00")&IF(HOUR((المدخلات!$B$4+8*المدخلات!$B$5/1440))<12," ص"," م") -> 7:00–7:15 م | C30: 5 ضد 7 | D30: 4 ضد 6
A31: اليوم 4 | B31: =MOD(HOUR((المدخلات!$B$4+0*المدخلات!$B$5/1440))-1,12)+1&":"&TEXT(MINUTE((المدخلات!$B$4+0*المدخلات!$B$5/1440)),"00")&"–"&MOD(HOUR((المدخلات!$B$4+0*المدخلات!$B$5/1440+المدخلات!$B$5/1440))-1,12)+1&":"&TEXT(MINUTE((المدخلات!$B$4+0*المدخلات!$B$5/1440+المدخلات!$B$5/1440)),"00")&IF(HOUR((المدخلات!$B$4+0*المدخلات!$B$5/1440))<12," ص"," م") -> 5:00–5:15 م | C31: 4 ضد 5 | D31: 1 ضد 7 | F31: =COUNTIF(C31:E39,"* ضد *") -> 14 | G31: =F31*2/'ملخص البطولات'!$A$5 -> 4
B32: =MOD(HOUR((المدخلات!$B$4+1*المدخلات!$B$5/1440))-1,12)+1&":"&TEXT(MINUTE((المدخلات!$B$4+1*المدخلات!$B$5/1440)),"00")&"–"&MOD(HOUR((المدخلات!$B$4+1*المدخلات!$B$5/1440+المدخلات!$B$5/1440))-1,12)+1&":"&TEXT(MINUTE((المدخلات!$B$4+1*المدخلات!$B$5/1440+المدخلات!$B$5/1440)),"00")&IF(HOUR((المدخلات!$B$4+1*المدخلات!$B$5/1440))<12," ص"," م") -> 5:15–5:30 م | C32: 2 ضد 3
B33: =MOD(HOUR((المدخلات!$B$4+2*المدخلات!$B$5/1440))-1,12)+1&":"&TEXT(MINUTE((المدخلات!$B$4+2*المدخلات!$B$5/1440)),"00")&"–"&MOD(HOUR((المدخلات!$B$4+2*المدخلات!$B$5/1440+المدخلات!$B$5/1440))-1,12)+1&":"&TEXT(MINUTE((المدخلات!$B$4+2*المدخلات!$B$5/1440+المدخلات!$B$5/1440)),"00")&IF(HOUR((المدخلات!$B$4+2*المدخلات!$B$5/1440))<12," ص"," م") -> 5:30–5:45 م | C33: 5 ضد 7 | D33: 4 ضد 6
B34: =MOD(HOUR((المدخلات!$B$4+3*المدخلات!$B$5/1440))-1,12)+1&":"&TEXT(MINUTE((المدخلات!$B$4+3*المدخلات!$B$5/1440)),"00")&"–"&MOD(HOUR((المدخلات!$B$4+3*المدخلات!$B$5/1440+المدخلات!$B$5/1440))-1,12)+1&":"&TEXT(MINUTE((المدخلات!$B$4+3*المدخلات!$B$5/1440+المدخلات!$B$5/1440)),"00")&IF(HOUR((المدخلات!$B$4+3*المدخلات!$B$5/1440))<12," ص"," م") -> 5:45–6:00 م | C34: 1 ضد 3
B35: =MOD(HOUR((المدخلات!$B$4+4*المدخلات!$B$5/1440))-1,12)+1&":"&TEXT(MINUTE((المدخلات!$B$4+4*المدخلات!$B$5/1440)),"00")&"–"&MOD(HOUR((المدخلات!$B$4+4*المدخلات!$B$5/1440+المدخلات!$B$5/1440))-1,12)+1&":"&TEXT(MINUTE((المدخلات!$B$4+4*المدخلات!$B$5/1440+المدخلات!$B$5/1440)),"00")&IF(HOUR((المدخلات!$B$4+4*المدخلات!$B$5/1440))<12," ص"," م") -> 6:00–6:15 م | C35: 6 ضد 7 | D35: 2 ضد 4
B36: =MOD(HOUR((المدخلات!$B$4+5*المدخلات!$B$5/1440))-1,12)+1&":"&TEXT(MINUTE((المدخلات!$B$4+5*المدخلات!$B$5/1440)),"00")&"–"&MOD(HOUR((المدخلات!$B$4+5*المدخلات!$B$5/1440+المدخلات!$B$5/1440))-1,12)+1&":"&TEXT(MINUTE((المدخلات!$B$4+5*المدخلات!$B$5/1440+المدخلات!$B$5/1440)),"00")&IF(HOUR((المدخلات!$B$4+5*المدخلات!$B$5/1440))<12," ص"," م") -> 6:15–6:30 م | C36: 3 ضد 5
B37: =MOD(HOUR((المدخلات!$B$4+6*المدخلات!$B$5/1440))-1,12)+1&":"&TEXT(MINUTE((المدخلات!$B$4+6*المدخلات!$B$5/1440)),"00")&"–"&MOD(HOUR((المدخلات!$B$4+6*المدخلات!$B$5/1440+المدخلات!$B$5/1440))-1,12)+1&":"&TEXT(MINUTE((المدخلات!$B$4+6*المدخلات!$B$5/1440+المدخلات!$B$5/1440)),"00")&IF(HOUR((المدخلات!$B$4+6*المدخلات!$B$5/1440))<12," ص"," م") -> 6:30–6:45 م | C37: 1 ضد 6 | D37: 2 ضد 7
B38: =MOD(HOUR((المدخلات!$B$4+7*المدخلات!$B$5/1440))-1,12)+1&":"&TEXT(MINUTE((المدخلات!$B$4+7*المدخلات!$B$5/1440)),"00")&"–"&MOD(HOUR((المدخلات!$B$4+7*المدخلات!$B$5/1440+المدخلات!$B$5/1440))-1,12)+1&":"&TEXT(MINUTE((المدخلات!$B$4+7*المدخلات!$B$5/1440+المدخلات!$B$5/1440)),"00")&IF(HOUR((المدخلات!$B$4+7*المدخلات!$B$5/1440))<12," ص"," م") -> 6:45–7:00 م | C38: 3 ضد 4
B39: =MOD(HOUR((المدخلات!$B$4+8*المدخلات!$B$5/1440))-1,12)+1&":"&TEXT(MINUTE((المدخلات!$B$4+8*المدخلات!$B$5/1440)),"00")&"–"&MOD(HOUR((المدخلات!$B$4+8*المدخلات!$B$5/1440+المدخلات!$B$5/1440))-1,12)+1&":"&TEXT(MINUTE((المدخلات!$B$4+8*المدخلات!$B$5/1440+المدخلات!$B$5/1440)),"00")&IF(HOUR((المدخلات!$B$4+8*المدخلات!$B$5/1440))<12," ص"," م") -> 7:00–7:15 م | C39: 1 ضد 2 | D39: 5 ضد 6
A40: اليوم 5 | B40: =MOD(HOUR((المدخلات!$B$4+0*المدخلات!$B$5/1440))-1,12)+1&":"&TEXT(MINUTE((المدخلات!$B$4+0*المدخلات!$B$5/1440)),"00")&"–"&MOD(HOUR((المدخلات!$B$4+0*المدخلات!$B$5/1440+المدخلات!$B$5/1440))-1,12)+1&":"&TEXT(MINUTE((المدخلات!$B$4+0*المدخلات!$B$5/1440+المدخلات!$B$5/1440)),"00")&IF(HOUR((المدخلات!$B$4+0*المدخلات!$B$5/1440))<12," ص"," م") -> 5:00–5:15 م | C40: 2 ضد 3 | D40: 4 ضد 7 | F40: =COUNTIF(C40:E48,"* ضد *") -> 14 | G40: =F40*2/'ملخص البطولات'!$A$5 -> 4
B41: =MOD(HOUR((المدخلات!$B$4+1*المدخلات!$B$5/1440))-1,12)+1&":"&TEXT(MINUTE((المدخلات!$B$4+1*المدخلات!$B$5/1440)),"00")&"–"&MOD(HOUR((المدخلات!$B$4+1*المدخلات!$B$5/1440+المدخلات!$B$5/1440))-1,12)+1&":"&TEXT(MINUTE((المدخلات!$B$4+1*المدخلات!$B$5/1440+المدخلات!$B$5/1440)),"00")&IF(HOUR((المدخلات!$B$4+1*المدخلات!$B$5/1440))<12," ص"," م") -> 5:15–5:30 م | C41: 5 ضد 6
...

Sheet 8 فرق
A1: جدول مباريات المجموعات التي فيها 8 فرق
A3: اليوم | B3: الوقت | C3: ملعب 1 | D3: ملعب 2 | E3: ملعب 3 | F3: ملعب 4 | G3: مجموع مباريات اليوم | H3: مباريات كل فريق في اليوم
A4: اليوم 1 | B4: =MOD(HOUR((المدخلات!$B$4+0*المدخلات!$B$5/1440))-1,12)+1&":"&TEXT(MINUTE((المدخلات!$B$4+0*المدخلات!$B$5/1440)),"00")&"–"&MOD(HOUR((المدخلات!$B$4+0*المدخلات!$B$5/1440+المدخلات!$B$5/1440))-1,12)+1&":"&TEXT(MINUTE((المدخلات!$B$4+0*المدخلات!$B$5/1440+المدخلات!$B$5/1440)),"00")&IF(HOUR((المدخلات!$B$4+0*المدخلات!$B$5/1440))<12," ص"," م") -> 5:00–5:15 م | C4: 1 ضد 8 | D4: 2 ضد 7 | E4: 3 ضد 6 | F4: 4 ضد 5 | G4: =COUNTIF(C4:F10,"* ضد *") -> 16 | H4: =G4*2/'ملخص البطولات'!$A$6 -> 4
B5: =MOD(HOUR((المدخلات!$B$4+1*المدخلات!$B$5/1440))-1,12)+1&":"&TEXT(MINUTE((المدخلات!$B$4+1*المدخلات!$B$5/1440)),"00")&"–"&MOD(HOUR((المدخلات!$B$4+1*المدخلات!$B$5/1440+المدخلات!$B$5/1440))-1,12)+1&":"&TEXT(MINUTE((المدخلات!$B$4+1*المدخلات!$B$5/1440+المدخلات!$B$5/1440)),"00")&IF(HOUR((المدخلات!$B$4+1*المدخلات!$B$5/1440))<12," ص"," م") -> 5:15–5:30 م | C5: استراحة (لا توجد مباريات)
B6: =MOD(HOUR((المدخلات!$B$4+2*المدخلات!$B$5/1440))-1,12)+1&":"&TEXT(MINUTE((المدخلات!$B$4+2*المدخلات!$B$5/1440)),"00")&"–"&MOD(HOUR((المدخلات!$B$4+2*المدخلات!$B$5/1440+المدخلات!$B$5/1440))-1,12)+1&":"&TEXT(MINUTE((المدخلات!$B$4+2*المدخلات!$B$5/1440+المدخلات!$B$5/1440)),"00")&IF(HOUR((المدخلات!$B$4+2*المدخلات!$B$5/1440))<12," ص"," م") -> 5:30–5:45 م | C6: 2 ضد 8 | D6: 1 ضد 3 | E6: 4 ضد 7 | F6: 5 ضد 6
B7: =MOD(HOUR((المدخلات!$B$4+3*المدخلات!$B$5/1440))-1,12)+1&":"&TEXT(MINUTE((المدخلات!$B$4+3*المدخلات!$B$5/1440)),"00")&"–"&MOD(HOUR((المدخلات!$B$4+3*المدخلات!$B$5/1440+المدخلات!$B$5/1440))-1,12)+1&":"&TEXT(MINUTE((المدخلات!$B$4+3*المدخلات!$B$5/1440+المدخلات!$B$5/1440)),"00")&IF(HOUR((المدخلات!$B$4+3*المدخلات!$B$5/1440))<12," ص"," م") -> 5:45–6:00 م | C7: استراحة (لا توجد مباريات)
B8: =MOD(HOUR((المدخلات!$B$4+4*المدخلات!$B$5/1440))-1,12)+1&":"&TEXT(MINUTE((المدخلات!$B$4+4*المدخلات!$B$5/1440)),"00")&"–"&MOD(HOUR((المدخلات!$B$4+4*المدخلات!$B$5/1440+المدخلات!$B$5/1440))-1,12)+1&":"&TEXT(MINUTE((المدخلات!$B$4+4*المدخلات!$B$5/1440+المدخلات!$B$5/1440)),"00")&IF(HOUR((المدخلات!$B$4+4*المدخلات!$B$5/1440))<12," ص"," م") -> 6:00–6:15 م | C8: 3 ضد 8 | D8: 2 ضد 4 | E8: 1 ضد 5 | F8: 6 ضد 7
B9: =MOD(HOUR((المدخلات!$B$4+5*المدخلات!$B$5/1440))-1,12)+1&":"&TEXT(MINUTE((المدخلات!$B$4+5*المدخلات!$B$5/1440)),"00")&"–"&MOD(HOUR((المدخلات!$B$4+5*المدخلات!$B$5/1440+المدخلات!$B$5/1440))-1,12)+1&":"&TEXT(MINUTE((المدخلات!$B$4+5*المدخلات!$B$5/1440+المدخلات!$B$5/1440)),"00")&IF(HOUR((المدخلات!$B$4+5*المدخلات!$B$5/1440))<12," ص"," م") -> 6:15–6:30 م | C9: استراحة (لا توجد مباريات)
B10: =MOD(HOUR((المدخلات!$B$4+6*المدخلات!$B$5/1440))-1,12)+1&":"&TEXT(MINUTE((المدخلات!$B$4+6*المدخلات!$B$5/1440)),"00")&"–"&MOD(HOUR((المدخلات!$B$4+6*المدخلات!$B$5/1440+المدخلات!$B$5/1440))-1,12)+1&":"&TEXT(MINUTE((المدخلات!$B$4+6*المدخلات!$B$5/1440+المدخلات!$B$5/1440)),"00")&IF(HOUR((المدخلات!$B$4+6*المدخلات!$B$5/1440))<12," ص"," م") -> 6:30–6:45 م | C10: 4 ضد 8 | D10: 3 ضد 5 | E10: 2 ضد 6 | F10: 1 ضد 7
A11: اليوم 2 | B11: =MOD(HOUR((المدخلات!$B$4+0*المدخلات!$B$5/1440))-1,12)+1&":"&TEXT(MINUTE((المدخلات!$B$4+0*المدخلات!$B$5/1440)),"00")&"–"&MOD(HOUR((المدخلات!$B$4+0*المدخلات!$B$5/1440+المدخلات!$B$5/1440))-1,12)+1&":"&TEXT(MINUTE((المدخلات!$B$4+0*المدخلات!$B$5/1440+المدخلات!$B$5/1440)),"00")&IF(HOUR((المدخلات!$B$4+0*المدخلات!$B$5/1440))<12," ص"," م") -> 5:00–5:15 م | C11: 5 ضد 8 | D11: 4 ضد 6 | E11: 3 ضد 7 | F11: 1 ضد 2 | G11: =COUNTIF(C11:F17,"* ضد *") -> 16 | H11: =G11*2/'ملخص البطولات'!$A$6 -> 4
B12: =MOD(HOUR((المدخلات!$B$4+1*المدخلات!$B$5/1440))-1,12)+1&":"&TEXT(MINUTE((المدخلات!$B$4+1*المدخلات!$B$5/1440)),"00")&"–"&MOD(HOUR((المدخلات!$B$4+1*المدخلات!$B$5/1440+المدخلات!$B$5/1440))-1,12)+1&":"&TEXT(MINUTE((المدخلات!$B$4+1*المدخلات!$B$5/1440+المدخلات!$B$5/1440)),"00")&IF(HOUR((المدخلات!$B$4+1*المدخلات!$B$5/1440))<12," ص"," م") -> 5:15–5:30 م | C12: استراحة (لا توجد مباريات)
B13: =MOD(HOUR((المدخلات!$B$4+2*المدخلات!$B$5/1440))-1,12)+1&":"&TEXT(MINUTE((المدخلات!$B$4+2*المدخلات!$B$5/1440)),"00")&"–"&MOD(HOUR((المدخلات!$B$4+2*المدخلات!$B$5/1440+المدخلات!$B$5/1440))-1,12)+1&":"&TEXT(MINUTE((المدخلات!$B$4+2*المدخلات!$B$5/1440+المدخلات!$B$5/1440)),"00")&IF(HOUR((المدخلات!$B$4+2*المدخلات!$B$5/1440))<12," ص"," م") -> 5:30–5:45 م | C13: 6 ضد 8 | D13: 5 ضد 7 | E13: 1 ضد 4 | F13: 2 ضد 3
B14: =MOD(HOUR((المدخلات!$B$4+3*المدخلات!$B$5/1440))-1,12)+1&":"&TEXT(MINUTE((المدخلات!$B$4+3*المدخلات!$B$5/1440)),"00")&"–"&MOD(HOUR((المدخلات!$B$4+3*المدخلات!$B$5/1440+المدخلات!$B$5/1440))-1,12)+1&":"&TEXT(MINUTE((المدخلات!$B$4+3*المدخلات!$B$5/1440+المدخلات!$B$5/1440)),"00")&IF(HOUR((المدخلات!$B$4+3*المدخلات!$B$5/1440))<12," ص"," م") -> 5:45–6:00 م | C14: استراحة (لا توجد مباريات)
B15: =MOD(HOUR((المدخلات!$B$4+4*المدخلات!$B$5/1440))-1,12)+1&":"&TEXT(MINUTE((المدخلات!$B$4+4*المدخلات!$B$5/1440)),"00")&"–"&MOD(HOUR((المدخلات!$B$4+4*المدخلات!$B$5/1440+المدخلات!$B$5/1440))-1,12)+1&":"&TEXT(MINUTE((المدخلات!$B$4+4*المدخلات!$B$5/1440+المدخلات!$B$5/1440)),"00")&IF(HOUR((المدخلات!$B$4+4*المدخلات!$B$5/1440))<12," ص"," م") -> 6:00–6:15 م | C15: 7 ضد 8 | D15: 1 ضد 6 | E15: 2 ضد 5 | F15: 3 ضد 4
B16: =MOD(HOUR((المدخلات!$B$4+5*المدخلات!$B$5/1440))-1,12)+1&":"&TEXT(MINUTE((المدخلات!$B$4+5*المدخلات!$B$5/1440)),"00")&"–"&MOD(HOUR((المدخلات!$B$4+5*المدخلات!$B$5/1440+المدخلات!$B$5/1440))-1,12)+1&":"&TEXT(MINUTE((المدخلات!$B$4+5*المدخلات!$B$5/1440+المدخلات!$B$5/1440)),"00")&IF(HOUR((المدخلات!$B$4+5*المدخلات!$B$5/1440))<12," ص"," م") -> 6:15–6:30 م | C16: استراحة (لا توجد مباريات)
B17: =MOD(HOUR((المدخلات!$B$4+6*المدخلات!$B$5/1440))-1,12)+1&":"&TEXT(MINUTE((المدخلات!$B$4+6*المدخلات!$B$5/1440)),"00")&"–"&MOD(HOUR((المدخلات!$B$4+6*المدخلات!$B$5/1440+المدخلات!$B$5/1440))-1,12)+1&":"&TEXT(MINUTE((المدخلات!$B$4+6*المدخلات!$B$5/1440+المدخلات!$B$5/1440)),"00")&IF(HOUR((المدخلات!$B$4+6*المدخلات!$B$5/1440))<12," ص"," م") -> 6:30–6:45 م | C17: 1 ضد 8 | D17: 2 ضد 7 | E17: 3 ضد 6 | F17: 4 ضد 5
A18: اليوم 3 | B18: =MOD(HOUR((المدخلات!$B$4+0*المدخلات!$B$5/1440))-1,12)+1&":"&TEXT(MINUTE((المدخلات!$B$4+0*المدخلات!$B$5/1440)),"00")&"–"&MOD(HOUR((المدخلات!$B$4+0*المدخلات!$B$5/1440+المدخلات!$B$5/1440))-1,12)+1&":"&TEXT(MINUTE((المدخلات!$B$4+0*المدخلات!$B$5/1440+المدخلات!$B$5/1440)),"00")&IF(HOUR((المدخلات!$B$4+0*المدخلات!$B$5/1440))<12," ص"," م") -> 5:00–5:15 م | C18: 2 ضد 8 | D18: 1 ضد 3 | E18: 4 ضد 7 | F18: 5 ضد 6 | G18: =COUNTIF(C18:F24,"* ضد *") -> 16 | H18: =G18*2/'ملخص البطولات'!$A$6 -> 4
B19: =MOD(HOUR((المدخلات!$B$4+1*المدخلات!$B$5/1440))-1,12)+1&":"&TEXT(MINUTE((المدخلات!$B$4+1*المدخلات!$B$5/1440)),"00")&"–"&MOD(HOUR((المدخلات!$B$4+1*المدخلات!$B$5/1440+المدخلات!$B$5/1440))-1,12)+1&":"&TEXT(MINUTE((المدخلات!$B$4+1*المدخلات!$B$5/1440+المدخلات!$B$5/1440)),"00")&IF(HOUR((المدخلات!$B$4+1*المدخلات!$B$5/1440))<12," ص"," م") -> 5:15–5:30 م | C19: استراحة (لا توجد مباريات)
B20: =MOD(HOUR((المدخلات!$B$4+2*المدخلات!$B$5/1440))-1,12)+1&":"&TEXT(MINUTE((المدخلات!$B$4+2*المدخلات!$B$5/1440)),"00")&"–"&MOD(HOUR((المدخلات!$B$4+2*المدخلات!$B$5/1440+المدخلات!$B$5/1440))-1,12)+1&":"&TEXT(MINUTE((المدخلات!$B$4+2*المدخلات!$B$5/1440+المدخلات!$B$5/1440)),"00")&IF(HOUR((المدخلات!$B$4+2*المدخلات!$B$5/1440))<12," ص"," م") -> 5:30–5:45 م | C20: 3 ضد 8 | D20: 2 ضد 4 | E20: 1 ضد 5 | F20: 6 ضد 7
B21: =MOD(HOUR((المدخلات!$B$4+3*المدخلات!$B$5/1440))-1,12)+1&":"&TEXT(MINUTE((المدخلات!$B$4+3*المدخلات!$B$5/1440)),"00")&"–"&MOD(HOUR((المدخلات!$B$4+3*المدخلات!$B$5/1440+المدخلات!$B$5/1440))-1,12)+1&":"&TEXT(MINUTE((المدخلات!$B$4+3*المدخلات!$B$5/1440+المدخلات!$B$5/1440)),"00")&IF(HOUR((المدخلات!$B$4+3*المدخلات!$B$5/1440))<12," ص"," م") -> 5:45–6:00 م | C21: استراحة (لا توجد مباريات)
B22: =MOD(HOUR((المدخلات!$B$4+4*المدخلات!$B$5/1440))-1,12)+1&":"&TEXT(MINUTE((المدخلات!$B$4+4*المدخلات!$B$5/1440)),"00")&"–"&MOD(HOUR((المدخلات!$B$4+4*المدخلات!$B$5/1440+المدخلات!$B$5/1440))-1,12)+1&":"&TEXT(MINUTE((المدخلات!$B$4+4*المدخلات!$B$5/1440+المدخلات!$B$5/1440)),"00")&IF(HOUR((المدخلات!$B$4+4*المدخلات!$B$5/1440))<12," ص"," م") -> 6:00–6:15 م | C22: 4 ضد 8 | D22: 3 ضد 5 | E22: 2 ضد 6 | F22: 1 ضد 7
B23: =MOD(HOUR((المدخلات!$B$4+5*المدخلات!$B$5/1440))-1,12)+1&":"&TEXT(MINUTE((المدخلات!$B$4+5*المدخلات!$B$5/1440)),"00")&"–"&MOD(HOUR((المدخلات!$B$4+5*المدخلات!$B$5/1440+المدخلات!$B$5/1440))-1,12)+1&":"&TEXT(MINUTE((المدخلات!$B$4+5*المدخلات!$B$5/1440+المدخلات!$B$5/1440)),"00")&IF(HOUR((المدخلات!$B$4+5*المدخلات!$B$5/1440))<12," ص"," م") -> 6:15–6:30 م | C23: استراحة (لا توجد مباريات)
B24: =MOD(HOUR((المدخلات!$B$4+6*المدخلات!$B$5/1440))-1,12)+1&":"&TEXT(MINUTE((المدخلات!$B$4+6*المدخلات!$B$5/1440)),"00")&"–"&MOD(HOUR((المدخلات!$B$4+6*المدخلات!$B$5/1440+المدخلات!$B$5/1440))-1,12)+1&":"&TEXT(MINUTE((المدخلات!$B$4+6*المدخلات!$B$5/1440+المدخلات!$B$5/1440)),"00")&IF(HOUR((المدخلات!$B$4+6*المدخلات!$B$5/1440))<12," ص"," م") -> 6:30–6:45 م | C24: 5 ضد 8 | D24: 4 ضد 6 | E24: 3 ضد 7 | F24: 1 ضد 2
A25: اليوم 4 | B25: =MOD(HOUR((المدخلات!$B$4+0*المدخلات!$B$5/1440))-1,12)+1&":"&TEXT(MINUTE((المدخلات!$B$4+0*المدخلات!$B$5/1440)),"00")&"–"&MOD(HOUR((المدخلات!$B$4+0*المدخلات!$B$5/1440+المدخلات!$B$5/1440))-1,12)+1&":"&TEXT(MINUTE((المدخلات!$B$4+0*المدخلات!$B$5/1440+المدخلات!$B$5/1440)),"00")&IF(HOUR((المدخلات!$B$4+0*المدخلات!$B$5/1440))<12," ص"," م") -> 5:00–5:15 م | C25: 6 ضد 8 | D25: 5 ضد 7 | E25: 1 ضد 4 | F25: 2 ضد 3 | G25: =COUNTIF(C25:F31,"* ضد *") -> 16 | H25: =G25*2/'ملخص البطولات'!$A$6 -> 4
B26: =MOD(HOUR((المدخلات!$B$4+1*المدخلات!$B$5/1440))-1,12)+1&":"&TEXT(MINUTE((المدخلات!$B$4+1*المدخلات!$B$5/1440)),"00")&"–"&MOD(HOUR((المدخلات!$B$4+1*المدخلات!$B$5/1440+المدخلات!$B$5/1440))-1,12)+1&":"&TEXT(MINUTE((المدخلات!$B$4+1*المدخلات!$B$5/1440+المدخلات!$B$5/1440)),"00")&IF(HOUR((المدخلات!$B$4+1*المدخلات!$B$5/1440))<12," ص"," م") -> 5:15–5:30 م | C26: استراحة (لا توجد مباريات)
B27: =MOD(HOUR((المدخلات!$B$4+2*المدخلات!$B$5/1440))-1,12)+1&":"&TEXT(MINUTE((المدخلات!$B$4+2*المدخلات!$B$5/1440)),"00")&"–"&MOD(HOUR((المدخلات!$B$4+2*المدخلات!$B$5/1440+المدخلات!$B$5/1440))-1,12)+1&":"&TEXT(MINUTE((المدخلات!$B$4+2*المدخلات!$B$5/1440+المدخلات!$B$5/1440)),"00")&IF(HOUR((المدخلات!$B$4+2*المدخلات!$B$5/1440))<12," ص"," م") -> 5:30–5:45 م | C27: 7 ضد 8 | D27: 1 ضد 6 | E27: 2 ضد 5 | F27: 3 ضد 4
B28: =MOD(HOUR((المدخلات!$B$4+3*المدخلات!$B$5/1440))-1,12)+1&":"&TEXT(MINUTE((المدخلات!$B$4+3*المدخلات!$B$5/1440)),"00")&"–"&MOD(HOUR((المدخلات!$B$4+3*المدخلات!$B$5/1440+المدخلات!$B$5/1440))-1,12)+1&":"&TEXT(MINUTE((المدخلات!$B$4+3*المدخلات!$B$5/1440+المدخلات!$B$5/1440)),"00")&IF(HOUR((المدخلات!$B$4+3*المدخلات!$B$5/1440))<12," ص"," م") -> 5:45–6:00 م | C28: استراحة (لا توجد مباريات)
B29: =MOD(HOUR((المدخلات!$B$4+4*المدخلات!$B$5/1440))-1,12)+1&":"&TEXT(MINUTE((المدخلات!$B$4+4*المدخلات!$B$5/1440)),"00")&"–"&MOD(HOUR((المدخلات!$B$4+4*المدخلات!$B$5/1440+المدخلات!$B$5/1440))-1,12)+1&":"&TEXT(MINUTE((المدخلات!$B$4+4*المدخلات!$B$5/1440+المدخلات!$B$5/1440)),"00")&IF(HOUR((المدخلات!$B$4+4*المدخلات!$B$5/1440))<12," ص"," م") -> 6:00–6:15 م | C29: 1 ضد 8 | D29: 2 ضد 7 | E29: 3 ضد 6 | F29: 4 ضد 5
B30: =MOD(HOUR((المدخلات!$B$4+5*المدخلات!$B$5/1440))-1,12)+1&":"&TEXT(MINUTE((المدخلات!$B$4+5*المدخلات!$B$5/1440)),"00")&"–"&MOD(HOUR((المدخلات!$B$4+5*المدخلات!$B$5/1440+المدخلات!$B$5/1440))-1,12)+1&":"&TEXT(MINUTE((المدخلات!$B$4+5*المدخلات!$B$5/1440+المدخلات!$B$5/1440)),"00")&IF(HOUR((المدخلات!$B$4+5*المدخلات!$B$5/1440))<12," ص"," م") -> 6:15–6:30 م | C30: استراحة (لا توجد مباريات)
B31: =MOD(HOUR((المدخلات!$B$4+6*المدخلات!$B$5/1440))-1,12)+1&":"&TEXT(MINUTE((المدخلات!$B$4+6*المدخلات!$B$5/1440)),"00")&"–"&MOD(HOUR((المدخلات!$B$4+6*المدخلات!$B$5/1440+المدخلات!$B$5/1440))-1,12)+1&":"&TEXT(MINUTE((المدخلات!$B$4+6*المدخلات!$B$5/1440+المدخلات!$B$5/1440)),"00")&IF(HOUR((المدخلات!$B$4+6*المدخلات!$B$5/1440))<12," ص"," م") -> 6:30–6:45 م | C31: 2 ضد 8 | D31: 1 ضد 3 | E31: 4 ضد 7 | F31: 5 ضد 6
A32: اليوم 5 | B32: =MOD(HOUR((المدخلات!$B$4+0*المدخلات!$B$5/1440))-1,12)+1&":"&TEXT(MINUTE((المدخلات!$B$4+0*المدخلات!$B$5/1440)),"00")&"–"&MOD(HOUR((المدخلات!$B$4+0*المدخلات!$B$5/1440+المدخلات!$B$5/1440))-1,12)+1&":"&TEXT(MINUTE((المدخلات!$B$4+0*المدخلات!$B$5/1440+المدخلات!$B$5/1440)),"00")&IF(HOUR((المدخلات!$B$4+0*المدخلات!$B$5/1440))<12," ص"," م") -> 5:00–5:15 م | C32: 3 ضد 8 | D32: 2 ضد 4 | E32: 1 ضد 5 | F32: 6 ضد 7 | G32: =COUNTIF(C32:F38,"* ضد *") -> 16 | H32: =G32*2/'ملخص البطولات'!$A$6 -> 4
B33: =MOD(HOUR((المدخلات!$B$4+1*المدخلات!$B$5/1440))-1,12)+1&":"&TEXT(MINUTE((المدخلات!$B$4+1*المدخلات!$B$5/1440)),"00")&"–"&MOD(HOUR((المدخلات!$B$4+1*المدخلات!$B$5/1440+المدخلات!$B$5/1440))-1,12)+1&":"&TEXT(MINUTE((المدخلات!$B$4+1*المدخلات!$B$5/1440+المدخلات!$B$5/1440)),"00")&IF(HOUR((المدخلات!$B$4+1*المدخلات!$B$5/1440))<12," ص"," م") -> 5:15–5:30 م | C33: استراحة (لا توجد مباريات)
B34: =MOD(HOUR((المدخلات!$B$4+2*المدخلات!$B$5/1440))-1,12)+1&":"&TEXT(MINUTE((المدخلات!$B$4+2*المدخلات!$B$5/1440)),"00")&"–"&MOD(HOUR((المدخلات!$B$4+2*المدخلات!$B$5/1440+المدخلات!$B$5/1440))-1,12)+1&":"&TEXT(MINUTE((المدخلات!$B$4+2*المدخلات!$B$5/1440+المدخلات!$B$5/1440)),"00")&IF(HOUR((المدخلات!$B$4+2*المدخلات!$B$5/1440))<12," ص"," م") -> 5:30–5:45 م | C34: 4 ضد 8 | D34: 3 ضد 5 | E34: 2 ضد 6 | F34: 1 ضد 7
B35: =MOD(HOUR((المدخلات!$B$4+3*المدخلات!$B$5/1440))-1,12)+1&":"&TEXT(MINUTE((المدخلات!$B$4+3*المدخلات!$B$5/1440)),"00")&"–"&MOD(HOUR((المدخلات!$B$4+3*المدخلات!$B$5/1440+المدخلات!$B$5/1440))-1,12)+1&":"&TEXT(MINUTE((المدخلات!$B$4+3*المدخلات!$B$5/1440+المدخلات!$B$5/1440)),"00")&IF(HOUR((المدخلات!$B$4+3*المدخلات!$B$5/1440))<12," ص"," م") -> 5:45–6:00 م | C35: استراحة (لا توجد مباريات)
B36: =MOD(HOUR((المدخلات!$B$4+4*المدخلات!$B$5/1440))-1,12)+1&":"&TEXT(MINUTE((المدخلات!$B$4+4*المدخلات!$B$5/1440)),"00")&"–"&MOD(HOUR((المدخلات!$B$4+4*المدخلات!$B$5/1440+المدخلات!$B$5/1440))-1,12)+1&":"&TEXT(MINUTE((المدخلات!$B$4+4*المدخلات!$B$5/1440+المدخلات!$B$5/1440)),"00")&IF(HOUR((المدخلات!$B$4+4*المدخلات!$B$5/1440))<12," ص"," م") -> 6:00–6:15 م | C36: 5 ضد 8 | D36: 4 ضد 6 | E36: 3 ضد 7 | F36: 1 ضد 2
B37: =MOD(HOUR((المدخلات!$B$4+5*المدخلات!$B$5/1440))-1,12)+1&":"&TEXT(MINUTE((المدخلات!$B$4+5*المدخلات!$B$5/1440)),"00")&"–"&MOD(HOUR((المدخلات!$B$4+5*المدخلات!$B$5/1440+المدخلات!$B$5/1440))-1,12)+1&":"&TEXT(MINUTE((المدخلات!$B$4+5*المدخلات!$B$5/1440+المدخلات!$B$5/1440)),"00")&IF(HOUR((المدخلات!$B$4+5*المدخلات!$B$5/1440))<12," ص"," م") -> 6:15–6:30 م | C37: استراحة (لا توجد مباريات)
B38: =MOD(HOUR((المدخلات!$B$4+6*المدخلات!$B$5/1440))-1,12)+1&":"&TEXT(MINUTE((المدخلات!$B$4+6*المدخلات!$B$5/1440)),"00")&"–"&MOD(HOUR((المدخلات!$B$4+6*المدخلات!$B$5/1440+المدخلات!$B$5/1440))-1,12)+1&":"&TEXT(MINUTE((المدخلات!$B$4+6*المدخلات!$B$5/1440+المدخلات!$B$5/1440)),"00")&IF(HOUR((المدخلات!$B$4+6*المدخلات!$B$5/1440))<12," ص"," م") -> 6:30–6:45 م | C38: 6 ضد 8 | D38: 5 ضد 7 | E38: 1 ضد 4 | F38: 2 ضد 3
A39: اليوم 6 | B39: =MOD(HOUR((المدخلات!$B$4+0*المدخلات!$B$5/1440))-1,12)+1&":"&TEXT(MINUTE((المدخلات!$B$4+0*المدخلات!$B$5/1440)),"00")&"–"&MOD(HOUR((المدخلات!$B$4+0*المدخلات!$B$5/1440+المدخلات!$B$5/1440))-1,12)+1&":"&TEXT(MINUTE((المدخلات!$B$4+0*المدخلات!$B$5/1440+المدخلات!$B$5/1440)),"00")&IF(HOUR((المدخلات!$B$4+0*المدخلات!$B$5/1440))<12," ص"," م") -> 5:00–5:15 م | C39: 7 ضد 8 | D39: 1 ضد 6 | E39: 2 ضد 5 | F39: 3 ضد 4 | G39: =COUNTIF(C39:F45,"* ضد *") -> 16 | H39: =G39*2/'ملخص البطولات'!$A$6 -> 4
B40: =MOD(HOUR((المدخلات!$B$4+1*المدخلات!$B$5/1440))-1,12)+1&":"&TEXT(MINUTE((المدخلات!$B$4+1*المدخلات!$B$5/1440)),"00")&"–"&MOD(HOUR((المدخلات!$B$4+1*المدخلات!$B$5/1440+المدخلات!$B$5/1440))-1,12)+1&":"&TEXT(MINUTE((المدخلات!$B$4+1*المدخلات!$B$5/1440+المدخلات!$B$5/1440)),"00")&IF(HOUR((المدخلات!$B$4+1*المدخلات!$B$5/1440))<12," ص"," م") -> 5:15–5:30 م | C40: استراحة (لا توجد مباريات)
B41: =MOD(HOUR((المدخلات!$B$4+2*المدخلات!$B$5/1440))-1,12)+1&":"&TEXT(MINUTE((المدخلات!$B$4+2*المدخلات!$B$5/1440)),"00")&"–"&MOD(HOUR((المدخلات!$B$4+2*المدخلات!$B$5/1440+المدخلات!$B$5/1440))-1,12)+1&":"&TEXT(MINUTE((المدخلات!$B$4+2*المدخلات!$B$5/1440+المدخلات!$B$5/1440)),"00")&IF(HOUR((المدخلات!$B$4+2*المدخلات!$B$5/1440))<12," ص"," م") -> 5:30–5:45 م | C41: 1 ضد 8 | D41: 2 ضد 7 | E41: 3 ضد 6 | F41: 4 ضد 5
...

Sheet 9 فرق
A1: جدول مباريات المجموعات التي فيها 9 فرق
A3: اليوم | B3: الوقت | C3: ملعب 1 | D3: ملعب 2 | E3: ملعب 3 | F3: ملعب 4 | G3: مجموع مباريات اليوم | H3: مباريات كل فريق في اليوم
A4: اليوم 1 | B4: =MOD(HOUR((المدخلات!$B$4+0*المدخلات!$B$5/1440))-1,12)+1&":"&TEXT(MINUTE((المدخلات!$B$4+0*المدخلات!$B$5/1440)),"00")&"–"&MOD(HOUR((المدخلات!$B$4+0*المدخلات!$B$5/1440+المدخلات!$B$5/1440))-1,12)+1&":"&TEXT(MINUTE((المدخلات!$B$4+0*المدخلات!$B$5/1440+المدخلات!$B$5/1440)),"00")&IF(HOUR((المدخلات!$B$4+0*المدخلات!$B$5/1440))<12," ص"," م") -> 5:00–5:15 م | C4: 2 ضد 7 | D4: 3 ضد 9 | G4: =COUNTIF(C4:F12,"* ضد *") -> 18 | H4: =G4*2/'ملخص البطولات'!$A$7 -> 4
B5: =MOD(HOUR((المدخلات!$B$4+1*المدخلات!$B$5/1440))-1,12)+1&":"&TEXT(MINUTE((المدخلات!$B$4+1*المدخلات!$B$5/1440)),"00")&"–"&MOD(HOUR((المدخلات!$B$4+1*المدخلات!$B$5/1440+المدخلات!$B$5/1440))-1,12)+1&":"&TEXT(MINUTE((المدخلات!$B$4+1*المدخلات!$B$5/1440+المدخلات!$B$5/1440)),"00")&IF(HOUR((المدخلات!$B$4+1*المدخلات!$B$5/1440))<12," ص"," م") -> 5:15–5:30 م | C5: 1 ضد 6
B6: =MOD(HOUR((المدخلات!$B$4+2*المدخلات!$B$5/1440))-1,12)+1&":"&TEXT(MINUTE((المدخلات!$B$4+2*المدخلات!$B$5/1440)),"00")&"–"&MOD(HOUR((المدخلات!$B$4+2*المدخلات!$B$5/1440+المدخلات!$B$5/1440))-1,12)+1&":"&TEXT(MINUTE((المدخلات!$B$4+2*المدخلات!$B$5/1440+المدخلات!$B$5/1440)),"00")&IF(HOUR((المدخلات!$B$4+2*المدخلات!$B$5/1440))<12," ص"," م") -> 5:30–5:45 م | C6: 4 ضد 7 | D6: 5 ضد 9 | E6: 2 ضد 8
B7: =MOD(HOUR((المدخلات!$B$4+3*المدخلات!$B$5/1440))-1,12)+1&":"&TEXT(MINUTE((المدخلات!$B$4+3*المدخلات!$B$5/1440)),"00")&"–"&MOD(HOUR((المدخلات!$B$4+3*المدخلات!$B$5/1440+المدخلات!$B$5/1440))-1,12)+1&":"&TEXT(MINUTE((المدخلات!$B$4+3*المدخلات!$B$5/1440+المدخلات!$B$5/1440)),"00")&IF(HOUR((المدخلات!$B$4+3*المدخلات!$B$5/1440))<12," ص"," م") -> 5:45–6:00 م | C7: 3 ضد 6
B8: =MOD(HOUR((المدخلات!$B$4+4*المدخلات!$B$5/1440))-1,12)+1&":"&TEXT(MINUTE((المدخلات!$B$4+4*المدخلات!$B$5/1440)),"00")&"–"&MOD(HOUR((المدخلات!$B$4+4*المدخلات!$B$5/1440+المدخلات!$B$5/1440))-1,12)+1&":"&TEXT(MINUTE((المدخلات!$B$4+4*المدخلات!$B$5/1440+المدخلات!$B$5/1440)),"00")&IF(HOUR((المدخلات!$B$4+4*المدخلات!$B$5/1440))<12," ص"," م") -> 6:00–6:15 م | C8: 4 ضد 9 | D8: 1 ضد 7 | E8: 5 ضد 8
B9: =MOD(HOUR((المدخلات!$B$4+5*المدخلات!$B$5/1440))-1,12)+1&":"&TEXT(MINUTE((المدخلات!$B$4+5*المدخلات!$B$5/1440)),"00")&"–"&MOD(HOUR((المدخلات!$B$4+5*المدخلات!$B$5/1440+المدخلات!$B$5/1440))-1,12)+1&":"&TEXT(MINUTE((المدخلات!$B$4+5*المدخلات!$B$5/1440+المدخلات!$B$5/1440)),"00")&IF(HOUR((المدخلات!$B$4+5*المدخلات!$B$5/1440))<12," ص"," م") -> 6:15–6:30 م | C9: 2 ضد 6
B10: =MOD(HOUR((المدخلات!$B$4+6*المدخلات!$B$5/1440))-1,12)+1&":"&TEXT(MINUTE((المدخلات!$B$4+6*المدخلات!$B$5/1440)),"00")&"–"&MOD(HOUR((المدخلات!$B$4+6*المدخلات!$B$5/1440+المدخلات!$B$5/1440))-1,12)+1&":"&TEXT(MINUTE((المدخلات!$B$4+6*المدخلات!$B$5/1440+المدخلات!$B$5/1440)),"00")&IF(HOUR((المدخلات!$B$4+6*المدخلات!$B$5/1440))<12," ص"," م") -> 6:30–6:45 م | C10: 4 ضد 8 | D10: 3 ضد 7 | E10: 1 ضد 5
