Workbook
Name الحد_الأدنى: [1]المدخلات!$N$3

Sheet أسماء المجموعات
B2: تحت 14 | C2: مجموعة نجران | D2: 1 | E2: نجران | F2: 5
B3: تحت 5 | C3: مجموعة طبرجل | D3: 1 | E3: طبرجل | F3: 5
B4: تحت 7 | C4: مجموعة طبرجل | D4: 1 | E4: طبرجل | F4: 5
B5: تحت 9 | C5: مجموعة الخرج | D5: 1 | E5: الخرج | F5: 5
B6: تحت 12 | C6: مجموعة طبرجل | D6: 1 | E6: طبرجل | F6: 5
B7: تحت 14 | C7: مجموعة طبرجل | D7: 1 | E7: طبرجل | F7: 5
B8: تحت 7 | C8: مجموعة شرورة | D8: 1 | E8: شرورة | F8: 5
B9: تحت 9 | C9: مجموعة شرورة | D9: 1 | E9: شرورة | F9: 5
B10: تحت 9 | C10: مجموعة الدوادمي | D10: 1 | E10: الدوادمي | F10: 5
B11: تحت 11 | C11: مجموعة القريات | D11: 1 | E11: القريات | F11: 5
B12: تحت 12 | C12: مجموعة القريات | D12: 1 | E12: القريات | F12: 5
B13: تحت 13 | C13: مجموعة القريات | D13: 1 | E13: القريات | F13: 5
... B185: تحت 12 | C185: مجموعة جدة | D185: 1 | E185: جدة | F185: 56

Sheet المدخلات
A1: المدخلات
A3: البند | B3: القيمة
A4: وقت بداية اليوم | B4: 0.66666667
A5: مدة المباراة (دقيقة) — ثابت | B5: 15
A6: الحد الأقصى لعدد المهرجانات في الموسم — ثابت | B6: 7
A7: ملاعب مصغّرة داخل الملعب القانوني — ثابت | B7: 4
A8: مستهدف مباريات الفريق في الموسم (حد أعلى) — ثابت | B8: 28
A9: مباريات الفريق في المهرجان الواحد — ثابت | B9: 4
A10: عدد الحكام لكل ملعب مصغّر — ثابت | B10: 1

Sheet المبادئ
A1: مبادئ بناء جداول المجموعات (من 5 إلى 22 فريقاً)
A3: # | B3: المبدأ | C3: الشرح
A4: 1 | B4: لا يلعب الفريق مباراتين ورا بعض | C4: القاعدة الأهم: لا يلعب أي فريق مباراتين متتاليتين أبدًا؛ بين مباراتيه فترة راحة كاملة على الأقل (15 دقيقة)، والتتابع صفر في جميع البطولات. ولا توجد راحة 45 دقيقة (ولا أطول) في أي جدول — الصفر في كل الجداول. المجموعات الزوجية (6 و8، ومجموعتا 12 (6+6) و16 (8+8)، ومجموعة الستة في 13، ومجموعة الثمانية في 15 و17) راحتها 15 دقيقة فقط. أما المجموعات الفردية (5 و7 و9 و11، ومجموعة السبعة في 13 و15، ومجموعة التسعة في 17، ومجموعتا الأحد عشر في 22) فلا يمكن رياضيًا أن تكون راحتها كلها 15 دقيقة، لأن فريقًا واحدًا على الأقل يجلس في كل فترة؛ فتُوزَّع مباريات الفرق على فترات متناوبة، ويحصل بعض الفرق على راحة 30 دقيقة مرة واحدة أو أكثر في اليوم بدل 45 دقيقة، وهي أقل قيمة ممكنة (6 راحات من 30 دقيقة في اليوم لكل مجموعة فردية، و7 في مجموعة 5 فرق).
A5: 2 | B5: طول اليوم وعدد الفترات | C5: المجموعة ذات العدد الزوجي: 7 فترات (4 فترات لعب + 3 استراحات)، وجميع فرقها تلعب في كل فترة لعب. المجموعة ذات العدد الفردي: 9 فترات (10 فترات في مجموعة 5 فرق)، يلعب في كل فترة بعض الفرق ويجلس الباقي، ويلعب كل فريق 4 مباريات في اليوم. والمهرجان الأخير وحده يختلف طوله تبعًا لمبارياته: 9 فترات لمجموعة الستة (5 مباريات بعد دمج المباراة الزائدة) في 6 و12 و13.
A6: 3 | B6: عدالة عدد المباريات | C6: 4 مباريات لكل فريق في كل مهرجان، وكل فرق المجموعة الواحدة تلعب العدد نفسه في اليوم وفي الموسم، ولا يستريح أي فريق مهرجانًا كاملًا. وإذا بقيت مباراة واحدة للفريق في مهرجان مستقل، دُمجت مع المهرجان الذي قبله. فالمهرجان الأخير وحده قد يختلف: 5 مباريات لكل فريق في مجموعة الستة (6 و12 و13)؛ أما في 15 و17 فتلعب المجموعة الفردية (السبعة في 15، والتسعة في 17) 4 مباريات في كل مهرجان بما فيها الأخير، مثل المجموعة الزوجية معها، فيصل عدد مباريات كل فريق إلى 28 في الموسم؛ وفي المهرجان الأخير يبدأ دور جديد جزئي بعد اكتمال الأدوار الكاملة، دون تكرار أي لقاء داخل المهرجان الواحد. وعدد المهرجانات واحد لكل المجموعات داخل البطولة الواحدة.
A7: 4 | B7: عدالة المواجهات (تساوٍ تام) | C7: يُختار عدد الأدوار بأكبر قيمة يبقى معها (الأدوار × عدد الخصوم) أقل من أو يساوي 28 مباراة: 5 فرق ← 7 أدوار × 4 = 28؛ 6 فرق ← 5 أدوار × 5 = 25؛ 7 فرق ← 4 × 6 = 24؛ 8 فرق ← 4 × 7 = 28؛ 9 فرق ← 3 × 8 = 24؛ 11 فريقًا ← 2 × 10 = 20.
A8: 5 | B8: تقسيم المجموعات عند الأعداد الكبيرة | C8: لكل مجموعة ملعب قانوني واحد (4 ملاعب مصغّرة)، وعدد الملاعب القانونية في البطولة لا يزيد على عدد مجموعاتها. لذلك تُقسّم الفرق التي تحتاج مجموعتها أكثر من 4 ملاعب مصغّرة إلى مجموعات فرعية بحيث يقترب ناتج (الأدوار × عدد الخصوم) من 28 مباراة دون تجاوزها، ولا تقل المجموعة عن 6 فرق، ويُفضل العدد الزوجي لإلغاء راحة 45 دقيقة. التقسيم المعتمد: 12 = 6 + 6، و13 = 6 + 7، و15 = 7 + 8، و16 = 8 + 8، و17 = 8 + 9، و22 = 11 + 11؛ وتبقى 5 و6 و7 و8 و9 و11 مجموعة واحدة. (الأعداد الفردية لا يمكن أن تخلو من مجموعة فردية واحدة على الأقل.)
A9: 6 | B9: اكتمال الدورة قبل التكرار | C9: يلتقي كل فريق بجميع خصومه في مجموعته مرة واحدة قبل أن يتكرر أي لقاء، ولا يتكرر لقاء الزوج نفسه داخل المهرجان الواحد إطلاقًا. وهذا متحقق في جميع المجموعات، ومنها المجموعات التي لا تنتهي فيها الدورة مع نهاية المهرجان (مجموعات 7 و11 مثلًا)، فتستمر الدورة من مهرجان إلى الذي يليه دون تكرار لأي لقاء قبل اكتمالها، مع الإبقاء على 4 مباريات لكل فريق في كل مهرجان.
A10: 7 | B10: عدالة توزيع الأوقات | C10: لا يتكرّر على فريق بعينه أن يبدأ أوّل فترة كل يوم، ولا أن ينال راحة 30 دقيقة دائمًا. في المجموعات الزوجية تلعب كل الفرق في كل فترة فالعدالة تامة تلقائيًا. وفي المجموعات الفردية تُوزَّع الراحات ذات 30 دقيقة وأوقات البدء بالتناوب على الفرق قدر الإمكان، بحيث لا يزيد الفرق بين أي فريقين في عدد مرات راحة 30 دقيقة عن مرتين في الموسم (وعن مرة واحدة في مجموعة 7 فرق)، ويُعرض عدد الراحات لكل فريق في الجداول المساعدة الملحقة بكل ورقة.

Sheet ملخص البطولات
A1: ملخص جداول المجموعات
A3: عدد الفرق | B3: عدد المجموعات | C3: توزيع الفرق في المجموعات | D3: عدد الأدوار | E3: مباريات كل فريق في الموسم | F3: عدد المهرجانات | G3: توزيع مباريات الفريق على المهرجانات | H3: وقت البداية | I3: وقت النهاية | J3: مدة اليوم | K3: عدد الملاعب (5 ضد 5) | L3: عدد الملاعب القانونية | M3: عدد البطولات
A4: 5 | B4: 1 | C4: 5 | D4: =COUNTIF('5 فرق'!$C$4:$C$73,"* ضد *")*2/5/4 -> 7 | E4: =COUNTIF('5 فرق'!$C$4:$C$73,"* ضد *")*2/5 -> 28 | F4: =COUNTIF('5 فرق'!$A$4:$A$73,"اليوم *") -> 7 | G4: ='5 فرق'!E4&" مباريات في "&COUNTIF('5 فرق'!$E$4:$E$73,'5 فرق'!E4)&" مهرجانات"&IF('5 فرق'!E64='5 فرق'!E4,"","، ثم "&'5 فرق'!E64&" مباريات في المهرجان الأخير")&" (المجموع "&E4&")" -> 4 مباريات في 7 مهرجانات (المجموع 28) | H4: =المدخلات!$B$4 -> 0.66666667 | I4: =H4+J4 -> 0.77083333 | J4: =COUNTA('5 فرق'!B4:B13)*المدخلات!$B$5/1440 -> 0.10416667 | K4: =COUNTIF('5 فرق'!$C$3:$C$3,"ملعب *") -> 1 | L4: =ROUNDUP(K4/المدخلات!$B$7,0) -> 1 | M4: 1
A5: 6 | B5: 1 | C5: 6 | D5: =COUNTIF('6 فرق'!$C$4:$E$47,"* ضد *")*2/6/5 -> 5 | E5: =COUNTIF('6 فرق'!$C$4:$E$47,"* ضد *")*2/6 -> 25 | F5: =COUNTIF('6 فرق'!$A$4:$A$47,"اليوم *") -> 6 | G5: ='6 فرق'!G4&" مباريات في "&COUNTIF('6 فرق'!$G$4:$G$47,'6 فرق'!G4)&" مهرجانات"&IF('6 فرق'!G39='6 فرق'!G4,"","، ثم "&IF('6 فرق'!G39=1,"مباراة واحدة",IF('6 فرق'!G39=2,"مباراتان",'6 فرق'!G39&" مباريات"))&" في المهرجان الأخير")&" (المجموع "&E5&")" -> 4 مباريات في 5 مهرجانات، ثم 5 مباريات في المهرجان الأخير (المجموع 25) | H5: =المدخلات!$B$4 -> 0.66666667 | I5: =H5+J5 -> 0.76041667 | J5: =COUNTA('6 فرق'!B39:B47)*المدخلات!$B$5/1440 -> 0.09375 | K5: =COUNTIF('6 فرق'!$C$3:$E$3,"ملعب *") -> 3 | L5: =ROUNDUP(K5/المدخلات!$B$7,0) -> 1 | M5: 3
A6: 7 | B6: 1 | C6: 7 | D6: =COUNTIF('7 فرق'!$C$4:$D$57,"* ضد *")*2/7/6 -> 4 | E6: =COUNTIF('7 فرق'!$C$4:$D$57,"* ضد *")*2/7 -> 24 | F6: =COUNTIF('7 فرق'!$A$4:$A$57,"اليوم *") -> 6 | G6: ='7 فرق'!F4&" مباريات في "&COUNTIF('7 فرق'!$F$4:$F$57,'7 فرق'!F4)&" مهرجانات"&IF('7 فرق'!F49='7 فرق'!F4,"","، ثم "&'7 فرق'!F49&" مباريات في المهرجان الأخير")&" (المجموع "&E6&")" -> 4 مباريات في 6 مهرجانات (المجموع 24) | H6: =المدخلات!$B$4 -> 0.66666667 | I6: =H6+J6 -> 0.76041667 | J6: =COUNTA('7 فرق'!B4:B12)*المدخلات!$B$5/1440 -> 0.09375 | K6: =COUNTIF('7 فرق'!$C$3:$D$3,"ملعب *") -> 2 | L6: =ROUNDUP(K6/المدخلات!$B$7,0) -> 1 | M6: 2
A7: 8 | B7: 1 | C7: 8 | D7: =COUNTIF('8 فرق'!$C$4:$F$52,"* ضد *")*2/8/7 -> 4 | E7: =COUNTIF('8 فرق'!$C$4:$F$52,"* ضد *")*2/8 -> 28 | F7: =COUNTIF('8 فرق'!$A$4:$A$52,"اليوم *") -> 7 | G7: ='8 فرق'!H4&" مباريات في "&COUNTIF('8 فرق'!$H$4:$H$52,'8 فرق'!H4)&" مهرجانات"&IF('8 فرق'!H46='8 فرق'!H4,"","، ثم "&IF('8 فرق'!H46=1,"مباراة واحدة",IF('8 فرق'!H46=2,"مباراتان",'8 فرق'!H46&" مباريات"))&" في المهرجان الأخير")&" (المجموع "&E7&")" -> 4 مباريات في 7 مهرجانات (المجموع 28) | H7: =المدخلات!$B$4 -> 0.66666667 | I7: =H7+J7 -> 0.73958333 | J7: =COUNTA('8 فرق'!B4:B10)*المدخلات!$B$5/1440 -> 0.072916667 | K7: =COUNTIF('8 فرق'!$C$3:$F$3,"ملعب *") -> 4 | L7: =ROUNDUP(K7/المدخلات!$B$7,0) -> 1 | M7: 3
A8: 9 | B8: 1 | C8: 9 | D8: =COUNTIF('9 فرق'!$C$4:$E$57,"* ضد *")*2/9/8 -> 3 | E8: =COUNTIF('9 فرق'!$C$4:$E$57,"* ضد *")*2/9 -> 24 | F8: =COUNTIF('9 فرق'!$A$4:$A$57,"اليوم *") -> 6 | G8: ='9 فرق'!G4&" مباريات في "&COUNTIF('9 فرق'!$G$4:$G$57,'9 فرق'!G4)&" مهرجانات"&IF('9 فرق'!G49='9 فرق'!G4,"","، ثم "&'9 فرق'!G49&" مباريات في المهرجان الأخير")&" (المجموع "&E8&")" -> 4 مباريات في 6 مهرجانات (المجموع 24) | H8: =المدخلات!$B$4 -> 0.66666667 | I8: =H8+J8 -> 0.76041667 | J8: =COUNTA('9 فرق'!B4:B12)*المدخلات!$B$5/1440 -> 0.09375 | K8: =COUNTIF('9 فرق'!$C$3:$E$3,"ملعب *") -> 3 | L8: =ROUNDUP(K8/المدخلات!$B$7,0) -> 1 | M8: 3
A9: 11 | B9: 1 | C9: 11 | D9: =COUNTIF('11 فريقًا'!$C$4:$F$48,"* ضد *")*2/11/10 -> 2 | E9: =COUNTIF('11 فريقًا'!$C$4:$F$48,"* ضد *")*2/11 -> 20 | F9: =COUNTIF('11 فريقًا'!$A$4:$A$48,"اليوم *") -> 5 | G9: ='11 فريقًا'!H4&" مباريات في "&COUNTIF('11 فريقًا'!$H$4:$H$48,'11 فريقًا'!H4)&" مهرجانات"&IF('11 فريقًا'!H40='11 فريقًا'!H4,"","، ثم "&'11 فريقًا'!H40&" مباريات في المهرجان الأخير")&" (المجموع "&E9&")" -> 4 مباريات في 5 مهرجانات (المجموع 20) | H9: =المدخلات!$B$4 -> 0.66666667 | I9: =H9+J9 -> 0.76041667 | J9: =COUNTA('11 فريقًا'!B4:B12)*المدخلات!$B$5/1440 -> 0.09375 | K9: =COUNTIF('11 فريقًا'!$C$3:$F$3,"ملعب *") -> 4 | L9: =ROUNDUP(K9/المدخلات!$B$7,0) -> 1 | M9: 1
A10: 12 | B10: 2 | C10: أ: 6 | ب: 6 | D10: =COUNTIF('12 فريقًا'!$C$4:$E$57,"* ضد *")*2/6/5&_xlfn.UNICHAR(8206)&" + "&_xlfn.UNICHAR(8206)&COUNTIF('12 فريقًا'!$F$4:$H$57,"* ضد *")*2/6/5 -> 5‎ + ‎5 | E10: =COUNTIF('12 فريقًا'!$C$4:$E$57,"* ضد *")*2/6&_xlfn.UNICHAR(8206)&" + "&_xlfn.UNICHAR(8206)&COUNTIF('12 فريقًا'!$F$4:$H$57,"* ضد *")*2/6 -> 25‎ + ‎25 | F10: =COUNTIF('12 فريقًا'!$A$4:$A$57,"اليوم *") -> 6 | G10: ="أ: "&'12 فريقًا'!J4&" مباريات في "&COUNTIF('12 فريقًا'!$J$4:$J$57,'12 فريقًا'!J4)&" مهرجانات"&IF('12 فريقًا'!J49='12 فريقًا'!J4,"","، ثم "&'12 فريقًا'!J49&" مباريات في المهرجان الأخير")&" (المجموع "&SUM('12 فريقًا'!$J$4:$J$57)&")"&" | "&"ب: "&'12 فريقًا'!K4&" مباريات في "&COUNTIF('12 فريقًا'!$K$4:$K$57,'12 فريقًا'!K4)&" مهرجانات"&IF('12 فريقًا'!K49='12 فريقًا'!K4,"","، ثم "&'12 فريقًا'!K49&" مباريات في المهرجان الأخير")&" (المجموع "&SUM('12 فريقًا'!$K$4:$K$57)&")" -> أ: 4 مباريات في 5 مهرجانات، ثم 5 مباريات في المهرجان الأخير (المجموع 25) | ب: 4 مباريات في 5 مهرجانات، ثم 5 مباريات في المهرجان الأخير (المجموع 25) | H10: =المدخلات!$B$4 -> 0.66666667 | I10: =H10+J10 -> 0.76041667 | J10: =COUNTA('12 فريقًا'!B4:B12)*المدخلات!$B$5/1440 -> 0.09375 | K10: =COUNTIF('12 فريقًا'!$C$3:$H$3,"ملعب *") -> 6 | L10: =ROUNDUP(K10/المدخلات!$B$7,0) -> 2 | M10: 2
A11: 13 | B11: 2 | C11: أ: 6 | ب: 7 | D11: =COUNTIF('13 فريقًا'!$C$4:$E$57,"* ضد *")*2/6/5&_xlfn.UNICHAR(8206)&" + "&_xlfn.UNICHAR(8206)&COUNTIF('13 فريقًا'!$F$4:$G$57,"* ضد *")*2/7/6 -> 5‎ + ‎4 | E11: =COUNTIF('13 فريقًا'!$C$4:$E$57,"* ضد *")*2/6&_xlfn.UNICHAR(8206)&" + "&_xlfn.UNICHAR(8206)&COUNTIF('13 فريقًا'!$F$4:$G$57,"* ضد *")*2/7 -> 25‎ + ‎24 | F11: =COUNTIF('13 فريقًا'!$A$4:$A$57,"اليوم *") -> 6 | G11: ="أ: "&'13 فريقًا'!I4&" مباريات في "&COUNTIF('13 فريقًا'!$I$4:$I$57,'13 فريقًا'!I4)&" مهرجانات"&IF('13 فريقًا'!I49='13 فريقًا'!I4,"","، ثم "&'13 فريقًا'!I49&" مباريات في المهرجان الأخير")&" (المجموع "&SUM('13 فريقًا'!$I$4:$I$57)&")"&" | "&"ب: "&'13 فريقًا'!J4&" مباريات في "&COUNTIF('13 فريقًا'!$J$4:$J$57,'13 فريقًا'!J4)&" مهرجانات"&IF('13 فريقًا'!J49='13 فريقًا'!J4,"","، ثم "&'13 فريقًا'!J49&" مباريات في المهرجان الأخير")&" (المجموع "&SUM('13 فريقًا'!$J$4:$J$57)&")" -> أ: 4 مباريات في 5 مهرجانات، ثم 5 مباريات في المهرجان الأخير (المجموع 25) | ب: 4 مباريات في 6 مهرجانات (المجموع 24) | H11: =المدخلات!$B$4 -> 0.66666667 | I11: =H11+J11 -> 0.76041667 | J11: =COUNTA('13 فريقًا'!B4:B12)*المدخلات!$B$5/1440 -> 0.09375 | K11: =COUNTIF('13 فريقًا'!$C$3:$G$3,"ملعب *") -> 5 | L11: =ROUNDUP(K11/المدخلات!$B$7,0) -> 2 | M11: 2
A12: 15 | B12: 2 | C12: أ: 7 | ب: 8 | D12: ="أ: "&INT(COUNTIF('15 فريقًا'!$C$4:$D$66,"* ضد *")*2/7/6)&" أدوار"&IF(MOD(COUNTIF('15 فريقًا'!$C$4:$D$66,"* ضد *")*2/7,6)=0,""," + "&MOD(COUNTIF('15 فريقًا'!$C$4:$D$66,"* ضد *")*2/7,6)&" مباريات")&" | ب: "&INT(COUNTIF('15 فريقًا'!$E$4:$H$66,"* ضد *")*2/8/7)&" أدوار"&IF(MOD(COUNTIF('15 فريقًا'!$E$4:$H$66,"* ضد *")*2/8,7)=0,""," + "&MOD(COUNTIF('15 فريقًا'!$E$4:$H$66,"* ضد *")*2/8,7)&" مباريات") -> أ: 4 أدوار + 4 مباريات | ب: 4 أدوار | E12: =COUNTIF('15 فريقًا'!$C$4:$D$66,"* ضد *")*2/7&_xlfn.UNICHAR(8206)&" + "&_xlfn.UNICHAR(8206)&COUNTIF('15 فريقًا'!$E$4:$H$66,"* ضد *")*2/8 -> 28‎ + ‎28 | F12: =COUNTIF('15 فريقًا'!$A$4:$A$66,"اليوم *") -> 7 | G12: ="أ: "&'15 فريقًا'!J4&" مباريات في "&COUNTIF('15 فريقًا'!$J$4:$J$66,'15 فريقًا'!J4)&" مهرجانات"&IF('15 فريقًا'!J58='15 فريقًا'!J4,"","، ثم "&'15 فريقًا'!J58&" مباريات في المهرجان الأخير")&" (المجموع "&SUM('15 فريقًا'!$J$4:$J$66)&")"&" | "&"ب: "&'15 فريقًا'!K4&" مباريات في "&COUNTIF('15 فريقًا'!$K$4:$K$66,'15 فريقًا'!K4)&" مهرجانات"&IF('15 فريقًا'!K58='15 فريقًا'!K4,"","، ثم "&'15 فريقًا'!K58&" مباريات في المهرجان الأخير")&" (المجموع "&SUM('15 فريقًا'!$K$4:$K$66)&")" -> أ: 4 مباريات في 7 مهرجانات (المجموع 28) | ب: 4 مباريات في 7 مهرجانات (المجموع 28) | H12: =المدخلات!$B$4 -> 0.66666667 | I12: =H12+J12 -> 0.76041667 | J12: =COUNTA('15 فريقًا'!B4:B12)*المدخلات!$B$5/1440 -> 0.09375 | K12: =COUNTIF('15 فريقًا'!$C$3:$H$3,"ملعب *") -> 6 | L12: =ROUNDUP(K12/المدخلات!$B$7,0) -> 2 | M12: 1
A13: 16 | B13: 2 | C13: أ: 8 | ب: 8 | D13: =COUNTIF('16 فريقًا'!$C$4:$F$52,"* ضد *")*2/8/7&_xlfn.UNICHAR(8206)&" + "&_xlfn.UNICHAR(8206)&COUNTIF('16 فريقًا'!$G$4:$J$52,"* ضد *")*2/8/7 -> 4‎ + ‎4 | E13: =COUNTIF('16 فريقًا'!$C$4:$F$52,"* ضد *")*2/8&_xlfn.UNICHAR(8206)&" + "&_xlfn.UNICHAR(8206)&COUNTIF('16 فريقًا'!$G$4:$J$52,"* ضد *")*2/8 -> 28‎ + ‎28 | F13: =COUNTIF('16 فريقًا'!$A$4:$A$52,"اليوم *") -> 7 | G13: ="كل مجموعة: "&'16 فريقًا'!L4&" مباريات في "&COUNTIF('16 فريقًا'!$L$4:$L$52,'16 فريقًا'!L4)&" مهرجانات (المجموع "&('16 فريقًا'!L4*COUNTIF('16 فريقًا'!$L$4:$L$52,'16 فريقًا'!L4))&" لكل فريق)" -> كل مجموعة: 4 مباريات في 7 مهرجانات (المجموع 28 لكل فريق) | H13: =المدخلات!$B$4 -> 0.66666667 | I13: =H13+J13 -> 0.73958333 | J13: =COUNTA('16 فريقًا'!B4:B10)*المدخلات!$B$5/1440 -> 0.072916667 | K13: =COUNTIF('16 فريقًا'!$C$3:$J$3,"ملعب *") -> 8 | L13: =ROUNDUP(K13/المدخلات!$B$7,0) -> 2 | M13: 1
A14: 17 | B14: 2 | C14: أ: 8 | ب: 9 | D14: ="أ: "&INT(COUNTIF('17 فريقًا'!$C$4:$F$66,"* ضد *")*2/8/7)&" أدوار"&IF(MOD(COUNTIF('17 فريقًا'!$C$4:$F$66,"* ضد *")*2/8,7)=0,""," + "&MOD(COUNTIF('17 فريقًا'!$C$4:$F$66,"* ضد *")*2/8,7)&" مباريات")&" | ب: "&INT(COUNTIF('17 فريقًا'!$G$4:$J$66,"* ضد *")*2/9/8)&" أدوار"&IF(MOD(COUNTIF('17 فريقًا'!$G$4:$J$66,"* ضد *")*2/9,8)=0,""," + "&MOD(COUNTIF('17 فريقًا'!$G$4:$J$66,"* ضد *")*2/9,8)&" مباريات") -> أ: 4 أدوار | ب: 3 أدوار + 4 مباريات | E14: =COUNTIF('17 فريقًا'!$C$4:$F$66,"* ضد *")*2/8&_xlfn.UNICHAR(8206)&" + "&_xlfn.UNICHAR(8206)&COUNTIF('17 فريقًا'!$G$4:$J$66,"* ضد *")*2/9 -> 28‎ + ‎28 | F14: =COUNTIF('17 فريقًا'!$A$4:$A$66,"اليوم *") -> 7 | G14: ="أ: "&'17 فريقًا'!L4&" مباريات في "&COUNTIF('17 فريقًا'!$L$4:$L$66,'17 فريقًا'!L4)&" مهرجانات"&IF('17 فريقًا'!L58='17 فريقًا'!L4,"","، ثم "&'17 فريقًا'!L58&" مباريات في المهرجان الأخير")&" (المجموع "&SUM('17 فريقًا'!$L$4:$L$66)&")"&" | "&"ب: "&'17 فريقًا'!M4&" مباريات في "&COUNTIF('17 فريقًا'!$M$4:$M$66,'17 فريقًا'!M4)&" مهرجانات"&IF('17 فريقًا'!M58='17 فريقًا'!M4,"","، ثم "&'17 فريقًا'!M58&" مباريات في المهرجان الأخير")&" (المجموع "&SUM('17 فريقًا'!$M$4:$M$66)&")" -> أ: 4 مباريات في 7 مهرجانات (المجموع 28) | ب: 4 مباريات في 7 مهرجانات (المجموع 28) | H14: =المدخلات!$B$4 -> 0.66666667 | I14: =H14+J14 -> 0.76041667 | J14: =COUNTA('17 فريقًا'!B4:B12)*المدخلات!$B$5/1440 -> 0.09375 | K14: =COUNTIF('17 فريقًا'!$C$3:$J$3,"ملعب *") -> 8 | L14: =ROUNDUP(K14/المدخلات!$B$7,0) -> 2 | M14: 1
A15: 22 | B15: 2 | C15: أ: 11 | ب: 11 | D15: =COUNTIF('22 فريقًا'!$C$4:$F$48,"* ضد *")*2/11/10&_xlfn.UNICHAR(8206)&" + "&_xlfn.UNICHAR(8206)&COUNTIF('22 فريقًا'!$G$4:$J$48,"* ضد *")*2/11/10 -> 2‎ + ‎2 | E15: =COUNTIF('22 فريقًا'!$C$4:$F$48,"* ضد *")*2/11&_xlfn.UNICHAR(8206)&" + "&_xlfn.UNICHAR(8206)&COUNTIF('22 فريقًا'!$G$4:$J$48,"* ضد *")*2/11 -> 20‎ + ‎20 | F15: =COUNTIF('22 فريقًا'!$A$4:$A$48,"اليوم *") -> 5 | G15: ="أ: "&'22 فريقًا'!L4&" مباريات في "&COUNTIF('22 فريقًا'!$L$4:$L$48,'22 فريقًا'!L4)&" مهرجانات"&IF('22 فريقًا'!L40='22 فريقًا'!L4,"","، ثم "&'22 فريقًا'!L40&" مباريات في المهرجان الأخير")&" (المجموع "&SUM('22 فريقًا'!$L$4:$L$48)&")"&" | "&"ب: "&'22 فريقًا'!M4&" مباريات في "&COUNTIF('22 فريقًا'!$M$4:$M$48,'22 فريقًا'!M4)&" مهرجانات"&IF('22 فريقًا'!M40='22 فريقًا'!M4,"","، ثم "&'22 فريقًا'!M40&" مباريات في المهرجان الأخير")&" (المجموع "&SUM('22 فريقًا'!$M$4:$M$48)&")" -> أ: 4 مباريات في 5 مهرجانات (المجموع 20) | ب: 4 مباريات في 5 مهرجانات (المجموع 20) | H15: =المدخلات!$B$4 -> 0.66666667 | I15: =H15+J15 -> 0.76041667 | J15: =COUNTA('22 فريقًا'!B4:B12)*المدخلات!$B$5/1440 -> 0.09375 | K15: =COUNTIF('22 فريقًا'!$C$3:$J$3,"ملعب *") -> 8 | L15: =ROUNDUP(K15/المدخلات!$B$7,0) -> 2 | M15: 1
A16: إجمالي عدد البطولات | M16: =SUM(M4:M15) -> 21
A18: توزيع فترات الراحة بين مباراتي الفريق في المهرجان الواحد
A19: عدد الفرق | B19: راحة 15 دقيقة | C19: راحة 30 دقيقة | D19: راحة 45 دقيقة | E19: إجمالي فترات الراحة | F19: نسبة الراحة القصيرة
A20: 5 | B20: ='5 فرق'!L9 -> 56 | C20: ='5 فرق'!M9 -> 49 | D20: ='5 فرق'!N9 -> 0 | E20: =B20+C20+D20 -> 105 | F20: =B20/E20 -> 0.53333333
A21: 6 | B21: 114 | C21: 0 | D21: 0 | E21: =B21+C21+D21 -> 114 | F21: =B21/E21 -> 1
A22: 7 | B22: ='7 فرق'!M11 -> 90 | C22: ='7 فرق'!N11 -> 36 | D22: ='7 فرق'!O11 -> 0 | E22: =B22+C22+D22 -> 126 | F22: =B22/E22 -> 0.71428571
A23: 8 | B23: 168 | C23: 0 | D23: 0 | E23: =B23+C23+D23 -> 168 | F23: =B23/E23 -> 1
A24: 9 | B24: ='9 فرق'!N13 -> 126 | C24: ='9 فرق'!O13 -> 36 | D24: ='9 فرق'!P13 -> 0 | E24: =B24+C24+D24 -> 162 | F24: =B24/E24 -> 0.77777778
A25: 11 | B25: ='11 فريقًا'!O15 -> 135 | C25: ='11 فريقًا'!P15 -> 30 | D25: ='11 فريقًا'!Q15 -> 0 | E25: =B25+C25+D25 -> 165 | F25: =B25/E25 -> 0.81818182
A26: 12 | B26: ='12 فريقًا'!R16 -> 228 | C26: ='12 فريقًا'!S16 -> 0 | D26: ='12 فريقًا'!T16 -> 0 | E26: =B26+C26+D26 -> 228 | F26: =B26/E26 -> 1
A27: 13 | B27: ='13 فريقًا'!Q17 -> 204 | C27: ='13 فريقًا'!R17 -> 36 | D27: ='13 فريقًا'!S17 -> 0 | E27: =B27+C27+D27 -> 240 | F27: =B27/E27 -> 0.85
A28: 15 | B28: ='15 فريقًا'!R19 -> 273 | C28: ='15 فريقًا'!S19 -> 42 | D28: ='15 فريقًا'!T19 -> 0 | E28: =B28+C28+D28 -> 315 | F28: =B28/E28 -> 0.86666667
A29: 16 | B29: =(COUNTIF('16 فريقًا'!$C$4:$J$52,"* ضد *")*2/A29-F13)*A29 -> 336 | C29: 0 | D29: 0 | E29: =B29+C29+D29 -> 336 | F29: =B29/E29 -> 1
A30: 17 | B30: ='17 فريقًا'!U21 -> 307 | C30: ='17 فريقًا'!V21 -> 50 | D30: ='17 فريقًا'!W21 -> 0 | E30: =B30+C30+D30 -> 357 | F30: =B30/E30 -> 0.85994398
A31: 22 | B31: ='22 فريقًا'!T26 -> 270 | C31: ='22 فريقًا'!U26 -> 60 | D31: ='22 فريقًا'!V26 -> 0 | E31: =B31+C31+D31 -> 330 | F31: =B31/E31 -> 0.81818182
A34: عدد الملاعب اللازمة لتحت 5 (كل البطولات الـ 21)
A35: أكبر عدد ملاعب قانونية تحتاجه بطولة واحدة | F35: =MAX(L4:L15) -> 2
A36: الملاعب المصغّرة إذا أُقيمت كل البطولات في وقت واحد | F36: =SUMPRODUCT(K4:K15,M4:M15) -> 91
A37: الملاعب القانونية إذا أُقيمت كل البطولات في وقت واحد (لكل بطولة ما تحتاجه) | F37: =SUMPRODUCT(L4:L15,M4:M15) -> 29
A38: الملاعب القانونية إذا رُتّبت الملاعب المصغّرة بلا هدر | F38: =ROUNDUP(F36/المدخلات!$B$7,0) -> 23

Sheet ملخص المجموعات
A1: المجموعات المعتمدة في فئة تحت 5 — الفرق والملاعب والمباريات
A3: عدد الفرق في المجموعة | B3: مباريات كل فريق في اليوم | C3: مباريات المجموعة في اليوم | D3: إجمالي فترات اليوم (مع الاستراحات) | E3: فترات اللعب في اليوم | F3: أقل عدد ملاعب مصغّرة بحساب السعة | G3: نوع المجموعة | H3: أقصى مباريات مسموحة (فترة لعب للزوجية / فترتان متتاليتان للفردية) | I3: عدد الملاعب المصغّرة المطلوبة | J3: لماذا هذا العدد من الملاعب؟
A4: ='ملخص البطولات'!A4 -> 5 | B4: =المدخلات!$B$9 -> 4 | C4: =A4*B4/2 -> 10 | D4: =MATCH("اليوم 2",'5 فرق'!$A:$A,0)-MATCH("اليوم 1",'5 فرق'!$A:$A,0) -> 10 | E4: =IF(G4="زوجية",(D4+1)/2,D4) -> 10 | F4: =ROUNDUP(C4/E4,0) -> 1 | G4: =IF(MOD(A4,2)=0,"زوجية","فردية") -> فردية | H4: =IF(G4="زوجية",A4/2,INT(A4/2)) -> 2 | I4: ='ملخص البطولات'!K4 -> 1 | J4: =IF(G4="زوجية","كل الفرق الـ "&A4&" تلعب في كل فترة لعب ("&H4&" مباريات متزامنة، كل مباراة على ملعب) ثم تأتي فترة استراحة قبل التالية، فالمطلوب "&I4&" ملاعب.","لا يلعب فريق مباراتين متتاليتين، فمجموع المباريات في أي فترتين متتاليتين لا يزيد على "&H4&"؛ ولتوزيع مباريات اليوم ("&C4&") على "&E4&" فترات لعب يكفي حسابيًا عدد ملاعب = "&F4&IF(I4>F4,"، لكن الجدول يتناوب في بعض الأيام بين فترات فيها مباريات أكثر وأقل، فتبلغ الذروة "&I4&" ملاعب.","، وهذا ما تستخدمه المجموعة.")) -> لا يلعب فريق مباراتين متتاليتين، فمجموع المباريات في أي فترتين متتاليتين لا يزيد على 2؛ ولتوزيع مباريات اليوم (10) على 10 فترات لعب يكفي حسابيًا عدد ملاعب = 1، وهذا ما تستخدمه المجموعة.
A5: ='ملخص البطولات'!A5 -> 6 | B5: =المدخلات!$B$9 -> 4 | C5: =A5*B5/2 -> 12 | D5: =MATCH("اليوم 2",'6 فرق'!$A:$A,0)-MATCH("اليوم 1",'6 فرق'!$A:$A,0) -> 7 | E5: =IF(G5="زوجية",(D5+1)/2,D5) -> 4 | F5: =ROUNDUP(C5/E5,0) -> 3 | G5: =IF(MOD(A5,2)=0,"زوجية","فردية") -> زوجية | H5: =IF(G5="زوجية",A5/2,INT(A5/2)) -> 3 | I5: ='ملخص البطولات'!K5 -> 3 | J5: =IF(G5="زوجية","كل الفرق الـ "&A5&" تلعب في كل فترة لعب ("&H5&" مباريات متزامنة، كل مباراة على ملعب) ثم تأتي فترة استراحة قبل التالية، فالمطلوب "&I5&" ملاعب.","لا يلعب فريق مباراتين متتاليتين، فمجموع المباريات في أي فترتين متتاليتين لا يزيد على "&H5&"؛ ولتوزيع مباريات اليوم ("&C5&") على "&E5&" فترات لعب يكفي حسابيًا عدد ملاعب = "&F5&IF(I5>F5,"، لكن الجدول يتناوب في بعض الأيام بين فترات فيها مباريات أكثر وأقل، فتبلغ الذروة "&I5&" ملاعب.","، وهذا ما تستخدمه المجموعة.")) -> كل الفرق الـ 6 تلعب في كل فترة لعب (3 مباريات متزامنة، كل مباراة على ملعب) ثم تأتي فترة استراحة قبل التالية، فالمطلوب 3 ملاعب.
A6: ='ملخص البطولات'!A6 -> 7 | B6: =المدخلات!$B$9 -> 4 | C6: =A6*B6/2 -> 14 | D6: =MATCH("اليوم 2",'7 فرق'!$A:$A,0)-MATCH("اليوم 1",'7 فرق'!$A:$A,0) -> 9 | E6: =IF(G6="زوجية",(D6+1)/2,D6) -> 9 | F6: =ROUNDUP(C6/E6,0) -> 2 | G6: =IF(MOD(A6,2)=0,"زوجية","فردية") -> فردية | H6: =IF(G6="زوجية",A6/2,INT(A6/2)) -> 3 | I6: ='ملخص البطولات'!K6 -> 2 | J6: =IF(G6="زوجية","كل الفرق الـ "&A6&" تلعب في كل فترة لعب ("&H6&" مباريات متزامنة، كل مباراة على ملعب) ثم تأتي فترة استراحة قبل التالية، فالمطلوب "&I6&" ملاعب.","لا يلعب فريق مباراتين متتاليتين، فمجموع المباريات في أي فترتين متتاليتين لا يزيد على "&H6&"؛ ولتوزيع مباريات اليوم ("&C6&") على "&E6&" فترات لعب يكفي حسابيًا عدد ملاعب = "&F6&IF(I6>F6,"، لكن الجدول يتناوب في بعض الأيام بين فترات فيها مباريات أكثر وأقل، فتبلغ الذروة "&I6&" ملاعب.","، وهذا ما تستخدمه المجموعة.")) -> لا يلعب فريق مباراتين متتاليتين، فمجموع المباريات في أي فترتين متتاليتين لا يزيد على 3؛ ولتوزيع مباريات اليوم (14) على 9 فترات لعب يكفي حسابيًا عدد ملاعب = 2، وهذا ما تستخدمه المجموعة.
A7: ='ملخص البطولات'!A7 -> 8 | B7: =المدخلات!$B$9 -> 4 | C7: =A7*B7/2 -> 16 | D7: =MATCH("اليوم 2",'8 فرق'!$A:$A,0)-MATCH("اليوم 1",'8 فرق'!$A:$A,0) -> 7 | E7: =IF(G7="زوجية",(D7+1)/2,D7) -> 4 | F7: =ROUNDUP(C7/E7,0) -> 4 | G7: =IF(MOD(A7,2)=0,"زوجية","فردية") -> زوجية | H7: =IF(G7="زوجية",A7/2,INT(A7/2)) -> 4 | I7: ='ملخص البطولات'!K7 -> 4 | J7: =IF(G7="زوجية","كل الفرق الـ "&A7&" تلعب في كل فترة لعب ("&H7&" مباريات متزامنة، كل مباراة على ملعب) ثم تأتي فترة استراحة قبل التالية، فالمطلوب "&I7&" ملاعب.","لا يلعب فريق مباراتين متتاليتين، فمجموع المباريات في أي فترتين متتاليتين لا يزيد على "&H7&"؛ ولتوزيع مباريات اليوم ("&C7&") على "&E7&" فترات لعب يكفي حسابيًا عدد ملاعب = "&F7&IF(I7>F7,"، لكن الجدول يتناوب في بعض الأيام بين فترات فيها مباريات أكثر وأقل، فتبلغ الذروة "&I7&" ملاعب.","، وهذا ما تستخدمه المجموعة.")) -> كل الفرق الـ 8 تلعب في كل فترة لعب (4 مباريات متزامنة، كل مباراة على ملعب) ثم تأتي فترة استراحة قبل التالية، فالمطلوب 4 ملاعب.
A8: ='ملخص البطولات'!A8 -> 9 | B8: =المدخلات!$B$9 -> 4 | C8: =A8*B8/2 -> 18 | D8: =MATCH("اليوم 2",'9 فرق'!$A:$A,0)-MATCH("اليوم 1",'9 فرق'!$A:$A,0) -> 9 | E8: =IF(G8="زوجية",(D8+1)/2,D8) -> 9 | F8: =ROUNDUP(C8/E8,0) -> 2 | G8: =IF(MOD(A8,2)=0,"زوجية","فردية") -> فردية | H8: =IF(G8="زوجية",A8/2,INT(A8/2)) -> 4 | I8: ='ملخص البطولات'!K8 -> 3 | J8: =IF(G8="زوجية","كل الفرق الـ "&A8&" تلعب في كل فترة لعب ("&H8&" مباريات متزامنة، كل مباراة على ملعب) ثم تأتي فترة استراحة قبل التالية، فالمطلوب "&I8&" ملاعب.","لا يلعب فريق مباراتين متتاليتين، فمجموع المباريات في أي فترتين متتاليتين لا يزيد على "&H8&"؛ ولتوزيع مباريات اليوم ("&C8&") على "&E8&" فترات لعب يكفي حسابيًا عدد ملاعب = "&F8&IF(I8>F8,"، لكن الجدول يتناوب في بعض الأيام بين فترات فيها مباريات أكثر وأقل، فتبلغ الذروة "&I8&" ملاعب.","، وهذا ما تستخدمه المجموعة.")) -> لا يلعب فريق مباراتين متتاليتين، فمجموع المباريات في أي فترتين متتاليتين لا يزيد على 4؛ ولتوزيع مباريات اليوم (18) على 9 فترات لعب يكفي حسابيًا عدد ملاعب = 2، لكن الجدول يتناوب في بعض الأيام بين فترات فيها مباريات أكثر وأقل، فتبلغ الذروة 3 ملاعب.
A9: ='ملخص البطولات'!A9 -> 11 | B9: =المدخلات!$B$9 -> 4 | C9: =A9*B9/2 -> 22 | D9: =MATCH("اليوم 2",'11 فريقًا'!$A:$A,0)-MATCH("اليوم 1",'11 فريقًا'!$A:$A,0) -> 9 | E9: =IF(G9="زوجية",(D9+1)/2,D9) -> 9 | F9: =ROUNDUP(C9/E9,0) -> 3 | G9: =IF(MOD(A9,2)=0,"زوجية","فردية") -> فردية | H9: =IF(G9="زوجية",A9/2,INT(A9/2)) -> 5 | I9: ='ملخص البطولات'!K9 -> 4 | J9: =IF(G9="زوجية","كل الفرق الـ "&A9&" تلعب في كل فترة لعب ("&H9&" مباريات متزامنة، كل مباراة على ملعب) ثم تأتي فترة استراحة قبل التالية، فالمطلوب "&I9&" ملاعب.","لا يلعب فريق مباراتين متتاليتين، فمجموع المباريات في أي فترتين متتاليتين لا يزيد على "&H9&"؛ ولتوزيع مباريات اليوم ("&C9&") على "&E9&" فترات لعب يكفي حسابيًا عدد ملاعب = "&F9&IF(I9>F9,"، لكن الجدول يتناوب في بعض الأيام بين فترات فيها مباريات أكثر وأقل، فتبلغ الذروة "&I9&" ملاعب.","، وهذا ما تستخدمه المجموعة.")) -> لا يلعب فريق مباراتين متتاليتين، فمجموع المباريات في أي فترتين متتاليتين لا يزيد على 5؛ ولتوزيع مباريات اليوم (22) على 9 فترات لعب يكفي حسابيًا عدد ملاعب = 3، لكن الجدول يتناوب في بعض الأيام بين فترات فيها مباريات أكثر وأقل، فتبلغ الذروة 4 ملاعب.
A11: ملاحظة: مجموعة الستة تلعب في مهرجانها الأخير 5 مباريات لكل فريق (15 مباراة في اليوم) بنفس الملاعب الثلاثة؛ الأرقام أعلاه تخص اليوم العادي (4 مباريات لكل فريق).
A12: الملعب المصغّر = ربع الملعب القانوني (5 ضد 5)، ومدة المباراة 15 دقيقة.

Sheet 5 فرق
A1: جدول مباريات المجموعات التي فيها 5 فرق
A3: اليوم | B3: الوقت | C3: ملعب 1 | D3: مجموع مباريات اليوم | E3: مباريات كل فريق في اليوم | G3: لاعبو الفترة (عمود مساعد) | I3: الفريق | J3: عدد مبارياته | K3: مباريات متتالية | L3: راحة 15 دقيقة | M3: راحة 30 دقيقة | N3: راحة أطول من 30
A4: اليوم 1 | B4: =MOD(HOUR((المدخلات!$B$4+0*المدخلات!$B$5/1440))-1,12)+1&":"&TEXT(MINUTE((المدخلات!$B$4+0*المدخلات!$B$5/1440)),"00")&"–"&MOD(HOUR((المدخلات!$B$4+0*المدخلات!$B$5/1440+المدخلات!$B$5/1440))-1,12)+1&":"&TEXT(MINUTE((المدخلات!$B$4+0*المدخلات!$B$5/1440+المدخلات!$B$5/1440)),"00")&IF(HOUR((المدخلات!$B$4+0*المدخلات!$B$5/1440))<12," ص"," م") -> 4:00–4:15 م | C4: 3 ضد 5 | D4: =COUNTIF(C4:C13,"* ضد *") -> 10 | E4: =COUNTIF(C4:C13,"* ضد *")*2/5 -> 4 | G4: =_xlfn.TEXTJOIN(" ",TRUE,C4:C4) -> 3 ضد 5 | I4: 1 | J4: {=SUMPRODUCT(--ISNUMBER(SEARCH(" "&$I4&" "," "&G$4:G$73&" ")))} -> 28 | K4: {=SUMPRODUCT(--ISNUMBER(SEARCH(" "&$I4&" "," "&G$4:G$72&" ")),--ISNUMBER(SEARCH(" "&$I4&" "," "&G$5:G$73&" ")),--(MOD(ROW(G$4:G$72)-4,$J$10)<=$J$10-2))} -> 0 | L4: {=SUMPRODUCT(--ISNUMBER(SEARCH(" "&$I4&" "," "&G$4:G$71&" ")),--ISNUMBER(SEARCH(" "&$I4&" "," "&G$6:G$73&" ")),--(MOD(ROW(G$4:G$71)-4,$J$10)<=$J$10-3))} -> 11 | M4: {=SUMPRODUCT(--ISNUMBER(SEARCH(" "&$I4&" "," "&G$4:G$70&" ")),--ISNUMBER(SEARCH(" "&$I4&" "," "&G$7:G$73&" ")),--(MOD(ROW(G$4:G$70)-4,$J$10)<=$J$10-4))} -> 10 | N4: =J4*3/4-K4-L4-M4 -> 0
B5: =MOD(HOUR((المدخلات!$B$4+1*المدخلات!$B$5/1440))-1,12)+1&":"&TEXT(MINUTE((المدخلات!$B$4+1*المدخلات!$B$5/1440)),"00")&"–"&MOD(HOUR((المدخلات!$B$4+1*المدخلات!$B$5/1440+المدخلات!$B$5/1440))-1,12)+1&":"&TEXT(MINUTE((المدخلات!$B$4+1*المدخلات!$B$5/1440+المدخلات!$B$5/1440)),"00")&IF(HOUR((المدخلات!$B$4+1*المدخلات!$B$5/1440))<12," ص"," م") -> 4:15–4:30 م | C5: 1 ضد 2 | G5: =_xlfn.TEXTJOIN(" ",TRUE,C5:C5) -> 1 ضد 2 | I5: 2 | J5: {=SUMPRODUCT(--ISNUMBER(SEARCH(" "&$I5&" "," "&G$4:G$73&" ")))} -> 28 | K5: {=SUMPRODUCT(--ISNUMBER(SEARCH(" "&$I5&" "," "&G$4:G$72&" ")),--ISNUMBER(SEARCH(" "&$I5&" "," "&G$5:G$73&" ")),--(MOD(ROW(G$4:G$72)-4,$J$10)<=$J$10-2))} -> 0 | L5: {=SUMPRODUCT(--ISNUMBER(SEARCH(" "&$I5&" "," "&G$4:G$71&" ")),--ISNUMBER(SEARCH(" "&$I5&" "," "&G$6:G$73&" ")),--(MOD(ROW(G$4:G$71)-4,$J$10)<=$J$10-3))} -> 10 | M5: {=SUMPRODUCT(--ISNUMBER(SEARCH(" "&$I5&" "," "&G$4:G$70&" ")),--ISNUMBER(SEARCH(" "&$I5&" "," "&G$7:G$73&" ")),--(MOD(ROW(G$4:G$70)-4,$J$10)<=$J$10-4))} -> 11 | N5: =J5*3/4-K5-L5-M5 -> 0
B6: =MOD(HOUR((المدخلات!$B$4+2*المدخلات!$B$5/1440))-1,12)+1&":"&TEXT(MINUTE((المدخلات!$B$4+2*المدخلات!$B$5/1440)),"00")&"–"&MOD(HOUR((المدخلات!$B$4+2*المدخلات!$B$5/1440+المدخلات!$B$5/1440))-1,12)+1&":"&TEXT(MINUTE((المدخلات!$B$4+2*المدخلات!$B$5/1440+المدخلات!$B$5/1440)),"00")&IF(HOUR((المدخلات!$B$4+2*المدخلات!$B$5/1440))<12," ص"," م") -> 4:30–4:45 م | C6: 4 ضد 5 | G6: =_xlfn.TEXTJOIN(" ",TRUE,C6:C6) -> 4 ضد 5 | I6: 3 | J6: {=SUMPRODUCT(--ISNUMBER(SEARCH(" "&$I6&" "," "&G$4:G$73&" ")))} -> 28 | K6: {=SUMPRODUCT(--ISNUMBER(SEARCH(" "&$I6&" "," "&G$4:G$72&" ")),--ISNUMBER(SEARCH(" "&$I6&" "," "&G$5:G$73&" ")),--(MOD(ROW(G$4:G$72)-4,$J$10)<=$J$10-2))} -> 0 | L6: {=SUMPRODUCT(--ISNUMBER(SEARCH(" "&$I6&" "," "&G$4:G$71&" ")),--ISNUMBER(SEARCH(" "&$I6&" "," "&G$6:G$73&" ")),--(MOD(ROW(G$4:G$71)-4,$J$10)<=$J$10-3))} -> 12 | M6: {=SUMPRODUCT(--ISNUMBER(SEARCH(" "&$I6&" "," "&G$4:G$70&" ")),--ISNUMBER(SEARCH(" "&$I6&" "," "&G$7:G$73&" ")),--(MOD(ROW(G$4:G$70)-4,$J$10)<=$J$10-4))} -> 9 | N6: =J6*3/4-K6-L6-M6 -> 0
B7: =MOD(HOUR((المدخلات!$B$4+3*المدخلات!$B$5/1440))-1,12)+1&":"&TEXT(MINUTE((المدخلات!$B$4+3*المدخلات!$B$5/1440)),"00")&"–"&MOD(HOUR((المدخلات!$B$4+3*المدخلات!$B$5/1440+المدخلات!$B$5/1440))-1,12)+1&":"&TEXT(MINUTE((المدخلات!$B$4+3*المدخلات!$B$5/1440+المدخلات!$B$5/1440)),"00")&IF(HOUR((المدخلات!$B$4+3*المدخلات!$B$5/1440))<12," ص"," م") -> 4:45–5:00 م | C7: 2 ضد 3 | G7: =_xlfn.TEXTJOIN(" ",TRUE,C7:C7) -> 2 ضد 3 | I7: 4 | J7: {=SUMPRODUCT(--ISNUMBER(SEARCH(" "&$I7&" "," "&G$4:G$73&" ")))} -> 28 | K7: {=SUMPRODUCT(--ISNUMBER(SEARCH(" "&$I7&" "," "&G$4:G$72&" ")),--ISNUMBER(SEARCH(" "&$I7&" "," "&G$5:G$73&" ")),--(MOD(ROW(G$4:G$72)-4,$J$10)<=$J$10-2))} -> 0 | L7: {=SUMPRODUCT(--ISNUMBER(SEARCH(" "&$I7&" "," "&G$4:G$71&" ")),--ISNUMBER(SEARCH(" "&$I7&" "," "&G$6:G$73&" ")),--(MOD(ROW(G$4:G$71)-4,$J$10)<=$J$10-3))} -> 11 | M7: {=SUMPRODUCT(--ISNUMBER(SEARCH(" "&$I7&" "," "&G$4:G$70&" ")),--ISNUMBER(SEARCH(" "&$I7&" "," "&G$7:G$73&" ")),--(MOD(ROW(G$4:G$70)-4,$J$10)<=$J$10-4))} -> 10 | N7: =J7*3/4-K7-L7-M7 -> 0
B8: =MOD(HOUR((المدخلات!$B$4+4*المدخلات!$B$5/1440))-1,12)+1&":"&TEXT(MINUTE((المدخلات!$B$4+4*المدخلات!$B$5/1440)),"00")&"–"&MOD(HOUR((المدخلات!$B$4+4*المدخلات!$B$5/1440+المدخلات!$B$5/1440))-1,12)+1&":"&TEXT(MINUTE((المدخلات!$B$4+4*المدخلات!$B$5/1440+المدخلات!$B$5/1440)),"00")&IF(HOUR((المدخلات!$B$4+4*المدخلات!$B$5/1440))<12," ص"," م") -> 5:00–5:15 م | C8: 1 ضد 4 | G8: =_xlfn.TEXTJOIN(" ",TRUE,C8:C8) -> 1 ضد 4 | I8: 5 | J8: {=SUMPRODUCT(--ISNUMBER(SEARCH(" "&$I8&" "," "&G$4:G$73&" ")))} -> 28 | K8: {=SUMPRODUCT(--ISNUMBER(SEARCH(" "&$I8&" "," "&G$4:G$72&" ")),--ISNUMBER(SEARCH(" "&$I8&" "," "&G$5:G$73&" ")),--(MOD(ROW(G$4:G$72)-4,$J$10)<=$J$10-2))} -> 0 | L8: {=SUMPRODUCT(--ISNUMBER(SEARCH(" "&$I8&" "," "&G$4:G$71&" ")),--ISNUMBER(SEARCH(" "&$I8&" "," "&G$6:G$73&" ")),--(MOD(ROW(G$4:G$71)-4,$J$10)<=$J$10-3))} -> 12 | M8: {=SUMPRODUCT(--ISNUMBER(SEARCH(" "&$I8&" "," "&G$4:G$70&" ")),--ISNUMBER(SEARCH(" "&$I8&" "," "&G$7:G$73&" ")),--(MOD(ROW(G$4:G$70)-4,$J$10)<=$J$10-4))} -> 9 | N8: =J8*3/4-K8-L8-M8 -> 0
B9: =MOD(HOUR((المدخلات!$B$4+5*المدخلات!$B$5/1440))-1,12)+1&":"&TEXT(MINUTE((المدخلات!$B$4+5*المدخلات!$B$5/1440)),"00")&"–"&MOD(HOUR((المدخلات!$B$4+5*المدخلات!$B$5/1440+المدخلات!$B$5/1440))-1,12)+1&":"&TEXT(MINUTE((المدخلات!$B$4+5*المدخلات!$B$5/1440+المدخلات!$B$5/1440)),"00")&IF(HOUR((المدخلات!$B$4+5*المدخلات!$B$5/1440))<12," ص"," م") -> 5:15–5:30 م | C9: 2 ضد 5 | G9: =_xlfn.TEXTJOIN(" ",TRUE,C9:C9) -> 2 ضد 5 | I9: المجموع | J9: =SUM(J4:J8) -> 140 | K9: =SUM(K4:K8) -> 0 | L9: =SUM(L4:L8) -> 56 | M9: =SUM(M4:M8) -> 49 | N9: =SUM(N4:N8) -> 0
B10: =MOD(HOUR((المدخلات!$B$4+6*المدخلات!$B$5/1440))-1,12)+1&":"&TEXT(MINUTE((المدخلات!$B$4+6*المدخلات!$B$5/1440)),"00")&"–"&MOD(HOUR((المدخلات!$B$4+6*المدخلات!$B$5/1440+المدخلات!$B$5/1440))-1,12)+1&":"&TEXT(MINUTE((المدخلات!$B$4+6*المدخلات!$B$5/1440+المدخلات!$B$5/1440)),"00")&IF(HOUR((المدخلات!$B$4+6*المدخلات!$B$5/1440))<12," ص"," م") -> 5:30–5:45 م | C10: 3 ضد 4 | G10: =_xlfn.TEXTJOIN(" ",TRUE,C10:C10) -> 3 ضد 4 | I10: فترات اليوم | J10: =COUNTA($B$4:$B$73)/COUNTIF($A$4:$A$73,"اليوم *") -> 10
B11: =MOD(HOUR((المدخلات!$B$4+7*المدخلات!$B$5/1440))-1,12)+1&":"&TEXT(MINUTE((المدخلات!$B$4+7*المدخلات!$B$5/1440)),"00")&"–"&MOD(HOUR((المدخلات!$B$4+7*المدخلات!$B$5/1440+المدخلات!$B$5/1440))-1,12)+1&":"&TEXT(MINUTE((المدخلات!$B$4+7*المدخلات!$B$5/1440+المدخلات!$B$5/1440)),"00")&IF(HOUR((المدخلات!$B$4+7*المدخلات!$B$5/1440))<12," ص"," م") -> 5:45–6:00 م | C11: 1 ضد 5 | G11: =_xlfn.TEXTJOIN(" ",TRUE,C11:C11) -> 1 ضد 5
B12: =MOD(HOUR((المدخلات!$B$4+8*المدخلات!$B$5/1440))-1,12)+1&":"&TEXT(MINUTE((المدخلات!$B$4+8*المدخلات!$B$5/1440)),"00")&"–"&MOD(HOUR((المدخلات!$B$4+8*المدخلات!$B$5/1440+المدخلات!$B$5/1440))-1,12)+1&":"&TEXT(MINUTE((المدخلات!$B$4+8*المدخلات!$B$5/1440+المدخلات!$B$5/1440)),"00")&IF(HOUR((المدخلات!$B$4+8*المدخلات!$B$5/1440))<12," ص"," م") -> 6:00–6:15 م | C12: 2 ضد 4 | G12: =_xlfn.TEXTJOIN(" ",TRUE,C12:C12) -> 2 ضد 4
B13: =MOD(HOUR((المدخلات!$B$4+9*المدخلات!$B$5/1440))-1,12)+1&":"&TEXT(MINUTE((المدخلات!$B$4+9*المدخلات!$B$5/1440)),"00")&"–"&MOD(HOUR((المدخلات!$B$4+9*المدخلات!$B$5/1440+المدخلات!$B$5/1440))-1,12)+1&":"&TEXT(MINUTE((المدخلات!$B$4+9*المدخلات!$B$5/1440+المدخلات!$B$5/1440)),"00")&IF(HOUR((المدخلات!$B$4+9*المدخلات!$B$5/1440))<12," ص"," م") -> 6:15–6:30 م | C13: 1 ضد 3 | G13: =_xlfn.TEXTJOIN(" ",TRUE,C13:C13) -> 1 ضد 3
A14: اليوم 2 | B14: =MOD(HOUR((المدخلات!$B$4+0*المدخلات!$B$5/1440))-1,12)+1&":"&TEXT(MINUTE((المدخلات!$B$4+0*المدخلات!$B$5/1440)),"00")&"–"&MOD(HOUR((المدخلات!$B$4+0*المدخلات!$B$5/1440+المدخلات!$B$5/1440))-1,12)+1&":"&TEXT(MINUTE((المدخلات!$B$4+0*المدخلات!$B$5/1440+المدخلات!$B$5/1440)),"00")&IF(HOUR((المدخلات!$B$4+0*المدخلات!$B$5/1440))<12," ص"," م") -> 4:00–4:15 م | C14: 1 ضد 4 | D14: =COUNTIF(C14:C23,"* ضد *") -> 10 | E14: =COUNTIF(C14:C23,"* ضد *")*2/5 -> 4 | G14: =_xlfn.TEXTJOIN(" ",TRUE,C14:C14) -> 1 ضد 4
B15: =MOD(HOUR((المدخلات!$B$4+1*المدخلات!$B$5/1440))-1,12)+1&":"&TEXT(MINUTE((المدخلات!$B$4+1*المدخلات!$B$5/1440)),"00")&"–"&MOD(HOUR((المدخلات!$B$4+1*المدخلات!$B$5/1440+المدخلات!$B$5/1440))-1,12)+1&":"&TEXT(MINUTE((المدخلات!$B$4+1*المدخلات!$B$5/1440+المدخلات!$B$5/1440)),"00")&IF(HOUR((المدخلات!$B$4+1*المدخلات!$B$5/1440))<12," ص"," م") -> 4:15–4:30 م | C15: 2 ضد 5 | G15: =_xlfn.TEXTJOIN(" ",TRUE,C15:C15) -> 2 ضد 5
B16: =MOD(HOUR((المدخلات!$B$4+2*المدخلات!$B$5/1440))-1,12)+1&":"&TEXT(MINUTE((المدخلات!$B$4+2*المدخلات!$B$5/1440)),"00")&"–"&MOD(HOUR((المدخلات!$B$4+2*المدخلات!$B$5/1440+المدخلات!$B$5/1440))-1,12)+1&":"&TEXT(MINUTE((المدخلات!$B$4+2*المدخلات!$B$5/1440+المدخلات!$B$5/1440)),"00")&IF(HOUR((المدخلات!$B$4+2*المدخلات!$B$5/1440))<12," ص"," م") -> 4:30–4:45 م | C16: 1 ضد 3 | G16: =_xlfn.TEXTJOIN(" ",TRUE,C16:C16) -> 1 ضد 3
B17: =MOD(HOUR((المدخلات!$B$4+3*المدخلات!$B$5/1440))-1,12)+1&":"&TEXT(MINUTE((المدخلات!$B$4+3*المدخلات!$B$5/1440)),"00")&"–"&MOD(HOUR((المدخلات!$B$4+3*المدخلات!$B$5/1440+المدخلات!$B$5/1440))-1,12)+1&":"&TEXT(MINUTE((المدخلات!$B$4+3*المدخلات!$B$5/1440+المدخلات!$B$5/1440)),"00")&IF(HOUR((المدخلات!$B$4+3*المدخلات!$B$5/1440))<12," ص"," م") -> 4:45–5:00 م | C17: 4 ضد 5 | G17: =_xlfn.TEXTJOIN(" ",TRUE,C17:C17) -> 4 ضد 5
B18: =MOD(HOUR((المدخلات!$B$4+4*المدخلات!$B$5/1440))-1,12)+1&":"&TEXT(MINUTE((المدخلات!$B$4+4*المدخلات!$B$5/1440)),"00")&"–"&MOD(HOUR((المدخلات!$B$4+4*المدخلات!$B$5/1440+المدخلات!$B$5/1440))-1,12)+1&":"&TEXT(MINUTE((المدخلات!$B$4+4*المدخلات!$B$5/1440+المدخلات!$B$5/1440)),"00")&IF(HOUR((المدخلات!$B$4+4*المدخلات!$B$5/1440))<12," ص"," م") -> 5:00–5:15 م | C18: 2 ضد 3 | G18: =_xlfn.TEXTJOIN(" ",TRUE,C18:C18) -> 2 ضد 3
B19: =MOD(HOUR((المدخلات!$B$4+5*المدخلات!$B$5/1440))-1,12)+1&":"&TEXT(MINUTE((المدخلات!$B$4+5*المدخلات!$B$5/1440)),"00")&"–"&MOD(HOUR((المدخلات!$B$4+5*المدخلات!$B$5/1440+المدخلات!$B$5/1440))-1,12)+1&":"&TEXT(MINUTE((المدخلات!$B$4+5*المدخلات!$B$5/1440+المدخلات!$B$5/1440)),"00")&IF(HOUR((المدخلات!$B$4+5*المدخلات!$B$5/1440))<12," ص"," م") -> 5:15–5:30 م | C19: 1 ضد 5 | G19: =_xlfn.TEXTJOIN(" ",TRUE,C19:C19) -> 1 ضد 5
B20: =MOD(HOUR((المدخلات!$B$4+6*المدخلات!$B$5/1440))-1,12)+1&":"&TEXT(MINUTE((المدخلات!$B$4+6*المدخلات!$B$5/1440)),"00")&"–"&MOD(HOUR((المدخلات!$B$4+6*المدخلات!$B$5/1440+المدخلات!$B$5/1440))-1,12)+1&":"&TEXT(MINUTE((المدخلات!$B$4+6*المدخلات!$B$5/1440+المدخلات!$B$5/1440)),"00")&IF(HOUR((المدخلات!$B$4+6*المدخلات!$B$5/1440))<12," ص"," م") -> 5:30–5:45 م | C20: 3 ضد 4 | G20: =_xlfn.TEXTJOIN(" ",TRUE,C20:C20) -> 3 ضد 4
B21: =MOD(HOUR((المدخلات!$B$4+7*المدخلات!$B$5/1440))-1,12)+1&":"&TEXT(MINUTE((المدخلات!$B$4+7*المدخلات!$B$5/1440)),"00")&"–"&MOD(HOUR((المدخلات!$B$4+7*المدخلات!$B$5/1440+المدخلات!$B$5/1440))-1,12)+1&":"&TEXT(MINUTE((المدخلات!$B$4+7*المدخلات!$B$5/1440+المدخلات!$B$5/1440)),"00")&IF(HOUR((المدخلات!$B$4+7*المدخلات!$B$5/1440))<12," ص"," م") -> 5:45–6:00 م | C21: 1 ضد 2 | G21: =_xlfn.TEXTJOIN(" ",TRUE,C21:C21) -> 1 ضد 2
B22: =MOD(HOUR((المدخلات!$B$4+8*المدخلات!$B$5/1440))-1,12)+1&":"&TEXT(MINUTE((المدخلات!$B$4+8*المدخلات!$B$5/1440)),"00")&"–"&MOD(HOUR((المدخلات!$B$4+8*المدخلات!$B$5/1440+المدخلات!$B$5/1440))-1,12)+1&":"&TEXT(MINUTE((المدخلات!$B$4+8*المدخلات!$B$5/1440+المدخلات!$B$5/1440)),"00")&IF(HOUR((المدخلات!$B$4+8*المدخلات!$B$5/1440))<12," ص"," م") -> 6:00–6:15 م | C22: 3 ضد 5 | G22: =_xlfn.TEXTJOIN(" ",TRUE,C22:C22) -> 3 ضد 5
B23: =MOD(HOUR((المدخلات!$B$4+9*المدخلات!$B$5/1440))-1,12)+1&":"&TEXT(MINUTE((المدخلات!$B$4+9*المدخلات!$B$5/1440)),"00")&"–"&MOD(HOUR((المدخلات!$B$4+9*المدخلات!$B$5/1440+المدخلات!$B$5/1440))-1,12)+1&":"&TEXT(MINUTE((المدخلات!$B$4+9*المدخلات!$B$5/1440+المدخلات!$B$5/1440)),"00")&IF(HOUR((المدخلات!$B$4+9*المدخلات!$B$5/1440))<12," ص"," م") -> 6:15–6:30 م | C23: 2 ضد 4 | G23: =_xlfn.TEXTJOIN(" ",TRUE,C23:C23) -> 2 ضد 4
A24: اليوم 3 | B24: =MOD(HOUR((المدخلات!$B$4+0*المدخلات!$B$5/1440))-1,12)+1&":"&TEXT(MINUTE((المدخلات!$B$4+0*المدخلات!$B$5/1440)),"00")&"–"&MOD(HOUR((المدخلات!$B$4+0*المدخلات!$B$5/1440+المدخلات!$B$5/1440))-1,12)+1&":"&TEXT(MINUTE((المدخلات!$B$4+0*المدخلات!$B$5/1440+المدخلات!$B$5/1440)),"00")&IF(HOUR((المدخلات!$B$4+0*المدخلات!$B$5/1440))<12," ص"," م") -> 4:00–4:15 م | C24: 2 ضد 5 | D24: =COUNTIF(C24:C33,"* ضد *") -> 10 | E24: =COUNTIF(C24:C33,"* ضد *")*2/5 -> 4 | G24: =_xlfn.TEXTJOIN(" ",TRUE,C24:C24) -> 2 ضد 5
B25: =MOD(HOUR((المدخلات!$B$4+1*المدخلات!$B$5/1440))-1,12)+1&":"&TEXT(MINUTE((المدخلات!$B$4+1*المدخلات!$B$5/1440)),"00")&"–"&MOD(HOUR((المدخلات!$B$4+1*المدخلات!$B$5/1440+المدخلات!$B$5/1440))-1,12)+1&":"&TEXT(MINUTE((المدخلات!$B$4+1*المدخلات!$B$5/1440+المدخلات!$B$5/1440)),"00")&IF(HOUR((المدخلات!$B$4+1*المدخلات!$B$5/1440))<12," ص"," م") -> 4:15–4:30 م | C25: 1 ضد 4 | G25: =_xlfn.TEXTJOIN(" ",TRUE,C25:C25) -> 1 ضد 4
B26: =MOD(HOUR((المدخلات!$B$4+2*المدخلات!$B$5/1440))-1,12)+1&":"&TEXT(MINUTE((المدخلات!$B$4+2*المدخلات!$B$5/1440)),"00")&"–"&MOD(HOUR((المدخلات!$B$4+2*المدخلات!$B$5/1440+المدخلات!$B$5/1440))-1,12)+1&":"&TEXT(MINUTE((المدخلات!$B$4+2*المدخلات!$B$5/1440+المدخلات!$B$5/1440)),"00")&IF(HOUR((المدخلات!$B$4+2*المدخلات!$B$5/1440))<12," ص"," م") -> 4:30–4:45 م | C26: 2 ضد 3 | G26: =_xlfn.TEXTJOIN(" ",TRUE,C26:C26) -> 2 ضد 3
B27: =MOD(HOUR((المدخلات!$B$4+3*المدخلات!$B$5/1440))-1,12)+1&":"&TEXT(MINUTE((المدخلات!$B$4+3*المدخلات!$B$5/1440)),"00")&"–"&MOD(HOUR((المدخلات!$B$4+3*المدخلات!$B$5/1440+المدخلات!$B$5/1440))-1,12)+1&":"&TEXT(MINUTE((المدخلات!$B$4+3*المدخلات!$B$5/1440+المدخلات!$B$5/1440)),"00")&IF(HOUR((المدخلات!$B$4+3*المدخلات!$B$5/1440))<12," ص"," م") -> 4:45–5:00 م | C27: 4 ضد 5 | G27: =_xlfn.TEXTJOIN(" ",TRUE,C27:C27) -> 4 ضد 5
B28: =MOD(HOUR((المدخلات!$B$4+4*المدخلات!$B$5/1440))-1,12)+1&":"&TEXT(MINUTE((المدخلات!$B$4+4*المدخلات!$B$5/1440)),"00")&"–"&MOD(HOUR((المدخلات!$B$4+4*المدخلات!$B$5/1440+المدخلات!$B$5/1440))-1,12)+1&":"&TEXT(MINUTE((المدخلات!$B$4+4*المدخلات!$B$5/1440+المدخلات!$B$5/1440)),"00")&IF(HOUR((المدخلات!$B$4+4*المدخلات!$B$5/1440))<12," ص"," م") -> 5:00–5:15 م | C28: 1 ضد 3 | G28: =_xlfn.TEXTJOIN(" ",TRUE,C28:C28) -> 1 ضد 3
B29: =MOD(HOUR((المدخلات!$B$4+5*المدخلات!$B$5/1440))-1,12)+1&":"&TEXT(MINUTE((المدخلات!$B$4+5*المدخلات!$B$5/1440)),"00")&"–"&MOD(HOUR((المدخلات!$B$4+5*المدخلات!$B$5/1440+المدخلات!$B$5/1440))-1,12)+1&":"&TEXT(MINUTE((المدخلات!$B$4+5*المدخلات!$B$5/1440+المدخلات!$B$5/1440)),"00")&IF(HOUR((المدخلات!$B$4+5*المدخلات!$B$5/1440))<12," ص"," م") -> 5:15–5:30 م | C29: 2 ضد 4 | G29: =_xlfn.TEXTJOIN(" ",TRUE,C29:C29) -> 2 ضد 4
B30: =MOD(HOUR((المدخلات!$B$4+6*المدخلات!$B$5/1440))-1,12)+1&":"&TEXT(MINUTE((المدخلات!$B$4+6*المدخلات!$B$5/1440)),"00")&"–"&MOD(HOUR((المدخلات!$B$4+6*المدخلات!$B$5/1440+المدخلات!$B$5/1440))-1,12)+1&":"&TEXT(MINUTE((المدخلات!$B$4+6*المدخلات!$B$5/1440+المدخلات!$B$5/1440)),"00")&IF(HOUR((المدخلات!$B$4+6*المدخلات!$B$5/1440))<12," ص"," م") -> 5:30–5:45 م | C30: 3 ضد 5 | G30: =_xlfn.TEXTJOIN(" ",TRUE,C30:C30) -> 3 ضد 5
B31: =MOD(HOUR((المدخلات!$B$4+7*المدخلات!$B$5/1440))-1,12)+1&":"&TEXT(MINUTE((المدخلات!$B$4+7*المدخلات!$B$5/1440)),"00")&"–"&MOD(HOUR((المدخلات!$B$4+7*المدخلات!$B$5/1440+المدخلات!$B$5/1440))-1,12)+1&":"&TEXT(MINUTE((المدخلات!$B$4+7*المدخلات!$B$5/1440+المدخلات!$B$5/1440)),"00")&IF(HOUR((المدخلات!$B$4+7*المدخلات!$B$5/1440))<12," ص"," م") -> 5:45–6:00 م | C31: 1 ضد 2 | G31: =_xlfn.TEXTJOIN(" ",TRUE,C31:C31) -> 1 ضد 2
B32: =MOD(HOUR((المدخلات!$B$4+8*المدخلات!$B$5/1440))-1,12)+1&":"&TEXT(MINUTE((المدخلات!$B$4+8*المدخلات!$B$5/1440)),"00")&"–"&MOD(HOUR((المدخلات!$B$4+8*المدخلات!$B$5/1440+المدخلات!$B$5/1440))-1,12)+1&":"&TEXT(MINUTE((المدخلات!$B$4+8*المدخلات!$B$5/1440+المدخلات!$B$5/1440)),"00")&IF(HOUR((المدخلات!$B$4+8*المدخلات!$B$5/1440))<12," ص"," م") -> 6:00–6:15 م | C32: 3 ضد 4 | G32: =_xlfn.TEXTJOIN(" ",TRUE,C32:C32) -> 3 ضد 4
B33: =MOD(HOUR((المدخلات!$B$4+9*المدخلات!$B$5/1440))-1,12)+1&":"&TEXT(MINUTE((المدخلات!$B$4+9*المدخلات!$B$5/1440)),"00")&"–"&MOD(HOUR((المدخلات!$B$4+9*المدخلات!$B$5/1440+المدخلات!$B$5/1440))-1,12)+1&":"&TEXT(MINUTE((المدخلات!$B$4+9*المدخلات!$B$5/1440+المدخلات!$B$5/1440)),"00")&IF(HOUR((المدخلات!$B$4+9*المدخلات!$B$5/1440))<12," ص"," م") -> 6:15–6:30 م | C33: 1 ضد 5 | G33: =_xlfn.TEXTJOIN(" ",TRUE,C33:C33) -> 1 ضد 5
A34: اليوم 4 | B34: =MOD(HOUR((المدخلات!$B$4+0*المدخلات!$B$5/1440))-1,12)+1&":"&TEXT(MINUTE((المدخلات!$B$4+0*المدخلات!$B$5/1440)),"00")&"–"&MOD(HOUR((المدخلات!$B$4+0*المدخلات!$B$5/1440+المدخلات!$B$5/1440))-1,12)+1&":"&TEXT(MINUTE((المدخلات!$B$4+0*المدخلات!$B$5/1440+المدخلات!$B$5/1440)),"00")&IF(HOUR((المدخلات!$B$4+0*المدخلات!$B$5/1440))<12," ص"," م") -> 4:00–4:15 م | C34: 2 ضد 3 | D34: =COUNTIF(C34:C43,"* ضد *") -> 10 | E34: =COUNTIF(C34:C43,"* ضد *")*2/5 -> 4 | G34: =_xlfn.TEXTJOIN(" ",TRUE,C34:C34) -> 2 ضد 3
B35: =MOD(HOUR((المدخلات!$B$4+1*المدخلات!$B$5/1440))-1,12)+1&":"&TEXT(MINUTE((المدخلات!$B$4+1*المدخلات!$B$5/1440)),"00")&"–"&MOD(HOUR((المدخلات!$B$4+1*المدخلات!$B$5/1440+المدخلات!$B$5/1440))-1,12)+1&":"&TEXT(MINUTE((المدخلات!$B$4+1*المدخلات!$B$5/1440+المدخلات!$B$5/1440)),"00")&IF(HOUR((المدخلات!$B$4+1*المدخلات!$B$5/1440))<12," ص"," م") -> 4:15–4:30 م | C35: 1 ضد 4 | G35: =_xlfn.TEXTJOIN(" ",TRUE,C35:C35) -> 1 ضد 4
B36: =MOD(HOUR((المدخلات!$B$4+2*المدخلات!$B$5/1440))-1,12)+1&":"&TEXT(MINUTE((المدخلات!$B$4+2*المدخلات!$B$5/1440)),"00")&"–"&MOD(HOUR((المدخلات!$B$4+2*المدخلات!$B$5/1440+المدخلات!$B$5/1440))-1,12)+1&":"&TEXT(MINUTE((المدخلات!$B$4+2*المدخلات!$B$5/1440+المدخلات!$B$5/1440)),"00")&IF(HOUR((المدخلات!$B$4+2*المدخلات!$B$5/1440))<12," ص"," م") -> 4:30–4:45 م | C36: 2 ضد 5 | G36: =_xlfn.TEXTJOIN(" ",TRUE,C36:C36) -> 2 ضد 5
B37: =MOD(HOUR((المدخلات!$B$4+3*المدخلات!$B$5/1440))-1,12)+1&":"&TEXT(MINUTE((المدخلات!$B$4+3*المدخلات!$B$5/1440)),"00")&"–"&MOD(HOUR((المدخلات!$B$4+3*المدخلات!$B$5/1440+المدخلات!$B$5/1440))-1,12)+1&":"&TEXT(MINUTE((المدخلات!$B$4+3*المدخلات!$B$5/1440+المدخلات!$B$5/1440)),"00")&IF(HOUR((المدخلات!$B$4+3*المدخلات!$B$5/1440))<12," ص"," م") -> 4:45–5:00 م | C37: 1 ضد 3 | G37: =_xlfn.TEXTJOIN(" ",TRUE,C37:C37) -> 1 ضد 3
B38: =MOD(HOUR((المدخلات!$B$4+4*المدخلات!$B$5/1440))-1,12)+1&":"&TEXT(MINUTE((المدخلات!$B$4+4*المدخلات!$B$5/1440)),"00")&"–"&MOD(HOUR((المدخلات!$B$4+4*المدخلات!$B$5/1440+المدخلات!$B$5/1440))-1,12)+1&":"&TEXT(MINUTE((المدخلات!$B$4+4*المدخلات!$B$5/1440+المدخلات!$B$5/1440)),"00")&IF(HOUR((المدخلات!$B$4+4*المدخلات!$B$5/1440))<12," ص"," م") -> 5:00–5:15 م | C38: 4 ضد 5 | G38: =_xlfn.TEXTJOIN(" ",TRUE,C38:C38) -> 4 ضد 5
B39: =MOD(HOUR((المدخلات!$B$4+5*المدخلات!$B$5/1440))-1,12)+1&":"&TEXT(MINUTE((المدخلات!$B$4+5*المدخلات!$B$5/1440)),"00")&"–"&MOD(HOUR((المدخلات!$B$4+5*المدخلات!$B$5/1440+المدخلات!$B$5/1440))-1,12)+1&":"&TEXT(MINUTE((المدخلات!$B$4+5*المدخلات!$B$5/1440+المدخلات!$B$5/1440)),"00")&IF(HOUR((المدخلات!$B$4+5*المدخلات!$B$5/1440))<12," ص"," م") -> 5:15–5:30 م | C39: 1 ضد 2 | G39: =_xlfn.TEXTJOIN(" ",TRUE,C39:C39) -> 1 ضد 2
B40: =MOD(HOUR((المدخلات!$B$4+6*المدخلات!$B$5/1440))-1,12)+1&":"&TEXT(MINUTE((المدخلات!$B$4+6*المدخلات!$B$5/1440)),"00")&"–"&MOD(HOUR((المدخلات!$B$4+6*المدخلات!$B$5/1440+المدخلات!$B$5/1440))-1,12)+1&":"&TEXT(MINUTE((المدخلات!$B$4+6*المدخلات!$B$5/1440+المدخلات!$B$5/1440)),"00")&IF(HOUR((المدخلات!$B$4+6*المدخلات!$B$5/1440))<12," ص"," م") -> 5:30–5:45 م | C40: 3 ضد 5 | G40: =_xlfn.TEXTJOIN(" ",TRUE,C40:C40) -> 3 ضد 5
B41: =MOD(HOUR((المدخلات!$B$4+7*المدخلات!$B$5/1440))-1,12)+1&":"&TEXT(MINUTE((المدخلات!$B$4+7*المدخلات!$B$5/1440)),"00")&"–"&MOD(HOUR((المدخلات!$B$4+7*المدخلات!$B$5/1440+المدخلات!$B$5/1440))-1,12)+1&":"&TEXT(MINUTE((المدخلات!$B$4+7*المدخلات!$B$5/1440+المدخلات!$B$5/1440)),"00")&IF(HOUR((المدخلات!$B$4+7*المدخلات!$B$5/1440))<12," ص"," م") -> 5:45–6:00 م | C41: 2 ضد 4 | G41: =_xlfn.TEXTJOIN(" ",TRUE,C41:C41) -> 2 ضد 4
...

Sheet 6 فرق
A1: جدول مباريات المجموعات التي فيها 6 فرق
A3: اليوم | B3: الوقت | C3: ملعب 1 | D3: ملعب 2 | E3: ملعب 3 | F3: مجموع مباريات اليوم | G3: مباريات كل فريق في اليوم
A4: اليوم 1 | B4: =MOD(HOUR((المدخلات!$B$4+0*المدخلات!$B$5/1440))-1,12)+1&":"&TEXT(MINUTE((المدخلات!$B$4+0*المدخلات!$B$5/1440)),"00")&"–"&MOD(HOUR((المدخلات!$B$4+0*المدخلات!$B$5/1440+المدخلات!$B$5/1440))-1,12)+1&":"&TEXT(MINUTE((المدخلات!$B$4+0*المدخلات!$B$5/1440+المدخلات!$B$5/1440)),"00")&IF(HOUR((المدخلات!$B$4+0*المدخلات!$B$5/1440))<12," ص"," م") -> 4:00–4:15 م | C4: 1 ضد 6 | D4: 2 ضد 5 | E4: 3 ضد 4 | F4: =COUNTIF(C4:E10,"* ضد *") -> 12 | G4: =COUNTIF(C4:E10,"* ضد *")*2/6 -> 4
B5: =MOD(HOUR((المدخلات!$B$4+1*المدخلات!$B$5/1440))-1,12)+1&":"&TEXT(MINUTE((المدخلات!$B$4+1*المدخلات!$B$5/1440)),"00")&"–"&MOD(HOUR((المدخلات!$B$4+1*المدخلات!$B$5/1440+المدخلات!$B$5/1440))-1,12)+1&":"&TEXT(MINUTE((المدخلات!$B$4+1*المدخلات!$B$5/1440+المدخلات!$B$5/1440)),"00")&IF(HOUR((المدخلات!$B$4+1*المدخلات!$B$5/1440))<12," ص"," م") -> 4:15–4:30 م | C5: استراحة (لا توجد مباريات)
B6: =MOD(HOUR((المدخلات!$B$4+2*المدخلات!$B$5/1440))-1,12)+1&":"&TEXT(MINUTE((المدخلات!$B$4+2*المدخلات!$B$5/1440)),"00")&"–"&MOD(HOUR((المدخلات!$B$4+2*المدخلات!$B$5/1440+المدخلات!$B$5/1440))-1,12)+1&":"&TEXT(MINUTE((المدخلات!$B$4+2*المدخلات!$B$5/1440+المدخلات!$B$5/1440)),"00")&IF(HOUR((المدخلات!$B$4+2*المدخلات!$B$5/1440))<12," ص"," م") -> 4:30–4:45 م | C6: 2 ضد 3 | D6: 6 ضد 4 | E6: 1 ضد 5
B7: =MOD(HOUR((المدخلات!$B$4+3*المدخلات!$B$5/1440))-1,12)+1&":"&TEXT(MINUTE((المدخلات!$B$4+3*المدخلات!$B$5/1440)),"00")&"–"&MOD(HOUR((المدخلات!$B$4+3*المدخلات!$B$5/1440+المدخلات!$B$5/1440))-1,12)+1&":"&TEXT(MINUTE((المدخلات!$B$4+3*المدخلات!$B$5/1440+المدخلات!$B$5/1440)),"00")&IF(HOUR((المدخلات!$B$4+3*المدخلات!$B$5/1440))<12," ص"," م") -> 4:45–5:00 م | C7: استراحة (لا توجد مباريات)
B8: =MOD(HOUR((المدخلات!$B$4+4*المدخلات!$B$5/1440))-1,12)+1&":"&TEXT(MINUTE((المدخلات!$B$4+4*المدخلات!$B$5/1440)),"00")&"–"&MOD(HOUR((المدخلات!$B$4+4*المدخلات!$B$5/1440+المدخلات!$B$5/1440))-1,12)+1&":"&TEXT(MINUTE((المدخلات!$B$4+4*المدخلات!$B$5/1440+المدخلات!$B$5/1440)),"00")&IF(HOUR((المدخلات!$B$4+4*المدخلات!$B$5/1440))<12," ص"," م") -> 5:00–5:15 م | C8: 5 ضد 3 | D8: 1 ضد 4 | E8: 6 ضد 2
B9: =MOD(HOUR((المدخلات!$B$4+5*المدخلات!$B$5/1440))-1,12)+1&":"&TEXT(MINUTE((المدخلات!$B$4+5*المدخلات!$B$5/1440)),"00")&"–"&MOD(HOUR((المدخلات!$B$4+5*المدخلات!$B$5/1440+المدخلات!$B$5/1440))-1,12)+1&":"&TEXT(MINUTE((المدخلات!$B$4+5*المدخلات!$B$5/1440+المدخلات!$B$5/1440)),"00")&IF(HOUR((المدخلات!$B$4+5*المدخلات!$B$5/1440))<12," ص"," م") -> 5:15–5:30 م | C9: استراحة (لا توجد مباريات)
B10: =MOD(HOUR((المدخلات!$B$4+6*المدخلات!$B$5/1440))-1,12)+1&":"&TEXT(MINUTE((المدخلات!$B$4+6*المدخلات!$B$5/1440)),"00")&"–"&MOD(HOUR((المدخلات!$B$4+6*المدخلات!$B$5/1440+المدخلات!$B$5/1440))-1,12)+1&":"&TEXT(MINUTE((المدخلات!$B$4+6*المدخلات!$B$5/1440+المدخلات!$B$5/1440)),"00")&IF(HOUR((المدخلات!$B$4+6*المدخلات!$B$5/1440))<12," ص"," م") -> 5:30–5:45 م | C10: 4 ضد 2 | D10: 1 ضد 3 | E10: 5 ضد 6
A11: اليوم 2 | B11: =MOD(HOUR((المدخلات!$B$4+0*المدخلات!$B$5/1440))-1,12)+1&":"&TEXT(MINUTE((المدخلات!$B$4+0*المدخلات!$B$5/1440)),"00")&"–"&MOD(HOUR((المدخلات!$B$4+0*المدخلات!$B$5/1440+المدخلات!$B$5/1440))-1,12)+1&":"&TEXT(MINUTE((المدخلات!$B$4+0*المدخلات!$B$5/1440+المدخلات!$B$5/1440)),"00")&IF(HOUR((المدخلات!$B$4+0*المدخلات!$B$5/1440))<12," ص"," م") -> 4:00–4:15 م | C11: 4 ضد 5 | D11: 3 ضد 6 | E11: 1 ضد 2 | F11: =COUNTIF(C11:E17,"* ضد *") -> 12 | G11: =COUNTIF(C11:E17,"* ضد *")*2/6 -> 4
B12: =MOD(HOUR((المدخلات!$B$4+1*المدخلات!$B$5/1440))-1,12)+1&":"&TEXT(MINUTE((المدخلات!$B$4+1*المدخلات!$B$5/1440)),"00")&"–"&MOD(HOUR((المدخلات!$B$4+1*المدخلات!$B$5/1440+المدخلات!$B$5/1440))-1,12)+1&":"&TEXT(MINUTE((المدخلات!$B$4+1*المدخلات!$B$5/1440+المدخلات!$B$5/1440)),"00")&IF(HOUR((المدخلات!$B$4+1*المدخلات!$B$5/1440))<12," ص"," م") -> 4:15–4:30 م | C12: استراحة (لا توجد مباريات)
B13: =MOD(HOUR((المدخلات!$B$4+2*المدخلات!$B$5/1440))-1,12)+1&":"&TEXT(MINUTE((المدخلات!$B$4+2*المدخلات!$B$5/1440)),"00")&"–"&MOD(HOUR((المدخلات!$B$4+2*المدخلات!$B$5/1440+المدخلات!$B$5/1440))-1,12)+1&":"&TEXT(MINUTE((المدخلات!$B$4+2*المدخلات!$B$5/1440+المدخلات!$B$5/1440)),"00")&IF(HOUR((المدخلات!$B$4+2*المدخلات!$B$5/1440))<12," ص"," م") -> 4:30–4:45 م | C13: 1 ضد 6 | D13: 2 ضد 5 | E13: 3 ضد 4
B14: =MOD(HOUR((المدخلات!$B$4+3*المدخلات!$B$5/1440))-1,12)+1&":"&TEXT(MINUTE((المدخلات!$B$4+3*المدخلات!$B$5/1440)),"00")&"–"&MOD(HOUR((المدخلات!$B$4+3*المدخلات!$B$5/1440+المدخلات!$B$5/1440))-1,12)+1&":"&TEXT(MINUTE((المدخلات!$B$4+3*المدخلات!$B$5/1440+المدخلات!$B$5/1440)),"00")&IF(HOUR((المدخلات!$B$4+3*المدخلات!$B$5/1440))<12," ص"," م") -> 4:45–5:00 م | C14: استراحة (لا توجد مباريات)
B15: =MOD(HOUR((المدخلات!$B$4+4*المدخلات!$B$5/1440))-1,12)+1&":"&TEXT(MINUTE((المدخلات!$B$4+4*المدخلات!$B$5/1440)),"00")&"–"&MOD(HOUR((المدخلات!$B$4+4*المدخلات!$B$5/1440+المدخلات!$B$5/1440))-1,12)+1&":"&TEXT(MINUTE((المدخلات!$B$4+4*المدخلات!$B$5/1440+المدخلات!$B$5/1440)),"00")&IF(HOUR((المدخلات!$B$4+4*المدخلات!$B$5/1440))<12," ص"," م") -> 5:00–5:15 م | C15: 1 ضد 5 | D15: 6 ضد 4 | E15: 2 ضد 3
B16: =MOD(HOUR((المدخلات!$B$4+5*المدخلات!$B$5/1440))-1,12)+1&":"&TEXT(MINUTE((المدخلات!$B$4+5*المدخلات!$B$5/1440)),"00")&"–"&MOD(HOUR((المدخلات!$B$4+5*المدخلات!$B$5/1440+المدخلات!$B$5/1440))-1,12)+1&":"&TEXT(MINUTE((المدخلات!$B$4+5*المدخلات!$B$5/1440+المدخلات!$B$5/1440)),"00")&IF(HOUR((المدخلات!$B$4+5*المدخلات!$B$5/1440))<12," ص"," م") -> 5:15–5:30 م | C16: استراحة (لا توجد مباريات)
B17: =MOD(HOUR((المدخلات!$B$4+6*المدخلات!$B$5/1440))-1,12)+1&":"&TEXT(MINUTE((المدخلات!$B$4+6*المدخلات!$B$5/1440)),"00")&"–"&MOD(HOUR((المدخلات!$B$4+6*المدخلات!$B$5/1440+المدخلات!$B$5/1440))-1,12)+1&":"&TEXT(MINUTE((المدخلات!$B$4+6*المدخلات!$B$5/1440+المدخلات!$B$5/1440)),"00")&IF(HOUR((المدخلات!$B$4+6*المدخلات!$B$5/1440))<12," ص"," م") -> 5:30–5:45 م | C17: 6 ضد 2 | D17: 5 ضد 3 | E17: 1 ضد 4
A18: اليوم 3 | B18: =MOD(HOUR((المدخلات!$B$4+0*المدخلات!$B$5/1440))-1,12)+1&":"&TEXT(MINUTE((المدخلات!$B$4+0*المدخلات!$B$5/1440)),"00")&"–"&MOD(HOUR((المدخلات!$B$4+0*المدخلات!$B$5/1440+المدخلات!$B$5/1440))-1,12)+1&":"&TEXT(MINUTE((المدخلات!$B$4+0*المدخلات!$B$5/1440+المدخلات!$B$5/1440)),"00")&IF(HOUR((المدخلات!$B$4+0*المدخلات!$B$5/1440))<12," ص"," م") -> 4:00–4:15 م | C18: 4 ضد 2 | D18: 1 ضد 3 | E18: 5 ضد 6 | F18: =COUNTIF(C18:E24,"* ضد *") -> 12 | G18: =COUNTIF(C18:E24,"* ضد *")*2/6 -> 4
B19: =MOD(HOUR((المدخلات!$B$4+1*المدخلات!$B$5/1440))-1,12)+1&":"&TEXT(MINUTE((المدخلات!$B$4+1*المدخلات!$B$5/1440)),"00")&"–"&MOD(HOUR((المدخلات!$B$4+1*المدخلات!$B$5/1440+المدخلات!$B$5/1440))-1,12)+1&":"&TEXT(MINUTE((المدخلات!$B$4+1*المدخلات!$B$5/1440+المدخلات!$B$5/1440)),"00")&IF(HOUR((المدخلات!$B$4+1*المدخلات!$B$5/1440))<12," ص"," م") -> 4:15–4:30 م | C19: استراحة (لا توجد مباريات)
B20: =MOD(HOUR((المدخلات!$B$4+2*المدخلات!$B$5/1440))-1,12)+1&":"&TEXT(MINUTE((المدخلات!$B$4+2*المدخلات!$B$5/1440)),"00")&"–"&MOD(HOUR((المدخلات!$B$4+2*المدخلات!$B$5/1440+المدخلات!$B$5/1440))-1,12)+1&":"&TEXT(MINUTE((المدخلات!$B$4+2*المدخلات!$B$5/1440+المدخلات!$B$5/1440)),"00")&IF(HOUR((المدخلات!$B$4+2*المدخلات!$B$5/1440))<12," ص"," م") -> 4:30–4:45 م | C20: 3 ضد 6 | D20: 1 ضد 2 | E20: 4 ضد 5
B21: =MOD(HOUR((المدخلات!$B$4+3*المدخلات!$B$5/1440))-1,12)+1&":"&TEXT(MINUTE((المدخلات!$B$4+3*المدخلات!$B$5/1440)),"00")&"–"&MOD(HOUR((المدخلات!$B$4+3*المدخلات!$B$5/1440+المدخلات!$B$5/1440))-1,12)+1&":"&TEXT(MINUTE((المدخلات!$B$4+3*المدخلات!$B$5/1440+المدخلات!$B$5/1440)),"00")&IF(HOUR((المدخلات!$B$4+3*المدخلات!$B$5/1440))<12," ص"," م") -> 4:45–5:00 م | C21: استراحة (لا توجد مباريات)
B22: =MOD(HOUR((المدخلات!$B$4+4*المدخلات!$B$5/1440))-1,12)+1&":"&TEXT(MINUTE((المدخلات!$B$4+4*المدخلات!$B$5/1440)),"00")&"–"&MOD(HOUR((المدخلات!$B$4+4*المدخلات!$B$5/1440+المدخلات!$B$5/1440))-1,12)+1&":"&TEXT(MINUTE((المدخلات!$B$4+4*المدخلات!$B$5/1440+المدخلات!$B$5/1440)),"00")&IF(HOUR((المدخلات!$B$4+4*المدخلات!$B$5/1440))<12," ص"," م") -> 5:00–5:15 م | C22: 3 ضد 4 | D22: 2 ضد 5 | E22: 1 ضد 6
B23: =MOD(HOUR((المدخلات!$B$4+5*المدخلات!$B$5/1440))-1,12)+1&":"&TEXT(MINUTE((المدخلات!$B$4+5*المدخلات!$B$5/1440)),"00")&"–"&MOD(HOUR((المدخلات!$B$4+5*المدخلات!$B$5/1440+المدخلات!$B$5/1440))-1,12)+1&":"&TEXT(MINUTE((المدخلات!$B$4+5*المدخلات!$B$5/1440+المدخلات!$B$5/1440)),"00")&IF(HOUR((المدخلات!$B$4+5*المدخلات!$B$5/1440))<12," ص"," م") -> 5:15–5:30 م | C23: استراحة (لا توجد مباريات)
B24: =MOD(HOUR((المدخلات!$B$4+6*المدخلات!$B$5/1440))-1,12)+1&":"&TEXT(MINUTE((المدخلات!$B$4+6*المدخلات!$B$5/1440)),"00")&"–"&MOD(HOUR((المدخلات!$B$4+6*المدخلات!$B$5/1440+المدخلات!$B$5/1440))-1,12)+1&":"&TEXT(MINUTE((المدخلات!$B$4+6*المدخلات!$B$5/1440+المدخلات!$B$5/1440)),"00")&IF(HOUR((المدخلات!$B$4+6*المدخلات!$B$5/1440))<12," ص"," م") -> 5:30–5:45 م | C24: 1 ضد 5 | D24: 6 ضد 4 | E24: 2 ضد 3
A25: اليوم 4 | B25: =MOD(HOUR((المدخلات!$B$4+0*المدخلات!$B$5/1440))-1,12)+1&":"&TEXT(MINUTE((المدخلات!$B$4+0*المدخلات!$B$5/1440)),"00")&"–"&MOD(HOUR((المدخلات!$B$4+0*المدخلات!$B$5/1440+المدخلات!$B$5/1440))-1,12)+1&":"&TEXT(MINUTE((المدخلات!$B$4+0*المدخلات!$B$5/1440+المدخلات!$B$5/1440)),"00")&IF(HOUR((المدخلات!$B$4+0*المدخلات!$B$5/1440))<12," ص"," م") -> 4:00–4:15 م | C25: 1 ضد 4 | D25: 5 ضد 3 | E25: 6 ضد 2 | F25: =COUNTIF(C25:E31,"* ضد *") -> 12 | G25: =COUNTIF(C25:E31,"* ضد *")*2/6 -> 4
B26: =MOD(HOUR((المدخلات!$B$4+1*المدخلات!$B$5/1440))-1,12)+1&":"&TEXT(MINUTE((المدخلات!$B$4+1*المدخلات!$B$5/1440)),"00")&"–"&MOD(HOUR((المدخلات!$B$4+1*المدخلات!$B$5/1440+المدخلات!$B$5/1440))-1,12)+1&":"&TEXT(MINUTE((المدخلات!$B$4+1*المدخلات!$B$5/1440+المدخلات!$B$5/1440)),"00")&IF(HOUR((المدخلات!$B$4+1*المدخلات!$B$5/1440))<12," ص"," م") -> 4:15–4:30 م | C26: استراحة (لا توجد مباريات)
B27: =MOD(HOUR((المدخلات!$B$4+2*المدخلات!$B$5/1440))-1,12)+1&":"&TEXT(MINUTE((المدخلات!$B$4+2*المدخلات!$B$5/1440)),"00")&"–"&MOD(HOUR((المدخلات!$B$4+2*المدخلات!$B$5/1440+المدخلات!$B$5/1440))-1,12)+1&":"&TEXT(MINUTE((المدخلات!$B$4+2*المدخلات!$B$5/1440+المدخلات!$B$5/1440)),"00")&IF(HOUR((المدخلات!$B$4+2*المدخلات!$B$5/1440))<12," ص"," م") -> 4:30–4:45 م | C27: 5 ضد 6 | D27: 4 ضد 2 | E27: 1 ضد 3
B28: =MOD(HOUR((المدخلات!$B$4+3*المدخلات!$B$5/1440))-1,12)+1&":"&TEXT(MINUTE((المدخلات!$B$4+3*المدخلات!$B$5/1440)),"00")&"–"&MOD(HOUR((المدخلات!$B$4+3*المدخلات!$B$5/1440+المدخلات!$B$5/1440))-1,12)+1&":"&TEXT(MINUTE((المدخلات!$B$4+3*المدخلات!$B$5/1440+المدخلات!$B$5/1440)),"00")&IF(HOUR((المدخلات!$B$4+3*المدخلات!$B$5/1440))<12," ص"," م") -> 4:45–5:00 م | C28: استراحة (لا توجد مباريات)
B29: =MOD(HOUR((المدخلات!$B$4+4*المدخلات!$B$5/1440))-1,12)+1&":"&TEXT(MINUTE((المدخلات!$B$4+4*المدخلات!$B$5/1440)),"00")&"–"&MOD(HOUR((المدخلات!$B$4+4*المدخلات!$B$5/1440+المدخلات!$B$5/1440))-1,12)+1&":"&TEXT(MINUTE((المدخلات!$B$4+4*المدخلات!$B$5/1440+المدخلات!$B$5/1440)),"00")&IF(HOUR((المدخلات!$B$4+4*المدخلات!$B$5/1440))<12," ص"," م") -> 5:00–5:15 م | C29: 3 ضد 6 | D29: 1 ضد 2 | E29: 4 ضد 5
B30: =MOD(HOUR((المدخلات!$B$4+5*المدخلات!$B$5/1440))-1,12)+1&":"&TEXT(MINUTE((المدخلات!$B$4+5*المدخلات!$B$5/1440)),"00")&"–"&MOD(HOUR((المدخلات!$B$4+5*المدخلات!$B$5/1440+المدخلات!$B$5/1440))-1,12)+1&":"&TEXT(MINUTE((المدخلات!$B$4+5*المدخلات!$B$5/1440+المدخلات!$B$5/1440)),"00")&IF(HOUR((المدخلات!$B$4+5*المدخلات!$B$5/1440))<12," ص"," م") -> 5:15–5:30 م | C30: استراحة (لا توجد مباريات)
B31: =MOD(HOUR((المدخلات!$B$4+6*المدخلات!$B$5/1440))-1,12)+1&":"&TEXT(MINUTE((المدخلات!$B$4+6*المدخلات!$B$5/1440)),"00")&"–"&MOD(HOUR((المدخلات!$B$4+6*المدخلات!$B$5/1440+المدخلات!$B$5/1440))-1,12)+1&":"&TEXT(MINUTE((المدخلات!$B$4+6*المدخلات!$B$5/1440+المدخلات!$B$5/1440)),"00")&IF(HOUR((المدخلات!$B$4+6*المدخلات!$B$5/1440))<12," ص"," م") -> 5:30–5:45 م | C31: 2 ضد 5 | D31: 1 ضد 6 | E31: 3 ضد 4
A32: اليوم 5 | B32: =MOD(HOUR((المدخلات!$B$4+0*المدخلات!$B$5/1440))-1,12)+1&":"&TEXT(MINUTE((المدخلات!$B$4+0*المدخلات!$B$5/1440)),"00")&"–"&MOD(HOUR((المدخلات!$B$4+0*المدخلات!$B$5/1440+المدخلات!$B$5/1440))-1,12)+1&":"&TEXT(MINUTE((المدخلات!$B$4+0*المدخلات!$B$5/1440+المدخلات!$B$5/1440)),"00")&IF(HOUR((المدخلات!$B$4+0*المدخلات!$B$5/1440))<12," ص"," م") -> 4:00–4:15 م | C32: 2 ضد 3 | D32: 6 ضد 4 | E32: 1 ضد 5 | F32: =COUNTIF(C32:E38,"* ضد *") -> 12 | G32: =COUNTIF(C32:E38,"* ضد *")*2/6 -> 4
B33: =MOD(HOUR((المدخلات!$B$4+1*المدخلات!$B$5/1440))-1,12)+1&":"&TEXT(MINUTE((المدخلات!$B$4+1*المدخلات!$B$5/1440)),"00")&"–"&MOD(HOUR((المدخلات!$B$4+1*المدخلات!$B$5/1440+المدخلات!$B$5/1440))-1,12)+1&":"&TEXT(MINUTE((المدخلات!$B$4+1*المدخلات!$B$5/1440+المدخلات!$B$5/1440)),"00")&IF(HOUR((المدخلات!$B$4+1*المدخلات!$B$5/1440))<12," ص"," م") -> 4:15–4:30 م | C33: استراحة (لا توجد مباريات)
B34: =MOD(HOUR((المدخلات!$B$4+2*المدخلات!$B$5/1440))-1,12)+1&":"&TEXT(MINUTE((المدخلات!$B$4+2*المدخلات!$B$5/1440)),"00")&"–"&MOD(HOUR((المدخلات!$B$4+2*المدخلات!$B$5/1440+المدخلات!$B$5/1440))-1,12)+1&":"&TEXT(MINUTE((المدخلات!$B$4+2*المدخلات!$B$5/1440+المدخلات!$B$5/1440)),"00")&IF(HOUR((المدخلات!$B$4+2*المدخلات!$B$5/1440))<12," ص"," م") -> 4:30–4:45 م | C34: 1 ضد 4 | D34: 5 ضد 3 | E34: 6 ضد 2
B35: =MOD(HOUR((المدخلات!$B$4+3*المدخلات!$B$5/1440))-1,12)+1&":"&TEXT(MINUTE((المدخلات!$B$4+3*المدخلات!$B$5/1440)),"00")&"–"&MOD(HOUR((المدخلات!$B$4+3*المدخلات!$B$5/1440+المدخلات!$B$5/1440))-1,12)+1&":"&TEXT(MINUTE((المدخلات!$B$4+3*المدخلات!$B$5/1440+المدخلات!$B$5/1440)),"00")&IF(HOUR((المدخلات!$B$4+3*المدخلات!$B$5/1440))<12," ص"," م") -> 4:45–5:00 م | C35: استراحة (لا توجد مباريات)
B36: =MOD(HOUR((المدخلات!$B$4+4*المدخلات!$B$5/1440))-1,12)+1&":"&TEXT(MINUTE((المدخلات!$B$4+4*المدخلات!$B$5/1440)),"00")&"–"&MOD(HOUR((المدخلات!$B$4+4*المدخلات!$B$5/1440+المدخلات!$B$5/1440))-1,12)+1&":"&TEXT(MINUTE((المدخلات!$B$4+4*المدخلات!$B$5/1440+المدخلات!$B$5/1440)),"00")&IF(HOUR((المدخلات!$B$4+4*المدخلات!$B$5/1440))<12," ص"," م") -> 5:00–5:15 م | C36: 1 ضد 3 | D36: 4 ضد 2 | E36: 5 ضد 6
B37: =MOD(HOUR((المدخلات!$B$4+5*المدخلات!$B$5/1440))-1,12)+1&":"&TEXT(MINUTE((المدخلات!$B$4+5*المدخلات!$B$5/1440)),"00")&"–"&MOD(HOUR((المدخلات!$B$4+5*المدخلات!$B$5/1440+المدخلات!$B$5/1440))-1,12)+1&":"&TEXT(MINUTE((المدخلات!$B$4+5*المدخلات!$B$5/1440+المدخلات!$B$5/1440)),"00")&IF(HOUR((المدخلات!$B$4+5*المدخلات!$B$5/1440))<12," ص"," م") -> 5:15–5:30 م | C37: استراحة (لا توجد مباريات)
