Workbook
Name الحد_الأدنى: [1]المدخلات!$N$3

Sheet Sheet1
G1: عدد الملاعب (تحت 13) | I1: إجمالي الملاعب المطلوبة (تحت 13) | J1: =SUM(G2:G185) -> 65
B2: تحت 14 | C2: مجموعة نجران | D2: 1 | E2: نجران | F2: 5 | G2: =IF(B2=المدخلات!$E$5,_xlfn.XLOOKUP(F2,الملخص!$A$4:$A$15,الملخص!$L$4:$L$15,"غير موجود"),"") | I2: عدد المجموعات (تحت 13) | J2: =COUNTIF(B2:B185,المدخلات!$E$5) -> 27
B3: تحت 5 | C3: مجموعة طبرجل | D3: 1 | E3: طبرجل | F3: 5 | G3: =IF(B3=المدخلات!$E$5,_xlfn.XLOOKUP(F3,الملخص!$A$4:$A$15,الملخص!$L$4:$L$15,"غير موجود"),"") | I3: أكبر عدد ملاعب لمجموعة واحدة | J3: =MAX(G2:G185) -> 6
B4: تحت 7 | C4: مجموعة طبرجل | D4: 1 | E4: طبرجل | F4: 5 | G4: =IF(B4=المدخلات!$E$5,_xlfn.XLOOKUP(F4,الملخص!$A$4:$A$15,الملخص!$L$4:$L$15,"غير موجود"),"")
B5: تحت 9 | C5: مجموعة الخرج | D5: 1 | E5: الخرج | F5: 5 | G5: =IF(B5=المدخلات!$E$5,_xlfn.XLOOKUP(F5,الملخص!$A$4:$A$15,الملخص!$L$4:$L$15,"غير موجود"),"")
B6: تحت 12 | C6: مجموعة طبرجل | D6: 1 | E6: طبرجل | F6: 5 | G6: =IF(B6=المدخلات!$E$5,_xlfn.XLOOKUP(F6,الملخص!$A$4:$A$15,الملخص!$L$4:$L$15,"غير موجود"),"")
B7: تحت 14 | C7: مجموعة طبرجل | D7: 1 | E7: طبرجل | F7: 5 | G7: =IF(B7=المدخلات!$E$5,_xlfn.XLOOKUP(F7,الملخص!$A$4:$A$15,الملخص!$L$4:$L$15,"غير موجود"),"")
B8: تحت 7 | C8: مجموعة شرورة | D8: 1 | E8: شرورة | F8: 5 | G8: =IF(B8=المدخلات!$E$5,_xlfn.XLOOKUP(F8,الملخص!$A$4:$A$15,الملخص!$L$4:$L$15,"غير موجود"),"")
B9: تحت 9 | C9: مجموعة شرورة | D9: 1 | E9: شرورة | F9: 5 | G9: =IF(B9=المدخلات!$E$5,_xlfn.XLOOKUP(F9,الملخص!$A$4:$A$15,الملخص!$L$4:$L$15,"غير موجود"),"")
B10: تحت 9 | C10: مجموعة الدوادمي | D10: 1 | E10: الدوادمي | F10: 5 | G10: =IF(B10=المدخلات!$E$5,_xlfn.XLOOKUP(F10,الملخص!$A$4:$A$15,الملخص!$L$4:$L$15,"غير موجود"),"")
B11: تحت 11 | C11: مجموعة القريات | D11: 1 | E11: القريات | F11: 5 | G11: =IF(B11=المدخلات!$E$5,_xlfn.XLOOKUP(F11,الملخص!$A$4:$A$15,الملخص!$L$4:$L$15,"غير موجود"),"")
B12: تحت 12 | C12: مجموعة القريات | D12: 1 | E12: القريات | F12: 5 | G12: =IF(B12=المدخلات!$E$5,_xlfn.XLOOKUP(F12,الملخص!$A$4:$A$15,الملخص!$L$4:$L$15,"غير موجود"),"")
B13: تحت 13 | C13: مجموعة القريات | D13: 1 | E13: القريات | F13: 5 | G13: =IF(B13=المدخلات!$E$5,_xlfn.XLOOKUP(F13,الملخص!$A$4:$A$15,الملخص!$L$4:$L$15,"غير موجود"),"") -> 1
B14: تحت 14 | C14: مجموعة القريات | D14: 1 | E14: القريات | F14: 5 | G14: =IF(B14=المدخلات!$E$5,_xlfn.XLOOKUP(F14,الملخص!$A$4:$A$15,الملخص!$L$4:$L$15,"غير موجود"),"")
B15: تحت 12 | C15: مجموعة الباحة | D15: 2 | E15: الباحة، العقيق | F15: 6 | G15: =IF(B15=المدخلات!$E$5,_xlfn.XLOOKUP(F15,الملخص!$A$4:$A$15,الملخص!$L$4:$L$15,"غير موجود"),"")
... B185: تحت 12 | C185: مجموعة جدة | D185: 1 | E185: جدة | F185: 56 | G185: =IF(B185=المدخلات!$E$5,_xlfn.XLOOKUP(F185,الملخص!$A$4:$A$15,الملخص!$L$4:$L$15,"غير موجود"),"")

Sheet المدخلات
A1: مدخلات جداول بطولات تحت 13
A3: الخلايا الزرقاء قابلة للتعديل — كل الجداول تتحدث تلقائياً
A4: البند | B4: القيمة | C4: ملاحظة | E4: الفئة | F4: المجموعة | G4: عدد المدن | H4: المدن | I4: مجموع الفرق
A5: وقت بداية اليوم | B5: 0.66666667 | C5: قابل للتعديل | E5: تحت 13 | F5: {=INDEX(Sheet1!$C$2:$C$185,_xlfn.AGGREGATE(15,6,(ROW(Sheet1!$B$2:$B$185)-1)/(Sheet1!$B$2:$B$185=$E5),COUNTIF($E$5:$E5,$E5)))} -> مجموعة القريات | G5: {=INDEX(Sheet1!$D$2:$D$185,_xlfn.AGGREGATE(15,6,(ROW(Sheet1!$B$2:$B$185)-1)/(Sheet1!$B$2:$B$185=$E5),COUNTIF($E$5:$E5,$E5)))} -> 1 | H5: {=INDEX(Sheet1!$E$2:$E$185,_xlfn.AGGREGATE(15,6,(ROW(Sheet1!$B$2:$B$185)-1)/(Sheet1!$B$2:$B$185=$E5),COUNTIF($E$5:$E5,$E5)))} -> القريات | I5: {=INDEX(Sheet1!$F$2:$F$185,_xlfn.AGGREGATE(15,6,(ROW(Sheet1!$B$2:$B$185)-1)/(Sheet1!$B$2:$B$185=$E5),COUNTIF($E$5:$E5,$E5)))} -> 5
A6: مدة المباراة (دقيقة) | B6: 85 | C6: قابل للتعديل | E6: تحت 13 | F6: {=INDEX(Sheet1!$C$2:$C$185,_xlfn.AGGREGATE(15,6,(ROW(Sheet1!$B$2:$B$185)-1)/(Sheet1!$B$2:$B$185=$E6),COUNTIF($E$5:$E6,$E6)))} -> مجموعة نجران | G6: {=INDEX(Sheet1!$D$2:$D$185,_xlfn.AGGREGATE(15,6,(ROW(Sheet1!$B$2:$B$185)-1)/(Sheet1!$B$2:$B$185=$E6),COUNTIF($E$5:$E6,$E6)))} -> 1 | H6: {=INDEX(Sheet1!$E$2:$E$185,_xlfn.AGGREGATE(15,6,(ROW(Sheet1!$B$2:$B$185)-1)/(Sheet1!$B$2:$B$185=$E6),COUNTIF($E$5:$E6,$E6)))} -> نجران | I6: {=INDEX(Sheet1!$F$2:$F$185,_xlfn.AGGREGATE(15,6,(ROW(Sheet1!$B$2:$B$185)-1)/(Sheet1!$B$2:$B$185=$E6),COUNTIF($E$5:$E6,$E6)))} -> 6
A7: الفاصل / ترتيب الملعب (دقيقة) | B7: 10 | C7: قابل للتعديل | E7: تحت 13 | F7: {=INDEX(Sheet1!$C$2:$C$185,_xlfn.AGGREGATE(15,6,(ROW(Sheet1!$B$2:$B$185)-1)/(Sheet1!$B$2:$B$185=$E7),COUNTIF($E$5:$E7,$E7)))} -> مجموعة الباحة | G7: {=INDEX(Sheet1!$D$2:$D$185,_xlfn.AGGREGATE(15,6,(ROW(Sheet1!$B$2:$B$185)-1)/(Sheet1!$B$2:$B$185=$E7),COUNTIF($E$5:$E7,$E7)))} -> 3 | H7: {=INDEX(Sheet1!$E$2:$E$185,_xlfn.AGGREGATE(15,6,(ROW(Sheet1!$B$2:$B$185)-1)/(Sheet1!$B$2:$B$185=$E7),COUNTIF($E$5:$E7,$E7)))} -> الباحة، بلقرن، العقيق | I7: {=INDEX(Sheet1!$F$2:$F$185,_xlfn.AGGREGATE(15,6,(ROW(Sheet1!$B$2:$B$185)-1)/(Sheet1!$B$2:$B$185=$E7),COUNTIF($E$5:$E7,$E7)))} -> 6
A8: طول الفترة الكاملة (دقيقة) | B8: =B6+B7 -> 95 | C8: محسوبة تلقائياً | E8: تحت 13 | F8: {=INDEX(Sheet1!$C$2:$C$185,_xlfn.AGGREGATE(15,6,(ROW(Sheet1!$B$2:$B$185)-1)/(Sheet1!$B$2:$B$185=$E8),COUNTIF($E$5:$E8,$E8)))} -> مجموعة الرس | G8: {=INDEX(Sheet1!$D$2:$D$185,_xlfn.AGGREGATE(15,6,(ROW(Sheet1!$B$2:$B$185)-1)/(Sheet1!$B$2:$B$185=$E8),COUNTIF($E$5:$E8,$E8)))} -> 2 | H8: {=INDEX(Sheet1!$E$2:$E$185,_xlfn.AGGREGATE(15,6,(ROW(Sheet1!$B$2:$B$185)-1)/(Sheet1!$B$2:$B$185=$E8),COUNTIF($E$5:$E8,$E8)))} -> الرس، البدائع | I8: {=INDEX(Sheet1!$F$2:$F$185,_xlfn.AGGREGATE(15,6,(ROW(Sheet1!$B$2:$B$185)-1)/(Sheet1!$B$2:$B$185=$E8),COUNTIF($E$5:$E8,$E8)))} -> 7
A9: أقصى عدد فترات في اليوم | B9: 3 | C9: قابل للتعديل | E9: تحت 13 | F9: {=INDEX(Sheet1!$C$2:$C$185,_xlfn.AGGREGATE(15,6,(ROW(Sheet1!$B$2:$B$185)-1)/(Sheet1!$B$2:$B$185=$E9),COUNTIF($E$5:$E9,$E9)))} -> مجموعة جازان | G9: {=INDEX(Sheet1!$D$2:$D$185,_xlfn.AGGREGATE(15,6,(ROW(Sheet1!$B$2:$B$185)-1)/(Sheet1!$B$2:$B$185=$E9),COUNTIF($E$5:$E9,$E9)))} -> 1 | H9: {=INDEX(Sheet1!$E$2:$E$185,_xlfn.AGGREGATE(15,6,(ROW(Sheet1!$B$2:$B$185)-1)/(Sheet1!$B$2:$B$185=$E9),COUNTIF($E$5:$E9,$E9)))} -> جيزان | I9: {=INDEX(Sheet1!$F$2:$F$185,_xlfn.AGGREGATE(15,6,(ROW(Sheet1!$B$2:$B$185)-1)/(Sheet1!$B$2:$B$185=$E9),COUNTIF($E$5:$E9,$E9)))} -> 7
A10: أقل عدد مباريات للفريق | B10: 16 | C10: قيد ملزم — يتقدّم على سقف الأيام | E10: تحت 13 | F10: {=INDEX(Sheet1!$C$2:$C$185,_xlfn.AGGREGATE(15,6,(ROW(Sheet1!$B$2:$B$185)-1)/(Sheet1!$B$2:$B$185=$E10),COUNTIF($E$5:$E10,$E10)))} -> مجموعة تبوك | G10: {=INDEX(Sheet1!$D$2:$D$185,_xlfn.AGGREGATE(15,6,(ROW(Sheet1!$B$2:$B$185)-1)/(Sheet1!$B$2:$B$185=$E10),COUNTIF($E$5:$E10,$E10)))} -> 1 | H10: {=INDEX(Sheet1!$E$2:$E$185,_xlfn.AGGREGATE(15,6,(ROW(Sheet1!$B$2:$B$185)-1)/(Sheet1!$B$2:$B$185=$E10),COUNTIF($E$5:$E10,$E10)))} -> تبوك | I10: {=INDEX(Sheet1!$F$2:$F$185,_xlfn.AGGREGATE(15,6,(ROW(Sheet1!$B$2:$B$185)-1)/(Sheet1!$B$2:$B$185=$E10),COUNTIF($E$5:$E10,$E10)))} -> 8
A11: سقف أيام البطولة (شامل الإقصاء) | B11: 22 | C11: يُتجاوز فقط عند تعارضه مع أقل عدد مباريات | E11: تحت 13 | F11: {=INDEX(Sheet1!$C$2:$C$185,_xlfn.AGGREGATE(15,6,(ROW(Sheet1!$B$2:$B$185)-1)/(Sheet1!$B$2:$B$185=$E11),COUNTIF($E$5:$E11,$E11)))} -> مجموعة حائل | G11: {=INDEX(Sheet1!$D$2:$D$185,_xlfn.AGGREGATE(15,6,(ROW(Sheet1!$B$2:$B$185)-1)/(Sheet1!$B$2:$B$185=$E11),COUNTIF($E$5:$E11,$E11)))} -> 1 | H11: {=INDEX(Sheet1!$E$2:$E$185,_xlfn.AGGREGATE(15,6,(ROW(Sheet1!$B$2:$B$185)-1)/(Sheet1!$B$2:$B$185=$E11),COUNTIF($E$5:$E11,$E11)))} -> حائل | I11: {=INDEX(Sheet1!$F$2:$F$185,_xlfn.AGGREGATE(15,6,(ROW(Sheet1!$B$2:$B$185)-1)/(Sheet1!$B$2:$B$185=$E11),COUNTIF($E$5:$E11,$E11)))} -> 8
E12: تحت 13 | F12: {=INDEX(Sheet1!$C$2:$C$185,_xlfn.AGGREGATE(15,6,(ROW(Sheet1!$B$2:$B$185)-1)/(Sheet1!$B$2:$B$185=$E12),COUNTIF($E$5:$E12,$E12)))} -> مجموعة مركز الرفيعة | G12: {=INDEX(Sheet1!$D$2:$D$185,_xlfn.AGGREGATE(15,6,(ROW(Sheet1!$B$2:$B$185)-1)/(Sheet1!$B$2:$B$185=$E12),COUNTIF($E$5:$E12,$E12)))} -> 1 | H12: {=INDEX(Sheet1!$E$2:$E$185,_xlfn.AGGREGATE(15,6,(ROW(Sheet1!$B$2:$B$185)-1)/(Sheet1!$B$2:$B$185=$E12),COUNTIF($E$5:$E12,$E12)))} -> مركز الرفيعة | I12: {=INDEX(Sheet1!$F$2:$F$185,_xlfn.AGGREGATE(15,6,(ROW(Sheet1!$B$2:$B$185)-1)/(Sheet1!$B$2:$B$185=$E12),COUNTIF($E$5:$E12,$E12)))} -> 8
E13: تحت 13 | F13: {=INDEX(Sheet1!$C$2:$C$185,_xlfn.AGGREGATE(15,6,(ROW(Sheet1!$B$2:$B$185)-1)/(Sheet1!$B$2:$B$185=$E13),COUNTIF($E$5:$E13,$E13)))} -> مجموعة الخرج | G13: {=INDEX(Sheet1!$D$2:$D$185,_xlfn.AGGREGATE(15,6,(ROW(Sheet1!$B$2:$B$185)-1)/(Sheet1!$B$2:$B$185=$E13),COUNTIF($E$5:$E13,$E13)))} -> 2 | H13: {=INDEX(Sheet1!$E$2:$E$185,_xlfn.AGGREGATE(15,6,(ROW(Sheet1!$B$2:$B$185)-1)/(Sheet1!$B$2:$B$185=$E13),COUNTIF($E$5:$E13,$E13)))} -> الخرج، الدلم | I13: {=INDEX(Sheet1!$F$2:$F$185,_xlfn.AGGREGATE(15,6,(ROW(Sheet1!$B$2:$B$185)-1)/(Sheet1!$B$2:$B$185=$E13),COUNTIF($E$5:$E13,$E13)))} -> 8
E14: تحت 13 | F14: {=INDEX(Sheet1!$C$2:$C$185,_xlfn.AGGREGATE(15,6,(ROW(Sheet1!$B$2:$B$185)-1)/(Sheet1!$B$2:$B$185=$E14),COUNTIF($E$5:$E14,$E14)))} -> مجموعة سكاكا | G14: {=INDEX(Sheet1!$D$2:$D$185,_xlfn.AGGREGATE(15,6,(ROW(Sheet1!$B$2:$B$185)-1)/(Sheet1!$B$2:$B$185=$E14),COUNTIF($E$5:$E14,$E14)))} -> 2 | H14: {=INDEX(Sheet1!$E$2:$E$185,_xlfn.AGGREGATE(15,6,(ROW(Sheet1!$B$2:$B$185)-1)/(Sheet1!$B$2:$B$185=$E14),COUNTIF($E$5:$E14,$E14)))} -> سكاكا، دومة الجندل | I14: {=INDEX(Sheet1!$F$2:$F$185,_xlfn.AGGREGATE(15,6,(ROW(Sheet1!$B$2:$B$185)-1)/(Sheet1!$B$2:$B$185=$E14),COUNTIF($E$5:$E14,$E14)))} -> 8
E15: تحت 13 | F15: {=INDEX(Sheet1!$C$2:$C$185,_xlfn.AGGREGATE(15,6,(ROW(Sheet1!$B$2:$B$185)-1)/(Sheet1!$B$2:$B$185=$E15),COUNTIF($E$5:$E15,$E15)))} -> مجموعة أحد المسارحة | G15: {=INDEX(Sheet1!$D$2:$D$185,_xlfn.AGGREGATE(15,6,(ROW(Sheet1!$B$2:$B$185)-1)/(Sheet1!$B$2:$B$185=$E15),COUNTIF($E$5:$E15,$E15)))} -> 1 | H15: {=INDEX(Sheet1!$E$2:$E$185,_xlfn.AGGREGATE(15,6,(ROW(Sheet1!$B$2:$B$185)-1)/(Sheet1!$B$2:$B$185=$E15),COUNTIF($E$5:$E15,$E15)))} -> أحد المسارحة | I15: {=INDEX(Sheet1!$F$2:$F$185,_xlfn.AGGREGATE(15,6,(ROW(Sheet1!$B$2:$B$185)-1)/(Sheet1!$B$2:$B$185=$E15),COUNTIF($E$5:$E15,$E15)))} -> 8
E16: تحت 13 | F16: {=INDEX(Sheet1!$C$2:$C$185,_xlfn.AGGREGATE(15,6,(ROW(Sheet1!$B$2:$B$185)-1)/(Sheet1!$B$2:$B$185=$E16),COUNTIF($E$5:$E16,$E16)))} -> مجموعة أبها | G16: {=INDEX(Sheet1!$D$2:$D$185,_xlfn.AGGREGATE(15,6,(ROW(Sheet1!$B$2:$B$185)-1)/(Sheet1!$B$2:$B$185=$E16),COUNTIF($E$5:$E16,$E16)))} -> 2 | H16: {=INDEX(Sheet1!$E$2:$E$185,_xlfn.AGGREGATE(15,6,(ROW(Sheet1!$B$2:$B$185)-1)/(Sheet1!$B$2:$B$185=$E16),COUNTIF($E$5:$E16,$E16)))} -> أبها، خميس مشيط | I16: {=INDEX(Sheet1!$F$2:$F$185,_xlfn.AGGREGATE(15,6,(ROW(Sheet1!$B$2:$B$185)-1)/(Sheet1!$B$2:$B$185=$E16),COUNTIF($E$5:$E16,$E16)))} -> 10
E17: تحت 13 | F17: {=INDEX(Sheet1!$C$2:$C$185,_xlfn.AGGREGATE(15,6,(ROW(Sheet1!$B$2:$B$185)-1)/(Sheet1!$B$2:$B$185=$E17),COUNTIF($E$5:$E17,$E17)))} -> مجموعة القصيم | G17: {=INDEX(Sheet1!$D$2:$D$185,_xlfn.AGGREGATE(15,6,(ROW(Sheet1!$B$2:$B$185)-1)/(Sheet1!$B$2:$B$185=$E17),COUNTIF($E$5:$E17,$E17)))} -> 4 | H17: {=INDEX(Sheet1!$E$2:$E$185,_xlfn.AGGREGATE(15,6,(ROW(Sheet1!$B$2:$B$185)-1)/(Sheet1!$B$2:$B$185=$E17),COUNTIF($E$5:$E17,$E17)))} -> بريدة، عيون الجواء، المذنب، عنيزة | I17: {=INDEX(Sheet1!$F$2:$F$185,_xlfn.AGGREGATE(15,6,(ROW(Sheet1!$B$2:$B$185)-1)/(Sheet1!$B$2:$B$185=$E17),COUNTIF($E$5:$E17,$E17)))} -> 10
E18: تحت 13 | F18: {=INDEX(Sheet1!$C$2:$C$185,_xlfn.AGGREGATE(15,6,(ROW(Sheet1!$B$2:$B$185)-1)/(Sheet1!$B$2:$B$185=$E18),COUNTIF($E$5:$E18,$E18)))} -> مجموعة القطيف | G18: {=INDEX(Sheet1!$D$2:$D$185,_xlfn.AGGREGATE(15,6,(ROW(Sheet1!$B$2:$B$185)-1)/(Sheet1!$B$2:$B$185=$E18),COUNTIF($E$5:$E18,$E18)))} -> 1 | H18: {=INDEX(Sheet1!$E$2:$E$185,_xlfn.AGGREGATE(15,6,(ROW(Sheet1!$B$2:$B$185)-1)/(Sheet1!$B$2:$B$185=$E18),COUNTIF($E$5:$E18,$E18)))} -> القطيف | I18: {=INDEX(Sheet1!$F$2:$F$185,_xlfn.AGGREGATE(15,6,(ROW(Sheet1!$B$2:$B$185)-1)/(Sheet1!$B$2:$B$185=$E18),COUNTIF($E$5:$E18,$E18)))} -> 10
E19: تحت 13 | F19: {=INDEX(Sheet1!$C$2:$C$185,_xlfn.AGGREGATE(15,6,(ROW(Sheet1!$B$2:$B$185)-1)/(Sheet1!$B$2:$B$185=$E19),COUNTIF($E$5:$E19,$E19)))} -> مجموعة أبو عريش | G19: {=INDEX(Sheet1!$D$2:$D$185,_xlfn.AGGREGATE(15,6,(ROW(Sheet1!$B$2:$B$185)-1)/(Sheet1!$B$2:$B$185=$E19),COUNTIF($E$5:$E19,$E19)))} -> 1 | H19: {=INDEX(Sheet1!$E$2:$E$185,_xlfn.AGGREGATE(15,6,(ROW(Sheet1!$B$2:$B$185)-1)/(Sheet1!$B$2:$B$185=$E19),COUNTIF($E$5:$E19,$E19)))} -> أبو عريش | I19: {=INDEX(Sheet1!$F$2:$F$185,_xlfn.AGGREGATE(15,6,(ROW(Sheet1!$B$2:$B$185)-1)/(Sheet1!$B$2:$B$185=$E19),COUNTIF($E$5:$E19,$E19)))} -> 10
E20: تحت 13 | F20: {=INDEX(Sheet1!$C$2:$C$185,_xlfn.AGGREGATE(15,6,(ROW(Sheet1!$B$2:$B$185)-1)/(Sheet1!$B$2:$B$185=$E20),COUNTIF($E$5:$E20,$E20)))} -> مجموعة صامطة | G20: {=INDEX(Sheet1!$D$2:$D$185,_xlfn.AGGREGATE(15,6,(ROW(Sheet1!$B$2:$B$185)-1)/(Sheet1!$B$2:$B$185=$E20),COUNTIF($E$5:$E20,$E20)))} -> 1 | H20: {=INDEX(Sheet1!$E$2:$E$185,_xlfn.AGGREGATE(15,6,(ROW(Sheet1!$B$2:$B$185)-1)/(Sheet1!$B$2:$B$185=$E20),COUNTIF($E$5:$E20,$E20)))} -> صامطة | I20: {=INDEX(Sheet1!$F$2:$F$185,_xlfn.AGGREGATE(15,6,(ROW(Sheet1!$B$2:$B$185)-1)/(Sheet1!$B$2:$B$185=$E20),COUNTIF($E$5:$E20,$E20)))} -> 10
E21: تحت 13 | F21: {=INDEX(Sheet1!$C$2:$C$185,_xlfn.AGGREGATE(15,6,(ROW(Sheet1!$B$2:$B$185)-1)/(Sheet1!$B$2:$B$185=$E21),COUNTIF($E$5:$E21,$E21)))} -> مجموعة القنفذة | G21: {=INDEX(Sheet1!$D$2:$D$185,_xlfn.AGGREGATE(15,6,(ROW(Sheet1!$B$2:$B$185)-1)/(Sheet1!$B$2:$B$185=$E21),COUNTIF($E$5:$E21,$E21)))} -> 1 | H21: {=INDEX(Sheet1!$E$2:$E$185,_xlfn.AGGREGATE(15,6,(ROW(Sheet1!$B$2:$B$185)-1)/(Sheet1!$B$2:$B$185=$E21),COUNTIF($E$5:$E21,$E21)))} -> القنفذة | I21: {=INDEX(Sheet1!$F$2:$F$185,_xlfn.AGGREGATE(15,6,(ROW(Sheet1!$B$2:$B$185)-1)/(Sheet1!$B$2:$B$185=$E21),COUNTIF($E$5:$E21,$E21)))} -> 13
E22: تحت 13 | F22: {=INDEX(Sheet1!$C$2:$C$185,_xlfn.AGGREGATE(15,6,(ROW(Sheet1!$B$2:$B$185)-1)/(Sheet1!$B$2:$B$185=$E22),COUNTIF($E$5:$E22,$E22)))} -> مجموعة المدينة المنورة | G22: {=INDEX(Sheet1!$D$2:$D$185,_xlfn.AGGREGATE(15,6,(ROW(Sheet1!$B$2:$B$185)-1)/(Sheet1!$B$2:$B$185=$E22),COUNTIF($E$5:$E22,$E22)))} -> 1 | H22: {=INDEX(Sheet1!$E$2:$E$185,_xlfn.AGGREGATE(15,6,(ROW(Sheet1!$B$2:$B$185)-1)/(Sheet1!$B$2:$B$185=$E22),COUNTIF($E$5:$E22,$E22)))} -> المدينة المنورة | I22: {=INDEX(Sheet1!$F$2:$F$185,_xlfn.AGGREGATE(15,6,(ROW(Sheet1!$B$2:$B$185)-1)/(Sheet1!$B$2:$B$185=$E22),COUNTIF($E$5:$E22,$E22)))} -> 13
E23: تحت 13 | F23: {=INDEX(Sheet1!$C$2:$C$185,_xlfn.AGGREGATE(15,6,(ROW(Sheet1!$B$2:$B$185)-1)/(Sheet1!$B$2:$B$185=$E23),COUNTIF($E$5:$E23,$E23)))} -> مجموعة الدمام | G23: {=INDEX(Sheet1!$D$2:$D$185,_xlfn.AGGREGATE(15,6,(ROW(Sheet1!$B$2:$B$185)-1)/(Sheet1!$B$2:$B$185=$E23),COUNTIF($E$5:$E23,$E23)))} -> 4 | H23: {=INDEX(Sheet1!$E$2:$E$185,_xlfn.AGGREGATE(15,6,(ROW(Sheet1!$B$2:$B$185)-1)/(Sheet1!$B$2:$B$185=$E23),COUNTIF($E$5:$E23,$E23)))} -> الظهران، الخبر، الدمام، سيهات | I23: {=INDEX(Sheet1!$F$2:$F$185,_xlfn.AGGREGATE(15,6,(ROW(Sheet1!$B$2:$B$185)-1)/(Sheet1!$B$2:$B$185=$E23),COUNTIF($E$5:$E23,$E23)))} -> 14
... E31: تحت 13 | F31: {=INDEX(Sheet1!$C$2:$C$185,_xlfn.AGGREGATE(15,6,(ROW(Sheet1!$B$2:$B$185)-1)/(Sheet1!$B$2:$B$185=$E31),COUNTIF($E$5:$E31,$E31)))} -> مجموعة الأحساء | G31: {=INDEX(Sheet1!$D$2:$D$185,_xlfn.AGGREGATE(15,6,(ROW(Sheet1!$B$2:$B$185)-1)/(Sheet1!$B$2:$B$185=$E31),COUNTIF($E$5:$E31,$E31)))} -> 1 | H31: {=INDEX(Sheet1!$E$2:$E$185,_xlfn.AGGREGATE(15,6,(ROW(Sheet1!$B$2:$B$185)-1)/(Sheet1!$B$2:$B$185=$E31),COUNTIF($E$5:$E31,$E31)))} -> الأحساء | I31: {=INDEX(Sheet1!$F$2:$F$185,_xlfn.AGGREGATE(15,6,(ROW(Sheet1!$B$2:$B$185)-1)/(Sheet1!$B$2:$B$185=$E31),COUNTIF($E$5:$E31,$E31)))} -> 34

Sheet الملخص
A1: ملخص بطولات تحت 13 – الأعداد المطلوبة
A3: عدد الفرق | B3: عدد المجموعات | C3: توزيع الفرق في المجموعات | D3: عدد الأدوار | E3: مباريات كل فريق في الموسم (غير شاملة الإقصاء) | F3: نظام الإقصاء | G3: أيام الدوري | H3: أيام الإقصاء | I3: إجمالي الأيام | J3: وقت البداية | K3: وقت النهاية | L3: عدد الملاعب القانونية | M3: تحقق القيود
A4: 5 | B4: {=ROUND(SUMPRODUCT(1/COUNTIF('بيانات الفرق U13'!$B$3:$B$7,'بيانات الفرق U13'!$B$3:$B$7)),0)} -> 1 | C4: {=_xlfn.TEXTJOIN(" + ",TRUE,_xlfn._xlws.SORT(COUNTIF('بيانات الفرق U13'!$B$3:$B$7,"المجموعة "&_xlfn.SEQUENCE(B4))))} -> 5 | D4: {=_xlfn.LET(_xlpm.gs,_xlfn.SEQUENCE(B4),_xlpm.op,_xlfn.MAXIFS('بيانات الفرق U13'!$D$3:$D$7,'بيانات الفرق U13'!$B$3:$B$7,"المجموعة "&_xlpm.gs),_xlpm.mt,_xlfn.MAXIFS('بيانات الفرق U13'!$C$3:$C$7,'بيانات الفرق U13'!$B$3:$B$7,"المجموعة "&_xlpm.gs),_xlfn.TEXTJOIN(" + ",TRUE,_xlfn.SORTBY(_xlpm.mt/_xlpm.op,_xlpm.op,1)))} -> 4 | E4: {=_xlfn.LET(_xlpm.gs,_xlfn.SEQUENCE(B4),_xlpm.ln,_xlfn.MAXIFS('بيانات الفرق U13'!$D$3:$D$7,'بيانات الفرق U13'!$B$3:$B$7,"المجموعة "&_xlpm.gs),_xlpm.mn,_xlfn.MINIFS('بيانات الفرق U13'!$C$3:$C$7,'بيانات الفرق U13'!$B$3:$B$7,"المجموعة "&_xlpm.gs),_xlpm.mx,_xlfn.MAXIFS('بيانات الفرق U13'!$C$3:$C$7,'بيانات الفرق U13'!$B$3:$B$7,"المجموعة "&_xlpm.gs),_xlpm.t,IF(_xlpm.mn=_xlpm.mx,_xlpm.mn&"",_xlpm.mn&"–"&_xlpm.mx),_xlfn.TEXTJOIN(" + ",TRUE,_xlfn.SORTBY(_xlpm.t,_xlpm.ln,1)))} -> 16 | F4: =IF(B4=1,"—",IF(B4=2,"نهائي مباشر",IF(B4<=4,"نصف نهائي ثم نهائي – كل دور في يوم","ربع نهائي ثم نصف نهائي ثم نهائي – كل دور في يوم"))) -> — | G4: =I4-H4 -> 20 | H4: {=MAX('5 فرق'!$A$4:$A$43)-SUMPRODUCT(MAX(ISNUMBER(IFERROR(--LEFT('5 فرق'!$D$4:$D$43,1),"x"))*'5 فرق'!$A$4:$A$43))} -> 0 | I4: =MAX('5 فرق'!$A$4:$A$43) -> 20 | J4: =MOD(HOUR(المدخلات!$B$5)-1,12)+1&":"&TEXT(MINUTE(المدخلات!$B$5),"00")&IF(HOUR(المدخلات!$B$5)<12," ص"," م") -> 4:00 م | K4: =MOD(HOUR(المدخلات!$B$5+((المدخلات!$B$9-1)*المدخلات!$B$8+المدخلات!$B$6)/1440)-1,12)+1&":"&TEXT(MINUTE(المدخلات!$B$5+((المدخلات!$B$9-1)*المدخلات!$B$8+المدخلات!$B$6)/1440),"00")&IF(HOUR(المدخلات!$B$5+((المدخلات!$B$9-1)*المدخلات!$B$8+المدخلات!$B$6)/1440)<12," ص"," م") -> 8:35 م | L4: =MAX('5 فرق'!$C$4:$C$43) -> 1 | M4: =IF(I4>المدخلات!$B$11,"⚠ تجاوز السقف ("&I4&" يوماً) لضمان "&المدخلات!$B$10&" مباراة","ضمن السقف") -> ضمن السقف
A5: 6 | B5: {=ROUND(SUMPRODUCT(1/COUNTIF('بيانات الفرق U13'!$G$3:$G$8,'بيانات الفرق U13'!$G$3:$G$8)),0)} -> 1 | C5: {=_xlfn.TEXTJOIN(" + ",TRUE,_xlfn._xlws.SORT(COUNTIF('بيانات الفرق U13'!$G$3:$G$8,"المجموعة "&_xlfn.SEQUENCE(B5))))} -> 6 | D5: {=_xlfn.LET(_xlpm.gs,_xlfn.SEQUENCE(B5),_xlpm.op,_xlfn.MAXIFS('بيانات الفرق U13'!$I$3:$I$8,'بيانات الفرق U13'!$G$3:$G$8,"المجموعة "&_xlpm.gs),_xlpm.mt,_xlfn.MAXIFS('بيانات الفرق U13'!$H$3:$H$8,'بيانات الفرق U13'!$G$3:$G$8,"المجموعة "&_xlpm.gs),_xlfn.TEXTJOIN(" + ",TRUE,_xlfn.SORTBY(_xlpm.mt/_xlpm.op,_xlpm.op,1)))} -> 4 | E5: {=_xlfn.LET(_xlpm.gs,_xlfn.SEQUENCE(B5),_xlpm.ln,_xlfn.MAXIFS('بيانات الفرق U13'!$I$3:$I$8,'بيانات الفرق U13'!$G$3:$G$8,"المجموعة "&_xlpm.gs),_xlpm.mn,_xlfn.MINIFS('بيانات الفرق U13'!$H$3:$H$8,'بيانات الفرق U13'!$G$3:$G$8,"المجموعة "&_xlpm.gs),_xlpm.mx,_xlfn.MAXIFS('بيانات الفرق U13'!$H$3:$H$8,'بيانات الفرق U13'!$G$3:$G$8,"المجموعة "&_xlpm.gs),_xlpm.t,IF(_xlpm.mn=_xlpm.mx,_xlpm.mn&"",_xlpm.mn&"–"&_xlpm.mx),_xlfn.TEXTJOIN(" + ",TRUE,_xlfn.SORTBY(_xlpm.t,_xlpm.ln,1)))} -> 20 | F5: =IF(B5=1,"—",IF(B5=2,"نهائي مباشر",IF(B5<=4,"نصف نهائي ثم نهائي – كل دور في يوم","ربع نهائي ثم نصف نهائي ثم نهائي – كل دور في يوم"))) -> — | G5: =I5-H5 -> 20 | H5: {=MAX('6 فرق'!$A$4:$A$63)-SUMPRODUCT(MAX(ISNUMBER(IFERROR(--LEFT('6 فرق'!$D$4:$D$63,1),"x"))*'6 فرق'!$A$4:$A$63))} -> 0 | I5: =MAX('6 فرق'!$A$4:$A$63) -> 20 | J5: =MOD(HOUR(المدخلات!$B$5)-1,12)+1&":"&TEXT(MINUTE(المدخلات!$B$5),"00")&IF(HOUR(المدخلات!$B$5)<12," ص"," م") -> 4:00 م | K5: =MOD(HOUR(المدخلات!$B$5+((المدخلات!$B$9-1)*المدخلات!$B$8+المدخلات!$B$6)/1440)-1,12)+1&":"&TEXT(MINUTE(المدخلات!$B$5+((المدخلات!$B$9-1)*المدخلات!$B$8+المدخلات!$B$6)/1440),"00")&IF(HOUR(المدخلات!$B$5+((المدخلات!$B$9-1)*المدخلات!$B$8+المدخلات!$B$6)/1440)<12," ص"," م") -> 8:35 م | L5: =MAX('6 فرق'!$C$4:$C$63) -> 1 | M5: =IF(I5>المدخلات!$B$11,"⚠ تجاوز السقف ("&I5&" يوماً) لضمان "&المدخلات!$B$10&" مباراة","ضمن السقف") -> ضمن السقف
A6: 7 | B6: {=ROUND(SUMPRODUCT(1/COUNTIF('بيانات الفرق U13'!$L$3:$L$9,'بيانات الفرق U13'!$L$3:$L$9)),0)} -> 1 | C6: {=_xlfn.TEXTJOIN(" + ",TRUE,_xlfn._xlws.SORT(COUNTIF('بيانات الفرق U13'!$L$3:$L$9,"المجموعة "&_xlfn.SEQUENCE(B6))))} -> 7 | D6: {=_xlfn.LET(_xlpm.gs,_xlfn.SEQUENCE(B6),_xlpm.op,_xlfn.MAXIFS('بيانات الفرق U13'!$N$3:$N$9,'بيانات الفرق U13'!$L$3:$L$9,"المجموعة "&_xlpm.gs),_xlpm.mt,_xlfn.MAXIFS('بيانات الفرق U13'!$M$3:$M$9,'بيانات الفرق U13'!$L$3:$L$9,"المجموعة "&_xlpm.gs),_xlfn.TEXTJOIN(" + ",TRUE,_xlfn.SORTBY(_xlpm.mt/_xlpm.op,_xlpm.op,1)))} -> 3 | E6: {=_xlfn.LET(_xlpm.gs,_xlfn.SEQUENCE(B6),_xlpm.ln,_xlfn.MAXIFS('بيانات الفرق U13'!$N$3:$N$9,'بيانات الفرق U13'!$L$3:$L$9,"المجموعة "&_xlpm.gs),_xlpm.mn,_xlfn.MINIFS('بيانات الفرق U13'!$M$3:$M$9,'بيانات الفرق U13'!$L$3:$L$9,"المجموعة "&_xlpm.gs),_xlpm.mx,_xlfn.MAXIFS('بيانات الفرق U13'!$M$3:$M$9,'بيانات الفرق U13'!$L$3:$L$9,"المجموعة "&_xlpm.gs),_xlpm.t,IF(_xlpm.mn=_xlpm.mx,_xlpm.mn&"",_xlpm.mn&"–"&_xlpm.mx),_xlfn.TEXTJOIN(" + ",TRUE,_xlfn.SORTBY(_xlpm.t,_xlpm.ln,1)))} -> 18 | F6: =IF(B6=1,"—",IF(B6=2,"نهائي مباشر",IF(B6<=4,"نصف نهائي ثم نهائي – كل دور في يوم","ربع نهائي ثم نصف نهائي ثم نهائي – كل دور في يوم"))) -> — | G6: =I6-H6 -> 21 | H6: {=MAX('7 فرق'!$A$4:$A$66)-SUMPRODUCT(MAX(ISNUMBER(IFERROR(--LEFT('7 فرق'!$D$4:$D$66,1),"x"))*'7 فرق'!$A$4:$A$66))} -> 0 | I6: =MAX('7 فرق'!$A$4:$A$66) -> 21 | J6: =MOD(HOUR(المدخلات!$B$5)-1,12)+1&":"&TEXT(MINUTE(المدخلات!$B$5),"00")&IF(HOUR(المدخلات!$B$5)<12," ص"," م") -> 4:00 م | K6: =MOD(HOUR(المدخلات!$B$5+((المدخلات!$B$9-1)*المدخلات!$B$8+المدخلات!$B$6)/1440)-1,12)+1&":"&TEXT(MINUTE(المدخلات!$B$5+((المدخلات!$B$9-1)*المدخلات!$B$8+المدخلات!$B$6)/1440),"00")&IF(HOUR(المدخلات!$B$5+((المدخلات!$B$9-1)*المدخلات!$B$8+المدخلات!$B$6)/1440)<12," ص"," م") -> 8:35 م | L6: =MAX('7 فرق'!$C$4:$C$66) -> 1 | M6: =IF(I6>المدخلات!$B$11,"⚠ تجاوز السقف ("&I6&" يوماً) لضمان "&المدخلات!$B$10&" مباراة","ضمن السقف") -> ضمن السقف
A7: 8 | B7: {=ROUND(SUMPRODUCT(1/COUNTIF('بيانات الفرق U13'!$Q$3:$Q$10,'بيانات الفرق U13'!$Q$3:$Q$10)),0)} -> 1 | C7: {=_xlfn.TEXTJOIN(" + ",TRUE,_xlfn._xlws.SORT(COUNTIF('بيانات الفرق U13'!$Q$3:$Q$10,"المجموعة "&_xlfn.SEQUENCE(B7))))} -> 8 | D7: {=_xlfn.LET(_xlpm.gs,_xlfn.SEQUENCE(B7),_xlpm.op,_xlfn.MAXIFS('بيانات الفرق U13'!$S$3:$S$10,'بيانات الفرق U13'!$Q$3:$Q$10,"المجموعة "&_xlpm.gs),_xlpm.mt,_xlfn.MAXIFS('بيانات الفرق U13'!$R$3:$R$10,'بيانات الفرق U13'!$Q$3:$Q$10,"المجموعة "&_xlpm.gs),_xlfn.TEXTJOIN(" + ",TRUE,_xlfn.SORTBY(_xlpm.mt/_xlpm.op,_xlpm.op,1)))} -> 3 | E7: {=_xlfn.LET(_xlpm.gs,_xlfn.SEQUENCE(B7),_xlpm.ln,_xlfn.MAXIFS('بيانات الفرق U13'!$S$3:$S$10,'بيانات الفرق U13'!$Q$3:$Q$10,"المجموعة "&_xlpm.gs),_xlpm.mn,_xlfn.MINIFS('بيانات الفرق U13'!$R$3:$R$10,'بيانات الفرق U13'!$Q$3:$Q$10,"المجموعة "&_xlpm.gs),_xlpm.mx,_xlfn.MAXIFS('بيانات الفرق U13'!$R$3:$R$10,'بيانات الفرق U13'!$Q$3:$Q$10,"المجموعة "&_xlpm.gs),_xlpm.t,IF(_xlpm.mn=_xlpm.mx,_xlpm.mn&"",_xlpm.mn&"–"&_xlpm.mx),_xlfn.TEXTJOIN(" + ",TRUE,_xlfn.SORTBY(_xlpm.t,_xlpm.ln,1)))} -> 21 | F7: =IF(B7=1,"—",IF(B7=2,"نهائي مباشر",IF(B7<=4,"نصف نهائي ثم نهائي – كل دور في يوم","ربع نهائي ثم نصف نهائي ثم نهائي – كل دور في يوم"))) -> — | G7: =I7-H7 -> 21 | H7: {=MAX('8 فرق'!$A$4:$A$87)-SUMPRODUCT(MAX(ISNUMBER(IFERROR(--LEFT('8 فرق'!$D$4:$D$87,1),"x"))*'8 فرق'!$A$4:$A$87))} -> 0 | I7: =MAX('8 فرق'!$A$4:$A$87) -> 21 | J7: =MOD(HOUR(المدخلات!$B$5)-1,12)+1&":"&TEXT(MINUTE(المدخلات!$B$5),"00")&IF(HOUR(المدخلات!$B$5)<12," ص"," م") -> 4:00 م | K7: =MOD(HOUR(المدخلات!$B$5+((المدخلات!$B$9-1)*المدخلات!$B$8+المدخلات!$B$6)/1440)-1,12)+1&":"&TEXT(MINUTE(المدخلات!$B$5+((المدخلات!$B$9-1)*المدخلات!$B$8+المدخلات!$B$6)/1440),"00")&IF(HOUR(المدخلات!$B$5+((المدخلات!$B$9-1)*المدخلات!$B$8+المدخلات!$B$6)/1440)<12," ص"," م") -> 8:35 م | L7: =MAX('8 فرق'!$C$4:$C$87) -> 2 | M7: =IF(I7>المدخلات!$B$11,"⚠ تجاوز السقف ("&I7&" يوماً) لضمان "&المدخلات!$B$10&" مباراة","ضمن السقف") -> ضمن السقف
A8: 10 | B8: {=ROUND(SUMPRODUCT(1/COUNTIF('بيانات الفرق U13'!$V$3:$V$12,'بيانات الفرق U13'!$V$3:$V$12)),0)} -> 1 | C8: {=_xlfn.TEXTJOIN(" + ",TRUE,_xlfn._xlws.SORT(COUNTIF('بيانات الفرق U13'!$V$3:$V$12,"المجموعة "&_xlfn.SEQUENCE(B8))))} -> 10 | D8: {=_xlfn.LET(_xlpm.gs,_xlfn.SEQUENCE(B8),_xlpm.op,_xlfn.MAXIFS('بيانات الفرق U13'!$X$3:$X$12,'بيانات الفرق U13'!$V$3:$V$12,"المجموعة "&_xlpm.gs),_xlpm.mt,_xlfn.MAXIFS('بيانات الفرق U13'!$W$3:$W$12,'بيانات الفرق U13'!$V$3:$V$12,"المجموعة "&_xlpm.gs),_xlfn.TEXTJOIN(" + ",TRUE,_xlfn.SORTBY(_xlpm.mt/_xlpm.op,_xlpm.op,1)))} -> 2 | E8: {=_xlfn.LET(_xlpm.gs,_xlfn.SEQUENCE(B8),_xlpm.ln,_xlfn.MAXIFS('بيانات الفرق U13'!$X$3:$X$12,'بيانات الفرق U13'!$V$3:$V$12,"المجموعة "&_xlpm.gs),_xlpm.mn,_xlfn.MINIFS('بيانات الفرق U13'!$W$3:$W$12,'بيانات الفرق U13'!$V$3:$V$12,"المجموعة "&_xlpm.gs),_xlpm.mx,_xlfn.MAXIFS('بيانات الفرق U13'!$W$3:$W$12,'بيانات الفرق U13'!$V$3:$V$12,"المجموعة "&_xlpm.gs),_xlpm.t,IF(_xlpm.mn=_xlpm.mx,_xlpm.mn&"",_xlpm.mn&"–"&_xlpm.mx),_xlfn.TEXTJOIN(" + ",TRUE,_xlfn.SORTBY(_xlpm.t,_xlpm.ln,1)))} -> 18 | F8: =IF(B8=1,"—",IF(B8=2,"نهائي مباشر",IF(B8<=4,"نصف نهائي ثم نهائي – كل دور في يوم","ربع نهائي ثم نصف نهائي ثم نهائي – كل دور في يوم"))) -> — | G8: =I8-H8 -> 18 | H8: {=MAX('10 فرق'!$A$4:$A$93)-SUMPRODUCT(MAX(ISNUMBER(IFERROR(--LEFT('10 فرق'!$D$4:$D$93,1),"x"))*'10 فرق'!$A$4:$A$93))} -> 0 | I8: =MAX('10 فرق'!$A$4:$A$93) -> 18 | J8: =MOD(HOUR(المدخلات!$B$5)-1,12)+1&":"&TEXT(MINUTE(المدخلات!$B$5),"00")&IF(HOUR(المدخلات!$B$5)<12," ص"," م") -> 4:00 م | K8: =MOD(HOUR(المدخلات!$B$5+((المدخلات!$B$9-1)*المدخلات!$B$8+المدخلات!$B$6)/1440)-1,12)+1&":"&TEXT(MINUTE(المدخلات!$B$5+((المدخلات!$B$9-1)*المدخلات!$B$8+المدخلات!$B$6)/1440),"00")&IF(HOUR(المدخلات!$B$5+((المدخلات!$B$9-1)*المدخلات!$B$8+المدخلات!$B$6)/1440)<12," ص"," م") -> 8:35 م | L8: =MAX('10 فرق'!$C$4:$C$93) -> 2 | M8: =IF(I8>المدخلات!$B$11,"⚠ تجاوز السقف ("&I8&" يوماً) لضمان "&المدخلات!$B$10&" مباراة","ضمن السقف") -> ضمن السقف
A9: 13 | B9: {=ROUND(SUMPRODUCT(1/COUNTIF('بيانات الفرق U13'!$AA$3:$AA$15,'بيانات الفرق U13'!$AA$3:$AA$15)),0)} -> 2 | C9: {=_xlfn.TEXTJOIN(" + ",TRUE,_xlfn._xlws.SORT(COUNTIF('بيانات الفرق U13'!$AA$3:$AA$15,"المجموعة "&_xlfn.SEQUENCE(B9))))} -> 6 + 7 | D9: {=_xlfn.LET(_xlpm.gs,_xlfn.SEQUENCE(B9),_xlpm.op,_xlfn.MAXIFS('بيانات الفرق U13'!$AC$3:$AC$15,'بيانات الفرق U13'!$AA$3:$AA$15,"المجموعة "&_xlpm.gs),_xlpm.mt,_xlfn.MAXIFS('بيانات الفرق U13'!$AB$3:$AB$15,'بيانات الفرق U13'!$AA$3:$AA$15,"المجموعة "&_xlpm.gs),_xlfn.TEXTJOIN(" + ",TRUE,_xlfn.SORTBY(_xlpm.mt/_xlpm.op,_xlpm.op,1)))} -> 4 + 3 | E9: {=_xlfn.LET(_xlpm.gs,_xlfn.SEQUENCE(B9),_xlpm.ln,_xlfn.MAXIFS('بيانات الفرق U13'!$AC$3:$AC$15,'بيانات الفرق U13'!$AA$3:$AA$15,"المجموعة "&_xlpm.gs),_xlpm.mn,_xlfn.MINIFS('بيانات الفرق U13'!$AB$3:$AB$15,'بيانات الفرق U13'!$AA$3:$AA$15,"المجموعة "&_xlpm.gs),_xlpm.mx,_xlfn.MAXIFS('بيانات الفرق U13'!$AB$3:$AB$15,'بيانات الفرق U13'!$AA$3:$AA$15,"المجموعة "&_xlpm.gs),_xlpm.t,IF(_xlpm.mn=_xlpm.mx,_xlpm.mn&"",_xlpm.mn&"–"&_xlpm.mx),_xlfn.TEXTJOIN(" + ",TRUE,_xlfn.SORTBY(_xlpm.t,_xlpm.ln,1)))} -> 20 + 18 | F9: =IF(B9=1,"—",IF(B9=2,"نهائي مباشر",IF(B9<=4,"نصف نهائي ثم نهائي – كل دور في يوم","ربع نهائي ثم نصف نهائي ثم نهائي – كل دور في يوم"))) -> نهائي مباشر | G9: =I9-H9 -> 21 | H9: {=MAX('13 فريق'!$A$4:$A$127)-SUMPRODUCT(MAX(ISNUMBER(IFERROR(--LEFT('13 فريق'!$E$4:$E$127,1),"x"))*'13 فريق'!$A$4:$A$127))} -> 1 | I9: =MAX('13 فريق'!$A$4:$A$127) -> 22 | J9: =MOD(HOUR(المدخلات!$B$5)-1,12)+1&":"&TEXT(MINUTE(المدخلات!$B$5),"00")&IF(HOUR(المدخلات!$B$5)<12," ص"," م") -> 4:00 م | K9: =MOD(HOUR(المدخلات!$B$5+((المدخلات!$B$9-1)*المدخلات!$B$8+المدخلات!$B$6)/1440)-1,12)+1&":"&TEXT(MINUTE(المدخلات!$B$5+((المدخلات!$B$9-1)*المدخلات!$B$8+المدخلات!$B$6)/1440),"00")&IF(HOUR(المدخلات!$B$5+((المدخلات!$B$9-1)*المدخلات!$B$8+المدخلات!$B$6)/1440)<12," ص"," م") -> 8:35 م | L9: =MAX('13 فريق'!$C$4:$C$127) -> 2 | M9: =IF(I9>المدخلات!$B$11,"⚠ تجاوز السقف ("&I9&" يوماً) لضمان "&المدخلات!$B$10&" مباراة","ضمن السقف") -> ضمن السقف
A10: 14 | B10: {=ROUND(SUMPRODUCT(1/COUNTIF('بيانات الفرق U13'!$AF$3:$AF$16,'بيانات الفرق U13'!$AF$3:$AF$16)),0)} -> 2 | C10: {=_xlfn.TEXTJOIN(" + ",TRUE,_xlfn._xlws.SORT(COUNTIF('بيانات الفرق U13'!$AF$3:$AF$16,"المجموعة "&_xlfn.SEQUENCE(B10))))} -> 7 + 7 | D10: {=_xlfn.LET(_xlpm.gs,_xlfn.SEQUENCE(B10),_xlpm.op,_xlfn.MAXIFS('بيانات الفرق U13'!$AH$3:$AH$16,'بيانات الفرق U13'!$AF$3:$AF$16,"المجموعة "&_xlpm.gs),_xlpm.mt,_xlfn.MAXIFS('بيانات الفرق U13'!$AG$3:$AG$16,'بيانات الفرق U13'!$AF$3:$AF$16,"المجموعة "&_xlpm.gs),_xlfn.TEXTJOIN(" + ",TRUE,_xlfn.SORTBY(_xlpm.mt/_xlpm.op,_xlpm.op,1)))} -> 3 + 3 | E10: {=_xlfn.LET(_xlpm.gs,_xlfn.SEQUENCE(B10),_xlpm.ln,_xlfn.MAXIFS('بيانات الفرق U13'!$AH$3:$AH$16,'بيانات الفرق U13'!$AF$3:$AF$16,"المجموعة "&_xlpm.gs),_xlpm.mn,_xlfn.MINIFS('بيانات الفرق U13'!$AG$3:$AG$16,'بيانات الفرق U13'!$AF$3:$AF$16,"المجموعة "&_xlpm.gs),_xlpm.mx,_xlfn.MAXIFS('بيانات الفرق U13'!$AG$3:$AG$16,'بيانات الفرق U13'!$AF$3:$AF$16,"المجموعة "&_xlpm.gs),_xlpm.t,IF(_xlpm.mn=_xlpm.mx,_xlpm.mn&"",_xlpm.mn&"–"&_xlpm.mx),_xlfn.TEXTJOIN(" + ",TRUE,_xlfn.SORTBY(_xlpm.t,_xlpm.ln,1)))} -> 18 + 18 | F10: =IF(B10=1,"—",IF(B10=2,"نهائي مباشر",IF(B10<=4,"نصف نهائي ثم نهائي – كل دور في يوم","ربع نهائي ثم نصف نهائي ثم نهائي – كل دور في يوم"))) -> نهائي مباشر | G10: =I10-H10 -> 21 | H10: {=MAX('14 فريق'!$A$4:$A$130)-SUMPRODUCT(MAX(ISNUMBER(IFERROR(--LEFT('14 فريق'!$E$4:$E$130,1),"x"))*'14 فريق'!$A$4:$A$130))} -> 1 | I10: =MAX('14 فريق'!$A$4:$A$130) -> 22 | J10: =MOD(HOUR(المدخلات!$B$5)-1,12)+1&":"&TEXT(MINUTE(المدخلات!$B$5),"00")&IF(HOUR(المدخلات!$B$5)<12," ص"," م") -> 4:00 م | K10: =MOD(HOUR(المدخلات!$B$5+((المدخلات!$B$9-1)*المدخلات!$B$8+المدخلات!$B$6)/1440)-1,12)+1&":"&TEXT(MINUTE(المدخلات!$B$5+((المدخلات!$B$9-1)*المدخلات!$B$8+المدخلات!$B$6)/1440),"00")&IF(HOUR(المدخلات!$B$5+((المدخلات!$B$9-1)*المدخلات!$B$8+المدخلات!$B$6)/1440)<12," ص"," م") -> 8:35 م | L10: =MAX('14 فريق'!$C$4:$C$130) -> 2 | M10: =IF(I10>المدخلات!$B$11,"⚠ تجاوز السقف ("&I10&" يوماً) لضمان "&المدخلات!$B$10&" مباراة","ضمن السقف") -> ضمن السقف
A11: 16 | B11: {=ROUND(SUMPRODUCT(1/COUNTIF('بيانات الفرق U13'!$AK$3:$AK$18,'بيانات الفرق U13'!$AK$3:$AK$18)),0)} -> 2 | C11: {=_xlfn.TEXTJOIN(" + ",TRUE,_xlfn._xlws.SORT(COUNTIF('بيانات الفرق U13'!$AK$3:$AK$18,"المجموعة "&_xlfn.SEQUENCE(B11))))} -> 8 + 8 | D11: {=_xlfn.LET(_xlpm.gs,_xlfn.SEQUENCE(B11),_xlpm.op,_xlfn.MAXIFS('بيانات الفرق U13'!$AM$3:$AM$18,'بيانات الفرق U13'!$AK$3:$AK$18,"المجموعة "&_xlpm.gs),_xlpm.mt,_xlfn.MAXIFS('بيانات الفرق U13'!$AL$3:$AL$18,'بيانات الفرق U13'!$AK$3:$AK$18,"المجموعة "&_xlpm.gs),_xlfn.TEXTJOIN(" + ",TRUE,_xlfn.SORTBY(_xlpm.mt/_xlpm.op,_xlpm.op,1)))} -> 3 + 3 | E11: {=_xlfn.LET(_xlpm.gs,_xlfn.SEQUENCE(B11),_xlpm.ln,_xlfn.MAXIFS('بيانات الفرق U13'!$AM$3:$AM$18,'بيانات الفرق U13'!$AK$3:$AK$18,"المجموعة "&_xlpm.gs),_xlpm.mn,_xlfn.MINIFS('بيانات الفرق U13'!$AL$3:$AL$18,'بيانات الفرق U13'!$AK$3:$AK$18,"المجموعة "&_xlpm.gs),_xlpm.mx,_xlfn.MAXIFS('بيانات الفرق U13'!$AL$3:$AL$18,'بيانات الفرق U13'!$AK$3:$AK$18,"المجموعة "&_xlpm.gs),_xlpm.t,IF(_xlpm.mn=_xlpm.mx,_xlpm.mn&"",_xlpm.mn&"–"&_xlpm.mx),_xlfn.TEXTJOIN(" + ",TRUE,_xlfn.SORTBY(_xlpm.t,_xlpm.ln,1)))} -> 21 + 21 | F11: =IF(B11=1,"—",IF(B11=2,"نهائي مباشر",IF(B11<=4,"نصف نهائي ثم نهائي – كل دور في يوم","ربع نهائي ثم نصف نهائي ثم نهائي – كل دور في يوم"))) -> نهائي مباشر | G11: =I11-H11 -> 21 | H11: {=MAX('16 فريق'!$A$4:$A$172)-SUMPRODUCT(MAX(ISNUMBER(IFERROR(--LEFT('16 فريق'!$E$4:$E$172,1),"x"))*'16 فريق'!$A$4:$A$172))} -> 1 | I11: =MAX('16 فريق'!$A$4:$A$172) -> 22 | J11: =MOD(HOUR(المدخلات!$B$5)-1,12)+1&":"&TEXT(MINUTE(المدخلات!$B$5),"00")&IF(HOUR(المدخلات!$B$5)<12," ص"," م") -> 4:00 م | K11: =MOD(HOUR(المدخلات!$B$5+((المدخلات!$B$9-1)*المدخلات!$B$8+المدخلات!$B$6)/1440)-1,12)+1&":"&TEXT(MINUTE(المدخلات!$B$5+((المدخلات!$B$9-1)*المدخلات!$B$8+المدخلات!$B$6)/1440),"00")&IF(HOUR(المدخلات!$B$5+((المدخلات!$B$9-1)*المدخلات!$B$8+المدخلات!$B$6)/1440)<12," ص"," م") -> 8:35 م | L11: =MAX('16 فريق'!$C$4:$C$172) -> 3 | M11: =IF(I11>المدخلات!$B$11,"⚠ تجاوز السقف ("&I11&" يوماً) لضمان "&المدخلات!$B$10&" مباراة","ضمن السقف") -> ضمن السقف
A12: 17 | B12: {=ROUND(SUMPRODUCT(1/COUNTIF('بيانات الفرق U13'!$AP$3:$AP$19,'بيانات الفرق U13'!$AP$3:$AP$19)),0)} -> 1 | C12: {=_xlfn.TEXTJOIN(" + ",TRUE,_xlfn._xlws.SORT(COUNTIF('بيانات الفرق U13'!$AP$3:$AP$19,"المجموعة "&_xlfn.SEQUENCE(B12))))} -> 17 | D12: {=_xlfn.LET(_xlpm.gs,_xlfn.SEQUENCE(B12),_xlpm.op,_xlfn.MAXIFS('بيانات الفرق U13'!$AR$3:$AR$19,'بيانات الفرق U13'!$AP$3:$AP$19,"المجموعة "&_xlpm.gs),_xlpm.mt,_xlfn.MAXIFS('بيانات الفرق U13'!$AQ$3:$AQ$19,'بيانات الفرق U13'!$AP$3:$AP$19,"المجموعة "&_xlpm.gs),_xlfn.TEXTJOIN(" + ",TRUE,_xlfn.SORTBY(_xlpm.mt/_xlpm.op,_xlpm.op,1)))} -> 1 | E12: {=_xlfn.LET(_xlpm.gs,_xlfn.SEQUENCE(B12),_xlpm.ln,_xlfn.MAXIFS('بيانات الفرق U13'!$AR$3:$AR$19,'بيانات الفرق U13'!$AP$3:$AP$19,"المجموعة "&_xlpm.gs),_xlpm.mn,_xlfn.MINIFS('بيانات الفرق U13'!$AQ$3:$AQ$19,'بيانات الفرق U13'!$AP$3:$AP$19,"المجموعة "&_xlpm.gs),_xlpm.mx,_xlfn.MAXIFS('بيانات الفرق U13'!$AQ$3:$AQ$19,'بيانات الفرق U13'!$AP$3:$AP$19,"المجموعة "&_xlpm.gs),_xlpm.t,IF(_xlpm.mn=_xlpm.mx,_xlpm.mn&"",_xlpm.mn&"–"&_xlpm.mx),_xlfn.TEXTJOIN(" + ",TRUE,_xlfn.SORTBY(_xlpm.t,_xlpm.ln,1)))} -> 16 | F12: =IF(B12=1,"—",IF(B12=2,"نهائي مباشر",IF(B12<=4,"نصف نهائي ثم نهائي – كل دور في يوم","ربع نهائي ثم نصف نهائي ثم نهائي – كل دور في يوم"))) -> — | G12: =I12-H12 -> 17 | H12: {=MAX('17 فريق'!$A$4:$A$139)-SUMPRODUCT(MAX(ISNUMBER(IFERROR(--LEFT('17 فريق'!$D$4:$D$139,1),"x"))*'17 فريق'!$A$4:$A$139))} -> 0 | I12: =MAX('17 فريق'!$A$4:$A$139) -> 17 | J12: =MOD(HOUR(المدخلات!$B$5)-1,12)+1&":"&TEXT(MINUTE(المدخلات!$B$5),"00")&IF(HOUR(المدخلات!$B$5)<12," ص"," م") -> 4:00 م | K12: =MOD(HOUR(المدخلات!$B$5+((المدخلات!$B$9-1)*المدخلات!$B$8+المدخلات!$B$6)/1440)-1,12)+1&":"&TEXT(MINUTE(المدخلات!$B$5+((المدخلات!$B$9-1)*المدخلات!$B$8+المدخلات!$B$6)/1440),"00")&IF(HOUR(المدخلات!$B$5+((المدخلات!$B$9-1)*المدخلات!$B$8+المدخلات!$B$6)/1440)<12," ص"," م") -> 8:35 م | L12: =MAX('17 فريق'!$C$4:$C$139) -> 3 | M12: =IF(I12>المدخلات!$B$11,"⚠ تجاوز السقف ("&I12&" يوماً) لضمان "&المدخلات!$B$10&" مباراة","ضمن السقف") -> ضمن السقف
A13: 24 | B13: {=ROUND(SUMPRODUCT(1/COUNTIF('بيانات الفرق U13'!$AU$3:$AU$26,'بيانات الفرق U13'!$AU$3:$AU$26)),0)} -> 4 | C13: {=_xlfn.TEXTJOIN(" + ",TRUE,_xlfn._xlws.SORT(COUNTIF('بيانات الفرق U13'!$AU$3:$AU$26,"المجموعة "&_xlfn.SEQUENCE(B13))))} -> 6 + 6 + 6 + 6 | D13: {=_xlfn.LET(_xlpm.gs,_xlfn.SEQUENCE(B13),_xlpm.op,_xlfn.MAXIFS('بيانات الفرق U13'!$AW$3:$AW$26,'بيانات الفرق U13'!$AU$3:$AU$26,"المجموعة "&_xlpm.gs),_xlpm.mt,_xlfn.MAXIFS('بيانات الفرق U13'!$AV$3:$AV$26,'بيانات الفرق U13'!$AU$3:$AU$26,"المجموعة "&_xlpm.gs),_xlfn.TEXTJOIN(" + ",TRUE,_xlfn.SORTBY(_xlpm.mt/_xlpm.op,_xlpm.op,1)))} -> 4 + 4 + 4 + 4 | E13: {=_xlfn.LET(_xlpm.gs,_xlfn.SEQUENCE(B13),_xlpm.ln,_xlfn.MAXIFS('بيانات الفرق U13'!$AW$3:$AW$26,'بيانات الفرق U13'!$AU$3:$AU$26,"المجموعة "&_xlpm.gs),_xlpm.mn,_xlfn.MINIFS('بيانات الفرق U13'!$AV$3:$AV$26,'بيانات الفرق U13'!$AU$3:$AU$26,"المجموعة "&_xlpm.gs),_xlpm.mx,_xlfn.MAXIFS('بيانات الفرق U13'!$AV$3:$AV$26,'بيانات الفرق U13'!$AU$3:$AU$26,"المجموعة "&_xlpm.gs),_xlpm.t,IF(_xlpm.mn=_xlpm.mx,_xlpm.mn&"",_xlpm.mn&"–"&_xlpm.mx),_xlfn.TEXTJOIN(" + ",TRUE,_xlfn.SORTBY(_xlpm.t,_xlpm.ln,1)))} -> 20 + 20 + 20 + 20 | F13: =IF(B13=1,"—",IF(B13=2,"نهائي مباشر",IF(B13<=4,"نصف نهائي ثم نهائي – كل دور في يوم","ربع نهائي ثم نصف نهائي ثم نهائي – كل دور في يوم"))) -> نصف نهائي ثم نهائي – كل دور في يوم | G13: =I13-H13 -> 20 | H13: {=MAX('24 فريق'!$A$4:$A$246)-SUMPRODUCT(MAX(ISNUMBER(IFERROR(--LEFT('24 فريق'!$E$4:$E$246,1),"x"))*'24 فريق'!$A$4:$A$246))} -> 2 | I13: =MAX('24 فريق'!$A$4:$A$246) -> 22 | J13: =MOD(HOUR(المدخلات!$B$5)-1,12)+1&":"&TEXT(MINUTE(المدخلات!$B$5),"00")&IF(HOUR(المدخلات!$B$5)<12," ص"," م") -> 4:00 م | K13: =MOD(HOUR(المدخلات!$B$5+((المدخلات!$B$9-1)*المدخلات!$B$8+المدخلات!$B$6)/1440)-1,12)+1&":"&TEXT(MINUTE(المدخلات!$B$5+((المدخلات!$B$9-1)*المدخلات!$B$8+المدخلات!$B$6)/1440),"00")&IF(HOUR(المدخلات!$B$5+((المدخلات!$B$9-1)*المدخلات!$B$8+المدخلات!$B$6)/1440)<12," ص"," م") -> 8:35 م | L13: =MAX('24 فريق'!$C$4:$C$246) -> 4 | M13: =IF(I13>المدخلات!$B$11,"⚠ تجاوز السقف ("&I13&" يوماً) لضمان "&المدخلات!$B$10&" مباراة","ضمن السقف") -> ضمن السقف
A14: 29 | B14: {=ROUND(SUMPRODUCT(1/COUNTIF('بيانات الفرق U13'!$AZ$3:$AZ$31,'بيانات الفرق U13'!$AZ$3:$AZ$31)),0)} -> 3 | C14: {=_xlfn.TEXTJOIN(" + ",TRUE,_xlfn._xlws.SORT(COUNTIF('بيانات الفرق U13'!$AZ$3:$AZ$31,"المجموعة "&_xlfn.SEQUENCE(B14))))} -> 9 + 10 + 10 | D14: {=_xlfn.LET(_xlpm.gs,_xlfn.SEQUENCE(B14),_xlpm.op,_xlfn.MAXIFS('بيانات الفرق U13'!$BB$3:$BB$31,'بيانات الفرق U13'!$AZ$3:$AZ$31,"المجموعة "&_xlpm.gs),_xlpm.mt,_xlfn.MAXIFS('بيانات الفرق U13'!$BA$3:$BA$31,'بيانات الفرق U13'!$AZ$3:$AZ$31,"المجموعة "&_xlpm.gs),_xlfn.TEXTJOIN(" + ",TRUE,_xlfn.SORTBY(_xlpm.mt/_xlpm.op,_xlpm.op,1)))} -> 2 + 2 + 2 | E14: {=_xlfn.LET(_xlpm.gs,_xlfn.SEQUENCE(B14),_xlpm.ln,_xlfn.MAXIFS('بيانات الفرق U13'!$BB$3:$BB$31,'بيانات الفرق U13'!$AZ$3:$AZ$31,"المجموعة "&_xlpm.gs),_xlpm.mn,_xlfn.MINIFS('بيانات الفرق U13'!$BA$3:$BA$31,'بيانات الفرق U13'!$AZ$3:$AZ$31,"المجموعة "&_xlpm.gs),_xlpm.mx,_xlfn.MAXIFS('بيانات الفرق U13'!$BA$3:$BA$31,'بيانات الفرق U13'!$AZ$3:$AZ$31,"المجموعة "&_xlpm.gs),_xlpm.t,IF(_xlpm.mn=_xlpm.mx,_xlpm.mn&"",_xlpm.mn&"–"&_xlpm.mx),_xlfn.TEXTJOIN(" + ",TRUE,_xlfn.SORTBY(_xlpm.t,_xlpm.ln,1)))} -> 16 + 18 + 18 | F14: =IF(B14=1,"—",IF(B14=2,"نهائي مباشر",IF(B14<=4,"نصف نهائي ثم نهائي – كل دور في يوم","ربع نهائي ثم نصف نهائي ثم نهائي – كل دور في يوم"))) -> نصف نهائي ثم نهائي – كل دور في يوم | G14: =I14-H14 -> 18 | H14: {=MAX('29 فريق'!$A$4:$A$258)-SUMPRODUCT(MAX(ISNUMBER(IFERROR(--LEFT('29 فريق'!$E$4:$E$258,1),"x"))*'29 فريق'!$A$4:$A$258))} -> 2 | I14: =MAX('29 فريق'!$A$4:$A$258) -> 20 | J14: =MOD(HOUR(المدخلات!$B$5)-1,12)+1&":"&TEXT(MINUTE(المدخلات!$B$5),"00")&IF(HOUR(المدخلات!$B$5)<12," ص"," م") -> 4:00 م | K14: =MOD(HOUR(المدخلات!$B$5+((المدخلات!$B$9-1)*المدخلات!$B$8+المدخلات!$B$6)/1440)-1,12)+1&":"&TEXT(MINUTE(المدخلات!$B$5+((المدخلات!$B$9-1)*المدخلات!$B$8+المدخلات!$B$6)/1440),"00")&IF(HOUR(المدخلات!$B$5+((المدخلات!$B$9-1)*المدخلات!$B$8+المدخلات!$B$6)/1440)<12," ص"," م") -> 8:35 م | L14: =MAX('29 فريق'!$C$4:$C$258) -> 5 | M14: =IF(I14>المدخلات!$B$11,"⚠ تجاوز السقف ("&I14&" يوماً) لضمان "&المدخلات!$B$10&" مباراة","ضمن السقف") -> ضمن السقف
A15: 34 | B15: {=ROUND(SUMPRODUCT(1/COUNTIF('بيانات الفرق U13'!$BE$3:$BE$36,'بيانات الفرق U13'!$BE$3:$BE$36)),0)} -> 2 | C15: {=_xlfn.TEXTJOIN(" + ",TRUE,_xlfn._xlws.SORT(COUNTIF('بيانات الفرق U13'!$BE$3:$BE$36,"المجموعة "&_xlfn.SEQUENCE(B15))))} -> 17 + 17 | D15: {=_xlfn.LET(_xlpm.gs,_xlfn.SEQUENCE(B15),_xlpm.op,_xlfn.MAXIFS('بيانات الفرق U13'!$BG$3:$BG$36,'بيانات الفرق U13'!$BE$3:$BE$36,"المجموعة "&_xlpm.gs),_xlpm.mt,_xlfn.MAXIFS('بيانات الفرق U13'!$BF$3:$BF$36,'بيانات الفرق U13'!$BE$3:$BE$36,"المجموعة "&_xlpm.gs),_xlfn.TEXTJOIN(" + ",TRUE,_xlfn.SORTBY(_xlpm.mt/_xlpm.op,_xlpm.op,1)))} -> 1 + 1 | E15: {=_xlfn.LET(_xlpm.gs,_xlfn.SEQUENCE(B15),_xlpm.ln,_xlfn.MAXIFS('بيانات الفرق U13'!$BG$3:$BG$36,'بيانات الفرق U13'!$BE$3:$BE$36,"المجموعة "&_xlpm.gs),_xlpm.mn,_xlfn.MINIFS('بيانات الفرق U13'!$BF$3:$BF$36,'بيانات الفرق U13'!$BE$3:$BE$36,"المجموعة "&_xlpm.gs),_xlpm.mx,_xlfn.MAXIFS('بيانات الفرق U13'!$BF$3:$BF$36,'بيانات الفرق U13'!$BE$3:$BE$36,"المجموعة "&_xlpm.gs),_xlpm.t,IF(_xlpm.mn=_xlpm.mx,_xlpm.mn&"",_xlpm.mn&"–"&_xlpm.mx),_xlfn.TEXTJOIN(" + ",TRUE,_xlfn.SORTBY(_xlpm.t,_xlpm.ln,1)))} -> 16 + 16 | F15: =IF(B15=1,"—",IF(B15=2,"نهائي مباشر",IF(B15<=4,"نصف نهائي ثم نهائي – كل دور في يوم","ربع نهائي ثم نصف نهائي ثم نهائي – كل دور في يوم"))) -> نهائي مباشر | G15: =I15-H15 -> 17 | H15: {=MAX('34 فريق'!$A$4:$A$276)-SUMPRODUCT(MAX(ISNUMBER(IFERROR(--LEFT('34 فريق'!$E$4:$E$276,1),"x"))*'34 فريق'!$A$4:$A$276))} -> 1 | I15: =MAX('34 فريق'!$A$4:$A$276) -> 18 | J15: =MOD(HOUR(المدخلات!$B$5)-1,12)+1&":"&TEXT(MINUTE(المدخلات!$B$5),"00")&IF(HOUR(المدخلات!$B$5)<12," ص"," م") -> 4:00 م | K15: =MOD(HOUR(المدخلات!$B$5+((المدخلات!$B$9-1)*المدخلات!$B$8+المدخلات!$B$6)/1440)-1,12)+1&":"&TEXT(MINUTE(المدخلات!$B$5+((المدخلات!$B$9-1)*المدخلات!$B$8+المدخلات!$B$6)/1440),"00")&IF(HOUR(المدخلات!$B$5+((المدخلات!$B$9-1)*المدخلات!$B$8+المدخلات!$B$6)/1440)<12," ص"," م") -> 8:35 م | L15: =MAX('34 فريق'!$C$4:$C$276) -> 6 | M15: =IF(I15>المدخلات!$B$11,"⚠ تجاوز السقف ("&I15&" يوماً) لضمان "&المدخلات!$B$10&" مباراة","ضمن السقف") -> ضمن السقف
B17: {=SUMPRODUCT(COUNTIF(المدخلات!$I$5:$I$31,$A$4:$A$15)*_xlfn.VSTACK(COUNTA('5 فرق'!$D$4:$D$43),COUNTA('6 فرق'!$D$4:$D$63),COUNTA('7 فرق'!$D$4:$D$66),COUNTA('8 فرق'!$D$4:$D$87),COUNTA('10 فرق'!$D$4:$D$93),COUNTA('13 فريق'!$E$4:$E$127),COUNTA('14 فريق'!$E$4:$E$130),COUNTA('16 فريق'!$E$4:$E$172),COUNTA('17 فريق'!$D$4:$D$139),COUNTA('24 فريق'!$E$4:$E$246),COUNTA('29 فريق'!$E$4:$E$258),COUNTA('34 فريق'!$E$4:$E$276)))} -> 3260 | C17: إجمالي عدد المباريات (كل المجموعات)

Sheet 5 فرق
A1: بطولة 5 فرق – تحت 13
A3: اليوم | B3: الوقت | C3: الملعب | D3: المباراة
A4: 1 | B4: 4:00–5:25 م | C4: 1 | D4: 2 ضد 5
A5: 1 | B5: 5:35–7:00 م | C5: 1 | D5: 3 ضد 4
A6: 2 | B6: 4:00–5:25 م | C6: 1 | D6: 2 ضد 3
A7: 2 | B7: 5:35–7:00 م | C7: 1 | D7: 1 ضد 5
A8: 3 | B8: 4:00–5:25 م | C8: 1 | D8: 1 ضد 4
A9: 3 | B9: 5:35–7:00 م | C9: 1 | D9: 5 ضد 3
A10: 4 | B10: 4:00–5:25 م | C10: 1 | D10: 1 ضد 3
A11: 4 | B11: 5:35–7:00 م | C11: 1 | D11: 4 ضد 2
A12: 5 | B12: 4:00–5:25 م | C12: 1 | D12: 4 ضد 5
A13: 5 | B13: 5:35–7:00 م | C13: 1 | D13: 1 ضد 2
A14: 6 | B14: 4:00–5:25 م | C14: 1 | D14: 5 ضد 2
A15: 6 | B15: 5:35–7:00 م | C15: 1 | D15: 4 ضد 3
... A43: 20 | B43: 5:35–7:00 م | C43: 1 | D43: 2 ضد 1
B46: توزيع الفرق على مجموعة القريات — يُعبّأ بأسماء الفرق
B47: # | C47: الفرق (1-5) | F47: التصنيف
B48: 1 | C48: القريات | F48: نادي
B49: 2 | C49: اشبيلية بارك الرياضية | F49: أكاديمية
B50: 3 | C50: وولف | F50: هواة
B51: 4 | C51: اكاديمية المستقبل | F51: هواة
B52: 5 | C52: باريس الجوف | F52: هواة

Sheet 6 فرق
A1: بطولة 6 فرق – تحت 13
A3: اليوم | B3: الوقت | C3: الملعب | D3: المباراة
A4: 1 | B4: 4:00–5:25 م | C4: 1 | D4: 2 ضد 5
A5: 1 | B5: 5:35–7:00 م | C5: 1 | D5: 3 ضد 4
A6: 1 | B6: 7:10–8:35 م | C6: 1 | D6: 1 ضد 6
A7: 2 | B7: 4:00–5:25 م | C7: 1 | D7: 6 ضد 4
A8: 2 | B8: 5:35–7:00 م | C8: 1 | D8: 1 ضد 5
A9: 2 | B9: 7:10–8:35 م | C9: 1 | D9: 2 ضد 3
A10: 3 | B10: 4:00–5:25 م | C10: 1 | D10: 5 ضد 3
A11: 3 | B11: 5:35–7:00 م | C11: 1 | D11: 6 ضد 2
A12: 3 | B12: 7:10–8:35 م | C12: 1 | D12: 1 ضد 4
A13: 4 | B13: 4:00–5:25 م | C13: 1 | D13: 4 ضد 2
A14: 4 | B14: 5:35–7:00 م | C14: 1 | D14: 1 ضد 3
A15: 4 | B15: 7:10–8:35 م | C15: 1 | D15: 5 ضد 6
... A63: 20 | B63: 7:10–8:35 م | C63: 1 | D63: 6 ضد 3
B66: توزيع الفرق على مجموعة نجران — يُعبّأ بأسماء الفرق
B67: # | C67: الفرق (1-6) | F67: التصنيف
B68: 1 | C68: إيزوف | F68: أكاديمية
B69: 2 | C69: اكاديمية سهيل | F69: أكاديمية
B70: 3 | C70: الوداد الشرقي | F70: أكاديمية
B71: 4 | C71: اكاديمية موهبه اجيال المنصورة | F71: أكاديمية
B72: 5 | C72: موهبة الاجيال | F72: أكاديمية
B73: 6 | C73: رواد الكرة | F73: أكاديمية
B76: توزيع الفرق على مجموعة الباحة — يُعبّأ بأسماء الفرق
B77: # | C77: الفرق (1-6) | F77: التصنيف
B78: 1 | C78: البشائر | F78: نادي
B79: 2 | C79: الحجاز | F79: نادي
B80: 3 | C80: الصحراء الرياضية | F80: أكاديمية
B81: 4 | C81: تيم قول | F81: أكاديمية
B82: 5 | C82: اكاديمية اس اف | F82: هواة
B83: 6 | C83: شعلة الباحة | F83: هواة

Sheet 7 فرق
A1: بطولة 7 فرق – تحت 13
A3: اليوم | B3: الوقت | C3: الملعب | D3: المباراة
A4: 1 | B4: 4:00–5:25 م | C4: 1 | D4: 2 ضد 7
A5: 1 | B5: 5:35–7:00 م | C5: 1 | D5: 4 ضد 5
A6: 1 | B6: 7:10–8:35 م | C6: 1 | D6: 3 ضد 6
A7: 2 | B7: 4:00–5:25 م | C7: 1 | D7: 2 ضد 5
A8: 2 | B8: 5:35–7:00 م | C8: 1 | D8: 3 ضد 4
A9: 2 | B9: 7:10–8:35 م | C9: 1 | D9: 1 ضد 7
A10: 3 | B10: 4:00–5:25 م | C10: 1 | D10: 1 ضد 6
A11: 3 | B11: 5:35–7:00 م | C11: 1 | D11: 7 ضد 5
A12: 3 | B12: 7:10–8:35 م | C12: 1 | D12: 2 ضد 3
A13: 4 | B13: 4:00–5:25 م | C13: 1 | D13: 6 ضد 4
A14: 4 | B14: 5:35–7:00 م | C14: 1 | D14: 7 ضد 3
A15: 4 | B15: 7:10–8:35 م | C15: 1 | D15: 1 ضد 5
... A66: 21 | B66: 7:10–8:35 م | C66: 1 | D66: 5 ضد 6
B69: توزيع الفرق على مجموعة الرس — يُعبّأ بأسماء الفرق
B70: # | C70: الفرق (1-7) | F70: التصنيف
B71: 1 | C71: القصيم | F71: نادي
B72: 2 | C72: الخلود | F72: نادي
B73: 3 | C73: نادي الحزم الرياضي | F73: نادي
B74: 4 | C74: نادي البدائع | F74: نادي
B75: 5 | C75: الشنانة | F75: أكاديمية
B76: 6 | C76: أتلتيك | F76: أكاديمية
B77: 7 | C77: اكاديمية بلنسية | F77: أكاديمية
B80: توزيع الفرق على مجموعة جازان — يُعبّأ بأسماء الفرق
B81: # | C81: الفرق (1-7) | F81: التصنيف
B82: 1 | C82: سحار | F82: هواة
B83: 2 | C83: الجاردن | F83: هواة
B84: 3 | C84: العدايا | F84: هواة
B85: 4 | C85: النجوم بجازان | F85: هواة
B86: 5 | C86: سانتوس جيزان | F86: هواة
B87: 6 | C87: صقور الوادي | F87: هواة
B88: 7 | C88: فريق منشبة | F88: هواة

Sheet 8 فرق
A1: بطولة 8 فرق – تحت 13
A3: اليوم | B3: الوقت | C3: الملعب | D3: المباراة
A4: 1 | B4: 4:00–5:25 م | C4: 1 | D4: 4 ضد 5
A5: 1 | B5: 5:35–7:00 م | C5: 1 | D5: 2 ضد 7
A6: 1 | B6: 5:35–7:00 م | C6: 2 | D6: 1 ضد 8
A7: 1 | B7: 7:10–8:35 م | C7: 1 | D7: 3 ضد 6
A8: 2 | B8: 4:00–5:25 م | C8: 1 | D8: 1 ضد 7
A9: 2 | B9: 5:35–7:00 م | C9: 1 | D9: 3 ضد 4
A10: 2 | B10: 7:10–8:35 م | C10: 1 | D10: 8 ضد 6
A11: 2 | B11: 7:10–8:35 م | C11: 2 | D11: 2 ضد 5
A12: 3 | B12: 4:00–5:25 م | C12: 1 | D12: 8 ضد 4
A13: 3 | B13: 5:35–7:00 م | C13: 1 | D13: 1 ضد 6
A14: 3 | B14: 7:10–8:35 م | C14: 1 | D14: 2 ضد 3
A15: 3 | B15: 7:10–8:35 م | C15: 2 | D15: 7 ضد 5
... A87: 21 | B87: 7:10–8:35 م | C87: 1 | D87: 4 ضد 7
B90: توزيع الفرق على مجموعة تبوك — يُعبّأ بأسماء الفرق
B91: # | C91: الفرق (1-8) | F91: التصنيف
B92: 1 | C92: نيوم | F92: نادي
B93: 2 | C93: الحوراء | F93: نادي
B94: 3 | C94: الكاسر | F94: أكاديمية
B95: 4 | C95: اكاديمية E9 | F95: أكاديمية
B96: 5 | C96: اكاديمية بيتيس تبوك | F96: هواة
B97: 6 | C97: نمور تبوك | F97: هواة
B98: 7 | C98: اكاديمية الامبراطور تبوك | F98: هواة
B99: 8 | C99: اكاديمية سمارت تبوك | F99: هواة
B102: توزيع الفرق على مجموعة حائل — يُعبّأ بأسماء الفرق
B103: # | C103: الفرق (1-8) | F103: التصنيف
B104: 1 | C104: الطائي | F104: نادي
B105: 2 | C105: الجبلين | F105: نادي
B106: 3 | C106: الريان | F106: نادي
B107: 4 | C107: نادي جبة | F107: نادي
B108: 5 | C108: فيد | F108: نادي
B109: 6 | C109: اكاديمية سلمى | F109: أكاديمية
B110: 7 | C110: تكتيك | F110: أكاديمية
B111: 8 | C111: العنابي الماسي | F111: أكاديمية
B114: توزيع الفرق على مجموعة مركز الرفيعة — يُعبّأ بأسماء الفرق
B115: # | C115: الفرق (1-8) | F115: التصنيف
B116: 1 | C116: قرية العليا | F116: أكاديمية
B117: 2 | C117: نخبة الصمان | F117: هواة
B118: 3 | C118: النخبوي | F118: هواة
...

Sheet 10 فرق
A1: بطولة 10 فرق – تحت 13
A3: اليوم | B3: الوقت | C3: الملعب | D3: المباراة
A4: 1 | B4: 4:00–5:25 م | C4: 1 | D4: 3 ضد 8
A5: 1 | B5: 4:00–5:25 م | C5: 2 | D5: 2 ضد 9
A6: 1 | B6: 5:35–7:00 م | C6: 1 | D6: 5 ضد 6
A7: 1 | B7: 7:10–8:35 م | C7: 1 | D7: 4 ضد 7
A8: 1 | B8: 7:10–8:35 م | C8: 2 | D8: 1 ضد 10
A9: 2 | B9: 4:00–5:25 م | C9: 1 | D9: 4 ضد 5
A10: 2 | B10: 4:00–5:25 م | C10: 2 | D10: 10 ضد 8
A11: 2 | B11: 5:35–7:00 م | C11: 1 | D11: 2 ضد 7
A12: 2 | B12: 5:35–7:00 م | C12: 2 | D12: 1 ضد 9
A13: 2 | B13: 7:10–8:35 م | C13: 1 | D13: 3 ضد 6
A14: 3 | B14: 4:00–5:25 م | C14: 1 | D14: 1 ضد 8
A15: 3 | B15: 4:00–5:25 م | C15: 2 | D15: 9 ضد 7
... A93: 18 | B93: 7:10–8:35 م | C93: 2 | D93: 8 ضد 5
B96: توزيع الفرق على مجموعة أبها — يُعبّأ بأسماء الفرق
B97: # | C97: الفرق (1-10) | F97: التصنيف
B98: 1 | C98: ضمك | F98: نادي
B99: 2 | C99: ابها | F99: نادي
B100: 3 | C100: الرواد الرياضية | F100: أكاديمية
B101: 4 | C101: مستقبل الخميس | F101: أكاديمية
B102: 5 | C102: اكاديمية نجوم الاوائل | F102: أكاديمية
B103: 6 | C103: غيوم الرياضية | F103: أكاديمية
B104: 7 | C104: براعم الموهوبين | F104: أكاديمية
B105: 8 | C105: اكاديمية وهب | F105: هواة
B106: 9 | C106: اكاديمية تندحة الرياضية | F106: هواة
B107: 10 | C107: زعيم الجنوب | F107: هواة
B110: توزيع الفرق على مجموعة القصيم — يُعبّأ بأسماء الفرق
B111: # | C111: الفرق (1-10) | F111: التصنيف
B112: 1 | C112: الصقر | F112: نادي
B113: 2 | C113: عيون الجواء | F113: نادي
B114: 3 | C114: التعاون | F114: نادي
B115: 4 | C115: نادي العربي | F115: نادي
B116: 5 | C116: التقدم | F116: نادي
B117: 6 | C117: تالنت | F117: أكاديمية
B118: 7 | C118: اكاديمية موهبة الرياضية | F118: أكاديمية
B119: 8 | C119: اكاديمية أبناء | F119: هواة
B120: 9 | C120: صانع الاهداف | F120: هواة
B121: 10 | C121: اف 10 شقة | F121: هواة
B124: توزيع الفرق على مجموعة القطيف — يُعبّأ بأسماء الفرق
...

Sheet 13 فريق
A1: بطولة 13 فريق – تحت 13
A3: اليوم | B3: الوقت | C3: الملعب | D3: المجموعة | E3: المباراة
A4: 1 | B4: 4:00–5:25 م | C4: 1 | D4: 1 | E4: 2 ضد 5
A5: 1 | B5: 4:00–5:25 م | C5: 2 | D5: 1 | E5: 1 ضد 6
A6: 1 | B6: 5:35–7:00 م | C6: 1 | D6: 1 | E6: 3 ضد 4
A7: 1 | B7: 5:35–7:00 م | C7: 2 | D7: 2 | E7: 10 ضد 11
A8: 1 | B8: 7:10–8:35 م | C8: 1 | D8: 2 | E8: 9 ضد 12
A9: 1 | B9: 7:10–8:35 م | C9: 2 | D9: 2 | E9: 8 ضد 13
A10: 2 | B10: 4:00–5:25 م | C10: 1 | D10: 2 | E10: 9 ضد 10
A11: 2 | B11: 4:00–5:25 م | C11: 2 | D11: 2 | E11: 8 ضد 11
A12: 2 | B12: 5:35–7:00 م | C12: 1 | D12: 1 | E12: 1 ضد 5
A13: 2 | B13: 5:35–7:00 م | C13: 2 | D13: 2 | E13: 7 ضد 13
A14: 2 | B14: 7:10–8:35 م | C14: 1 | D14: 1 | E14: 2 ضد 3
A15: 2 | B15: 7:10–8:35 م | C15: 2 | D15: 1 | E15: 6 ضد 4
... A126: 21 | B126: 7:10–8:35 م | C126: 1 | D126: 2 | E126: 7 ضد 8
A127: 22 | B127: =MOD(HOUR(المدخلات!$B$5+0*المدخلات!$B$8/1440)-1,12)+1&":"&TEXT(MINUTE(المدخلات!$B$5+0*المدخلات!$B$8/1440),"00")&"–"&MOD(HOUR(المدخلات!$B$5+0*المدخلات!$B$8/1440+المدخلات!$B$6/1440)-1,12)+1&":"&TEXT(MINUTE(المدخلات!$B$5+0*المدخلات!$B$8/1440+المدخلات!$B$6/1440),"00")&IF(HOUR(المدخلات!$B$5+0*المدخلات!$B$8/1440)<12," ص"," م") -> 4:00–5:25 م | C127: 1 | D127: — | E127: أول المجموعة 1 ضد أول المجموعة 2
B130: توزيع الفرق على مجموعة القنفذة — يُعبّأ بأسماء الفرق
B131: # | C131: المجموعة أ (الفرق 1-6) | F131: التصنيف | I131: # | J131: المجموعة ب (الفرق 7-13) | M131: التصنيف
B132: 1 | C132: تضامن القنفذة بالقوز | F132: أكاديمية | I132: 7 | J132: القنفذة | M132: نادي
B133: 2 | C133: فريق بحلي | F133: هواة | I133: 8 | J133: شباب الفلحة | M133: هواة
B134: 3 | C134: ثلاثا يبه | F134: هواة | I134: 9 | J134: النجم بالحويرس | M134: هواة
B135: 4 | C135: اتحاد دوقة | F135: هواة | I135: 10 | J135: اكادمية السهم | M135: هواة
B136: 5 | C136: البرك | F136: هواة | I136: 11 | J136: وحدة عنيكر | M136: هواة
B137: 6 | C137: اكاديمية عز تن | F137: هواة | I137: 12 | J137: زد ام سي القنفذة | M137: هواة
I138: 13 | J138: اكاديمية X5 | M138: هواة
B141: توزيع الفرق على مجموعة المدينة المنورة — يُعبّأ بأسماء الفرق
B142: # | C142: المجموعة أ (الفرق 1-6) | F142: التصنيف | I142: # | J142: المجموعة ب (الفرق 7-13) | M142: التصنيف
B143: 1 | C143: الانصار | F143: نادي | I143: 7 | J143: أحد | M143: نادي
B144: 2 | C144: الكالتشيو | F144: أكاديمية | I144: 8 | J144: العلا | M144: نادي
B145: 3 | C145: اكاديمية مجتمعي | F145: أكاديمية | I145: 9 | J145: شباب طيبة | M145: أكاديمية
B146: 4 | C146: السفير | F146: أكاديمية | I146: 10 | J146: واعي | M146: أكاديمية
B147: 5 | C147: اكاديمية الفالي بارك | F147: أكاديمية | I147: 11 | J147: اكاديمية الحزام | M147: أكاديمية
B148: 6 | C148: البلاك ستارز | F148: هواة | I148: 12 | J148: اكاديمية الليجا الرياضية | M148: هواة
I149: 13 | J149: اكاديمية نجوم الدعيثة | M149: هواة

Sheet 14 فريق
A1: بطولة 14 فريق – تحت 13
A3: اليوم | B3: الوقت | C3: الملعب | D3: المجموعة | E3: المباراة
A4: 1 | B4: 4:00–5:25 م | C4: 1 | D4: 1 | E4: 3 ضد 6
A5: 1 | B5: 4:00–5:25 م | C5: 2 | D5: 2 | E5: 11 ضد 12
A6: 1 | B6: 5:35–7:00 م | C6: 1 | D6: 1 | E6: 4 ضد 5
A7: 1 | B7: 5:35–7:00 م | C7: 2 | D7: 1 | E7: 2 ضد 7
A8: 1 | B8: 7:10–8:35 م | C8: 1 | D8: 2 | E8: 10 ضد 13
A9: 1 | B9: 7:10–8:35 م | C9: 2 | D9: 2 | E9: 9 ضد 14
A10: 2 | B10: 4:00–5:25 م | C10: 1 | D10: 2 | E10: 10 ضد 11
A11: 2 | B11: 4:00–5:25 م | C11: 2 | D11: 2 | E11: 8 ضد 14
A12: 2 | B12: 5:35–7:00 م | C12: 1 | D12: 2 | E12: 9 ضد 12
A13: 2 | B13: 5:35–7:00 م | C13: 2 | D13: 1 | E13: 1 ضد 7
A14: 2 | B14: 7:10–8:35 م | C14: 1 | D14: 1 | E14: 2 ضد 5
A15: 2 | B15: 7:10–8:35 م | C15: 2 | D15: 1 | E15: 3 ضد 4
... A129: 21 | B129: 7:10–8:35 م | C129: 2 | D129: 2 | E129: 8 ضد 9
A130: 22 | B130: =MOD(HOUR(المدخلات!$B$5+0*المدخلات!$B$8/1440)-1,12)+1&":"&TEXT(MINUTE(المدخلات!$B$5+0*المدخلات!$B$8/1440),"00")&"–"&MOD(HOUR(المدخلات!$B$5+0*المدخلات!$B$8/1440+المدخلات!$B$6/1440)-1,12)+1&":"&TEXT(MINUTE(المدخلات!$B$5+0*المدخلات!$B$8/1440+المدخلات!$B$6/1440),"00")&IF(HOUR(المدخلات!$B$5+0*المدخلات!$B$8/1440)<12," ص"," م") -> 4:00–5:25 م | C130: 1 | D130: — | E130: أول المجموعة 1 ضد أول المجموعة 2
B133: توزيع الفرق على مجموعة الدمام — يُعبّأ بأسماء الفرق
B134: # | C134: المجموعة أ (الفرق 1-7) | F134: التصنيف | I134: # | J134: المجموعة ب (الفرق 8-14) | M134: التصنيف
B135: 1 | C135: وينرز | F135: نادي | I135: 8 | J135: الخليج | M135: نادي
B136: 2 | C136: الاتفاق | F136: نادي | I136: 9 | J136: القادسية | M136: نادي
B137: 3 | C137: الدمام السعودي | F137: نادي | I137: 10 | J137: الثقبة | M137: نادي
B138: 4 | C138: أشبال البراعم | F138: أكاديمية | I138: 11 | J138: اكاديمية ستاليونز ايليت | M138: أكاديمية
B139: 5 | C139: قادسية الخبر | F139: أكاديمية | I139: 12 | J139: مدريدستا | M139: أكاديمية
B140: 6 | C140: اسبايرالظهران | F140: أكاديمية | I140: 13 | J140: اكاديمية الظهران | M140: أكاديمية
B141: 7 | C141: اكاديمية اجيال التفوق | F141: أكاديمية | I141: 14 | J141: اكاديمية مروم الشرق | M141: أكاديمية
B144: توزيع الفرق على مجموعة صبيا — يُعبّأ بأسماء الفرق
B145: # | C145: المجموعة أ (الفرق 1-7) | F145: التصنيف | I145: # | J145: المجموعة ب (الفرق 8-14) | M145: التصنيف
B146: 1 | C146: الوطن | F146: نادي | I146: 8 | J146: اكاديمية ليبرو | M146: أكاديمية
B147: 2 | C147: الليث الابيض | F147: أكاديمية | I147: 9 | J147: وفاق الجنوب | M147: أكاديمية
B148: 3 | C148: جميما | F148: هواة | I148: 10 | J148: الجزيرة بالحسيني | M148: هواة
B149: 4 | C149: المحمدية | F149: هواة | I149: 11 | J149: الصمود | M149: هواة
B150: 5 | C150: الشاطئ | F150: هواة | I150: 12 | J150: جريبة | M150: هواة
B151: 6 | C151: العروبة بجخيرة | F151: هواة | I151: 13 | J151: شباب ابو القعايد | M151: هواة
B152: 7 | C152: القاضي | F152: هواة | I152: 14 | J152: الامجاد ضمد | M152: هواة

Sheet 16 فريق
A1: بطولة 16 فريق – تحت 13
A3: اليوم | B3: الوقت | C3: الملعب | D3: المجموعة | E3: المباراة
A4: 1 | B4: 4:00–5:25 م | C4: 1 | D4: 1 | E4: 2 ضد 7
A5: 1 | B5: 4:00–5:25 م | C5: 2 | D5: 1 | E5: 3 ضد 6
A6: 1 | B6: 4:00–5:25 م | C6: 3 | D6: 1 | E6: 4 ضد 5
A7: 1 | B7: 5:35–7:00 م | C7: 1 | D7: 2 | E7: 10 ضد 15
A8: 1 | B8: 5:35–7:00 م | C8: 2 | D8: 2 | E8: 9 ضد 16
A9: 1 | B9: 7:10–8:35 م | C9: 1 | D9: 1 | E9: 1 ضد 8
A10: 1 | B10: 7:10–8:35 م | C10: 2 | D10: 2 | E10: 11 ضد 14
A11: 1 | B11: 7:10–8:35 م | C11: 3 | D11: 2 | E11: 12 ضد 13
A12: 2 | B12: 4:00–5:25 م | C12: 1 | D12: 2 | E12: 11 ضد 12
A13: 2 | B13: 4:00–5:25 م | C13: 2 | D13: 1 | E13: 1 ضد 7
A14: 2 | B14: 4:00–5:25 م | C14: 3 | D14: 2 | E14: 16 ضد 14
A15: 2 | B15: 5:35–7:00 م | C15: 1 | D15: 1 | E15: 3 ضد 4
... A171: 21 | B171: 7:10–8:35 م | C171: 3 | D171: 2 | E171: 11 ضد 16
A172: 22 | B172: =MOD(HOUR(المدخلات!$B$5+0*المدخلات!$B$8/1440)-1,12)+1&":"&TEXT(MINUTE(المدخلات!$B$5+0*المدخلات!$B$8/1440),"00")&"–"&MOD(HOUR(المدخلات!$B$5+0*المدخلات!$B$8/1440+المدخلات!$B$6/1440)-1,12)+1&":"&TEXT(MINUTE(المدخلات!$B$5+0*المدخلات!$B$8/1440+المدخلات!$B$6/1440),"00")&IF(HOUR(المدخلات!$B$5+0*المدخلات!$B$8/1440)<12," ص"," م") -> 4:00–5:25 م | C172: 1 | D172: — | E172: أول المجموعة 1 ضد أول المجموعة 2
B175: توزيع الفرق على مجموعة الخفجي — يُعبّأ بأسماء الفرق
B176: # | C176: المجموعة أ (الفرق 1-8) | F176: التصنيف | I176: # | J176: المجموعة ب (الفرق 9-16) | M176: التصنيف
B177: 1 | C177: العلمين | F177: نادي | I177: 9 | J177: الايمان الرياضية | M177: أكاديمية
B178: 2 | C178: حزم الخفجي | F178: هواة | I178: 10 | J178: مدرسة الشرق الاهلية | M178: هواة
B179: 3 | C179: زعيم الخفجي | F179: هواة | I179: 11 | J179: اولمبي الحزم | M179: هواة
B180: 4 | C180: نابولي الخفجي | F180: هواة | I180: 12 | J180: القانرز | M180: هواة
B181: 5 | C181: ميلان الخفجي | F181: هواة | I181: 13 | J181: مدرسة اجيال الخفجي | M181: هواة
B182: 6 | C182: نجوم الخفجي | F182: هواة | I182: 14 | J182: الفرسان | M182: هواة
B183: 7 | C183: السهم | F183: هواة | I183: 15 | J183: افاق الخفجي | M183: هواة
B184: 8 | C184: اشبال الحديبية | F184: هواة | I184: 16 | J184: السروات | M184: هواة
B187: توزيع الفرق على مجموعة الطائف — يُعبّأ بأسماء الفرق
B188: # | C188: المجموعة أ (الفرق 1-8) | F188: التصنيف | I188: # | J188: المجموعة ب (الفرق 9-16) | M188: التصنيف
B189: 1 | C189: عكاظ | F189: نادي | I189: 9 | J189: الأغر | M189: نادي
B190: 2 | C190: الوداد الطائفي | F190: نادي | I190: 10 | J190: فالكون | M190: أكاديمية
B191: 3 | C191: نجوم مجد | F191: أكاديمية | I191: 11 | J191: نخبة بالطايف | M191: أكاديمية
B192: 4 | C192: تورنيدو | F192: هواة | I192: 12 | J192: سر النجوم | M192: هواة
B193: 5 | C193: نجوم النخبة | F193: هواة | I193: 13 | J193: برشا الشطبة | M193: هواة
B194: 6 | C194: اكاديمة السامبا | F194: هواة | I194: 14 | J194: إي إس زد الطائف | M194: هواة
B195: 7 | C195: الطموح | F195: هواة | I195: 15 | J195: اكاديمية الرواد بالطائف | M195: هواة
B196: 8 | C196: اكاديمية الجوهره | F196: هواة | I196: 16 | J196: شباب الحرمين | M196: هواة

Sheet 17 فريق
A1: بطولة 17 فريق – تحت 13
A3: اليوم | B3: الوقت | C3: الملعب | D3: المباراة
A4: 1 | B4: 4:00–5:25 م | C4: 1 | D4: 5 ضد 14
A5: 1 | B5: 4:00–5:25 م | C5: 2 | D5: 6 ضد 13
A6: 1 | B6: 5:35–7:00 م | C6: 1 | D6: 7 ضد 12
A7: 1 | B7: 5:35–7:00 م | C7: 2 | D7: 3 ضد 16
A8: 1 | B8: 5:35–7:00 م | C8: 3 | D8: 9 ضد 10
A9: 1 | B9: 7:10–8:35 م | C9: 1 | D9: 4 ضد 15
A10: 1 | B10: 7:10–8:35 م | C10: 2 | D10: 2 ضد 17
A11: 1 | B11: 7:10–8:35 م | C11: 3 | D11: 8 ضد 11
A12: 2 | B12: 4:00–5:25 م | C12: 1 | D12: 3 ضد 14
A13: 2 | B13: 4:00–5:25 م | C13: 2 | D13: 1 ضد 17
A14: 2 | B14: 4:00–5:25 م | C14: 3 | D14: 2 ضد 15
A15: 2 | B15: 5:35–7:00 م | C15: 1 | D15: 4 ضد 13
... A139: 17 | B139: 7:10–8:35 م | C139: 2 | D139: 5 ضد 16
B142: توزيع الفرق على مجموعة حفر الباطن — يُعبّأ بأسماء الفرق
B143: # | C143: الفرق (1-17) | F143: التصنيف
B144: 1 | C144: نادي الحفر | F144: نادي
B145: 2 | C145: الباطن | F145: نادي
B146: 3 | C146: القيصومة | F146: نادي
B147: 4 | C147: مواهب الحفر | F147: أكاديمية
B148: 5 | C148: فيصل الدخيل | F148: أكاديمية
B149: 6 | C149: القمة الرياضية | F149: أكاديمية
B150: 7 | C150: اف ستة عشر العالمية | F150: أكاديمية
B151: 8 | C151: مواهب اسباير | F151: أكاديمية
B152: 9 | C152: مواهب السد | F152: أكاديمية
B153: 10 | C153: اكاديمية المملكة | F153: أكاديمية
B154: 11 | C154: اكاديمية النجم | F154: أكاديمية
B155: 12 | C155: اكاديمة شرق الباطن | F155: أكاديمية
... B160: 17 | C160: فريق اكاديمية الحفر | F160: هواة

Sheet 24 فريق
A1: بطولة 24 فريق – تحت 13
A3: اليوم | B3: الوقت | C3: الملعب | D3: المجموعة | E3: المباراة
A4: 1 | B4: 4:00–5:25 م | C4: 1 | D4: 3 | E4: 15 ضد 16
A5: 1 | B5: 4:00–5:25 م | C5: 2 | D5: 1 | E5: 3 ضد 4
A6: 1 | B6: 4:00–5:25 م | C6: 3 | D6: 4 | E6: 19 ضد 24
A7: 1 | B7: 4:00–5:25 م | C7: 4 | D7: 3 | E7: 14 ضد 17
A8: 1 | B8: 5:35–7:00 م | C8: 1 | D8: 3 | E8: 13 ضد 18
A9: 1 | B9: 5:35–7:00 م | C9: 2 | D9: 2 | E9: 9 ضد 10
A10: 1 | B10: 5:35–7:00 م | C10: 3 | D10: 2 | E10: 8 ضد 11
A11: 1 | B11: 5:35–7:00 م | C11: 4 | D11: 2 | E11: 7 ضد 12
A12: 1 | B12: 7:10–8:35 م | C12: 1 | D12: 1 | E12: 1 ضد 6
A13: 1 | B13: 7:10–8:35 م | C13: 2 | D13: 1 | E13: 2 ضد 5
A14: 1 | B14: 7:10–8:35 م | C14: 3 | D14: 4 | E14: 20 ضد 23
A15: 1 | B15: 7:10–8:35 م | C15: 4 | D15: 4 | E15: 21 ضد 22
... A243: 20 | B243: 7:10–8:35 م | C243: 4 | D243: 4 | E243: 24 ضد 21
A244: 21 | B244: =MOD(HOUR(المدخلات!$B$5+0*المدخلات!$B$8/1440)-1,12)+1&":"&TEXT(MINUTE(المدخلات!$B$5+0*المدخلات!$B$8/1440),"00")&"–"&MOD(HOUR(المدخلات!$B$5+0*المدخلات!$B$8/1440+المدخلات!$B$6/1440)-1,12)+1&":"&TEXT(MINUTE(المدخلات!$B$5+0*المدخلات!$B$8/1440+المدخلات!$B$6/1440),"00")&IF(HOUR(المدخلات!$B$5+0*المدخلات!$B$8/1440)<12," ص"," م") -> 4:00–5:25 م | C244: 1 | D244: — | E244: أول المجموعة 1 ضد أول المجموعة 4
A245: 21 | B245: =MOD(HOUR(المدخلات!$B$5+0*المدخلات!$B$8/1440)-1,12)+1&":"&TEXT(MINUTE(المدخلات!$B$5+0*المدخلات!$B$8/1440),"00")&"–"&MOD(HOUR(المدخلات!$B$5+0*المدخلات!$B$8/1440+المدخلات!$B$6/1440)-1,12)+1&":"&TEXT(MINUTE(المدخلات!$B$5+0*المدخلات!$B$8/1440+المدخلات!$B$6/1440),"00")&IF(HOUR(المدخلات!$B$5+0*المدخلات!$B$8/1440)<12," ص"," م") -> 4:00–5:25 م | C245: 2 | D245: — | E245: أول المجموعة 2 ضد أول المجموعة 3
A246: 22 | B246: =MOD(HOUR(المدخلات!$B$5+0*المدخلات!$B$8/1440)-1,12)+1&":"&TEXT(MINUTE(المدخلات!$B$5+0*المدخلات!$B$8/1440),"00")&"–"&MOD(HOUR(المدخلات!$B$5+0*المدخلات!$B$8/1440+المدخلات!$B$6/1440)-1,12)+1&":"&TEXT(MINUTE(المدخلات!$B$5+0*المدخلات!$B$8/1440+المدخلات!$B$6/1440),"00")&IF(HOUR(المدخلات!$B$5+0*المدخلات!$B$8/1440)<12," ص"," م") -> 4:00–5:25 م | C246: 1 | D246: — | E246: الفائز 1 ضد الفائز 2
B249: توزيع الفرق على مجموعة مكة المكرمة — يُعبّأ بأسماء الفرق
B250: # | C250: المجموعة أ (الفرق 1-6) | F250: التصنيف | I250: # | J250: المجموعة ب (الفرق 7-12) | M250: التصنيف | P250: # | Q250: المجموعة ج (الفرق 13-18) | T250: التصنيف | W250: # | X250: المجموعة د (الفرق 19-24) | AA250: التصنيف
