Workbook

Sheet المدخلات
A1: صفحة المدخلات – بطولات تحت 11 / تحت 12
A3: البند | B3: القيمة | C3: ملاحظة | E3: الفترة | F3: التوقيت
A4: وقت بداية اليوم | B4: 0.66666667 | C4: مشترك لكل البطولات | E4: =IF(1<=$B$8,1,"") -> 1 | F4: =IF(1>$B$8,"",MOD(HOUR($B$4+0*$B$7/1440)-1,12)+1&":"&TEXT(MINUTE($B$4+0*$B$7/1440),"00")&"–"&MOD(HOUR($B$4+0*$B$7/1440+$B$5/1440)-1,12)+1&":"&TEXT(MINUTE($B$4+0*$B$7/1440+$B$5/1440),"00")&IF(HOUR($B$4+0*$B$7/1440)<12," ص"," م")) -> 4:00–5:10 م
A5: مدة المباراة (دقيقة) | B5: 70 | C5: زمن المباراة الفعلي | E5: =IF(2<=$B$8,2,"") -> 2 | F5: =IF(2>$B$8,"",MOD(HOUR($B$4+1*$B$7/1440)-1,12)+1&":"&TEXT(MINUTE($B$4+1*$B$7/1440),"00")&"–"&MOD(HOUR($B$4+1*$B$7/1440+$B$5/1440)-1,12)+1&":"&TEXT(MINUTE($B$4+1*$B$7/1440+$B$5/1440),"00")&IF(HOUR($B$4+1*$B$7/1440)<12," ص"," م")) -> 5:20–6:30 م
A6: الفاصل/ترتيب الملعب (دقيقة) | B6: 10 | C6: راحة وترتيب الملعب بين المباريات | E6: =IF(3<=$B$8,3,"") -> 3 | F6: =IF(3>$B$8,"",MOD(HOUR($B$4+2*$B$7/1440)-1,12)+1&":"&TEXT(MINUTE($B$4+2*$B$7/1440),"00")&"–"&MOD(HOUR($B$4+2*$B$7/1440+$B$5/1440)-1,12)+1&":"&TEXT(MINUTE($B$4+2*$B$7/1440+$B$5/1440),"00")&IF(HOUR($B$4+2*$B$7/1440)<12," ص"," م")) -> 6:40–7:50 م
A7: طول الفترة الكاملة (دقيقة) | B7: =B5+B6 -> 80 | C7: محسوبة = مدة + فاصل | E7: =IF(4<=$B$8,4,"") | F7: =IF(4>$B$8,"",MOD(HOUR($B$4+3*$B$7/1440)-1,12)+1&":"&TEXT(MINUTE($B$4+3*$B$7/1440),"00")&"–"&MOD(HOUR($B$4+3*$B$7/1440+$B$5/1440)-1,12)+1&":"&TEXT(MINUTE($B$4+3*$B$7/1440+$B$5/1440),"00")&IF(HOUR($B$4+3*$B$7/1440)<12," ص"," م"))
A8: أقصى عدد فترات في اليوم | B8: 3 | C8: يحدد عدد الملاعب المطلوبة
A9: عدد ملاعب 7×7 داخل الملعب القانوني | B9: 2 | C9: يُستخدم لحساب عدد الملاعب القانونية في الملخص

Sheet الملخص
A1: ملخص بطولات تحت 11 / تحت 12 — الأعداد المطلوبة
A3: عدد الفرق | B3: عدد المجموعات | C3: توزيع الفرق في المجموعات | D3: لقاءات كل خصم | E3: مباريات كل فريق في الموسم | F3: نظام الإقصاء | G3: أيام الدوري | H3: أيام الإقصاء | I3: إجمالي الأيام | J3: وقت البداية | K3: وقت النهاية | L3: عدد الملاعب (7 ضد 7) | M3: عدد الملاعب القانونية
A4: 6 | B4: {=ROUND(SUMPRODUCT(1/COUNTIF('بيانات الفرق'!$B$3:$B$8,'بيانات الفرق'!$B$3:$B$8)),0)} -> 1 | C4: {=_xlfn.TEXTJOIN(" + ",TRUE,COUNTIF('بيانات الفرق'!$B$3:$B$8,"المجموعة "&_xlfn.SEQUENCE($B4)))} -> 6 | D4: {=_xlfn.TEXTJOIN(" + ",TRUE,IF(ROUNDDOWN(_xlfn.MINIFS('بيانات الفرق'!$C$3:$C$8,'بيانات الفرق'!$B$3:$B$8,"المجموعة "&_xlfn.SEQUENCE($B4))/_xlfn.MINIFS('بيانات الفرق'!$D$3:$D$8,'بيانات الفرق'!$B$3:$B$8,"المجموعة "&_xlfn.SEQUENCE($B4)),0)=ROUNDUP(_xlfn.MAXIFS('بيانات الفرق'!$C$3:$C$8,'بيانات الفرق'!$B$3:$B$8,"المجموعة "&_xlfn.SEQUENCE($B4))/_xlfn.MINIFS('بيانات الفرق'!$D$3:$D$8,'بيانات الفرق'!$B$3:$B$8,"المجموعة "&_xlfn.SEQUENCE($B4)),0),ROUNDDOWN(_xlfn.MINIFS('بيانات الفرق'!$C$3:$C$8,'بيانات الفرق'!$B$3:$B$8,"المجموعة "&_xlfn.SEQUENCE($B4))/_xlfn.MINIFS('بيانات الفرق'!$D$3:$D$8,'بيانات الفرق'!$B$3:$B$8,"المجموعة "&_xlfn.SEQUENCE($B4)),0),ROUNDDOWN(_xlfn.MINIFS('بيانات الفرق'!$C$3:$C$8,'بيانات الفرق'!$B$3:$B$8,"المجموعة "&_xlfn.SEQUENCE($B4))/_xlfn.MINIFS('بيانات الفرق'!$D$3:$D$8,'بيانات الفرق'!$B$3:$B$8,"المجموعة "&_xlfn.SEQUENCE($B4)),0)&"–"&ROUNDUP(_xlfn.MAXIFS('بيانات الفرق'!$C$3:$C$8,'بيانات الفرق'!$B$3:$B$8,"المجموعة "&_xlfn.SEQUENCE($B4))/_xlfn.MINIFS('بيانات الفرق'!$D$3:$D$8,'بيانات الفرق'!$B$3:$B$8,"المجموعة "&_xlfn.SEQUENCE($B4)),0)))} -> 4 | E4: {=_xlfn.TEXTJOIN(" + ",TRUE,IF(_xlfn.MINIFS('بيانات الفرق'!$C$3:$C$8,'بيانات الفرق'!$B$3:$B$8,"المجموعة "&_xlfn.SEQUENCE($B4))=_xlfn.MAXIFS('بيانات الفرق'!$C$3:$C$8,'بيانات الفرق'!$B$3:$B$8,"المجموعة "&_xlfn.SEQUENCE($B4)),_xlfn.MINIFS('بيانات الفرق'!$C$3:$C$8,'بيانات الفرق'!$B$3:$B$8,"المجموعة "&_xlfn.SEQUENCE($B4)),_xlfn.MINIFS('بيانات الفرق'!$C$3:$C$8,'بيانات الفرق'!$B$3:$B$8,"المجموعة "&_xlfn.SEQUENCE($B4))&"–"&_xlfn.MAXIFS('بيانات الفرق'!$C$3:$C$8,'بيانات الفرق'!$B$3:$B$8,"المجموعة "&_xlfn.SEQUENCE($B4))))} -> 20 | F4: =IF(COUNTIF('6 فرق'!$D$4:$D$1999,"*فائز ر*")>0,"ربع نهائي ثم نصف نهائي ثم نهائي",IF(COUNTIF('6 فرق'!$D$4:$D$1999,"*فائز*")>0,"نصف نهائي ثم نهائي",IF(COUNTIF('6 فرق'!$D$4:$D$1999,"*أول المجموعة*")>0,"نهائي مباشر","—"))) -> — | G4: =_xlfn.MAXIFS('6 فرق'!$A$4:$A$1999,'6 فرق'!$D$4:$D$1999,"* ضد *",'6 فرق'!$D$4:$D$1999,"<>*فائز*",'6 فرق'!$D$4:$D$1999,"<>*أول المجموعة*",'6 فرق'!$D$4:$D$1999,"<>*المتأهل*") -> 20 | H4: =$I4-$G4 -> 0 | I4: =_xlfn.MAXIFS('6 فرق'!$A$4:$A$1999,'6 فرق'!$D$4:$D$1999,"* ضد *") -> 20 | J4: =MOD(HOUR(المدخلات!$B$4)-1,12)+1&":"&TEXT(MINUTE(المدخلات!$B$4),"00")&IF(HOUR(المدخلات!$B$4)<12," ص"," م") -> 4:00 م | K4: {=_xlfn.LET(_xlpm.p,SUMPRODUCT(MAX((COUNTIF('6 فرق'!$B$4:$B$1999,المدخلات!$F$4:$F$7)>0)*(المدخلات!$F$4:$F$7<>"")*ROW(المدخلات!$F$4:$F$7)))-3,_xlpm.t,INDEX(المدخلات!$F$4:$F$7,_xlpm.p),TRIM(MID(_xlpm.t,FIND("–",_xlpm.t)+1,20)))} -> 7:50 م | L4: =_xlfn.MAXIFS('6 فرق'!$C$4:$C$1999,'6 فرق'!$D$4:$D$1999,"* ضد *") -> 1 | M4: =ROUNDUP($L4/المدخلات!$B$9,0) -> 1
A5: 7 | B5: {=ROUND(SUMPRODUCT(1/COUNTIF('بيانات الفرق'!$G$3:$G$9,'بيانات الفرق'!$G$3:$G$9)),0)} -> 1 | C5: {=_xlfn.TEXTJOIN(" + ",TRUE,COUNTIF('بيانات الفرق'!$G$3:$G$9,"المجموعة "&_xlfn.SEQUENCE($B5)))} -> 7 | D5: {=_xlfn.TEXTJOIN(" + ",TRUE,IF(ROUNDDOWN(_xlfn.MINIFS('بيانات الفرق'!$H$3:$H$9,'بيانات الفرق'!$G$3:$G$9,"المجموعة "&_xlfn.SEQUENCE($B5))/_xlfn.MINIFS('بيانات الفرق'!$I$3:$I$9,'بيانات الفرق'!$G$3:$G$9,"المجموعة "&_xlfn.SEQUENCE($B5)),0)=ROUNDUP(_xlfn.MAXIFS('بيانات الفرق'!$H$3:$H$9,'بيانات الفرق'!$G$3:$G$9,"المجموعة "&_xlfn.SEQUENCE($B5))/_xlfn.MINIFS('بيانات الفرق'!$I$3:$I$9,'بيانات الفرق'!$G$3:$G$9,"المجموعة "&_xlfn.SEQUENCE($B5)),0),ROUNDDOWN(_xlfn.MINIFS('بيانات الفرق'!$H$3:$H$9,'بيانات الفرق'!$G$3:$G$9,"المجموعة "&_xlfn.SEQUENCE($B5))/_xlfn.MINIFS('بيانات الفرق'!$I$3:$I$9,'بيانات الفرق'!$G$3:$G$9,"المجموعة "&_xlfn.SEQUENCE($B5)),0),ROUNDDOWN(_xlfn.MINIFS('بيانات الفرق'!$H$3:$H$9,'بيانات الفرق'!$G$3:$G$9,"المجموعة "&_xlfn.SEQUENCE($B5))/_xlfn.MINIFS('بيانات الفرق'!$I$3:$I$9,'بيانات الفرق'!$G$3:$G$9,"المجموعة "&_xlfn.SEQUENCE($B5)),0)&"–"&ROUNDUP(_xlfn.MAXIFS('بيانات الفرق'!$H$3:$H$9,'بيانات الفرق'!$G$3:$G$9,"المجموعة "&_xlfn.SEQUENCE($B5))/_xlfn.MINIFS('بيانات الفرق'!$I$3:$I$9,'بيانات الفرق'!$G$3:$G$9,"المجموعة "&_xlfn.SEQUENCE($B5)),0)))} -> 3 | E5: {=_xlfn.TEXTJOIN(" + ",TRUE,IF(_xlfn.MINIFS('بيانات الفرق'!$H$3:$H$9,'بيانات الفرق'!$G$3:$G$9,"المجموعة "&_xlfn.SEQUENCE($B5))=_xlfn.MAXIFS('بيانات الفرق'!$H$3:$H$9,'بيانات الفرق'!$G$3:$G$9,"المجموعة "&_xlfn.SEQUENCE($B5)),_xlfn.MINIFS('بيانات الفرق'!$H$3:$H$9,'بيانات الفرق'!$G$3:$G$9,"المجموعة "&_xlfn.SEQUENCE($B5)),_xlfn.MINIFS('بيانات الفرق'!$H$3:$H$9,'بيانات الفرق'!$G$3:$G$9,"المجموعة "&_xlfn.SEQUENCE($B5))&"–"&_xlfn.MAXIFS('بيانات الفرق'!$H$3:$H$9,'بيانات الفرق'!$G$3:$G$9,"المجموعة "&_xlfn.SEQUENCE($B5))))} -> 18 | F5: =IF(COUNTIF('7 فرق'!$D$4:$D$1999,"*فائز ر*")>0,"ربع نهائي ثم نصف نهائي ثم نهائي",IF(COUNTIF('7 فرق'!$D$4:$D$1999,"*فائز*")>0,"نصف نهائي ثم نهائي",IF(COUNTIF('7 فرق'!$D$4:$D$1999,"*أول المجموعة*")>0,"نهائي مباشر","—"))) -> — | G5: =_xlfn.MAXIFS('7 فرق'!$A$4:$A$1999,'7 فرق'!$D$4:$D$1999,"* ضد *",'7 فرق'!$D$4:$D$1999,"<>*فائز*",'7 فرق'!$D$4:$D$1999,"<>*أول المجموعة*",'7 فرق'!$D$4:$D$1999,"<>*المتأهل*") -> 21 | H5: =$I5-$G5 -> 0 | I5: =_xlfn.MAXIFS('7 فرق'!$A$4:$A$1999,'7 فرق'!$D$4:$D$1999,"* ضد *") -> 21 | J5: =MOD(HOUR(المدخلات!$B$4)-1,12)+1&":"&TEXT(MINUTE(المدخلات!$B$4),"00")&IF(HOUR(المدخلات!$B$4)<12," ص"," م") -> 4:00 م | K5: {=_xlfn.LET(_xlpm.p,SUMPRODUCT(MAX((COUNTIF('7 فرق'!$B$4:$B$1999,المدخلات!$F$4:$F$7)>0)*(المدخلات!$F$4:$F$7<>"")*ROW(المدخلات!$F$4:$F$7)))-3,_xlpm.t,INDEX(المدخلات!$F$4:$F$7,_xlpm.p),TRIM(MID(_xlpm.t,FIND("–",_xlpm.t)+1,20)))} -> 7:50 م | L5: =_xlfn.MAXIFS('7 فرق'!$C$4:$C$1999,'7 فرق'!$D$4:$D$1999,"* ضد *") -> 1 | M5: =ROUNDUP($L5/المدخلات!$B$9,0) -> 1
A6: 8 | B6: {=ROUND(SUMPRODUCT(1/COUNTIF('بيانات الفرق'!$L$3:$L$10,'بيانات الفرق'!$L$3:$L$10)),0)} -> 1 | C6: {=_xlfn.TEXTJOIN(" + ",TRUE,COUNTIF('بيانات الفرق'!$L$3:$L$10,"المجموعة "&_xlfn.SEQUENCE($B6)))} -> 8 | D6: {=_xlfn.TEXTJOIN(" + ",TRUE,IF(ROUNDDOWN(_xlfn.MINIFS('بيانات الفرق'!$M$3:$M$10,'بيانات الفرق'!$L$3:$L$10,"المجموعة "&_xlfn.SEQUENCE($B6))/_xlfn.MINIFS('بيانات الفرق'!$N$3:$N$10,'بيانات الفرق'!$L$3:$L$10,"المجموعة "&_xlfn.SEQUENCE($B6)),0)=ROUNDUP(_xlfn.MAXIFS('بيانات الفرق'!$M$3:$M$10,'بيانات الفرق'!$L$3:$L$10,"المجموعة "&_xlfn.SEQUENCE($B6))/_xlfn.MINIFS('بيانات الفرق'!$N$3:$N$10,'بيانات الفرق'!$L$3:$L$10,"المجموعة "&_xlfn.SEQUENCE($B6)),0),ROUNDDOWN(_xlfn.MINIFS('بيانات الفرق'!$M$3:$M$10,'بيانات الفرق'!$L$3:$L$10,"المجموعة "&_xlfn.SEQUENCE($B6))/_xlfn.MINIFS('بيانات الفرق'!$N$3:$N$10,'بيانات الفرق'!$L$3:$L$10,"المجموعة "&_xlfn.SEQUENCE($B6)),0),ROUNDDOWN(_xlfn.MINIFS('بيانات الفرق'!$M$3:$M$10,'بيانات الفرق'!$L$3:$L$10,"المجموعة "&_xlfn.SEQUENCE($B6))/_xlfn.MINIFS('بيانات الفرق'!$N$3:$N$10,'بيانات الفرق'!$L$3:$L$10,"المجموعة "&_xlfn.SEQUENCE($B6)),0)&"–"&ROUNDUP(_xlfn.MAXIFS('بيانات الفرق'!$M$3:$M$10,'بيانات الفرق'!$L$3:$L$10,"المجموعة "&_xlfn.SEQUENCE($B6))/_xlfn.MINIFS('بيانات الفرق'!$N$3:$N$10,'بيانات الفرق'!$L$3:$L$10,"المجموعة "&_xlfn.SEQUENCE($B6)),0)))} -> 3 | E6: {=_xlfn.TEXTJOIN(" + ",TRUE,IF(_xlfn.MINIFS('بيانات الفرق'!$M$3:$M$10,'بيانات الفرق'!$L$3:$L$10,"المجموعة "&_xlfn.SEQUENCE($B6))=_xlfn.MAXIFS('بيانات الفرق'!$M$3:$M$10,'بيانات الفرق'!$L$3:$L$10,"المجموعة "&_xlfn.SEQUENCE($B6)),_xlfn.MINIFS('بيانات الفرق'!$M$3:$M$10,'بيانات الفرق'!$L$3:$L$10,"المجموعة "&_xlfn.SEQUENCE($B6)),_xlfn.MINIFS('بيانات الفرق'!$M$3:$M$10,'بيانات الفرق'!$L$3:$L$10,"المجموعة "&_xlfn.SEQUENCE($B6))&"–"&_xlfn.MAXIFS('بيانات الفرق'!$M$3:$M$10,'بيانات الفرق'!$L$3:$L$10,"المجموعة "&_xlfn.SEQUENCE($B6))))} -> 21 | F6: =IF(COUNTIF('8 فرق'!$D$4:$D$1999,"*فائز ر*")>0,"ربع نهائي ثم نصف نهائي ثم نهائي",IF(COUNTIF('8 فرق'!$D$4:$D$1999,"*فائز*")>0,"نصف نهائي ثم نهائي",IF(COUNTIF('8 فرق'!$D$4:$D$1999,"*أول المجموعة*")>0,"نهائي مباشر","—"))) -> — | G6: =_xlfn.MAXIFS('8 فرق'!$A$4:$A$1999,'8 فرق'!$D$4:$D$1999,"* ضد *",'8 فرق'!$D$4:$D$1999,"<>*فائز*",'8 فرق'!$D$4:$D$1999,"<>*أول المجموعة*",'8 فرق'!$D$4:$D$1999,"<>*المتأهل*") -> 21 | H6: =$I6-$G6 -> 0 | I6: =_xlfn.MAXIFS('8 فرق'!$A$4:$A$1999,'8 فرق'!$D$4:$D$1999,"* ضد *") -> 21 | J6: =MOD(HOUR(المدخلات!$B$4)-1,12)+1&":"&TEXT(MINUTE(المدخلات!$B$4),"00")&IF(HOUR(المدخلات!$B$4)<12," ص"," م") -> 4:00 م | K6: {=_xlfn.LET(_xlpm.p,SUMPRODUCT(MAX((COUNTIF('8 فرق'!$B$4:$B$1999,المدخلات!$F$4:$F$7)>0)*(المدخلات!$F$4:$F$7<>"")*ROW(المدخلات!$F$4:$F$7)))-3,_xlpm.t,INDEX(المدخلات!$F$4:$F$7,_xlpm.p),TRIM(MID(_xlpm.t,FIND("–",_xlpm.t)+1,20)))} -> 6:30 م | L6: =_xlfn.MAXIFS('8 فرق'!$C$4:$C$1999,'8 فرق'!$D$4:$D$1999,"* ضد *") -> 2 | M6: =ROUNDUP($L6/المدخلات!$B$9,0) -> 1
A7: 9 | B7: {=ROUND(SUMPRODUCT(1/COUNTIF('بيانات الفرق'!$Q$3:$Q$11,'بيانات الفرق'!$Q$3:$Q$11)),0)} -> 1 | C7: {=_xlfn.TEXTJOIN(" + ",TRUE,COUNTIF('بيانات الفرق'!$Q$3:$Q$11,"المجموعة "&_xlfn.SEQUENCE($B7)))} -> 9 | D7: {=_xlfn.TEXTJOIN(" + ",TRUE,IF(ROUNDDOWN(_xlfn.MINIFS('بيانات الفرق'!$R$3:$R$11,'بيانات الفرق'!$Q$3:$Q$11,"المجموعة "&_xlfn.SEQUENCE($B7))/_xlfn.MINIFS('بيانات الفرق'!$S$3:$S$11,'بيانات الفرق'!$Q$3:$Q$11,"المجموعة "&_xlfn.SEQUENCE($B7)),0)=ROUNDUP(_xlfn.MAXIFS('بيانات الفرق'!$R$3:$R$11,'بيانات الفرق'!$Q$3:$Q$11,"المجموعة "&_xlfn.SEQUENCE($B7))/_xlfn.MINIFS('بيانات الفرق'!$S$3:$S$11,'بيانات الفرق'!$Q$3:$Q$11,"المجموعة "&_xlfn.SEQUENCE($B7)),0),ROUNDDOWN(_xlfn.MINIFS('بيانات الفرق'!$R$3:$R$11,'بيانات الفرق'!$Q$3:$Q$11,"المجموعة "&_xlfn.SEQUENCE($B7))/_xlfn.MINIFS('بيانات الفرق'!$S$3:$S$11,'بيانات الفرق'!$Q$3:$Q$11,"المجموعة "&_xlfn.SEQUENCE($B7)),0),ROUNDDOWN(_xlfn.MINIFS('بيانات الفرق'!$R$3:$R$11,'بيانات الفرق'!$Q$3:$Q$11,"المجموعة "&_xlfn.SEQUENCE($B7))/_xlfn.MINIFS('بيانات الفرق'!$S$3:$S$11,'بيانات الفرق'!$Q$3:$Q$11,"المجموعة "&_xlfn.SEQUENCE($B7)),0)&"–"&ROUNDUP(_xlfn.MAXIFS('بيانات الفرق'!$R$3:$R$11,'بيانات الفرق'!$Q$3:$Q$11,"المجموعة "&_xlfn.SEQUENCE($B7))/_xlfn.MINIFS('بيانات الفرق'!$S$3:$S$11,'بيانات الفرق'!$Q$3:$Q$11,"المجموعة "&_xlfn.SEQUENCE($B7)),0)))} -> 2–3 | E7: {=_xlfn.TEXTJOIN(" + ",TRUE,IF(_xlfn.MINIFS('بيانات الفرق'!$R$3:$R$11,'بيانات الفرق'!$Q$3:$Q$11,"المجموعة "&_xlfn.SEQUENCE($B7))=_xlfn.MAXIFS('بيانات الفرق'!$R$3:$R$11,'بيانات الفرق'!$Q$3:$Q$11,"المجموعة "&_xlfn.SEQUENCE($B7)),_xlfn.MINIFS('بيانات الفرق'!$R$3:$R$11,'بيانات الفرق'!$Q$3:$Q$11,"المجموعة "&_xlfn.SEQUENCE($B7)),_xlfn.MINIFS('بيانات الفرق'!$R$3:$R$11,'بيانات الفرق'!$Q$3:$Q$11,"المجموعة "&_xlfn.SEQUENCE($B7))&"–"&_xlfn.MAXIFS('بيانات الفرق'!$R$3:$R$11,'بيانات الفرق'!$Q$3:$Q$11,"المجموعة "&_xlfn.SEQUENCE($B7))))} -> 18 | F7: =IF(COUNTIF('9 فرق'!$D$4:$D$1999,"*فائز ر*")>0,"ربع نهائي ثم نصف نهائي ثم نهائي",IF(COUNTIF('9 فرق'!$D$4:$D$1999,"*فائز*")>0,"نصف نهائي ثم نهائي",IF(COUNTIF('9 فرق'!$D$4:$D$1999,"*أول المجموعة*")>0,"نهائي مباشر","—"))) -> — | G7: =_xlfn.MAXIFS('9 فرق'!$A$4:$A$1999,'9 فرق'!$D$4:$D$1999,"* ضد *",'9 فرق'!$D$4:$D$1999,"<>*فائز*",'9 فرق'!$D$4:$D$1999,"<>*أول المجموعة*",'9 فرق'!$D$4:$D$1999,"<>*المتأهل*") -> 21 | H7: =$I7-$G7 -> 0 | I7: =_xlfn.MAXIFS('9 فرق'!$A$4:$A$1999,'9 فرق'!$D$4:$D$1999,"* ضد *") -> 21 | J7: =MOD(HOUR(المدخلات!$B$4)-1,12)+1&":"&TEXT(MINUTE(المدخلات!$B$4),"00")&IF(HOUR(المدخلات!$B$4)<12," ص"," م") -> 4:00 م | K7: {=_xlfn.LET(_xlpm.p,SUMPRODUCT(MAX((COUNTIF('9 فرق'!$B$4:$B$1999,المدخلات!$F$4:$F$7)>0)*(المدخلات!$F$4:$F$7<>"")*ROW(المدخلات!$F$4:$F$7)))-3,_xlpm.t,INDEX(المدخلات!$F$4:$F$7,_xlpm.p),TRIM(MID(_xlpm.t,FIND("–",_xlpm.t)+1,20)))} -> 6:30 م | L7: =_xlfn.MAXIFS('9 فرق'!$C$4:$C$1999,'9 فرق'!$D$4:$D$1999,"* ضد *") -> 2 | M7: =ROUNDUP($L7/المدخلات!$B$9,0) -> 1
A8: 11 | B8: {=ROUND(SUMPRODUCT(1/COUNTIF('بيانات الفرق'!$V$3:$V$13,'بيانات الفرق'!$V$3:$V$13)),0)} -> 1 | C8: {=_xlfn.TEXTJOIN(" + ",TRUE,COUNTIF('بيانات الفرق'!$V$3:$V$13,"المجموعة "&_xlfn.SEQUENCE($B8)))} -> 11 | D8: {=_xlfn.TEXTJOIN(" + ",TRUE,IF(ROUNDDOWN(_xlfn.MINIFS('بيانات الفرق'!$W$3:$W$13,'بيانات الفرق'!$V$3:$V$13,"المجموعة "&_xlfn.SEQUENCE($B8))/_xlfn.MINIFS('بيانات الفرق'!$X$3:$X$13,'بيانات الفرق'!$V$3:$V$13,"المجموعة "&_xlfn.SEQUENCE($B8)),0)=ROUNDUP(_xlfn.MAXIFS('بيانات الفرق'!$W$3:$W$13,'بيانات الفرق'!$V$3:$V$13,"المجموعة "&_xlfn.SEQUENCE($B8))/_xlfn.MINIFS('بيانات الفرق'!$X$3:$X$13,'بيانات الفرق'!$V$3:$V$13,"المجموعة "&_xlfn.SEQUENCE($B8)),0),ROUNDDOWN(_xlfn.MINIFS('بيانات الفرق'!$W$3:$W$13,'بيانات الفرق'!$V$3:$V$13,"المجموعة "&_xlfn.SEQUENCE($B8))/_xlfn.MINIFS('بيانات الفرق'!$X$3:$X$13,'بيانات الفرق'!$V$3:$V$13,"المجموعة "&_xlfn.SEQUENCE($B8)),0),ROUNDDOWN(_xlfn.MINIFS('بيانات الفرق'!$W$3:$W$13,'بيانات الفرق'!$V$3:$V$13,"المجموعة "&_xlfn.SEQUENCE($B8))/_xlfn.MINIFS('بيانات الفرق'!$X$3:$X$13,'بيانات الفرق'!$V$3:$V$13,"المجموعة "&_xlfn.SEQUENCE($B8)),0)&"–"&ROUNDUP(_xlfn.MAXIFS('بيانات الفرق'!$W$3:$W$13,'بيانات الفرق'!$V$3:$V$13,"المجموعة "&_xlfn.SEQUENCE($B8))/_xlfn.MINIFS('بيانات الفرق'!$X$3:$X$13,'بيانات الفرق'!$V$3:$V$13,"المجموعة "&_xlfn.SEQUENCE($B8)),0)))} -> 2 | E8: {=_xlfn.TEXTJOIN(" + ",TRUE,IF(_xlfn.MINIFS('بيانات الفرق'!$W$3:$W$13,'بيانات الفرق'!$V$3:$V$13,"المجموعة "&_xlfn.SEQUENCE($B8))=_xlfn.MAXIFS('بيانات الفرق'!$W$3:$W$13,'بيانات الفرق'!$V$3:$V$13,"المجموعة "&_xlfn.SEQUENCE($B8)),_xlfn.MINIFS('بيانات الفرق'!$W$3:$W$13,'بيانات الفرق'!$V$3:$V$13,"المجموعة "&_xlfn.SEQUENCE($B8)),_xlfn.MINIFS('بيانات الفرق'!$W$3:$W$13,'بيانات الفرق'!$V$3:$V$13,"المجموعة "&_xlfn.SEQUENCE($B8))&"–"&_xlfn.MAXIFS('بيانات الفرق'!$W$3:$W$13,'بيانات الفرق'!$V$3:$V$13,"المجموعة "&_xlfn.SEQUENCE($B8))))} -> 20 | F8: =IF(COUNTIF('11 فريقًا'!$D$4:$D$1999,"*فائز ر*")>0,"ربع نهائي ثم نصف نهائي ثم نهائي",IF(COUNTIF('11 فريقًا'!$D$4:$D$1999,"*فائز*")>0,"نصف نهائي ثم نهائي",IF(COUNTIF('11 فريقًا'!$D$4:$D$1999,"*أول المجموعة*")>0,"نهائي مباشر","—"))) -> — | G8: =_xlfn.MAXIFS('11 فريقًا'!$A$4:$A$1999,'11 فريقًا'!$D$4:$D$1999,"* ضد *",'11 فريقًا'!$D$4:$D$1999,"<>*فائز*",'11 فريقًا'!$D$4:$D$1999,"<>*أول المجموعة*",'11 فريقًا'!$D$4:$D$1999,"<>*المتأهل*") -> 22 | H8: =$I8-$G8 -> 0 | I8: =_xlfn.MAXIFS('11 فريقًا'!$A$4:$A$1999,'11 فريقًا'!$D$4:$D$1999,"* ضد *") -> 22 | J8: =MOD(HOUR(المدخلات!$B$4)-1,12)+1&":"&TEXT(MINUTE(المدخلات!$B$4),"00")&IF(HOUR(المدخلات!$B$4)<12," ص"," م") -> 4:00 م | K8: {=_xlfn.LET(_xlpm.p,SUMPRODUCT(MAX((COUNTIF('11 فريقًا'!$B$4:$B$1999,المدخلات!$F$4:$F$7)>0)*(المدخلات!$F$4:$F$7<>"")*ROW(المدخلات!$F$4:$F$7)))-3,_xlpm.t,INDEX(المدخلات!$F$4:$F$7,_xlpm.p),TRIM(MID(_xlpm.t,FIND("–",_xlpm.t)+1,20)))} -> 7:50 م | L8: =_xlfn.MAXIFS('11 فريقًا'!$C$4:$C$1999,'11 فريقًا'!$D$4:$D$1999,"* ضد *") -> 2 | M8: =ROUNDUP($L8/المدخلات!$B$9,0) -> 1
A9: 12 | B9: {=ROUND(SUMPRODUCT(1/COUNTIF('بيانات الفرق'!$AA$3:$AA$14,'بيانات الفرق'!$AA$3:$AA$14)),0)} -> 1 | C9: {=_xlfn.TEXTJOIN(" + ",TRUE,COUNTIF('بيانات الفرق'!$AA$3:$AA$14,"المجموعة "&_xlfn.SEQUENCE($B9)))} -> 12 | D9: {=_xlfn.TEXTJOIN(" + ",TRUE,IF(ROUNDDOWN(_xlfn.MINIFS('بيانات الفرق'!$AB$3:$AB$14,'بيانات الفرق'!$AA$3:$AA$14,"المجموعة "&_xlfn.SEQUENCE($B9))/_xlfn.MINIFS('بيانات الفرق'!$AC$3:$AC$14,'بيانات الفرق'!$AA$3:$AA$14,"المجموعة "&_xlfn.SEQUENCE($B9)),0)=ROUNDUP(_xlfn.MAXIFS('بيانات الفرق'!$AB$3:$AB$14,'بيانات الفرق'!$AA$3:$AA$14,"المجموعة "&_xlfn.SEQUENCE($B9))/_xlfn.MINIFS('بيانات الفرق'!$AC$3:$AC$14,'بيانات الفرق'!$AA$3:$AA$14,"المجموعة "&_xlfn.SEQUENCE($B9)),0),ROUNDDOWN(_xlfn.MINIFS('بيانات الفرق'!$AB$3:$AB$14,'بيانات الفرق'!$AA$3:$AA$14,"المجموعة "&_xlfn.SEQUENCE($B9))/_xlfn.MINIFS('بيانات الفرق'!$AC$3:$AC$14,'بيانات الفرق'!$AA$3:$AA$14,"المجموعة "&_xlfn.SEQUENCE($B9)),0),ROUNDDOWN(_xlfn.MINIFS('بيانات الفرق'!$AB$3:$AB$14,'بيانات الفرق'!$AA$3:$AA$14,"المجموعة "&_xlfn.SEQUENCE($B9))/_xlfn.MINIFS('بيانات الفرق'!$AC$3:$AC$14,'بيانات الفرق'!$AA$3:$AA$14,"المجموعة "&_xlfn.SEQUENCE($B9)),0)&"–"&ROUNDUP(_xlfn.MAXIFS('بيانات الفرق'!$AB$3:$AB$14,'بيانات الفرق'!$AA$3:$AA$14,"المجموعة "&_xlfn.SEQUENCE($B9))/_xlfn.MINIFS('بيانات الفرق'!$AC$3:$AC$14,'بيانات الفرق'!$AA$3:$AA$14,"المجموعة "&_xlfn.SEQUENCE($B9)),0)))} -> 2 | E9: {=_xlfn.TEXTJOIN(" + ",TRUE,IF(_xlfn.MINIFS('بيانات الفرق'!$AB$3:$AB$14,'بيانات الفرق'!$AA$3:$AA$14,"المجموعة "&_xlfn.SEQUENCE($B9))=_xlfn.MAXIFS('بيانات الفرق'!$AB$3:$AB$14,'بيانات الفرق'!$AA$3:$AA$14,"المجموعة "&_xlfn.SEQUENCE($B9)),_xlfn.MINIFS('بيانات الفرق'!$AB$3:$AB$14,'بيانات الفرق'!$AA$3:$AA$14,"المجموعة "&_xlfn.SEQUENCE($B9)),_xlfn.MINIFS('بيانات الفرق'!$AB$3:$AB$14,'بيانات الفرق'!$AA$3:$AA$14,"المجموعة "&_xlfn.SEQUENCE($B9))&"–"&_xlfn.MAXIFS('بيانات الفرق'!$AB$3:$AB$14,'بيانات الفرق'!$AA$3:$AA$14,"المجموعة "&_xlfn.SEQUENCE($B9))))} -> 22 | F9: =IF(COUNTIF('12 فريقًا'!$D$4:$D$1999,"*فائز ر*")>0,"ربع نهائي ثم نصف نهائي ثم نهائي",IF(COUNTIF('12 فريقًا'!$D$4:$D$1999,"*فائز*")>0,"نصف نهائي ثم نهائي",IF(COUNTIF('12 فريقًا'!$D$4:$D$1999,"*أول المجموعة*")>0,"نهائي مباشر","—"))) -> — | G9: =_xlfn.MAXIFS('12 فريقًا'!$A$4:$A$1999,'12 فريقًا'!$D$4:$D$1999,"* ضد *",'12 فريقًا'!$D$4:$D$1999,"<>*فائز*",'12 فريقًا'!$D$4:$D$1999,"<>*أول المجموعة*",'12 فريقًا'!$D$4:$D$1999,"<>*المتأهل*") -> 22 | H9: =$I9-$G9 -> 0 | I9: =_xlfn.MAXIFS('12 فريقًا'!$A$4:$A$1999,'12 فريقًا'!$D$4:$D$1999,"* ضد *") -> 22 | J9: =MOD(HOUR(المدخلات!$B$4)-1,12)+1&":"&TEXT(MINUTE(المدخلات!$B$4),"00")&IF(HOUR(المدخلات!$B$4)<12," ص"," م") -> 4:00 م | K9: {=_xlfn.LET(_xlpm.p,SUMPRODUCT(MAX((COUNTIF('12 فريقًا'!$B$4:$B$1999,المدخلات!$F$4:$F$7)>0)*(المدخلات!$F$4:$F$7<>"")*ROW(المدخلات!$F$4:$F$7)))-3,_xlpm.t,INDEX(المدخلات!$F$4:$F$7,_xlpm.p),TRIM(MID(_xlpm.t,FIND("–",_xlpm.t)+1,20)))} -> 7:50 م | L9: =_xlfn.MAXIFS('12 فريقًا'!$C$4:$C$1999,'12 فريقًا'!$D$4:$D$1999,"* ضد *") -> 2 | M9: =ROUNDUP($L9/المدخلات!$B$9,0) -> 1
A10: 13 | B10: {=ROUND(SUMPRODUCT(1/COUNTIF('بيانات الفرق'!$AF$3:$AF$15,'بيانات الفرق'!$AF$3:$AF$15)),0)} -> 2 | C10: {=_xlfn.TEXTJOIN(" + ",TRUE,COUNTIF('بيانات الفرق'!$AF$3:$AF$15,"المجموعة "&_xlfn.SEQUENCE($B10)))} -> 7 + 6 | D10: {=_xlfn.TEXTJOIN(" + ",TRUE,IF(ROUNDDOWN(_xlfn.MINIFS('بيانات الفرق'!$AG$3:$AG$15,'بيانات الفرق'!$AF$3:$AF$15,"المجموعة "&_xlfn.SEQUENCE($B10))/_xlfn.MINIFS('بيانات الفرق'!$AH$3:$AH$15,'بيانات الفرق'!$AF$3:$AF$15,"المجموعة "&_xlfn.SEQUENCE($B10)),0)=ROUNDUP(_xlfn.MAXIFS('بيانات الفرق'!$AG$3:$AG$15,'بيانات الفرق'!$AF$3:$AF$15,"المجموعة "&_xlfn.SEQUENCE($B10))/_xlfn.MINIFS('بيانات الفرق'!$AH$3:$AH$15,'بيانات الفرق'!$AF$3:$AF$15,"المجموعة "&_xlfn.SEQUENCE($B10)),0),ROUNDDOWN(_xlfn.MINIFS('بيانات الفرق'!$AG$3:$AG$15,'بيانات الفرق'!$AF$3:$AF$15,"المجموعة "&_xlfn.SEQUENCE($B10))/_xlfn.MINIFS('بيانات الفرق'!$AH$3:$AH$15,'بيانات الفرق'!$AF$3:$AF$15,"المجموعة "&_xlfn.SEQUENCE($B10)),0),ROUNDDOWN(_xlfn.MINIFS('بيانات الفرق'!$AG$3:$AG$15,'بيانات الفرق'!$AF$3:$AF$15,"المجموعة "&_xlfn.SEQUENCE($B10))/_xlfn.MINIFS('بيانات الفرق'!$AH$3:$AH$15,'بيانات الفرق'!$AF$3:$AF$15,"المجموعة "&_xlfn.SEQUENCE($B10)),0)&"–"&ROUNDUP(_xlfn.MAXIFS('بيانات الفرق'!$AG$3:$AG$15,'بيانات الفرق'!$AF$3:$AF$15,"المجموعة "&_xlfn.SEQUENCE($B10))/_xlfn.MINIFS('بيانات الفرق'!$AH$3:$AH$15,'بيانات الفرق'!$AF$3:$AF$15,"المجموعة "&_xlfn.SEQUENCE($B10)),0)))} -> 3 + 4 | E10: {=_xlfn.TEXTJOIN(" + ",TRUE,IF(_xlfn.MINIFS('بيانات الفرق'!$AG$3:$AG$15,'بيانات الفرق'!$AF$3:$AF$15,"المجموعة "&_xlfn.SEQUENCE($B10))=_xlfn.MAXIFS('بيانات الفرق'!$AG$3:$AG$15,'بيانات الفرق'!$AF$3:$AF$15,"المجموعة "&_xlfn.SEQUENCE($B10)),_xlfn.MINIFS('بيانات الفرق'!$AG$3:$AG$15,'بيانات الفرق'!$AF$3:$AF$15,"المجموعة "&_xlfn.SEQUENCE($B10)),_xlfn.MINIFS('بيانات الفرق'!$AG$3:$AG$15,'بيانات الفرق'!$AF$3:$AF$15,"المجموعة "&_xlfn.SEQUENCE($B10))&"–"&_xlfn.MAXIFS('بيانات الفرق'!$AG$3:$AG$15,'بيانات الفرق'!$AF$3:$AF$15,"المجموعة "&_xlfn.SEQUENCE($B10))))} -> 18 + 20 | F10: =IF(COUNTIF('13 فريقًا'!$E$4:$E$1999,"*فائز ر*")>0,"ربع نهائي ثم نصف نهائي ثم نهائي",IF(COUNTIF('13 فريقًا'!$E$4:$E$1999,"*فائز*")>0,"نصف نهائي ثم نهائي",IF(COUNTIF('13 فريقًا'!$E$4:$E$1999,"*أول المجموعة*")>0,"نهائي مباشر","—"))) -> نهائي مباشر | G10: =_xlfn.MAXIFS('13 فريقًا'!$A$4:$A$1999,'13 فريقًا'!$E$4:$E$1999,"* ضد *",'13 فريقًا'!$E$4:$E$1999,"<>*فائز*",'13 فريقًا'!$E$4:$E$1999,"<>*أول المجموعة*",'13 فريقًا'!$E$4:$E$1999,"<>*المتأهل*") -> 21 | H10: =$I10-$G10 -> 1 | I10: =_xlfn.MAXIFS('13 فريقًا'!$A$4:$A$1999,'13 فريقًا'!$E$4:$E$1999,"* ضد *") -> 22 | J10: =MOD(HOUR(المدخلات!$B$4)-1,12)+1&":"&TEXT(MINUTE(المدخلات!$B$4),"00")&IF(HOUR(المدخلات!$B$4)<12," ص"," م") -> 4:00 م | K10: {=_xlfn.LET(_xlpm.p,SUMPRODUCT(MAX((COUNTIF('13 فريقًا'!$B$4:$B$1999,المدخلات!$F$4:$F$7)>0)*(المدخلات!$F$4:$F$7<>"")*ROW(المدخلات!$F$4:$F$7)))-3,_xlpm.t,INDEX(المدخلات!$F$4:$F$7,_xlpm.p),TRIM(MID(_xlpm.t,FIND("–",_xlpm.t)+1,20)))} -> 7:50 م | L10: =_xlfn.MAXIFS('13 فريقًا'!$C$4:$C$1999,'13 فريقًا'!$E$4:$E$1999,"* ضد *") -> 2 | M10: =ROUNDUP($L10/المدخلات!$B$9,0) -> 1
A11: 14 | B11: {=ROUND(SUMPRODUCT(1/COUNTIF('بيانات الفرق'!$AK$3:$AK$16,'بيانات الفرق'!$AK$3:$AK$16)),0)} -> 2 | C11: {=_xlfn.TEXTJOIN(" + ",TRUE,COUNTIF('بيانات الفرق'!$AK$3:$AK$16,"المجموعة "&_xlfn.SEQUENCE($B11)))} -> 7 + 7 | D11: {=_xlfn.TEXTJOIN(" + ",TRUE,IF(ROUNDDOWN(_xlfn.MINIFS('بيانات الفرق'!$AL$3:$AL$16,'بيانات الفرق'!$AK$3:$AK$16,"المجموعة "&_xlfn.SEQUENCE($B11))/_xlfn.MINIFS('بيانات الفرق'!$AM$3:$AM$16,'بيانات الفرق'!$AK$3:$AK$16,"المجموعة "&_xlfn.SEQUENCE($B11)),0)=ROUNDUP(_xlfn.MAXIFS('بيانات الفرق'!$AL$3:$AL$16,'بيانات الفرق'!$AK$3:$AK$16,"المجموعة "&_xlfn.SEQUENCE($B11))/_xlfn.MINIFS('بيانات الفرق'!$AM$3:$AM$16,'بيانات الفرق'!$AK$3:$AK$16,"المجموعة "&_xlfn.SEQUENCE($B11)),0),ROUNDDOWN(_xlfn.MINIFS('بيانات الفرق'!$AL$3:$AL$16,'بيانات الفرق'!$AK$3:$AK$16,"المجموعة "&_xlfn.SEQUENCE($B11))/_xlfn.MINIFS('بيانات الفرق'!$AM$3:$AM$16,'بيانات الفرق'!$AK$3:$AK$16,"المجموعة "&_xlfn.SEQUENCE($B11)),0),ROUNDDOWN(_xlfn.MINIFS('بيانات الفرق'!$AL$3:$AL$16,'بيانات الفرق'!$AK$3:$AK$16,"المجموعة "&_xlfn.SEQUENCE($B11))/_xlfn.MINIFS('بيانات الفرق'!$AM$3:$AM$16,'بيانات الفرق'!$AK$3:$AK$16,"المجموعة "&_xlfn.SEQUENCE($B11)),0)&"–"&ROUNDUP(_xlfn.MAXIFS('بيانات الفرق'!$AL$3:$AL$16,'بيانات الفرق'!$AK$3:$AK$16,"المجموعة "&_xlfn.SEQUENCE($B11))/_xlfn.MINIFS('بيانات الفرق'!$AM$3:$AM$16,'بيانات الفرق'!$AK$3:$AK$16,"المجموعة "&_xlfn.SEQUENCE($B11)),0)))} -> 3 + 3 | E11: {=_xlfn.TEXTJOIN(" + ",TRUE,IF(_xlfn.MINIFS('بيانات الفرق'!$AL$3:$AL$16,'بيانات الفرق'!$AK$3:$AK$16,"المجموعة "&_xlfn.SEQUENCE($B11))=_xlfn.MAXIFS('بيانات الفرق'!$AL$3:$AL$16,'بيانات الفرق'!$AK$3:$AK$16,"المجموعة "&_xlfn.SEQUENCE($B11)),_xlfn.MINIFS('بيانات الفرق'!$AL$3:$AL$16,'بيانات الفرق'!$AK$3:$AK$16,"المجموعة "&_xlfn.SEQUENCE($B11)),_xlfn.MINIFS('بيانات الفرق'!$AL$3:$AL$16,'بيانات الفرق'!$AK$3:$AK$16,"المجموعة "&_xlfn.SEQUENCE($B11))&"–"&_xlfn.MAXIFS('بيانات الفرق'!$AL$3:$AL$16,'بيانات الفرق'!$AK$3:$AK$16,"المجموعة "&_xlfn.SEQUENCE($B11))))} -> 18 + 18 | F11: =IF(COUNTIF('14 فريقًا'!$E$4:$E$1999,"*فائز ر*")>0,"ربع نهائي ثم نصف نهائي ثم نهائي",IF(COUNTIF('14 فريقًا'!$E$4:$E$1999,"*فائز*")>0,"نصف نهائي ثم نهائي",IF(COUNTIF('14 فريقًا'!$E$4:$E$1999,"*أول المجموعة*")>0,"نهائي مباشر","—"))) -> نهائي مباشر | G11: =_xlfn.MAXIFS('14 فريقًا'!$A$4:$A$1999,'14 فريقًا'!$E$4:$E$1999,"* ضد *",'14 فريقًا'!$E$4:$E$1999,"<>*فائز*",'14 فريقًا'!$E$4:$E$1999,"<>*أول المجموعة*",'14 فريقًا'!$E$4:$E$1999,"<>*المتأهل*") -> 21 | H11: =$I11-$G11 -> 1 | I11: =_xlfn.MAXIFS('14 فريقًا'!$A$4:$A$1999,'14 فريقًا'!$E$4:$E$1999,"* ضد *") -> 22 | J11: =MOD(HOUR(المدخلات!$B$4)-1,12)+1&":"&TEXT(MINUTE(المدخلات!$B$4),"00")&IF(HOUR(المدخلات!$B$4)<12," ص"," م") -> 4:00 م | K11: {=_xlfn.LET(_xlpm.p,SUMPRODUCT(MAX((COUNTIF('14 فريقًا'!$B$4:$B$1999,المدخلات!$F$4:$F$7)>0)*(المدخلات!$F$4:$F$7<>"")*ROW(المدخلات!$F$4:$F$7)))-3,_xlpm.t,INDEX(المدخلات!$F$4:$F$7,_xlpm.p),TRIM(MID(_xlpm.t,FIND("–",_xlpm.t)+1,20)))} -> 7:50 م | L11: =_xlfn.MAXIFS('14 فريقًا'!$C$4:$C$1999,'14 فريقًا'!$E$4:$E$1999,"* ضد *") -> 2 | M11: =ROUNDUP($L11/المدخلات!$B$9,0) -> 1
A12: 15 | B12: {=ROUND(SUMPRODUCT(1/COUNTIF('بيانات الفرق'!$AP$3:$AP$17,'بيانات الفرق'!$AP$3:$AP$17)),0)} -> 2 | C12: {=_xlfn.TEXTJOIN(" + ",TRUE,COUNTIF('بيانات الفرق'!$AP$3:$AP$17,"المجموعة "&_xlfn.SEQUENCE($B12)))} -> 8 + 7 | D12: {=_xlfn.TEXTJOIN(" + ",TRUE,IF(ROUNDDOWN(_xlfn.MINIFS('بيانات الفرق'!$AQ$3:$AQ$17,'بيانات الفرق'!$AP$3:$AP$17,"المجموعة "&_xlfn.SEQUENCE($B12))/_xlfn.MINIFS('بيانات الفرق'!$AR$3:$AR$17,'بيانات الفرق'!$AP$3:$AP$17,"المجموعة "&_xlfn.SEQUENCE($B12)),0)=ROUNDUP(_xlfn.MAXIFS('بيانات الفرق'!$AQ$3:$AQ$17,'بيانات الفرق'!$AP$3:$AP$17,"المجموعة "&_xlfn.SEQUENCE($B12))/_xlfn.MINIFS('بيانات الفرق'!$AR$3:$AR$17,'بيانات الفرق'!$AP$3:$AP$17,"المجموعة "&_xlfn.SEQUENCE($B12)),0),ROUNDDOWN(_xlfn.MINIFS('بيانات الفرق'!$AQ$3:$AQ$17,'بيانات الفرق'!$AP$3:$AP$17,"المجموعة "&_xlfn.SEQUENCE($B12))/_xlfn.MINIFS('بيانات الفرق'!$AR$3:$AR$17,'بيانات الفرق'!$AP$3:$AP$17,"المجموعة "&_xlfn.SEQUENCE($B12)),0),ROUNDDOWN(_xlfn.MINIFS('بيانات الفرق'!$AQ$3:$AQ$17,'بيانات الفرق'!$AP$3:$AP$17,"المجموعة "&_xlfn.SEQUENCE($B12))/_xlfn.MINIFS('بيانات الفرق'!$AR$3:$AR$17,'بيانات الفرق'!$AP$3:$AP$17,"المجموعة "&_xlfn.SEQUENCE($B12)),0)&"–"&ROUNDUP(_xlfn.MAXIFS('بيانات الفرق'!$AQ$3:$AQ$17,'بيانات الفرق'!$AP$3:$AP$17,"المجموعة "&_xlfn.SEQUENCE($B12))/_xlfn.MINIFS('بيانات الفرق'!$AR$3:$AR$17,'بيانات الفرق'!$AP$3:$AP$17,"المجموعة "&_xlfn.SEQUENCE($B12)),0)))} -> 3 + 3 | E12: {=_xlfn.TEXTJOIN(" + ",TRUE,IF(_xlfn.MINIFS('بيانات الفرق'!$AQ$3:$AQ$17,'بيانات الفرق'!$AP$3:$AP$17,"المجموعة "&_xlfn.SEQUENCE($B12))=_xlfn.MAXIFS('بيانات الفرق'!$AQ$3:$AQ$17,'بيانات الفرق'!$AP$3:$AP$17,"المجموعة "&_xlfn.SEQUENCE($B12)),_xlfn.MINIFS('بيانات الفرق'!$AQ$3:$AQ$17,'بيانات الفرق'!$AP$3:$AP$17,"المجموعة "&_xlfn.SEQUENCE($B12)),_xlfn.MINIFS('بيانات الفرق'!$AQ$3:$AQ$17,'بيانات الفرق'!$AP$3:$AP$17,"المجموعة "&_xlfn.SEQUENCE($B12))&"–"&_xlfn.MAXIFS('بيانات الفرق'!$AQ$3:$AQ$17,'بيانات الفرق'!$AP$3:$AP$17,"المجموعة "&_xlfn.SEQUENCE($B12))))} -> 21 + 18 | F12: =IF(COUNTIF('15 فريقًا'!$E$4:$E$1999,"*فائز ر*")>0,"ربع نهائي ثم نصف نهائي ثم نهائي",IF(COUNTIF('15 فريقًا'!$E$4:$E$1999,"*فائز*")>0,"نصف نهائي ثم نهائي",IF(COUNTIF('15 فريقًا'!$E$4:$E$1999,"*أول المجموعة*")>0,"نهائي مباشر","—"))) -> نهائي مباشر | G12: =_xlfn.MAXIFS('15 فريقًا'!$A$4:$A$1999,'15 فريقًا'!$E$4:$E$1999,"* ضد *",'15 فريقًا'!$E$4:$E$1999,"<>*فائز*",'15 فريقًا'!$E$4:$E$1999,"<>*أول المجموعة*",'15 فريقًا'!$E$4:$E$1999,"<>*المتأهل*") -> 21 | H12: =$I12-$G12 -> 1 | I12: =_xlfn.MAXIFS('15 فريقًا'!$A$4:$A$1999,'15 فريقًا'!$E$4:$E$1999,"* ضد *") -> 22 | J12: =MOD(HOUR(المدخلات!$B$4)-1,12)+1&":"&TEXT(MINUTE(المدخلات!$B$4),"00")&IF(HOUR(المدخلات!$B$4)<12," ص"," م") -> 4:00 م | K12: {=_xlfn.LET(_xlpm.p,SUMPRODUCT(MAX((COUNTIF('15 فريقًا'!$B$4:$B$1999,المدخلات!$F$4:$F$7)>0)*(المدخلات!$F$4:$F$7<>"")*ROW(المدخلات!$F$4:$F$7)))-3,_xlpm.t,INDEX(المدخلات!$F$4:$F$7,_xlpm.p),TRIM(MID(_xlpm.t,FIND("–",_xlpm.t)+1,20)))} -> 7:50 م | L12: =_xlfn.MAXIFS('15 فريقًا'!$C$4:$C$1999,'15 فريقًا'!$E$4:$E$1999,"* ضد *") -> 3 | M12: =ROUNDUP($L12/المدخلات!$B$9,0) -> 2
A13: 16 | B13: {=ROUND(SUMPRODUCT(1/COUNTIF('بيانات الفرق'!$AU$3:$AU$18,'بيانات الفرق'!$AU$3:$AU$18)),0)} -> 2 | C13: {=_xlfn.TEXTJOIN(" + ",TRUE,COUNTIF('بيانات الفرق'!$AU$3:$AU$18,"المجموعة "&_xlfn.SEQUENCE($B13)))} -> 8 + 8 | D13: {=_xlfn.TEXTJOIN(" + ",TRUE,IF(ROUNDDOWN(_xlfn.MINIFS('بيانات الفرق'!$AV$3:$AV$18,'بيانات الفرق'!$AU$3:$AU$18,"المجموعة "&_xlfn.SEQUENCE($B13))/_xlfn.MINIFS('بيانات الفرق'!$AW$3:$AW$18,'بيانات الفرق'!$AU$3:$AU$18,"المجموعة "&_xlfn.SEQUENCE($B13)),0)=ROUNDUP(_xlfn.MAXIFS('بيانات الفرق'!$AV$3:$AV$18,'بيانات الفرق'!$AU$3:$AU$18,"المجموعة "&_xlfn.SEQUENCE($B13))/_xlfn.MINIFS('بيانات الفرق'!$AW$3:$AW$18,'بيانات الفرق'!$AU$3:$AU$18,"المجموعة "&_xlfn.SEQUENCE($B13)),0),ROUNDDOWN(_xlfn.MINIFS('بيانات الفرق'!$AV$3:$AV$18,'بيانات الفرق'!$AU$3:$AU$18,"المجموعة "&_xlfn.SEQUENCE($B13))/_xlfn.MINIFS('بيانات الفرق'!$AW$3:$AW$18,'بيانات الفرق'!$AU$3:$AU$18,"المجموعة "&_xlfn.SEQUENCE($B13)),0),ROUNDDOWN(_xlfn.MINIFS('بيانات الفرق'!$AV$3:$AV$18,'بيانات الفرق'!$AU$3:$AU$18,"المجموعة "&_xlfn.SEQUENCE($B13))/_xlfn.MINIFS('بيانات الفرق'!$AW$3:$AW$18,'بيانات الفرق'!$AU$3:$AU$18,"المجموعة "&_xlfn.SEQUENCE($B13)),0)&"–"&ROUNDUP(_xlfn.MAXIFS('بيانات الفرق'!$AV$3:$AV$18,'بيانات الفرق'!$AU$3:$AU$18,"المجموعة "&_xlfn.SEQUENCE($B13))/_xlfn.MINIFS('بيانات الفرق'!$AW$3:$AW$18,'بيانات الفرق'!$AU$3:$AU$18,"المجموعة "&_xlfn.SEQUENCE($B13)),0)))} -> 3 + 3 | E13: {=_xlfn.TEXTJOIN(" + ",TRUE,IF(_xlfn.MINIFS('بيانات الفرق'!$AV$3:$AV$18,'بيانات الفرق'!$AU$3:$AU$18,"المجموعة "&_xlfn.SEQUENCE($B13))=_xlfn.MAXIFS('بيانات الفرق'!$AV$3:$AV$18,'بيانات الفرق'!$AU$3:$AU$18,"المجموعة "&_xlfn.SEQUENCE($B13)),_xlfn.MINIFS('بيانات الفرق'!$AV$3:$AV$18,'بيانات الفرق'!$AU$3:$AU$18,"المجموعة "&_xlfn.SEQUENCE($B13)),_xlfn.MINIFS('بيانات الفرق'!$AV$3:$AV$18,'بيانات الفرق'!$AU$3:$AU$18,"المجموعة "&_xlfn.SEQUENCE($B13))&"–"&_xlfn.MAXIFS('بيانات الفرق'!$AV$3:$AV$18,'بيانات الفرق'!$AU$3:$AU$18,"المجموعة "&_xlfn.SEQUENCE($B13))))} -> 21 + 21 | F13: =IF(COUNTIF('16 فريقًا'!$E$4:$E$1999,"*فائز ر*")>0,"ربع نهائي ثم نصف نهائي ثم نهائي",IF(COUNTIF('16 فريقًا'!$E$4:$E$1999,"*فائز*")>0,"نصف نهائي ثم نهائي",IF(COUNTIF('16 فريقًا'!$E$4:$E$1999,"*أول المجموعة*")>0,"نهائي مباشر","—"))) -> نهائي مباشر | G13: =_xlfn.MAXIFS('16 فريقًا'!$A$4:$A$1999,'16 فريقًا'!$E$4:$E$1999,"* ضد *",'16 فريقًا'!$E$4:$E$1999,"<>*فائز*",'16 فريقًا'!$E$4:$E$1999,"<>*أول المجموعة*",'16 فريقًا'!$E$4:$E$1999,"<>*المتأهل*") -> 21 | H13: =$I13-$G13 -> 1 | I13: =_xlfn.MAXIFS('16 فريقًا'!$A$4:$A$1999,'16 فريقًا'!$E$4:$E$1999,"* ضد *") -> 22 | J13: =MOD(HOUR(المدخلات!$B$4)-1,12)+1&":"&TEXT(MINUTE(المدخلات!$B$4),"00")&IF(HOUR(المدخلات!$B$4)<12," ص"," م") -> 4:00 م | K13: {=_xlfn.LET(_xlpm.p,SUMPRODUCT(MAX((COUNTIF('16 فريقًا'!$B$4:$B$1999,المدخلات!$F$4:$F$7)>0)*(المدخلات!$F$4:$F$7<>"")*ROW(المدخلات!$F$4:$F$7)))-3,_xlpm.t,INDEX(المدخلات!$F$4:$F$7,_xlpm.p),TRIM(MID(_xlpm.t,FIND("–",_xlpm.t)+1,20)))} -> 6:30 م | L13: =_xlfn.MAXIFS('16 فريقًا'!$C$4:$C$1999,'16 فريقًا'!$E$4:$E$1999,"* ضد *") -> 4 | M13: =ROUNDUP($L13/المدخلات!$B$9,0) -> 2
A14: 17 | B14: {=ROUND(SUMPRODUCT(1/COUNTIF('بيانات الفرق'!$AZ$3:$AZ$19,'بيانات الفرق'!$AZ$3:$AZ$19)),0)} -> 1 | C14: {=_xlfn.TEXTJOIN(" + ",TRUE,COUNTIF('بيانات الفرق'!$AZ$3:$AZ$19,"المجموعة "&_xlfn.SEQUENCE($B14)))} -> 17 | D14: {=_xlfn.TEXTJOIN(" + ",TRUE,IF(ROUNDDOWN(_xlfn.MINIFS('بيانات الفرق'!$BA$3:$BA$19,'بيانات الفرق'!$AZ$3:$AZ$19,"المجموعة "&_xlfn.SEQUENCE($B14))/_xlfn.MINIFS('بيانات الفرق'!$BB$3:$BB$19,'بيانات الفرق'!$AZ$3:$AZ$19,"المجموعة "&_xlfn.SEQUENCE($B14)),0)=ROUNDUP(_xlfn.MAXIFS('بيانات الفرق'!$BA$3:$BA$19,'بيانات الفرق'!$AZ$3:$AZ$19,"المجموعة "&_xlfn.SEQUENCE($B14))/_xlfn.MINIFS('بيانات الفرق'!$BB$3:$BB$19,'بيانات الفرق'!$AZ$3:$AZ$19,"المجموعة "&_xlfn.SEQUENCE($B14)),0),ROUNDDOWN(_xlfn.MINIFS('بيانات الفرق'!$BA$3:$BA$19,'بيانات الفرق'!$AZ$3:$AZ$19,"المجموعة "&_xlfn.SEQUENCE($B14))/_xlfn.MINIFS('بيانات الفرق'!$BB$3:$BB$19,'بيانات الفرق'!$AZ$3:$AZ$19,"المجموعة "&_xlfn.SEQUENCE($B14)),0),ROUNDDOWN(_xlfn.MINIFS('بيانات الفرق'!$BA$3:$BA$19,'بيانات الفرق'!$AZ$3:$AZ$19,"المجموعة "&_xlfn.SEQUENCE($B14))/_xlfn.MINIFS('بيانات الفرق'!$BB$3:$BB$19,'بيانات الفرق'!$AZ$3:$AZ$19,"المجموعة "&_xlfn.SEQUENCE($B14)),0)&"–"&ROUNDUP(_xlfn.MAXIFS('بيانات الفرق'!$BA$3:$BA$19,'بيانات الفرق'!$AZ$3:$AZ$19,"المجموعة "&_xlfn.SEQUENCE($B14))/_xlfn.MINIFS('بيانات الفرق'!$BB$3:$BB$19,'بيانات الفرق'!$AZ$3:$AZ$19,"المجموعة "&_xlfn.SEQUENCE($B14)),0)))} -> 1–2 | E14: {=_xlfn.TEXTJOIN(" + ",TRUE,IF(_xlfn.MINIFS('بيانات الفرق'!$BA$3:$BA$19,'بيانات الفرق'!$AZ$3:$AZ$19,"المجموعة "&_xlfn.SEQUENCE($B14))=_xlfn.MAXIFS('بيانات الفرق'!$BA$3:$BA$19,'بيانات الفرق'!$AZ$3:$AZ$19,"المجموعة "&_xlfn.SEQUENCE($B14)),_xlfn.MINIFS('بيانات الفرق'!$BA$3:$BA$19,'بيانات الفرق'!$AZ$3:$AZ$19,"المجموعة "&_xlfn.SEQUENCE($B14)),_xlfn.MINIFS('بيانات الفرق'!$BA$3:$BA$19,'بيانات الفرق'!$AZ$3:$AZ$19,"المجموعة "&_xlfn.SEQUENCE($B14))&"–"&_xlfn.MAXIFS('بيانات الفرق'!$BA$3:$BA$19,'بيانات الفرق'!$AZ$3:$AZ$19,"المجموعة "&_xlfn.SEQUENCE($B14))))} -> 18 | F14: =IF(COUNTIF('17 فريقًا'!$D$4:$D$1999,"*فائز ر*")>0,"ربع نهائي ثم نصف نهائي ثم نهائي",IF(COUNTIF('17 فريقًا'!$D$4:$D$1999,"*فائز*")>0,"نصف نهائي ثم نهائي",IF(COUNTIF('17 فريقًا'!$D$4:$D$1999,"*أول المجموعة*")>0,"نهائي مباشر","—"))) -> — | G14: =_xlfn.MAXIFS('17 فريقًا'!$A$4:$A$1999,'17 فريقًا'!$D$4:$D$1999,"* ضد *",'17 فريقًا'!$D$4:$D$1999,"<>*فائز*",'17 فريقًا'!$D$4:$D$1999,"<>*أول المجموعة*",'17 فريقًا'!$D$4:$D$1999,"<>*المتأهل*") -> 20 | H14: =$I14-$G14 -> 0 | I14: =_xlfn.MAXIFS('17 فريقًا'!$A$4:$A$1999,'17 فريقًا'!$D$4:$D$1999,"* ضد *") -> 20 | J14: =MOD(HOUR(المدخلات!$B$4)-1,12)+1&":"&TEXT(MINUTE(المدخلات!$B$4),"00")&IF(HOUR(المدخلات!$B$4)<12," ص"," م") -> 4:00 م | K14: {=_xlfn.LET(_xlpm.p,SUMPRODUCT(MAX((COUNTIF('17 فريقًا'!$B$4:$B$1999,المدخلات!$F$4:$F$7)>0)*(المدخلات!$F$4:$F$7<>"")*ROW(المدخلات!$F$4:$F$7)))-3,_xlpm.t,INDEX(المدخلات!$F$4:$F$7,_xlpm.p),TRIM(MID(_xlpm.t,FIND("–",_xlpm.t)+1,20)))} -> 7:50 م | L14: =_xlfn.MAXIFS('17 فريقًا'!$C$4:$C$1999,'17 فريقًا'!$D$4:$D$1999,"* ضد *") -> 3 | M14: =ROUNDUP($L14/المدخلات!$B$9,0) -> 2
A15: 18 | B15: {=ROUND(SUMPRODUCT(1/COUNTIF('بيانات الفرق'!$BE$3:$BE$20,'بيانات الفرق'!$BE$3:$BE$20)),0)} -> 3 | C15: {=_xlfn.TEXTJOIN(" + ",TRUE,COUNTIF('بيانات الفرق'!$BE$3:$BE$20,"المجموعة "&_xlfn.SEQUENCE($B15)))} -> 6 + 6 + 6 | D15: {=_xlfn.TEXTJOIN(" + ",TRUE,IF(ROUNDDOWN(_xlfn.MINIFS('بيانات الفرق'!$BF$3:$BF$20,'بيانات الفرق'!$BE$3:$BE$20,"المجموعة "&_xlfn.SEQUENCE($B15))/_xlfn.MINIFS('بيانات الفرق'!$BG$3:$BG$20,'بيانات الفرق'!$BE$3:$BE$20,"المجموعة "&_xlfn.SEQUENCE($B15)),0)=ROUNDUP(_xlfn.MAXIFS('بيانات الفرق'!$BF$3:$BF$20,'بيانات الفرق'!$BE$3:$BE$20,"المجموعة "&_xlfn.SEQUENCE($B15))/_xlfn.MINIFS('بيانات الفرق'!$BG$3:$BG$20,'بيانات الفرق'!$BE$3:$BE$20,"المجموعة "&_xlfn.SEQUENCE($B15)),0),ROUNDDOWN(_xlfn.MINIFS('بيانات الفرق'!$BF$3:$BF$20,'بيانات الفرق'!$BE$3:$BE$20,"المجموعة "&_xlfn.SEQUENCE($B15))/_xlfn.MINIFS('بيانات الفرق'!$BG$3:$BG$20,'بيانات الفرق'!$BE$3:$BE$20,"المجموعة "&_xlfn.SEQUENCE($B15)),0),ROUNDDOWN(_xlfn.MINIFS('بيانات الفرق'!$BF$3:$BF$20,'بيانات الفرق'!$BE$3:$BE$20,"المجموعة "&_xlfn.SEQUENCE($B15))/_xlfn.MINIFS('بيانات الفرق'!$BG$3:$BG$20,'بيانات الفرق'!$BE$3:$BE$20,"المجموعة "&_xlfn.SEQUENCE($B15)),0)&"–"&ROUNDUP(_xlfn.MAXIFS('بيانات الفرق'!$BF$3:$BF$20,'بيانات الفرق'!$BE$3:$BE$20,"المجموعة "&_xlfn.SEQUENCE($B15))/_xlfn.MINIFS('بيانات الفرق'!$BG$3:$BG$20,'بيانات الفرق'!$BE$3:$BE$20,"المجموعة "&_xlfn.SEQUENCE($B15)),0)))} -> 4 + 4 + 4 | E15: {=_xlfn.TEXTJOIN(" + ",TRUE,IF(_xlfn.MINIFS('بيانات الفرق'!$BF$3:$BF$20,'بيانات الفرق'!$BE$3:$BE$20,"المجموعة "&_xlfn.SEQUENCE($B15))=_xlfn.MAXIFS('بيانات الفرق'!$BF$3:$BF$20,'بيانات الفرق'!$BE$3:$BE$20,"المجموعة "&_xlfn.SEQUENCE($B15)),_xlfn.MINIFS('بيانات الفرق'!$BF$3:$BF$20,'بيانات الفرق'!$BE$3:$BE$20,"المجموعة "&_xlfn.SEQUENCE($B15)),_xlfn.MINIFS('بيانات الفرق'!$BF$3:$BF$20,'بيانات الفرق'!$BE$3:$BE$20,"المجموعة "&_xlfn.SEQUENCE($B15))&"–"&_xlfn.MAXIFS('بيانات الفرق'!$BF$3:$BF$20,'بيانات الفرق'!$BE$3:$BE$20,"المجموعة "&_xlfn.SEQUENCE($B15))))} -> 20 + 20 + 20 | F15: =IF(COUNTIF('18 فريقًا'!$E$4:$E$1999,"*فائز ر*")>0,"ربع نهائي ثم نصف نهائي ثم نهائي",IF(COUNTIF('18 فريقًا'!$E$4:$E$1999,"*فائز*")>0,"نصف نهائي ثم نهائي",IF(COUNTIF('18 فريقًا'!$E$4:$E$1999,"*أول المجموعة*")>0,"نهائي مباشر","—"))) -> نصف نهائي ثم نهائي | G15: =_xlfn.MAXIFS('18 فريقًا'!$A$4:$A$1999,'18 فريقًا'!$E$4:$E$1999,"* ضد *",'18 فريقًا'!$E$4:$E$1999,"<>*فائز*",'18 فريقًا'!$E$4:$E$1999,"<>*أول المجموعة*",'18 فريقًا'!$E$4:$E$1999,"<>*المتأهل*") -> 20 | H15: =$I15-$G15 -> 2 | I15: =_xlfn.MAXIFS('18 فريقًا'!$A$4:$A$1999,'18 فريقًا'!$E$4:$E$1999,"* ضد *") -> 22 | J15: =MOD(HOUR(المدخلات!$B$4)-1,12)+1&":"&TEXT(MINUTE(المدخلات!$B$4),"00")&IF(HOUR(المدخلات!$B$4)<12," ص"," م") -> 4:00 م | K15: {=_xlfn.LET(_xlpm.p,SUMPRODUCT(MAX((COUNTIF('18 فريقًا'!$B$4:$B$1999,المدخلات!$F$4:$F$7)>0)*(المدخلات!$F$4:$F$7<>"")*ROW(المدخلات!$F$4:$F$7)))-3,_xlpm.t,INDEX(المدخلات!$F$4:$F$7,_xlpm.p),TRIM(MID(_xlpm.t,FIND("–",_xlpm.t)+1,20)))} -> 7:50 م | L15: =_xlfn.MAXIFS('18 فريقًا'!$C$4:$C$1999,'18 فريقًا'!$E$4:$E$1999,"* ضد *") -> 3 | M15: =ROUNDUP($L15/المدخلات!$B$9,0) -> 2
A16: 19 | B16: {=ROUND(SUMPRODUCT(1/COUNTIF('بيانات الفرق'!$BJ$3:$BJ$21,'بيانات الفرق'!$BJ$3:$BJ$21)),0)} -> 1 | C16: {=_xlfn.TEXTJOIN(" + ",TRUE,COUNTIF('بيانات الفرق'!$BJ$3:$BJ$21,"المجموعة "&_xlfn.SEQUENCE($B16)))} -> 19 | D16: {=_xlfn.TEXTJOIN(" + ",TRUE,IF(ROUNDDOWN(_xlfn.MINIFS('بيانات الفرق'!$BK$3:$BK$21,'بيانات الفرق'!$BJ$3:$BJ$21,"المجموعة "&_xlfn.SEQUENCE($B16))/_xlfn.MINIFS('بيانات الفرق'!$BL$3:$BL$21,'بيانات الفرق'!$BJ$3:$BJ$21,"المجموعة "&_xlfn.SEQUENCE($B16)),0)=ROUNDUP(_xlfn.MAXIFS('بيانات الفرق'!$BK$3:$BK$21,'بيانات الفرق'!$BJ$3:$BJ$21,"المجموعة "&_xlfn.SEQUENCE($B16))/_xlfn.MINIFS('بيانات الفرق'!$BL$3:$BL$21,'بيانات الفرق'!$BJ$3:$BJ$21,"المجموعة "&_xlfn.SEQUENCE($B16)),0),ROUNDDOWN(_xlfn.MINIFS('بيانات الفرق'!$BK$3:$BK$21,'بيانات الفرق'!$BJ$3:$BJ$21,"المجموعة "&_xlfn.SEQUENCE($B16))/_xlfn.MINIFS('بيانات الفرق'!$BL$3:$BL$21,'بيانات الفرق'!$BJ$3:$BJ$21,"المجموعة "&_xlfn.SEQUENCE($B16)),0),ROUNDDOWN(_xlfn.MINIFS('بيانات الفرق'!$BK$3:$BK$21,'بيانات الفرق'!$BJ$3:$BJ$21,"المجموعة "&_xlfn.SEQUENCE($B16))/_xlfn.MINIFS('بيانات الفرق'!$BL$3:$BL$21,'بيانات الفرق'!$BJ$3:$BJ$21,"المجموعة "&_xlfn.SEQUENCE($B16)),0)&"–"&ROUNDUP(_xlfn.MAXIFS('بيانات الفرق'!$BK$3:$BK$21,'بيانات الفرق'!$BJ$3:$BJ$21,"المجموعة "&_xlfn.SEQUENCE($B16))/_xlfn.MINIFS('بيانات الفرق'!$BL$3:$BL$21,'بيانات الفرق'!$BJ$3:$BJ$21,"المجموعة "&_xlfn.SEQUENCE($B16)),0)))} -> 1 | E16: {=_xlfn.TEXTJOIN(" + ",TRUE,IF(_xlfn.MINIFS('بيانات الفرق'!$BK$3:$BK$21,'بيانات الفرق'!$BJ$3:$BJ$21,"المجموعة "&_xlfn.SEQUENCE($B16))=_xlfn.MAXIFS('بيانات الفرق'!$BK$3:$BK$21,'بيانات الفرق'!$BJ$3:$BJ$21,"المجموعة "&_xlfn.SEQUENCE($B16)),_xlfn.MINIFS('بيانات الفرق'!$BK$3:$BK$21,'بيانات الفرق'!$BJ$3:$BJ$21,"المجموعة "&_xlfn.SEQUENCE($B16)),_xlfn.MINIFS('بيانات الفرق'!$BK$3:$BK$21,'بيانات الفرق'!$BJ$3:$BJ$21,"المجموعة "&_xlfn.SEQUENCE($B16))&"–"&_xlfn.MAXIFS('بيانات الفرق'!$BK$3:$BK$21,'بيانات الفرق'!$BJ$3:$BJ$21,"المجموعة "&_xlfn.SEQUENCE($B16))))} -> 18 | F16: =IF(COUNTIF('19 فريقًا'!$D$4:$D$1999,"*فائز ر*")>0,"ربع نهائي ثم نصف نهائي ثم نهائي",IF(COUNTIF('19 فريقًا'!$D$4:$D$1999,"*فائز*")>0,"نصف نهائي ثم نهائي",IF(COUNTIF('19 فريقًا'!$D$4:$D$1999,"*أول المجموعة*")>0,"نهائي مباشر","—"))) -> — | G16: =_xlfn.MAXIFS('19 فريقًا'!$A$4:$A$1999,'19 فريقًا'!$D$4:$D$1999,"* ضد *",'19 فريقًا'!$D$4:$D$1999,"<>*فائز*",'19 فريقًا'!$D$4:$D$1999,"<>*أول المجموعة*",'19 فريقًا'!$D$4:$D$1999,"<>*المتأهل*") -> 19 | H16: =$I16-$G16 -> 0 | I16: =_xlfn.MAXIFS('19 فريقًا'!$A$4:$A$1999,'19 فريقًا'!$D$4:$D$1999,"* ضد *") -> 19 | J16: =MOD(HOUR(المدخلات!$B$4)-1,12)+1&":"&TEXT(MINUTE(المدخلات!$B$4),"00")&IF(HOUR(المدخلات!$B$4)<12," ص"," م") -> 4:00 م | K16: {=_xlfn.LET(_xlpm.p,SUMPRODUCT(MAX((COUNTIF('19 فريقًا'!$B$4:$B$1999,المدخلات!$F$4:$F$7)>0)*(المدخلات!$F$4:$F$7<>"")*ROW(المدخلات!$F$4:$F$7)))-3,_xlpm.t,INDEX(المدخلات!$F$4:$F$7,_xlpm.p),TRIM(MID(_xlpm.t,FIND("–",_xlpm.t)+1,20)))} -> 7:50 م | L16: =_xlfn.MAXIFS('19 فريقًا'!$C$4:$C$1999,'19 فريقًا'!$D$4:$D$1999,"* ضد *") -> 3 | M16: =ROUNDUP($L16/المدخلات!$B$9,0) -> 2
A17: 20 | B17: {=ROUND(SUMPRODUCT(1/COUNTIF('بيانات الفرق'!$BO$3:$BO$22,'بيانات الفرق'!$BO$3:$BO$22)),0)} -> 1 | C17: {=_xlfn.TEXTJOIN(" + ",TRUE,COUNTIF('بيانات الفرق'!$BO$3:$BO$22,"المجموعة "&_xlfn.SEQUENCE($B17)))} -> 20 | D17: {=_xlfn.TEXTJOIN(" + ",TRUE,IF(ROUNDDOWN(_xlfn.MINIFS('بيانات الفرق'!$BP$3:$BP$22,'بيانات الفرق'!$BO$3:$BO$22,"المجموعة "&_xlfn.SEQUENCE($B17))/_xlfn.MINIFS('بيانات الفرق'!$BQ$3:$BQ$22,'بيانات الفرق'!$BO$3:$BO$22,"المجموعة "&_xlfn.SEQUENCE($B17)),0)=ROUNDUP(_xlfn.MAXIFS('بيانات الفرق'!$BP$3:$BP$22,'بيانات الفرق'!$BO$3:$BO$22,"المجموعة "&_xlfn.SEQUENCE($B17))/_xlfn.MINIFS('بيانات الفرق'!$BQ$3:$BQ$22,'بيانات الفرق'!$BO$3:$BO$22,"المجموعة "&_xlfn.SEQUENCE($B17)),0),ROUNDDOWN(_xlfn.MINIFS('بيانات الفرق'!$BP$3:$BP$22,'بيانات الفرق'!$BO$3:$BO$22,"المجموعة "&_xlfn.SEQUENCE($B17))/_xlfn.MINIFS('بيانات الفرق'!$BQ$3:$BQ$22,'بيانات الفرق'!$BO$3:$BO$22,"المجموعة "&_xlfn.SEQUENCE($B17)),0),ROUNDDOWN(_xlfn.MINIFS('بيانات الفرق'!$BP$3:$BP$22,'بيانات الفرق'!$BO$3:$BO$22,"المجموعة "&_xlfn.SEQUENCE($B17))/_xlfn.MINIFS('بيانات الفرق'!$BQ$3:$BQ$22,'بيانات الفرق'!$BO$3:$BO$22,"المجموعة "&_xlfn.SEQUENCE($B17)),0)&"–"&ROUNDUP(_xlfn.MAXIFS('بيانات الفرق'!$BP$3:$BP$22,'بيانات الفرق'!$BO$3:$BO$22,"المجموعة "&_xlfn.SEQUENCE($B17))/_xlfn.MINIFS('بيانات الفرق'!$BQ$3:$BQ$22,'بيانات الفرق'!$BO$3:$BO$22,"المجموعة "&_xlfn.SEQUENCE($B17)),0)))} -> 1 | E17: {=_xlfn.TEXTJOIN(" + ",TRUE,IF(_xlfn.MINIFS('بيانات الفرق'!$BP$3:$BP$22,'بيانات الفرق'!$BO$3:$BO$22,"المجموعة "&_xlfn.SEQUENCE($B17))=_xlfn.MAXIFS('بيانات الفرق'!$BP$3:$BP$22,'بيانات الفرق'!$BO$3:$BO$22,"المجموعة "&_xlfn.SEQUENCE($B17)),_xlfn.MINIFS('بيانات الفرق'!$BP$3:$BP$22,'بيانات الفرق'!$BO$3:$BO$22,"المجموعة "&_xlfn.SEQUENCE($B17)),_xlfn.MINIFS('بيانات الفرق'!$BP$3:$BP$22,'بيانات الفرق'!$BO$3:$BO$22,"المجموعة "&_xlfn.SEQUENCE($B17))&"–"&_xlfn.MAXIFS('بيانات الفرق'!$BP$3:$BP$22,'بيانات الفرق'!$BO$3:$BO$22,"المجموعة "&_xlfn.SEQUENCE($B17))))} -> 19 | F17: =IF(COUNTIF('20 فريقًا'!$D$4:$D$1999,"*فائز ر*")>0,"ربع نهائي ثم نصف نهائي ثم نهائي",IF(COUNTIF('20 فريقًا'!$D$4:$D$1999,"*فائز*")>0,"نصف نهائي ثم نهائي",IF(COUNTIF('20 فريقًا'!$D$4:$D$1999,"*أول المجموعة*")>0,"نهائي مباشر","—"))) -> — | G17: =_xlfn.MAXIFS('20 فريقًا'!$A$4:$A$1999,'20 فريقًا'!$D$4:$D$1999,"* ضد *",'20 فريقًا'!$D$4:$D$1999,"<>*فائز*",'20 فريقًا'!$D$4:$D$1999,"<>*أول المجموعة*",'20 فريقًا'!$D$4:$D$1999,"<>*المتأهل*") -> 19 | H17: =$I17-$G17 -> 0 | I17: =_xlfn.MAXIFS('20 فريقًا'!$A$4:$A$1999,'20 فريقًا'!$D$4:$D$1999,"* ضد *") -> 19 | J17: =MOD(HOUR(المدخلات!$B$4)-1,12)+1&":"&TEXT(MINUTE(المدخلات!$B$4),"00")&IF(HOUR(المدخلات!$B$4)<12," ص"," م") -> 4:00 م | K17: {=_xlfn.LET(_xlpm.p,SUMPRODUCT(MAX((COUNTIF('20 فريقًا'!$B$4:$B$1999,المدخلات!$F$4:$F$7)>0)*(المدخلات!$F$4:$F$7<>"")*ROW(المدخلات!$F$4:$F$7)))-3,_xlpm.t,INDEX(المدخلات!$F$4:$F$7,_xlpm.p),TRIM(MID(_xlpm.t,FIND("–",_xlpm.t)+1,20)))} -> 7:50 م | L17: =_xlfn.MAXIFS('20 فريقًا'!$C$4:$C$1999,'20 فريقًا'!$D$4:$D$1999,"* ضد *") -> 4 | M17: =ROUNDUP($L17/المدخلات!$B$9,0) -> 2
A18: 21 | B18: {=ROUND(SUMPRODUCT(1/COUNTIF('بيانات الفرق'!$BT$3:$BT$23,'بيانات الفرق'!$BT$3:$BT$23)),0)} -> 1 | C18: {=_xlfn.TEXTJOIN(" + ",TRUE,COUNTIF('بيانات الفرق'!$BT$3:$BT$23,"المجموعة "&_xlfn.SEQUENCE($B18)))} -> 21 | D18: {=_xlfn.TEXTJOIN(" + ",TRUE,IF(ROUNDDOWN(_xlfn.MINIFS('بيانات الفرق'!$BU$3:$BU$23,'بيانات الفرق'!$BT$3:$BT$23,"المجموعة "&_xlfn.SEQUENCE($B18))/_xlfn.MINIFS('بيانات الفرق'!$BV$3:$BV$23,'بيانات الفرق'!$BT$3:$BT$23,"المجموعة "&_xlfn.SEQUENCE($B18)),0)=ROUNDUP(_xlfn.MAXIFS('بيانات الفرق'!$BU$3:$BU$23,'بيانات الفرق'!$BT$3:$BT$23,"المجموعة "&_xlfn.SEQUENCE($B18))/_xlfn.MINIFS('بيانات الفرق'!$BV$3:$BV$23,'بيانات الفرق'!$BT$3:$BT$23,"المجموعة "&_xlfn.SEQUENCE($B18)),0),ROUNDDOWN(_xlfn.MINIFS('بيانات الفرق'!$BU$3:$BU$23,'بيانات الفرق'!$BT$3:$BT$23,"المجموعة "&_xlfn.SEQUENCE($B18))/_xlfn.MINIFS('بيانات الفرق'!$BV$3:$BV$23,'بيانات الفرق'!$BT$3:$BT$23,"المجموعة "&_xlfn.SEQUENCE($B18)),0),ROUNDDOWN(_xlfn.MINIFS('بيانات الفرق'!$BU$3:$BU$23,'بيانات الفرق'!$BT$3:$BT$23,"المجموعة "&_xlfn.SEQUENCE($B18))/_xlfn.MINIFS('بيانات الفرق'!$BV$3:$BV$23,'بيانات الفرق'!$BT$3:$BT$23,"المجموعة "&_xlfn.SEQUENCE($B18)),0)&"–"&ROUNDUP(_xlfn.MAXIFS('بيانات الفرق'!$BU$3:$BU$23,'بيانات الفرق'!$BT$3:$BT$23,"المجموعة "&_xlfn.SEQUENCE($B18))/_xlfn.MINIFS('بيانات الفرق'!$BV$3:$BV$23,'بيانات الفرق'!$BT$3:$BT$23,"المجموعة "&_xlfn.SEQUENCE($B18)),0)))} -> 1 | E18: {=_xlfn.TEXTJOIN(" + ",TRUE,IF(_xlfn.MINIFS('بيانات الفرق'!$BU$3:$BU$23,'بيانات الفرق'!$BT$3:$BT$23,"المجموعة "&_xlfn.SEQUENCE($B18))=_xlfn.MAXIFS('بيانات الفرق'!$BU$3:$BU$23,'بيانات الفرق'!$BT$3:$BT$23,"المجموعة "&_xlfn.SEQUENCE($B18)),_xlfn.MINIFS('بيانات الفرق'!$BU$3:$BU$23,'بيانات الفرق'!$BT$3:$BT$23,"المجموعة "&_xlfn.SEQUENCE($B18)),_xlfn.MINIFS('بيانات الفرق'!$BU$3:$BU$23,'بيانات الفرق'!$BT$3:$BT$23,"المجموعة "&_xlfn.SEQUENCE($B18))&"–"&_xlfn.MAXIFS('بيانات الفرق'!$BU$3:$BU$23,'بيانات الفرق'!$BT$3:$BT$23,"المجموعة "&_xlfn.SEQUENCE($B18))))} -> 20 | F18: =IF(COUNTIF('21 فريقًا'!$D$4:$D$1999,"*فائز ر*")>0,"ربع نهائي ثم نصف نهائي ثم نهائي",IF(COUNTIF('21 فريقًا'!$D$4:$D$1999,"*فائز*")>0,"نصف نهائي ثم نهائي",IF(COUNTIF('21 فريقًا'!$D$4:$D$1999,"*أول المجموعة*")>0,"نهائي مباشر","—"))) -> — | G18: =_xlfn.MAXIFS('21 فريقًا'!$A$4:$A$1999,'21 فريقًا'!$D$4:$D$1999,"* ضد *",'21 فريقًا'!$D$4:$D$1999,"<>*فائز*",'21 فريقًا'!$D$4:$D$1999,"<>*أول المجموعة*",'21 فريقًا'!$D$4:$D$1999,"<>*المتأهل*") -> 21 | H18: =$I18-$G18 -> 0 | I18: =_xlfn.MAXIFS('21 فريقًا'!$A$4:$A$1999,'21 فريقًا'!$D$4:$D$1999,"* ضد *") -> 21 | J18: =MOD(HOUR(المدخلات!$B$4)-1,12)+1&":"&TEXT(MINUTE(المدخلات!$B$4),"00")&IF(HOUR(المدخلات!$B$4)<12," ص"," م") -> 4:00 م | K18: {=_xlfn.LET(_xlpm.p,SUMPRODUCT(MAX((COUNTIF('21 فريقًا'!$B$4:$B$1999,المدخلات!$F$4:$F$7)>0)*(المدخلات!$F$4:$F$7<>"")*ROW(المدخلات!$F$4:$F$7)))-3,_xlpm.t,INDEX(المدخلات!$F$4:$F$7,_xlpm.p),TRIM(MID(_xlpm.t,FIND("–",_xlpm.t)+1,20)))} -> 7:50 م | L18: =_xlfn.MAXIFS('21 فريقًا'!$C$4:$C$1999,'21 فريقًا'!$D$4:$D$1999,"* ضد *") -> 4 | M18: =ROUNDUP($L18/المدخلات!$B$9,0) -> 2
A19: 22 | B19: {=ROUND(SUMPRODUCT(1/COUNTIF('بيانات الفرق'!$BY$3:$BY$24,'بيانات الفرق'!$BY$3:$BY$24)),0)} -> 1 | C19: {=_xlfn.TEXTJOIN(" + ",TRUE,COUNTIF('بيانات الفرق'!$BY$3:$BY$24,"المجموعة "&_xlfn.SEQUENCE($B19)))} -> 22 | D19: {=_xlfn.TEXTJOIN(" + ",TRUE,IF(ROUNDDOWN(_xlfn.MINIFS('بيانات الفرق'!$BZ$3:$BZ$24,'بيانات الفرق'!$BY$3:$BY$24,"المجموعة "&_xlfn.SEQUENCE($B19))/_xlfn.MINIFS('بيانات الفرق'!$CA$3:$CA$24,'بيانات الفرق'!$BY$3:$BY$24,"المجموعة "&_xlfn.SEQUENCE($B19)),0)=ROUNDUP(_xlfn.MAXIFS('بيانات الفرق'!$BZ$3:$BZ$24,'بيانات الفرق'!$BY$3:$BY$24,"المجموعة "&_xlfn.SEQUENCE($B19))/_xlfn.MINIFS('بيانات الفرق'!$CA$3:$CA$24,'بيانات الفرق'!$BY$3:$BY$24,"المجموعة "&_xlfn.SEQUENCE($B19)),0),ROUNDDOWN(_xlfn.MINIFS('بيانات الفرق'!$BZ$3:$BZ$24,'بيانات الفرق'!$BY$3:$BY$24,"المجموعة "&_xlfn.SEQUENCE($B19))/_xlfn.MINIFS('بيانات الفرق'!$CA$3:$CA$24,'بيانات الفرق'!$BY$3:$BY$24,"المجموعة "&_xlfn.SEQUENCE($B19)),0),ROUNDDOWN(_xlfn.MINIFS('بيانات الفرق'!$BZ$3:$BZ$24,'بيانات الفرق'!$BY$3:$BY$24,"المجموعة "&_xlfn.SEQUENCE($B19))/_xlfn.MINIFS('بيانات الفرق'!$CA$3:$CA$24,'بيانات الفرق'!$BY$3:$BY$24,"المجموعة "&_xlfn.SEQUENCE($B19)),0)&"–"&ROUNDUP(_xlfn.MAXIFS('بيانات الفرق'!$BZ$3:$BZ$24,'بيانات الفرق'!$BY$3:$BY$24,"المجموعة "&_xlfn.SEQUENCE($B19))/_xlfn.MINIFS('بيانات الفرق'!$CA$3:$CA$24,'بيانات الفرق'!$BY$3:$BY$24,"المجموعة "&_xlfn.SEQUENCE($B19)),0)))} -> 1 | E19: {=_xlfn.TEXTJOIN(" + ",TRUE,IF(_xlfn.MINIFS('بيانات الفرق'!$BZ$3:$BZ$24,'بيانات الفرق'!$BY$3:$BY$24,"المجموعة "&_xlfn.SEQUENCE($B19))=_xlfn.MAXIFS('بيانات الفرق'!$BZ$3:$BZ$24,'بيانات الفرق'!$BY$3:$BY$24,"المجموعة "&_xlfn.SEQUENCE($B19)),_xlfn.MINIFS('بيانات الفرق'!$BZ$3:$BZ$24,'بيانات الفرق'!$BY$3:$BY$24,"المجموعة "&_xlfn.SEQUENCE($B19)),_xlfn.MINIFS('بيانات الفرق'!$BZ$3:$BZ$24,'بيانات الفرق'!$BY$3:$BY$24,"المجموعة "&_xlfn.SEQUENCE($B19))&"–"&_xlfn.MAXIFS('بيانات الفرق'!$BZ$3:$BZ$24,'بيانات الفرق'!$BY$3:$BY$24,"المجموعة "&_xlfn.SEQUENCE($B19))))} -> 21 | F19: =IF(COUNTIF('22 فريقًا'!$D$4:$D$1999,"*فائز ر*")>0,"ربع نهائي ثم نصف نهائي ثم نهائي",IF(COUNTIF('22 فريقًا'!$D$4:$D$1999,"*فائز*")>0,"نصف نهائي ثم نهائي",IF(COUNTIF('22 فريقًا'!$D$4:$D$1999,"*أول المجموعة*")>0,"نهائي مباشر","—"))) -> — | G19: =_xlfn.MAXIFS('22 فريقًا'!$A$4:$A$1999,'22 فريقًا'!$D$4:$D$1999,"* ضد *",'22 فريقًا'!$D$4:$D$1999,"<>*فائز*",'22 فريقًا'!$D$4:$D$1999,"<>*أول المجموعة*",'22 فريقًا'!$D$4:$D$1999,"<>*المتأهل*") -> 21 | H19: =$I19-$G19 -> 0 | I19: =_xlfn.MAXIFS('22 فريقًا'!$A$4:$A$1999,'22 فريقًا'!$D$4:$D$1999,"* ضد *") -> 21 | J19: =MOD(HOUR(المدخلات!$B$4)-1,12)+1&":"&TEXT(MINUTE(المدخلات!$B$4),"00")&IF(HOUR(المدخلات!$B$4)<12," ص"," م") -> 4:00 م | K19: {=_xlfn.LET(_xlpm.p,SUMPRODUCT(MAX((COUNTIF('22 فريقًا'!$B$4:$B$1999,المدخلات!$F$4:$F$7)>0)*(المدخلات!$F$4:$F$7<>"")*ROW(المدخلات!$F$4:$F$7)))-3,_xlpm.t,INDEX(المدخلات!$F$4:$F$7,_xlpm.p),TRIM(MID(_xlpm.t,FIND("–",_xlpm.t)+1,20)))} -> 7:50 م | L19: =_xlfn.MAXIFS('22 فريقًا'!$C$4:$C$1999,'22 فريقًا'!$D$4:$D$1999,"* ضد *") -> 4 | M19: =ROUNDUP($L19/المدخلات!$B$9,0) -> 2
A20: 23 | B20: {=ROUND(SUMPRODUCT(1/COUNTIF('بيانات الفرق'!$CD$3:$CD$25,'بيانات الفرق'!$CD$3:$CD$25)),0)} -> 2 | C20: {=_xlfn.TEXTJOIN(" + ",TRUE,COUNTIF('بيانات الفرق'!$CD$3:$CD$25,"المجموعة "&_xlfn.SEQUENCE($B20)))} -> 12 + 11 | D20: {=_xlfn.TEXTJOIN(" + ",TRUE,IF(ROUNDDOWN(_xlfn.MINIFS('بيانات الفرق'!$CE$3:$CE$25,'بيانات الفرق'!$CD$3:$CD$25,"المجموعة "&_xlfn.SEQUENCE($B20))/_xlfn.MINIFS('بيانات الفرق'!$CF$3:$CF$25,'بيانات الفرق'!$CD$3:$CD$25,"المجموعة "&_xlfn.SEQUENCE($B20)),0)=ROUNDUP(_xlfn.MAXIFS('بيانات الفرق'!$CE$3:$CE$25,'بيانات الفرق'!$CD$3:$CD$25,"المجموعة "&_xlfn.SEQUENCE($B20))/_xlfn.MINIFS('بيانات الفرق'!$CF$3:$CF$25,'بيانات الفرق'!$CD$3:$CD$25,"المجموعة "&_xlfn.SEQUENCE($B20)),0),ROUNDDOWN(_xlfn.MINIFS('بيانات الفرق'!$CE$3:$CE$25,'بيانات الفرق'!$CD$3:$CD$25,"المجموعة "&_xlfn.SEQUENCE($B20))/_xlfn.MINIFS('بيانات الفرق'!$CF$3:$CF$25,'بيانات الفرق'!$CD$3:$CD$25,"المجموعة "&_xlfn.SEQUENCE($B20)),0),ROUNDDOWN(_xlfn.MINIFS('بيانات الفرق'!$CE$3:$CE$25,'بيانات الفرق'!$CD$3:$CD$25,"المجموعة "&_xlfn.SEQUENCE($B20))/_xlfn.MINIFS('بيانات الفرق'!$CF$3:$CF$25,'بيانات الفرق'!$CD$3:$CD$25,"المجموعة "&_xlfn.SEQUENCE($B20)),0)&"–"&ROUNDUP(_xlfn.MAXIFS('بيانات الفرق'!$CE$3:$CE$25,'بيانات الفرق'!$CD$3:$CD$25,"المجموعة "&_xlfn.SEQUENCE($B20))/_xlfn.MINIFS('بيانات الفرق'!$CF$3:$CF$25,'بيانات الفرق'!$CD$3:$CD$25,"المجموعة "&_xlfn.SEQUENCE($B20)),0)))} -> 1–2 + 1–2 | E20: {=_xlfn.TEXTJOIN(" + ",TRUE,IF(_xlfn.MINIFS('بيانات الفرق'!$CE$3:$CE$25,'بيانات الفرق'!$CD$3:$CD$25,"المجموعة "&_xlfn.SEQUENCE($B20))=_xlfn.MAXIFS('بيانات الفرق'!$CE$3:$CE$25,'بيانات الفرق'!$CD$3:$CD$25,"المجموعة "&_xlfn.SEQUENCE($B20)),_xlfn.MINIFS('بيانات الفرق'!$CE$3:$CE$25,'بيانات الفرق'!$CD$3:$CD$25,"المجموعة "&_xlfn.SEQUENCE($B20)),_xlfn.MINIFS('بيانات الفرق'!$CE$3:$CE$25,'بيانات الفرق'!$CD$3:$CD$25,"المجموعة "&_xlfn.SEQUENCE($B20))&"–"&_xlfn.MAXIFS('بيانات الفرق'!$CE$3:$CE$25,'بيانات الفرق'!$CD$3:$CD$25,"المجموعة "&_xlfn.SEQUENCE($B20))))} -> 18 + 18 | F20: =IF(COUNTIF('23 فريقًا'!$E$4:$E$1999,"*فائز ر*")>0,"ربع نهائي ثم نصف نهائي ثم نهائي",IF(COUNTIF('23 فريقًا'!$E$4:$E$1999,"*فائز*")>0,"نصف نهائي ثم نهائي",IF(COUNTIF('23 فريقًا'!$E$4:$E$1999,"*أول المجموعة*")>0,"نهائي مباشر","—"))) -> نهائي مباشر | G20: =_xlfn.MAXIFS('23 فريقًا'!$A$4:$A$1999,'23 فريقًا'!$E$4:$E$1999,"* ضد *",'23 فريقًا'!$E$4:$E$1999,"<>*فائز*",'23 فريقًا'!$E$4:$E$1999,"<>*أول المجموعة*",'23 فريقًا'!$E$4:$E$1999,"<>*المتأهل*") -> 21 | H20: =$I20-$G20 -> 1 | I20: =_xlfn.MAXIFS('23 فريقًا'!$A$4:$A$1999,'23 فريقًا'!$E$4:$E$1999,"* ضد *") -> 22 | J20: =MOD(HOUR(المدخلات!$B$4)-1,12)+1&":"&TEXT(MINUTE(المدخلات!$B$4),"00")&IF(HOUR(المدخلات!$B$4)<12," ص"," م") -> 4:00 م | K20: {=_xlfn.LET(_xlpm.p,SUMPRODUCT(MAX((COUNTIF('23 فريقًا'!$B$4:$B$1999,المدخلات!$F$4:$F$7)>0)*(المدخلات!$F$4:$F$7<>"")*ROW(المدخلات!$F$4:$F$7)))-3,_xlpm.t,INDEX(المدخلات!$F$4:$F$7,_xlpm.p),TRIM(MID(_xlpm.t,FIND("–",_xlpm.t)+1,20)))} -> 7:50 م | L20: =_xlfn.MAXIFS('23 فريقًا'!$C$4:$C$1999,'23 فريقًا'!$E$4:$E$1999,"* ضد *") -> 4 | M20: =ROUNDUP($L20/المدخلات!$B$9,0) -> 2
A21: 25 | B21: {=ROUND(SUMPRODUCT(1/COUNTIF('بيانات الفرق'!$CI$3:$CI$27,'بيانات الفرق'!$CI$3:$CI$27)),0)} -> 2 | C21: {=_xlfn.TEXTJOIN(" + ",TRUE,COUNTIF('بيانات الفرق'!$CI$3:$CI$27,"المجموعة "&_xlfn.SEQUENCE($B21)))} -> 13 + 12 | D21: {=_xlfn.TEXTJOIN(" + ",TRUE,IF(ROUNDDOWN(_xlfn.MINIFS('بيانات الفرق'!$CJ$3:$CJ$27,'بيانات الفرق'!$CI$3:$CI$27,"المجموعة "&_xlfn.SEQUENCE($B21))/_xlfn.MINIFS('بيانات الفرق'!$CK$3:$CK$27,'بيانات الفرق'!$CI$3:$CI$27,"المجموعة "&_xlfn.SEQUENCE($B21)),0)=ROUNDUP(_xlfn.MAXIFS('بيانات الفرق'!$CJ$3:$CJ$27,'بيانات الفرق'!$CI$3:$CI$27,"المجموعة "&_xlfn.SEQUENCE($B21))/_xlfn.MINIFS('بيانات الفرق'!$CK$3:$CK$27,'بيانات الفرق'!$CI$3:$CI$27,"المجموعة "&_xlfn.SEQUENCE($B21)),0),ROUNDDOWN(_xlfn.MINIFS('بيانات الفرق'!$CJ$3:$CJ$27,'بيانات الفرق'!$CI$3:$CI$27,"المجموعة "&_xlfn.SEQUENCE($B21))/_xlfn.MINIFS('بيانات الفرق'!$CK$3:$CK$27,'بيانات الفرق'!$CI$3:$CI$27,"المجموعة "&_xlfn.SEQUENCE($B21)),0),ROUNDDOWN(_xlfn.MINIFS('بيانات الفرق'!$CJ$3:$CJ$27,'بيانات الفرق'!$CI$3:$CI$27,"المجموعة "&_xlfn.SEQUENCE($B21))/_xlfn.MINIFS('بيانات الفرق'!$CK$3:$CK$27,'بيانات الفرق'!$CI$3:$CI$27,"المجموعة "&_xlfn.SEQUENCE($B21)),0)&"–"&ROUNDUP(_xlfn.MAXIFS('بيانات الفرق'!$CJ$3:$CJ$27,'بيانات الفرق'!$CI$3:$CI$27,"المجموعة "&_xlfn.SEQUENCE($B21))/_xlfn.MINIFS('بيانات الفرق'!$CK$3:$CK$27,'بيانات الفرق'!$CI$3:$CI$27,"المجموعة "&_xlfn.SEQUENCE($B21)),0)))} -> 1–2 + 1–2 | E21: {=_xlfn.TEXTJOIN(" + ",TRUE,IF(_xlfn.MINIFS('بيانات الفرق'!$CJ$3:$CJ$27,'بيانات الفرق'!$CI$3:$CI$27,"المجموعة "&_xlfn.SEQUENCE($B21))=_xlfn.MAXIFS('بيانات الفرق'!$CJ$3:$CJ$27,'بيانات الفرق'!$CI$3:$CI$27,"المجموعة "&_xlfn.SEQUENCE($B21)),_xlfn.MINIFS('بيانات الفرق'!$CJ$3:$CJ$27,'بيانات الفرق'!$CI$3:$CI$27,"المجموعة "&_xlfn.SEQUENCE($B21)),_xlfn.MINIFS('بيانات الفرق'!$CJ$3:$CJ$27,'بيانات الفرق'!$CI$3:$CI$27,"المجموعة "&_xlfn.SEQUENCE($B21))&"–"&_xlfn.MAXIFS('بيانات الفرق'!$CJ$3:$CJ$27,'بيانات الفرق'!$CI$3:$CI$27,"المجموعة "&_xlfn.SEQUENCE($B21))))} -> 18 + 18 | F21: =IF(COUNTIF('25 فريقًا'!$E$4:$E$1999,"*فائز ر*")>0,"ربع نهائي ثم نصف نهائي ثم نهائي",IF(COUNTIF('25 فريقًا'!$E$4:$E$1999,"*فائز*")>0,"نصف نهائي ثم نهائي",IF(COUNTIF('25 فريقًا'!$E$4:$E$1999,"*أول المجموعة*")>0,"نهائي مباشر","—"))) -> نهائي مباشر | G21: =_xlfn.MAXIFS('25 فريقًا'!$A$4:$A$1999,'25 فريقًا'!$E$4:$E$1999,"* ضد *",'25 فريقًا'!$E$4:$E$1999,"<>*فائز*",'25 فريقًا'!$E$4:$E$1999,"<>*أول المجموعة*",'25 فريقًا'!$E$4:$E$1999,"<>*المتأهل*") -> 21 | H21: =$I21-$G21 -> 1 | I21: =_xlfn.MAXIFS('25 فريقًا'!$A$4:$A$1999,'25 فريقًا'!$E$4:$E$1999,"* ضد *") -> 22 | J21: =MOD(HOUR(المدخلات!$B$4)-1,12)+1&":"&TEXT(MINUTE(المدخلات!$B$4),"00")&IF(HOUR(المدخلات!$B$4)<12," ص"," م") -> 4:00 م | K21: {=_xlfn.LET(_xlpm.p,SUMPRODUCT(MAX((COUNTIF('25 فريقًا'!$B$4:$B$1999,المدخلات!$F$4:$F$7)>0)*(المدخلات!$F$4:$F$7<>"")*ROW(المدخلات!$F$4:$F$7)))-3,_xlpm.t,INDEX(المدخلات!$F$4:$F$7,_xlpm.p),TRIM(MID(_xlpm.t,FIND("–",_xlpm.t)+1,20)))} -> 7:50 م | L21: =_xlfn.MAXIFS('25 فريقًا'!$C$4:$C$1999,'25 فريقًا'!$E$4:$E$1999,"* ضد *") -> 4 | M21: =ROUNDUP($L21/المدخلات!$B$9,0) -> 2
A22: 26 | B22: {=ROUND(SUMPRODUCT(1/COUNTIF('بيانات الفرق'!$CN$3:$CN$28,'بيانات الفرق'!$CN$3:$CN$28)),0)} -> 2 | C22: {=_xlfn.TEXTJOIN(" + ",TRUE,COUNTIF('بيانات الفرق'!$CN$3:$CN$28,"المجموعة "&_xlfn.SEQUENCE($B22)))} -> 14 + 12 | D22: {=_xlfn.TEXTJOIN(" + ",TRUE,IF(ROUNDDOWN(_xlfn.MINIFS('بيانات الفرق'!$CO$3:$CO$28,'بيانات الفرق'!$CN$3:$CN$28,"المجموعة "&_xlfn.SEQUENCE($B22))/_xlfn.MINIFS('بيانات الفرق'!$CP$3:$CP$28,'بيانات الفرق'!$CN$3:$CN$28,"المجموعة "&_xlfn.SEQUENCE($B22)),0)=ROUNDUP(_xlfn.MAXIFS('بيانات الفرق'!$CO$3:$CO$28,'بيانات الفرق'!$CN$3:$CN$28,"المجموعة "&_xlfn.SEQUENCE($B22))/_xlfn.MINIFS('بيانات الفرق'!$CP$3:$CP$28,'بيانات الفرق'!$CN$3:$CN$28,"المجموعة "&_xlfn.SEQUENCE($B22)),0),ROUNDDOWN(_xlfn.MINIFS('بيانات الفرق'!$CO$3:$CO$28,'بيانات الفرق'!$CN$3:$CN$28,"المجموعة "&_xlfn.SEQUENCE($B22))/_xlfn.MINIFS('بيانات الفرق'!$CP$3:$CP$28,'بيانات الفرق'!$CN$3:$CN$28,"المجموعة "&_xlfn.SEQUENCE($B22)),0),ROUNDDOWN(_xlfn.MINIFS('بيانات الفرق'!$CO$3:$CO$28,'بيانات الفرق'!$CN$3:$CN$28,"المجموعة "&_xlfn.SEQUENCE($B22))/_xlfn.MINIFS('بيانات الفرق'!$CP$3:$CP$28,'بيانات الفرق'!$CN$3:$CN$28,"المجموعة "&_xlfn.SEQUENCE($B22)),0)&"–"&ROUNDUP(_xlfn.MAXIFS('بيانات الفرق'!$CO$3:$CO$28,'بيانات الفرق'!$CN$3:$CN$28,"المجموعة "&_xlfn.SEQUENCE($B22))/_xlfn.MINIFS('بيانات الفرق'!$CP$3:$CP$28,'بيانات الفرق'!$CN$3:$CN$28,"المجموعة "&_xlfn.SEQUENCE($B22)),0)))} -> 1–2 + 1–2 | E22: {=_xlfn.TEXTJOIN(" + ",TRUE,IF(_xlfn.MINIFS('بيانات الفرق'!$CO$3:$CO$28,'بيانات الفرق'!$CN$3:$CN$28,"المجموعة "&_xlfn.SEQUENCE($B22))=_xlfn.MAXIFS('بيانات الفرق'!$CO$3:$CO$28,'بيانات الفرق'!$CN$3:$CN$28,"المجموعة "&_xlfn.SEQUENCE($B22)),_xlfn.MINIFS('بيانات الفرق'!$CO$3:$CO$28,'بيانات الفرق'!$CN$3:$CN$28,"المجموعة "&_xlfn.SEQUENCE($B22)),_xlfn.MINIFS('بيانات الفرق'!$CO$3:$CO$28,'بيانات الفرق'!$CN$3:$CN$28,"المجموعة "&_xlfn.SEQUENCE($B22))&"–"&_xlfn.MAXIFS('بيانات الفرق'!$CO$3:$CO$28,'بيانات الفرق'!$CN$3:$CN$28,"المجموعة "&_xlfn.SEQUENCE($B22))))} -> 18 + 18 | F22: =IF(COUNTIF('26 فريقًا'!$E$4:$E$1999,"*فائز ر*")>0,"ربع نهائي ثم نصف نهائي ثم نهائي",IF(COUNTIF('26 فريقًا'!$E$4:$E$1999,"*فائز*")>0,"نصف نهائي ثم نهائي",IF(COUNTIF('26 فريقًا'!$E$4:$E$1999,"*أول المجموعة*")>0,"نهائي مباشر","—"))) -> نهائي مباشر | G22: =_xlfn.MAXIFS('26 فريقًا'!$A$4:$A$1999,'26 فريقًا'!$E$4:$E$1999,"* ضد *",'26 فريقًا'!$E$4:$E$1999,"<>*فائز*",'26 فريقًا'!$E$4:$E$1999,"<>*أول المجموعة*",'26 فريقًا'!$E$4:$E$1999,"<>*المتأهل*") -> 18 | H22: =$I22-$G22 -> 1 | I22: =_xlfn.MAXIFS('26 فريقًا'!$A$4:$A$1999,'26 فريقًا'!$E$4:$E$1999,"* ضد *") -> 19 | J22: =MOD(HOUR(المدخلات!$B$4)-1,12)+1&":"&TEXT(MINUTE(المدخلات!$B$4),"00")&IF(HOUR(المدخلات!$B$4)<12," ص"," م") -> 4:00 م | K22: {=_xlfn.LET(_xlpm.p,SUMPRODUCT(MAX((COUNTIF('26 فريقًا'!$B$4:$B$1999,المدخلات!$F$4:$F$7)>0)*(المدخلات!$F$4:$F$7<>"")*ROW(المدخلات!$F$4:$F$7)))-3,_xlpm.t,INDEX(المدخلات!$F$4:$F$7,_xlpm.p),TRIM(MID(_xlpm.t,FIND("–",_xlpm.t)+1,20)))} -> 7:50 م | L22: =_xlfn.MAXIFS('26 فريقًا'!$C$4:$C$1999,'26 فريقًا'!$E$4:$E$1999,"* ضد *") -> 5 | M22: =ROUNDUP($L22/المدخلات!$B$9,0) -> 3
