Workbook
Name الحد_الأدنى: [1]المدخلات!$N$3

Sheet 49 فريق
A1: جدول مباريات بطولة 49 فريقاً — أربع مجموعات (12 + 12 + 12 + 13) في أربعة ملاعب قانونية منفصلة
C2: الملعب القانوني 1 — المجموعة أ (الفرق 1–12) | G2: الملعب القانوني 2 — المجموعة ب (الفرق 13–24) | K2: الملعب القانوني 3 — المجموعة ج (الفرق 25–36) | O2: الملعب القانوني 4 — المجموعة د (الفرق 37–49)
A3: المهرجان | B3: الوقت | C3: ملعب 1 | D3: ملعب 2 | E3: ملعب 3 | F3: ملعب 4 | G3: ملعب 1 | H3: ملعب 2 | I3: ملعب 3 | J3: ملعب 4 | K3: ملعب 1 | L3: ملعب 2 | M3: ملعب 3 | N3: ملعب 4 | O3: ملعب 1 | P3: ملعب 2 | Q3: ملعب 3 | R3: ملعب 4 | S3: مجموع مباريات المهرجان
A4: المهرجان 1 | B4: =(MOD(HOUR([2]المدخلات!$B$4+(1-1)*[2]المدخلات!$B$7/1440)-1,12)+1)&":"&TEXT(MINUTE([2]المدخلات!$B$4+(1-1)*[2]المدخلات!$B$7/1440),"00")&"–"&(MOD(HOUR([2]المدخلات!$B$4+(1-1)*[2]المدخلات!$B$7/1440+[2]المدخلات!$B$5/1440)-1,12)+1)&":"&TEXT(MINUTE([2]المدخلات!$B$4+(1-1)*[2]المدخلات!$B$7/1440+[2]المدخلات!$B$5/1440),"00")&" م" -> 4:00–4:15 م | C4: 4 ضد 8 | G4: 16 ضد 20 | K4: 28 ضد 32 | O4: 45 ضد 49 | P4: 37 ضد 41 | Q4: 43 ضد 47 | R4: 42 ضد 44 | S4: =COUNTA(C4:R12) -> 98
B5: =(MOD(HOUR([2]المدخلات!$B$4+(2-1)*[2]المدخلات!$B$7/1440)-1,12)+1)&":"&TEXT(MINUTE([2]المدخلات!$B$4+(2-1)*[2]المدخلات!$B$7/1440),"00")&"–"&(MOD(HOUR([2]المدخلات!$B$4+(2-1)*[2]المدخلات!$B$7/1440+[2]المدخلات!$B$5/1440)-1,12)+1)&":"&TEXT(MINUTE([2]المدخلات!$B$4+(2-1)*[2]المدخلات!$B$7/1440+[2]المدخلات!$B$5/1440),"00")&" م" -> 4:15–4:30 م | C5: 2 ضد 6 | D5: 11 ضد 12 | E5: 7 ضد 9 | G5: 14 ضد 18 | H5: 23 ضد 24 | I5: 19 ضد 21 | K5: 26 ضد 30 | L5: 35 ضد 36 | M5: 31 ضد 33 | O5: 38 ضد 39 | P5: 40 ضد 46
B6: =(MOD(HOUR([2]المدخلات!$B$4+(3-1)*[2]المدخلات!$B$7/1440)-1,12)+1)&":"&TEXT(MINUTE([2]المدخلات!$B$4+(3-1)*[2]المدخلات!$B$7/1440),"00")&"–"&(MOD(HOUR([2]المدخلات!$B$4+(3-1)*[2]المدخلات!$B$7/1440+[2]المدخلات!$B$5/1440)-1,12)+1)&":"&TEXT(MINUTE([2]المدخلات!$B$4+(3-1)*[2]المدخلات!$B$7/1440+[2]المدخلات!$B$5/1440),"00")&" م" -> 4:30–4:45 م | C6: 3 ضد 5 | D6: 1 ضد 10 | G6: 15 ضد 17 | H6: 13 ضد 22 | K6: 27 ضد 29 | L6: 25 ضد 34 | O6: 43 ضد 49 | P6: 44 ضد 47 | Q6: 42 ضد 48
B7: =(MOD(HOUR([2]المدخلات!$B$4+(4-1)*[2]المدخلات!$B$7/1440)-1,12)+1)&":"&TEXT(MINUTE([2]المدخلات!$B$4+(4-1)*[2]المدخلات!$B$7/1440),"00")&"–"&(MOD(HOUR([2]المدخلات!$B$4+(4-1)*[2]المدخلات!$B$7/1440+[2]المدخلات!$B$5/1440)-1,12)+1)&":"&TEXT(MINUTE([2]المدخلات!$B$4+(4-1)*[2]المدخلات!$B$7/1440+[2]المدخلات!$B$5/1440),"00")&" م" -> 4:45–5:00 م | C7: 4 ضد 7 | D7: 2 ضد 8 | E7: 6 ضد 12 | F7: 9 ضد 11 | G7: 16 ضد 19 | H7: 14 ضد 20 | I7: 18 ضد 24 | J7: 21 ضد 23 | K7: 28 ضد 31 | L7: 26 ضد 32 | M7: 30 ضد 36 | N7: 33 ضد 35 | O7: 39 ضد 41 | P7: 38 ضد 46 | Q7: 37 ضد 45
B8: =(MOD(HOUR([2]المدخلات!$B$4+(5-1)*[2]المدخلات!$B$7/1440)-1,12)+1)&":"&TEXT(MINUTE([2]المدخلات!$B$4+(5-1)*[2]المدخلات!$B$7/1440),"00")&"–"&(MOD(HOUR([2]المدخلات!$B$4+(5-1)*[2]المدخلات!$B$7/1440+[2]المدخلات!$B$5/1440)-1,12)+1)&":"&TEXT(MINUTE([2]المدخلات!$B$4+(5-1)*[2]المدخلات!$B$7/1440+[2]المدخلات!$B$5/1440),"00")&" م" -> 5:00–5:15 م | C8: 1 ضد 5 | D8: 3 ضد 10 | G8: 13 ضد 17 | H8: 15 ضد 22 | K8: 25 ضد 29 | L8: 27 ضد 34 | O8: 40 ضد 47 | P8: 44 ضد 48
B9: =(MOD(HOUR([2]المدخلات!$B$4+(6-1)*[2]المدخلات!$B$7/1440)-1,12)+1)&":"&TEXT(MINUTE([2]المدخلات!$B$4+(6-1)*[2]المدخلات!$B$7/1440),"00")&"–"&(MOD(HOUR([2]المدخلات!$B$4+(6-1)*[2]المدخلات!$B$7/1440+[2]المدخلات!$B$5/1440)-1,12)+1)&":"&TEXT(MINUTE([2]المدخلات!$B$4+(6-1)*[2]المدخلات!$B$7/1440+[2]المدخلات!$B$5/1440),"00")&" م" -> 5:15–5:30 م | C9: 7 ضد 12 | D9: 6 ضد 8 | G9: 19 ضد 24 | H9: 18 ضد 20 | K9: 31 ضد 36 | L9: 30 ضد 32 | O9: 43 ضد 45 | P9: 37 ضد 49 | Q9: 42 ضد 46 | R9: 38 ضد 41
B10: =(MOD(HOUR([2]المدخلات!$B$4+(7-1)*[2]المدخلات!$B$7/1440)-1,12)+1)&":"&TEXT(MINUTE([2]المدخلات!$B$4+(7-1)*[2]المدخلات!$B$7/1440),"00")&"–"&(MOD(HOUR([2]المدخلات!$B$4+(7-1)*[2]المدخلات!$B$7/1440+[2]المدخلات!$B$5/1440)-1,12)+1)&":"&TEXT(MINUTE([2]المدخلات!$B$4+(7-1)*[2]المدخلات!$B$7/1440+[2]المدخلات!$B$5/1440),"00")&" م" -> 5:30–5:45 م | C10: 9 ضد 10 | D10: 4 ضد 5 | E10: 1 ضد 11 | F10: 2 ضد 3 | G10: 21 ضد 22 | H10: 16 ضد 17 | I10: 13 ضد 23 | J10: 14 ضد 15 | K10: 33 ضد 34 | L10: 28 ضد 29 | M10: 25 ضد 35 | N10: 26 ضد 27 | O10: 40 ضد 44 | P10: 39 ضد 48
B11: =(MOD(HOUR([2]المدخلات!$B$4+(8-1)*[2]المدخلات!$B$7/1440)-1,12)+1)&":"&TEXT(MINUTE([2]المدخلات!$B$4+(8-1)*[2]المدخلات!$B$7/1440),"00")&"–"&(MOD(HOUR([2]المدخلات!$B$4+(8-1)*[2]المدخلات!$B$7/1440+[2]المدخلات!$B$5/1440)-1,12)+1)&":"&TEXT(MINUTE([2]المدخلات!$B$4+(8-1)*[2]المدخلات!$B$7/1440+[2]المدخلات!$B$5/1440),"00")&" م" -> 5:45–6:00 م | C11: 6 ضد 7 | D11: 8 ضد 12 | G11: 18 ضد 19 | H11: 20 ضد 24 | K11: 30 ضد 31 | L11: 32 ضد 36 | O11: 41 ضد 43 | P11: 46 ضد 49 | Q11: 38 ضد 47
B12: =(MOD(HOUR([2]المدخلات!$B$4+(9-1)*[2]المدخلات!$B$7/1440)-1,12)+1)&":"&TEXT(MINUTE([2]المدخلات!$B$4+(9-1)*[2]المدخلات!$B$7/1440),"00")&"–"&(MOD(HOUR([2]المدخلات!$B$4+(9-1)*[2]المدخلات!$B$7/1440+[2]المدخلات!$B$5/1440)-1,12)+1)&":"&TEXT(MINUTE([2]المدخلات!$B$4+(9-1)*[2]المدخلات!$B$7/1440+[2]المدخلات!$B$5/1440),"00")&" م" -> 6:00–6:15 م | C12: 1 ضد 3 | D12: 4 ضد 11 | E12: 2 ضد 10 | F12: 5 ضد 9 | G12: 13 ضد 15 | H12: 16 ضد 23 | I12: 14 ضد 22 | J12: 17 ضد 21 | K12: 25 ضد 27 | L12: 28 ضد 35 | M12: 26 ضد 34 | N12: 29 ضد 33 | O12: 39 ضد 40 | P12: 42 ضد 45 | Q12: 37 ضد 48
A13: المهرجان 2 | B13: =(MOD(HOUR([2]المدخلات!$B$4+(1-1)*[2]المدخلات!$B$7/1440)-1,12)+1)&":"&TEXT(MINUTE([2]المدخلات!$B$4+(1-1)*[2]المدخلات!$B$7/1440),"00")&"–"&(MOD(HOUR([2]المدخلات!$B$4+(1-1)*[2]المدخلات!$B$7/1440+[2]المدخلات!$B$5/1440)-1,12)+1)&":"&TEXT(MINUTE([2]المدخلات!$B$4+(1-1)*[2]المدخلات!$B$7/1440+[2]المدخلات!$B$5/1440),"00")&" م" -> 4:00–4:15 م | C13: 1 ضد 7 | D13: 3 ضد 11 | E13: 5 ضد 10 | G13: 13 ضد 19 | H13: 15 ضد 23 | I13: 17 ضد 22 | K13: 25 ضد 31 | L13: 27 ضد 35 | M13: 29 ضد 34 | O13: 43 ضد 46 | P13: 39 ضد 45 | Q13: 37 ضد 44 | R13: 38 ضد 49 | S13: =COUNTA(C13:R21) -> 98
B14: =(MOD(HOUR([2]المدخلات!$B$4+(2-1)*[2]المدخلات!$B$7/1440)-1,12)+1)&":"&TEXT(MINUTE([2]المدخلات!$B$4+(2-1)*[2]المدخلات!$B$7/1440),"00")&"–"&(MOD(HOUR([2]المدخلات!$B$4+(2-1)*[2]المدخلات!$B$7/1440+[2]المدخلات!$B$5/1440)-1,12)+1)&":"&TEXT(MINUTE([2]المدخلات!$B$4+(2-1)*[2]المدخلات!$B$7/1440+[2]المدخلات!$B$5/1440),"00")&" م" -> 4:15–4:30 م | C14: 9 ضد 12 | D14: 2 ضد 4 | G14: 21 ضد 24 | H14: 14 ضد 16 | K14: 33 ضد 36 | L14: 26 ضد 28 | O14: 42 ضد 47 | P14: 40 ضد 41
B15: =(MOD(HOUR([2]المدخلات!$B$4+(3-1)*[2]المدخلات!$B$7/1440)-1,12)+1)&":"&TEXT(MINUTE([2]المدخلات!$B$4+(3-1)*[2]المدخلات!$B$7/1440),"00")&"–"&(MOD(HOUR([2]المدخلات!$B$4+(3-1)*[2]المدخلات!$B$7/1440+[2]المدخلات!$B$5/1440)-1,12)+1)&":"&TEXT(MINUTE([2]المدخلات!$B$4+(3-1)*[2]المدخلات!$B$7/1440+[2]المدخلات!$B$5/1440),"00")&" م" -> 4:30–4:45 م | C15: 6 ضد 11 | D15: 3 ضد 8 | G15: 18 ضد 23 | H15: 15 ضد 20 | K15: 30 ضد 35 | L15: 27 ضد 32 | O15: 37 ضد 43 | P15: 48 ضد 49 | Q15: 38 ضد 45
B16: =(MOD(HOUR([2]المدخلات!$B$4+(4-1)*[2]المدخلات!$B$7/1440)-1,12)+1)&":"&TEXT(MINUTE([2]المدخلات!$B$4+(4-1)*[2]المدخلات!$B$7/1440),"00")&"–"&(MOD(HOUR([2]المدخلات!$B$4+(4-1)*[2]المدخلات!$B$7/1440+[2]المدخلات!$B$5/1440)-1,12)+1)&":"&TEXT(MINUTE([2]المدخلات!$B$4+(4-1)*[2]المدخلات!$B$7/1440+[2]المدخلات!$B$5/1440),"00")&" م" -> 4:45–5:00 م | C16: 1 ضد 2 | D16: 5 ضد 12 | E16: 7 ضد 10 | G16: 13 ضد 14 | H16: 17 ضد 24 | I16: 19 ضد 22 | K16: 25 ضد 26 | L16: 29 ضد 36 | M16: 31 ضد 34 | O16: 39 ضد 44 | P16: 40 ضد 42 | Q16: 46 ضد 47
B17: =(MOD(HOUR([2]المدخلات!$B$4+(5-1)*[2]المدخلات!$B$7/1440)-1,12)+1)&":"&TEXT(MINUTE([2]المدخلات!$B$4+(5-1)*[2]المدخلات!$B$7/1440),"00")&"–"&(MOD(HOUR([2]المدخلات!$B$4+(5-1)*[2]المدخلات!$B$7/1440+[2]المدخلات!$B$5/1440)-1,12)+1)&":"&TEXT(MINUTE([2]المدخلات!$B$4+(5-1)*[2]المدخلات!$B$7/1440+[2]المدخلات!$B$5/1440),"00")&" م" -> 5:00–5:15 م | C17: 4 ضد 6 | D17: 8 ضد 11 | E17: 3 ضد 9 | G17: 16 ضد 18 | H17: 20 ضد 23 | I17: 15 ضد 21 | K17: 28 ضد 30 | L17: 32 ضد 35 | M17: 27 ضد 33 | O17: 38 ضد 48 | P17: 41 ضد 45
B18: =(MOD(HOUR([2]المدخلات!$B$4+(6-1)*[2]المدخلات!$B$7/1440)-1,12)+1)&":"&TEXT(MINUTE([2]المدخلات!$B$4+(6-1)*[2]المدخلات!$B$7/1440),"00")&"–"&(MOD(HOUR([2]المدخلات!$B$4+(6-1)*[2]المدخلات!$B$7/1440+[2]المدخلات!$B$5/1440)-1,12)+1)&":"&TEXT(MINUTE([2]المدخلات!$B$4+(6-1)*[2]المدخلات!$B$7/1440+[2]المدخلات!$B$5/1440),"00")&" م" -> 5:15–5:30 م | C18: 2 ضد 7 | D18: 10 ضد 12 | G18: 14 ضد 19 | H18: 22 ضد 24 | K18: 26 ضد 31 | L18: 34 ضد 36 | O18: 40 ضد 49 | P18: 39 ضد 43 | Q18: 37 ضد 42
B19: =(MOD(HOUR([2]المدخلات!$B$4+(7-1)*[2]المدخلات!$B$7/1440)-1,12)+1)&":"&TEXT(MINUTE([2]المدخلات!$B$4+(7-1)*[2]المدخلات!$B$7/1440),"00")&"–"&(MOD(HOUR([2]المدخلات!$B$4+(7-1)*[2]المدخلات!$B$7/1440+[2]المدخلات!$B$5/1440)-1,12)+1)&":"&TEXT(MINUTE([2]المدخلات!$B$4+(7-1)*[2]المدخلات!$B$7/1440+[2]المدخلات!$B$5/1440),"00")&" م" -> 5:30–5:45 م | C19: 5 ضد 11 | D19: 1 ضد 6 | E19: 8 ضد 9 | F19: 3 ضد 4 | G19: 17 ضد 23 | H19: 13 ضد 18 | I19: 20 ضد 21 | J19: 15 ضد 16 | K19: 29 ضد 35 | L19: 25 ضد 30 | M19: 32 ضد 33 | N19: 27 ضد 28 | O19: 44 ضد 46 | P19: 41 ضد 48 | Q19: 45 ضد 47
B20: =(MOD(HOUR([2]المدخلات!$B$4+(8-1)*[2]المدخلات!$B$7/1440)-1,12)+1)&":"&TEXT(MINUTE([2]المدخلات!$B$4+(8-1)*[2]المدخلات!$B$7/1440),"00")&"–"&(MOD(HOUR([2]المدخلات!$B$4+(8-1)*[2]المدخلات!$B$7/1440+[2]المدخلات!$B$5/1440)-1,12)+1)&":"&TEXT(MINUTE([2]المدخلات!$B$4+(8-1)*[2]المدخلات!$B$7/1440+[2]المدخلات!$B$5/1440),"00")&" م" -> 5:45–6:00 م | C20: 2 ضد 12 | G20: 14 ضد 24 | K20: 26 ضد 36 | O20: 39 ضد 42 | P20: 38 ضد 43
B21: =(MOD(HOUR([2]المدخلات!$B$4+(9-1)*[2]المدخلات!$B$7/1440)-1,12)+1)&":"&TEXT(MINUTE([2]المدخلات!$B$4+(9-1)*[2]المدخلات!$B$7/1440),"00")&"–"&(MOD(HOUR([2]المدخلات!$B$4+(9-1)*[2]المدخلات!$B$7/1440+[2]المدخلات!$B$5/1440)-1,12)+1)&":"&TEXT(MINUTE([2]المدخلات!$B$4+(9-1)*[2]المدخلات!$B$7/1440+[2]المدخلات!$B$5/1440),"00")&" م" -> 6:00–6:15 م | C21: 5 ضد 6 | D21: 4 ضد 10 | E21: 7 ضد 8 | F21: 1 ضد 9 | G21: 17 ضد 18 | H21: 16 ضد 22 | I21: 19 ضد 20 | J21: 13 ضد 21 | K21: 29 ضد 30 | L21: 28 ضد 34 | M21: 31 ضد 32 | N21: 25 ضد 33 | O21: 37 ضد 40 | P21: 41 ضد 46 | Q21: 47 ضد 48 | R21: 44 ضد 49
A22: المهرجان 3 | B22: =(MOD(HOUR([2]المدخلات!$B$4+(1-1)*[2]المدخلات!$B$7/1440)-1,12)+1)&":"&TEXT(MINUTE([2]المدخلات!$B$4+(1-1)*[2]المدخلات!$B$7/1440),"00")&"–"&(MOD(HOUR([2]المدخلات!$B$4+(1-1)*[2]المدخلات!$B$7/1440+[2]المدخلات!$B$5/1440)-1,12)+1)&":"&TEXT(MINUTE([2]المدخلات!$B$4+(1-1)*[2]المدخلات!$B$7/1440+[2]المدخلات!$B$5/1440),"00")&" م" -> 4:00–4:15 م | C22: 3 ضد 6 | D22: 2 ضد 9 | E22: 1 ضد 8 | G22: 15 ضد 18 | H22: 14 ضد 21 | I22: 13 ضد 20 | K22: 27 ضد 30 | L22: 26 ضد 33 | M22: 25 ضد 32 | O22: 43 ضد 48 | P22: 37 ضد 38 | Q22: 39 ضد 46 | R22: 41 ضد 47 | S22: =COUNTA(C22:R30) -> 98
B23: =(MOD(HOUR([2]المدخلات!$B$4+(2-1)*[2]المدخلات!$B$7/1440)-1,12)+1)&":"&TEXT(MINUTE([2]المدخلات!$B$4+(2-1)*[2]المدخلات!$B$7/1440),"00")&"–"&(MOD(HOUR([2]المدخلات!$B$4+(2-1)*[2]المدخلات!$B$7/1440+[2]المدخلات!$B$5/1440)-1,12)+1)&":"&TEXT(MINUTE([2]المدخلات!$B$4+(2-1)*[2]المدخلات!$B$7/1440+[2]المدخلات!$B$5/1440),"00")&" م" -> 4:15–4:30 م | C23: 5 ضد 7 | D23: 10 ضد 11 | G23: 17 ضد 19 | H23: 22 ضد 23 | K23: 29 ضد 31 | L23: 34 ضد 35 | O23: 44 ضد 45 | P23: 42 ضد 49
B24: =(MOD(HOUR([2]المدخلات!$B$4+(3-1)*[2]المدخلات!$B$7/1440)-1,12)+1)&":"&TEXT(MINUTE([2]المدخلات!$B$4+(3-1)*[2]المدخلات!$B$7/1440),"00")&"–"&(MOD(HOUR([2]المدخلات!$B$4+(3-1)*[2]المدخلات!$B$7/1440+[2]المدخلات!$B$5/1440)-1,12)+1)&":"&TEXT(MINUTE([2]المدخلات!$B$4+(3-1)*[2]المدخلات!$B$7/1440+[2]المدخلات!$B$5/1440),"00")&" م" -> 4:30–4:45 م | C24: 1 ضد 4 | D24: 3 ضد 12 | E24: 6 ضد 9 | G24: 13 ضد 16 | H24: 15 ضد 24 | I24: 18 ضد 21 | K24: 25 ضد 28 | L24: 27 ضد 36 | M24: 30 ضد 33 | O24: 46 ضد 48 | P24: 40 ضد 43
B25: =(MOD(HOUR([2]المدخلات!$B$4+(4-1)*[2]المدخلات!$B$7/1440)-1,12)+1)&":"&TEXT(MINUTE([2]المدخلات!$B$4+(4-1)*[2]المدخلات!$B$7/1440),"00")&"–"&(MOD(HOUR([2]المدخلات!$B$4+(4-1)*[2]المدخلات!$B$7/1440+[2]المدخلات!$B$5/1440)-1,12)+1)&":"&TEXT(MINUTE([2]المدخلات!$B$4+(4-1)*[2]المدخلات!$B$7/1440+[2]المدخلات!$B$5/1440),"00")&" م" -> 4:45–5:00 م | C25: 2 ضد 5 | D25: 7 ضد 11 | E25: 8 ضد 10 | G25: 14 ضد 17 | H25: 19 ضد 23 | I25: 20 ضد 22 | K25: 26 ضد 29 | L25: 31 ضد 35 | M25: 32 ضد 34 | O25: 37 ضد 39 | P25: 38 ضد 42 | Q25: 41 ضد 44 | R25: 47 ضد 49
B26: =(MOD(HOUR([2]المدخلات!$B$4+(5-1)*[2]المدخلات!$B$7/1440)-1,12)+1)&":"&TEXT(MINUTE([2]المدخلات!$B$4+(5-1)*[2]المدخلات!$B$7/1440),"00")&"–"&(MOD(HOUR([2]المدخلات!$B$4+(5-1)*[2]المدخلات!$B$7/1440+[2]المدخلات!$B$5/1440)-1,12)+1)&":"&TEXT(MINUTE([2]المدخلات!$B$4+(5-1)*[2]المدخلات!$B$7/1440+[2]المدخلات!$B$5/1440),"00")&" م" -> 5:00–5:15 م | C26: 4 ضد 9 | D26: 1 ضد 12 | G26: 16 ضد 21 | H26: 13 ضد 24 | K26: 28 ضد 33 | L26: 25 ضد 36 | O26: 40 ضد 48 | P26: 45 ضد 46
B27: =(MOD(HOUR([2]المدخلات!$B$4+(6-1)*[2]المدخلات!$B$7/1440)-1,12)+1)&":"&TEXT(MINUTE([2]المدخلات!$B$4+(6-1)*[2]المدخلات!$B$7/1440),"00")&"–"&(MOD(HOUR([2]المدخلات!$B$4+(6-1)*[2]المدخلات!$B$7/1440+[2]المدخلات!$B$5/1440)-1,12)+1)&":"&TEXT(MINUTE([2]المدخلات!$B$4+(6-1)*[2]المدخلات!$B$7/1440+[2]المدخلات!$B$5/1440),"00")&" م" -> 5:15–5:30 م | C27: 5 ضد 8 | D27: 3 ضد 7 | E27: 6 ضد 10 | G27: 17 ضد 20 | H27: 15 ضد 19 | I27: 18 ضد 22 | K27: 29 ضد 32 | L27: 27 ضد 31 | M27: 30 ضد 34 | O27: 43 ضد 44 | P27: 41 ضد 42 | Q27: 37 ضد 47 | R27: 39 ضد 49
B28: =(MOD(HOUR([2]المدخلات!$B$4+(7-1)*[2]المدخلات!$B$7/1440)-1,12)+1)&":"&TEXT(MINUTE([2]المدخلات!$B$4+(7-1)*[2]المدخلات!$B$7/1440),"00")&"–"&(MOD(HOUR([2]المدخلات!$B$4+(7-1)*[2]المدخلات!$B$7/1440+[2]المدخلات!$B$5/1440)-1,12)+1)&":"&TEXT(MINUTE([2]المدخلات!$B$4+(7-1)*[2]المدخلات!$B$7/1440+[2]المدخلات!$B$5/1440),"00")&" م" -> 5:30–5:45 م | C28: 4 ضد 12 | D28: 2 ضد 11 | E28: 1 ضد 9 | G28: 16 ضد 24 | H28: 14 ضد 23 | I28: 13 ضد 21 | K28: 28 ضد 36 | L28: 26 ضد 35 | M28: 25 ضد 33 | O28: 45 ضد 48 | P28: 38 ضد 40
B29: =(MOD(HOUR([2]المدخلات!$B$4+(8-1)*[2]المدخلات!$B$7/1440)-1,12)+1)&":"&TEXT(MINUTE([2]المدخلات!$B$4+(8-1)*[2]المدخلات!$B$7/1440),"00")&"–"&(MOD(HOUR([2]المدخلات!$B$4+(8-1)*[2]المدخلات!$B$7/1440+[2]المدخلات!$B$5/1440)-1,12)+1)&":"&TEXT(MINUTE([2]المدخلات!$B$4+(8-1)*[2]المدخلات!$B$7/1440+[2]المدخلات!$B$5/1440),"00")&" م" -> 5:45–6:00 م | C29: 3 ضد 10 | G29: 15 ضد 22 | K29: 27 ضد 34 | O29: 37 ضد 46 | P29: 41 ضد 49 | Q29: 39 ضد 47
B30: =(MOD(HOUR([2]المدخلات!$B$4+(9-1)*[2]المدخلات!$B$7/1440)-1,12)+1)&":"&TEXT(MINUTE([2]المدخلات!$B$4+(9-1)*[2]المدخلات!$B$7/1440),"00")&"–"&(MOD(HOUR([2]المدخلات!$B$4+(9-1)*[2]المدخلات!$B$7/1440+[2]المدخلات!$B$5/1440)-1,12)+1)&":"&TEXT(MINUTE([2]المدخلات!$B$4+(9-1)*[2]المدخلات!$B$7/1440+[2]المدخلات!$B$5/1440),"00")&" م" -> 6:00–6:15 م | C30: 6 ضد 11 | D30: 2 ضد 8 | E30: 5 ضد 12 | F30: 4 ضد 7 | G30: 18 ضد 23 | H30: 14 ضد 20 | I30: 17 ضد 24 | J30: 16 ضد 19 | K30: 30 ضد 35 | L30: 26 ضد 32 | M30: 29 ضد 36 | N30: 28 ضد 31 | O30: 38 ضد 44 | P30: 40 ضد 45 | Q30: 42 ضد 43
A31: المهرجان 4 | B31: =(MOD(HOUR([2]المدخلات!$B$4+(1-1)*[2]المدخلات!$B$7/1440)-1,12)+1)&":"&TEXT(MINUTE([2]المدخلات!$B$4+(1-1)*[2]المدخلات!$B$7/1440),"00")&"–"&(MOD(HOUR([2]المدخلات!$B$4+(1-1)*[2]المدخلات!$B$7/1440+[2]المدخلات!$B$5/1440)-1,12)+1)&":"&TEXT(MINUTE([2]المدخلات!$B$4+(1-1)*[2]المدخلات!$B$7/1440+[2]المدخلات!$B$5/1440),"00")&" م" -> 4:00–4:15 م | C31: 9 ضد 11 | D31: 5 ضد 10 | E31: 3 ضد 12 | F31: 1 ضد 7 | G31: 21 ضد 23 | H31: 17 ضد 22 | I31: 15 ضد 24 | J31: 13 ضد 19 | K31: 33 ضد 35 | L31: 29 ضد 34 | M31: 27 ضد 36 | N31: 25 ضد 31 | O31: 38 ضد 39 | P31: 43 ضد 46 | Q31: 47 ضد 48 | R31: 40 ضد 42 | S31: =COUNTA(C31:R39) -> 98
B32: =(MOD(HOUR([2]المدخلات!$B$4+(2-1)*[2]المدخلات!$B$7/1440)-1,12)+1)&":"&TEXT(MINUTE([2]المدخلات!$B$4+(2-1)*[2]المدخلات!$B$7/1440),"00")&"–"&(MOD(HOUR([2]المدخلات!$B$4+(2-1)*[2]المدخلات!$B$7/1440+[2]المدخلات!$B$5/1440)-1,12)+1)&":"&TEXT(MINUTE([2]المدخلات!$B$4+(2-1)*[2]المدخلات!$B$7/1440+[2]المدخلات!$B$5/1440),"00")&" م" -> 4:15–4:30 م | C32: 6 ضد 8 | G32: 18 ضد 20 | K32: 30 ضد 32 | O32: 37 ضد 41 | P32: 44 ضد 45
B33: =(MOD(HOUR([2]المدخلات!$B$4+(3-1)*[2]المدخلات!$B$7/1440)-1,12)+1)&":"&TEXT(MINUTE([2]المدخلات!$B$4+(3-1)*[2]المدخلات!$B$7/1440),"00")&"–"&(MOD(HOUR([2]المدخلات!$B$4+(3-1)*[2]المدخلات!$B$7/1440+[2]المدخلات!$B$5/1440)-1,12)+1)&":"&TEXT(MINUTE([2]المدخلات!$B$4+(3-1)*[2]المدخلات!$B$7/1440+[2]المدخلات!$B$5/1440),"00")&" م" -> 4:30–4:45 م | C33: 2 ضد 10 | D33: 4 ضد 11 | E33: 5 ضد 9 | G33: 14 ضد 22 | H33: 16 ضد 23 | I33: 17 ضد 21 | K33: 26 ضد 34 | L33: 28 ضد 35 | M33: 29 ضد 33 | O33: 40 ضد 43 | P33: 42 ضد 49
B34: =(MOD(HOUR([2]المدخلات!$B$4+(4-1)*[2]المدخلات!$B$7/1440)-1,12)+1)&":"&TEXT(MINUTE([2]المدخلات!$B$4+(4-1)*[2]المدخلات!$B$7/1440),"00")&"–"&(MOD(HOUR([2]المدخلات!$B$4+(4-1)*[2]المدخلات!$B$7/1440+[2]المدخلات!$B$5/1440)-1,12)+1)&":"&TEXT(MINUTE([2]المدخلات!$B$4+(4-1)*[2]المدخلات!$B$7/1440+[2]المدخلات!$B$5/1440),"00")&" م" -> 4:45–5:00 م | C34: 1 ضد 8 | D34: 3 ضد 6 | E34: 7 ضد 12 | G34: 13 ضد 20 | H34: 15 ضد 18 | I34: 19 ضد 24 | K34: 25 ضد 32 | L34: 27 ضد 30 | M34: 31 ضد 36 | O34: 41 ضد 47 | P34: 44 ضد 46 | Q34: 39 ضد 48 | R34: 38 ضد 45
B35: =(MOD(HOUR([2]المدخلات!$B$4+(5-1)*[2]المدخلات!$B$7/1440)-1,12)+1)&":"&TEXT(MINUTE([2]المدخلات!$B$4+(5-1)*[2]المدخلات!$B$7/1440),"00")&"–"&(MOD(HOUR([2]المدخلات!$B$4+(5-1)*[2]المدخلات!$B$7/1440+[2]المدخلات!$B$5/1440)-1,12)+1)&":"&TEXT(MINUTE([2]المدخلات!$B$4+(5-1)*[2]المدخلات!$B$7/1440+[2]المدخلات!$B$5/1440),"00")&" م" -> 5:00–5:15 م | C35: 2 ضد 5 | D35: 4 ضد 9 | G35: 14 ضد 17 | H35: 16 ضد 21 | K35: 26 ضد 29 | L35: 28 ضد 33 | O35: 37 ضد 43 | P35: 40 ضد 49
B36: =(MOD(HOUR([2]المدخلات!$B$4+(6-1)*[2]المدخلات!$B$7/1440)-1,12)+1)&":"&TEXT(MINUTE([2]المدخلات!$B$4+(6-1)*[2]المدخلات!$B$7/1440),"00")&"–"&(MOD(HOUR([2]المدخلات!$B$4+(6-1)*[2]المدخلات!$B$7/1440+[2]المدخلات!$B$5/1440)-1,12)+1)&":"&TEXT(MINUTE([2]المدخلات!$B$4+(6-1)*[2]المدخلات!$B$7/1440+[2]المدخلات!$B$5/1440),"00")&" م" -> 5:15–5:30 م | C36: 7 ضد 10 | D36: 3 ضد 11 | E36: 1 ضد 6 | G36: 19 ضد 22 | H36: 15 ضد 23 | I36: 13 ضد 18 | K36: 31 ضد 34 | L36: 27 ضد 35 | M36: 25 ضد 30 | O36: 45 ضد 47 | P36: 38 ضد 42 | Q36: 39 ضد 46 | R36: 41 ضد 44
B37: =(MOD(HOUR([2]المدخلات!$B$4+(7-1)*[2]المدخلات!$B$7/1440)-1,12)+1)&":"&TEXT(MINUTE([2]المدخلات!$B$4+(7-1)*[2]المدخلات!$B$7/1440),"00")&"–"&(MOD(HOUR([2]المدخلات!$B$4+(7-1)*[2]المدخلات!$B$7/1440+[2]المدخلات!$B$5/1440)-1,12)+1)&":"&TEXT(MINUTE([2]المدخلات!$B$4+(7-1)*[2]المدخلات!$B$7/1440+[2]المدخلات!$B$5/1440),"00")&" م" -> 5:30–5:45 م | C37: 8 ضد 12 | D37: 2 ضد 4 | G37: 20 ضد 24 | H37: 14 ضد 16 | K37: 32 ضد 36 | L37: 26 ضد 28 | O37: 37 ضد 48 | P37: 43 ضد 49
B38: =(MOD(HOUR([2]المدخلات!$B$4+(8-1)*[2]المدخلات!$B$7/1440)-1,12)+1)&":"&TEXT(MINUTE([2]المدخلات!$B$4+(8-1)*[2]المدخلات!$B$7/1440),"00")&"–"&(MOD(HOUR([2]المدخلات!$B$4+(8-1)*[2]المدخلات!$B$7/1440+[2]المدخلات!$B$5/1440)-1,12)+1)&":"&TEXT(MINUTE([2]المدخلات!$B$4+(8-1)*[2]المدخلات!$B$7/1440+[2]المدخلات!$B$5/1440),"00")&" م" -> 5:45–6:00 م | C38: 7 ضد 9 | D38: 3 ضد 5 | E38: 6 ضد 10 | G38: 19 ضد 21 | H38: 15 ضد 17 | I38: 18 ضد 22 | K38: 31 ضد 33 | L38: 27 ضد 29 | M38: 30 ضد 34 | O38: 41 ضد 42 | P38: 39 ضد 47 | Q38: 40 ضد 44
B39: =(MOD(HOUR([2]المدخلات!$B$4+(9-1)*[2]المدخلات!$B$7/1440)-1,12)+1)&":"&TEXT(MINUTE([2]المدخلات!$B$4+(9-1)*[2]المدخلات!$B$7/1440),"00")&"–"&(MOD(HOUR([2]المدخلات!$B$4+(9-1)*[2]المدخلات!$B$7/1440+[2]المدخلات!$B$5/1440)-1,12)+1)&":"&TEXT(MINUTE([2]المدخلات!$B$4+(9-1)*[2]المدخلات!$B$7/1440+[2]المدخلات!$B$5/1440),"00")&" م" -> 6:00–6:15 م | C39: 1 ضد 2 | D39: 4 ضد 8 | E39: 11 ضد 12 | G39: 13 ضد 14 | H39: 16 ضد 20 | I39: 23 ضد 24 | K39: 25 ضد 26 | L39: 28 ضد 32 | M39: 35 ضد 36 | O39: 37 ضد 45 | P39: 38 ضد 46 | Q39: 48 ضد 49
A40: المهرجان 5 | B40: =(MOD(HOUR([2]المدخلات!$B$4+(1-1)*[2]المدخلات!$B$7/1440)-1,12)+1)&":"&TEXT(MINUTE([2]المدخلات!$B$4+(1-1)*[2]المدخلات!$B$7/1440),"00")&"–"&(MOD(HOUR([2]المدخلات!$B$4+(1-1)*[2]المدخلات!$B$7/1440+[2]المدخلات!$B$5/1440)-1,12)+1)&":"&TEXT(MINUTE([2]المدخلات!$B$4+(1-1)*[2]المدخلات!$B$7/1440+[2]المدخلات!$B$5/1440),"00")&" م" -> 4:00–4:15 م | C40: 5 ضد 6 | D40: 2 ضد 9 | E40: 4 ضد 12 | G40: 17 ضد 18 | H40: 14 ضد 21 | I40: 16 ضد 24 | K40: 29 ضد 30 | L40: 26 ضد 33 | M40: 28 ضد 36 | O40: 38 ضد 40 | P40: 44 ضد 49 | Q40: 42 ضد 45 | S40: =COUNTA(C40:R48) -> 98
...

Sheet Sheet1
B2: تحت 14 | C2: مجموعة نجران | D2: 1 | E2: نجران | F2: 5
B3: تحت 5 | C3: مجموعة طبرجل | D3: 1 | E3: طبرجل | F3: 5
B4: تحت 7 | C4: مجموعة طبرجل | D4: 1 | E4: طبرجل | F4: 5
B5: تحت 9 | C5: مجموعة الخرج | D5: 1 | E5: الخرج | F5: 5
B6: تحت 12 | C6: مجموعة طبرجل | D6: 1 | E6: طبرجل | F6: 5
B7: تحت 14 | C7: مجموعة طبرجل | D7: 1 | E7: طبرجل | F7: 5
B8: تحت 7 | C8: مجموعة شرورة | D8: 1 | E8: شرورة | F8: 5
B9: تحت 9 | C9: مجموعة شرورة | D9: 1 | E9: شرورة | F9: 5
B10: تحت 9 | C10: مجموعة الدوادمي | D10: 1 | E10: الدوادمي | F10: 5
B11: تحت 11 | C11: مجموعة القريات | D11: 1 | E11: القريات | F11: 5
B12: تحت 12 | C12: مجموعة القريات | D12: 1 | E12: القريات | F12: 5
B13: تحت 13 | C13: مجموعة القريات | D13: 1 | E13: القريات | F13: 5
... B185: تحت 12 | C185: مجموعة جدة | D185: 1 | E185: جدة | F185: 56

Sheet المدخلات
A1: صفحة المدخلات – بطولات تحت 11 / تحت 12
A3: البند | B3: القيمة | C3: ملاحظة | E3: الفترة | F3: التوقيت | H3: رقم المجموعة | I3: عدد الفرق
A4: وقت بداية اليوم | B4: 0.66666667 | C4: مشترك لكل البطولات | E4: =IF(1<=$B$8,1,"") -> 1 | F4: =IF(1>$B$8,"",MOD(HOUR($B$4+0*$B$7/1440)-1,12)+1&":"&TEXT(MINUTE($B$4+0*$B$7/1440),"00")&"–"&MOD(HOUR($B$4+0*$B$7/1440+$B$5/1440)-1,12)+1&":"&TEXT(MINUTE($B$4+0*$B$7/1440+$B$5/1440),"00")&IF(HOUR($B$4+0*$B$7/1440)<12," ص"," م")) -> 4:00–5:10 م | H4: 1 | I4: 5
A5: مدة المباراة (دقيقة) | B5: 70 | C5: زمن المباراة الفعلي | E5: =IF(2<=$B$8,2,"") -> 2 | F5: =IF(2>$B$8,"",MOD(HOUR($B$4+1*$B$7/1440)-1,12)+1&":"&TEXT(MINUTE($B$4+1*$B$7/1440),"00")&"–"&MOD(HOUR($B$4+1*$B$7/1440+$B$5/1440)-1,12)+1&":"&TEXT(MINUTE($B$4+1*$B$7/1440+$B$5/1440),"00")&IF(HOUR($B$4+1*$B$7/1440)<12," ص"," م")) -> 5:20–6:30 م | H5: 2 | I5: 5
A6: الفاصل/ترتيب الملعب (دقيقة) | B6: 10 | C6: راحة وترتيب الملعب بين المباريات | E6: =IF(3<=$B$8,3,"") -> 3 | F6: =IF(3>$B$8,"",MOD(HOUR($B$4+2*$B$7/1440)-1,12)+1&":"&TEXT(MINUTE($B$4+2*$B$7/1440),"00")&"–"&MOD(HOUR($B$4+2*$B$7/1440+$B$5/1440)-1,12)+1&":"&TEXT(MINUTE($B$4+2*$B$7/1440+$B$5/1440),"00")&IF(HOUR($B$4+2*$B$7/1440)<12," ص"," م")) -> 6:40–7:50 م | H6: 3 | I6: 5
A7: طول الفترة الكاملة (دقيقة) | B7: =B5+B6 -> 80 | C7: محسوبة = مدة + فاصل | E7: =IF(4<=$B$8,4,"") | F7: =IF(4>$B$8,"",MOD(HOUR($B$4+3*$B$7/1440)-1,12)+1&":"&TEXT(MINUTE($B$4+3*$B$7/1440),"00")&"–"&MOD(HOUR($B$4+3*$B$7/1440+$B$5/1440)-1,12)+1&":"&TEXT(MINUTE($B$4+3*$B$7/1440+$B$5/1440),"00")&IF(HOUR($B$4+3*$B$7/1440)<12," ص"," م")) | H7: 4 | I7: 6
A8: أقصى عدد فترات في اليوم | B8: 3 | C8: يحدد عدد الملاعب المطلوبة | H8: 5 | I8: 8
A9: عدد ملاعب 7×7 داخل الملعب القانوني | B9: 2 | C9: يُستخدم لحساب عدد الملاعب القانونية في الملخص | H9: 6 | I9: 8
A10: عدد المباريات المستهدف للفريق | B10: 20 | C10: يُختار عدد الأدوار الأقرب لهذا الهدف (يُسمح بأقل أو بتجاوز بسيط) | H10: 7 | I10: 8
A11: الحد الأدنى لعدد فرق المجموعة | B11: 5 | C11: لا توجد مجموعة أقل من هذا العدد | H11: 8 | I11: 8
A12: أقصى حجم للمجموعة | B12: 22 | C12: لا تزيد المجموعة عن هذا العدد (يحدد عدد المجموعات) | H12: 9 | I12: 8
A13: سقف أيام البطولة | B13: 23 | C13: يشمل أيام الدوري والإقصاء معاً | H13: 10 | I13: 9
A14: أقل عدد مباريات للفريق | B14: 16 | C14: لا تقل مباريات أي فريق عن هذا العدد | H14: 11 | I14: 9
A15: جدول مراحل الإقصاء حسب عدد المجموعات | H15: 12 | I15: 9
A16: من | B16: إلى | C16: نظام الإقصاء | H16: 13 | I16: 9
A17: 1 | B17: 1 | C17: — (دوري فقط، البطل أول المجموعة) | H17: 14 | I17: 10
A18: 2 | B18: 2 | C18: نهائي مباشر | H18: 15 | I18: 10
A19: 3 | B19: 4 | C19: نصف نهائي ثم نهائي | H19: 16 | I19: 10
A20: 5 | B20: 8 | C20: ربع نهائي ثم نصف نهائي ثم نهائي | H20: 17 | I20: 10
H21: 18 | I21: 10
H22: 19 | I22: 10
H23: 20 | I23: 10
H24: 21 | I24: 10
H25: 22 | I25: 11
H26: 23 | I26: 11
H27: 24 | I27: 11
H28: 25 | I28: 11
H29: 26 | I29: 12
H30: 27 | I30: 12
H31: 28 | I31: 12
H32: 29 | I32: 13
... H59: 56 | I59: 56

Sheet الملخص
A1: ملخص بطولات تحت 11 / تحت 12 — الأعداد المطلوبة
A3: عدد الفرق | B3: عدد المجموعات | C3: توزيع الفرق في المجموعات | D3: عدد الأدوار | E3: مباريات كل فريق (مخططة) | F3: نظام الإقصاء | G3: أيام الدوري | H3: أيام الإقصاء | I3: إجمالي الأيام (دوري + إقصاء) | J3: وقت البداية | K3: وقت النهاية | L3: عدد الملاعب (7 ضد 7) | M3: عدد الملاعب القانونية | N3: تحقق: أصغر مجموعة ≥ الحد | O3: تحقق: الأيام ≤ السقف | P3: تحقق: أقل مباريات ≥ الحد | Q3: عدد مباريات البطولة الواحدة | R3: عدد المجموعات بهذا العدد
A4: 5 | B4: {=ROUND(SUMPRODUCT(1/COUNTIF('بيانات الفرق'!$B$3:$B$7,'بيانات الفرق'!$B$3:$B$7)),0)} -> 1 | C4: {=_xlfn.TEXTJOIN(" + ",TRUE,COUNTIF('بيانات الفرق'!$B$3:$B$7,"المجموعة "&_xlfn.SEQUENCE($B4)))} -> 5 | D4: {=_xlfn.LET(_xlpm.c,COUNTIF('بيانات الفرق'!$B$3:$B$7,"المجموعة "&_xlfn.SEQUENCE($B4)),_xlpm.mm,AVERAGEIFS('بيانات الفرق'!$C$3:$C$7,'بيانات الفرق'!$B$3:$B$7,"المجموعة "&_xlfn.SEQUENCE($B4)),_xlfn.TEXTJOIN(" + ",TRUE,_xlpm.mm/(_xlpm.c-1)))} -> 4 | E4: {=_xlfn.LET(_xlpm.c,COUNTIF('بيانات الفرق'!$B$3:$B$7,"المجموعة "&_xlfn.SEQUENCE($B4)),_xlpm.mm,AVERAGEIFS('بيانات الفرق'!$C$3:$C$7,'بيانات الفرق'!$B$3:$B$7,"المجموعة "&_xlfn.SEQUENCE($B4)),_xlfn.TEXTJOIN(" + ",TRUE,_xlpm.mm))} -> 16 | F4: =IF($B4>MAX(المدخلات!$B$17:$B$20),"—",LOOKUP($B4,المدخلات!$A$17:$A$20,المدخلات!$C$17:$C$20)) -> — (دوري فقط، البطل أول المجموعة) | G4: =_xlfn.MAXIFS('5 فرق'!$A$4:$A$1999,'5 فرق'!$D$4:$D$1999,"* ضد *",'5 فرق'!$D$4:$D$1999,"<>*فائز*",'5 فرق'!$D$4:$D$1999,"<>*أول المجموعة*",'5 فرق'!$D$4:$D$1999,"<>*أفضل ثانٍ*") -> 20 | H4: =$I4-$G4 -> 0 | I4: =_xlfn.MAXIFS('5 فرق'!$A$4:$A$1999,'5 فرق'!$D$4:$D$1999,"* ضد *") -> 20 | J4: =MOD(HOUR(المدخلات!$B$4)-1,12)+1&":"&TEXT(MINUTE(المدخلات!$B$4),"00")&IF(HOUR(المدخلات!$B$4)<12," ص"," م") -> 4:00 م | K4: {=_xlfn.LET(_xlpm.p,SUMPRODUCT(MAX((COUNTIF('5 فرق'!$B$4:$B$1999,المدخلات!$F$4:$F$7)>0)*(المدخلات!$F$4:$F$7<>"")*ROW(المدخلات!$F$4:$F$7)))-3,_xlpm.t,INDEX(المدخلات!$F$4:$F$7,_xlpm.p),TRIM(MID(_xlpm.t,FIND("–",_xlpm.t)+1,20)))} -> 7:50 م | L4: =_xlfn.MAXIFS('5 فرق'!$C$4:$C$1999,'5 فرق'!$D$4:$D$1999,"* ضد *") -> 1 | M4: =ROUNDUP($L4/المدخلات!$B$9,0) -> 1 | N4: {=IF(MIN(COUNTIF('بيانات الفرق'!$B$3:$B$7,"المجموعة "&_xlfn.SEQUENCE($B4)))>=المدخلات!$B$11,"✔ "&MIN(COUNTIF('بيانات الفرق'!$B$3:$B$7,"المجموعة "&_xlfn.SEQUENCE($B4))),"✘ "&MIN(COUNTIF('بيانات الفرق'!$B$3:$B$7,"المجموعة "&_xlfn.SEQUENCE($B4))))} -> ✔ 5 | O4: =IF($I4<=المدخلات!$B$13,"✔ "&$I4," ⚠ "&$I4&" يوماً — تجاوز السقف ("&المدخلات!$B$13&") لضمان "&المدخلات!$B$14&" مباراة") -> ✔ 20 | P4: {=_xlfn.LET(_xlpm.c,COUNTIF('بيانات الفرق'!$B$3:$B$7,"المجموعة "&_xlfn.SEQUENCE($B4)),_xlpm.mm,AVERAGEIFS('بيانات الفرق'!$C$3:$C$7,'بيانات الفرق'!$B$3:$B$7,"المجموعة "&_xlfn.SEQUENCE($B4)),IF(MIN(_xlpm.mm)>=المدخلات!$B$14,"✔ "&MIN(_xlpm.mm)," ✘ "&MIN(_xlpm.mm)&" / "&المدخلات!$B$14))} -> ✔ 16 | Q4: =COUNTIF('5 فرق'!$D$4:$D$1999,"* ضد *") -> 40 | R4: =COUNTIF(المدخلات!$I$4:$I$200,$A4) -> 3
A5: 6 | B5: {=ROUND(SUMPRODUCT(1/COUNTIF('بيانات الفرق'!$G$3:$G$8,'بيانات الفرق'!$G$3:$G$8)),0)} -> 1 | C5: {=_xlfn.TEXTJOIN(" + ",TRUE,COUNTIF('بيانات الفرق'!$G$3:$G$8,"المجموعة "&_xlfn.SEQUENCE($B5)))} -> 6 | D5: {=_xlfn.LET(_xlpm.c,COUNTIF('بيانات الفرق'!$G$3:$G$8,"المجموعة "&_xlfn.SEQUENCE($B5)),_xlpm.mm,AVERAGEIFS('بيانات الفرق'!$H$3:$H$8,'بيانات الفرق'!$G$3:$G$8,"المجموعة "&_xlfn.SEQUENCE($B5)),_xlfn.TEXTJOIN(" + ",TRUE,_xlpm.mm/(_xlpm.c-1)))} -> 4 | E5: {=_xlfn.LET(_xlpm.c,COUNTIF('بيانات الفرق'!$G$3:$G$8,"المجموعة "&_xlfn.SEQUENCE($B5)),_xlpm.mm,AVERAGEIFS('بيانات الفرق'!$H$3:$H$8,'بيانات الفرق'!$G$3:$G$8,"المجموعة "&_xlfn.SEQUENCE($B5)),_xlfn.TEXTJOIN(" + ",TRUE,_xlpm.mm))} -> 20 | F5: =IF($B5>MAX(المدخلات!$B$17:$B$20),"—",LOOKUP($B5,المدخلات!$A$17:$A$20,المدخلات!$C$17:$C$20)) -> — (دوري فقط، البطل أول المجموعة) | G5: =_xlfn.MAXIFS('6 فرق'!$A$4:$A$1999,'6 فرق'!$D$4:$D$1999,"* ضد *",'6 فرق'!$D$4:$D$1999,"<>*فائز*",'6 فرق'!$D$4:$D$1999,"<>*أول المجموعة*",'6 فرق'!$D$4:$D$1999,"<>*أفضل ثانٍ*") -> 20 | H5: =$I5-$G5 -> 0 | I5: =_xlfn.MAXIFS('6 فرق'!$A$4:$A$1999,'6 فرق'!$D$4:$D$1999,"* ضد *") -> 20 | J5: =MOD(HOUR(المدخلات!$B$4)-1,12)+1&":"&TEXT(MINUTE(المدخلات!$B$4),"00")&IF(HOUR(المدخلات!$B$4)<12," ص"," م") -> 4:00 م | K5: {=_xlfn.LET(_xlpm.p,SUMPRODUCT(MAX((COUNTIF('6 فرق'!$B$4:$B$1999,المدخلات!$F$4:$F$7)>0)*(المدخلات!$F$4:$F$7<>"")*ROW(المدخلات!$F$4:$F$7)))-3,_xlpm.t,INDEX(المدخلات!$F$4:$F$7,_xlpm.p),TRIM(MID(_xlpm.t,FIND("–",_xlpm.t)+1,20)))} -> 7:50 م | L5: =_xlfn.MAXIFS('6 فرق'!$C$4:$C$1999,'6 فرق'!$D$4:$D$1999,"* ضد *") -> 1 | M5: =ROUNDUP($L5/المدخلات!$B$9,0) -> 1 | N5: {=IF(MIN(COUNTIF('بيانات الفرق'!$G$3:$G$8,"المجموعة "&_xlfn.SEQUENCE($B5)))>=المدخلات!$B$11,"✔ "&MIN(COUNTIF('بيانات الفرق'!$G$3:$G$8,"المجموعة "&_xlfn.SEQUENCE($B5))),"✘ "&MIN(COUNTIF('بيانات الفرق'!$G$3:$G$8,"المجموعة "&_xlfn.SEQUENCE($B5))))} -> ✔ 6 | O5: =IF($I5<=المدخلات!$B$13,"✔ "&$I5," ⚠ "&$I5&" يوماً — تجاوز السقف ("&المدخلات!$B$13&") لضمان "&المدخلات!$B$14&" مباراة") -> ✔ 20 | P5: {=_xlfn.LET(_xlpm.c,COUNTIF('بيانات الفرق'!$G$3:$G$8,"المجموعة "&_xlfn.SEQUENCE($B5)),_xlpm.mm,AVERAGEIFS('بيانات الفرق'!$H$3:$H$8,'بيانات الفرق'!$G$3:$G$8,"المجموعة "&_xlfn.SEQUENCE($B5)),IF(MIN(_xlpm.mm)>=المدخلات!$B$14,"✔ "&MIN(_xlpm.mm)," ✘ "&MIN(_xlpm.mm)&" / "&المدخلات!$B$14))} -> ✔ 20 | Q5: =COUNTIF('6 فرق'!$D$4:$D$1999,"* ضد *") -> 60 | R5: =COUNTIF(المدخلات!$I$4:$I$200,$A5) -> 1
A6: 8 | B6: {=ROUND(SUMPRODUCT(1/COUNTIF('بيانات الفرق'!$L$3:$L$10,'بيانات الفرق'!$L$3:$L$10)),0)} -> 1 | C6: {=_xlfn.TEXTJOIN(" + ",TRUE,COUNTIF('بيانات الفرق'!$L$3:$L$10,"المجموعة "&_xlfn.SEQUENCE($B6)))} -> 8 | D6: {=_xlfn.LET(_xlpm.c,COUNTIF('بيانات الفرق'!$L$3:$L$10,"المجموعة "&_xlfn.SEQUENCE($B6)),_xlpm.mm,AVERAGEIFS('بيانات الفرق'!$M$3:$M$10,'بيانات الفرق'!$L$3:$L$10,"المجموعة "&_xlfn.SEQUENCE($B6)),_xlfn.TEXTJOIN(" + ",TRUE,_xlpm.mm/(_xlpm.c-1)))} -> 3 | E6: {=_xlfn.LET(_xlpm.c,COUNTIF('بيانات الفرق'!$L$3:$L$10,"المجموعة "&_xlfn.SEQUENCE($B6)),_xlpm.mm,AVERAGEIFS('بيانات الفرق'!$M$3:$M$10,'بيانات الفرق'!$L$3:$L$10,"المجموعة "&_xlfn.SEQUENCE($B6)),_xlfn.TEXTJOIN(" + ",TRUE,_xlpm.mm))} -> 21 | F6: =IF($B6>MAX(المدخلات!$B$17:$B$20),"—",LOOKUP($B6,المدخلات!$A$17:$A$20,المدخلات!$C$17:$C$20)) -> — (دوري فقط، البطل أول المجموعة) | G6: =_xlfn.MAXIFS('8 فرق'!$A$4:$A$1999,'8 فرق'!$D$4:$D$1999,"* ضد *",'8 فرق'!$D$4:$D$1999,"<>*فائز*",'8 فرق'!$D$4:$D$1999,"<>*أول المجموعة*",'8 فرق'!$D$4:$D$1999,"<>*أفضل ثانٍ*") -> 21 | H6: =$I6-$G6 -> 0 | I6: =_xlfn.MAXIFS('8 فرق'!$A$4:$A$1999,'8 فرق'!$D$4:$D$1999,"* ضد *") -> 21 | J6: =MOD(HOUR(المدخلات!$B$4)-1,12)+1&":"&TEXT(MINUTE(المدخلات!$B$4),"00")&IF(HOUR(المدخلات!$B$4)<12," ص"," م") -> 4:00 م | K6: {=_xlfn.LET(_xlpm.p,SUMPRODUCT(MAX((COUNTIF('8 فرق'!$B$4:$B$1999,المدخلات!$F$4:$F$7)>0)*(المدخلات!$F$4:$F$7<>"")*ROW(المدخلات!$F$4:$F$7)))-3,_xlpm.t,INDEX(المدخلات!$F$4:$F$7,_xlpm.p),TRIM(MID(_xlpm.t,FIND("–",_xlpm.t)+1,20)))} -> 7:50 م | L6: =_xlfn.MAXIFS('8 فرق'!$C$4:$C$1999,'8 فرق'!$D$4:$D$1999,"* ضد *") -> 2 | M6: =ROUNDUP($L6/المدخلات!$B$9,0) -> 1 | N6: {=IF(MIN(COUNTIF('بيانات الفرق'!$L$3:$L$10,"المجموعة "&_xlfn.SEQUENCE($B6)))>=المدخلات!$B$11,"✔ "&MIN(COUNTIF('بيانات الفرق'!$L$3:$L$10,"المجموعة "&_xlfn.SEQUENCE($B6))),"✘ "&MIN(COUNTIF('بيانات الفرق'!$L$3:$L$10,"المجموعة "&_xlfn.SEQUENCE($B6))))} -> ✔ 8 | O6: =IF($I6<=المدخلات!$B$13,"✔ "&$I6," ⚠ "&$I6&" يوماً — تجاوز السقف ("&المدخلات!$B$13&") لضمان "&المدخلات!$B$14&" مباراة") -> ✔ 21 | P6: {=_xlfn.LET(_xlpm.c,COUNTIF('بيانات الفرق'!$L$3:$L$10,"المجموعة "&_xlfn.SEQUENCE($B6)),_xlpm.mm,AVERAGEIFS('بيانات الفرق'!$M$3:$M$10,'بيانات الفرق'!$L$3:$L$10,"المجموعة "&_xlfn.SEQUENCE($B6)),IF(MIN(_xlpm.mm)>=المدخلات!$B$14,"✔ "&MIN(_xlpm.mm)," ✘ "&MIN(_xlpm.mm)&" / "&المدخلات!$B$14))} -> ✔ 21 | Q6: =COUNTIF('8 فرق'!$D$4:$D$1999,"* ضد *") -> 84 | R6: =COUNTIF(المدخلات!$I$4:$I$200,$A6) -> 5
A7: 9 | B7: {=ROUND(SUMPRODUCT(1/COUNTIF('بيانات الفرق'!$Q$3:$Q$11,'بيانات الفرق'!$Q$3:$Q$11)),0)} -> 1 | C7: {=_xlfn.TEXTJOIN(" + ",TRUE,COUNTIF('بيانات الفرق'!$Q$3:$Q$11,"المجموعة "&_xlfn.SEQUENCE($B7)))} -> 9 | D7: {=_xlfn.LET(_xlpm.c,COUNTIF('بيانات الفرق'!$Q$3:$Q$11,"المجموعة "&_xlfn.SEQUENCE($B7)),_xlpm.mm,AVERAGEIFS('بيانات الفرق'!$R$3:$R$11,'بيانات الفرق'!$Q$3:$Q$11,"المجموعة "&_xlfn.SEQUENCE($B7)),_xlfn.TEXTJOIN(" + ",TRUE,_xlpm.mm/(_xlpm.c-1)))} -> 2 | E7: {=_xlfn.LET(_xlpm.c,COUNTIF('بيانات الفرق'!$Q$3:$Q$11,"المجموعة "&_xlfn.SEQUENCE($B7)),_xlpm.mm,AVERAGEIFS('بيانات الفرق'!$R$3:$R$11,'بيانات الفرق'!$Q$3:$Q$11,"المجموعة "&_xlfn.SEQUENCE($B7)),_xlfn.TEXTJOIN(" + ",TRUE,_xlpm.mm))} -> 16 | F7: =IF($B7>MAX(المدخلات!$B$17:$B$20),"—",LOOKUP($B7,المدخلات!$A$17:$A$20,المدخلات!$C$17:$C$20)) -> — (دوري فقط، البطل أول المجموعة) | G7: =_xlfn.MAXIFS('9 فرق'!$A$4:$A$1999,'9 فرق'!$D$4:$D$1999,"* ضد *",'9 فرق'!$D$4:$D$1999,"<>*فائز*",'9 فرق'!$D$4:$D$1999,"<>*أول المجموعة*",'9 فرق'!$D$4:$D$1999,"<>*أفضل ثانٍ*") -> 18 | H7: =$I7-$G7 -> 0 | I7: =_xlfn.MAXIFS('9 فرق'!$A$4:$A$1999,'9 فرق'!$D$4:$D$1999,"* ضد *") -> 18 | J7: =MOD(HOUR(المدخلات!$B$4)-1,12)+1&":"&TEXT(MINUTE(المدخلات!$B$4),"00")&IF(HOUR(المدخلات!$B$4)<12," ص"," م") -> 4:00 م | K7: {=_xlfn.LET(_xlpm.p,SUMPRODUCT(MAX((COUNTIF('9 فرق'!$B$4:$B$1999,المدخلات!$F$4:$F$7)>0)*(المدخلات!$F$4:$F$7<>"")*ROW(المدخلات!$F$4:$F$7)))-3,_xlpm.t,INDEX(المدخلات!$F$4:$F$7,_xlpm.p),TRIM(MID(_xlpm.t,FIND("–",_xlpm.t)+1,20)))} -> 7:50 م | L7: =_xlfn.MAXIFS('9 فرق'!$C$4:$C$1999,'9 فرق'!$D$4:$D$1999,"* ضد *") -> 2 | M7: =ROUNDUP($L7/المدخلات!$B$9,0) -> 1 | N7: {=IF(MIN(COUNTIF('بيانات الفرق'!$Q$3:$Q$11,"المجموعة "&_xlfn.SEQUENCE($B7)))>=المدخلات!$B$11,"✔ "&MIN(COUNTIF('بيانات الفرق'!$Q$3:$Q$11,"المجموعة "&_xlfn.SEQUENCE($B7))),"✘ "&MIN(COUNTIF('بيانات الفرق'!$Q$3:$Q$11,"المجموعة "&_xlfn.SEQUENCE($B7))))} -> ✔ 9 | O7: =IF($I7<=المدخلات!$B$13,"✔ "&$I7," ⚠ "&$I7&" يوماً — تجاوز السقف ("&المدخلات!$B$13&") لضمان "&المدخلات!$B$14&" مباراة") -> ✔ 18 | P7: {=_xlfn.LET(_xlpm.c,COUNTIF('بيانات الفرق'!$Q$3:$Q$11,"المجموعة "&_xlfn.SEQUENCE($B7)),_xlpm.mm,AVERAGEIFS('بيانات الفرق'!$R$3:$R$11,'بيانات الفرق'!$Q$3:$Q$11,"المجموعة "&_xlfn.SEQUENCE($B7)),IF(MIN(_xlpm.mm)>=المدخلات!$B$14,"✔ "&MIN(_xlpm.mm)," ✘ "&MIN(_xlpm.mm)&" / "&المدخلات!$B$14))} -> ✔ 16 | Q7: =COUNTIF('9 فرق'!$D$4:$D$1999,"* ضد *") -> 72 | R7: =COUNTIF(المدخلات!$I$4:$I$200,$A7) -> 4
A8: 10 | B8: {=ROUND(SUMPRODUCT(1/COUNTIF('بيانات الفرق'!$V$3:$V$12,'بيانات الفرق'!$V$3:$V$12)),0)} -> 1 | C8: {=_xlfn.TEXTJOIN(" + ",TRUE,COUNTIF('بيانات الفرق'!$V$3:$V$12,"المجموعة "&_xlfn.SEQUENCE($B8)))} -> 10 | D8: {=_xlfn.LET(_xlpm.c,COUNTIF('بيانات الفرق'!$V$3:$V$12,"المجموعة "&_xlfn.SEQUENCE($B8)),_xlpm.mm,AVERAGEIFS('بيانات الفرق'!$W$3:$W$12,'بيانات الفرق'!$V$3:$V$12,"المجموعة "&_xlfn.SEQUENCE($B8)),_xlfn.TEXTJOIN(" + ",TRUE,_xlpm.mm/(_xlpm.c-1)))} -> 2 | E8: {=_xlfn.LET(_xlpm.c,COUNTIF('بيانات الفرق'!$V$3:$V$12,"المجموعة "&_xlfn.SEQUENCE($B8)),_xlpm.mm,AVERAGEIFS('بيانات الفرق'!$W$3:$W$12,'بيانات الفرق'!$V$3:$V$12,"المجموعة "&_xlfn.SEQUENCE($B8)),_xlfn.TEXTJOIN(" + ",TRUE,_xlpm.mm))} -> 18 | F8: =IF($B8>MAX(المدخلات!$B$17:$B$20),"—",LOOKUP($B8,المدخلات!$A$17:$A$20,المدخلات!$C$17:$C$20)) -> — (دوري فقط، البطل أول المجموعة) | G8: =_xlfn.MAXIFS('10 فرق'!$A$4:$A$1999,'10 فرق'!$D$4:$D$1999,"* ضد *",'10 فرق'!$D$4:$D$1999,"<>*فائز*",'10 فرق'!$D$4:$D$1999,"<>*أول المجموعة*",'10 فرق'!$D$4:$D$1999,"<>*أفضل ثانٍ*") -> 18 | H8: =$I8-$G8 -> 0 | I8: =_xlfn.MAXIFS('10 فرق'!$A$4:$A$1999,'10 فرق'!$D$4:$D$1999,"* ضد *") -> 18 | J8: =MOD(HOUR(المدخلات!$B$4)-1,12)+1&":"&TEXT(MINUTE(المدخلات!$B$4),"00")&IF(HOUR(المدخلات!$B$4)<12," ص"," م") -> 4:00 م | K8: {=_xlfn.LET(_xlpm.p,SUMPRODUCT(MAX((COUNTIF('10 فرق'!$B$4:$B$1999,المدخلات!$F$4:$F$7)>0)*(المدخلات!$F$4:$F$7<>"")*ROW(المدخلات!$F$4:$F$7)))-3,_xlpm.t,INDEX(المدخلات!$F$4:$F$7,_xlpm.p),TRIM(MID(_xlpm.t,FIND("–",_xlpm.t)+1,20)))} -> 7:50 م | L8: =_xlfn.MAXIFS('10 فرق'!$C$4:$C$1999,'10 فرق'!$D$4:$D$1999,"* ضد *") -> 2 | M8: =ROUNDUP($L8/المدخلات!$B$9,0) -> 1 | N8: {=IF(MIN(COUNTIF('بيانات الفرق'!$V$3:$V$12,"المجموعة "&_xlfn.SEQUENCE($B8)))>=المدخلات!$B$11,"✔ "&MIN(COUNTIF('بيانات الفرق'!$V$3:$V$12,"المجموعة "&_xlfn.SEQUENCE($B8))),"✘ "&MIN(COUNTIF('بيانات الفرق'!$V$3:$V$12,"المجموعة "&_xlfn.SEQUENCE($B8))))} -> ✔ 10 | O8: =IF($I8<=المدخلات!$B$13,"✔ "&$I8," ⚠ "&$I8&" يوماً — تجاوز السقف ("&المدخلات!$B$13&") لضمان "&المدخلات!$B$14&" مباراة") -> ✔ 18 | P8: {=_xlfn.LET(_xlpm.c,COUNTIF('بيانات الفرق'!$V$3:$V$12,"المجموعة "&_xlfn.SEQUENCE($B8)),_xlpm.mm,AVERAGEIFS('بيانات الفرق'!$W$3:$W$12,'بيانات الفرق'!$V$3:$V$12,"المجموعة "&_xlfn.SEQUENCE($B8)),IF(MIN(_xlpm.mm)>=المدخلات!$B$14,"✔ "&MIN(_xlpm.mm)," ✘ "&MIN(_xlpm.mm)&" / "&المدخلات!$B$14))} -> ✔ 18 | Q8: =COUNTIF('10 فرق'!$D$4:$D$1999,"* ضد *") -> 90 | R8: =COUNTIF(المدخلات!$I$4:$I$200,$A8) -> 8
A9: 11 | B9: {=ROUND(SUMPRODUCT(1/COUNTIF('بيانات الفرق'!$AA$3:$AA$13,'بيانات الفرق'!$AA$3:$AA$13)),0)} -> 1 | C9: {=_xlfn.TEXTJOIN(" + ",TRUE,COUNTIF('بيانات الفرق'!$AA$3:$AA$13,"المجموعة "&_xlfn.SEQUENCE($B9)))} -> 11 | D9: {=_xlfn.LET(_xlpm.c,COUNTIF('بيانات الفرق'!$AA$3:$AA$13,"المجموعة "&_xlfn.SEQUENCE($B9)),_xlpm.mm,AVERAGEIFS('بيانات الفرق'!$AB$3:$AB$13,'بيانات الفرق'!$AA$3:$AA$13,"المجموعة "&_xlfn.SEQUENCE($B9)),_xlfn.TEXTJOIN(" + ",TRUE,_xlpm.mm/(_xlpm.c-1)))} -> 2 | E9: {=_xlfn.LET(_xlpm.c,COUNTIF('بيانات الفرق'!$AA$3:$AA$13,"المجموعة "&_xlfn.SEQUENCE($B9)),_xlpm.mm,AVERAGEIFS('بيانات الفرق'!$AB$3:$AB$13,'بيانات الفرق'!$AA$3:$AA$13,"المجموعة "&_xlfn.SEQUENCE($B9)),_xlfn.TEXTJOIN(" + ",TRUE,_xlpm.mm))} -> 20 | F9: =IF($B9>MAX(المدخلات!$B$17:$B$20),"—",LOOKUP($B9,المدخلات!$A$17:$A$20,المدخلات!$C$17:$C$20)) -> — (دوري فقط، البطل أول المجموعة) | G9: =_xlfn.MAXIFS('11 فريقًا'!$A$4:$A$1999,'11 فريقًا'!$D$4:$D$1999,"* ضد *",'11 فريقًا'!$D$4:$D$1999,"<>*فائز*",'11 فريقًا'!$D$4:$D$1999,"<>*أول المجموعة*",'11 فريقًا'!$D$4:$D$1999,"<>*أفضل ثانٍ*") -> 22 | H9: =$I9-$G9 -> 0 | I9: =_xlfn.MAXIFS('11 فريقًا'!$A$4:$A$1999,'11 فريقًا'!$D$4:$D$1999,"* ضد *") -> 22 | J9: =MOD(HOUR(المدخلات!$B$4)-1,12)+1&":"&TEXT(MINUTE(المدخلات!$B$4),"00")&IF(HOUR(المدخلات!$B$4)<12," ص"," م") -> 4:00 م | K9: {=_xlfn.LET(_xlpm.p,SUMPRODUCT(MAX((COUNTIF('11 فريقًا'!$B$4:$B$1999,المدخلات!$F$4:$F$7)>0)*(المدخلات!$F$4:$F$7<>"")*ROW(المدخلات!$F$4:$F$7)))-3,_xlpm.t,INDEX(المدخلات!$F$4:$F$7,_xlpm.p),TRIM(MID(_xlpm.t,FIND("–",_xlpm.t)+1,20)))} -> 7:50 م | L9: =_xlfn.MAXIFS('11 فريقًا'!$C$4:$C$1999,'11 فريقًا'!$D$4:$D$1999,"* ضد *") -> 2 | M9: =ROUNDUP($L9/المدخلات!$B$9,0) -> 1 | N9: {=IF(MIN(COUNTIF('بيانات الفرق'!$AA$3:$AA$13,"المجموعة "&_xlfn.SEQUENCE($B9)))>=المدخلات!$B$11,"✔ "&MIN(COUNTIF('بيانات الفرق'!$AA$3:$AA$13,"المجموعة "&_xlfn.SEQUENCE($B9))),"✘ "&MIN(COUNTIF('بيانات الفرق'!$AA$3:$AA$13,"المجموعة "&_xlfn.SEQUENCE($B9))))} -> ✔ 11 | O9: =IF($I9<=المدخلات!$B$13,"✔ "&$I9," ⚠ "&$I9&" يوماً — تجاوز السقف ("&المدخلات!$B$13&") لضمان "&المدخلات!$B$14&" مباراة") -> ✔ 22 | P9: {=_xlfn.LET(_xlpm.c,COUNTIF('بيانات الفرق'!$AA$3:$AA$13,"المجموعة "&_xlfn.SEQUENCE($B9)),_xlpm.mm,AVERAGEIFS('بيانات الفرق'!$AB$3:$AB$13,'بيانات الفرق'!$AA$3:$AA$13,"المجموعة "&_xlfn.SEQUENCE($B9)),IF(MIN(_xlpm.mm)>=المدخلات!$B$14,"✔ "&MIN(_xlpm.mm)," ✘ "&MIN(_xlpm.mm)&" / "&المدخلات!$B$14))} -> ✔ 20 | Q9: =COUNTIF('11 فريقًا'!$D$4:$D$1999,"* ضد *") -> 110 | R9: =COUNTIF(المدخلات!$I$4:$I$200,$A9) -> 4
A10: 12 | B10: {=ROUND(SUMPRODUCT(1/COUNTIF('بيانات الفرق'!$AF$3:$AF$14,'بيانات الفرق'!$AF$3:$AF$14)),0)} -> 1 | C10: {=_xlfn.TEXTJOIN(" + ",TRUE,COUNTIF('بيانات الفرق'!$AF$3:$AF$14,"المجموعة "&_xlfn.SEQUENCE($B10)))} -> 12 | D10: {=_xlfn.LET(_xlpm.c,COUNTIF('بيانات الفرق'!$AF$3:$AF$14,"المجموعة "&_xlfn.SEQUENCE($B10)),_xlpm.mm,AVERAGEIFS('بيانات الفرق'!$AG$3:$AG$14,'بيانات الفرق'!$AF$3:$AF$14,"المجموعة "&_xlfn.SEQUENCE($B10)),_xlfn.TEXTJOIN(" + ",TRUE,_xlpm.mm/(_xlpm.c-1)))} -> 2 | E10: {=_xlfn.LET(_xlpm.c,COUNTIF('بيانات الفرق'!$AF$3:$AF$14,"المجموعة "&_xlfn.SEQUENCE($B10)),_xlpm.mm,AVERAGEIFS('بيانات الفرق'!$AG$3:$AG$14,'بيانات الفرق'!$AF$3:$AF$14,"المجموعة "&_xlfn.SEQUENCE($B10)),_xlfn.TEXTJOIN(" + ",TRUE,_xlpm.mm))} -> 22 | F10: =IF($B10>MAX(المدخلات!$B$17:$B$20),"—",LOOKUP($B10,المدخلات!$A$17:$A$20,المدخلات!$C$17:$C$20)) -> — (دوري فقط، البطل أول المجموعة) | G10: =_xlfn.MAXIFS('12 فريقًا'!$A$4:$A$1999,'12 فريقًا'!$D$4:$D$1999,"* ضد *",'12 فريقًا'!$D$4:$D$1999,"<>*فائز*",'12 فريقًا'!$D$4:$D$1999,"<>*أول المجموعة*",'12 فريقًا'!$D$4:$D$1999,"<>*أفضل ثانٍ*") -> 22 | H10: =$I10-$G10 -> 0 | I10: =_xlfn.MAXIFS('12 فريقًا'!$A$4:$A$1999,'12 فريقًا'!$D$4:$D$1999,"* ضد *") -> 22 | J10: =MOD(HOUR(المدخلات!$B$4)-1,12)+1&":"&TEXT(MINUTE(المدخلات!$B$4),"00")&IF(HOUR(المدخلات!$B$4)<12," ص"," م") -> 4:00 م | K10: {=_xlfn.LET(_xlpm.p,SUMPRODUCT(MAX((COUNTIF('12 فريقًا'!$B$4:$B$1999,المدخلات!$F$4:$F$7)>0)*(المدخلات!$F$4:$F$7<>"")*ROW(المدخلات!$F$4:$F$7)))-3,_xlpm.t,INDEX(المدخلات!$F$4:$F$7,_xlpm.p),TRIM(MID(_xlpm.t,FIND("–",_xlpm.t)+1,20)))} -> 7:50 م | L10: =_xlfn.MAXIFS('12 فريقًا'!$C$4:$C$1999,'12 فريقًا'!$D$4:$D$1999,"* ضد *") -> 2 | M10: =ROUNDUP($L10/المدخلات!$B$9,0) -> 1 | N10: {=IF(MIN(COUNTIF('بيانات الفرق'!$AF$3:$AF$14,"المجموعة "&_xlfn.SEQUENCE($B10)))>=المدخلات!$B$11,"✔ "&MIN(COUNTIF('بيانات الفرق'!$AF$3:$AF$14,"المجموعة "&_xlfn.SEQUENCE($B10))),"✘ "&MIN(COUNTIF('بيانات الفرق'!$AF$3:$AF$14,"المجموعة "&_xlfn.SEQUENCE($B10))))} -> ✔ 12 | O10: =IF($I10<=المدخلات!$B$13,"✔ "&$I10," ⚠ "&$I10&" يوماً — تجاوز السقف ("&المدخلات!$B$13&") لضمان "&المدخلات!$B$14&" مباراة") -> ✔ 22 | P10: {=_xlfn.LET(_xlpm.c,COUNTIF('بيانات الفرق'!$AF$3:$AF$14,"المجموعة "&_xlfn.SEQUENCE($B10)),_xlpm.mm,AVERAGEIFS('بيانات الفرق'!$AG$3:$AG$14,'بيانات الفرق'!$AF$3:$AF$14,"المجموعة "&_xlfn.SEQUENCE($B10)),IF(MIN(_xlpm.mm)>=المدخلات!$B$14,"✔ "&MIN(_xlpm.mm)," ✘ "&MIN(_xlpm.mm)&" / "&المدخلات!$B$14))} -> ✔ 22 | Q10: =COUNTIF('12 فريقًا'!$D$4:$D$1999,"* ضد *") -> 132 | R10: =COUNTIF(المدخلات!$I$4:$I$200,$A10) -> 3
A11: 13 | B11: {=ROUND(SUMPRODUCT(1/COUNTIF('بيانات الفرق'!$AK$3:$AK$15,'بيانات الفرق'!$AK$3:$AK$15)),0)} -> 2 | C11: {=_xlfn.TEXTJOIN(" + ",TRUE,COUNTIF('بيانات الفرق'!$AK$3:$AK$15,"المجموعة "&_xlfn.SEQUENCE($B11)))} -> 6 + 7 | D11: {=_xlfn.LET(_xlpm.c,COUNTIF('بيانات الفرق'!$AK$3:$AK$15,"المجموعة "&_xlfn.SEQUENCE($B11)),_xlpm.mm,AVERAGEIFS('بيانات الفرق'!$AL$3:$AL$15,'بيانات الفرق'!$AK$3:$AK$15,"المجموعة "&_xlfn.SEQUENCE($B11)),_xlfn.TEXTJOIN(" + ",TRUE,_xlpm.mm/(_xlpm.c-1)))} -> 4 + 3 | E11: {=_xlfn.LET(_xlpm.c,COUNTIF('بيانات الفرق'!$AK$3:$AK$15,"المجموعة "&_xlfn.SEQUENCE($B11)),_xlpm.mm,AVERAGEIFS('بيانات الفرق'!$AL$3:$AL$15,'بيانات الفرق'!$AK$3:$AK$15,"المجموعة "&_xlfn.SEQUENCE($B11)),_xlfn.TEXTJOIN(" + ",TRUE,_xlpm.mm))} -> 20 + 18 | F11: =IF($B11>MAX(المدخلات!$B$17:$B$20),"—",LOOKUP($B11,المدخلات!$A$17:$A$20,المدخلات!$C$17:$C$20)) -> نهائي مباشر | G11: =_xlfn.MAXIFS('13 فريقًا'!$A$4:$A$1999,'13 فريقًا'!$E$4:$E$1999,"* ضد *",'13 فريقًا'!$E$4:$E$1999,"<>*فائز*",'13 فريقًا'!$E$4:$E$1999,"<>*أول المجموعة*",'13 فريقًا'!$E$4:$E$1999,"<>*أفضل ثانٍ*") -> 21 | H11: =$I11-$G11 -> 1 | I11: =_xlfn.MAXIFS('13 فريقًا'!$A$4:$A$1999,'13 فريقًا'!$E$4:$E$1999,"* ضد *") -> 22 | J11: =MOD(HOUR(المدخلات!$B$4)-1,12)+1&":"&TEXT(MINUTE(المدخلات!$B$4),"00")&IF(HOUR(المدخلات!$B$4)<12," ص"," م") -> 4:00 م | K11: {=_xlfn.LET(_xlpm.p,SUMPRODUCT(MAX((COUNTIF('13 فريقًا'!$B$4:$B$1999,المدخلات!$F$4:$F$7)>0)*(المدخلات!$F$4:$F$7<>"")*ROW(المدخلات!$F$4:$F$7)))-3,_xlpm.t,INDEX(المدخلات!$F$4:$F$7,_xlpm.p),TRIM(MID(_xlpm.t,FIND("–",_xlpm.t)+1,20)))} -> 7:50 م | L11: =_xlfn.MAXIFS('13 فريقًا'!$C$4:$C$1999,'13 فريقًا'!$E$4:$E$1999,"* ضد *") -> 2 | M11: =ROUNDUP($L11/المدخلات!$B$9,0) -> 1 | N11: {=IF(MIN(COUNTIF('بيانات الفرق'!$AK$3:$AK$15,"المجموعة "&_xlfn.SEQUENCE($B11)))>=المدخلات!$B$11,"✔ "&MIN(COUNTIF('بيانات الفرق'!$AK$3:$AK$15,"المجموعة "&_xlfn.SEQUENCE($B11))),"✘ "&MIN(COUNTIF('بيانات الفرق'!$AK$3:$AK$15,"المجموعة "&_xlfn.SEQUENCE($B11))))} -> ✔ 6 | O11: =IF($I11<=المدخلات!$B$13,"✔ "&$I11," ⚠ "&$I11&" يوماً — تجاوز السقف ("&المدخلات!$B$13&") لضمان "&المدخلات!$B$14&" مباراة") -> ✔ 22 | P11: {=_xlfn.LET(_xlpm.c,COUNTIF('بيانات الفرق'!$AK$3:$AK$15,"المجموعة "&_xlfn.SEQUENCE($B11)),_xlpm.mm,AVERAGEIFS('بيانات الفرق'!$AL$3:$AL$15,'بيانات الفرق'!$AK$3:$AK$15,"المجموعة "&_xlfn.SEQUENCE($B11)),IF(MIN(_xlpm.mm)>=المدخلات!$B$14,"✔ "&MIN(_xlpm.mm)," ✘ "&MIN(_xlpm.mm)&" / "&المدخلات!$B$14))} -> ✔ 18 | Q11: =COUNTIF('13 فريقًا'!$E$4:$E$1999,"* ضد *") -> 124 | R11: =COUNTIF(المدخلات!$I$4:$I$200,$A11) -> 1
A12: 14 | B12: {=ROUND(SUMPRODUCT(1/COUNTIF('بيانات الفرق'!$AP$3:$AP$16,'بيانات الفرق'!$AP$3:$AP$16)),0)} -> 2 | C12: {=_xlfn.TEXTJOIN(" + ",TRUE,COUNTIF('بيانات الفرق'!$AP$3:$AP$16,"المجموعة "&_xlfn.SEQUENCE($B12)))} -> 7 + 7 | D12: {=_xlfn.LET(_xlpm.c,COUNTIF('بيانات الفرق'!$AP$3:$AP$16,"المجموعة "&_xlfn.SEQUENCE($B12)),_xlpm.mm,AVERAGEIFS('بيانات الفرق'!$AQ$3:$AQ$16,'بيانات الفرق'!$AP$3:$AP$16,"المجموعة "&_xlfn.SEQUENCE($B12)),_xlfn.TEXTJOIN(" + ",TRUE,_xlpm.mm/(_xlpm.c-1)))} -> 3 + 3 | E12: {=_xlfn.LET(_xlpm.c,COUNTIF('بيانات الفرق'!$AP$3:$AP$16,"المجموعة "&_xlfn.SEQUENCE($B12)),_xlpm.mm,AVERAGEIFS('بيانات الفرق'!$AQ$3:$AQ$16,'بيانات الفرق'!$AP$3:$AP$16,"المجموعة "&_xlfn.SEQUENCE($B12)),_xlfn.TEXTJOIN(" + ",TRUE,_xlpm.mm))} -> 18 + 18 | F12: =IF($B12>MAX(المدخلات!$B$17:$B$20),"—",LOOKUP($B12,المدخلات!$A$17:$A$20,المدخلات!$C$17:$C$20)) -> نهائي مباشر | G12: =_xlfn.MAXIFS('14 فريقًا'!$A$4:$A$1999,'14 فريقًا'!$E$4:$E$1999,"* ضد *",'14 فريقًا'!$E$4:$E$1999,"<>*فائز*",'14 فريقًا'!$E$4:$E$1999,"<>*أول المجموعة*",'14 فريقًا'!$E$4:$E$1999,"<>*أفضل ثانٍ*") -> 21 | H12: =$I12-$G12 -> 1 | I12: =_xlfn.MAXIFS('14 فريقًا'!$A$4:$A$1999,'14 فريقًا'!$E$4:$E$1999,"* ضد *") -> 22 | J12: =MOD(HOUR(المدخلات!$B$4)-1,12)+1&":"&TEXT(MINUTE(المدخلات!$B$4),"00")&IF(HOUR(المدخلات!$B$4)<12," ص"," م") -> 4:00 م | K12: {=_xlfn.LET(_xlpm.p,SUMPRODUCT(MAX((COUNTIF('14 فريقًا'!$B$4:$B$1999,المدخلات!$F$4:$F$7)>0)*(المدخلات!$F$4:$F$7<>"")*ROW(المدخلات!$F$4:$F$7)))-3,_xlpm.t,INDEX(المدخلات!$F$4:$F$7,_xlpm.p),TRIM(MID(_xlpm.t,FIND("–",_xlpm.t)+1,20)))} -> 7:50 م | L12: =_xlfn.MAXIFS('14 فريقًا'!$C$4:$C$1999,'14 فريقًا'!$E$4:$E$1999,"* ضد *") -> 2 | M12: =ROUNDUP($L12/المدخلات!$B$9,0) -> 1 | N12: {=IF(MIN(COUNTIF('بيانات الفرق'!$AP$3:$AP$16,"المجموعة "&_xlfn.SEQUENCE($B12)))>=المدخلات!$B$11,"✔ "&MIN(COUNTIF('بيانات الفرق'!$AP$3:$AP$16,"المجموعة "&_xlfn.SEQUENCE($B12))),"✘ "&MIN(COUNTIF('بيانات الفرق'!$AP$3:$AP$16,"المجموعة "&_xlfn.SEQUENCE($B12))))} -> ✔ 7 | O12: =IF($I12<=المدخلات!$B$13,"✔ "&$I12," ⚠ "&$I12&" يوماً — تجاوز السقف ("&المدخلات!$B$13&") لضمان "&المدخلات!$B$14&" مباراة") -> ✔ 22 | P12: {=_xlfn.LET(_xlpm.c,COUNTIF('بيانات الفرق'!$AP$3:$AP$16,"المجموعة "&_xlfn.SEQUENCE($B12)),_xlpm.mm,AVERAGEIFS('بيانات الفرق'!$AQ$3:$AQ$16,'بيانات الفرق'!$AP$3:$AP$16,"المجموعة "&_xlfn.SEQUENCE($B12)),IF(MIN(_xlpm.mm)>=المدخلات!$B$14,"✔ "&MIN(_xlpm.mm)," ✘ "&MIN(_xlpm.mm)&" / "&المدخلات!$B$14))} -> ✔ 18 | Q12: =COUNTIF('14 فريقًا'!$E$4:$E$1999,"* ضد *") -> 127 | R12: =COUNTIF(المدخلات!$I$4:$I$200,$A12) -> 5
A13: 15 | B13: {=ROUND(SUMPRODUCT(1/COUNTIF('بيانات الفرق'!$AU$3:$AU$17,'بيانات الفرق'!$AU$3:$AU$17)),0)} -> 2 | C13: {=_xlfn.TEXTJOIN(" + ",TRUE,COUNTIF('بيانات الفرق'!$AU$3:$AU$17,"المجموعة "&_xlfn.SEQUENCE($B13)))} -> 7 + 8 | D13: {=_xlfn.LET(_xlpm.c,COUNTIF('بيانات الفرق'!$AU$3:$AU$17,"المجموعة "&_xlfn.SEQUENCE($B13)),_xlpm.mm,AVERAGEIFS('بيانات الفرق'!$AV$3:$AV$17,'بيانات الفرق'!$AU$3:$AU$17,"المجموعة "&_xlfn.SEQUENCE($B13)),_xlfn.TEXTJOIN(" + ",TRUE,_xlpm.mm/(_xlpm.c-1)))} -> 3 + 3 | E13: {=_xlfn.LET(_xlpm.c,COUNTIF('بيانات الفرق'!$AU$3:$AU$17,"المجموعة "&_xlfn.SEQUENCE($B13)),_xlpm.mm,AVERAGEIFS('بيانات الفرق'!$AV$3:$AV$17,'بيانات الفرق'!$AU$3:$AU$17,"المجموعة "&_xlfn.SEQUENCE($B13)),_xlfn.TEXTJOIN(" + ",TRUE,_xlpm.mm))} -> 18 + 21 | F13: =IF($B13>MAX(المدخلات!$B$17:$B$20),"—",LOOKUP($B13,المدخلات!$A$17:$A$20,المدخلات!$C$17:$C$20)) -> نهائي مباشر | G13: =_xlfn.MAXIFS('15 فريقًا'!$A$4:$A$1999,'15 فريقًا'!$E$4:$E$1999,"* ضد *",'15 فريقًا'!$E$4:$E$1999,"<>*فائز*",'15 فريقًا'!$E$4:$E$1999,"<>*أول المجموعة*",'15 فريقًا'!$E$4:$E$1999,"<>*أفضل ثانٍ*") -> 21 | H13: =$I13-$G13 -> 1 | I13: =_xlfn.MAXIFS('15 فريقًا'!$A$4:$A$1999,'15 فريقًا'!$E$4:$E$1999,"* ضد *") -> 22 | J13: =MOD(HOUR(المدخلات!$B$4)-1,12)+1&":"&TEXT(MINUTE(المدخلات!$B$4),"00")&IF(HOUR(المدخلات!$B$4)<12," ص"," م") -> 4:00 م | K13: {=_xlfn.LET(_xlpm.p,SUMPRODUCT(MAX((COUNTIF('15 فريقًا'!$B$4:$B$1999,المدخلات!$F$4:$F$7)>0)*(المدخلات!$F$4:$F$7<>"")*ROW(المدخلات!$F$4:$F$7)))-3,_xlpm.t,INDEX(المدخلات!$F$4:$F$7,_xlpm.p),TRIM(MID(_xlpm.t,FIND("–",_xlpm.t)+1,20)))} -> 7:50 م | L13: =_xlfn.MAXIFS('15 فريقًا'!$C$4:$C$1999,'15 فريقًا'!$E$4:$E$1999,"* ضد *") -> 3 | M13: =ROUNDUP($L13/المدخلات!$B$9,0) -> 2 | N13: {=IF(MIN(COUNTIF('بيانات الفرق'!$AU$3:$AU$17,"المجموعة "&_xlfn.SEQUENCE($B13)))>=المدخلات!$B$11,"✔ "&MIN(COUNTIF('بيانات الفرق'!$AU$3:$AU$17,"المجموعة "&_xlfn.SEQUENCE($B13))),"✘ "&MIN(COUNTIF('بيانات الفرق'!$AU$3:$AU$17,"المجموعة "&_xlfn.SEQUENCE($B13))))} -> ✔ 7 | O13: =IF($I13<=المدخلات!$B$13,"✔ "&$I13," ⚠ "&$I13&" يوماً — تجاوز السقف ("&المدخلات!$B$13&") لضمان "&المدخلات!$B$14&" مباراة") -> ✔ 22 | P13: {=_xlfn.LET(_xlpm.c,COUNTIF('بيانات الفرق'!$AU$3:$AU$17,"المجموعة "&_xlfn.SEQUENCE($B13)),_xlpm.mm,AVERAGEIFS('بيانات الفرق'!$AV$3:$AV$17,'بيانات الفرق'!$AU$3:$AU$17,"المجموعة "&_xlfn.SEQUENCE($B13)),IF(MIN(_xlpm.mm)>=المدخلات!$B$14,"✔ "&MIN(_xlpm.mm)," ✘ "&MIN(_xlpm.mm)&" / "&المدخلات!$B$14))} -> ✔ 18 | Q13: =COUNTIF('15 فريقًا'!$E$4:$E$1999,"* ضد *") -> 148 | R13: =COUNTIF(المدخلات!$I$4:$I$200,$A13) -> 4
A14: 16 | B14: {=ROUND(SUMPRODUCT(1/COUNTIF('بيانات الفرق'!$AZ$3:$AZ$18,'بيانات الفرق'!$AZ$3:$AZ$18)),0)} -> 2 | C14: {=_xlfn.TEXTJOIN(" + ",TRUE,COUNTIF('بيانات الفرق'!$AZ$3:$AZ$18,"المجموعة "&_xlfn.SEQUENCE($B14)))} -> 8 + 8 | D14: {=_xlfn.LET(_xlpm.c,COUNTIF('بيانات الفرق'!$AZ$3:$AZ$18,"المجموعة "&_xlfn.SEQUENCE($B14)),_xlpm.mm,AVERAGEIFS('بيانات الفرق'!$BA$3:$BA$18,'بيانات الفرق'!$AZ$3:$AZ$18,"المجموعة "&_xlfn.SEQUENCE($B14)),_xlfn.TEXTJOIN(" + ",TRUE,_xlpm.mm/(_xlpm.c-1)))} -> 3 + 3 | E14: {=_xlfn.LET(_xlpm.c,COUNTIF('بيانات الفرق'!$AZ$3:$AZ$18,"المجموعة "&_xlfn.SEQUENCE($B14)),_xlpm.mm,AVERAGEIFS('بيانات الفرق'!$BA$3:$BA$18,'بيانات الفرق'!$AZ$3:$AZ$18,"المجموعة "&_xlfn.SEQUENCE($B14)),_xlfn.TEXTJOIN(" + ",TRUE,_xlpm.mm))} -> 21 + 21 | F14: =IF($B14>MAX(المدخلات!$B$17:$B$20),"—",LOOKUP($B14,المدخلات!$A$17:$A$20,المدخلات!$C$17:$C$20)) -> نهائي مباشر | G14: =_xlfn.MAXIFS('16 فريقًا'!$A$4:$A$1999,'16 فريقًا'!$E$4:$E$1999,"* ضد *",'16 فريقًا'!$E$4:$E$1999,"<>*فائز*",'16 فريقًا'!$E$4:$E$1999,"<>*أول المجموعة*",'16 فريقًا'!$E$4:$E$1999,"<>*أفضل ثانٍ*") -> 21 | H14: =$I14-$G14 -> 1 | I14: =_xlfn.MAXIFS('16 فريقًا'!$A$4:$A$1999,'16 فريقًا'!$E$4:$E$1999,"* ضد *") -> 22 | J14: =MOD(HOUR(المدخلات!$B$4)-1,12)+1&":"&TEXT(MINUTE(المدخلات!$B$4),"00")&IF(HOUR(المدخلات!$B$4)<12," ص"," م") -> 4:00 م | K14: {=_xlfn.LET(_xlpm.p,SUMPRODUCT(MAX((COUNTIF('16 فريقًا'!$B$4:$B$1999,المدخلات!$F$4:$F$7)>0)*(المدخلات!$F$4:$F$7<>"")*ROW(المدخلات!$F$4:$F$7)))-3,_xlpm.t,INDEX(المدخلات!$F$4:$F$7,_xlpm.p),TRIM(MID(_xlpm.t,FIND("–",_xlpm.t)+1,20)))} -> 7:50 م | L14: =_xlfn.MAXIFS('16 فريقًا'!$C$4:$C$1999,'16 فريقًا'!$E$4:$E$1999,"* ضد *") -> 3 | M14: =ROUNDUP($L14/المدخلات!$B$9,0) -> 2 | N14: {=IF(MIN(COUNTIF('بيانات الفرق'!$AZ$3:$AZ$18,"المجموعة "&_xlfn.SEQUENCE($B14)))>=المدخلات!$B$11,"✔ "&MIN(COUNTIF('بيانات الفرق'!$AZ$3:$AZ$18,"المجموعة "&_xlfn.SEQUENCE($B14))),"✘ "&MIN(COUNTIF('بيانات الفرق'!$AZ$3:$AZ$18,"المجموعة "&_xlfn.SEQUENCE($B14))))} -> ✔ 8 | O14: =IF($I14<=المدخلات!$B$13,"✔ "&$I14," ⚠ "&$I14&" يوماً — تجاوز السقف ("&المدخلات!$B$13&") لضمان "&المدخلات!$B$14&" مباراة") -> ✔ 22 | P14: {=_xlfn.LET(_xlpm.c,COUNTIF('بيانات الفرق'!$AZ$3:$AZ$18,"المجموعة "&_xlfn.SEQUENCE($B14)),_xlpm.mm,AVERAGEIFS('بيانات الفرق'!$BA$3:$BA$18,'بيانات الفرق'!$AZ$3:$AZ$18,"المجموعة "&_xlfn.SEQUENCE($B14)),IF(MIN(_xlpm.mm)>=المدخلات!$B$14,"✔ "&MIN(_xlpm.mm)," ✘ "&MIN(_xlpm.mm)&" / "&المدخلات!$B$14))} -> ✔ 21 | Q14: =COUNTIF('16 فريقًا'!$E$4:$E$1999,"* ضد *") -> 169 | R14: =COUNTIF(المدخلات!$I$4:$I$200,$A14) -> 5
A15: 18 | B15: {=ROUND(SUMPRODUCT(1/COUNTIF('بيانات الفرق'!$BE$3:$BE$20,'بيانات الفرق'!$BE$3:$BE$20)),0)} -> 1 | C15: {=_xlfn.TEXTJOIN(" + ",TRUE,COUNTIF('بيانات الفرق'!$BE$3:$BE$20,"المجموعة "&_xlfn.SEQUENCE($B15)))} -> 18 | D15: {=_xlfn.LET(_xlpm.c,COUNTIF('بيانات الفرق'!$BE$3:$BE$20,"المجموعة "&_xlfn.SEQUENCE($B15)),_xlpm.mm,AVERAGEIFS('بيانات الفرق'!$BF$3:$BF$20,'بيانات الفرق'!$BE$3:$BE$20,"المجموعة "&_xlfn.SEQUENCE($B15)),_xlfn.TEXTJOIN(" + ",TRUE,_xlpm.mm/(_xlpm.c-1)))} -> 1 | E15: {=_xlfn.LET(_xlpm.c,COUNTIF('بيانات الفرق'!$BE$3:$BE$20,"المجموعة "&_xlfn.SEQUENCE($B15)),_xlpm.mm,AVERAGEIFS('بيانات الفرق'!$BF$3:$BF$20,'بيانات الفرق'!$BE$3:$BE$20,"المجموعة "&_xlfn.SEQUENCE($B15)),_xlfn.TEXTJOIN(" + ",TRUE,_xlpm.mm))} -> 17 | F15: =IF($B15>MAX(المدخلات!$B$17:$B$20),"—",LOOKUP($B15,المدخلات!$A$17:$A$20,المدخلات!$C$17:$C$20)) -> — (دوري فقط، البطل أول المجموعة) | G15: =_xlfn.MAXIFS('18 فريقًا'!$A$4:$A$1999,'18 فريقًا'!$E$4:$E$1999,"* ضد *",'18 فريقًا'!$E$4:$E$1999,"<>*فائز*",'18 فريقًا'!$E$4:$E$1999,"<>*أول المجموعة*",'18 فريقًا'!$E$4:$E$1999,"<>*أفضل ثانٍ*") -> 17 | H15: =$I15-$G15 -> 0 | I15: =_xlfn.MAXIFS('18 فريقًا'!$A$4:$A$1999,'18 فريقًا'!$E$4:$E$1999,"* ضد *") -> 17 | J15: =MOD(HOUR(المدخلات!$B$4)-1,12)+1&":"&TEXT(MINUTE(المدخلات!$B$4),"00")&IF(HOUR(المدخلات!$B$4)<12," ص"," م") -> 4:00 م | K15: {=_xlfn.LET(_xlpm.p,SUMPRODUCT(MAX((COUNTIF('18 فريقًا'!$B$4:$B$1999,المدخلات!$F$4:$F$7)>0)*(المدخلات!$F$4:$F$7<>"")*ROW(المدخلات!$F$4:$F$7)))-3,_xlpm.t,INDEX(المدخلات!$F$4:$F$7,_xlpm.p),TRIM(MID(_xlpm.t,FIND("–",_xlpm.t)+1,20)))} -> 7:50 م | L15: =_xlfn.MAXIFS('18 فريقًا'!$C$4:$C$1999,'18 فريقًا'!$E$4:$E$1999,"* ضد *") -> 3 | M15: =ROUNDUP($L15/المدخلات!$B$9,0) -> 2 | N15: {=IF(MIN(COUNTIF('بيانات الفرق'!$BE$3:$BE$20,"المجموعة "&_xlfn.SEQUENCE($B15)))>=المدخلات!$B$11,"✔ "&MIN(COUNTIF('بيانات الفرق'!$BE$3:$BE$20,"المجموعة "&_xlfn.SEQUENCE($B15))),"✘ "&MIN(COUNTIF('بيانات الفرق'!$BE$3:$BE$20,"المجموعة "&_xlfn.SEQUENCE($B15))))} -> ✔ 18 | O15: =IF($I15<=المدخلات!$B$13,"✔ "&$I15," ⚠ "&$I15&" يوماً — تجاوز السقف ("&المدخلات!$B$13&") لضمان "&المدخلات!$B$14&" مباراة") -> ✔ 17 | P15: {=_xlfn.LET(_xlpm.c,COUNTIF('بيانات الفرق'!$BE$3:$BE$20,"المجموعة "&_xlfn.SEQUENCE($B15)),_xlpm.mm,AVERAGEIFS('بيانات الفرق'!$BF$3:$BF$20,'بيانات الفرق'!$BE$3:$BE$20,"المجموعة "&_xlfn.SEQUENCE($B15)),IF(MIN(_xlpm.mm)>=المدخلات!$B$14,"✔ "&MIN(_xlpm.mm)," ✘ "&MIN(_xlpm.mm)&" / "&المدخلات!$B$14))} -> ✔ 17 | Q15: =COUNTIF('18 فريقًا'!$E$4:$E$1999,"* ضد *") -> 153 | R15: =COUNTIF(المدخلات!$I$4:$I$200,$A15) -> 1
A16: 21 | B16: {=ROUND(SUMPRODUCT(1/COUNTIF('بيانات الفرق'!$BJ$3:$BJ$23,'بيانات الفرق'!$BJ$3:$BJ$23)),0)} -> 1 | C16: {=_xlfn.TEXTJOIN(" + ",TRUE,COUNTIF('بيانات الفرق'!$BJ$3:$BJ$23,"المجموعة "&_xlfn.SEQUENCE($B16)))} -> 21 | D16: {=_xlfn.LET(_xlpm.c,COUNTIF('بيانات الفرق'!$BJ$3:$BJ$23,"المجموعة "&_xlfn.SEQUENCE($B16)),_xlpm.mm,AVERAGEIFS('بيانات الفرق'!$BK$3:$BK$23,'بيانات الفرق'!$BJ$3:$BJ$23,"المجموعة "&_xlfn.SEQUENCE($B16)),_xlfn.TEXTJOIN(" + ",TRUE,_xlpm.mm/(_xlpm.c-1)))} -> 1 | E16: {=_xlfn.LET(_xlpm.c,COUNTIF('بيانات الفرق'!$BJ$3:$BJ$23,"المجموعة "&_xlfn.SEQUENCE($B16)),_xlpm.mm,AVERAGEIFS('بيانات الفرق'!$BK$3:$BK$23,'بيانات الفرق'!$BJ$3:$BJ$23,"المجموعة "&_xlfn.SEQUENCE($B16)),_xlfn.TEXTJOIN(" + ",TRUE,_xlpm.mm))} -> 20 | F16: =IF($B16>MAX(المدخلات!$B$17:$B$20),"—",LOOKUP($B16,المدخلات!$A$17:$A$20,المدخلات!$C$17:$C$20)) -> — (دوري فقط، البطل أول المجموعة) | G16: =_xlfn.MAXIFS('21 فريقًا'!$A$4:$A$1999,'21 فريقًا'!$E$4:$E$1999,"* ضد *",'21 فريقًا'!$E$4:$E$1999,"<>*فائز*",'21 فريقًا'!$E$4:$E$1999,"<>*أول المجموعة*",'21 فريقًا'!$E$4:$E$1999,"<>*أفضل ثانٍ*") -> 21 | H16: =$I16-$G16 -> 0 | I16: =_xlfn.MAXIFS('21 فريقًا'!$A$4:$A$1999,'21 فريقًا'!$E$4:$E$1999,"* ضد *") -> 21 | J16: =MOD(HOUR(المدخلات!$B$4)-1,12)+1&":"&TEXT(MINUTE(المدخلات!$B$4),"00")&IF(HOUR(المدخلات!$B$4)<12," ص"," م") -> 4:00 م | K16: {=_xlfn.LET(_xlpm.p,SUMPRODUCT(MAX((COUNTIF('21 فريقًا'!$B$4:$B$1999,المدخلات!$F$4:$F$7)>0)*(المدخلات!$F$4:$F$7<>"")*ROW(المدخلات!$F$4:$F$7)))-3,_xlpm.t,INDEX(المدخلات!$F$4:$F$7,_xlpm.p),TRIM(MID(_xlpm.t,FIND("–",_xlpm.t)+1,20)))} -> 7:50 م | L16: =_xlfn.MAXIFS('21 فريقًا'!$C$4:$C$1999,'21 فريقًا'!$E$4:$E$1999,"* ضد *") -> 4 | M16: =ROUNDUP($L16/المدخلات!$B$9,0) -> 2 | N16: {=IF(MIN(COUNTIF('بيانات الفرق'!$BJ$3:$BJ$23,"المجموعة "&_xlfn.SEQUENCE($B16)))>=المدخلات!$B$11,"✔ "&MIN(COUNTIF('بيانات الفرق'!$BJ$3:$BJ$23,"المجموعة "&_xlfn.SEQUENCE($B16))),"✘ "&MIN(COUNTIF('بيانات الفرق'!$BJ$3:$BJ$23,"المجموعة "&_xlfn.SEQUENCE($B16))))} -> ✔ 21 | O16: =IF($I16<=المدخلات!$B$13,"✔ "&$I16," ⚠ "&$I16&" يوماً — تجاوز السقف ("&المدخلات!$B$13&") لضمان "&المدخلات!$B$14&" مباراة") -> ✔ 21 | P16: {=_xlfn.LET(_xlpm.c,COUNTIF('بيانات الفرق'!$BJ$3:$BJ$23,"المجموعة "&_xlfn.SEQUENCE($B16)),_xlpm.mm,AVERAGEIFS('بيانات الفرق'!$BK$3:$BK$23,'بيانات الفرق'!$BJ$3:$BJ$23,"المجموعة "&_xlfn.SEQUENCE($B16)),IF(MIN(_xlpm.mm)>=المدخلات!$B$14,"✔ "&MIN(_xlpm.mm)," ✘ "&MIN(_xlpm.mm)&" / "&المدخلات!$B$14))} -> ✔ 20 | Q16: =COUNTIF('21 فريقًا'!$E$4:$E$1999,"* ضد *") -> 210 | R16: =COUNTIF(المدخلات!$I$4:$I$200,$A16) -> 1
A17: 22 | B17: {=ROUND(SUMPRODUCT(1/COUNTIF('بيانات الفرق'!$BO$3:$BO$24,'بيانات الفرق'!$BO$3:$BO$24)),0)} -> 1 | C17: {=_xlfn.TEXTJOIN(" + ",TRUE,COUNTIF('بيانات الفرق'!$BO$3:$BO$24,"المجموعة "&_xlfn.SEQUENCE($B17)))} -> 22 | D17: {=_xlfn.LET(_xlpm.c,COUNTIF('بيانات الفرق'!$BO$3:$BO$24,"المجموعة "&_xlfn.SEQUENCE($B17)),_xlpm.mm,AVERAGEIFS('بيانات الفرق'!$BP$3:$BP$24,'بيانات الفرق'!$BO$3:$BO$24,"المجموعة "&_xlfn.SEQUENCE($B17)),_xlfn.TEXTJOIN(" + ",TRUE,_xlpm.mm/(_xlpm.c-1)))} -> 1 | E17: {=_xlfn.LET(_xlpm.c,COUNTIF('بيانات الفرق'!$BO$3:$BO$24,"المجموعة "&_xlfn.SEQUENCE($B17)),_xlpm.mm,AVERAGEIFS('بيانات الفرق'!$BP$3:$BP$24,'بيانات الفرق'!$BO$3:$BO$24,"المجموعة "&_xlfn.SEQUENCE($B17)),_xlfn.TEXTJOIN(" + ",TRUE,_xlpm.mm))} -> 21 | F17: =IF($B17>MAX(المدخلات!$B$17:$B$20),"—",LOOKUP($B17,المدخلات!$A$17:$A$20,المدخلات!$C$17:$C$20)) -> — (دوري فقط، البطل أول المجموعة) | G17: =_xlfn.MAXIFS('22 فريقًا'!$A$4:$A$1999,'22 فريقًا'!$E$4:$E$1999,"* ضد *",'22 فريقًا'!$E$4:$E$1999,"<>*فائز*",'22 فريقًا'!$E$4:$E$1999,"<>*أول المجموعة*",'22 فريقًا'!$E$4:$E$1999,"<>*أفضل ثانٍ*") -> 21 | H17: =$I17-$G17 -> 0 | I17: =_xlfn.MAXIFS('22 فريقًا'!$A$4:$A$1999,'22 فريقًا'!$E$4:$E$1999,"* ضد *") -> 21 | J17: =MOD(HOUR(المدخلات!$B$4)-1,12)+1&":"&TEXT(MINUTE(المدخلات!$B$4),"00")&IF(HOUR(المدخلات!$B$4)<12," ص"," م") -> 4:00 م | K17: {=_xlfn.LET(_xlpm.p,SUMPRODUCT(MAX((COUNTIF('22 فريقًا'!$B$4:$B$1999,المدخلات!$F$4:$F$7)>0)*(المدخلات!$F$4:$F$7<>"")*ROW(المدخلات!$F$4:$F$7)))-3,_xlpm.t,INDEX(المدخلات!$F$4:$F$7,_xlpm.p),TRIM(MID(_xlpm.t,FIND("–",_xlpm.t)+1,20)))} -> 7:50 م | L17: =_xlfn.MAXIFS('22 فريقًا'!$C$4:$C$1999,'22 فريقًا'!$E$4:$E$1999,"* ضد *") -> 4 | M17: =ROUNDUP($L17/المدخلات!$B$9,0) -> 2 | N17: {=IF(MIN(COUNTIF('بيانات الفرق'!$BO$3:$BO$24,"المجموعة "&_xlfn.SEQUENCE($B17)))>=المدخلات!$B$11,"✔ "&MIN(COUNTIF('بيانات الفرق'!$BO$3:$BO$24,"المجموعة "&_xlfn.SEQUENCE($B17))),"✘ "&MIN(COUNTIF('بيانات الفرق'!$BO$3:$BO$24,"المجموعة "&_xlfn.SEQUENCE($B17))))} -> ✔ 22 | O17: =IF($I17<=المدخلات!$B$13,"✔ "&$I17," ⚠ "&$I17&" يوماً — تجاوز السقف ("&المدخلات!$B$13&") لضمان "&المدخلات!$B$14&" مباراة") -> ✔ 21 | P17: {=_xlfn.LET(_xlpm.c,COUNTIF('بيانات الفرق'!$BO$3:$BO$24,"المجموعة "&_xlfn.SEQUENCE($B17)),_xlpm.mm,AVERAGEIFS('بيانات الفرق'!$BP$3:$BP$24,'بيانات الفرق'!$BO$3:$BO$24,"المجموعة "&_xlfn.SEQUENCE($B17)),IF(MIN(_xlpm.mm)>=المدخلات!$B$14,"✔ "&MIN(_xlpm.mm)," ✘ "&MIN(_xlpm.mm)&" / "&المدخلات!$B$14))} -> ✔ 21 | Q17: =COUNTIF('22 فريقًا'!$E$4:$E$1999,"* ضد *") -> 231 | R17: =COUNTIF(المدخلات!$I$4:$I$200,$A17) -> 1
