Workbook

Sheet المدخلات
A1: مدخلات جداول بطولات تحت 13
A3: الخلايا الزرقاء قابلة للتعديل — كل الجداول تتحدث تلقائياً
A4: البند | B4: القيمة | C4: ملاحظة
A5: وقت بداية اليوم | B5: 0.66666667 | C5: قابل للتعديل
A6: مدة المباراة (دقيقة) | B6: 85 | C6: قابل للتعديل
A7: الفاصل / ترتيب الملعب (دقيقة) | B7: 10 | C7: قابل للتعديل
A8: طول الفترة الكاملة (دقيقة) | B8: =B6+B7 -> 95 | C8: محسوبة تلقائياً
A9: أقصى عدد فترات في اليوم | B9: 3 | C9: قابل للتعديل

Sheet الملخص
A1: ملخص بطولات تحت 13 – الأعداد المطلوبة
A3: عدد الفرق | B3: عدد المجموعات | C3: توزيع الفرق في المجموعات | D3: لقاءات كل خصم | E3: مباريات كل فريق في الموسم (غير شاملة الإقصاء) | F3: نظام الإقصاء | G3: أيام الدوري | H3: أيام الإقصاء | I3: إجمالي الأيام | J3: وقت البداية | K3: وقت النهاية | L3: عدد الملاعب القانونية
A4: 6 | B4: {=ROUND(SUMPRODUCT(1/COUNTIF('بيانات الفرق U13'!$B$3:$B$8,'بيانات الفرق U13'!$B$3:$B$8)),0)} -> 1 | C4: {=_xlfn.TEXTJOIN(" + ",TRUE,_xlfn._xlws.SORT(COUNTIF('بيانات الفرق U13'!$B$3:$B$8,"المجموعة "&_xlfn.SEQUENCE(B4))))} -> 6 | D4: {=_xlfn.LET(_xlpm.gs,_xlfn.SEQUENCE(B4),_xlpm.ln,_xlfn.MAXIFS('بيانات الفرق U13'!$D$3:$D$8,'بيانات الفرق U13'!$B$3:$B$8,"المجموعة "&_xlpm.gs),_xlpm.mn,_xlfn.MINIFS('بيانات الفرق U13'!$C$3:$C$8,'بيانات الفرق U13'!$B$3:$B$8,"المجموعة "&_xlpm.gs),_xlpm.mx,_xlfn.MAXIFS('بيانات الفرق U13'!$C$3:$C$8,'بيانات الفرق U13'!$B$3:$B$8,"المجموعة "&_xlpm.gs),_xlpm.lo,FLOOR(_xlpm.mn/_xlpm.ln,1),_xlpm.hi,CEILING(_xlpm.mx/_xlpm.ln,1),_xlpm.t,IF(_xlpm.lo=_xlpm.hi,_xlpm.lo&"",_xlpm.lo&"–"&_xlpm.hi),_xlfn.TEXTJOIN(" + ",TRUE,_xlfn.SORTBY(_xlpm.t,_xlpm.ln,1)))} -> 4 | E4: {=_xlfn.LET(_xlpm.gs,_xlfn.SEQUENCE(B4),_xlpm.ln,_xlfn.MAXIFS('بيانات الفرق U13'!$D$3:$D$8,'بيانات الفرق U13'!$B$3:$B$8,"المجموعة "&_xlpm.gs),_xlpm.mn,_xlfn.MINIFS('بيانات الفرق U13'!$C$3:$C$8,'بيانات الفرق U13'!$B$3:$B$8,"المجموعة "&_xlpm.gs),_xlpm.mx,_xlfn.MAXIFS('بيانات الفرق U13'!$C$3:$C$8,'بيانات الفرق U13'!$B$3:$B$8,"المجموعة "&_xlpm.gs),_xlpm.t,IF(_xlpm.mn=_xlpm.mx,_xlpm.mn&"",_xlpm.mn&"–"&_xlpm.mx),_xlfn.TEXTJOIN(" + ",TRUE,_xlfn.SORTBY(_xlpm.t,_xlpm.ln,1)))} -> 20 | F4: =IF(H4=0,"—",IF(H4=1,"نهائي مباشر",IF(H4=2,"نصف نهائي ثم نهائي","ربع نهائي ثم نصف نهائي ثم نهائي"))) -> — | G4: =I4-H4 -> 20 | H4: {=MAX('6 فرق'!$A$4:$A$63)-SUMPRODUCT(MAX(ISNUMBER(IFERROR(--LEFT('6 فرق'!$D$4:$D$63,1),"x"))*'6 فرق'!$A$4:$A$63))} -> 0 | I4: =MAX('6 فرق'!$A$4:$A$63) -> 20 | J4: =MOD(HOUR(المدخلات!$B$5)-1,12)+1&":"&TEXT(MINUTE(المدخلات!$B$5),"00")&IF(HOUR(المدخلات!$B$5)<12," ص"," م") -> 4:00 م | K4: =MOD(HOUR(المدخلات!$B$5+((المدخلات!$B$9-1)*المدخلات!$B$8+المدخلات!$B$6)/1440)-1,12)+1&":"&TEXT(MINUTE(المدخلات!$B$5+((المدخلات!$B$9-1)*المدخلات!$B$8+المدخلات!$B$6)/1440),"00")&IF(HOUR(المدخلات!$B$5+((المدخلات!$B$9-1)*المدخلات!$B$8+المدخلات!$B$6)/1440)<12," ص"," م") -> 8:35 م | L4: =MAX('6 فرق'!$C$4:$C$63) -> 1
A5: 7 | B5: {=ROUND(SUMPRODUCT(1/COUNTIF('بيانات الفرق U13'!$G$3:$G$9,'بيانات الفرق U13'!$G$3:$G$9)),0)} -> 1 | C5: {=_xlfn.TEXTJOIN(" + ",TRUE,_xlfn._xlws.SORT(COUNTIF('بيانات الفرق U13'!$G$3:$G$9,"المجموعة "&_xlfn.SEQUENCE(B5))))} -> 7 | D5: {=_xlfn.LET(_xlpm.gs,_xlfn.SEQUENCE(B5),_xlpm.ln,_xlfn.MAXIFS('بيانات الفرق U13'!$I$3:$I$9,'بيانات الفرق U13'!$G$3:$G$9,"المجموعة "&_xlpm.gs),_xlpm.mn,_xlfn.MINIFS('بيانات الفرق U13'!$H$3:$H$9,'بيانات الفرق U13'!$G$3:$G$9,"المجموعة "&_xlpm.gs),_xlpm.mx,_xlfn.MAXIFS('بيانات الفرق U13'!$H$3:$H$9,'بيانات الفرق U13'!$G$3:$G$9,"المجموعة "&_xlpm.gs),_xlpm.lo,FLOOR(_xlpm.mn/_xlpm.ln,1),_xlpm.hi,CEILING(_xlpm.mx/_xlpm.ln,1),_xlpm.t,IF(_xlpm.lo=_xlpm.hi,_xlpm.lo&"",_xlpm.lo&"–"&_xlpm.hi),_xlfn.TEXTJOIN(" + ",TRUE,_xlfn.SORTBY(_xlpm.t,_xlpm.ln,1)))} -> 3 | E5: {=_xlfn.LET(_xlpm.gs,_xlfn.SEQUENCE(B5),_xlpm.ln,_xlfn.MAXIFS('بيانات الفرق U13'!$I$3:$I$9,'بيانات الفرق U13'!$G$3:$G$9,"المجموعة "&_xlpm.gs),_xlpm.mn,_xlfn.MINIFS('بيانات الفرق U13'!$H$3:$H$9,'بيانات الفرق U13'!$G$3:$G$9,"المجموعة "&_xlpm.gs),_xlpm.mx,_xlfn.MAXIFS('بيانات الفرق U13'!$H$3:$H$9,'بيانات الفرق U13'!$G$3:$G$9,"المجموعة "&_xlpm.gs),_xlpm.t,IF(_xlpm.mn=_xlpm.mx,_xlpm.mn&"",_xlpm.mn&"–"&_xlpm.mx),_xlfn.TEXTJOIN(" + ",TRUE,_xlfn.SORTBY(_xlpm.t,_xlpm.ln,1)))} -> 18 | F5: =IF(H5=0,"—",IF(H5=1,"نهائي مباشر",IF(H5=2,"نصف نهائي ثم نهائي","ربع نهائي ثم نصف نهائي ثم نهائي"))) -> — | G5: =I5-H5 -> 21 | H5: {=MAX('7 فرق'!$A$4:$A$66)-SUMPRODUCT(MAX(ISNUMBER(IFERROR(--LEFT('7 فرق'!$D$4:$D$66,1),"x"))*'7 فرق'!$A$4:$A$66))} -> 0 | I5: =MAX('7 فرق'!$A$4:$A$66) -> 21 | J5: =MOD(HOUR(المدخلات!$B$5)-1,12)+1&":"&TEXT(MINUTE(المدخلات!$B$5),"00")&IF(HOUR(المدخلات!$B$5)<12," ص"," م") -> 4:00 م | K5: =MOD(HOUR(المدخلات!$B$5+((المدخلات!$B$9-1)*المدخلات!$B$8+المدخلات!$B$6)/1440)-1,12)+1&":"&TEXT(MINUTE(المدخلات!$B$5+((المدخلات!$B$9-1)*المدخلات!$B$8+المدخلات!$B$6)/1440),"00")&IF(HOUR(المدخلات!$B$5+((المدخلات!$B$9-1)*المدخلات!$B$8+المدخلات!$B$6)/1440)<12," ص"," م") -> 8:35 م | L5: =MAX('7 فرق'!$C$4:$C$66) -> 1
A6: 8 | B6: {=ROUND(SUMPRODUCT(1/COUNTIF('بيانات الفرق U13'!$L$3:$L$10,'بيانات الفرق U13'!$L$3:$L$10)),0)} -> 1 | C6: {=_xlfn.TEXTJOIN(" + ",TRUE,_xlfn._xlws.SORT(COUNTIF('بيانات الفرق U13'!$L$3:$L$10,"المجموعة "&_xlfn.SEQUENCE(B6))))} -> 8 | D6: {=_xlfn.LET(_xlpm.gs,_xlfn.SEQUENCE(B6),_xlpm.ln,_xlfn.MAXIFS('بيانات الفرق U13'!$N$3:$N$10,'بيانات الفرق U13'!$L$3:$L$10,"المجموعة "&_xlpm.gs),_xlpm.mn,_xlfn.MINIFS('بيانات الفرق U13'!$M$3:$M$10,'بيانات الفرق U13'!$L$3:$L$10,"المجموعة "&_xlpm.gs),_xlpm.mx,_xlfn.MAXIFS('بيانات الفرق U13'!$M$3:$M$10,'بيانات الفرق U13'!$L$3:$L$10,"المجموعة "&_xlpm.gs),_xlpm.lo,FLOOR(_xlpm.mn/_xlpm.ln,1),_xlpm.hi,CEILING(_xlpm.mx/_xlpm.ln,1),_xlpm.t,IF(_xlpm.lo=_xlpm.hi,_xlpm.lo&"",_xlpm.lo&"–"&_xlpm.hi),_xlfn.TEXTJOIN(" + ",TRUE,_xlfn.SORTBY(_xlpm.t,_xlpm.ln,1)))} -> 3 | E6: {=_xlfn.LET(_xlpm.gs,_xlfn.SEQUENCE(B6),_xlpm.ln,_xlfn.MAXIFS('بيانات الفرق U13'!$N$3:$N$10,'بيانات الفرق U13'!$L$3:$L$10,"المجموعة "&_xlpm.gs),_xlpm.mn,_xlfn.MINIFS('بيانات الفرق U13'!$M$3:$M$10,'بيانات الفرق U13'!$L$3:$L$10,"المجموعة "&_xlpm.gs),_xlpm.mx,_xlfn.MAXIFS('بيانات الفرق U13'!$M$3:$M$10,'بيانات الفرق U13'!$L$3:$L$10,"المجموعة "&_xlpm.gs),_xlpm.t,IF(_xlpm.mn=_xlpm.mx,_xlpm.mn&"",_xlpm.mn&"–"&_xlpm.mx),_xlfn.TEXTJOIN(" + ",TRUE,_xlfn.SORTBY(_xlpm.t,_xlpm.ln,1)))} -> 21 | F6: =IF(H6=0,"—",IF(H6=1,"نهائي مباشر",IF(H6=2,"نصف نهائي ثم نهائي","ربع نهائي ثم نصف نهائي ثم نهائي"))) -> — | G6: =I6-H6 -> 21 | H6: {=MAX('8 فرق'!$A$4:$A$87)-SUMPRODUCT(MAX(ISNUMBER(IFERROR(--LEFT('8 فرق'!$D$4:$D$87,1),"x"))*'8 فرق'!$A$4:$A$87))} -> 0 | I6: =MAX('8 فرق'!$A$4:$A$87) -> 21 | J6: =MOD(HOUR(المدخلات!$B$5)-1,12)+1&":"&TEXT(MINUTE(المدخلات!$B$5),"00")&IF(HOUR(المدخلات!$B$5)<12," ص"," م") -> 4:00 م | K6: =MOD(HOUR(المدخلات!$B$5+((المدخلات!$B$9-1)*المدخلات!$B$8+المدخلات!$B$6)/1440)-1,12)+1&":"&TEXT(MINUTE(المدخلات!$B$5+((المدخلات!$B$9-1)*المدخلات!$B$8+المدخلات!$B$6)/1440),"00")&IF(HOUR(المدخلات!$B$5+((المدخلات!$B$9-1)*المدخلات!$B$8+المدخلات!$B$6)/1440)<12," ص"," م") -> 8:35 م | L6: =MAX('8 فرق'!$C$4:$C$87) -> 2
A7: 9 | B7: {=ROUND(SUMPRODUCT(1/COUNTIF('بيانات الفرق U13'!$Q$3:$Q$11,'بيانات الفرق U13'!$Q$3:$Q$11)),0)} -> 1 | C7: {=_xlfn.TEXTJOIN(" + ",TRUE,_xlfn._xlws.SORT(COUNTIF('بيانات الفرق U13'!$Q$3:$Q$11,"المجموعة "&_xlfn.SEQUENCE(B7))))} -> 9 | D7: {=_xlfn.LET(_xlpm.gs,_xlfn.SEQUENCE(B7),_xlpm.ln,_xlfn.MAXIFS('بيانات الفرق U13'!$S$3:$S$11,'بيانات الفرق U13'!$Q$3:$Q$11,"المجموعة "&_xlpm.gs),_xlpm.mn,_xlfn.MINIFS('بيانات الفرق U13'!$R$3:$R$11,'بيانات الفرق U13'!$Q$3:$Q$11,"المجموعة "&_xlpm.gs),_xlpm.mx,_xlfn.MAXIFS('بيانات الفرق U13'!$R$3:$R$11,'بيانات الفرق U13'!$Q$3:$Q$11,"المجموعة "&_xlpm.gs),_xlpm.lo,FLOOR(_xlpm.mn/_xlpm.ln,1),_xlpm.hi,CEILING(_xlpm.mx/_xlpm.ln,1),_xlpm.t,IF(_xlpm.lo=_xlpm.hi,_xlpm.lo&"",_xlpm.lo&"–"&_xlpm.hi),_xlfn.TEXTJOIN(" + ",TRUE,_xlfn.SORTBY(_xlpm.t,_xlpm.ln,1)))} -> 2–3 | E7: {=_xlfn.LET(_xlpm.gs,_xlfn.SEQUENCE(B7),_xlpm.ln,_xlfn.MAXIFS('بيانات الفرق U13'!$S$3:$S$11,'بيانات الفرق U13'!$Q$3:$Q$11,"المجموعة "&_xlpm.gs),_xlpm.mn,_xlfn.MINIFS('بيانات الفرق U13'!$R$3:$R$11,'بيانات الفرق U13'!$Q$3:$Q$11,"المجموعة "&_xlpm.gs),_xlpm.mx,_xlfn.MAXIFS('بيانات الفرق U13'!$R$3:$R$11,'بيانات الفرق U13'!$Q$3:$Q$11,"المجموعة "&_xlpm.gs),_xlpm.t,IF(_xlpm.mn=_xlpm.mx,_xlpm.mn&"",_xlpm.mn&"–"&_xlpm.mx),_xlfn.TEXTJOIN(" + ",TRUE,_xlfn.SORTBY(_xlpm.t,_xlpm.ln,1)))} -> 18 | F7: =IF(H7=0,"—",IF(H7=1,"نهائي مباشر",IF(H7=2,"نصف نهائي ثم نهائي","ربع نهائي ثم نصف نهائي ثم نهائي"))) -> — | G7: =I7-H7 -> 21 | H7: {=MAX('9 فرق'!$A$4:$A$84)-SUMPRODUCT(MAX(ISNUMBER(IFERROR(--LEFT('9 فرق'!$D$4:$D$84,1),"x"))*'9 فرق'!$A$4:$A$84))} -> 0 | I7: =MAX('9 فرق'!$A$4:$A$84) -> 21 | J7: =MOD(HOUR(المدخلات!$B$5)-1,12)+1&":"&TEXT(MINUTE(المدخلات!$B$5),"00")&IF(HOUR(المدخلات!$B$5)<12," ص"," م") -> 4:00 م | K7: =MOD(HOUR(المدخلات!$B$5+((المدخلات!$B$9-1)*المدخلات!$B$8+المدخلات!$B$6)/1440)-1,12)+1&":"&TEXT(MINUTE(المدخلات!$B$5+((المدخلات!$B$9-1)*المدخلات!$B$8+المدخلات!$B$6)/1440),"00")&IF(HOUR(المدخلات!$B$5+((المدخلات!$B$9-1)*المدخلات!$B$8+المدخلات!$B$6)/1440)<12," ص"," م") -> 8:35 م | L7: =MAX('9 فرق'!$C$4:$C$84) -> 2
A8: 11 | B8: {=ROUND(SUMPRODUCT(1/COUNTIF('بيانات الفرق U13'!$V$3:$V$13,'بيانات الفرق U13'!$V$3:$V$13)),0)} -> 1 | C8: {=_xlfn.TEXTJOIN(" + ",TRUE,_xlfn._xlws.SORT(COUNTIF('بيانات الفرق U13'!$V$3:$V$13,"المجموعة "&_xlfn.SEQUENCE(B8))))} -> 11 | D8: {=_xlfn.LET(_xlpm.gs,_xlfn.SEQUENCE(B8),_xlpm.ln,_xlfn.MAXIFS('بيانات الفرق U13'!$X$3:$X$13,'بيانات الفرق U13'!$V$3:$V$13,"المجموعة "&_xlpm.gs),_xlpm.mn,_xlfn.MINIFS('بيانات الفرق U13'!$W$3:$W$13,'بيانات الفرق U13'!$V$3:$V$13,"المجموعة "&_xlpm.gs),_xlpm.mx,_xlfn.MAXIFS('بيانات الفرق U13'!$W$3:$W$13,'بيانات الفرق U13'!$V$3:$V$13,"المجموعة "&_xlpm.gs),_xlpm.lo,FLOOR(_xlpm.mn/_xlpm.ln,1),_xlpm.hi,CEILING(_xlpm.mx/_xlpm.ln,1),_xlpm.t,IF(_xlpm.lo=_xlpm.hi,_xlpm.lo&"",_xlpm.lo&"–"&_xlpm.hi),_xlfn.TEXTJOIN(" + ",TRUE,_xlfn.SORTBY(_xlpm.t,_xlpm.ln,1)))} -> 2 | E8: {=_xlfn.LET(_xlpm.gs,_xlfn.SEQUENCE(B8),_xlpm.ln,_xlfn.MAXIFS('بيانات الفرق U13'!$X$3:$X$13,'بيانات الفرق U13'!$V$3:$V$13,"المجموعة "&_xlpm.gs),_xlpm.mn,_xlfn.MINIFS('بيانات الفرق U13'!$W$3:$W$13,'بيانات الفرق U13'!$V$3:$V$13,"المجموعة "&_xlpm.gs),_xlpm.mx,_xlfn.MAXIFS('بيانات الفرق U13'!$W$3:$W$13,'بيانات الفرق U13'!$V$3:$V$13,"المجموعة "&_xlpm.gs),_xlpm.t,IF(_xlpm.mn=_xlpm.mx,_xlpm.mn&"",_xlpm.mn&"–"&_xlpm.mx),_xlfn.TEXTJOIN(" + ",TRUE,_xlfn.SORTBY(_xlpm.t,_xlpm.ln,1)))} -> 20 | F8: =IF(H8=0,"—",IF(H8=1,"نهائي مباشر",IF(H8=2,"نصف نهائي ثم نهائي","ربع نهائي ثم نصف نهائي ثم نهائي"))) -> — | G8: =I8-H8 -> 22 | H8: {=MAX('11 فريق'!$A$4:$A$113)-SUMPRODUCT(MAX(ISNUMBER(IFERROR(--LEFT('11 فريق'!$D$4:$D$113,1),"x"))*'11 فريق'!$A$4:$A$113))} -> 0 | I8: =MAX('11 فريق'!$A$4:$A$113) -> 22 | J8: =MOD(HOUR(المدخلات!$B$5)-1,12)+1&":"&TEXT(MINUTE(المدخلات!$B$5),"00")&IF(HOUR(المدخلات!$B$5)<12," ص"," م") -> 4:00 م | K8: =MOD(HOUR(المدخلات!$B$5+((المدخلات!$B$9-1)*المدخلات!$B$8+المدخلات!$B$6)/1440)-1,12)+1&":"&TEXT(MINUTE(المدخلات!$B$5+((المدخلات!$B$9-1)*المدخلات!$B$8+المدخلات!$B$6)/1440),"00")&IF(HOUR(المدخلات!$B$5+((المدخلات!$B$9-1)*المدخلات!$B$8+المدخلات!$B$6)/1440)<12," ص"," م") -> 8:35 م | L8: =MAX('11 فريق'!$C$4:$C$113) -> 2
A9: 13 | B9: {=ROUND(SUMPRODUCT(1/COUNTIF('بيانات الفرق U13'!$AA$3:$AA$15,'بيانات الفرق U13'!$AA$3:$AA$15)),0)} -> 2 | C9: {=_xlfn.TEXTJOIN(" + ",TRUE,_xlfn._xlws.SORT(COUNTIF('بيانات الفرق U13'!$AA$3:$AA$15,"المجموعة "&_xlfn.SEQUENCE(B9))))} -> 6 + 7 | D9: {=_xlfn.LET(_xlpm.gs,_xlfn.SEQUENCE(B9),_xlpm.ln,_xlfn.MAXIFS('بيانات الفرق U13'!$AC$3:$AC$15,'بيانات الفرق U13'!$AA$3:$AA$15,"المجموعة "&_xlpm.gs),_xlpm.mn,_xlfn.MINIFS('بيانات الفرق U13'!$AB$3:$AB$15,'بيانات الفرق U13'!$AA$3:$AA$15,"المجموعة "&_xlpm.gs),_xlpm.mx,_xlfn.MAXIFS('بيانات الفرق U13'!$AB$3:$AB$15,'بيانات الفرق U13'!$AA$3:$AA$15,"المجموعة "&_xlpm.gs),_xlpm.lo,FLOOR(_xlpm.mn/_xlpm.ln,1),_xlpm.hi,CEILING(_xlpm.mx/_xlpm.ln,1),_xlpm.t,IF(_xlpm.lo=_xlpm.hi,_xlpm.lo&"",_xlpm.lo&"–"&_xlpm.hi),_xlfn.TEXTJOIN(" + ",TRUE,_xlfn.SORTBY(_xlpm.t,_xlpm.ln,1)))} -> 4 + 3 | E9: {=_xlfn.LET(_xlpm.gs,_xlfn.SEQUENCE(B9),_xlpm.ln,_xlfn.MAXIFS('بيانات الفرق U13'!$AC$3:$AC$15,'بيانات الفرق U13'!$AA$3:$AA$15,"المجموعة "&_xlpm.gs),_xlpm.mn,_xlfn.MINIFS('بيانات الفرق U13'!$AB$3:$AB$15,'بيانات الفرق U13'!$AA$3:$AA$15,"المجموعة "&_xlpm.gs),_xlpm.mx,_xlfn.MAXIFS('بيانات الفرق U13'!$AB$3:$AB$15,'بيانات الفرق U13'!$AA$3:$AA$15,"المجموعة "&_xlpm.gs),_xlpm.t,IF(_xlpm.mn=_xlpm.mx,_xlpm.mn&"",_xlpm.mn&"–"&_xlpm.mx),_xlfn.TEXTJOIN(" + ",TRUE,_xlfn.SORTBY(_xlpm.t,_xlpm.ln,1)))} -> 20 + 18 | F9: =IF(H9=0,"—",IF(H9=1,"نهائي مباشر",IF(H9=2,"نصف نهائي ثم نهائي","ربع نهائي ثم نصف نهائي ثم نهائي"))) -> نهائي مباشر | G9: =I9-H9 -> 21 | H9: {=MAX('13 فريق'!$A$4:$A$127)-SUMPRODUCT(MAX(ISNUMBER(IFERROR(--LEFT('13 فريق'!$D$4:$D$127,1),"x"))*'13 فريق'!$A$4:$A$127))} -> 1 | I9: =MAX('13 فريق'!$A$4:$A$127) -> 22 | J9: =MOD(HOUR(المدخلات!$B$5)-1,12)+1&":"&TEXT(MINUTE(المدخلات!$B$5),"00")&IF(HOUR(المدخلات!$B$5)<12," ص"," م") -> 4:00 م | K9: =MOD(HOUR(المدخلات!$B$5+((المدخلات!$B$9-1)*المدخلات!$B$8+المدخلات!$B$6)/1440)-1,12)+1&":"&TEXT(MINUTE(المدخلات!$B$5+((المدخلات!$B$9-1)*المدخلات!$B$8+المدخلات!$B$6)/1440),"00")&IF(HOUR(المدخلات!$B$5+((المدخلات!$B$9-1)*المدخلات!$B$8+المدخلات!$B$6)/1440)<12," ص"," م") -> 8:35 م | L9: =MAX('13 فريق'!$C$4:$C$127) -> 2
A10: 14 | B10: {=ROUND(SUMPRODUCT(1/COUNTIF('بيانات الفرق U13'!$AF$3:$AF$16,'بيانات الفرق U13'!$AF$3:$AF$16)),0)} -> 2 | C10: {=_xlfn.TEXTJOIN(" + ",TRUE,_xlfn._xlws.SORT(COUNTIF('بيانات الفرق U13'!$AF$3:$AF$16,"المجموعة "&_xlfn.SEQUENCE(B10))))} -> 6 + 8 | D10: {=_xlfn.LET(_xlpm.gs,_xlfn.SEQUENCE(B10),_xlpm.ln,_xlfn.MAXIFS('بيانات الفرق U13'!$AH$3:$AH$16,'بيانات الفرق U13'!$AF$3:$AF$16,"المجموعة "&_xlpm.gs),_xlpm.mn,_xlfn.MINIFS('بيانات الفرق U13'!$AG$3:$AG$16,'بيانات الفرق U13'!$AF$3:$AF$16,"المجموعة "&_xlpm.gs),_xlpm.mx,_xlfn.MAXIFS('بيانات الفرق U13'!$AG$3:$AG$16,'بيانات الفرق U13'!$AF$3:$AF$16,"المجموعة "&_xlpm.gs),_xlpm.lo,FLOOR(_xlpm.mn/_xlpm.ln,1),_xlpm.hi,CEILING(_xlpm.mx/_xlpm.ln,1),_xlpm.t,IF(_xlpm.lo=_xlpm.hi,_xlpm.lo&"",_xlpm.lo&"–"&_xlpm.hi),_xlfn.TEXTJOIN(" + ",TRUE,_xlfn.SORTBY(_xlpm.t,_xlpm.ln,1)))} -> 4 + 3 | E10: {=_xlfn.LET(_xlpm.gs,_xlfn.SEQUENCE(B10),_xlpm.ln,_xlfn.MAXIFS('بيانات الفرق U13'!$AH$3:$AH$16,'بيانات الفرق U13'!$AF$3:$AF$16,"المجموعة "&_xlpm.gs),_xlpm.mn,_xlfn.MINIFS('بيانات الفرق U13'!$AG$3:$AG$16,'بيانات الفرق U13'!$AF$3:$AF$16,"المجموعة "&_xlpm.gs),_xlpm.mx,_xlfn.MAXIFS('بيانات الفرق U13'!$AG$3:$AG$16,'بيانات الفرق U13'!$AF$3:$AF$16,"المجموعة "&_xlpm.gs),_xlpm.t,IF(_xlpm.mn=_xlpm.mx,_xlpm.mn&"",_xlpm.mn&"–"&_xlpm.mx),_xlfn.TEXTJOIN(" + ",TRUE,_xlfn.SORTBY(_xlpm.t,_xlpm.ln,1)))} -> 20 + 21 | F10: =IF(H10=0,"—",IF(H10=1,"نهائي مباشر",IF(H10=2,"نصف نهائي ثم نهائي","ربع نهائي ثم نصف نهائي ثم نهائي"))) -> نهائي مباشر | G10: =I10-H10 -> 21 | H10: {=MAX('14 فريق'!$A$4:$A$148)-SUMPRODUCT(MAX(ISNUMBER(IFERROR(--LEFT('14 فريق'!$D$4:$D$148,1),"x"))*'14 فريق'!$A$4:$A$148))} -> 1 | I10: =MAX('14 فريق'!$A$4:$A$148) -> 22 | J10: =MOD(HOUR(المدخلات!$B$5)-1,12)+1&":"&TEXT(MINUTE(المدخلات!$B$5),"00")&IF(HOUR(المدخلات!$B$5)<12," ص"," م") -> 4:00 م | K10: =MOD(HOUR(المدخلات!$B$5+((المدخلات!$B$9-1)*المدخلات!$B$8+المدخلات!$B$6)/1440)-1,12)+1&":"&TEXT(MINUTE(المدخلات!$B$5+((المدخلات!$B$9-1)*المدخلات!$B$8+المدخلات!$B$6)/1440),"00")&IF(HOUR(المدخلات!$B$5+((المدخلات!$B$9-1)*المدخلات!$B$8+المدخلات!$B$6)/1440)<12," ص"," م") -> 8:35 م | L10: =MAX('14 فريق'!$C$4:$C$148) -> 3
A11: 15 | B11: {=ROUND(SUMPRODUCT(1/COUNTIF('بيانات الفرق U13'!$AK$3:$AK$17,'بيانات الفرق U13'!$AK$3:$AK$17)),0)} -> 2 | C11: {=_xlfn.TEXTJOIN(" + ",TRUE,_xlfn._xlws.SORT(COUNTIF('بيانات الفرق U13'!$AK$3:$AK$17,"المجموعة "&_xlfn.SEQUENCE(B11))))} -> 7 + 8 | D11: {=_xlfn.LET(_xlpm.gs,_xlfn.SEQUENCE(B11),_xlpm.ln,_xlfn.MAXIFS('بيانات الفرق U13'!$AM$3:$AM$17,'بيانات الفرق U13'!$AK$3:$AK$17,"المجموعة "&_xlpm.gs),_xlpm.mn,_xlfn.MINIFS('بيانات الفرق U13'!$AL$3:$AL$17,'بيانات الفرق U13'!$AK$3:$AK$17,"المجموعة "&_xlpm.gs),_xlpm.mx,_xlfn.MAXIFS('بيانات الفرق U13'!$AL$3:$AL$17,'بيانات الفرق U13'!$AK$3:$AK$17,"المجموعة "&_xlpm.gs),_xlpm.lo,FLOOR(_xlpm.mn/_xlpm.ln,1),_xlpm.hi,CEILING(_xlpm.mx/_xlpm.ln,1),_xlpm.t,IF(_xlpm.lo=_xlpm.hi,_xlpm.lo&"",_xlpm.lo&"–"&_xlpm.hi),_xlfn.TEXTJOIN(" + ",TRUE,_xlfn.SORTBY(_xlpm.t,_xlpm.ln,1)))} -> 3 + 3 | E11: {=_xlfn.LET(_xlpm.gs,_xlfn.SEQUENCE(B11),_xlpm.ln,_xlfn.MAXIFS('بيانات الفرق U13'!$AM$3:$AM$17,'بيانات الفرق U13'!$AK$3:$AK$17,"المجموعة "&_xlpm.gs),_xlpm.mn,_xlfn.MINIFS('بيانات الفرق U13'!$AL$3:$AL$17,'بيانات الفرق U13'!$AK$3:$AK$17,"المجموعة "&_xlpm.gs),_xlpm.mx,_xlfn.MAXIFS('بيانات الفرق U13'!$AL$3:$AL$17,'بيانات الفرق U13'!$AK$3:$AK$17,"المجموعة "&_xlpm.gs),_xlpm.t,IF(_xlpm.mn=_xlpm.mx,_xlpm.mn&"",_xlpm.mn&"–"&_xlpm.mx),_xlfn.TEXTJOIN(" + ",TRUE,_xlfn.SORTBY(_xlpm.t,_xlpm.ln,1)))} -> 18 + 21 | F11: =IF(H11=0,"—",IF(H11=1,"نهائي مباشر",IF(H11=2,"نصف نهائي ثم نهائي","ربع نهائي ثم نصف نهائي ثم نهائي"))) -> نهائي مباشر | G11: =I11-H11 -> 21 | H11: {=MAX('15 فريق'!$A$4:$A$151)-SUMPRODUCT(MAX(ISNUMBER(IFERROR(--LEFT('15 فريق'!$D$4:$D$151,1),"x"))*'15 فريق'!$A$4:$A$151))} -> 1 | I11: =MAX('15 فريق'!$A$4:$A$151) -> 22 | J11: =MOD(HOUR(المدخلات!$B$5)-1,12)+1&":"&TEXT(MINUTE(المدخلات!$B$5),"00")&IF(HOUR(المدخلات!$B$5)<12," ص"," م") -> 4:00 م | K11: =MOD(HOUR(المدخلات!$B$5+((المدخلات!$B$9-1)*المدخلات!$B$8+المدخلات!$B$6)/1440)-1,12)+1&":"&TEXT(MINUTE(المدخلات!$B$5+((المدخلات!$B$9-1)*المدخلات!$B$8+المدخلات!$B$6)/1440),"00")&IF(HOUR(المدخلات!$B$5+((المدخلات!$B$9-1)*المدخلات!$B$8+المدخلات!$B$6)/1440)<12," ص"," م") -> 8:35 م | L11: =MAX('15 فريق'!$C$4:$C$151) -> 3
A12: 16 | B12: {=ROUND(SUMPRODUCT(1/COUNTIF('بيانات الفرق U13'!$AP$3:$AP$18,'بيانات الفرق U13'!$AP$3:$AP$18)),0)} -> 2 | C12: {=_xlfn.TEXTJOIN(" + ",TRUE,_xlfn._xlws.SORT(COUNTIF('بيانات الفرق U13'!$AP$3:$AP$18,"المجموعة "&_xlfn.SEQUENCE(B12))))} -> 8 + 8 | D12: {=_xlfn.LET(_xlpm.gs,_xlfn.SEQUENCE(B12),_xlpm.ln,_xlfn.MAXIFS('بيانات الفرق U13'!$AR$3:$AR$18,'بيانات الفرق U13'!$AP$3:$AP$18,"المجموعة "&_xlpm.gs),_xlpm.mn,_xlfn.MINIFS('بيانات الفرق U13'!$AQ$3:$AQ$18,'بيانات الفرق U13'!$AP$3:$AP$18,"المجموعة "&_xlpm.gs),_xlpm.mx,_xlfn.MAXIFS('بيانات الفرق U13'!$AQ$3:$AQ$18,'بيانات الفرق U13'!$AP$3:$AP$18,"المجموعة "&_xlpm.gs),_xlpm.lo,FLOOR(_xlpm.mn/_xlpm.ln,1),_xlpm.hi,CEILING(_xlpm.mx/_xlpm.ln,1),_xlpm.t,IF(_xlpm.lo=_xlpm.hi,_xlpm.lo&"",_xlpm.lo&"–"&_xlpm.hi),_xlfn.TEXTJOIN(" + ",TRUE,_xlfn.SORTBY(_xlpm.t,_xlpm.ln,1)))} -> 3 + 3 | E12: {=_xlfn.LET(_xlpm.gs,_xlfn.SEQUENCE(B12),_xlpm.ln,_xlfn.MAXIFS('بيانات الفرق U13'!$AR$3:$AR$18,'بيانات الفرق U13'!$AP$3:$AP$18,"المجموعة "&_xlpm.gs),_xlpm.mn,_xlfn.MINIFS('بيانات الفرق U13'!$AQ$3:$AQ$18,'بيانات الفرق U13'!$AP$3:$AP$18,"المجموعة "&_xlpm.gs),_xlpm.mx,_xlfn.MAXIFS('بيانات الفرق U13'!$AQ$3:$AQ$18,'بيانات الفرق U13'!$AP$3:$AP$18,"المجموعة "&_xlpm.gs),_xlpm.t,IF(_xlpm.mn=_xlpm.mx,_xlpm.mn&"",_xlpm.mn&"–"&_xlpm.mx),_xlfn.TEXTJOIN(" + ",TRUE,_xlfn.SORTBY(_xlpm.t,_xlpm.ln,1)))} -> 21 + 21 | F12: =IF(H12=0,"—",IF(H12=1,"نهائي مباشر",IF(H12=2,"نصف نهائي ثم نهائي","ربع نهائي ثم نصف نهائي ثم نهائي"))) -> نهائي مباشر | G12: =I12-H12 -> 21 | H12: {=MAX('16 فريق'!$A$4:$A$172)-SUMPRODUCT(MAX(ISNUMBER(IFERROR(--LEFT('16 فريق'!$D$4:$D$172,1),"x"))*'16 فريق'!$A$4:$A$172))} -> 1 | I12: =MAX('16 فريق'!$A$4:$A$172) -> 22 | J12: =MOD(HOUR(المدخلات!$B$5)-1,12)+1&":"&TEXT(MINUTE(المدخلات!$B$5),"00")&IF(HOUR(المدخلات!$B$5)<12," ص"," م") -> 4:00 م | K12: =MOD(HOUR(المدخلات!$B$5+((المدخلات!$B$9-1)*المدخلات!$B$8+المدخلات!$B$6)/1440)-1,12)+1&":"&TEXT(MINUTE(المدخلات!$B$5+((المدخلات!$B$9-1)*المدخلات!$B$8+المدخلات!$B$6)/1440),"00")&IF(HOUR(المدخلات!$B$5+((المدخلات!$B$9-1)*المدخلات!$B$8+المدخلات!$B$6)/1440)<12," ص"," م") -> 8:35 م | L12: =MAX('16 فريق'!$C$4:$C$172) -> 3
A13: 17 | B13: {=ROUND(SUMPRODUCT(1/COUNTIF('بيانات الفرق U13'!$AU$3:$AU$19,'بيانات الفرق U13'!$AU$3:$AU$19)),0)} -> 2 | C13: {=_xlfn.TEXTJOIN(" + ",TRUE,_xlfn._xlws.SORT(COUNTIF('بيانات الفرق U13'!$AU$3:$AU$19,"المجموعة "&_xlfn.SEQUENCE(B13))))} -> 7 + 10 | D13: {=_xlfn.LET(_xlpm.gs,_xlfn.SEQUENCE(B13),_xlpm.ln,_xlfn.MAXIFS('بيانات الفرق U13'!$AW$3:$AW$19,'بيانات الفرق U13'!$AU$3:$AU$19,"المجموعة "&_xlpm.gs),_xlpm.mn,_xlfn.MINIFS('بيانات الفرق U13'!$AV$3:$AV$19,'بيانات الفرق U13'!$AU$3:$AU$19,"المجموعة "&_xlpm.gs),_xlpm.mx,_xlfn.MAXIFS('بيانات الفرق U13'!$AV$3:$AV$19,'بيانات الفرق U13'!$AU$3:$AU$19,"المجموعة "&_xlpm.gs),_xlpm.lo,FLOOR(_xlpm.mn/_xlpm.ln,1),_xlpm.hi,CEILING(_xlpm.mx/_xlpm.ln,1),_xlpm.t,IF(_xlpm.lo=_xlpm.hi,_xlpm.lo&"",_xlpm.lo&"–"&_xlpm.hi),_xlfn.TEXTJOIN(" + ",TRUE,_xlfn.SORTBY(_xlpm.t,_xlpm.ln,1)))} -> 3 + 2 | E13: {=_xlfn.LET(_xlpm.gs,_xlfn.SEQUENCE(B13),_xlpm.ln,_xlfn.MAXIFS('بيانات الفرق U13'!$AW$3:$AW$19,'بيانات الفرق U13'!$AU$3:$AU$19,"المجموعة "&_xlpm.gs),_xlpm.mn,_xlfn.MINIFS('بيانات الفرق U13'!$AV$3:$AV$19,'بيانات الفرق U13'!$AU$3:$AU$19,"المجموعة "&_xlpm.gs),_xlpm.mx,_xlfn.MAXIFS('بيانات الفرق U13'!$AV$3:$AV$19,'بيانات الفرق U13'!$AU$3:$AU$19,"المجموعة "&_xlpm.gs),_xlpm.t,IF(_xlpm.mn=_xlpm.mx,_xlpm.mn&"",_xlpm.mn&"–"&_xlpm.mx),_xlfn.TEXTJOIN(" + ",TRUE,_xlfn.SORTBY(_xlpm.t,_xlpm.ln,1)))} -> 18 + 18 | F13: =IF(H13=0,"—",IF(H13=1,"نهائي مباشر",IF(H13=2,"نصف نهائي ثم نهائي","ربع نهائي ثم نصف نهائي ثم نهائي"))) -> نهائي مباشر | G13: =I13-H13 -> 21 | H13: {=MAX('17 فريق'!$A$4:$A$157)-SUMPRODUCT(MAX(ISNUMBER(IFERROR(--LEFT('17 فريق'!$D$4:$D$157,1),"x"))*'17 فريق'!$A$4:$A$157))} -> 1 | I13: =MAX('17 فريق'!$A$4:$A$157) -> 22 | J13: =MOD(HOUR(المدخلات!$B$5)-1,12)+1&":"&TEXT(MINUTE(المدخلات!$B$5),"00")&IF(HOUR(المدخلات!$B$5)<12," ص"," م") -> 4:00 م | K13: =MOD(HOUR(المدخلات!$B$5+((المدخلات!$B$9-1)*المدخلات!$B$8+المدخلات!$B$6)/1440)-1,12)+1&":"&TEXT(MINUTE(المدخلات!$B$5+((المدخلات!$B$9-1)*المدخلات!$B$8+المدخلات!$B$6)/1440),"00")&IF(HOUR(المدخلات!$B$5+((المدخلات!$B$9-1)*المدخلات!$B$8+المدخلات!$B$6)/1440)<12," ص"," م") -> 8:35 م | L13: =MAX('17 فريق'!$C$4:$C$157) -> 3
A14: 18 | B14: {=ROUND(SUMPRODUCT(1/COUNTIF('بيانات الفرق U13'!$AZ$3:$AZ$20,'بيانات الفرق U13'!$AZ$3:$AZ$20)),0)} -> 3 | C14: {=_xlfn.TEXTJOIN(" + ",TRUE,_xlfn._xlws.SORT(COUNTIF('بيانات الفرق U13'!$AZ$3:$AZ$20,"المجموعة "&_xlfn.SEQUENCE(B14))))} -> 6 + 6 + 6 | D14: {=_xlfn.LET(_xlpm.gs,_xlfn.SEQUENCE(B14),_xlpm.ln,_xlfn.MAXIFS('بيانات الفرق U13'!$BB$3:$BB$20,'بيانات الفرق U13'!$AZ$3:$AZ$20,"المجموعة "&_xlpm.gs),_xlpm.mn,_xlfn.MINIFS('بيانات الفرق U13'!$BA$3:$BA$20,'بيانات الفرق U13'!$AZ$3:$AZ$20,"المجموعة "&_xlpm.gs),_xlpm.mx,_xlfn.MAXIFS('بيانات الفرق U13'!$BA$3:$BA$20,'بيانات الفرق U13'!$AZ$3:$AZ$20,"المجموعة "&_xlpm.gs),_xlpm.lo,FLOOR(_xlpm.mn/_xlpm.ln,1),_xlpm.hi,CEILING(_xlpm.mx/_xlpm.ln,1),_xlpm.t,IF(_xlpm.lo=_xlpm.hi,_xlpm.lo&"",_xlpm.lo&"–"&_xlpm.hi),_xlfn.TEXTJOIN(" + ",TRUE,_xlfn.SORTBY(_xlpm.t,_xlpm.ln,1)))} -> 4 + 4 + 4 | E14: {=_xlfn.LET(_xlpm.gs,_xlfn.SEQUENCE(B14),_xlpm.ln,_xlfn.MAXIFS('بيانات الفرق U13'!$BB$3:$BB$20,'بيانات الفرق U13'!$AZ$3:$AZ$20,"المجموعة "&_xlpm.gs),_xlpm.mn,_xlfn.MINIFS('بيانات الفرق U13'!$BA$3:$BA$20,'بيانات الفرق U13'!$AZ$3:$AZ$20,"المجموعة "&_xlpm.gs),_xlpm.mx,_xlfn.MAXIFS('بيانات الفرق U13'!$BA$3:$BA$20,'بيانات الفرق U13'!$AZ$3:$AZ$20,"المجموعة "&_xlpm.gs),_xlpm.t,IF(_xlpm.mn=_xlpm.mx,_xlpm.mn&"",_xlpm.mn&"–"&_xlpm.mx),_xlfn.TEXTJOIN(" + ",TRUE,_xlfn.SORTBY(_xlpm.t,_xlpm.ln,1)))} -> 20 + 20 + 20 | F14: =IF(H14=0,"—",IF(H14=1,"نهائي مباشر",IF(H14=2,"نصف نهائي ثم نهائي","ربع نهائي ثم نصف نهائي ثم نهائي"))) -> نصف نهائي ثم نهائي | G14: =I14-H14 -> 20 | H14: {=MAX('18 فريق'!$A$4:$A$186)-SUMPRODUCT(MAX(ISNUMBER(IFERROR(--LEFT('18 فريق'!$D$4:$D$186,1),"x"))*'18 فريق'!$A$4:$A$186))} -> 2 | I14: =MAX('18 فريق'!$A$4:$A$186) -> 22 | J14: =MOD(HOUR(المدخلات!$B$5)-1,12)+1&":"&TEXT(MINUTE(المدخلات!$B$5),"00")&IF(HOUR(المدخلات!$B$5)<12," ص"," م") -> 4:00 م | K14: =MOD(HOUR(المدخلات!$B$5+((المدخلات!$B$9-1)*المدخلات!$B$8+المدخلات!$B$6)/1440)-1,12)+1&":"&TEXT(MINUTE(المدخلات!$B$5+((المدخلات!$B$9-1)*المدخلات!$B$8+المدخلات!$B$6)/1440),"00")&IF(HOUR(المدخلات!$B$5+((المدخلات!$B$9-1)*المدخلات!$B$8+المدخلات!$B$6)/1440)<12," ص"," م") -> 8:35 م | L14: =MAX('18 فريق'!$C$4:$C$186) -> 3
A15: 20 | B15: {=ROUND(SUMPRODUCT(1/COUNTIF('بيانات الفرق U13'!$BE$3:$BE$22,'بيانات الفرق U13'!$BE$3:$BE$22)),0)} -> 1 | C15: {=_xlfn.TEXTJOIN(" + ",TRUE,_xlfn._xlws.SORT(COUNTIF('بيانات الفرق U13'!$BE$3:$BE$22,"المجموعة "&_xlfn.SEQUENCE(B15))))} -> 20 | D15: {=_xlfn.LET(_xlpm.gs,_xlfn.SEQUENCE(B15),_xlpm.ln,_xlfn.MAXIFS('بيانات الفرق U13'!$BG$3:$BG$22,'بيانات الفرق U13'!$BE$3:$BE$22,"المجموعة "&_xlpm.gs),_xlpm.mn,_xlfn.MINIFS('بيانات الفرق U13'!$BF$3:$BF$22,'بيانات الفرق U13'!$BE$3:$BE$22,"المجموعة "&_xlpm.gs),_xlpm.mx,_xlfn.MAXIFS('بيانات الفرق U13'!$BF$3:$BF$22,'بيانات الفرق U13'!$BE$3:$BE$22,"المجموعة "&_xlpm.gs),_xlpm.lo,FLOOR(_xlpm.mn/_xlpm.ln,1),_xlpm.hi,CEILING(_xlpm.mx/_xlpm.ln,1),_xlpm.t,IF(_xlpm.lo=_xlpm.hi,_xlpm.lo&"",_xlpm.lo&"–"&_xlpm.hi),_xlfn.TEXTJOIN(" + ",TRUE,_xlfn.SORTBY(_xlpm.t,_xlpm.ln,1)))} -> 1 | E15: {=_xlfn.LET(_xlpm.gs,_xlfn.SEQUENCE(B15),_xlpm.ln,_xlfn.MAXIFS('بيانات الفرق U13'!$BG$3:$BG$22,'بيانات الفرق U13'!$BE$3:$BE$22,"المجموعة "&_xlpm.gs),_xlpm.mn,_xlfn.MINIFS('بيانات الفرق U13'!$BF$3:$BF$22,'بيانات الفرق U13'!$BE$3:$BE$22,"المجموعة "&_xlpm.gs),_xlpm.mx,_xlfn.MAXIFS('بيانات الفرق U13'!$BF$3:$BF$22,'بيانات الفرق U13'!$BE$3:$BE$22,"المجموعة "&_xlpm.gs),_xlpm.t,IF(_xlpm.mn=_xlpm.mx,_xlpm.mn&"",_xlpm.mn&"–"&_xlpm.mx),_xlfn.TEXTJOIN(" + ",TRUE,_xlfn.SORTBY(_xlpm.t,_xlpm.ln,1)))} -> 19 | F15: =IF(H15=0,"—",IF(H15=1,"نهائي مباشر",IF(H15=2,"نصف نهائي ثم نهائي","ربع نهائي ثم نصف نهائي ثم نهائي"))) -> — | G15: =I15-H15 -> 19 | H15: {=MAX('20 فريق'!$A$4:$A$193)-SUMPRODUCT(MAX(ISNUMBER(IFERROR(--LEFT('20 فريق'!$D$4:$D$193,1),"x"))*'20 فريق'!$A$4:$A$193))} -> 0 | I15: =MAX('20 فريق'!$A$4:$A$193) -> 19 | J15: =MOD(HOUR(المدخلات!$B$5)-1,12)+1&":"&TEXT(MINUTE(المدخلات!$B$5),"00")&IF(HOUR(المدخلات!$B$5)<12," ص"," م") -> 4:00 م | K15: =MOD(HOUR(المدخلات!$B$5+((المدخلات!$B$9-1)*المدخلات!$B$8+المدخلات!$B$6)/1440)-1,12)+1&":"&TEXT(MINUTE(المدخلات!$B$5+((المدخلات!$B$9-1)*المدخلات!$B$8+المدخلات!$B$6)/1440),"00")&IF(HOUR(المدخلات!$B$5+((المدخلات!$B$9-1)*المدخلات!$B$8+المدخلات!$B$6)/1440)<12," ص"," م") -> 8:35 م | L15: =MAX('20 فريق'!$C$4:$C$193) -> 4
A16: 21 | B16: {=ROUND(SUMPRODUCT(1/COUNTIF('بيانات الفرق U13'!$BJ$3:$BJ$23,'بيانات الفرق U13'!$BJ$3:$BJ$23)),0)} -> 1 | C16: {=_xlfn.TEXTJOIN(" + ",TRUE,_xlfn._xlws.SORT(COUNTIF('بيانات الفرق U13'!$BJ$3:$BJ$23,"المجموعة "&_xlfn.SEQUENCE(B16))))} -> 21 | D16: {=_xlfn.LET(_xlpm.gs,_xlfn.SEQUENCE(B16),_xlpm.ln,_xlfn.MAXIFS('بيانات الفرق U13'!$BL$3:$BL$23,'بيانات الفرق U13'!$BJ$3:$BJ$23,"المجموعة "&_xlpm.gs),_xlpm.mn,_xlfn.MINIFS('بيانات الفرق U13'!$BK$3:$BK$23,'بيانات الفرق U13'!$BJ$3:$BJ$23,"المجموعة "&_xlpm.gs),_xlpm.mx,_xlfn.MAXIFS('بيانات الفرق U13'!$BK$3:$BK$23,'بيانات الفرق U13'!$BJ$3:$BJ$23,"المجموعة "&_xlpm.gs),_xlpm.lo,FLOOR(_xlpm.mn/_xlpm.ln,1),_xlpm.hi,CEILING(_xlpm.mx/_xlpm.ln,1),_xlpm.t,IF(_xlpm.lo=_xlpm.hi,_xlpm.lo&"",_xlpm.lo&"–"&_xlpm.hi),_xlfn.TEXTJOIN(" + ",TRUE,_xlfn.SORTBY(_xlpm.t,_xlpm.ln,1)))} -> 1 | E16: {=_xlfn.LET(_xlpm.gs,_xlfn.SEQUENCE(B16),_xlpm.ln,_xlfn.MAXIFS('بيانات الفرق U13'!$BL$3:$BL$23,'بيانات الفرق U13'!$BJ$3:$BJ$23,"المجموعة "&_xlpm.gs),_xlpm.mn,_xlfn.MINIFS('بيانات الفرق U13'!$BK$3:$BK$23,'بيانات الفرق U13'!$BJ$3:$BJ$23,"المجموعة "&_xlpm.gs),_xlpm.mx,_xlfn.MAXIFS('بيانات الفرق U13'!$BK$3:$BK$23,'بيانات الفرق U13'!$BJ$3:$BJ$23,"المجموعة "&_xlpm.gs),_xlpm.t,IF(_xlpm.mn=_xlpm.mx,_xlpm.mn&"",_xlpm.mn&"–"&_xlpm.mx),_xlfn.TEXTJOIN(" + ",TRUE,_xlfn.SORTBY(_xlpm.t,_xlpm.ln,1)))} -> 20 | F16: =IF(H16=0,"—",IF(H16=1,"نهائي مباشر",IF(H16=2,"نصف نهائي ثم نهائي","ربع نهائي ثم نصف نهائي ثم نهائي"))) -> — | G16: =I16-H16 -> 21 | H16: {=MAX('21 فريق'!$A$4:$A$213)-SUMPRODUCT(MAX(ISNUMBER(IFERROR(--LEFT('21 فريق'!$D$4:$D$213,1),"x"))*'21 فريق'!$A$4:$A$213))} -> 0 | I16: =MAX('21 فريق'!$A$4:$A$213) -> 21 | J16: =MOD(HOUR(المدخلات!$B$5)-1,12)+1&":"&TEXT(MINUTE(المدخلات!$B$5),"00")&IF(HOUR(المدخلات!$B$5)<12," ص"," م") -> 4:00 م | K16: =MOD(HOUR(المدخلات!$B$5+((المدخلات!$B$9-1)*المدخلات!$B$8+المدخلات!$B$6)/1440)-1,12)+1&":"&TEXT(MINUTE(المدخلات!$B$5+((المدخلات!$B$9-1)*المدخلات!$B$8+المدخلات!$B$6)/1440),"00")&IF(HOUR(المدخلات!$B$5+((المدخلات!$B$9-1)*المدخلات!$B$8+المدخلات!$B$6)/1440)<12," ص"," م") -> 8:35 م | L16: =MAX('21 فريق'!$C$4:$C$213) -> 4
A17: 25 | B17: {=ROUND(SUMPRODUCT(1/COUNTIF('بيانات الفرق U13'!$BO$3:$BO$27,'بيانات الفرق U13'!$BO$3:$BO$27)),0)} -> 2 | C17: {=_xlfn.TEXTJOIN(" + ",TRUE,_xlfn._xlws.SORT(COUNTIF('بيانات الفرق U13'!$BO$3:$BO$27,"المجموعة "&_xlfn.SEQUENCE(B17))))} -> 6 + 19 | D17: {=_xlfn.LET(_xlpm.gs,_xlfn.SEQUENCE(B17),_xlpm.ln,_xlfn.MAXIFS('بيانات الفرق U13'!$BQ$3:$BQ$27,'بيانات الفرق U13'!$BO$3:$BO$27,"المجموعة "&_xlpm.gs),_xlpm.mn,_xlfn.MINIFS('بيانات الفرق U13'!$BP$3:$BP$27,'بيانات الفرق U13'!$BO$3:$BO$27,"المجموعة "&_xlpm.gs),_xlpm.mx,_xlfn.MAXIFS('بيانات الفرق U13'!$BP$3:$BP$27,'بيانات الفرق U13'!$BO$3:$BO$27,"المجموعة "&_xlpm.gs),_xlpm.lo,FLOOR(_xlpm.mn/_xlpm.ln,1),_xlpm.hi,CEILING(_xlpm.mx/_xlpm.ln,1),_xlpm.t,IF(_xlpm.lo=_xlpm.hi,_xlpm.lo&"",_xlpm.lo&"–"&_xlpm.hi),_xlfn.TEXTJOIN(" + ",TRUE,_xlfn.SORTBY(_xlpm.t,_xlpm.ln,1)))} -> 4 + 1 | E17: {=_xlfn.LET(_xlpm.gs,_xlfn.SEQUENCE(B17),_xlpm.ln,_xlfn.MAXIFS('بيانات الفرق U13'!$BQ$3:$BQ$27,'بيانات الفرق U13'!$BO$3:$BO$27,"المجموعة "&_xlpm.gs),_xlpm.mn,_xlfn.MINIFS('بيانات الفرق U13'!$BP$3:$BP$27,'بيانات الفرق U13'!$BO$3:$BO$27,"المجموعة "&_xlpm.gs),_xlpm.mx,_xlfn.MAXIFS('بيانات الفرق U13'!$BP$3:$BP$27,'بيانات الفرق U13'!$BO$3:$BO$27,"المجموعة "&_xlpm.gs),_xlpm.t,IF(_xlpm.mn=_xlpm.mx,_xlpm.mn&"",_xlpm.mn&"–"&_xlpm.mx),_xlfn.TEXTJOIN(" + ",TRUE,_xlfn.SORTBY(_xlpm.t,_xlpm.ln,1)))} -> 20 + 18 | F17: =IF(H17=0,"—",IF(H17=1,"نهائي مباشر",IF(H17=2,"نصف نهائي ثم نهائي","ربع نهائي ثم نصف نهائي ثم نهائي"))) -> نهائي مباشر | G17: =I17-H17 -> 20 | H17: {=MAX('25 فريق'!$A$4:$A$235)-SUMPRODUCT(MAX(ISNUMBER(IFERROR(--LEFT('25 فريق'!$D$4:$D$235,1),"x"))*'25 فريق'!$A$4:$A$235))} -> 1 | I17: =MAX('25 فريق'!$A$4:$A$235) -> 21 | J17: =MOD(HOUR(المدخلات!$B$5)-1,12)+1&":"&TEXT(MINUTE(المدخلات!$B$5),"00")&IF(HOUR(المدخلات!$B$5)<12," ص"," م") -> 4:00 م | K17: =MOD(HOUR(المدخلات!$B$5+((المدخلات!$B$9-1)*المدخلات!$B$8+المدخلات!$B$6)/1440)-1,12)+1&":"&TEXT(MINUTE(المدخلات!$B$5+((المدخلات!$B$9-1)*المدخلات!$B$8+المدخلات!$B$6)/1440),"00")&IF(HOUR(المدخلات!$B$5+((المدخلات!$B$9-1)*المدخلات!$B$8+المدخلات!$B$6)/1440)<12," ص"," م") -> 8:35 م | L17: =MAX('25 فريق'!$C$4:$C$235) -> 4
A18: 34 | B18: {=ROUND(SUMPRODUCT(1/COUNTIF('بيانات الفرق U13'!$BT$3:$BT$36,'بيانات الفرق U13'!$BT$3:$BT$36)),0)} -> 3 | C18: {=_xlfn.TEXTJOIN(" + ",TRUE,_xlfn._xlws.SORT(COUNTIF('بيانات الفرق U13'!$BT$3:$BT$36,"المجموعة "&_xlfn.SEQUENCE(B18))))} -> 10 + 12 + 12 | D18: {=_xlfn.LET(_xlpm.gs,_xlfn.SEQUENCE(B18),_xlpm.ln,_xlfn.MAXIFS('بيانات الفرق U13'!$BV$3:$BV$36,'بيانات الفرق U13'!$BT$3:$BT$36,"المجموعة "&_xlpm.gs),_xlpm.mn,_xlfn.MINIFS('بيانات الفرق U13'!$BU$3:$BU$36,'بيانات الفرق U13'!$BT$3:$BT$36,"المجموعة "&_xlpm.gs),_xlpm.mx,_xlfn.MAXIFS('بيانات الفرق U13'!$BU$3:$BU$36,'بيانات الفرق U13'!$BT$3:$BT$36,"المجموعة "&_xlpm.gs),_xlpm.lo,FLOOR(_xlpm.mn/_xlpm.ln,1),_xlpm.hi,CEILING(_xlpm.mx/_xlpm.ln,1),_xlpm.t,IF(_xlpm.lo=_xlpm.hi,_xlpm.lo&"",_xlpm.lo&"–"&_xlpm.hi),_xlfn.TEXTJOIN(" + ",TRUE,_xlfn.SORTBY(_xlpm.t,_xlpm.ln,1)))} -> 2–3 + 1–2 + 1–2 | E18: {=_xlfn.LET(_xlpm.gs,_xlfn.SEQUENCE(B18),_xlpm.ln,_xlfn.MAXIFS('بيانات الفرق U13'!$BV$3:$BV$36,'بيانات الفرق U13'!$BT$3:$BT$36,"المجموعة "&_xlpm.gs),_xlpm.mn,_xlfn.MINIFS('بيانات الفرق U13'!$BU$3:$BU$36,'بيانات الفرق U13'!$BT$3:$BT$36,"المجموعة "&_xlpm.gs),_xlpm.mx,_xlfn.MAXIFS('بيانات الفرق U13'!$BU$3:$BU$36,'بيانات الفرق U13'!$BT$3:$BT$36,"المجموعة "&_xlpm.gs),_xlpm.t,IF(_xlpm.mn=_xlpm.mx,_xlpm.mn&"",_xlpm.mn&"–"&_xlpm.mx),_xlfn.TEXTJOIN(" + ",TRUE,_xlfn.SORTBY(_xlpm.t,_xlpm.ln,1)))} -> 20 + 20 + 20 | F18: =IF(H18=0,"—",IF(H18=1,"نهائي مباشر",IF(H18=2,"نصف نهائي ثم نهائي","ربع نهائي ثم نصف نهائي ثم نهائي"))) -> نصف نهائي ثم نهائي | G18: =I18-H18 -> 20 | H18: {=MAX('34 فريق'!$A$4:$A$346)-SUMPRODUCT(MAX(ISNUMBER(IFERROR(--LEFT('34 فريق'!$D$4:$D$346,1),"x"))*'34 فريق'!$A$4:$A$346))} -> 2 | I18: =MAX('34 فريق'!$A$4:$A$346) -> 22 | J18: =MOD(HOUR(المدخلات!$B$5)-1,12)+1&":"&TEXT(MINUTE(المدخلات!$B$5),"00")&IF(HOUR(المدخلات!$B$5)<12," ص"," م") -> 4:00 م | K18: =MOD(HOUR(المدخلات!$B$5+((المدخلات!$B$9-1)*المدخلات!$B$8+المدخلات!$B$6)/1440)-1,12)+1&":"&TEXT(MINUTE(المدخلات!$B$5+((المدخلات!$B$9-1)*المدخلات!$B$8+المدخلات!$B$6)/1440),"00")&IF(HOUR(المدخلات!$B$5+((المدخلات!$B$9-1)*المدخلات!$B$8+المدخلات!$B$6)/1440)<12," ص"," م") -> 8:35 م | L18: =MAX('34 فريق'!$C$4:$C$346) -> 6
A19: 41 | B19: {=ROUND(SUMPRODUCT(1/COUNTIF('بيانات الفرق U13'!$BY$3:$BY$43,'بيانات الفرق U13'!$BY$3:$BY$43)),0)} -> 2 | C19: {=_xlfn.TEXTJOIN(" + ",TRUE,_xlfn._xlws.SORT(COUNTIF('بيانات الفرق U13'!$BY$3:$BY$43,"المجموعة "&_xlfn.SEQUENCE(B19))))} -> 20 + 21 | D19: {=_xlfn.LET(_xlpm.gs,_xlfn.SEQUENCE(B19),_xlpm.ln,_xlfn.MAXIFS('بيانات الفرق U13'!$CA$3:$CA$43,'بيانات الفرق U13'!$BY$3:$BY$43,"المجموعة "&_xlpm.gs),_xlpm.mn,_xlfn.MINIFS('بيانات الفرق U13'!$BZ$3:$BZ$43,'بيانات الفرق U13'!$BY$3:$BY$43,"المجموعة "&_xlpm.gs),_xlpm.mx,_xlfn.MAXIFS('بيانات الفرق U13'!$BZ$3:$BZ$43,'بيانات الفرق U13'!$BY$3:$BY$43,"المجموعة "&_xlpm.gs),_xlpm.lo,FLOOR(_xlpm.mn/_xlpm.ln,1),_xlpm.hi,CEILING(_xlpm.mx/_xlpm.ln,1),_xlpm.t,IF(_xlpm.lo=_xlpm.hi,_xlpm.lo&"",_xlpm.lo&"–"&_xlpm.hi),_xlfn.TEXTJOIN(" + ",TRUE,_xlfn.SORTBY(_xlpm.t,_xlpm.ln,1)))} -> 1 + 1 | E19: {=_xlfn.LET(_xlpm.gs,_xlfn.SEQUENCE(B19),_xlpm.ln,_xlfn.MAXIFS('بيانات الفرق U13'!$CA$3:$CA$43,'بيانات الفرق U13'!$BY$3:$BY$43,"المجموعة "&_xlpm.gs),_xlpm.mn,_xlfn.MINIFS('بيانات الفرق U13'!$BZ$3:$BZ$43,'بيانات الفرق U13'!$BY$3:$BY$43,"المجموعة "&_xlpm.gs),_xlpm.mx,_xlfn.MAXIFS('بيانات الفرق U13'!$BZ$3:$BZ$43,'بيانات الفرق U13'!$BY$3:$BY$43,"المجموعة "&_xlpm.gs),_xlpm.t,IF(_xlpm.mn=_xlpm.mx,_xlpm.mn&"",_xlpm.mn&"–"&_xlpm.mx),_xlfn.TEXTJOIN(" + ",TRUE,_xlfn.SORTBY(_xlpm.t,_xlpm.ln,1)))} -> 19 + 20 | F19: =IF(H19=0,"—",IF(H19=1,"نهائي مباشر",IF(H19=2,"نصف نهائي ثم نهائي","ربع نهائي ثم نصف نهائي ثم نهائي"))) -> نهائي مباشر | G19: =I19-H19 -> 21 | H19: {=MAX('41 فريق'!$A$4:$A$404)-SUMPRODUCT(MAX(ISNUMBER(IFERROR(--LEFT('41 فريق'!$D$4:$D$404,1),"x"))*'41 فريق'!$A$4:$A$404))} -> 1 | I19: =MAX('41 فريق'!$A$4:$A$404) -> 22 | J19: =MOD(HOUR(المدخلات!$B$5)-1,12)+1&":"&TEXT(MINUTE(المدخلات!$B$5),"00")&IF(HOUR(المدخلات!$B$5)<12," ص"," م") -> 4:00 م | K19: =MOD(HOUR(المدخلات!$B$5+((المدخلات!$B$9-1)*المدخلات!$B$8+المدخلات!$B$6)/1440)-1,12)+1&":"&TEXT(MINUTE(المدخلات!$B$5+((المدخلات!$B$9-1)*المدخلات!$B$8+المدخلات!$B$6)/1440),"00")&IF(HOUR(المدخلات!$B$5+((المدخلات!$B$9-1)*المدخلات!$B$8+المدخلات!$B$6)/1440)<12," ص"," م") -> 8:35 م | L19: =MAX('41 فريق'!$C$4:$C$404) -> 7
A20: 45 | B20: {=ROUND(SUMPRODUCT(1/COUNTIF('بيانات الفرق U13'!$CD$3:$CD$47,'بيانات الفرق U13'!$CD$3:$CD$47)),0)} -> 3 | C20: {=_xlfn.TEXTJOIN(" + ",TRUE,_xlfn._xlws.SORT(COUNTIF('بيانات الفرق U13'!$CD$3:$CD$47,"المجموعة "&_xlfn.SEQUENCE(B20))))} -> 6 + 19 + 20 | D20: {=_xlfn.LET(_xlpm.gs,_xlfn.SEQUENCE(B20),_xlpm.ln,_xlfn.MAXIFS('بيانات الفرق U13'!$CF$3:$CF$47,'بيانات الفرق U13'!$CD$3:$CD$47,"المجموعة "&_xlpm.gs),_xlpm.mn,_xlfn.MINIFS('بيانات الفرق U13'!$CE$3:$CE$47,'بيانات الفرق U13'!$CD$3:$CD$47,"المجموعة "&_xlpm.gs),_xlpm.mx,_xlfn.MAXIFS('بيانات الفرق U13'!$CE$3:$CE$47,'بيانات الفرق U13'!$CD$3:$CD$47,"المجموعة "&_xlpm.gs),_xlpm.lo,FLOOR(_xlpm.mn/_xlpm.ln,1),_xlpm.hi,CEILING(_xlpm.mx/_xlpm.ln,1),_xlpm.t,IF(_xlpm.lo=_xlpm.hi,_xlpm.lo&"",_xlpm.lo&"–"&_xlpm.hi),_xlfn.TEXTJOIN(" + ",TRUE,_xlfn.SORTBY(_xlpm.t,_xlpm.ln,1)))} -> 4 + 1 + 1 | E20: {=_xlfn.LET(_xlpm.gs,_xlfn.SEQUENCE(B20),_xlpm.ln,_xlfn.MAXIFS('بيانات الفرق U13'!$CF$3:$CF$47,'بيانات الفرق U13'!$CD$3:$CD$47,"المجموعة "&_xlpm.gs),_xlpm.mn,_xlfn.MINIFS('بيانات الفرق U13'!$CE$3:$CE$47,'بيانات الفرق U13'!$CD$3:$CD$47,"المجموعة "&_xlpm.gs),_xlpm.mx,_xlfn.MAXIFS('بيانات الفرق U13'!$CE$3:$CE$47,'بيانات الفرق U13'!$CD$3:$CD$47,"المجموعة "&_xlpm.gs),_xlpm.t,IF(_xlpm.mn=_xlpm.mx,_xlpm.mn&"",_xlpm.mn&"–"&_xlpm.mx),_xlfn.TEXTJOIN(" + ",TRUE,_xlfn.SORTBY(_xlpm.t,_xlpm.ln,1)))} -> 20 + 18 + 19 | F20: =IF(H20=0,"—",IF(H20=1,"نهائي مباشر",IF(H20=2,"نصف نهائي ثم نهائي","ربع نهائي ثم نصف نهائي ثم نهائي"))) -> نصف نهائي ثم نهائي | G20: =I20-H20 -> 20 | H20: {=MAX('45 فريق'!$A$4:$A$427)-SUMPRODUCT(MAX(ISNUMBER(IFERROR(--LEFT('45 فريق'!$D$4:$D$427,1),"x"))*'45 فريق'!$A$4:$A$427))} -> 2 | I20: =MAX('45 فريق'!$A$4:$A$427) -> 22 | J20: =MOD(HOUR(المدخلات!$B$5)-1,12)+1&":"&TEXT(MINUTE(المدخلات!$B$5),"00")&IF(HOUR(المدخلات!$B$5)<12," ص"," م") -> 4:00 م | K20: =MOD(HOUR(المدخلات!$B$5+((المدخلات!$B$9-1)*المدخلات!$B$8+المدخلات!$B$6)/1440)-1,12)+1&":"&TEXT(MINUTE(المدخلات!$B$5+((المدخلات!$B$9-1)*المدخلات!$B$8+المدخلات!$B$6)/1440),"00")&IF(HOUR(المدخلات!$B$5+((المدخلات!$B$9-1)*المدخلات!$B$8+المدخلات!$B$6)/1440)<12," ص"," م") -> 8:35 م | L20: =MAX('45 فريق'!$C$4:$C$427) -> 8

Sheet 6 فرق
A1: بطولة 6 فرق – تحت 13
A3: اليوم | B3: الوقت | C3: الملعب | D3: المباراة
A4: 1 | B4: =MOD(HOUR(المدخلات!$B$5+0*المدخلات!$B$8/1440)-1,12)+1&":"&TEXT(MINUTE(المدخلات!$B$5+0*المدخلات!$B$8/1440),"00")&"–"&MOD(HOUR(المدخلات!$B$5+0*المدخلات!$B$8/1440+المدخلات!$B$6/1440)-1,12)+1&":"&TEXT(MINUTE(المدخلات!$B$5+0*المدخلات!$B$8/1440+المدخلات!$B$6/1440),"00")&IF(HOUR(المدخلات!$B$5+0*المدخلات!$B$8/1440)<12," ص"," م") -> 4:00–5:25 م | C4: 1 | D4: 1 ضد 6
A5: 1 | B5: =MOD(HOUR(المدخلات!$B$5+1*المدخلات!$B$8/1440)-1,12)+1&":"&TEXT(MINUTE(المدخلات!$B$5+1*المدخلات!$B$8/1440),"00")&"–"&MOD(HOUR(المدخلات!$B$5+1*المدخلات!$B$8/1440+المدخلات!$B$6/1440)-1,12)+1&":"&TEXT(MINUTE(المدخلات!$B$5+1*المدخلات!$B$8/1440+المدخلات!$B$6/1440),"00")&IF(HOUR(المدخلات!$B$5+1*المدخلات!$B$8/1440)<12," ص"," م") -> 5:35–7:00 م | C5: 1 | D5: 2 ضد 5
A6: 1 | B6: =MOD(HOUR(المدخلات!$B$5+2*المدخلات!$B$8/1440)-1,12)+1&":"&TEXT(MINUTE(المدخلات!$B$5+2*المدخلات!$B$8/1440),"00")&"–"&MOD(HOUR(المدخلات!$B$5+2*المدخلات!$B$8/1440+المدخلات!$B$6/1440)-1,12)+1&":"&TEXT(MINUTE(المدخلات!$B$5+2*المدخلات!$B$8/1440+المدخلات!$B$6/1440),"00")&IF(HOUR(المدخلات!$B$5+2*المدخلات!$B$8/1440)<12," ص"," م") -> 7:10–8:35 م | C6: 1 | D6: 3 ضد 4
A7: 2 | B7: =MOD(HOUR(المدخلات!$B$5+0*المدخلات!$B$8/1440)-1,12)+1&":"&TEXT(MINUTE(المدخلات!$B$5+0*المدخلات!$B$8/1440),"00")&"–"&MOD(HOUR(المدخلات!$B$5+0*المدخلات!$B$8/1440+المدخلات!$B$6/1440)-1,12)+1&":"&TEXT(MINUTE(المدخلات!$B$5+0*المدخلات!$B$8/1440+المدخلات!$B$6/1440),"00")&IF(HOUR(المدخلات!$B$5+0*المدخلات!$B$8/1440)<12," ص"," م") -> 4:00–5:25 م | C7: 1 | D7: 2 ضد 3
A8: 2 | B8: =MOD(HOUR(المدخلات!$B$5+1*المدخلات!$B$8/1440)-1,12)+1&":"&TEXT(MINUTE(المدخلات!$B$5+1*المدخلات!$B$8/1440),"00")&"–"&MOD(HOUR(المدخلات!$B$5+1*المدخلات!$B$8/1440+المدخلات!$B$6/1440)-1,12)+1&":"&TEXT(MINUTE(المدخلات!$B$5+1*المدخلات!$B$8/1440+المدخلات!$B$6/1440),"00")&IF(HOUR(المدخلات!$B$5+1*المدخلات!$B$8/1440)<12," ص"," م") -> 5:35–7:00 م | C8: 1 | D8: 6 ضد 4
A9: 2 | B9: =MOD(HOUR(المدخلات!$B$5+2*المدخلات!$B$8/1440)-1,12)+1&":"&TEXT(MINUTE(المدخلات!$B$5+2*المدخلات!$B$8/1440),"00")&"–"&MOD(HOUR(المدخلات!$B$5+2*المدخلات!$B$8/1440+المدخلات!$B$6/1440)-1,12)+1&":"&TEXT(MINUTE(المدخلات!$B$5+2*المدخلات!$B$8/1440+المدخلات!$B$6/1440),"00")&IF(HOUR(المدخلات!$B$5+2*المدخلات!$B$8/1440)<12," ص"," م") -> 7:10–8:35 م | C9: 1 | D9: 1 ضد 5
A10: 3 | B10: =MOD(HOUR(المدخلات!$B$5+0*المدخلات!$B$8/1440)-1,12)+1&":"&TEXT(MINUTE(المدخلات!$B$5+0*المدخلات!$B$8/1440),"00")&"–"&MOD(HOUR(المدخلات!$B$5+0*المدخلات!$B$8/1440+المدخلات!$B$6/1440)-1,12)+1&":"&TEXT(MINUTE(المدخلات!$B$5+0*المدخلات!$B$8/1440+المدخلات!$B$6/1440),"00")&IF(HOUR(المدخلات!$B$5+0*المدخلات!$B$8/1440)<12," ص"," م") -> 4:00–5:25 م | C10: 1 | D10: 1 ضد 4
A11: 3 | B11: =MOD(HOUR(المدخلات!$B$5+1*المدخلات!$B$8/1440)-1,12)+1&":"&TEXT(MINUTE(المدخلات!$B$5+1*المدخلات!$B$8/1440),"00")&"–"&MOD(HOUR(المدخلات!$B$5+1*المدخلات!$B$8/1440+المدخلات!$B$6/1440)-1,12)+1&":"&TEXT(MINUTE(المدخلات!$B$5+1*المدخلات!$B$8/1440+المدخلات!$B$6/1440),"00")&IF(HOUR(المدخلات!$B$5+1*المدخلات!$B$8/1440)<12," ص"," م") -> 5:35–7:00 م | C11: 1 | D11: 5 ضد 3
A12: 3 | B12: =MOD(HOUR(المدخلات!$B$5+2*المدخلات!$B$8/1440)-1,12)+1&":"&TEXT(MINUTE(المدخلات!$B$5+2*المدخلات!$B$8/1440),"00")&"–"&MOD(HOUR(المدخلات!$B$5+2*المدخلات!$B$8/1440+المدخلات!$B$6/1440)-1,12)+1&":"&TEXT(MINUTE(المدخلات!$B$5+2*المدخلات!$B$8/1440+المدخلات!$B$6/1440),"00")&IF(HOUR(المدخلات!$B$5+2*المدخلات!$B$8/1440)<12," ص"," م") -> 7:10–8:35 م | C12: 1 | D12: 6 ضد 2
A13: 4 | B13: =MOD(HOUR(المدخلات!$B$5+0*المدخلات!$B$8/1440)-1,12)+1&":"&TEXT(MINUTE(المدخلات!$B$5+0*المدخلات!$B$8/1440),"00")&"–"&MOD(HOUR(المدخلات!$B$5+0*المدخلات!$B$8/1440+المدخلات!$B$6/1440)-1,12)+1&":"&TEXT(MINUTE(المدخلات!$B$5+0*المدخلات!$B$8/1440+المدخلات!$B$6/1440),"00")&IF(HOUR(المدخلات!$B$5+0*المدخلات!$B$8/1440)<12," ص"," م") -> 4:00–5:25 م | C13: 1 | D13: 5 ضد 6
A14: 4 | B14: =MOD(HOUR(المدخلات!$B$5+1*المدخلات!$B$8/1440)-1,12)+1&":"&TEXT(MINUTE(المدخلات!$B$5+1*المدخلات!$B$8/1440),"00")&"–"&MOD(HOUR(المدخلات!$B$5+1*المدخلات!$B$8/1440+المدخلات!$B$6/1440)-1,12)+1&":"&TEXT(MINUTE(المدخلات!$B$5+1*المدخلات!$B$8/1440+المدخلات!$B$6/1440),"00")&IF(HOUR(المدخلات!$B$5+1*المدخلات!$B$8/1440)<12," ص"," م") -> 5:35–7:00 م | C14: 1 | D14: 1 ضد 3
A15: 4 | B15: =MOD(HOUR(المدخلات!$B$5+2*المدخلات!$B$8/1440)-1,12)+1&":"&TEXT(MINUTE(المدخلات!$B$5+2*المدخلات!$B$8/1440),"00")&"–"&MOD(HOUR(المدخلات!$B$5+2*المدخلات!$B$8/1440+المدخلات!$B$6/1440)-1,12)+1&":"&TEXT(MINUTE(المدخلات!$B$5+2*المدخلات!$B$8/1440+المدخلات!$B$6/1440),"00")&IF(HOUR(المدخلات!$B$5+2*المدخلات!$B$8/1440)<12," ص"," م") -> 7:10–8:35 م | C15: 1 | D15: 4 ضد 2
A16: 5 | B16: =MOD(HOUR(المدخلات!$B$5+0*المدخلات!$B$8/1440)-1,12)+1&":"&TEXT(MINUTE(المدخلات!$B$5+0*المدخلات!$B$8/1440),"00")&"–"&MOD(HOUR(المدخلات!$B$5+0*المدخلات!$B$8/1440+المدخلات!$B$6/1440)-1,12)+1&":"&TEXT(MINUTE(المدخلات!$B$5+0*المدخلات!$B$8/1440+المدخلات!$B$6/1440),"00")&IF(HOUR(المدخلات!$B$5+0*المدخلات!$B$8/1440)<12," ص"," م") -> 4:00–5:25 م | C16: 1 | D16: 4 ضد 5
A17: 5 | B17: =MOD(HOUR(المدخلات!$B$5+1*المدخلات!$B$8/1440)-1,12)+1&":"&TEXT(MINUTE(المدخلات!$B$5+1*المدخلات!$B$8/1440),"00")&"–"&MOD(HOUR(المدخلات!$B$5+1*المدخلات!$B$8/1440+المدخلات!$B$6/1440)-1,12)+1&":"&TEXT(MINUTE(المدخلات!$B$5+1*المدخلات!$B$8/1440+المدخلات!$B$6/1440),"00")&IF(HOUR(المدخلات!$B$5+1*المدخلات!$B$8/1440)<12," ص"," م") -> 5:35–7:00 م | C17: 1 | D17: 1 ضد 2
A18: 5 | B18: =MOD(HOUR(المدخلات!$B$5+2*المدخلات!$B$8/1440)-1,12)+1&":"&TEXT(MINUTE(المدخلات!$B$5+2*المدخلات!$B$8/1440),"00")&"–"&MOD(HOUR(المدخلات!$B$5+2*المدخلات!$B$8/1440+المدخلات!$B$6/1440)-1,12)+1&":"&TEXT(MINUTE(المدخلات!$B$5+2*المدخلات!$B$8/1440+المدخلات!$B$6/1440),"00")&IF(HOUR(المدخلات!$B$5+2*المدخلات!$B$8/1440)<12," ص"," م") -> 7:10–8:35 م | C18: 1 | D18: 3 ضد 6
A19: 6 | B19: =MOD(HOUR(المدخلات!$B$5+0*المدخلات!$B$8/1440)-1,12)+1&":"&TEXT(MINUTE(المدخلات!$B$5+0*المدخلات!$B$8/1440),"00")&"–"&MOD(HOUR(المدخلات!$B$5+0*المدخلات!$B$8/1440+المدخلات!$B$6/1440)-1,12)+1&":"&TEXT(MINUTE(المدخلات!$B$5+0*المدخلات!$B$8/1440+المدخلات!$B$6/1440),"00")&IF(HOUR(المدخلات!$B$5+0*المدخلات!$B$8/1440)<12," ص"," م") -> 4:00–5:25 م | C19: 1 | D19: 5 ضد 2
A20: 6 | B20: =MOD(HOUR(المدخلات!$B$5+1*المدخلات!$B$8/1440)-1,12)+1&":"&TEXT(MINUTE(المدخلات!$B$5+1*المدخلات!$B$8/1440),"00")&"–"&MOD(HOUR(المدخلات!$B$5+1*المدخلات!$B$8/1440+المدخلات!$B$6/1440)-1,12)+1&":"&TEXT(MINUTE(المدخلات!$B$5+1*المدخلات!$B$8/1440+المدخلات!$B$6/1440),"00")&IF(HOUR(المدخلات!$B$5+1*المدخلات!$B$8/1440)<12," ص"," م") -> 5:35–7:00 م | C20: 1 | D20: 6 ضد 1
A21: 6 | B21: =MOD(HOUR(المدخلات!$B$5+2*المدخلات!$B$8/1440)-1,12)+1&":"&TEXT(MINUTE(المدخلات!$B$5+2*المدخلات!$B$8/1440),"00")&"–"&MOD(HOUR(المدخلات!$B$5+2*المدخلات!$B$8/1440+المدخلات!$B$6/1440)-1,12)+1&":"&TEXT(MINUTE(المدخلات!$B$5+2*المدخلات!$B$8/1440+المدخلات!$B$6/1440),"00")&IF(HOUR(المدخلات!$B$5+2*المدخلات!$B$8/1440)<12," ص"," م") -> 7:10–8:35 م | C21: 1 | D21: 4 ضد 3
A22: 7 | B22: =MOD(HOUR(المدخلات!$B$5+0*المدخلات!$B$8/1440)-1,12)+1&":"&TEXT(MINUTE(المدخلات!$B$5+0*المدخلات!$B$8/1440),"00")&"–"&MOD(HOUR(المدخلات!$B$5+0*المدخلات!$B$8/1440+المدخلات!$B$6/1440)-1,12)+1&":"&TEXT(MINUTE(المدخلات!$B$5+0*المدخلات!$B$8/1440+المدخلات!$B$6/1440),"00")&IF(HOUR(المدخلات!$B$5+0*المدخلات!$B$8/1440)<12," ص"," م") -> 4:00–5:25 م | C22: 1 | D22: 3 ضد 2
A23: 7 | B23: =MOD(HOUR(المدخلات!$B$5+1*المدخلات!$B$8/1440)-1,12)+1&":"&TEXT(MINUTE(المدخلات!$B$5+1*المدخلات!$B$8/1440),"00")&"–"&MOD(HOUR(المدخلات!$B$5+1*المدخلات!$B$8/1440+المدخلات!$B$6/1440)-1,12)+1&":"&TEXT(MINUTE(المدخلات!$B$5+1*المدخلات!$B$8/1440+المدخلات!$B$6/1440),"00")&IF(HOUR(المدخلات!$B$5+1*المدخلات!$B$8/1440)<12," ص"," م") -> 5:35–7:00 م | C23: 1 | D23: 4 ضد 6
A24: 7 | B24: =MOD(HOUR(المدخلات!$B$5+2*المدخلات!$B$8/1440)-1,12)+1&":"&TEXT(MINUTE(المدخلات!$B$5+2*المدخلات!$B$8/1440),"00")&"–"&MOD(HOUR(المدخلات!$B$5+2*المدخلات!$B$8/1440+المدخلات!$B$6/1440)-1,12)+1&":"&TEXT(MINUTE(المدخلات!$B$5+2*المدخلات!$B$8/1440+المدخلات!$B$6/1440),"00")&IF(HOUR(المدخلات!$B$5+2*المدخلات!$B$8/1440)<12," ص"," م") -> 7:10–8:35 م | C24: 1 | D24: 5 ضد 1
A25: 8 | B25: =MOD(HOUR(المدخلات!$B$5+0*المدخلات!$B$8/1440)-1,12)+1&":"&TEXT(MINUTE(المدخلات!$B$5+0*المدخلات!$B$8/1440),"00")&"–"&MOD(HOUR(المدخلات!$B$5+0*المدخلات!$B$8/1440+المدخلات!$B$6/1440)-1,12)+1&":"&TEXT(MINUTE(المدخلات!$B$5+0*المدخلات!$B$8/1440+المدخلات!$B$6/1440),"00")&IF(HOUR(المدخلات!$B$5+0*المدخلات!$B$8/1440)<12," ص"," م") -> 4:00–5:25 م | C25: 1 | D25: 4 ضد 1
A26: 8 | B26: =MOD(HOUR(المدخلات!$B$5+1*المدخلات!$B$8/1440)-1,12)+1&":"&TEXT(MINUTE(المدخلات!$B$5+1*المدخلات!$B$8/1440),"00")&"–"&MOD(HOUR(المدخلات!$B$5+1*المدخلات!$B$8/1440+المدخلات!$B$6/1440)-1,12)+1&":"&TEXT(MINUTE(المدخلات!$B$5+1*المدخلات!$B$8/1440+المدخلات!$B$6/1440),"00")&IF(HOUR(المدخلات!$B$5+1*المدخلات!$B$8/1440)<12," ص"," م") -> 5:35–7:00 م | C26: 1 | D26: 3 ضد 5
A27: 8 | B27: =MOD(HOUR(المدخلات!$B$5+2*المدخلات!$B$8/1440)-1,12)+1&":"&TEXT(MINUTE(المدخلات!$B$5+2*المدخلات!$B$8/1440),"00")&"–"&MOD(HOUR(المدخلات!$B$5+2*المدخلات!$B$8/1440+المدخلات!$B$6/1440)-1,12)+1&":"&TEXT(MINUTE(المدخلات!$B$5+2*المدخلات!$B$8/1440+المدخلات!$B$6/1440),"00")&IF(HOUR(المدخلات!$B$5+2*المدخلات!$B$8/1440)<12," ص"," م") -> 7:10–8:35 م | C27: 1 | D27: 2 ضد 6
A28: 9 | B28: =MOD(HOUR(المدخلات!$B$5+0*المدخلات!$B$8/1440)-1,12)+1&":"&TEXT(MINUTE(المدخلات!$B$5+0*المدخلات!$B$8/1440),"00")&"–"&MOD(HOUR(المدخلات!$B$5+0*المدخلات!$B$8/1440+المدخلات!$B$6/1440)-1,12)+1&":"&TEXT(MINUTE(المدخلات!$B$5+0*المدخلات!$B$8/1440+المدخلات!$B$6/1440),"00")&IF(HOUR(المدخلات!$B$5+0*المدخلات!$B$8/1440)<12," ص"," م") -> 4:00–5:25 م | C28: 1 | D28: 3 ضد 1
A29: 9 | B29: =MOD(HOUR(المدخلات!$B$5+1*المدخلات!$B$8/1440)-1,12)+1&":"&TEXT(MINUTE(المدخلات!$B$5+1*المدخلات!$B$8/1440),"00")&"–"&MOD(HOUR(المدخلات!$B$5+1*المدخلات!$B$8/1440+المدخلات!$B$6/1440)-1,12)+1&":"&TEXT(MINUTE(المدخلات!$B$5+1*المدخلات!$B$8/1440+المدخلات!$B$6/1440),"00")&IF(HOUR(المدخلات!$B$5+1*المدخلات!$B$8/1440)<12," ص"," م") -> 5:35–7:00 م | C29: 1 | D29: 2 ضد 4
A30: 9 | B30: =MOD(HOUR(المدخلات!$B$5+2*المدخلات!$B$8/1440)-1,12)+1&":"&TEXT(MINUTE(المدخلات!$B$5+2*المدخلات!$B$8/1440),"00")&"–"&MOD(HOUR(المدخلات!$B$5+2*المدخلات!$B$8/1440+المدخلات!$B$6/1440)-1,12)+1&":"&TEXT(MINUTE(المدخلات!$B$5+2*المدخلات!$B$8/1440+المدخلات!$B$6/1440),"00")&IF(HOUR(المدخلات!$B$5+2*المدخلات!$B$8/1440)<12," ص"," م") -> 7:10–8:35 م | C30: 1 | D30: 6 ضد 5
A31: 10 | B31: =MOD(HOUR(المدخلات!$B$5+0*المدخلات!$B$8/1440)-1,12)+1&":"&TEXT(MINUTE(المدخلات!$B$5+0*المدخلات!$B$8/1440),"00")&"–"&MOD(HOUR(المدخلات!$B$5+0*المدخلات!$B$8/1440+المدخلات!$B$6/1440)-1,12)+1&":"&TEXT(MINUTE(المدخلات!$B$5+0*المدخلات!$B$8/1440+المدخلات!$B$6/1440),"00")&IF(HOUR(المدخلات!$B$5+0*المدخلات!$B$8/1440)<12," ص"," م") -> 4:00–5:25 م | C31: 1 | D31: 6 ضد 3
A32: 10 | B32: =MOD(HOUR(المدخلات!$B$5+1*المدخلات!$B$8/1440)-1,12)+1&":"&TEXT(MINUTE(المدخلات!$B$5+1*المدخلات!$B$8/1440),"00")&"–"&MOD(HOUR(المدخلات!$B$5+1*المدخلات!$B$8/1440+المدخلات!$B$6/1440)-1,12)+1&":"&TEXT(MINUTE(المدخلات!$B$5+1*المدخلات!$B$8/1440+المدخلات!$B$6/1440),"00")&IF(HOUR(المدخلات!$B$5+1*المدخلات!$B$8/1440)<12," ص"," م") -> 5:35–7:00 م | C32: 1 | D32: 5 ضد 4
A33: 10 | B33: =MOD(HOUR(المدخلات!$B$5+2*المدخلات!$B$8/1440)-1,12)+1&":"&TEXT(MINUTE(المدخلات!$B$5+2*المدخلات!$B$8/1440),"00")&"–"&MOD(HOUR(المدخلات!$B$5+2*المدخلات!$B$8/1440+المدخلات!$B$6/1440)-1,12)+1&":"&TEXT(MINUTE(المدخلات!$B$5+2*المدخلات!$B$8/1440+المدخلات!$B$6/1440),"00")&IF(HOUR(المدخلات!$B$5+2*المدخلات!$B$8/1440)<12," ص"," م") -> 7:10–8:35 م | C33: 1 | D33: 2 ضد 1
A34: 11 | B34: =MOD(HOUR(المدخلات!$B$5+0*المدخلات!$B$8/1440)-1,12)+1&":"&TEXT(MINUTE(المدخلات!$B$5+0*المدخلات!$B$8/1440),"00")&"–"&MOD(HOUR(المدخلات!$B$5+0*المدخلات!$B$8/1440+المدخلات!$B$6/1440)-1,12)+1&":"&TEXT(MINUTE(المدخلات!$B$5+0*المدخلات!$B$8/1440+المدخلات!$B$6/1440),"00")&IF(HOUR(المدخلات!$B$5+0*المدخلات!$B$8/1440)<12," ص"," م") -> 4:00–5:25 م | C34: 1 | D34: 2 ضد 5
A35: 11 | B35: =MOD(HOUR(المدخلات!$B$5+1*المدخلات!$B$8/1440)-1,12)+1&":"&TEXT(MINUTE(المدخلات!$B$5+1*المدخلات!$B$8/1440),"00")&"–"&MOD(HOUR(المدخلات!$B$5+1*المدخلات!$B$8/1440+المدخلات!$B$6/1440)-1,12)+1&":"&TEXT(MINUTE(المدخلات!$B$5+1*المدخلات!$B$8/1440+المدخلات!$B$6/1440),"00")&IF(HOUR(المدخلات!$B$5+1*المدخلات!$B$8/1440)<12," ص"," م") -> 5:35–7:00 م | C35: 1 | D35: 1 ضد 6
A36: 11 | B36: =MOD(HOUR(المدخلات!$B$5+2*المدخلات!$B$8/1440)-1,12)+1&":"&TEXT(MINUTE(المدخلات!$B$5+2*المدخلات!$B$8/1440),"00")&"–"&MOD(HOUR(المدخلات!$B$5+2*المدخلات!$B$8/1440+المدخلات!$B$6/1440)-1,12)+1&":"&TEXT(MINUTE(المدخلات!$B$5+2*المدخلات!$B$8/1440+المدخلات!$B$6/1440),"00")&IF(HOUR(المدخلات!$B$5+2*المدخلات!$B$8/1440)<12," ص"," م") -> 7:10–8:35 م | C36: 1 | D36: 3 ضد 4
A37: 12 | B37: =MOD(HOUR(المدخلات!$B$5+0*المدخلات!$B$8/1440)-1,12)+1&":"&TEXT(MINUTE(المدخلات!$B$5+0*المدخلات!$B$8/1440),"00")&"–"&MOD(HOUR(المدخلات!$B$5+0*المدخلات!$B$8/1440+المدخلات!$B$6/1440)-1,12)+1&":"&TEXT(MINUTE(المدخلات!$B$5+0*المدخلات!$B$8/1440+المدخلات!$B$6/1440),"00")&IF(HOUR(المدخلات!$B$5+0*المدخلات!$B$8/1440)<12," ص"," م") -> 4:00–5:25 م | C37: 1 | D37: 6 ضد 4
A38: 12 | B38: =MOD(HOUR(المدخلات!$B$5+1*المدخلات!$B$8/1440)-1,12)+1&":"&TEXT(MINUTE(المدخلات!$B$5+1*المدخلات!$B$8/1440),"00")&"–"&MOD(HOUR(المدخلات!$B$5+1*المدخلات!$B$8/1440+المدخلات!$B$6/1440)-1,12)+1&":"&TEXT(MINUTE(المدخلات!$B$5+1*المدخلات!$B$8/1440+المدخلات!$B$6/1440),"00")&IF(HOUR(المدخلات!$B$5+1*المدخلات!$B$8/1440)<12," ص"," م") -> 5:35–7:00 م | C38: 1 | D38: 2 ضد 3
A39: 12 | B39: =MOD(HOUR(المدخلات!$B$5+2*المدخلات!$B$8/1440)-1,12)+1&":"&TEXT(MINUTE(المدخلات!$B$5+2*المدخلات!$B$8/1440),"00")&"–"&MOD(HOUR(المدخلات!$B$5+2*المدخلات!$B$8/1440+المدخلات!$B$6/1440)-1,12)+1&":"&TEXT(MINUTE(المدخلات!$B$5+2*المدخلات!$B$8/1440+المدخلات!$B$6/1440),"00")&IF(HOUR(المدخلات!$B$5+2*المدخلات!$B$8/1440)<12," ص"," م") -> 7:10–8:35 م | C39: 1 | D39: 1 ضد 5
A40: 13 | B40: =MOD(HOUR(المدخلات!$B$5+0*المدخلات!$B$8/1440)-1,12)+1&":"&TEXT(MINUTE(المدخلات!$B$5+0*المدخلات!$B$8/1440),"00")&"–"&MOD(HOUR(المدخلات!$B$5+0*المدخلات!$B$8/1440+المدخلات!$B$6/1440)-1,12)+1&":"&TEXT(MINUTE(المدخلات!$B$5+0*المدخلات!$B$8/1440+المدخلات!$B$6/1440),"00")&IF(HOUR(المدخلات!$B$5+0*المدخلات!$B$8/1440)<12," ص"," م") -> 4:00–5:25 م | C40: 1 | D40: 1 ضد 4
A41: 13 | B41: =MOD(HOUR(المدخلات!$B$5+1*المدخلات!$B$8/1440)-1,12)+1&":"&TEXT(MINUTE(المدخلات!$B$5+1*المدخلات!$B$8/1440),"00")&"–"&MOD(HOUR(المدخلات!$B$5+1*المدخلات!$B$8/1440+المدخلات!$B$6/1440)-1,12)+1&":"&TEXT(MINUTE(المدخلات!$B$5+1*المدخلات!$B$8/1440+المدخلات!$B$6/1440),"00")&IF(HOUR(المدخلات!$B$5+1*المدخلات!$B$8/1440)<12," ص"," م") -> 5:35–7:00 م | C41: 1 | D41: 5 ضد 3
...

Sheet 7 فرق
A1: بطولة 7 فرق – تحت 13
A3: اليوم | B3: الوقت | C3: الملعب | D3: المباراة
A4: 1 | B4: =MOD(HOUR(المدخلات!$B$5+0*المدخلات!$B$8/1440)-1,12)+1&":"&TEXT(MINUTE(المدخلات!$B$5+0*المدخلات!$B$8/1440),"00")&"–"&MOD(HOUR(المدخلات!$B$5+0*المدخلات!$B$8/1440+المدخلات!$B$6/1440)-1,12)+1&":"&TEXT(MINUTE(المدخلات!$B$5+0*المدخلات!$B$8/1440+المدخلات!$B$6/1440),"00")&IF(HOUR(المدخلات!$B$5+0*المدخلات!$B$8/1440)<12," ص"," م") -> 4:00–5:25 م | C4: 1 | D4: 2 ضد 7
A5: 1 | B5: =MOD(HOUR(المدخلات!$B$5+1*المدخلات!$B$8/1440)-1,12)+1&":"&TEXT(MINUTE(المدخلات!$B$5+1*المدخلات!$B$8/1440),"00")&"–"&MOD(HOUR(المدخلات!$B$5+1*المدخلات!$B$8/1440+المدخلات!$B$6/1440)-1,12)+1&":"&TEXT(MINUTE(المدخلات!$B$5+1*المدخلات!$B$8/1440+المدخلات!$B$6/1440),"00")&IF(HOUR(المدخلات!$B$5+1*المدخلات!$B$8/1440)<12," ص"," م") -> 5:35–7:00 م | C5: 1 | D5: 3 ضد 6
A6: 1 | B6: =MOD(HOUR(المدخلات!$B$5+2*المدخلات!$B$8/1440)-1,12)+1&":"&TEXT(MINUTE(المدخلات!$B$5+2*المدخلات!$B$8/1440),"00")&"–"&MOD(HOUR(المدخلات!$B$5+2*المدخلات!$B$8/1440+المدخلات!$B$6/1440)-1,12)+1&":"&TEXT(MINUTE(المدخلات!$B$5+2*المدخلات!$B$8/1440+المدخلات!$B$6/1440),"00")&IF(HOUR(المدخلات!$B$5+2*المدخلات!$B$8/1440)<12," ص"," م") -> 7:10–8:35 م | C6: 1 | D6: 4 ضد 5
A7: 2 | B7: =MOD(HOUR(المدخلات!$B$5+0*المدخلات!$B$8/1440)-1,12)+1&":"&TEXT(MINUTE(المدخلات!$B$5+0*المدخلات!$B$8/1440),"00")&"–"&MOD(HOUR(المدخلات!$B$5+0*المدخلات!$B$8/1440+المدخلات!$B$6/1440)-1,12)+1&":"&TEXT(MINUTE(المدخلات!$B$5+0*المدخلات!$B$8/1440+المدخلات!$B$6/1440),"00")&IF(HOUR(المدخلات!$B$5+0*المدخلات!$B$8/1440)<12," ص"," م") -> 4:00–5:25 م | C7: 1 | D7: 3 ضد 4
A8: 2 | B8: =MOD(HOUR(المدخلات!$B$5+1*المدخلات!$B$8/1440)-1,12)+1&":"&TEXT(MINUTE(المدخلات!$B$5+1*المدخلات!$B$8/1440),"00")&"–"&MOD(HOUR(المدخلات!$B$5+1*المدخلات!$B$8/1440+المدخلات!$B$6/1440)-1,12)+1&":"&TEXT(MINUTE(المدخلات!$B$5+1*المدخلات!$B$8/1440+المدخلات!$B$6/1440),"00")&IF(HOUR(المدخلات!$B$5+1*المدخلات!$B$8/1440)<12," ص"," م") -> 5:35–7:00 م | C8: 1 | D8: 2 ضد 5
A9: 2 | B9: =MOD(HOUR(المدخلات!$B$5+2*المدخلات!$B$8/1440)-1,12)+1&":"&TEXT(MINUTE(المدخلات!$B$5+2*المدخلات!$B$8/1440),"00")&"–"&MOD(HOUR(المدخلات!$B$5+2*المدخلات!$B$8/1440+المدخلات!$B$6/1440)-1,12)+1&":"&TEXT(MINUTE(المدخلات!$B$5+2*المدخلات!$B$8/1440+المدخلات!$B$6/1440),"00")&IF(HOUR(المدخلات!$B$5+2*المدخلات!$B$8/1440)<12," ص"," م") -> 7:10–8:35 م | C9: 1 | D9: 1 ضد 7
A10: 3 | B10: =MOD(HOUR(المدخلات!$B$5+0*المدخلات!$B$8/1440)-1,12)+1&":"&TEXT(MINUTE(المدخلات!$B$5+0*المدخلات!$B$8/1440),"00")&"–"&MOD(HOUR(المدخلات!$B$5+0*المدخلات!$B$8/1440+المدخلات!$B$6/1440)-1,12)+1&":"&TEXT(MINUTE(المدخلات!$B$5+0*المدخلات!$B$8/1440+المدخلات!$B$6/1440),"00")&IF(HOUR(المدخلات!$B$5+0*المدخلات!$B$8/1440)<12," ص"," م") -> 4:00–5:25 م | C10: 1 | D10: 1 ضد 6
A11: 3 | B11: =MOD(HOUR(المدخلات!$B$5+1*المدخلات!$B$8/1440)-1,12)+1&":"&TEXT(MINUTE(المدخلات!$B$5+1*المدخلات!$B$8/1440),"00")&"–"&MOD(HOUR(المدخلات!$B$5+1*المدخلات!$B$8/1440+المدخلات!$B$6/1440)-1,12)+1&":"&TEXT(MINUTE(المدخلات!$B$5+1*المدخلات!$B$8/1440+المدخلات!$B$6/1440),"00")&IF(HOUR(المدخلات!$B$5+1*المدخلات!$B$8/1440)<12," ص"," م") -> 5:35–7:00 م | C11: 1 | D11: 7 ضد 5
A12: 3 | B12: =MOD(HOUR(المدخلات!$B$5+2*المدخلات!$B$8/1440)-1,12)+1&":"&TEXT(MINUTE(المدخلات!$B$5+2*المدخلات!$B$8/1440),"00")&"–"&MOD(HOUR(المدخلات!$B$5+2*المدخلات!$B$8/1440+المدخلات!$B$6/1440)-1,12)+1&":"&TEXT(MINUTE(المدخلات!$B$5+2*المدخلات!$B$8/1440+المدخلات!$B$6/1440),"00")&IF(HOUR(المدخلات!$B$5+2*المدخلات!$B$8/1440)<12," ص"," م") -> 7:10–8:35 م | C12: 1 | D12: 2 ضد 3
A13: 4 | B13: =MOD(HOUR(المدخلات!$B$5+0*المدخلات!$B$8/1440)-1,12)+1&":"&TEXT(MINUTE(المدخلات!$B$5+0*المدخلات!$B$8/1440),"00")&"–"&MOD(HOUR(المدخلات!$B$5+0*المدخلات!$B$8/1440+المدخلات!$B$6/1440)-1,12)+1&":"&TEXT(MINUTE(المدخلات!$B$5+0*المدخلات!$B$8/1440+المدخلات!$B$6/1440),"00")&IF(HOUR(المدخلات!$B$5+0*المدخلات!$B$8/1440)<12," ص"," م") -> 4:00–5:25 م | C13: 1 | D13: 1 ضد 5
A14: 4 | B14: =MOD(HOUR(المدخلات!$B$5+1*المدخلات!$B$8/1440)-1,12)+1&":"&TEXT(MINUTE(المدخلات!$B$5+1*المدخلات!$B$8/1440),"00")&"–"&MOD(HOUR(المدخلات!$B$5+1*المدخلات!$B$8/1440+المدخلات!$B$6/1440)-1,12)+1&":"&TEXT(MINUTE(المدخلات!$B$5+1*المدخلات!$B$8/1440+المدخلات!$B$6/1440),"00")&IF(HOUR(المدخلات!$B$5+1*المدخلات!$B$8/1440)<12," ص"," م") -> 5:35–7:00 م | C14: 1 | D14: 6 ضد 4
A15: 4 | B15: =MOD(HOUR(المدخلات!$B$5+2*المدخلات!$B$8/1440)-1,12)+1&":"&TEXT(MINUTE(المدخلات!$B$5+2*المدخلات!$B$8/1440),"00")&"–"&MOD(HOUR(المدخلات!$B$5+2*المدخلات!$B$8/1440+المدخلات!$B$6/1440)-1,12)+1&":"&TEXT(MINUTE(المدخلات!$B$5+2*المدخلات!$B$8/1440+المدخلات!$B$6/1440),"00")&IF(HOUR(المدخلات!$B$5+2*المدخلات!$B$8/1440)<12," ص"," م") -> 7:10–8:35 م | C15: 1 | D15: 7 ضد 3
A16: 5 | B16: =MOD(HOUR(المدخلات!$B$5+0*المدخلات!$B$8/1440)-1,12)+1&":"&TEXT(MINUTE(المدخلات!$B$5+0*المدخلات!$B$8/1440),"00")&"–"&MOD(HOUR(المدخلات!$B$5+0*المدخلات!$B$8/1440+المدخلات!$B$6/1440)-1,12)+1&":"&TEXT(MINUTE(المدخلات!$B$5+0*المدخلات!$B$8/1440+المدخلات!$B$6/1440),"00")&IF(HOUR(المدخلات!$B$5+0*المدخلات!$B$8/1440)<12," ص"," م") -> 4:00–5:25 م | C16: 1 | D16: 5 ضد 3
A17: 5 | B17: =MOD(HOUR(المدخلات!$B$5+1*المدخلات!$B$8/1440)-1,12)+1&":"&TEXT(MINUTE(المدخلات!$B$5+1*المدخلات!$B$8/1440),"00")&"–"&MOD(HOUR(المدخلات!$B$5+1*المدخلات!$B$8/1440+المدخلات!$B$6/1440)-1,12)+1&":"&TEXT(MINUTE(المدخلات!$B$5+1*المدخلات!$B$8/1440+المدخلات!$B$6/1440),"00")&IF(HOUR(المدخلات!$B$5+1*المدخلات!$B$8/1440)<12," ص"," م") -> 5:35–7:00 م | C17: 1 | D17: 1 ضد 4
A18: 5 | B18: =MOD(HOUR(المدخلات!$B$5+2*المدخلات!$B$8/1440)-1,12)+1&":"&TEXT(MINUTE(المدخلات!$B$5+2*المدخلات!$B$8/1440),"00")&"–"&MOD(HOUR(المدخلات!$B$5+2*المدخلات!$B$8/1440+المدخلات!$B$6/1440)-1,12)+1&":"&TEXT(MINUTE(المدخلات!$B$5+2*المدخلات!$B$8/1440+المدخلات!$B$6/1440),"00")&IF(HOUR(المدخلات!$B$5+2*المدخلات!$B$8/1440)<12," ص"," م") -> 7:10–8:35 م | C18: 1 | D18: 6 ضد 2
A19: 6 | B19: =MOD(HOUR(المدخلات!$B$5+0*المدخلات!$B$8/1440)-1,12)+1&":"&TEXT(MINUTE(المدخلات!$B$5+0*المدخلات!$B$8/1440),"00")&"–"&MOD(HOUR(المدخلات!$B$5+0*المدخلات!$B$8/1440+المدخلات!$B$6/1440)-1,12)+1&":"&TEXT(MINUTE(المدخلات!$B$5+0*المدخلات!$B$8/1440+المدخلات!$B$6/1440),"00")&IF(HOUR(المدخلات!$B$5+0*المدخلات!$B$8/1440)<12," ص"," م") -> 4:00–5:25 م | C19: 1 | D19: 4 ضد 2
A20: 6 | B20: =MOD(HOUR(المدخلات!$B$5+1*المدخلات!$B$8/1440)-1,12)+1&":"&TEXT(MINUTE(المدخلات!$B$5+1*المدخلات!$B$8/1440),"00")&"–"&MOD(HOUR(المدخلات!$B$5+1*المدخلات!$B$8/1440+المدخلات!$B$6/1440)-1,12)+1&":"&TEXT(MINUTE(المدخلات!$B$5+1*المدخلات!$B$8/1440+المدخلات!$B$6/1440),"00")&IF(HOUR(المدخلات!$B$5+1*المدخلات!$B$8/1440)<12," ص"," م") -> 5:35–7:00 م | C20: 1 | D20: 1 ضد 3
A21: 6 | B21: =MOD(HOUR(المدخلات!$B$5+2*المدخلات!$B$8/1440)-1,12)+1&":"&TEXT(MINUTE(المدخلات!$B$5+2*المدخلات!$B$8/1440),"00")&"–"&MOD(HOUR(المدخلات!$B$5+2*المدخلات!$B$8/1440+المدخلات!$B$6/1440)-1,12)+1&":"&TEXT(MINUTE(المدخلات!$B$5+2*المدخلات!$B$8/1440+المدخلات!$B$6/1440),"00")&IF(HOUR(المدخلات!$B$5+2*المدخلات!$B$8/1440)<12," ص"," م") -> 7:10–8:35 م | C21: 1 | D21: 6 ضد 7
A22: 7 | B22: =MOD(HOUR(المدخلات!$B$5+0*المدخلات!$B$8/1440)-1,12)+1&":"&TEXT(MINUTE(المدخلات!$B$5+0*المدخلات!$B$8/1440),"00")&"–"&MOD(HOUR(المدخلات!$B$5+0*المدخلات!$B$8/1440+المدخلات!$B$6/1440)-1,12)+1&":"&TEXT(MINUTE(المدخلات!$B$5+0*المدخلات!$B$8/1440+المدخلات!$B$6/1440),"00")&IF(HOUR(المدخلات!$B$5+0*المدخلات!$B$8/1440)<12," ص"," م") -> 4:00–5:25 م | C22: 1 | D22: 4 ضد 7
A23: 7 | B23: =MOD(HOUR(المدخلات!$B$5+1*المدخلات!$B$8/1440)-1,12)+1&":"&TEXT(MINUTE(المدخلات!$B$5+1*المدخلات!$B$8/1440),"00")&"–"&MOD(HOUR(المدخلات!$B$5+1*المدخلات!$B$8/1440+المدخلات!$B$6/1440)-1,12)+1&":"&TEXT(MINUTE(المدخلات!$B$5+1*المدخلات!$B$8/1440+المدخلات!$B$6/1440),"00")&IF(HOUR(المدخلات!$B$5+1*المدخلات!$B$8/1440)<12," ص"," م") -> 5:35–7:00 م | C23: 1 | D23: 1 ضد 2
A24: 7 | B24: =MOD(HOUR(المدخلات!$B$5+2*المدخلات!$B$8/1440)-1,12)+1&":"&TEXT(MINUTE(المدخلات!$B$5+2*المدخلات!$B$8/1440),"00")&"–"&MOD(HOUR(المدخلات!$B$5+2*المدخلات!$B$8/1440+المدخلات!$B$6/1440)-1,12)+1&":"&TEXT(MINUTE(المدخلات!$B$5+2*المدخلات!$B$8/1440+المدخلات!$B$6/1440),"00")&IF(HOUR(المدخلات!$B$5+2*المدخلات!$B$8/1440)<12," ص"," م") -> 7:10–8:35 م | C24: 1 | D24: 5 ضد 6
A25: 8 | B25: =MOD(HOUR(المدخلات!$B$5+0*المدخلات!$B$8/1440)-1,12)+1&":"&TEXT(MINUTE(المدخلات!$B$5+0*المدخلات!$B$8/1440),"00")&"–"&MOD(HOUR(المدخلات!$B$5+0*المدخلات!$B$8/1440+المدخلات!$B$6/1440)-1,12)+1&":"&TEXT(MINUTE(المدخلات!$B$5+0*المدخلات!$B$8/1440+المدخلات!$B$6/1440),"00")&IF(HOUR(المدخلات!$B$5+0*المدخلات!$B$8/1440)<12," ص"," م") -> 4:00–5:25 م | C25: 1 | D25: 6 ضد 3
A26: 8 | B26: =MOD(HOUR(المدخلات!$B$5+1*المدخلات!$B$8/1440)-1,12)+1&":"&TEXT(MINUTE(المدخلات!$B$5+1*المدخلات!$B$8/1440),"00")&"–"&MOD(HOUR(المدخلات!$B$5+1*المدخلات!$B$8/1440+المدخلات!$B$6/1440)-1,12)+1&":"&TEXT(MINUTE(المدخلات!$B$5+1*المدخلات!$B$8/1440+المدخلات!$B$6/1440),"00")&IF(HOUR(المدخلات!$B$5+1*المدخلات!$B$8/1440)<12," ص"," م") -> 5:35–7:00 م | C26: 1 | D26: 7 ضد 2
A27: 8 | B27: =MOD(HOUR(المدخلات!$B$5+2*المدخلات!$B$8/1440)-1,12)+1&":"&TEXT(MINUTE(المدخلات!$B$5+2*المدخلات!$B$8/1440),"00")&"–"&MOD(HOUR(المدخلات!$B$5+2*المدخلات!$B$8/1440+المدخلات!$B$6/1440)-1,12)+1&":"&TEXT(MINUTE(المدخلات!$B$5+2*المدخلات!$B$8/1440+المدخلات!$B$6/1440),"00")&IF(HOUR(المدخلات!$B$5+2*المدخلات!$B$8/1440)<12," ص"," م") -> 7:10–8:35 م | C27: 1 | D27: 5 ضد 4
