Workbook

Sheet المدخلات
A1: مدخلات جداول تحت 14 | E1: جدول الفترات
A3: البند | B3: القيمة | C3: ملاحظة | E3: الفترة | F3: التوقيت
E4: 1 | F4: =MOD(HOUR($B$5+0*$B$8/1440)-1,12)+1&":"&TEXT(MINUTE($B$5+0*$B$8/1440),"00")&"–"&MOD(HOUR($B$5+0*$B$8/1440+$B$6/1440)-1,12)+1&":"&TEXT(MINUTE($B$5+0*$B$8/1440+$B$6/1440),"00")&IF(HOUR($B$5+0*$B$8/1440)<12," ص"," م") -> 4:00–5:30 م
A5: وقت بداية اليوم | B5: 0.6666667 | C5: قابل للتعديل | E5: 2 | F5: =MOD(HOUR($B$5+1*$B$8/1440)-1,12)+1&":"&TEXT(MINUTE($B$5+1*$B$8/1440),"00")&"–"&MOD(HOUR($B$5+1*$B$8/1440+$B$6/1440)-1,12)+1&":"&TEXT(MINUTE($B$5+1*$B$8/1440+$B$6/1440),"00")&IF(HOUR($B$5+1*$B$8/1440)<12," ص"," م") -> 5:40–7:10 م
A6: مدة المباراة (دقيقة) | B6: 90 | C6: قابل للتعديل | E6: 3 | F6: =MOD(HOUR($B$5+2*$B$8/1440)-1,12)+1&":"&TEXT(MINUTE($B$5+2*$B$8/1440),"00")&"–"&MOD(HOUR($B$5+2*$B$8/1440+$B$6/1440)-1,12)+1&":"&TEXT(MINUTE($B$5+2*$B$8/1440+$B$6/1440),"00")&IF(HOUR($B$5+2*$B$8/1440)<12," ص"," م") -> 7:20–8:50 م
A7: الفاصل / ترتيب الملعب (دقيقة) | B7: 10 | C7: قابل للتعديل
A8: طول الفترة الكاملة (دقيقة) | B8: =B6+B7 -> 100 | C8: محسوبة تلقائياً
A9: أقصى عدد فترات في اليوم | B9: 3 | C9: قابل للتعديل

Sheet المبادئ
A1: مبادئ بناء جداول تحت 14 (من 6 إلى 48 فريقًا) — وحالة الالتزام الفعلية
A3: # | B3: المبدأ | C3: الشرح | D3: الحالة | E3: الاستثناءات والملاحظات
A4: 1 | B4: لا يلعب الفريق مباراتين ورا بعض | C4: القاعدة الأهم في التصميم: يحصل كل فريق على فترة راحة كاملة (15 دقيقة على الأقل، وفعلياً فترة 100 دقيقة كاملة) بين مباراتيه. ويُحقَّق ذلك إما بحجز فترات استراحة كاملة في الأعداد الصغيرة، أو بتوزيع الفرق على فترات وملاعب أكثر في الأعداد الكبيرة. | D4: ✔ مطبق بالكامل | E4: لا استثناء. فحص الـ17 ورقة: صفر حالة فريق يلعب في فترتين متتاليتين في نفس اليوم.
A5: 2 | B5: لا يوجد تتابع إطلاقاً | C5: إذا ضاقت الفترات عن عدد المباريات المطلوبة، يُزاد عدد الملاعب أو تُزاد الأيام، ولا يُضحّى براحة اللاعبين بأي حال. | D5: ✔ مطبق بالكامل | E5: لا استثناء. أيضاً صفر حالة فريق له مباراتان في نفس الفترة.
A6: 3 | B6: عدالة عدد المباريات | C6: كل الفرق تلعب العدد نفسه في اليوم الواحد وفي البطولة ككل — لا فريق يلعب أكثر من آخر. | D6: ⚠ مطبق باستثناءات | E6: مطبق بالكامل داخل كل مجموعة وفي اليوم الواحد (تفاوت صفر). الاستثناء بين المجموعات عند الأعداد الفردية: 13 فريقًا (20 و18)، 15 (21 و18)، 23 (21/21/18)، 31 (21/21/21/18). أما 35 فصارت متساوية تماماً (18 لكل الفرق) بعد تقسيمها 5 مجموعات × 7.
A7: 4 | B7: عدالة المواجهات | C7: تُوزَّع فرص اللقاء على الجميع بدل أن تتكرر بين فرق معيّنة: يُقسم إجمالي المباريات على عدد الأزواج الممكنة، ويُسمح بمستويين فقط فرقهما مباراة واحدة. | D7: ⚠ مطبق باستثناءات | E7: أقوى من الحد المطلوب: داخل كل مجموعة الفرق بين الأزواج = صفر (كل زوج يلتقي نفس العدد بالضبط) وكل الأزواج مغطاة بلا زوج محروم. الاستثناء الوحيد المتبقي بين المجموعات: 13 فريقًا (4 مقابل 3). و35 فريقًا صارت 3 لقاءات لكل زوج في كل المجموعات.
A8: 5 | B8: تقسيم المجموعات عند الأعداد الكبيرة | C8: إذا كبر عدد الفرق حتى لم تكفِ مباريات الموسم للقاء الجميع، يُقسم العدد إلى مجموعات متساوية تلعب كل منها على ملاعبها الخاصة في نفس الوقت. | D8: ⚠ مطبق باستثناءات | E8: مجموعات متساوية تماماً: 14 (7+7)، 16 (8+8)، 18 (6+6+6)، 35 (7×5)، 48 (6×8). الأعداد الفردية بفرق فريق واحد: 13 (7+6)، 15 (8+7)، 23 (8+8+7)، 31 (8+8+8+7).
A9: 6 | B9: أقصى 3 فترات في اليوم | C9: اليوم يبدأ 4:00 م وينتهي 8:50 م بثلاث فترات فقط (مباراة 90 دقيقة + 10 دقائق ترتيب الملعب)، ولا يُطال اليوم أكثر من ذلك. | D9: ✔ مطبق بالكامل | E9: لا تجاوز في أي ورقة. الاستثناء للأسفل فقط: بطولة 8 فرق تستخدم فترتين فقط وتنتهي 7:10 م.
A10: 7 | B10: الحد الأقصى لأيام الدوري = 21 يوماً | C10: دوري المجموعات لا يتجاوز 21 يوم مهرجان، وإذا لم تكفِ الأيام يُزاد عدد الملاعب لا الأيام. | D10: ✔ مطبق بالكامل | E10: أعلى قيمة مستخدمة 21 يوماً (معظم البطولات)، وأقلها 18 يوماً (10 فرق). لا تجاوز في أي ورقة.
A11: 8 | B11: إجمالي أيام البطولة لا يتجاوز 23 يوماً | C11: أيام الدوري + أيام الإقصاء معاً في سقف واحد، وأيام الإقصاء تأتي إضافةً بعد انتهاء الدوري. | D11: ✔ مطبق بالكامل | E11: الأقصى المسجل 23 يوماً في 23 و31 و35 و48 فريقًا (21 دوري + 2–3 إقصاء)، والأقل 18 يوماً.
A12: 9 | B12: الإقصاء فقط عند تعدد المجموعات | C12: المجموعة الواحدة تحسم بالدوري بدون إقصاء، وعند تعدد المجموعات يتأهل متصدر كل مجموعة لدور إقصائي بحجم عدد المجموعات. | D12: ✔ مطبق بالكامل | E12: بدون إقصاء: 6، 7، 8، 10، 19، 20، 21، 22. نهائي مباشر (مجموعتان): 13، 14، 15، 16. نصف نهائي ثم نهائي: 18، 23، 31. ربع نهائي فما بعده: 35، 48.
A13: 10 | B13: أقل عدد ممكن من الملاعب | C13: لا يُفتح ملعب إضافي إلا إذا لم تكفِ الفترات الثلاث وأيام السقف 21 يوماً لتغطية المباريات. | D13: ✔ مطبق بالكامل | E13: ملعب واحد: 6 و7. ملعبان: 8، 10، 13، 14. ثم يزيد تدريجياً: 3 ملاعب (15–19)، 4 (20–23)، 5 (31 و35)، 8 (48).
A14: 11 | B14: كل المجموعات تلعب في نفس الوقت | C14: المجموعات لا تتناوب على الأيام؛ كل المجموعات تلعب في نفس المهرجان ونفس الأيام، وتُوزَّع مبارياتها على الملاعب والفترات المتاحة في اليوم نفسه. | D14: ✔ مطبق بالكامل | E14: متحقق في جميع الأوراق متعددة المجموعات: نفس الأيام لكل المجموعات. ملاحظة: الملاعب لم تُعد مثبَّتة لكل مجموعة، بل تُوزَّع بالتناوب لتحقيق عدالة الفترات (مبدأ 13).
A15: 12 | B15: وقت موحد لكل البطولات | C15: كل جداول تحت 14 تبدأ 4:00 م وتستخدم نفس الفترات المعرفة في ورقة المدخلات، وأي تعديل في المدخلات ينعكس تلقائياً على كل الأوراق. | D15: ✔ مطبق بالكامل | E15: أعمدة الوقت في كل الأوراق مربوطة بصيغة بورقة المدخلات وليست قيماً ثابتة.
A16: 13 | B16: عدالة توزيع الفترات | C16: لا يُثبَّت فريق أو مجموعة على فترة واحدة طول الموسم؛ تتدوّر فترات المباريات (4:00 / 5:40 / 7:20) بين كل الفرق بالتساوي داخل كل مجموعة. | D16: ✔ مطبق بالكامل | E16: بعد إعادة التوزيع: الفرق بين أي فريقين في عدد مرات اللعب في نفس الفترة لا يتجاوز مباراتين داخل المجموعة الواحدة، وزال تثبيت الفريق 1 على الفترة الأولى وتثبيت المجموعات على فترة واحدة في 31 و48 فريقًا. الفترة الثالثة تُستخدم أقل في بعض الأعداد لأن مباريات اليوم لا تحتاجها (مبدأ 6).

Sheet الملخص
A1: ملخص بطولات تحت 14 — الأعداد المطلوبة
A3: عدد الفرق | B3: عدد المجموعات | C3: توزيع الفرق في المجموعات | D3: لقاءات كل خصم | E3: مباريات كل فريق في الموسم | F3: نظام الإقصاء | G3: أيام الدوري | H3: أيام الإقصاء | I3: إجمالي الأيام | J3: وقت البداية | K3: وقت النهاية | L3: عدد الملاعب القانونية
A4: 6 | B4: {=ROUND(SUMPRODUCT(1/COUNTIF('بيانات الفرق'!$B$3:$B$8,'بيانات الفرق'!$B$3:$B$8)),0)} -> 1 | C4: {=_xlfn.TEXTJOIN(" + ",TRUE,_xlfn._xlws.SORT(COUNTIF('بيانات الفرق'!$B$3:$B$8,"المجموعة "&_xlfn.SEQUENCE(B4))))} -> 6 | D4: {=_xlfn.LET(_xlpm.gs,_xlfn.SEQUENCE(B4),_xlpm.ln,_xlfn.MAXIFS('بيانات الفرق'!$D$3:$D$8,'بيانات الفرق'!$B$3:$B$8,"المجموعة "&_xlpm.gs),_xlpm.mn,_xlfn.MINIFS('بيانات الفرق'!$C$3:$C$8,'بيانات الفرق'!$B$3:$B$8,"المجموعة "&_xlpm.gs),_xlpm.mx,_xlfn.MAXIFS('بيانات الفرق'!$C$3:$C$8,'بيانات الفرق'!$B$3:$B$8,"المجموعة "&_xlpm.gs),_xlpm.lo,FLOOR(_xlpm.mn/_xlpm.ln,1),_xlpm.hi,CEILING(_xlpm.mx/_xlpm.ln,1),_xlpm.t,IF(_xlpm.lo=_xlpm.hi,_xlpm.lo&"",_xlpm.lo&"–"&_xlpm.hi),_xlfn.TEXTJOIN(" + ",TRUE,_xlfn.SORTBY(_xlpm.t,_xlpm.ln,1)))} -> 4 | E4: {=_xlfn.LET(_xlpm.gs,_xlfn.SEQUENCE(B4),_xlpm.ln,_xlfn.MAXIFS('بيانات الفرق'!$D$3:$D$8,'بيانات الفرق'!$B$3:$B$8,"المجموعة "&_xlpm.gs),_xlpm.mn,_xlfn.MINIFS('بيانات الفرق'!$C$3:$C$8,'بيانات الفرق'!$B$3:$B$8,"المجموعة "&_xlpm.gs),_xlpm.mx,_xlfn.MAXIFS('بيانات الفرق'!$C$3:$C$8,'بيانات الفرق'!$B$3:$B$8,"المجموعة "&_xlpm.gs),_xlpm.t,IF(_xlpm.mn=_xlpm.mx,_xlpm.mn&"",_xlpm.mn&"–"&_xlpm.mx),_xlfn.TEXTJOIN(" + ",TRUE,_xlfn.SORTBY(_xlpm.t,_xlpm.ln,1)))} -> 20 | F4: ="—" -> — | G4: =MAX('6 فرق'!$A$4:$A$63) -> 20 | H4: =MAX('6 فرق'!$A$4:$A$63)-G4 -> 0 | I4: =MAX('6 فرق'!$A$4:$A$63) -> 20 | J4: =MOD(HOUR(المدخلات!$B$5)-1,12)+1&":"&TEXT(MINUTE(المدخلات!$B$5),"00")&IF(HOUR(المدخلات!$B$5)<12," ص"," م") -> 4:00 م | K4: {=MOD(HOUR(المدخلات!$B$5+((ROUND(SUMPRODUCT(1/COUNTIF('6 فرق'!$B$4:$B$63,'6 فرق'!$B$4:$B$63)),0)-1)*المدخلات!$B$8+المدخلات!$B$6)/1440)-1,12)+1&":"&TEXT(MINUTE(المدخلات!$B$5+((ROUND(SUMPRODUCT(1/COUNTIF('6 فرق'!$B$4:$B$63,'6 فرق'!$B$4:$B$63)),0)-1)*المدخلات!$B$8+المدخلات!$B$6)/1440),"00")&IF(HOUR(المدخلات!$B$5+((ROUND(SUMPRODUCT(1/COUNTIF('6 فرق'!$B$4:$B$63,'6 فرق'!$B$4:$B$63)),0)-1)*المدخلات!$B$8+المدخلات!$B$6)/1440)<12," ص"," م")} -> 8:50 م | L4: =MAX('6 فرق'!$C$4:$C$63) -> 1
A5: 7 | B5: {=ROUND(SUMPRODUCT(1/COUNTIF('بيانات الفرق'!$G$3:$G$9,'بيانات الفرق'!$G$3:$G$9)),0)} -> 1 | C5: {=_xlfn.TEXTJOIN(" + ",TRUE,_xlfn._xlws.SORT(COUNTIF('بيانات الفرق'!$G$3:$G$9,"المجموعة "&_xlfn.SEQUENCE(B5))))} -> 7 | D5: {=_xlfn.LET(_xlpm.gs,_xlfn.SEQUENCE(B5),_xlpm.ln,_xlfn.MAXIFS('بيانات الفرق'!$I$3:$I$9,'بيانات الفرق'!$G$3:$G$9,"المجموعة "&_xlpm.gs),_xlpm.mn,_xlfn.MINIFS('بيانات الفرق'!$H$3:$H$9,'بيانات الفرق'!$G$3:$G$9,"المجموعة "&_xlpm.gs),_xlpm.mx,_xlfn.MAXIFS('بيانات الفرق'!$H$3:$H$9,'بيانات الفرق'!$G$3:$G$9,"المجموعة "&_xlpm.gs),_xlpm.lo,FLOOR(_xlpm.mn/_xlpm.ln,1),_xlpm.hi,CEILING(_xlpm.mx/_xlpm.ln,1),_xlpm.t,IF(_xlpm.lo=_xlpm.hi,_xlpm.lo&"",_xlpm.lo&"–"&_xlpm.hi),_xlfn.TEXTJOIN(" + ",TRUE,_xlfn.SORTBY(_xlpm.t,_xlpm.ln,1)))} -> 3 | E5: {=_xlfn.LET(_xlpm.gs,_xlfn.SEQUENCE(B5),_xlpm.ln,_xlfn.MAXIFS('بيانات الفرق'!$I$3:$I$9,'بيانات الفرق'!$G$3:$G$9,"المجموعة "&_xlpm.gs),_xlpm.mn,_xlfn.MINIFS('بيانات الفرق'!$H$3:$H$9,'بيانات الفرق'!$G$3:$G$9,"المجموعة "&_xlpm.gs),_xlpm.mx,_xlfn.MAXIFS('بيانات الفرق'!$H$3:$H$9,'بيانات الفرق'!$G$3:$G$9,"المجموعة "&_xlpm.gs),_xlpm.t,IF(_xlpm.mn=_xlpm.mx,_xlpm.mn&"",_xlpm.mn&"–"&_xlpm.mx),_xlfn.TEXTJOIN(" + ",TRUE,_xlfn.SORTBY(_xlpm.t,_xlpm.ln,1)))} -> 18 | F5: ="—" -> — | G5: =MAX('7 فرق'!$A$4:$A$66) -> 21 | H5: =MAX('7 فرق'!$A$4:$A$66)-G5 -> 0 | I5: =MAX('7 فرق'!$A$4:$A$66) -> 21 | J5: =MOD(HOUR(المدخلات!$B$5)-1,12)+1&":"&TEXT(MINUTE(المدخلات!$B$5),"00")&IF(HOUR(المدخلات!$B$5)<12," ص"," م") -> 4:00 م | K5: {=MOD(HOUR(المدخلات!$B$5+((ROUND(SUMPRODUCT(1/COUNTIF('7 فرق'!$B$4:$B$66,'7 فرق'!$B$4:$B$66)),0)-1)*المدخلات!$B$8+المدخلات!$B$6)/1440)-1,12)+1&":"&TEXT(MINUTE(المدخلات!$B$5+((ROUND(SUMPRODUCT(1/COUNTIF('7 فرق'!$B$4:$B$66,'7 فرق'!$B$4:$B$66)),0)-1)*المدخلات!$B$8+المدخلات!$B$6)/1440),"00")&IF(HOUR(المدخلات!$B$5+((ROUND(SUMPRODUCT(1/COUNTIF('7 فرق'!$B$4:$B$66,'7 فرق'!$B$4:$B$66)),0)-1)*المدخلات!$B$8+المدخلات!$B$6)/1440)<12," ص"," م")} -> 8:50 م | L5: =MAX('7 فرق'!$C$4:$C$66) -> 1
A6: 8 | B6: {=ROUND(SUMPRODUCT(1/COUNTIF('بيانات الفرق'!$L$3:$L$10,'بيانات الفرق'!$L$3:$L$10)),0)} -> 1 | C6: {=_xlfn.TEXTJOIN(" + ",TRUE,_xlfn._xlws.SORT(COUNTIF('بيانات الفرق'!$L$3:$L$10,"المجموعة "&_xlfn.SEQUENCE(B6))))} -> 8 | D6: {=_xlfn.LET(_xlpm.gs,_xlfn.SEQUENCE(B6),_xlpm.ln,_xlfn.MAXIFS('بيانات الفرق'!$N$3:$N$10,'بيانات الفرق'!$L$3:$L$10,"المجموعة "&_xlpm.gs),_xlpm.mn,_xlfn.MINIFS('بيانات الفرق'!$M$3:$M$10,'بيانات الفرق'!$L$3:$L$10,"المجموعة "&_xlpm.gs),_xlpm.mx,_xlfn.MAXIFS('بيانات الفرق'!$M$3:$M$10,'بيانات الفرق'!$L$3:$L$10,"المجموعة "&_xlpm.gs),_xlpm.lo,FLOOR(_xlpm.mn/_xlpm.ln,1),_xlpm.hi,CEILING(_xlpm.mx/_xlpm.ln,1),_xlpm.t,IF(_xlpm.lo=_xlpm.hi,_xlpm.lo&"",_xlpm.lo&"–"&_xlpm.hi),_xlfn.TEXTJOIN(" + ",TRUE,_xlfn.SORTBY(_xlpm.t,_xlpm.ln,1)))} -> 3 | E6: {=_xlfn.LET(_xlpm.gs,_xlfn.SEQUENCE(B6),_xlpm.ln,_xlfn.MAXIFS('بيانات الفرق'!$N$3:$N$10,'بيانات الفرق'!$L$3:$L$10,"المجموعة "&_xlpm.gs),_xlpm.mn,_xlfn.MINIFS('بيانات الفرق'!$M$3:$M$10,'بيانات الفرق'!$L$3:$L$10,"المجموعة "&_xlpm.gs),_xlpm.mx,_xlfn.MAXIFS('بيانات الفرق'!$M$3:$M$10,'بيانات الفرق'!$L$3:$L$10,"المجموعة "&_xlpm.gs),_xlpm.t,IF(_xlpm.mn=_xlpm.mx,_xlpm.mn&"",_xlpm.mn&"–"&_xlpm.mx),_xlfn.TEXTJOIN(" + ",TRUE,_xlfn.SORTBY(_xlpm.t,_xlpm.ln,1)))} -> 21 | F6: ="—" -> — | G6: =MAX('8 فرق'!$A$4:$A$87) -> 21 | H6: =MAX('8 فرق'!$A$4:$A$87)-G6 -> 0 | I6: =MAX('8 فرق'!$A$4:$A$87) -> 21 | J6: =MOD(HOUR(المدخلات!$B$5)-1,12)+1&":"&TEXT(MINUTE(المدخلات!$B$5),"00")&IF(HOUR(المدخلات!$B$5)<12," ص"," م") -> 4:00 م | K6: {=MOD(HOUR(المدخلات!$B$5+((ROUND(SUMPRODUCT(1/COUNTIF('8 فرق'!$B$4:$B$87,'8 فرق'!$B$4:$B$87)),0)-1)*المدخلات!$B$8+المدخلات!$B$6)/1440)-1,12)+1&":"&TEXT(MINUTE(المدخلات!$B$5+((ROUND(SUMPRODUCT(1/COUNTIF('8 فرق'!$B$4:$B$87,'8 فرق'!$B$4:$B$87)),0)-1)*المدخلات!$B$8+المدخلات!$B$6)/1440),"00")&IF(HOUR(المدخلات!$B$5+((ROUND(SUMPRODUCT(1/COUNTIF('8 فرق'!$B$4:$B$87,'8 فرق'!$B$4:$B$87)),0)-1)*المدخلات!$B$8+المدخلات!$B$6)/1440)<12," ص"," م")} -> 7:10 م | L6: =MAX('8 فرق'!$C$4:$C$87) -> 2
A7: 10 | B7: {=ROUND(SUMPRODUCT(1/COUNTIF('بيانات الفرق'!$Q$3:$Q$12,'بيانات الفرق'!$Q$3:$Q$12)),0)} -> 1 | C7: {=_xlfn.TEXTJOIN(" + ",TRUE,_xlfn._xlws.SORT(COUNTIF('بيانات الفرق'!$Q$3:$Q$12,"المجموعة "&_xlfn.SEQUENCE(B7))))} -> 10 | D7: {=_xlfn.LET(_xlpm.gs,_xlfn.SEQUENCE(B7),_xlpm.ln,_xlfn.MAXIFS('بيانات الفرق'!$S$3:$S$12,'بيانات الفرق'!$Q$3:$Q$12,"المجموعة "&_xlpm.gs),_xlpm.mn,_xlfn.MINIFS('بيانات الفرق'!$R$3:$R$12,'بيانات الفرق'!$Q$3:$Q$12,"المجموعة "&_xlpm.gs),_xlpm.mx,_xlfn.MAXIFS('بيانات الفرق'!$R$3:$R$12,'بيانات الفرق'!$Q$3:$Q$12,"المجموعة "&_xlpm.gs),_xlpm.lo,FLOOR(_xlpm.mn/_xlpm.ln,1),_xlpm.hi,CEILING(_xlpm.mx/_xlpm.ln,1),_xlpm.t,IF(_xlpm.lo=_xlpm.hi,_xlpm.lo&"",_xlpm.lo&"–"&_xlpm.hi),_xlfn.TEXTJOIN(" + ",TRUE,_xlfn.SORTBY(_xlpm.t,_xlpm.ln,1)))} -> 2 | E7: {=_xlfn.LET(_xlpm.gs,_xlfn.SEQUENCE(B7),_xlpm.ln,_xlfn.MAXIFS('بيانات الفرق'!$S$3:$S$12,'بيانات الفرق'!$Q$3:$Q$12,"المجموعة "&_xlpm.gs),_xlpm.mn,_xlfn.MINIFS('بيانات الفرق'!$R$3:$R$12,'بيانات الفرق'!$Q$3:$Q$12,"المجموعة "&_xlpm.gs),_xlpm.mx,_xlfn.MAXIFS('بيانات الفرق'!$R$3:$R$12,'بيانات الفرق'!$Q$3:$Q$12,"المجموعة "&_xlpm.gs),_xlpm.t,IF(_xlpm.mn=_xlpm.mx,_xlpm.mn&"",_xlpm.mn&"–"&_xlpm.mx),_xlfn.TEXTJOIN(" + ",TRUE,_xlfn.SORTBY(_xlpm.t,_xlpm.ln,1)))} -> 18 | F7: ="—" -> — | G7: =MAX('10 فرق'!$A$4:$A$93) -> 18 | H7: =MAX('10 فرق'!$A$4:$A$93)-G7 -> 0 | I7: =MAX('10 فرق'!$A$4:$A$93) -> 18 | J7: =MOD(HOUR(المدخلات!$B$5)-1,12)+1&":"&TEXT(MINUTE(المدخلات!$B$5),"00")&IF(HOUR(المدخلات!$B$5)<12," ص"," م") -> 4:00 م | K7: {=MOD(HOUR(المدخلات!$B$5+((ROUND(SUMPRODUCT(1/COUNTIF('10 فرق'!$B$4:$B$93,'10 فرق'!$B$4:$B$93)),0)-1)*المدخلات!$B$8+المدخلات!$B$6)/1440)-1,12)+1&":"&TEXT(MINUTE(المدخلات!$B$5+((ROUND(SUMPRODUCT(1/COUNTIF('10 فرق'!$B$4:$B$93,'10 فرق'!$B$4:$B$93)),0)-1)*المدخلات!$B$8+المدخلات!$B$6)/1440),"00")&IF(HOUR(المدخلات!$B$5+((ROUND(SUMPRODUCT(1/COUNTIF('10 فرق'!$B$4:$B$93,'10 فرق'!$B$4:$B$93)),0)-1)*المدخلات!$B$8+المدخلات!$B$6)/1440)<12," ص"," م")} -> 8:50 م | L7: =MAX('10 فرق'!$C$4:$C$93) -> 2
A8: 13 | B8: {=ROUND(SUMPRODUCT(1/COUNTIF('بيانات الفرق'!$V$3:$V$15,'بيانات الفرق'!$V$3:$V$15)),0)} -> 2 | C8: {=_xlfn.TEXTJOIN(" + ",TRUE,_xlfn._xlws.SORT(COUNTIF('بيانات الفرق'!$V$3:$V$15,"المجموعة "&_xlfn.SEQUENCE(B8))))} -> 6 + 7 | D8: {=_xlfn.LET(_xlpm.gs,_xlfn.SEQUENCE(B8),_xlpm.ln,_xlfn.MAXIFS('بيانات الفرق'!$X$3:$X$15,'بيانات الفرق'!$V$3:$V$15,"المجموعة "&_xlpm.gs),_xlpm.mn,_xlfn.MINIFS('بيانات الفرق'!$W$3:$W$15,'بيانات الفرق'!$V$3:$V$15,"المجموعة "&_xlpm.gs),_xlpm.mx,_xlfn.MAXIFS('بيانات الفرق'!$W$3:$W$15,'بيانات الفرق'!$V$3:$V$15,"المجموعة "&_xlpm.gs),_xlpm.lo,FLOOR(_xlpm.mn/_xlpm.ln,1),_xlpm.hi,CEILING(_xlpm.mx/_xlpm.ln,1),_xlpm.t,IF(_xlpm.lo=_xlpm.hi,_xlpm.lo&"",_xlpm.lo&"–"&_xlpm.hi),_xlfn.TEXTJOIN(" + ",TRUE,_xlfn.SORTBY(_xlpm.t,_xlpm.ln,1)))} -> 4 + 3 | E8: {=_xlfn.LET(_xlpm.gs,_xlfn.SEQUENCE(B8),_xlpm.ln,_xlfn.MAXIFS('بيانات الفرق'!$X$3:$X$15,'بيانات الفرق'!$V$3:$V$15,"المجموعة "&_xlpm.gs),_xlpm.mn,_xlfn.MINIFS('بيانات الفرق'!$W$3:$W$15,'بيانات الفرق'!$V$3:$V$15,"المجموعة "&_xlpm.gs),_xlpm.mx,_xlfn.MAXIFS('بيانات الفرق'!$W$3:$W$15,'بيانات الفرق'!$V$3:$V$15,"المجموعة "&_xlpm.gs),_xlpm.t,IF(_xlpm.mn=_xlpm.mx,_xlpm.mn&"",_xlpm.mn&"–"&_xlpm.mx),_xlfn.TEXTJOIN(" + ",TRUE,_xlfn.SORTBY(_xlpm.t,_xlpm.ln,1)))} -> 20 + 18 | F8: =IF(COUNTIF('13 فريقًا'!$D$4:$D$127,"نهائي")=0,"—",IF(COUNTIF('13 فريقًا'!$D$4:$D$127,"ربع نهائي")>0,"ربع نهائي ثم نصف نهائي ثم نهائي",IF(COUNTIF('13 فريقًا'!$D$4:$D$127,"نصف نهائي")>0,"نصف نهائي ثم نهائي","نهائي مباشر"))) -> نهائي مباشر | G8: =_xlfn.MAXIFS('13 فريقًا'!$A$4:$A$127,'13 فريقًا'!$D$4:$D$127,"المجموعة*") -> 21 | H8: =MAX('13 فريقًا'!$A$4:$A$127)-G8 -> 1 | I8: =MAX('13 فريقًا'!$A$4:$A$127) -> 22 | J8: =MOD(HOUR(المدخلات!$B$5)-1,12)+1&":"&TEXT(MINUTE(المدخلات!$B$5),"00")&IF(HOUR(المدخلات!$B$5)<12," ص"," م") -> 4:00 م | K8: {=MOD(HOUR(المدخلات!$B$5+((ROUND(SUMPRODUCT(1/COUNTIF('13 فريقًا'!$B$4:$B$127,'13 فريقًا'!$B$4:$B$127)),0)-1)*المدخلات!$B$8+المدخلات!$B$6)/1440)-1,12)+1&":"&TEXT(MINUTE(المدخلات!$B$5+((ROUND(SUMPRODUCT(1/COUNTIF('13 فريقًا'!$B$4:$B$127,'13 فريقًا'!$B$4:$B$127)),0)-1)*المدخلات!$B$8+المدخلات!$B$6)/1440),"00")&IF(HOUR(المدخلات!$B$5+((ROUND(SUMPRODUCT(1/COUNTIF('13 فريقًا'!$B$4:$B$127,'13 فريقًا'!$B$4:$B$127)),0)-1)*المدخلات!$B$8+المدخلات!$B$6)/1440)<12," ص"," م")} -> 8:50 م | L8: =MAX('13 فريقًا'!$C$4:$C$127) -> 2
A9: 14 | B9: {=ROUND(SUMPRODUCT(1/COUNTIF('بيانات الفرق'!$AA$3:$AA$16,'بيانات الفرق'!$AA$3:$AA$16)),0)} -> 2 | C9: {=_xlfn.TEXTJOIN(" + ",TRUE,_xlfn._xlws.SORT(COUNTIF('بيانات الفرق'!$AA$3:$AA$16,"المجموعة "&_xlfn.SEQUENCE(B9))))} -> 7 + 7 | D9: {=_xlfn.LET(_xlpm.gs,_xlfn.SEQUENCE(B9),_xlpm.ln,_xlfn.MAXIFS('بيانات الفرق'!$AC$3:$AC$16,'بيانات الفرق'!$AA$3:$AA$16,"المجموعة "&_xlpm.gs),_xlpm.mn,_xlfn.MINIFS('بيانات الفرق'!$AB$3:$AB$16,'بيانات الفرق'!$AA$3:$AA$16,"المجموعة "&_xlpm.gs),_xlpm.mx,_xlfn.MAXIFS('بيانات الفرق'!$AB$3:$AB$16,'بيانات الفرق'!$AA$3:$AA$16,"المجموعة "&_xlpm.gs),_xlpm.lo,FLOOR(_xlpm.mn/_xlpm.ln,1),_xlpm.hi,CEILING(_xlpm.mx/_xlpm.ln,1),_xlpm.t,IF(_xlpm.lo=_xlpm.hi,_xlpm.lo&"",_xlpm.lo&"–"&_xlpm.hi),_xlfn.TEXTJOIN(" + ",TRUE,_xlfn.SORTBY(_xlpm.t,_xlpm.ln,1)))} -> 3 + 3 | E9: {=_xlfn.LET(_xlpm.gs,_xlfn.SEQUENCE(B9),_xlpm.ln,_xlfn.MAXIFS('بيانات الفرق'!$AC$3:$AC$16,'بيانات الفرق'!$AA$3:$AA$16,"المجموعة "&_xlpm.gs),_xlpm.mn,_xlfn.MINIFS('بيانات الفرق'!$AB$3:$AB$16,'بيانات الفرق'!$AA$3:$AA$16,"المجموعة "&_xlpm.gs),_xlpm.mx,_xlfn.MAXIFS('بيانات الفرق'!$AB$3:$AB$16,'بيانات الفرق'!$AA$3:$AA$16,"المجموعة "&_xlpm.gs),_xlpm.t,IF(_xlpm.mn=_xlpm.mx,_xlpm.mn&"",_xlpm.mn&"–"&_xlpm.mx),_xlfn.TEXTJOIN(" + ",TRUE,_xlfn.SORTBY(_xlpm.t,_xlpm.ln,1)))} -> 18 + 18 | F9: =IF(COUNTIF('14 فريقًا'!$D$4:$D$130,"نهائي")=0,"—",IF(COUNTIF('14 فريقًا'!$D$4:$D$130,"ربع نهائي")>0,"ربع نهائي ثم نصف نهائي ثم نهائي",IF(COUNTIF('14 فريقًا'!$D$4:$D$130,"نصف نهائي")>0,"نصف نهائي ثم نهائي","نهائي مباشر"))) -> نهائي مباشر | G9: =_xlfn.MAXIFS('14 فريقًا'!$A$4:$A$130,'14 فريقًا'!$D$4:$D$130,"المجموعة*") -> 21 | H9: =MAX('14 فريقًا'!$A$4:$A$130)-G9 -> 1 | I9: =MAX('14 فريقًا'!$A$4:$A$130) -> 22 | J9: =MOD(HOUR(المدخلات!$B$5)-1,12)+1&":"&TEXT(MINUTE(المدخلات!$B$5),"00")&IF(HOUR(المدخلات!$B$5)<12," ص"," م") -> 4:00 م | K9: {=MOD(HOUR(المدخلات!$B$5+((ROUND(SUMPRODUCT(1/COUNTIF('14 فريقًا'!$B$4:$B$130,'14 فريقًا'!$B$4:$B$130)),0)-1)*المدخلات!$B$8+المدخلات!$B$6)/1440)-1,12)+1&":"&TEXT(MINUTE(المدخلات!$B$5+((ROUND(SUMPRODUCT(1/COUNTIF('14 فريقًا'!$B$4:$B$130,'14 فريقًا'!$B$4:$B$130)),0)-1)*المدخلات!$B$8+المدخلات!$B$6)/1440),"00")&IF(HOUR(المدخلات!$B$5+((ROUND(SUMPRODUCT(1/COUNTIF('14 فريقًا'!$B$4:$B$130,'14 فريقًا'!$B$4:$B$130)),0)-1)*المدخلات!$B$8+المدخلات!$B$6)/1440)<12," ص"," م")} -> 8:50 م | L9: =MAX('14 فريقًا'!$C$4:$C$130) -> 2
A10: 15 | B10: {=ROUND(SUMPRODUCT(1/COUNTIF('بيانات الفرق'!$AF$3:$AF$17,'بيانات الفرق'!$AF$3:$AF$17)),0)} -> 2 | C10: {=_xlfn.TEXTJOIN(" + ",TRUE,_xlfn._xlws.SORT(COUNTIF('بيانات الفرق'!$AF$3:$AF$17,"المجموعة "&_xlfn.SEQUENCE(B10))))} -> 7 + 8 | D10: {=_xlfn.LET(_xlpm.gs,_xlfn.SEQUENCE(B10),_xlpm.ln,_xlfn.MAXIFS('بيانات الفرق'!$AH$3:$AH$17,'بيانات الفرق'!$AF$3:$AF$17,"المجموعة "&_xlpm.gs),_xlpm.mn,_xlfn.MINIFS('بيانات الفرق'!$AG$3:$AG$17,'بيانات الفرق'!$AF$3:$AF$17,"المجموعة "&_xlpm.gs),_xlpm.mx,_xlfn.MAXIFS('بيانات الفرق'!$AG$3:$AG$17,'بيانات الفرق'!$AF$3:$AF$17,"المجموعة "&_xlpm.gs),_xlpm.lo,FLOOR(_xlpm.mn/_xlpm.ln,1),_xlpm.hi,CEILING(_xlpm.mx/_xlpm.ln,1),_xlpm.t,IF(_xlpm.lo=_xlpm.hi,_xlpm.lo&"",_xlpm.lo&"–"&_xlpm.hi),_xlfn.TEXTJOIN(" + ",TRUE,_xlfn.SORTBY(_xlpm.t,_xlpm.ln,1)))} -> 3 + 3 | E10: {=_xlfn.LET(_xlpm.gs,_xlfn.SEQUENCE(B10),_xlpm.ln,_xlfn.MAXIFS('بيانات الفرق'!$AH$3:$AH$17,'بيانات الفرق'!$AF$3:$AF$17,"المجموعة "&_xlpm.gs),_xlpm.mn,_xlfn.MINIFS('بيانات الفرق'!$AG$3:$AG$17,'بيانات الفرق'!$AF$3:$AF$17,"المجموعة "&_xlpm.gs),_xlpm.mx,_xlfn.MAXIFS('بيانات الفرق'!$AG$3:$AG$17,'بيانات الفرق'!$AF$3:$AF$17,"المجموعة "&_xlpm.gs),_xlpm.t,IF(_xlpm.mn=_xlpm.mx,_xlpm.mn&"",_xlpm.mn&"–"&_xlpm.mx),_xlfn.TEXTJOIN(" + ",TRUE,_xlfn.SORTBY(_xlpm.t,_xlpm.ln,1)))} -> 18 + 21 | F10: =IF(COUNTIF('15 فريقًا'!$D$4:$D$151,"نهائي")=0,"—",IF(COUNTIF('15 فريقًا'!$D$4:$D$151,"ربع نهائي")>0,"ربع نهائي ثم نصف نهائي ثم نهائي",IF(COUNTIF('15 فريقًا'!$D$4:$D$151,"نصف نهائي")>0,"نصف نهائي ثم نهائي","نهائي مباشر"))) -> نهائي مباشر | G10: =_xlfn.MAXIFS('15 فريقًا'!$A$4:$A$151,'15 فريقًا'!$D$4:$D$151,"المجموعة*") -> 21 | H10: =MAX('15 فريقًا'!$A$4:$A$151)-G10 -> 1 | I10: =MAX('15 فريقًا'!$A$4:$A$151) -> 22 | J10: =MOD(HOUR(المدخلات!$B$5)-1,12)+1&":"&TEXT(MINUTE(المدخلات!$B$5),"00")&IF(HOUR(المدخلات!$B$5)<12," ص"," م") -> 4:00 م | K10: {=MOD(HOUR(المدخلات!$B$5+((ROUND(SUMPRODUCT(1/COUNTIF('15 فريقًا'!$B$4:$B$151,'15 فريقًا'!$B$4:$B$151)),0)-1)*المدخلات!$B$8+المدخلات!$B$6)/1440)-1,12)+1&":"&TEXT(MINUTE(المدخلات!$B$5+((ROUND(SUMPRODUCT(1/COUNTIF('15 فريقًا'!$B$4:$B$151,'15 فريقًا'!$B$4:$B$151)),0)-1)*المدخلات!$B$8+المدخلات!$B$6)/1440),"00")&IF(HOUR(المدخلات!$B$5+((ROUND(SUMPRODUCT(1/COUNTIF('15 فريقًا'!$B$4:$B$151,'15 فريقًا'!$B$4:$B$151)),0)-1)*المدخلات!$B$8+المدخلات!$B$6)/1440)<12," ص"," م")} -> 8:50 م | L10: =MAX('15 فريقًا'!$C$4:$C$151) -> 3
A11: 16 | B11: {=ROUND(SUMPRODUCT(1/COUNTIF('بيانات الفرق'!$AK$3:$AK$18,'بيانات الفرق'!$AK$3:$AK$18)),0)} -> 2 | C11: {=_xlfn.TEXTJOIN(" + ",TRUE,_xlfn._xlws.SORT(COUNTIF('بيانات الفرق'!$AK$3:$AK$18,"المجموعة "&_xlfn.SEQUENCE(B11))))} -> 8 + 8 | D11: {=_xlfn.LET(_xlpm.gs,_xlfn.SEQUENCE(B11),_xlpm.ln,_xlfn.MAXIFS('بيانات الفرق'!$AM$3:$AM$18,'بيانات الفرق'!$AK$3:$AK$18,"المجموعة "&_xlpm.gs),_xlpm.mn,_xlfn.MINIFS('بيانات الفرق'!$AL$3:$AL$18,'بيانات الفرق'!$AK$3:$AK$18,"المجموعة "&_xlpm.gs),_xlpm.mx,_xlfn.MAXIFS('بيانات الفرق'!$AL$3:$AL$18,'بيانات الفرق'!$AK$3:$AK$18,"المجموعة "&_xlpm.gs),_xlpm.lo,FLOOR(_xlpm.mn/_xlpm.ln,1),_xlpm.hi,CEILING(_xlpm.mx/_xlpm.ln,1),_xlpm.t,IF(_xlpm.lo=_xlpm.hi,_xlpm.lo&"",_xlpm.lo&"–"&_xlpm.hi),_xlfn.TEXTJOIN(" + ",TRUE,_xlfn.SORTBY(_xlpm.t,_xlpm.ln,1)))} -> 3 + 3 | E11: {=_xlfn.LET(_xlpm.gs,_xlfn.SEQUENCE(B11),_xlpm.ln,_xlfn.MAXIFS('بيانات الفرق'!$AM$3:$AM$18,'بيانات الفرق'!$AK$3:$AK$18,"المجموعة "&_xlpm.gs),_xlpm.mn,_xlfn.MINIFS('بيانات الفرق'!$AL$3:$AL$18,'بيانات الفرق'!$AK$3:$AK$18,"المجموعة "&_xlpm.gs),_xlpm.mx,_xlfn.MAXIFS('بيانات الفرق'!$AL$3:$AL$18,'بيانات الفرق'!$AK$3:$AK$18,"المجموعة "&_xlpm.gs),_xlpm.t,IF(_xlpm.mn=_xlpm.mx,_xlpm.mn&"",_xlpm.mn&"–"&_xlpm.mx),_xlfn.TEXTJOIN(" + ",TRUE,_xlfn.SORTBY(_xlpm.t,_xlpm.ln,1)))} -> 21 + 21 | F11: =IF(COUNTIF('16 فريقًا'!$D$4:$D$172,"نهائي")=0,"—",IF(COUNTIF('16 فريقًا'!$D$4:$D$172,"ربع نهائي")>0,"ربع نهائي ثم نصف نهائي ثم نهائي",IF(COUNTIF('16 فريقًا'!$D$4:$D$172,"نصف نهائي")>0,"نصف نهائي ثم نهائي","نهائي مباشر"))) -> نهائي مباشر | G11: =_xlfn.MAXIFS('16 فريقًا'!$A$4:$A$172,'16 فريقًا'!$D$4:$D$172,"المجموعة*") -> 21 | H11: =MAX('16 فريقًا'!$A$4:$A$172)-G11 -> 1 | I11: =MAX('16 فريقًا'!$A$4:$A$172) -> 22 | J11: =MOD(HOUR(المدخلات!$B$5)-1,12)+1&":"&TEXT(MINUTE(المدخلات!$B$5),"00")&IF(HOUR(المدخلات!$B$5)<12," ص"," م") -> 4:00 م | K11: {=MOD(HOUR(المدخلات!$B$5+((ROUND(SUMPRODUCT(1/COUNTIF('16 فريقًا'!$B$4:$B$172,'16 فريقًا'!$B$4:$B$172)),0)-1)*المدخلات!$B$8+المدخلات!$B$6)/1440)-1,12)+1&":"&TEXT(MINUTE(المدخلات!$B$5+((ROUND(SUMPRODUCT(1/COUNTIF('16 فريقًا'!$B$4:$B$172,'16 فريقًا'!$B$4:$B$172)),0)-1)*المدخلات!$B$8+المدخلات!$B$6)/1440),"00")&IF(HOUR(المدخلات!$B$5+((ROUND(SUMPRODUCT(1/COUNTIF('16 فريقًا'!$B$4:$B$172,'16 فريقًا'!$B$4:$B$172)),0)-1)*المدخلات!$B$8+المدخلات!$B$6)/1440)<12," ص"," م")} -> 8:50 م | L11: =MAX('16 فريقًا'!$C$4:$C$172) -> 3
A12: 18 | B12: {=ROUND(SUMPRODUCT(1/COUNTIF('بيانات الفرق'!$AP$3:$AP$20,'بيانات الفرق'!$AP$3:$AP$20)),0)} -> 3 | C12: {=_xlfn.TEXTJOIN(" + ",TRUE,_xlfn._xlws.SORT(COUNTIF('بيانات الفرق'!$AP$3:$AP$20,"المجموعة "&_xlfn.SEQUENCE(B12))))} -> 6 + 6 + 6 | D12: {=_xlfn.LET(_xlpm.gs,_xlfn.SEQUENCE(B12),_xlpm.ln,_xlfn.MAXIFS('بيانات الفرق'!$AR$3:$AR$20,'بيانات الفرق'!$AP$3:$AP$20,"المجموعة "&_xlpm.gs),_xlpm.mn,_xlfn.MINIFS('بيانات الفرق'!$AQ$3:$AQ$20,'بيانات الفرق'!$AP$3:$AP$20,"المجموعة "&_xlpm.gs),_xlpm.mx,_xlfn.MAXIFS('بيانات الفرق'!$AQ$3:$AQ$20,'بيانات الفرق'!$AP$3:$AP$20,"المجموعة "&_xlpm.gs),_xlpm.lo,FLOOR(_xlpm.mn/_xlpm.ln,1),_xlpm.hi,CEILING(_xlpm.mx/_xlpm.ln,1),_xlpm.t,IF(_xlpm.lo=_xlpm.hi,_xlpm.lo&"",_xlpm.lo&"–"&_xlpm.hi),_xlfn.TEXTJOIN(" + ",TRUE,_xlfn.SORTBY(_xlpm.t,_xlpm.ln,1)))} -> 4 + 4 + 4 | E12: {=_xlfn.LET(_xlpm.gs,_xlfn.SEQUENCE(B12),_xlpm.ln,_xlfn.MAXIFS('بيانات الفرق'!$AR$3:$AR$20,'بيانات الفرق'!$AP$3:$AP$20,"المجموعة "&_xlpm.gs),_xlpm.mn,_xlfn.MINIFS('بيانات الفرق'!$AQ$3:$AQ$20,'بيانات الفرق'!$AP$3:$AP$20,"المجموعة "&_xlpm.gs),_xlpm.mx,_xlfn.MAXIFS('بيانات الفرق'!$AQ$3:$AQ$20,'بيانات الفرق'!$AP$3:$AP$20,"المجموعة "&_xlpm.gs),_xlpm.t,IF(_xlpm.mn=_xlpm.mx,_xlpm.mn&"",_xlpm.mn&"–"&_xlpm.mx),_xlfn.TEXTJOIN(" + ",TRUE,_xlfn.SORTBY(_xlpm.t,_xlpm.ln,1)))} -> 20 + 20 + 20 | F12: =IF(COUNTIF('18 فريقًا'!$D$4:$D$186,"نهائي")=0,"—",IF(COUNTIF('18 فريقًا'!$D$4:$D$186,"ربع نهائي")>0,"ربع نهائي ثم نصف نهائي ثم نهائي",IF(COUNTIF('18 فريقًا'!$D$4:$D$186,"نصف نهائي")>0,"نصف نهائي ثم نهائي","نهائي مباشر"))) -> نصف نهائي ثم نهائي | G12: =_xlfn.MAXIFS('18 فريقًا'!$A$4:$A$186,'18 فريقًا'!$D$4:$D$186,"المجموعة*") -> 20 | H12: =MAX('18 فريقًا'!$A$4:$A$186)-G12 -> 2 | I12: =MAX('18 فريقًا'!$A$4:$A$186) -> 22 | J12: =MOD(HOUR(المدخلات!$B$5)-1,12)+1&":"&TEXT(MINUTE(المدخلات!$B$5),"00")&IF(HOUR(المدخلات!$B$5)<12," ص"," م") -> 4:00 م | K12: {=MOD(HOUR(المدخلات!$B$5+((ROUND(SUMPRODUCT(1/COUNTIF('18 فريقًا'!$B$4:$B$186,'18 فريقًا'!$B$4:$B$186)),0)-1)*المدخلات!$B$8+المدخلات!$B$6)/1440)-1,12)+1&":"&TEXT(MINUTE(المدخلات!$B$5+((ROUND(SUMPRODUCT(1/COUNTIF('18 فريقًا'!$B$4:$B$186,'18 فريقًا'!$B$4:$B$186)),0)-1)*المدخلات!$B$8+المدخلات!$B$6)/1440),"00")&IF(HOUR(المدخلات!$B$5+((ROUND(SUMPRODUCT(1/COUNTIF('18 فريقًا'!$B$4:$B$186,'18 فريقًا'!$B$4:$B$186)),0)-1)*المدخلات!$B$8+المدخلات!$B$6)/1440)<12," ص"," م")} -> 8:50 م | L12: =MAX('18 فريقًا'!$C$4:$C$186) -> 3
A13: 19 | B13: {=ROUND(SUMPRODUCT(1/COUNTIF('بيانات الفرق'!$AU$3:$AU$21,'بيانات الفرق'!$AU$3:$AU$21)),0)} -> 1 | C13: {=_xlfn.TEXTJOIN(" + ",TRUE,_xlfn._xlws.SORT(COUNTIF('بيانات الفرق'!$AU$3:$AU$21,"المجموعة "&_xlfn.SEQUENCE(B13))))} -> 19 | D13: {=_xlfn.LET(_xlpm.gs,_xlfn.SEQUENCE(B13),_xlpm.ln,_xlfn.MAXIFS('بيانات الفرق'!$AW$3:$AW$21,'بيانات الفرق'!$AU$3:$AU$21,"المجموعة "&_xlpm.gs),_xlpm.mn,_xlfn.MINIFS('بيانات الفرق'!$AV$3:$AV$21,'بيانات الفرق'!$AU$3:$AU$21,"المجموعة "&_xlpm.gs),_xlpm.mx,_xlfn.MAXIFS('بيانات الفرق'!$AV$3:$AV$21,'بيانات الفرق'!$AU$3:$AU$21,"المجموعة "&_xlpm.gs),_xlpm.lo,FLOOR(_xlpm.mn/_xlpm.ln,1),_xlpm.hi,CEILING(_xlpm.mx/_xlpm.ln,1),_xlpm.t,IF(_xlpm.lo=_xlpm.hi,_xlpm.lo&"",_xlpm.lo&"–"&_xlpm.hi),_xlfn.TEXTJOIN(" + ",TRUE,_xlfn.SORTBY(_xlpm.t,_xlpm.ln,1)))} -> 1 | E13: {=_xlfn.LET(_xlpm.gs,_xlfn.SEQUENCE(B13),_xlpm.ln,_xlfn.MAXIFS('بيانات الفرق'!$AW$3:$AW$21,'بيانات الفرق'!$AU$3:$AU$21,"المجموعة "&_xlpm.gs),_xlpm.mn,_xlfn.MINIFS('بيانات الفرق'!$AV$3:$AV$21,'بيانات الفرق'!$AU$3:$AU$21,"المجموعة "&_xlpm.gs),_xlpm.mx,_xlfn.MAXIFS('بيانات الفرق'!$AV$3:$AV$21,'بيانات الفرق'!$AU$3:$AU$21,"المجموعة "&_xlpm.gs),_xlpm.t,IF(_xlpm.mn=_xlpm.mx,_xlpm.mn&"",_xlpm.mn&"–"&_xlpm.mx),_xlfn.TEXTJOIN(" + ",TRUE,_xlfn.SORTBY(_xlpm.t,_xlpm.ln,1)))} -> 18 | F13: ="—" -> — | G13: =MAX('19 فريقًا'!$A$4:$A$174) -> 19 | H13: =MAX('19 فريقًا'!$A$4:$A$174)-G13 -> 0 | I13: =MAX('19 فريقًا'!$A$4:$A$174) -> 19 | J13: =MOD(HOUR(المدخلات!$B$5)-1,12)+1&":"&TEXT(MINUTE(المدخلات!$B$5),"00")&IF(HOUR(المدخلات!$B$5)<12," ص"," م") -> 4:00 م | K13: {=MOD(HOUR(المدخلات!$B$5+((ROUND(SUMPRODUCT(1/COUNTIF('19 فريقًا'!$B$4:$B$174,'19 فريقًا'!$B$4:$B$174)),0)-1)*المدخلات!$B$8+المدخلات!$B$6)/1440)-1,12)+1&":"&TEXT(MINUTE(المدخلات!$B$5+((ROUND(SUMPRODUCT(1/COUNTIF('19 فريقًا'!$B$4:$B$174,'19 فريقًا'!$B$4:$B$174)),0)-1)*المدخلات!$B$8+المدخلات!$B$6)/1440),"00")&IF(HOUR(المدخلات!$B$5+((ROUND(SUMPRODUCT(1/COUNTIF('19 فريقًا'!$B$4:$B$174,'19 فريقًا'!$B$4:$B$174)),0)-1)*المدخلات!$B$8+المدخلات!$B$6)/1440)<12," ص"," م")} -> 8:50 م | L13: =MAX('19 فريقًا'!$C$4:$C$174) -> 3
A14: 20 | B14: {=ROUND(SUMPRODUCT(1/COUNTIF('بيانات الفرق'!$AZ$3:$AZ$22,'بيانات الفرق'!$AZ$3:$AZ$22)),0)} -> 1 | C14: {=_xlfn.TEXTJOIN(" + ",TRUE,_xlfn._xlws.SORT(COUNTIF('بيانات الفرق'!$AZ$3:$AZ$22,"المجموعة "&_xlfn.SEQUENCE(B14))))} -> 20 | D14: {=_xlfn.LET(_xlpm.gs,_xlfn.SEQUENCE(B14),_xlpm.ln,_xlfn.MAXIFS('بيانات الفرق'!$BB$3:$BB$22,'بيانات الفرق'!$AZ$3:$AZ$22,"المجموعة "&_xlpm.gs),_xlpm.mn,_xlfn.MINIFS('بيانات الفرق'!$BA$3:$BA$22,'بيانات الفرق'!$AZ$3:$AZ$22,"المجموعة "&_xlpm.gs),_xlpm.mx,_xlfn.MAXIFS('بيانات الفرق'!$BA$3:$BA$22,'بيانات الفرق'!$AZ$3:$AZ$22,"المجموعة "&_xlpm.gs),_xlpm.lo,FLOOR(_xlpm.mn/_xlpm.ln,1),_xlpm.hi,CEILING(_xlpm.mx/_xlpm.ln,1),_xlpm.t,IF(_xlpm.lo=_xlpm.hi,_xlpm.lo&"",_xlpm.lo&"–"&_xlpm.hi),_xlfn.TEXTJOIN(" + ",TRUE,_xlfn.SORTBY(_xlpm.t,_xlpm.ln,1)))} -> 1 | E14: {=_xlfn.LET(_xlpm.gs,_xlfn.SEQUENCE(B14),_xlpm.ln,_xlfn.MAXIFS('بيانات الفرق'!$BB$3:$BB$22,'بيانات الفرق'!$AZ$3:$AZ$22,"المجموعة "&_xlpm.gs),_xlpm.mn,_xlfn.MINIFS('بيانات الفرق'!$BA$3:$BA$22,'بيانات الفرق'!$AZ$3:$AZ$22,"المجموعة "&_xlpm.gs),_xlpm.mx,_xlfn.MAXIFS('بيانات الفرق'!$BA$3:$BA$22,'بيانات الفرق'!$AZ$3:$AZ$22,"المجموعة "&_xlpm.gs),_xlpm.t,IF(_xlpm.mn=_xlpm.mx,_xlpm.mn&"",_xlpm.mn&"–"&_xlpm.mx),_xlfn.TEXTJOIN(" + ",TRUE,_xlfn.SORTBY(_xlpm.t,_xlpm.ln,1)))} -> 19 | F14: ="—" -> — | G14: =MAX('20 فريقًا'!$A$4:$A$193) -> 19 | H14: =MAX('20 فريقًا'!$A$4:$A$193)-G14 -> 0 | I14: =MAX('20 فريقًا'!$A$4:$A$193) -> 19 | J14: =MOD(HOUR(المدخلات!$B$5)-1,12)+1&":"&TEXT(MINUTE(المدخلات!$B$5),"00")&IF(HOUR(المدخلات!$B$5)<12," ص"," م") -> 4:00 م | K14: {=MOD(HOUR(المدخلات!$B$5+((ROUND(SUMPRODUCT(1/COUNTIF('20 فريقًا'!$B$4:$B$193,'20 فريقًا'!$B$4:$B$193)),0)-1)*المدخلات!$B$8+المدخلات!$B$6)/1440)-1,12)+1&":"&TEXT(MINUTE(المدخلات!$B$5+((ROUND(SUMPRODUCT(1/COUNTIF('20 فريقًا'!$B$4:$B$193,'20 فريقًا'!$B$4:$B$193)),0)-1)*المدخلات!$B$8+المدخلات!$B$6)/1440),"00")&IF(HOUR(المدخلات!$B$5+((ROUND(SUMPRODUCT(1/COUNTIF('20 فريقًا'!$B$4:$B$193,'20 فريقًا'!$B$4:$B$193)),0)-1)*المدخلات!$B$8+المدخلات!$B$6)/1440)<12," ص"," م")} -> 8:50 م | L14: =MAX('20 فريقًا'!$C$4:$C$193) -> 4
A15: 21 | B15: {=ROUND(SUMPRODUCT(1/COUNTIF('بيانات الفرق'!$BE$3:$BE$23,'بيانات الفرق'!$BE$3:$BE$23)),0)} -> 1 | C15: {=_xlfn.TEXTJOIN(" + ",TRUE,_xlfn._xlws.SORT(COUNTIF('بيانات الفرق'!$BE$3:$BE$23,"المجموعة "&_xlfn.SEQUENCE(B15))))} -> 21 | D15: {=_xlfn.LET(_xlpm.gs,_xlfn.SEQUENCE(B15),_xlpm.ln,_xlfn.MAXIFS('بيانات الفرق'!$BG$3:$BG$23,'بيانات الفرق'!$BE$3:$BE$23,"المجموعة "&_xlpm.gs),_xlpm.mn,_xlfn.MINIFS('بيانات الفرق'!$BF$3:$BF$23,'بيانات الفرق'!$BE$3:$BE$23,"المجموعة "&_xlpm.gs),_xlpm.mx,_xlfn.MAXIFS('بيانات الفرق'!$BF$3:$BF$23,'بيانات الفرق'!$BE$3:$BE$23,"المجموعة "&_xlpm.gs),_xlpm.lo,FLOOR(_xlpm.mn/_xlpm.ln,1),_xlpm.hi,CEILING(_xlpm.mx/_xlpm.ln,1),_xlpm.t,IF(_xlpm.lo=_xlpm.hi,_xlpm.lo&"",_xlpm.lo&"–"&_xlpm.hi),_xlfn.TEXTJOIN(" + ",TRUE,_xlfn.SORTBY(_xlpm.t,_xlpm.ln,1)))} -> 1 | E15: {=_xlfn.LET(_xlpm.gs,_xlfn.SEQUENCE(B15),_xlpm.ln,_xlfn.MAXIFS('بيانات الفرق'!$BG$3:$BG$23,'بيانات الفرق'!$BE$3:$BE$23,"المجموعة "&_xlpm.gs),_xlpm.mn,_xlfn.MINIFS('بيانات الفرق'!$BF$3:$BF$23,'بيانات الفرق'!$BE$3:$BE$23,"المجموعة "&_xlpm.gs),_xlpm.mx,_xlfn.MAXIFS('بيانات الفرق'!$BF$3:$BF$23,'بيانات الفرق'!$BE$3:$BE$23,"المجموعة "&_xlpm.gs),_xlpm.t,IF(_xlpm.mn=_xlpm.mx,_xlpm.mn&"",_xlpm.mn&"–"&_xlpm.mx),_xlfn.TEXTJOIN(" + ",TRUE,_xlfn.SORTBY(_xlpm.t,_xlpm.ln,1)))} -> 20 | F15: ="—" -> — | G15: =MAX('21 فريقًا'!$A$4:$A$213) -> 21 | H15: =MAX('21 فريقًا'!$A$4:$A$213)-G15 -> 0 | I15: =MAX('21 فريقًا'!$A$4:$A$213) -> 21 | J15: =MOD(HOUR(المدخلات!$B$5)-1,12)+1&":"&TEXT(MINUTE(المدخلات!$B$5),"00")&IF(HOUR(المدخلات!$B$5)<12," ص"," م") -> 4:00 م | K15: {=MOD(HOUR(المدخلات!$B$5+((ROUND(SUMPRODUCT(1/COUNTIF('21 فريقًا'!$B$4:$B$213,'21 فريقًا'!$B$4:$B$213)),0)-1)*المدخلات!$B$8+المدخلات!$B$6)/1440)-1,12)+1&":"&TEXT(MINUTE(المدخلات!$B$5+((ROUND(SUMPRODUCT(1/COUNTIF('21 فريقًا'!$B$4:$B$213,'21 فريقًا'!$B$4:$B$213)),0)-1)*المدخلات!$B$8+المدخلات!$B$6)/1440),"00")&IF(HOUR(المدخلات!$B$5+((ROUND(SUMPRODUCT(1/COUNTIF('21 فريقًا'!$B$4:$B$213,'21 فريقًا'!$B$4:$B$213)),0)-1)*المدخلات!$B$8+المدخلات!$B$6)/1440)<12," ص"," م")} -> 8:50 م | L15: =MAX('21 فريقًا'!$C$4:$C$213) -> 4
A16: 22 | B16: {=ROUND(SUMPRODUCT(1/COUNTIF('بيانات الفرق'!$BJ$3:$BJ$24,'بيانات الفرق'!$BJ$3:$BJ$24)),0)} -> 1 | C16: {=_xlfn.TEXTJOIN(" + ",TRUE,_xlfn._xlws.SORT(COUNTIF('بيانات الفرق'!$BJ$3:$BJ$24,"المجموعة "&_xlfn.SEQUENCE(B16))))} -> 22 | D16: {=_xlfn.LET(_xlpm.gs,_xlfn.SEQUENCE(B16),_xlpm.ln,_xlfn.MAXIFS('بيانات الفرق'!$BL$3:$BL$24,'بيانات الفرق'!$BJ$3:$BJ$24,"المجموعة "&_xlpm.gs),_xlpm.mn,_xlfn.MINIFS('بيانات الفرق'!$BK$3:$BK$24,'بيانات الفرق'!$BJ$3:$BJ$24,"المجموعة "&_xlpm.gs),_xlpm.mx,_xlfn.MAXIFS('بيانات الفرق'!$BK$3:$BK$24,'بيانات الفرق'!$BJ$3:$BJ$24,"المجموعة "&_xlpm.gs),_xlpm.lo,FLOOR(_xlpm.mn/_xlpm.ln,1),_xlpm.hi,CEILING(_xlpm.mx/_xlpm.ln,1),_xlpm.t,IF(_xlpm.lo=_xlpm.hi,_xlpm.lo&"",_xlpm.lo&"–"&_xlpm.hi),_xlfn.TEXTJOIN(" + ",TRUE,_xlfn.SORTBY(_xlpm.t,_xlpm.ln,1)))} -> 1 | E16: {=_xlfn.LET(_xlpm.gs,_xlfn.SEQUENCE(B16),_xlpm.ln,_xlfn.MAXIFS('بيانات الفرق'!$BL$3:$BL$24,'بيانات الفرق'!$BJ$3:$BJ$24,"المجموعة "&_xlpm.gs),_xlpm.mn,_xlfn.MINIFS('بيانات الفرق'!$BK$3:$BK$24,'بيانات الفرق'!$BJ$3:$BJ$24,"المجموعة "&_xlpm.gs),_xlpm.mx,_xlfn.MAXIFS('بيانات الفرق'!$BK$3:$BK$24,'بيانات الفرق'!$BJ$3:$BJ$24,"المجموعة "&_xlpm.gs),_xlpm.t,IF(_xlpm.mn=_xlpm.mx,_xlpm.mn&"",_xlpm.mn&"–"&_xlpm.mx),_xlfn.TEXTJOIN(" + ",TRUE,_xlfn.SORTBY(_xlpm.t,_xlpm.ln,1)))} -> 21 | F16: ="—" -> — | G16: =MAX('22 فريقًا'!$A$4:$A$234) -> 21 | H16: =MAX('22 فريقًا'!$A$4:$A$234)-G16 -> 0 | I16: =MAX('22 فريقًا'!$A$4:$A$234) -> 21 | J16: =MOD(HOUR(المدخلات!$B$5)-1,12)+1&":"&TEXT(MINUTE(المدخلات!$B$5),"00")&IF(HOUR(المدخلات!$B$5)<12," ص"," م") -> 4:00 م | K16: {=MOD(HOUR(المدخلات!$B$5+((ROUND(SUMPRODUCT(1/COUNTIF('22 فريقًا'!$B$4:$B$234,'22 فريقًا'!$B$4:$B$234)),0)-1)*المدخلات!$B$8+المدخلات!$B$6)/1440)-1,12)+1&":"&TEXT(MINUTE(المدخلات!$B$5+((ROUND(SUMPRODUCT(1/COUNTIF('22 فريقًا'!$B$4:$B$234,'22 فريقًا'!$B$4:$B$234)),0)-1)*المدخلات!$B$8+المدخلات!$B$6)/1440),"00")&IF(HOUR(المدخلات!$B$5+((ROUND(SUMPRODUCT(1/COUNTIF('22 فريقًا'!$B$4:$B$234,'22 فريقًا'!$B$4:$B$234)),0)-1)*المدخلات!$B$8+المدخلات!$B$6)/1440)<12," ص"," م")} -> 8:50 م | L16: =MAX('22 فريقًا'!$C$4:$C$234) -> 4
A17: 23 | B17: {=ROUND(SUMPRODUCT(1/COUNTIF('بيانات الفرق'!$BO$3:$BO$25,'بيانات الفرق'!$BO$3:$BO$25)),0)} -> 3 | C17: {=_xlfn.TEXTJOIN(" + ",TRUE,_xlfn._xlws.SORT(COUNTIF('بيانات الفرق'!$BO$3:$BO$25,"المجموعة "&_xlfn.SEQUENCE(B17))))} -> 7 + 8 + 8 | D17: {=_xlfn.LET(_xlpm.gs,_xlfn.SEQUENCE(B17),_xlpm.ln,_xlfn.MAXIFS('بيانات الفرق'!$BQ$3:$BQ$25,'بيانات الفرق'!$BO$3:$BO$25,"المجموعة "&_xlpm.gs),_xlpm.mn,_xlfn.MINIFS('بيانات الفرق'!$BP$3:$BP$25,'بيانات الفرق'!$BO$3:$BO$25,"المجموعة "&_xlpm.gs),_xlpm.mx,_xlfn.MAXIFS('بيانات الفرق'!$BP$3:$BP$25,'بيانات الفرق'!$BO$3:$BO$25,"المجموعة "&_xlpm.gs),_xlpm.lo,FLOOR(_xlpm.mn/_xlpm.ln,1),_xlpm.hi,CEILING(_xlpm.mx/_xlpm.ln,1),_xlpm.t,IF(_xlpm.lo=_xlpm.hi,_xlpm.lo&"",_xlpm.lo&"–"&_xlpm.hi),_xlfn.TEXTJOIN(" + ",TRUE,_xlfn.SORTBY(_xlpm.t,_xlpm.ln,1)))} -> 3 + 3 + 3 | E17: {=_xlfn.LET(_xlpm.gs,_xlfn.SEQUENCE(B17),_xlpm.ln,_xlfn.MAXIFS('بيانات الفرق'!$BQ$3:$BQ$25,'بيانات الفرق'!$BO$3:$BO$25,"المجموعة "&_xlpm.gs),_xlpm.mn,_xlfn.MINIFS('بيانات الفرق'!$BP$3:$BP$25,'بيانات الفرق'!$BO$3:$BO$25,"المجموعة "&_xlpm.gs),_xlpm.mx,_xlfn.MAXIFS('بيانات الفرق'!$BP$3:$BP$25,'بيانات الفرق'!$BO$3:$BO$25,"المجموعة "&_xlpm.gs),_xlpm.t,IF(_xlpm.mn=_xlpm.mx,_xlpm.mn&"",_xlpm.mn&"–"&_xlpm.mx),_xlfn.TEXTJOIN(" + ",TRUE,_xlfn.SORTBY(_xlpm.t,_xlpm.ln,1)))} -> 18 + 21 + 21 | F17: =IF(COUNTIF('23 فريقًا'!$D$4:$D$237,"نهائي")=0,"—",IF(COUNTIF('23 فريقًا'!$D$4:$D$237,"ربع نهائي")>0,"ربع نهائي ثم نصف نهائي ثم نهائي",IF(COUNTIF('23 فريقًا'!$D$4:$D$237,"نصف نهائي")>0,"نصف نهائي ثم نهائي","نهائي مباشر"))) -> نصف نهائي ثم نهائي | G17: =_xlfn.MAXIFS('23 فريقًا'!$A$4:$A$237,'23 فريقًا'!$D$4:$D$237,"المجموعة*") -> 21 | H17: =MAX('23 فريقًا'!$A$4:$A$237)-G17 -> 2 | I17: =MAX('23 فريقًا'!$A$4:$A$237) -> 23 | J17: =MOD(HOUR(المدخلات!$B$5)-1,12)+1&":"&TEXT(MINUTE(المدخلات!$B$5),"00")&IF(HOUR(المدخلات!$B$5)<12," ص"," م") -> 4:00 م | K17: {=MOD(HOUR(المدخلات!$B$5+((ROUND(SUMPRODUCT(1/COUNTIF('23 فريقًا'!$B$4:$B$237,'23 فريقًا'!$B$4:$B$237)),0)-1)*المدخلات!$B$8+المدخلات!$B$6)/1440)-1,12)+1&":"&TEXT(MINUTE(المدخلات!$B$5+((ROUND(SUMPRODUCT(1/COUNTIF('23 فريقًا'!$B$4:$B$237,'23 فريقًا'!$B$4:$B$237)),0)-1)*المدخلات!$B$8+المدخلات!$B$6)/1440),"00")&IF(HOUR(المدخلات!$B$5+((ROUND(SUMPRODUCT(1/COUNTIF('23 فريقًا'!$B$4:$B$237,'23 فريقًا'!$B$4:$B$237)),0)-1)*المدخلات!$B$8+المدخلات!$B$6)/1440)<12," ص"," م")} -> 8:50 م | L17: =MAX('23 فريقًا'!$C$4:$C$237) -> 4
A18: 31 | B18: {=ROUND(SUMPRODUCT(1/COUNTIF('بيانات الفرق'!$BT$3:$BT$33,'بيانات الفرق'!$BT$3:$BT$33)),0)} -> 4 | C18: {=_xlfn.TEXTJOIN(" + ",TRUE,_xlfn._xlws.SORT(COUNTIF('بيانات الفرق'!$BT$3:$BT$33,"المجموعة "&_xlfn.SEQUENCE(B18))))} -> 7 + 8 + 8 + 8 | D18: {=_xlfn.LET(_xlpm.gs,_xlfn.SEQUENCE(B18),_xlpm.ln,_xlfn.MAXIFS('بيانات الفرق'!$BV$3:$BV$33,'بيانات الفرق'!$BT$3:$BT$33,"المجموعة "&_xlpm.gs),_xlpm.mn,_xlfn.MINIFS('بيانات الفرق'!$BU$3:$BU$33,'بيانات الفرق'!$BT$3:$BT$33,"المجموعة "&_xlpm.gs),_xlpm.mx,_xlfn.MAXIFS('بيانات الفرق'!$BU$3:$BU$33,'بيانات الفرق'!$BT$3:$BT$33,"المجموعة "&_xlpm.gs),_xlpm.lo,FLOOR(_xlpm.mn/_xlpm.ln,1),_xlpm.hi,CEILING(_xlpm.mx/_xlpm.ln,1),_xlpm.t,IF(_xlpm.lo=_xlpm.hi,_xlpm.lo&"",_xlpm.lo&"–"&_xlpm.hi),_xlfn.TEXTJOIN(" + ",TRUE,_xlfn.SORTBY(_xlpm.t,_xlpm.ln,1)))} -> 3 + 3 + 3 + 3 | E18: {=_xlfn.LET(_xlpm.gs,_xlfn.SEQUENCE(B18),_xlpm.ln,_xlfn.MAXIFS('بيانات الفرق'!$BV$3:$BV$33,'بيانات الفرق'!$BT$3:$BT$33,"المجموعة "&_xlpm.gs),_xlpm.mn,_xlfn.MINIFS('بيانات الفرق'!$BU$3:$BU$33,'بيانات الفرق'!$BT$3:$BT$33,"المجموعة "&_xlpm.gs),_xlpm.mx,_xlfn.MAXIFS('بيانات الفرق'!$BU$3:$BU$33,'بيانات الفرق'!$BT$3:$BT$33,"المجموعة "&_xlpm.gs),_xlpm.t,IF(_xlpm.mn=_xlpm.mx,_xlpm.mn&"",_xlpm.mn&"–"&_xlpm.mx),_xlfn.TEXTJOIN(" + ",TRUE,_xlfn.SORTBY(_xlpm.t,_xlpm.ln,1)))} -> 18 + 21 + 21 + 21 | F18: =IF(COUNTIF('31 فريقًا'!$D$4:$D$321,"نهائي")=0,"—",IF(COUNTIF('31 فريقًا'!$D$4:$D$321,"ربع نهائي")>0,"ربع نهائي ثم نصف نهائي ثم نهائي",IF(COUNTIF('31 فريقًا'!$D$4:$D$321,"نصف نهائي")>0,"نصف نهائي ثم نهائي","نهائي مباشر"))) -> نصف نهائي ثم نهائي | G18: =_xlfn.MAXIFS('31 فريقًا'!$A$4:$A$321,'31 فريقًا'!$D$4:$D$321,"المجموعة*") -> 21 | H18: =MAX('31 فريقًا'!$A$4:$A$321)-G18 -> 2 | I18: =MAX('31 فريقًا'!$A$4:$A$321) -> 23 | J18: =MOD(HOUR(المدخلات!$B$5)-1,12)+1&":"&TEXT(MINUTE(المدخلات!$B$5),"00")&IF(HOUR(المدخلات!$B$5)<12," ص"," م") -> 4:00 م | K18: {=MOD(HOUR(المدخلات!$B$5+((ROUND(SUMPRODUCT(1/COUNTIF('31 فريقًا'!$B$4:$B$321,'31 فريقًا'!$B$4:$B$321)),0)-1)*المدخلات!$B$8+المدخلات!$B$6)/1440)-1,12)+1&":"&TEXT(MINUTE(المدخلات!$B$5+((ROUND(SUMPRODUCT(1/COUNTIF('31 فريقًا'!$B$4:$B$321,'31 فريقًا'!$B$4:$B$321)),0)-1)*المدخلات!$B$8+المدخلات!$B$6)/1440),"00")&IF(HOUR(المدخلات!$B$5+((ROUND(SUMPRODUCT(1/COUNTIF('31 فريقًا'!$B$4:$B$321,'31 فريقًا'!$B$4:$B$321)),0)-1)*المدخلات!$B$8+المدخلات!$B$6)/1440)<12," ص"," م")} -> 8:50 م | L18: =MAX('31 فريقًا'!$C$4:$C$321) -> 5
A19: 35 | B19: {=ROUND(SUMPRODUCT(1/COUNTIF('بيانات الفرق'!$BY$3:$BY$37,'بيانات الفرق'!$BY$3:$BY$37)),0)} -> 5 | C19: {=_xlfn.TEXTJOIN(" + ",TRUE,_xlfn._xlws.SORT(COUNTIF('بيانات الفرق'!$BY$3:$BY$37,"المجموعة "&_xlfn.SEQUENCE(B19))))} -> 7 + 7 + 7 + 7 + 7 | D19: {=_xlfn.LET(_xlpm.gs,_xlfn.SEQUENCE(B19),_xlpm.ln,_xlfn.MAXIFS('بيانات الفرق'!$CA$3:$CA$37,'بيانات الفرق'!$BY$3:$BY$37,"المجموعة "&_xlpm.gs),_xlpm.mn,_xlfn.MINIFS('بيانات الفرق'!$BZ$3:$BZ$37,'بيانات الفرق'!$BY$3:$BY$37,"المجموعة "&_xlpm.gs),_xlpm.mx,_xlfn.MAXIFS('بيانات الفرق'!$BZ$3:$BZ$37,'بيانات الفرق'!$BY$3:$BY$37,"المجموعة "&_xlpm.gs),_xlpm.lo,FLOOR(_xlpm.mn/_xlpm.ln,1),_xlpm.hi,CEILING(_xlpm.mx/_xlpm.ln,1),_xlpm.t,IF(_xlpm.lo=_xlpm.hi,_xlpm.lo&"",_xlpm.lo&"–"&_xlpm.hi),_xlfn.TEXTJOIN(" + ",TRUE,_xlfn.SORTBY(_xlpm.t,_xlpm.ln,1)))} -> 3 + 3 + 3 + 3 + 3 | E19: {=_xlfn.LET(_xlpm.gs,_xlfn.SEQUENCE(B19),_xlpm.ln,_xlfn.MAXIFS('بيانات الفرق'!$CA$3:$CA$37,'بيانات الفرق'!$BY$3:$BY$37,"المجموعة "&_xlpm.gs),_xlpm.mn,_xlfn.MINIFS('بيانات الفرق'!$BZ$3:$BZ$37,'بيانات الفرق'!$BY$3:$BY$37,"المجموعة "&_xlpm.gs),_xlpm.mx,_xlfn.MAXIFS('بيانات الفرق'!$BZ$3:$BZ$37,'بيانات الفرق'!$BY$3:$BY$37,"المجموعة "&_xlpm.gs),_xlpm.t,IF(_xlpm.mn=_xlpm.mx,_xlpm.mn&"",_xlpm.mn&"–"&_xlpm.mx),_xlfn.TEXTJOIN(" + ",TRUE,_xlfn.SORTBY(_xlpm.t,_xlpm.ln,1)))} -> 18 + 18 + 18 + 18 + 18 | F19: =IF(COUNTIF('35 فريقًا'!$D$4:$D$325,"نهائي")=0,"—",IF(COUNTIF('35 فريقًا'!$D$4:$D$325,"ربع نهائي")>0,"ربع نهائي ثم نصف نهائي ثم نهائي",IF(COUNTIF('35 فريقًا'!$D$4:$D$325,"نصف نهائي")>0,"نصف نهائي ثم نهائي","نهائي مباشر"))) -> ربع نهائي ثم نصف نهائي ثم نهائي | G19: =_xlfn.MAXIFS('35 فريقًا'!$A$4:$A$325,'35 فريقًا'!$D$4:$D$325,"المجموعة*") -> 21 | H19: =MAX('35 فريقًا'!$A$4:$A$325)-G19 -> 2 | I19: =MAX('35 فريقًا'!$A$4:$A$325) -> 23 | J19: =MOD(HOUR(المدخلات!$B$5)-1,12)+1&":"&TEXT(MINUTE(المدخلات!$B$5),"00")&IF(HOUR(المدخلات!$B$5)<12," ص"," م") -> 4:00 م | K19: {=MOD(HOUR(المدخلات!$B$5+((ROUND(SUMPRODUCT(1/COUNTIF('35 فريقًا'!$B$4:$B$325,'35 فريقًا'!$B$4:$B$325)),0)-1)*المدخلات!$B$8+المدخلات!$B$6)/1440)-1,12)+1&":"&TEXT(MINUTE(المدخلات!$B$5+((ROUND(SUMPRODUCT(1/COUNTIF('35 فريقًا'!$B$4:$B$325,'35 فريقًا'!$B$4:$B$325)),0)-1)*المدخلات!$B$8+المدخلات!$B$6)/1440),"00")&IF(HOUR(المدخلات!$B$5+((ROUND(SUMPRODUCT(1/COUNTIF('35 فريقًا'!$B$4:$B$325,'35 فريقًا'!$B$4:$B$325)),0)-1)*المدخلات!$B$8+المدخلات!$B$6)/1440)<12," ص"," م")} -> 8:50 م | L19: =MAX('35 فريقًا'!$C$4:$C$325) -> 5
A20: 48 | B20: {=ROUND(SUMPRODUCT(1/COUNTIF('بيانات الفرق'!$CD$3:$CD$50,'بيانات الفرق'!$CD$3:$CD$50)),0)} -> 8 | C20: {=_xlfn.TEXTJOIN(" + ",TRUE,_xlfn._xlws.SORT(COUNTIF('بيانات الفرق'!$CD$3:$CD$50,"المجموعة "&_xlfn.SEQUENCE(B20))))} -> 6 + 6 + 6 + 6 + 6 + 6 + 6 + 6 | D20: {=_xlfn.LET(_xlpm.gs,_xlfn.SEQUENCE(B20),_xlpm.ln,_xlfn.MAXIFS('بيانات الفرق'!$CF$3:$CF$50,'بيانات الفرق'!$CD$3:$CD$50,"المجموعة "&_xlpm.gs),_xlpm.mn,_xlfn.MINIFS('بيانات الفرق'!$CE$3:$CE$50,'بيانات الفرق'!$CD$3:$CD$50,"المجموعة "&_xlpm.gs),_xlpm.mx,_xlfn.MAXIFS('بيانات الفرق'!$CE$3:$CE$50,'بيانات الفرق'!$CD$3:$CD$50,"المجموعة "&_xlpm.gs),_xlpm.lo,FLOOR(_xlpm.mn/_xlpm.ln,1),_xlpm.hi,CEILING(_xlpm.mx/_xlpm.ln,1),_xlpm.t,IF(_xlpm.lo=_xlpm.hi,_xlpm.lo&"",_xlpm.lo&"–"&_xlpm.hi),_xlfn.TEXTJOIN(" + ",TRUE,_xlfn.SORTBY(_xlpm.t,_xlpm.ln,1)))} -> 4 + 4 + 4 + 4 + 4 + 4 + 4 + 4 | E20: {=_xlfn.LET(_xlpm.gs,_xlfn.SEQUENCE(B20),_xlpm.ln,_xlfn.MAXIFS('بيانات الفرق'!$CF$3:$CF$50,'بيانات الفرق'!$CD$3:$CD$50,"المجموعة "&_xlpm.gs),_xlpm.mn,_xlfn.MINIFS('بيانات الفرق'!$CE$3:$CE$50,'بيانات الفرق'!$CD$3:$CD$50,"المجموعة "&_xlpm.gs),_xlpm.mx,_xlfn.MAXIFS('بيانات الفرق'!$CE$3:$CE$50,'بيانات الفرق'!$CD$3:$CD$50,"المجموعة "&_xlpm.gs),_xlpm.t,IF(_xlpm.mn=_xlpm.mx,_xlpm.mn&"",_xlpm.mn&"–"&_xlpm.mx),_xlfn.TEXTJOIN(" + ",TRUE,_xlfn.SORTBY(_xlpm.t,_xlpm.ln,1)))} -> 20 + 20 + 20 + 20 + 20 + 20 + 20 + 20 | F20: =IF(COUNTIF('48 فريقًا'!$D$4:$D$490,"نهائي")=0,"—",IF(COUNTIF('48 فريقًا'!$D$4:$D$490,"ربع نهائي")>0,"ربع نهائي ثم نصف نهائي ثم نهائي",IF(COUNTIF('48 فريقًا'!$D$4:$D$490,"نصف نهائي")>0,"نصف نهائي ثم نهائي","نهائي مباشر"))) -> ربع نهائي ثم نصف نهائي ثم نهائي | G20: =_xlfn.MAXIFS('48 فريقًا'!$A$4:$A$490,'48 فريقًا'!$D$4:$D$490,"المجموعة*") -> 20 | H20: =MAX('48 فريقًا'!$A$4:$A$490)-G20 -> 3 | I20: =MAX('48 فريقًا'!$A$4:$A$490) -> 23 | J20: =MOD(HOUR(المدخلات!$B$5)-1,12)+1&":"&TEXT(MINUTE(المدخلات!$B$5),"00")&IF(HOUR(المدخلات!$B$5)<12," ص"," م") -> 4:00 م | K20: {=MOD(HOUR(المدخلات!$B$5+((ROUND(SUMPRODUCT(1/COUNTIF('48 فريقًا'!$B$4:$B$490,'48 فريقًا'!$B$4:$B$490)),0)-1)*المدخلات!$B$8+المدخلات!$B$6)/1440)-1,12)+1&":"&TEXT(MINUTE(المدخلات!$B$5+((ROUND(SUMPRODUCT(1/COUNTIF('48 فريقًا'!$B$4:$B$490,'48 فريقًا'!$B$4:$B$490)),0)-1)*المدخلات!$B$8+المدخلات!$B$6)/1440),"00")&IF(HOUR(المدخلات!$B$5+((ROUND(SUMPRODUCT(1/COUNTIF('48 فريقًا'!$B$4:$B$490,'48 فريقًا'!$B$4:$B$490)),0)-1)*المدخلات!$B$8+المدخلات!$B$6)/1440)<12," ص"," م")} -> 8:50 م | L20: =MAX('48 فريقًا'!$C$4:$C$490) -> 8

Sheet 6 فرق
A1: بطولة 6 فرق – تحت 14
A3: اليوم | B3: الوقت | C3: الملعب | D3: المباراة
A4: 1 | B4: =المدخلات!$F$4 -> 4:00–5:30 م | C4: 1 | D4: 1 ضد 6
A5: 1 | B5: =المدخلات!$F$5 -> 5:40–7:10 م | C5: 1 | D5: 2 ضد 5
A6: 1 | B6: =المدخلات!$F$6 -> 7:20–8:50 م | C6: 1 | D6: 3 ضد 4
A7: 2 | B7: =المدخلات!$F$4 -> 4:00–5:30 م | C7: 1 | D7: 2 ضد 3
A8: 2 | B8: =المدخلات!$F$5 -> 5:40–7:10 م | C8: 1 | D8: 4 ضد 6
A9: 2 | B9: =المدخلات!$F$6 -> 7:20–8:50 م | C9: 1 | D9: 1 ضد 5
A10: 3 | B10: =المدخلات!$F$4 -> 4:00–5:30 م | C10: 1 | D10: 1 ضد 4
A11: 3 | B11: =المدخلات!$F$5 -> 5:40–7:10 م | C11: 1 | D11: 3 ضد 5
A12: 3 | B12: =المدخلات!$F$6 -> 7:20–8:50 م | C12: 1 | D12: 2 ضد 6
A13: 4 | B13: =المدخلات!$F$4 -> 4:00–5:30 م | C13: 1 | D13: 5 ضد 6
A14: 4 | B14: =المدخلات!$F$5 -> 5:40–7:10 م | C14: 1 | D14: 1 ضد 3
A15: 4 | B15: =المدخلات!$F$6 -> 7:20–8:50 م | C15: 1 | D15: 2 ضد 4
A16: 5 | B16: =المدخلات!$F$4 -> 4:00–5:30 م | C16: 1 | D16: 4 ضد 5
A17: 5 | B17: =المدخلات!$F$5 -> 5:40–7:10 م | C17: 1 | D17: 1 ضد 2
A18: 5 | B18: =المدخلات!$F$6 -> 7:20–8:50 م | C18: 1 | D18: 3 ضد 6
A19: 6 | B19: =المدخلات!$F$4 -> 4:00–5:30 م | C19: 1 | D19: 1 ضد 2
A20: 6 | B20: =المدخلات!$F$5 -> 5:40–7:10 م | C20: 1 | D20: 3 ضد 6
A21: 6 | B21: =المدخلات!$F$6 -> 7:20–8:50 م | C21: 1 | D21: 4 ضد 5
A22: 7 | B22: =المدخلات!$F$4 -> 4:00–5:30 م | C22: 1 | D22: 3 ضد 4
A23: 7 | B23: =المدخلات!$F$5 -> 5:40–7:10 م | C23: 1 | D23: 2 ضد 5
A24: 7 | B24: =المدخلات!$F$6 -> 7:20–8:50 م | C24: 1 | D24: 1 ضد 6
A25: 8 | B25: =المدخلات!$F$4 -> 4:00–5:30 م | C25: 1 | D25: 2 ضد 3
A26: 8 | B26: =المدخلات!$F$5 -> 5:40–7:10 م | C26: 1 | D26: 4 ضد 6
A27: 8 | B27: =المدخلات!$F$6 -> 7:20–8:50 م | C27: 1 | D27: 1 ضد 5
A28: 9 | B28: =المدخلات!$F$4 -> 4:00–5:30 م | C28: 1 | D28: 3 ضد 5
A29: 9 | B29: =المدخلات!$F$5 -> 5:40–7:10 م | C29: 1 | D29: 1 ضد 4
A30: 9 | B30: =المدخلات!$F$6 -> 7:20–8:50 م | C30: 1 | D30: 2 ضد 6
A31: 10 | B31: =المدخلات!$F$4 -> 4:00–5:30 م | C31: 1 | D31: 5 ضد 6
A32: 10 | B32: =المدخلات!$F$5 -> 5:40–7:10 م | C32: 1 | D32: 2 ضد 4
A33: 10 | B33: =المدخلات!$F$6 -> 7:20–8:50 م | C33: 1 | D33: 1 ضد 3
A34: 11 | B34: =المدخلات!$F$4 -> 4:00–5:30 م | C34: 1 | D34: 2 ضد 4
A35: 11 | B35: =المدخلات!$F$5 -> 5:40–7:10 م | C35: 1 | D35: 1 ضد 3
A36: 11 | B36: =المدخلات!$F$6 -> 7:20–8:50 م | C36: 1 | D36: 5 ضد 6
A37: 12 | B37: =المدخلات!$F$4 -> 4:00–5:30 م | C37: 1 | D37: 1 ضد 2
A38: 12 | B38: =المدخلات!$F$5 -> 5:40–7:10 م | C38: 1 | D38: 3 ضد 6
A39: 12 | B39: =المدخلات!$F$6 -> 7:20–8:50 م | C39: 1 | D39: 4 ضد 5
A40: 13 | B40: =المدخلات!$F$4 -> 4:00–5:30 م | C40: 1 | D40: 1 ضد 6
A41: 13 | B41: =المدخلات!$F$5 -> 5:40–7:10 م | C41: 1 | D41: 2 ضد 5
...

Sheet 7 فرق
A1: بطولة 7 فرق – تحت 14
A3: اليوم | B3: الوقت | C3: الملعب | D3: المباراة
A4: 1 | B4: =المدخلات!$F$4 -> 4:00–5:30 م | C4: 1 | D4: 2 ضد 7
A5: 1 | B5: =المدخلات!$F$5 -> 5:40–7:10 م | C5: 1 | D5: 3 ضد 6
A6: 1 | B6: =المدخلات!$F$6 -> 7:20–8:50 م | C6: 1 | D6: 4 ضد 5
A7: 2 | B7: =المدخلات!$F$4 -> 4:00–5:30 م | C7: 1 | D7: 3 ضد 4
A8: 2 | B8: =المدخلات!$F$5 -> 5:40–7:10 م | C8: 1 | D8: 2 ضد 5
A9: 2 | B9: =المدخلات!$F$6 -> 7:20–8:50 م | C9: 1 | D9: 1 ضد 7
A10: 3 | B10: =المدخلات!$F$4 -> 4:00–5:30 م | C10: 1 | D10: 1 ضد 6
A11: 3 | B11: =المدخلات!$F$5 -> 5:40–7:10 م | C11: 1 | D11: 5 ضد 7
A12: 3 | B12: =المدخلات!$F$6 -> 7:20–8:50 م | C12: 1 | D12: 2 ضد 3
A13: 4 | B13: =المدخلات!$F$4 -> 4:00–5:30 م | C13: 1 | D13: 1 ضد 5
A14: 4 | B14: =المدخلات!$F$5 -> 5:40–7:10 م | C14: 1 | D14: 4 ضد 6
A15: 4 | B15: =المدخلات!$F$6 -> 7:20–8:50 م | C15: 1 | D15: 3 ضد 7
A16: 5 | B16: =المدخلات!$F$4 -> 4:00–5:30 م | C16: 1 | D16: 3 ضد 5
A17: 5 | B17: =المدخلات!$F$5 -> 5:40–7:10 م | C17: 1 | D17: 1 ضد 4
A18: 5 | B18: =المدخلات!$F$6 -> 7:20–8:50 م | C18: 1 | D18: 2 ضد 6
A19: 6 | B19: =المدخلات!$F$4 -> 4:00–5:30 م | C19: 1 | D19: 2 ضد 4
A20: 6 | B20: =المدخلات!$F$5 -> 5:40–7:10 م | C20: 1 | D20: 1 ضد 3
A21: 6 | B21: =المدخلات!$F$6 -> 7:20–8:50 م | C21: 1 | D21: 6 ضد 7
A22: 7 | B22: =المدخلات!$F$4 -> 4:00–5:30 م | C22: 1 | D22: 4 ضد 7
A23: 7 | B23: =المدخلات!$F$5 -> 5:40–7:10 م | C23: 1 | D23: 1 ضد 2
A24: 7 | B24: =المدخلات!$F$6 -> 7:20–8:50 م | C24: 1 | D24: 5 ضد 6
A25: 8 | B25: =المدخلات!$F$4 -> 4:00–5:30 م | C25: 1 | D25: 5 ضد 6
A26: 8 | B26: =المدخلات!$F$5 -> 5:40–7:10 م | C26: 1 | D26: 4 ضد 7
A27: 8 | B27: =المدخلات!$F$6 -> 7:20–8:50 م | C27: 1 | D27: 1 ضد 2
A28: 9 | B28: =المدخلات!$F$4 -> 4:00–5:30 م | C28: 1 | D28: 3 ضد 6
A29: 9 | B29: =المدخلات!$F$5 -> 5:40–7:10 م | C29: 1 | D29: 2 ضد 7
A30: 9 | B30: =المدخلات!$F$6 -> 7:20–8:50 م | C30: 1 | D30: 4 ضد 5
A31: 10 | B31: =المدخلات!$F$4 -> 4:00–5:30 م | C31: 1 | D31: 1 ضد 7
A32: 10 | B32: =المدخلات!$F$5 -> 5:40–7:10 م | C32: 1 | D32: 2 ضد 5
A33: 10 | B33: =المدخلات!$F$6 -> 7:20–8:50 م | C33: 1 | D33: 3 ضد 4
A34: 11 | B34: =المدخلات!$F$4 -> 4:00–5:30 م | C34: 1 | D34: 2 ضد 3
A35: 11 | B35: =المدخلات!$F$5 -> 5:40–7:10 م | C35: 1 | D35: 1 ضد 6
A36: 11 | B36: =المدخلات!$F$6 -> 7:20–8:50 م | C36: 1 | D36: 5 ضد 7
A37: 12 | B37: =المدخلات!$F$4 -> 4:00–5:30 م | C37: 1 | D37: 1 ضد 5
A38: 12 | B38: =المدخلات!$F$5 -> 5:40–7:10 م | C38: 1 | D38: 3 ضد 7
A39: 12 | B39: =المدخلات!$F$6 -> 7:20–8:50 م | C39: 1 | D39: 4 ضد 6
A40: 13 | B40: =المدخلات!$F$4 -> 4:00–5:30 م | C40: 1 | D40: 2 ضد 6
A41: 13 | B41: =المدخلات!$F$5 -> 5:40–7:10 م | C41: 1 | D41: 3 ضد 5
...

Sheet 8 فرق
A1: بطولة 8 فرق – تحت 14
A3: اليوم | B3: الوقت | C3: الملعب | D3: المباراة
A4: 1 | B4: =المدخلات!$F$4 -> 4:00–5:30 م | C4: 1 | D4: 1 ضد 8
A5: 1 | B5: =المدخلات!$F$4 -> 4:00–5:30 م | C5: 2 | D5: 2 ضد 7
A6: 1 | B6: =المدخلات!$F$5 -> 5:40–7:10 م | C6: 1 | D6: 3 ضد 6
A7: 1 | B7: =المدخلات!$F$5 -> 5:40–7:10 م | C7: 2 | D7: 4 ضد 5
A8: 2 | B8: =المدخلات!$F$4 -> 4:00–5:30 م | C8: 1 | D8: 2 ضد 5
A9: 2 | B9: =المدخلات!$F$4 -> 4:00–5:30 م | C9: 2 | D9: 3 ضد 4
A10: 2 | B10: =المدخلات!$F$5 -> 5:40–7:10 م | C10: 1 | D10: 1 ضد 7
A11: 2 | B11: =المدخلات!$F$5 -> 5:40–7:10 م | C11: 2 | D11: 6 ضد 8
A12: 3 | B12: =المدخلات!$F$4 -> 4:00–5:30 م | C12: 1 | D12: 4 ضد 8
A13: 3 | B13: =المدخلات!$F$4 -> 4:00–5:30 م | C13: 2 | D13: 1 ضد 6
A14: 3 | B14: =المدخلات!$F$5 -> 5:40–7:10 م | C14: 1 | D14: 5 ضد 7
A15: 3 | B15: =المدخلات!$F$5 -> 5:40–7:10 م | C15: 2 | D15: 2 ضد 3
A16: 4 | B16: =المدخلات!$F$4 -> 4:00–5:30 م | C16: 1 | D16: 3 ضد 7
A17: 4 | B17: =المدخلات!$F$4 -> 4:00–5:30 م | C17: 2 | D17: 1 ضد 5
A18: 4 | B18: =المدخلات!$F$5 -> 5:40–7:10 م | C18: 1 | D18: 4 ضد 6
A19: 4 | B19: =المدخلات!$F$5 -> 5:40–7:10 م | C19: 2 | D19: 2 ضد 8
A20: 5 | B20: =المدخلات!$F$4 -> 4:00–5:30 م | C20: 1 | D20: 2 ضد 6
A21: 5 | B21: =المدخلات!$F$4 -> 4:00–5:30 م | C21: 2 | D21: 3 ضد 5
A22: 5 | B22: =المدخلات!$F$5 -> 5:40–7:10 م | C22: 1 | D22: 1 ضد 4
A23: 5 | B23: =المدخلات!$F$5 -> 5:40–7:10 م | C23: 2 | D23: 7 ضد 8
A24: 6 | B24: =المدخلات!$F$4 -> 4:00–5:30 م | C24: 1 | D24: 5 ضد 8
A25: 6 | B25: =المدخلات!$F$4 -> 4:00–5:30 م | C25: 2 | D25: 6 ضد 7
A26: 6 | B26: =المدخلات!$F$5 -> 5:40–7:10 م | C26: 1 | D26: 1 ضد 3
A27: 6 | B27: =المدخلات!$F$5 -> 5:40–7:10 م | C27: 2 | D27: 2 ضد 4
A28: 7 | B28: =المدخلات!$F$4 -> 4:00–5:30 م | C28: 1 | D28: 3 ضد 8
A29: 7 | B29: =المدخلات!$F$4 -> 4:00–5:30 م | C29: 2 | D29: 4 ضد 7
A30: 7 | B30: =المدخلات!$F$5 -> 5:40–7:10 م | C30: 1 | D30: 1 ضد 2
A31: 7 | B31: =المدخلات!$F$5 -> 5:40–7:10 م | C31: 2 | D31: 5 ضد 6
A32: 8 | B32: =المدخلات!$F$4 -> 4:00–5:30 م | C32: 1 | D32: 4 ضد 7
A33: 8 | B33: =المدخلات!$F$4 -> 4:00–5:30 م | C33: 2 | D33: 1 ضد 2
A34: 8 | B34: =المدخلات!$F$5 -> 5:40–7:10 م | C34: 1 | D34: 5 ضد 6
A35: 8 | B35: =المدخلات!$F$5 -> 5:40–7:10 م | C35: 2 | D35: 3 ضد 8
A36: 9 | B36: =المدخلات!$F$4 -> 4:00–5:30 م | C36: 1 | D36: 3 ضد 6
A37: 9 | B37: =المدخلات!$F$4 -> 4:00–5:30 م | C37: 2 | D37: 1 ضد 8
A38: 9 | B38: =المدخلات!$F$5 -> 5:40–7:10 م | C38: 1 | D38: 2 ضد 7
A39: 9 | B39: =المدخلات!$F$5 -> 5:40–7:10 م | C39: 2 | D39: 4 ضد 5
A40: 10 | B40: =المدخلات!$F$4 -> 4:00–5:30 م | C40: 1 | D40: 2 ضد 5
A41: 10 | B41: =المدخلات!$F$4 -> 4:00–5:30 م | C41: 2 | D41: 3 ضد 4
...

Sheet 10 فرق
A1: بطولة 10 فرق – تحت 14
A3: اليوم | B3: الوقت | C3: الملعب | D3: المباراة
A4: 1 | B4: =المدخلات!$F$4 -> 4:00–5:30 م | C4: 1 | D4: 1 ضد 10
A5: 1 | B5: =المدخلات!$F$4 -> 4:00–5:30 م | C5: 2 | D5: 2 ضد 9
A6: 1 | B6: =المدخلات!$F$5 -> 5:40–7:10 م | C6: 1 | D6: 3 ضد 8
A7: 1 | B7: =المدخلات!$F$5 -> 5:40–7:10 م | C7: 2 | D7: 4 ضد 7
A8: 1 | B8: =المدخلات!$F$6 -> 7:20–8:50 م | C8: 1 | D8: 5 ضد 6
A9: 2 | B9: =المدخلات!$F$4 -> 4:00–5:30 م | C9: 1 | D9: 4 ضد 5
A10: 2 | B10: =المدخلات!$F$4 -> 4:00–5:30 م | C10: 2 | D10: 3 ضد 6
A11: 2 | B11: =المدخلات!$F$5 -> 5:40–7:10 م | C11: 1 | D11: 1 ضد 9
A12: 2 | B12: =المدخلات!$F$5 -> 5:40–7:10 م | C12: 2 | D12: 8 ضد 10
A13: 2 | B13: =المدخلات!$F$6 -> 7:20–8:50 م | C13: 1 | D13: 2 ضد 7
A14: 3 | B14: =المدخلات!$F$4 -> 4:00–5:30 م | C14: 1 | D14: 7 ضد 9
A15: 3 | B15: =المدخلات!$F$4 -> 4:00–5:30 م | C15: 2 | D15: 1 ضد 8
A16: 3 | B16: =المدخلات!$F$5 -> 5:40–7:10 م | C16: 1 | D16: 6 ضد 10
A17: 3 | B17: =المدخلات!$F$5 -> 5:40–7:10 م | C17: 2 | D17: 2 ضد 5
A18: 3 | B18: =المدخلات!$F$6 -> 7:20–8:50 م | C18: 1 | D18: 3 ضد 4
A19: 4 | B19: =المدخلات!$F$4 -> 4:00–5:30 م | C19: 1 | D19: 6 ضد 8
A20: 4 | B20: =المدخلات!$F$4 -> 4:00–5:30 م | C20: 2 | D20: 4 ضد 10
A21: 4 | B21: =المدخلات!$F$5 -> 5:40–7:10 م | C21: 1 | D21: 2 ضد 3
A22: 4 | B22: =المدخلات!$F$5 -> 5:40–7:10 م | C22: 2 | D22: 1 ضد 7
A23: 4 | B23: =المدخلات!$F$6 -> 7:20–8:50 م | C23: 1 | D23: 5 ضد 9
A24: 5 | B24: =المدخلات!$F$4 -> 4:00–5:30 م | C24: 1 | D24: 2 ضد 10
A25: 5 | B25: =المدخلات!$F$4 -> 4:00–5:30 م | C25: 2 | D25: 5 ضد 7
A26: 5 | B26: =المدخلات!$F$5 -> 5:40–7:10 م | C26: 1 | D26: 1 ضد 6
A27: 5 | B27: =المدخلات!$F$5 -> 5:40–7:10 م | C27: 2 | D27: 3 ضد 9
A28: 5 | B28: =المدخلات!$F$6 -> 7:20–8:50 م | C28: 1 | D28: 4 ضد 8
A29: 6 | B29: =المدخلات!$F$4 -> 4:00–5:30 م | C29: 1 | D29: 3 ضد 7
A30: 6 | B30: =المدخلات!$F$4 -> 4:00–5:30 م | C30: 2 | D30: 2 ضد 8
A31: 6 | B31: =المدخلات!$F$5 -> 5:40–7:10 م | C31: 1 | D31: 1 ضد 5
A32: 6 | B32: =المدخلات!$F$5 -> 5:40–7:10 م | C32: 2 | D32: 4 ضد 6
A33: 6 | B33: =المدخلات!$F$6 -> 7:20–8:50 م | C33: 1 | D33: 9 ضد 10
A34: 7 | B34: =المدخلات!$F$4 -> 4:00–5:30 م | C34: 1 | D34: 1 ضد 4
A35: 7 | B35: =المدخلات!$F$4 -> 4:00–5:30 م | C35: 2 | D35: 3 ضد 5
A36: 7 | B36: =المدخلات!$F$5 -> 5:40–7:10 م | C36: 1 | D36: 7 ضد 10
A37: 7 | B37: =المدخلات!$F$5 -> 5:40–7:10 م | C37: 2 | D37: 8 ضد 9
A38: 7 | B38: =المدخلات!$F$6 -> 7:20–8:50 م | C38: 1 | D38: 2 ضد 6
A39: 8 | B39: =المدخلات!$F$4 -> 4:00–5:30 م | C39: 1 | D39: 7 ضد 8
A40: 8 | B40: =المدخلات!$F$4 -> 4:00–5:30 م | C40: 2 | D40: 6 ضد 9
A41: 8 | B41: =المدخلات!$F$5 -> 5:40–7:10 م | C41: 1 | D41: 2 ضد 4
...

Sheet 13 فريقًا
A1: بطولة 13 فريقًا – تحت 14
A3: اليوم | B3: الوقت | C3: الملعب | D3: المجموعة / الدور | E3: المباراة | G3: المتأهلان: متصدر كل مجموعة، ويلتقيان في النهائي مباشرة.
A4: 1 | B4: =المدخلات!$F$4 -> 4:00–5:30 م | C4: 1 | D4: المجموعة 1 | E4: 2 ضد 7
A5: 1 | B5: =المدخلات!$F$4 -> 4:00–5:30 م | C5: 2 | D5: المجموعة 1 | E5: 3 ضد 6
A6: 1 | B6: =المدخلات!$F$5 -> 5:40–7:10 م | C6: 1 | D6: المجموعة 1 | E6: 4 ضد 5
A7: 1 | B7: =المدخلات!$F$5 -> 5:40–7:10 م | C7: 2 | D7: المجموعة 2 | E7: 9 ضد 12
A8: 1 | B8: =المدخلات!$F$6 -> 7:20–8:50 م | C8: 1 | D8: المجموعة 2 | E8: 8 ضد 13
A9: 1 | B9: =المدخلات!$F$6 -> 7:20–8:50 م | C9: 2 | D9: المجموعة 2 | E9: 10 ضد 11
A10: 2 | B10: =المدخلات!$F$4 -> 4:00–5:30 م | C10: 1 | D10: المجموعة 2 | E10: 9 ضد 10
A11: 2 | B11: =المدخلات!$F$4 -> 4:00–5:30 م | C11: 2 | D11: المجموعة 2 | E11: 8 ضد 12
A12: 2 | B12: =المدخلات!$F$5 -> 5:40–7:10 م | C12: 1 | D12: المجموعة 2 | E12: 11 ضد 13
A13: 2 | B13: =المدخلات!$F$5 -> 5:40–7:10 م | C13: 2 | D13: المجموعة 1 | E13: 1 ضد 7
A14: 2 | B14: =المدخلات!$F$6 -> 7:20–8:50 م | C14: 1 | D14: المجموعة 1 | E14: 3 ضد 4
A15: 2 | B15: =المدخلات!$F$6 -> 7:20–8:50 م | C15: 2 | D15: المجموعة 1 | E15: 2 ضد 5
A16: 3 | B16: =المدخلات!$F$4 -> 4:00–5:30 م | C16: 1 | D16: المجموعة 1 | E16: 5 ضد 7
A17: 3 | B17: =المدخلات!$F$4 -> 4:00–5:30 م | C17: 2 | D17: المجموعة 2 | E17: 8 ضد 11
A18: 3 | B18: =المدخلات!$F$5 -> 5:40–7:10 م | C18: 1 | D18: المجموعة 2 | E18: 10 ضد 12
A19: 3 | B19: =المدخلات!$F$5 -> 5:40–7:10 م | C19: 2 | D19: المجموعة 1 | E19: 2 ضد 3
A20: 3 | B20: =المدخلات!$F$6 -> 7:20–8:50 م | C20: 1 | D20: المجموعة 1 | E20: 1 ضد 6
A21: 3 | B21: =المدخلات!$F$6 -> 7:20–8:50 م | C21: 2 | D21: المجموعة 2 | E21: 9 ضد 13
A22: 4 | B22: =المدخلات!$F$4 -> 4:00–5:30 م | C22: 1 | D22: المجموعة 2 | E22: 12 ضد 13
A23: 4 | B23: =المدخلات!$F$4 -> 4:00–5:30 م | C23: 2 | D23: المجموعة 1 | E23: 1 ضد 5
A24: 4 | B24: =المدخلات!$F$5 -> 5:40–7:10 م | C24: 1 | D24: المجموعة 2 | E24: 8 ضد 10
A25: 4 | B25: =المدخلات!$F$5 -> 5:40–7:10 م | C25: 2 | D25: المجموعة 1 | E25: 4 ضد 6
A26: 4 | B26: =المدخلات!$F$6 -> 7:20–8:50 م | C26: 1 | D26: المجموعة 2 | E26: 9 ضد 11
A27: 4 | B27: =المدخلات!$F$6 -> 7:20–8:50 م | C27: 2 | D27: المجموعة 1 | E27: 3 ضد 7
A28: 5 | B28: =المدخلات!$F$4 -> 4:00–5:30 م | C28: 1 | D28: المجموعة 1 | E28: 1 ضد 4
A29: 5 | B29: =المدخلات!$F$4 -> 4:00–5:30 م | C29: 2 | D29: المجموعة 2 | E29: 10 ضد 13
A30: 5 | B30: =المدخلات!$F$5 -> 5:40–7:10 م | C30: 1 | D30: المجموعة 1 | E30: 3 ضد 5
A31: 5 | B31: =المدخلات!$F$5 -> 5:40–7:10 م | C31: 2 | D31: المجموعة 2 | E31: 8 ضد 9
A32: 5 | B32: =المدخلات!$F$6 -> 7:20–8:50 م | C32: 1 | D32: المجموعة 1 | E32: 2 ضد 6
A33: 5 | B33: =المدخلات!$F$6 -> 7:20–8:50 م | C33: 2 | D33: المجموعة 2 | E33: 11 ضد 12
A34: 6 | B34: =المدخلات!$F$4 -> 4:00–5:30 م | C34: 1 | D34: المجموعة 1 | E34: 1 ضد 3
A35: 6 | B35: =المدخلات!$F$4 -> 4:00–5:30 م | C35: 2 | D35: المجموعة 1 | E35: 2 ضد 4
A36: 6 | B36: =المدخلات!$F$5 -> 5:40–7:10 م | C36: 1 | D36: المجموعة 1 | E36: 6 ضد 7
A37: 6 | B37: =المدخلات!$F$5 -> 5:40–7:10 م | C37: 2 | D37: المجموعة 2 | E37: 11 ضد 12
A38: 6 | B38: =المدخلات!$F$6 -> 7:20–8:50 م | C38: 1 | D38: المجموعة 2 | E38: 8 ضد 9
A39: 6 | B39: =المدخلات!$F$6 -> 7:20–8:50 م | C39: 2 | D39: المجموعة 2 | E39: 10 ضد 13
A40: 7 | B40: =المدخلات!$F$4 -> 4:00–5:30 م | C40: 1 | D40: المجموعة 1 | E40: 4 ضد 7
A41: 7 | B41: =المدخلات!$F$4 -> 4:00–5:30 م | C41: 2 | D41: المجموعة 1 | E41: 5 ضد 6
...

Sheet 14 فريقًا
A1: بطولة 14 فريقًا – تحت 14
A3: اليوم | B3: الوقت | C3: الملعب | D3: المجموعة / الدور | E3: المباراة | G3: المتأهلان: متصدر كل مجموعة، ويلتقيان في النهائي مباشرة.
A4: 1 | B4: =المدخلات!$F$4 -> 4:00–5:30 م | C4: 1 | D4: المجموعة 1 | E4: 2 ضد 7
A5: 1 | B5: =المدخلات!$F$4 -> 4:00–5:30 م | C5: 2 | D5: المجموعة 1 | E5: 3 ضد 6
A6: 1 | B6: =المدخلات!$F$5 -> 5:40–7:10 م | C6: 1 | D6: المجموعة 1 | E6: 4 ضد 5
A7: 1 | B7: =المدخلات!$F$5 -> 5:40–7:10 م | C7: 2 | D7: المجموعة 2 | E7: 10 ضد 13
A8: 1 | B8: =المدخلات!$F$6 -> 7:20–8:50 م | C8: 1 | D8: المجموعة 2 | E8: 9 ضد 14
A9: 1 | B9: =المدخلات!$F$6 -> 7:20–8:50 م | C9: 2 | D9: المجموعة 2 | E9: 11 ضد 12
A10: 2 | B10: =المدخلات!$F$4 -> 4:00–5:30 م | C10: 1 | D10: المجموعة 2 | E10: 10 ضد 11
A11: 2 | B11: =المدخلات!$F$4 -> 4:00–5:30 م | C11: 2 | D11: المجموعة 2 | E11: 8 ضد 14
A12: 2 | B12: =المدخلات!$F$5 -> 5:40–7:10 م | C12: 1 | D12: المجموعة 2 | E12: 9 ضد 12
A13: 2 | B13: =المدخلات!$F$5 -> 5:40–7:10 م | C13: 2 | D13: المجموعة 1 | E13: 1 ضد 7
A14: 2 | B14: =المدخلات!$F$6 -> 7:20–8:50 م | C14: 1 | D14: المجموعة 1 | E14: 3 ضد 4
A15: 2 | B15: =المدخلات!$F$6 -> 7:20–8:50 م | C15: 2 | D15: المجموعة 1 | E15: 2 ضد 5
A16: 3 | B16: =المدخلات!$F$4 -> 4:00–5:30 م | C16: 1 | D16: المجموعة 1 | E16: 5 ضد 7
A17: 3 | B17: =المدخلات!$F$4 -> 4:00–5:30 م | C17: 2 | D17: المجموعة 2 | E17: 9 ضد 10
A18: 3 | B18: =المدخلات!$F$5 -> 5:40–7:10 م | C18: 1 | D18: المجموعة 1 | E18: 2 ضد 3
A19: 3 | B19: =المدخلات!$F$5 -> 5:40–7:10 م | C19: 2 | D19: المجموعة 2 | E19: 12 ضد 14
A20: 3 | B20: =المدخلات!$F$6 -> 7:20–8:50 م | C20: 1 | D20: المجموعة 1 | E20: 1 ضد 6
A21: 3 | B21: =المدخلات!$F$6 -> 7:20–8:50 م | C21: 2 | D21: المجموعة 2 | E21: 8 ضد 13
A22: 4 | B22: =المدخلات!$F$4 -> 4:00–5:30 م | C22: 1 | D22: المجموعة 2 | E22: 8 ضد 12
A23: 4 | B23: =المدخلات!$F$4 -> 4:00–5:30 م | C23: 2 | D23: المجموعة 1 | E23: 1 ضد 5
A24: 4 | B24: =المدخلات!$F$5 -> 5:40–7:10 م | C24: 1 | D24: المجموعة 2 | E24: 11 ضد 13
A25: 4 | B25: =المدخلات!$F$5 -> 5:40–7:10 م | C25: 2 | D25: المجموعة 1 | E25: 4 ضد 6
A26: 4 | B26: =المدخلات!$F$6 -> 7:20–8:50 م | C26: 1 | D26: المجموعة 2 | E26: 10 ضد 14
A27: 4 | B27: =المدخلات!$F$6 -> 7:20–8:50 م | C27: 2 | D27: المجموعة 1 | E27: 3 ضد 7
A28: 5 | B28: =المدخلات!$F$4 -> 4:00–5:30 م | C28: 1 | D28: المجموعة 2 | E28: 9 ضد 13
A29: 5 | B29: =المدخلات!$F$4 -> 4:00–5:30 م | C29: 2 | D29: المجموعة 1 | E29: 1 ضد 4
A30: 5 | B30: =المدخلات!$F$5 -> 5:40–7:10 م | C30: 1 | D30: المجموعة 1 | E30: 3 ضد 5
