Workbook
Name الحد_الأدنى: [1]المدخلات!$N$3

Sheet 12 فريقًا
A1: جدول مباريات المجموعات التي فيها 12 فريقًا — أ: 6 فرق (1-6) | ب: 6 فرق (7-12)
A3: اليوم | B3: الوقت | C3: ملعب 1 (أ) | D3: ملعب 2 (أ) | E3: ملعب 3 (أ) | F3: ملعب 4 (ب) | G3: ملعب 5 (ب) | H3: ملعب 6 (ب) | I3: مجموع مباريات اليوم | J3: مباريات كل فريق (أ) | K3: مباريات كل فريق (ب) | M3: لاعبو الفترة (عمود مساعد) | O3: الفريق | P3: عدد مبارياته | Q3: مباريات متتالية | R3: راحة 15 دقيقة | S3: راحة 30 دقيقة | T3: راحة أطول من 30
A4: اليوم 1 | B4: =MOD(HOUR(([2]المدخلات!$B$4+0*[2]المدخلات!$B$5/1440))-1,12)+1&":"&TEXT(MINUTE(([2]المدخلات!$B$4+0*[2]المدخلات!$B$5/1440)),"00")&"–"&MOD(HOUR(([2]المدخلات!$B$4+0*[2]المدخلات!$B$5/1440+[2]المدخلات!$B$5/1440))-1,12)+1&":"&TEXT(MINUTE(([2]المدخلات!$B$4+0*[2]المدخلات!$B$5/1440+[2]المدخلات!$B$5/1440)),"00")&IF(HOUR(([2]المدخلات!$B$4+0*[2]المدخلات!$B$5/1440))<12," ص"," م") -> 4:00–4:15 م | C4: 1 ضد 6 | D4: 2 ضد 5 | E4: 3 ضد 4 | F4: 7 ضد 12 | G4: 8 ضد 11 | H4: 9 ضد 10 | I4: =COUNTIF(C4:H12,"* ضد *") -> 24 | J4: =COUNTIF(C4:E12,"* ضد *")*2/6 -> 4 | K4: =COUNTIF(F4:H12,"* ضد *")*2/6 -> 4 | M4: =_xlfn.TEXTJOIN(" ",TRUE,C4:H4) -> 1 ضد 6 2 ضد 5 3 ضد 4 7 ضد 12 8 ضد 11 9 ضد 10 | O4: 1 | P4: {=SUMPRODUCT(--ISNUMBER(SEARCH(" "&$O4&" "," "&M$4:M$57&" ")))} -> 25 | Q4: {=SUMPRODUCT(--ISNUMBER(SEARCH(" "&$O4&" "," "&M$4:M$56&" ")),--ISNUMBER(SEARCH(" "&$O4&" "," "&M$5:M$57&" ")),--(MOD(ROW(M$4:M$56)-4,$P$17)<=$P$17-2))} -> 0 | R4: {=SUMPRODUCT(--ISNUMBER(SEARCH(" "&$O4&" "," "&M$4:M$55&" ")),--ISNUMBER(SEARCH(" "&$O4&" "," "&M$6:M$57&" ")),--(MOD(ROW(M$4:M$55)-4,$P$17)<=$P$17-3))} -> 19 | S4: {=SUMPRODUCT(--ISNUMBER(SEARCH(" "&$O4&" "," "&M$4:M$54&" ")),--ISNUMBER(SEARCH(" "&$O4&" "," "&M$7:M$57&" ")),--(MOD(ROW(M$4:M$54)-4,$P$17)<=$P$17-4))} -> 0 | T4: =P4-COUNTIF($A$4:$A$57,"اليوم *")-Q4-R4-S4 -> 0
B5: =MOD(HOUR(([2]المدخلات!$B$4+1*[2]المدخلات!$B$5/1440))-1,12)+1&":"&TEXT(MINUTE(([2]المدخلات!$B$4+1*[2]المدخلات!$B$5/1440)),"00")&"–"&MOD(HOUR(([2]المدخلات!$B$4+1*[2]المدخلات!$B$5/1440+[2]المدخلات!$B$5/1440))-1,12)+1&":"&TEXT(MINUTE(([2]المدخلات!$B$4+1*[2]المدخلات!$B$5/1440+[2]المدخلات!$B$5/1440)),"00")&IF(HOUR(([2]المدخلات!$B$4+1*[2]المدخلات!$B$5/1440))<12," ص"," م") -> 4:15–4:30 م | C5: استراحة (لا توجد مباريات) | F5: استراحة (لا توجد مباريات) | M5: =_xlfn.TEXTJOIN(" ",TRUE,C5:H5) -> استراحة (لا توجد مباريات) استراحة (لا توجد مباريات) | O5: 2 | P5: {=SUMPRODUCT(--ISNUMBER(SEARCH(" "&$O5&" "," "&M$4:M$57&" ")))} -> 25 | Q5: {=SUMPRODUCT(--ISNUMBER(SEARCH(" "&$O5&" "," "&M$4:M$56&" ")),--ISNUMBER(SEARCH(" "&$O5&" "," "&M$5:M$57&" ")),--(MOD(ROW(M$4:M$56)-4,$P$17)<=$P$17-2))} -> 0 | R5: {=SUMPRODUCT(--ISNUMBER(SEARCH(" "&$O5&" "," "&M$4:M$55&" ")),--ISNUMBER(SEARCH(" "&$O5&" "," "&M$6:M$57&" ")),--(MOD(ROW(M$4:M$55)-4,$P$17)<=$P$17-3))} -> 19 | S5: {=SUMPRODUCT(--ISNUMBER(SEARCH(" "&$O5&" "," "&M$4:M$54&" ")),--ISNUMBER(SEARCH(" "&$O5&" "," "&M$7:M$57&" ")),--(MOD(ROW(M$4:M$54)-4,$P$17)<=$P$17-4))} -> 0 | T5: =P5-COUNTIF($A$4:$A$57,"اليوم *")-Q5-R5-S5 -> 0
B6: =MOD(HOUR(([2]المدخلات!$B$4+2*[2]المدخلات!$B$5/1440))-1,12)+1&":"&TEXT(MINUTE(([2]المدخلات!$B$4+2*[2]المدخلات!$B$5/1440)),"00")&"–"&MOD(HOUR(([2]المدخلات!$B$4+2*[2]المدخلات!$B$5/1440+[2]المدخلات!$B$5/1440))-1,12)+1&":"&TEXT(MINUTE(([2]المدخلات!$B$4+2*[2]المدخلات!$B$5/1440+[2]المدخلات!$B$5/1440)),"00")&IF(HOUR(([2]المدخلات!$B$4+2*[2]المدخلات!$B$5/1440))<12," ص"," م") -> 4:30–4:45 م | C6: 2 ضد 3 | D6: 6 ضد 4 | E6: 1 ضد 5 | F6: 8 ضد 9 | G6: 12 ضد 10 | H6: 7 ضد 11 | M6: =_xlfn.TEXTJOIN(" ",TRUE,C6:H6) -> 2 ضد 3 6 ضد 4 1 ضد 5 8 ضد 9 12 ضد 10 7 ضد 11 | O6: 3 | P6: {=SUMPRODUCT(--ISNUMBER(SEARCH(" "&$O6&" "," "&M$4:M$57&" ")))} -> 25 | Q6: {=SUMPRODUCT(--ISNUMBER(SEARCH(" "&$O6&" "," "&M$4:M$56&" ")),--ISNUMBER(SEARCH(" "&$O6&" "," "&M$5:M$57&" ")),--(MOD(ROW(M$4:M$56)-4,$P$17)<=$P$17-2))} -> 0 | R6: {=SUMPRODUCT(--ISNUMBER(SEARCH(" "&$O6&" "," "&M$4:M$55&" ")),--ISNUMBER(SEARCH(" "&$O6&" "," "&M$6:M$57&" ")),--(MOD(ROW(M$4:M$55)-4,$P$17)<=$P$17-3))} -> 19 | S6: {=SUMPRODUCT(--ISNUMBER(SEARCH(" "&$O6&" "," "&M$4:M$54&" ")),--ISNUMBER(SEARCH(" "&$O6&" "," "&M$7:M$57&" ")),--(MOD(ROW(M$4:M$54)-4,$P$17)<=$P$17-4))} -> 0 | T6: =P6-COUNTIF($A$4:$A$57,"اليوم *")-Q6-R6-S6 -> 0
B7: =MOD(HOUR(([2]المدخلات!$B$4+3*[2]المدخلات!$B$5/1440))-1,12)+1&":"&TEXT(MINUTE(([2]المدخلات!$B$4+3*[2]المدخلات!$B$5/1440)),"00")&"–"&MOD(HOUR(([2]المدخلات!$B$4+3*[2]المدخلات!$B$5/1440+[2]المدخلات!$B$5/1440))-1,12)+1&":"&TEXT(MINUTE(([2]المدخلات!$B$4+3*[2]المدخلات!$B$5/1440+[2]المدخلات!$B$5/1440)),"00")&IF(HOUR(([2]المدخلات!$B$4+3*[2]المدخلات!$B$5/1440))<12," ص"," م") -> 4:45–5:00 م | C7: استراحة (لا توجد مباريات) | F7: استراحة (لا توجد مباريات) | M7: =_xlfn.TEXTJOIN(" ",TRUE,C7:H7) -> استراحة (لا توجد مباريات) استراحة (لا توجد مباريات) | O7: 4 | P7: {=SUMPRODUCT(--ISNUMBER(SEARCH(" "&$O7&" "," "&M$4:M$57&" ")))} -> 25 | Q7: {=SUMPRODUCT(--ISNUMBER(SEARCH(" "&$O7&" "," "&M$4:M$56&" ")),--ISNUMBER(SEARCH(" "&$O7&" "," "&M$5:M$57&" ")),--(MOD(ROW(M$4:M$56)-4,$P$17)<=$P$17-2))} -> 0 | R7: {=SUMPRODUCT(--ISNUMBER(SEARCH(" "&$O7&" "," "&M$4:M$55&" ")),--ISNUMBER(SEARCH(" "&$O7&" "," "&M$6:M$57&" ")),--(MOD(ROW(M$4:M$55)-4,$P$17)<=$P$17-3))} -> 19 | S7: {=SUMPRODUCT(--ISNUMBER(SEARCH(" "&$O7&" "," "&M$4:M$54&" ")),--ISNUMBER(SEARCH(" "&$O7&" "," "&M$7:M$57&" ")),--(MOD(ROW(M$4:M$54)-4,$P$17)<=$P$17-4))} -> 0 | T7: =P7-COUNTIF($A$4:$A$57,"اليوم *")-Q7-R7-S7 -> 0
B8: =MOD(HOUR(([2]المدخلات!$B$4+4*[2]المدخلات!$B$5/1440))-1,12)+1&":"&TEXT(MINUTE(([2]المدخلات!$B$4+4*[2]المدخلات!$B$5/1440)),"00")&"–"&MOD(HOUR(([2]المدخلات!$B$4+4*[2]المدخلات!$B$5/1440+[2]المدخلات!$B$5/1440))-1,12)+1&":"&TEXT(MINUTE(([2]المدخلات!$B$4+4*[2]المدخلات!$B$5/1440+[2]المدخلات!$B$5/1440)),"00")&IF(HOUR(([2]المدخلات!$B$4+4*[2]المدخلات!$B$5/1440))<12," ص"," م") -> 5:00–5:15 م | C8: 5 ضد 3 | D8: 1 ضد 4 | E8: 6 ضد 2 | F8: 11 ضد 9 | G8: 7 ضد 10 | H8: 12 ضد 8 | M8: =_xlfn.TEXTJOIN(" ",TRUE,C8:H8) -> 5 ضد 3 1 ضد 4 6 ضد 2 11 ضد 9 7 ضد 10 12 ضد 8 | O8: 5 | P8: {=SUMPRODUCT(--ISNUMBER(SEARCH(" "&$O8&" "," "&M$4:M$57&" ")))} -> 25 | Q8: {=SUMPRODUCT(--ISNUMBER(SEARCH(" "&$O8&" "," "&M$4:M$56&" ")),--ISNUMBER(SEARCH(" "&$O8&" "," "&M$5:M$57&" ")),--(MOD(ROW(M$4:M$56)-4,$P$17)<=$P$17-2))} -> 0 | R8: {=SUMPRODUCT(--ISNUMBER(SEARCH(" "&$O8&" "," "&M$4:M$55&" ")),--ISNUMBER(SEARCH(" "&$O8&" "," "&M$6:M$57&" ")),--(MOD(ROW(M$4:M$55)-4,$P$17)<=$P$17-3))} -> 19 | S8: {=SUMPRODUCT(--ISNUMBER(SEARCH(" "&$O8&" "," "&M$4:M$54&" ")),--ISNUMBER(SEARCH(" "&$O8&" "," "&M$7:M$57&" ")),--(MOD(ROW(M$4:M$54)-4,$P$17)<=$P$17-4))} -> 0 | T8: =P8-COUNTIF($A$4:$A$57,"اليوم *")-Q8-R8-S8 -> 0
B9: =MOD(HOUR(([2]المدخلات!$B$4+5*[2]المدخلات!$B$5/1440))-1,12)+1&":"&TEXT(MINUTE(([2]المدخلات!$B$4+5*[2]المدخلات!$B$5/1440)),"00")&"–"&MOD(HOUR(([2]المدخلات!$B$4+5*[2]المدخلات!$B$5/1440+[2]المدخلات!$B$5/1440))-1,12)+1&":"&TEXT(MINUTE(([2]المدخلات!$B$4+5*[2]المدخلات!$B$5/1440+[2]المدخلات!$B$5/1440)),"00")&IF(HOUR(([2]المدخلات!$B$4+5*[2]المدخلات!$B$5/1440))<12," ص"," م") -> 5:15–5:30 م | C9: استراحة (لا توجد مباريات) | F9: استراحة (لا توجد مباريات) | M9: =_xlfn.TEXTJOIN(" ",TRUE,C9:H9) -> استراحة (لا توجد مباريات) استراحة (لا توجد مباريات) | O9: 6 | P9: {=SUMPRODUCT(--ISNUMBER(SEARCH(" "&$O9&" "," "&M$4:M$57&" ")))} -> 25 | Q9: {=SUMPRODUCT(--ISNUMBER(SEARCH(" "&$O9&" "," "&M$4:M$56&" ")),--ISNUMBER(SEARCH(" "&$O9&" "," "&M$5:M$57&" ")),--(MOD(ROW(M$4:M$56)-4,$P$17)<=$P$17-2))} -> 0 | R9: {=SUMPRODUCT(--ISNUMBER(SEARCH(" "&$O9&" "," "&M$4:M$55&" ")),--ISNUMBER(SEARCH(" "&$O9&" "," "&M$6:M$57&" ")),--(MOD(ROW(M$4:M$55)-4,$P$17)<=$P$17-3))} -> 19 | S9: {=SUMPRODUCT(--ISNUMBER(SEARCH(" "&$O9&" "," "&M$4:M$54&" ")),--ISNUMBER(SEARCH(" "&$O9&" "," "&M$7:M$57&" ")),--(MOD(ROW(M$4:M$54)-4,$P$17)<=$P$17-4))} -> 0 | T9: =P9-COUNTIF($A$4:$A$57,"اليوم *")-Q9-R9-S9 -> 0
B10: =MOD(HOUR(([2]المدخلات!$B$4+6*[2]المدخلات!$B$5/1440))-1,12)+1&":"&TEXT(MINUTE(([2]المدخلات!$B$4+6*[2]المدخلات!$B$5/1440)),"00")&"–"&MOD(HOUR(([2]المدخلات!$B$4+6*[2]المدخلات!$B$5/1440+[2]المدخلات!$B$5/1440))-1,12)+1&":"&TEXT(MINUTE(([2]المدخلات!$B$4+6*[2]المدخلات!$B$5/1440+[2]المدخلات!$B$5/1440)),"00")&IF(HOUR(([2]المدخلات!$B$4+6*[2]المدخلات!$B$5/1440))<12," ص"," م") -> 5:30–5:45 م | C10: 4 ضد 2 | D10: 1 ضد 3 | E10: 5 ضد 6 | F10: 10 ضد 8 | G10: 7 ضد 9 | H10: 11 ضد 12 | M10: =_xlfn.TEXTJOIN(" ",TRUE,C10:H10) -> 4 ضد 2 1 ضد 3 5 ضد 6 10 ضد 8 7 ضد 9 11 ضد 12 | O10: 7 | P10: {=SUMPRODUCT(--ISNUMBER(SEARCH(" "&$O10&" "," "&M$4:M$57&" ")))} -> 25 | Q10: {=SUMPRODUCT(--ISNUMBER(SEARCH(" "&$O10&" "," "&M$4:M$56&" ")),--ISNUMBER(SEARCH(" "&$O10&" "," "&M$5:M$57&" ")),--(MOD(ROW(M$4:M$56)-4,$P$17)<=$P$17-2))} -> 0 | R10: {=SUMPRODUCT(--ISNUMBER(SEARCH(" "&$O10&" "," "&M$4:M$55&" ")),--ISNUMBER(SEARCH(" "&$O10&" "," "&M$6:M$57&" ")),--(MOD(ROW(M$4:M$55)-4,$P$17)<=$P$17-3))} -> 19 | S10: {=SUMPRODUCT(--ISNUMBER(SEARCH(" "&$O10&" "," "&M$4:M$54&" ")),--ISNUMBER(SEARCH(" "&$O10&" "," "&M$7:M$57&" ")),--(MOD(ROW(M$4:M$54)-4,$P$17)<=$P$17-4))} -> 0 | T10: =P10-COUNTIF($A$4:$A$57,"اليوم *")-Q10-R10-S10 -> 0
B11: =MOD(HOUR(([2]المدخلات!$B$4+7*[2]المدخلات!$B$5/1440))-1,12)+1&":"&TEXT(MINUTE(([2]المدخلات!$B$4+7*[2]المدخلات!$B$5/1440)),"00")&"–"&MOD(HOUR(([2]المدخلات!$B$4+7*[2]المدخلات!$B$5/1440+[2]المدخلات!$B$5/1440))-1,12)+1&":"&TEXT(MINUTE(([2]المدخلات!$B$4+7*[2]المدخلات!$B$5/1440+[2]المدخلات!$B$5/1440)),"00")&IF(HOUR(([2]المدخلات!$B$4+7*[2]المدخلات!$B$5/1440))<12," ص"," م") -> 5:45–6:00 م | M11: =_xlfn.TEXTJOIN(" ",TRUE,C11:H11) | O11: 8 | P11: {=SUMPRODUCT(--ISNUMBER(SEARCH(" "&$O11&" "," "&M$4:M$57&" ")))} -> 25 | Q11: {=SUMPRODUCT(--ISNUMBER(SEARCH(" "&$O11&" "," "&M$4:M$56&" ")),--ISNUMBER(SEARCH(" "&$O11&" "," "&M$5:M$57&" ")),--(MOD(ROW(M$4:M$56)-4,$P$17)<=$P$17-2))} -> 0 | R11: {=SUMPRODUCT(--ISNUMBER(SEARCH(" "&$O11&" "," "&M$4:M$55&" ")),--ISNUMBER(SEARCH(" "&$O11&" "," "&M$6:M$57&" ")),--(MOD(ROW(M$4:M$55)-4,$P$17)<=$P$17-3))} -> 19 | S11: {=SUMPRODUCT(--ISNUMBER(SEARCH(" "&$O11&" "," "&M$4:M$54&" ")),--ISNUMBER(SEARCH(" "&$O11&" "," "&M$7:M$57&" ")),--(MOD(ROW(M$4:M$54)-4,$P$17)<=$P$17-4))} -> 0 | T11: =P11-COUNTIF($A$4:$A$57,"اليوم *")-Q11-R11-S11 -> 0
B12: =MOD(HOUR(([2]المدخلات!$B$4+8*[2]المدخلات!$B$5/1440))-1,12)+1&":"&TEXT(MINUTE(([2]المدخلات!$B$4+8*[2]المدخلات!$B$5/1440)),"00")&"–"&MOD(HOUR(([2]المدخلات!$B$4+8*[2]المدخلات!$B$5/1440+[2]المدخلات!$B$5/1440))-1,12)+1&":"&TEXT(MINUTE(([2]المدخلات!$B$4+8*[2]المدخلات!$B$5/1440+[2]المدخلات!$B$5/1440)),"00")&IF(HOUR(([2]المدخلات!$B$4+8*[2]المدخلات!$B$5/1440))<12," ص"," م") -> 6:00–6:15 م | M12: =_xlfn.TEXTJOIN(" ",TRUE,C12:H12) | O12: 9 | P12: {=SUMPRODUCT(--ISNUMBER(SEARCH(" "&$O12&" "," "&M$4:M$57&" ")))} -> 25 | Q12: {=SUMPRODUCT(--ISNUMBER(SEARCH(" "&$O12&" "," "&M$4:M$56&" ")),--ISNUMBER(SEARCH(" "&$O12&" "," "&M$5:M$57&" ")),--(MOD(ROW(M$4:M$56)-4,$P$17)<=$P$17-2))} -> 0 | R12: {=SUMPRODUCT(--ISNUMBER(SEARCH(" "&$O12&" "," "&M$4:M$55&" ")),--ISNUMBER(SEARCH(" "&$O12&" "," "&M$6:M$57&" ")),--(MOD(ROW(M$4:M$55)-4,$P$17)<=$P$17-3))} -> 19 | S12: {=SUMPRODUCT(--ISNUMBER(SEARCH(" "&$O12&" "," "&M$4:M$54&" ")),--ISNUMBER(SEARCH(" "&$O12&" "," "&M$7:M$57&" ")),--(MOD(ROW(M$4:M$54)-4,$P$17)<=$P$17-4))} -> 0 | T12: =P12-COUNTIF($A$4:$A$57,"اليوم *")-Q12-R12-S12 -> 0
A13: اليوم 2 | B13: =MOD(HOUR(([2]المدخلات!$B$4+0*[2]المدخلات!$B$5/1440))-1,12)+1&":"&TEXT(MINUTE(([2]المدخلات!$B$4+0*[2]المدخلات!$B$5/1440)),"00")&"–"&MOD(HOUR(([2]المدخلات!$B$4+0*[2]المدخلات!$B$5/1440+[2]المدخلات!$B$5/1440))-1,12)+1&":"&TEXT(MINUTE(([2]المدخلات!$B$4+0*[2]المدخلات!$B$5/1440+[2]المدخلات!$B$5/1440)),"00")&IF(HOUR(([2]المدخلات!$B$4+0*[2]المدخلات!$B$5/1440))<12," ص"," م") -> 4:00–4:15 م | C13: 4 ضد 5 | D13: 3 ضد 6 | E13: 1 ضد 2 | F13: 10 ضد 11 | G13: 9 ضد 12 | H13: 7 ضد 8 | I13: =COUNTIF(C13:H21,"* ضد *") -> 24 | J13: =COUNTIF(C13:E21,"* ضد *")*2/6 -> 4 | K13: =COUNTIF(F13:H21,"* ضد *")*2/6 -> 4 | M13: =_xlfn.TEXTJOIN(" ",TRUE,C13:H13) -> 4 ضد 5 3 ضد 6 1 ضد 2 10 ضد 11 9 ضد 12 7 ضد 8 | O13: 10 | P13: {=SUMPRODUCT(--ISNUMBER(SEARCH(" "&$O13&" "," "&M$4:M$57&" ")))} -> 25 | Q13: {=SUMPRODUCT(--ISNUMBER(SEARCH(" "&$O13&" "," "&M$4:M$56&" ")),--ISNUMBER(SEARCH(" "&$O13&" "," "&M$5:M$57&" ")),--(MOD(ROW(M$4:M$56)-4,$P$17)<=$P$17-2))} -> 0 | R13: {=SUMPRODUCT(--ISNUMBER(SEARCH(" "&$O13&" "," "&M$4:M$55&" ")),--ISNUMBER(SEARCH(" "&$O13&" "," "&M$6:M$57&" ")),--(MOD(ROW(M$4:M$55)-4,$P$17)<=$P$17-3))} -> 19 | S13: {=SUMPRODUCT(--ISNUMBER(SEARCH(" "&$O13&" "," "&M$4:M$54&" ")),--ISNUMBER(SEARCH(" "&$O13&" "," "&M$7:M$57&" ")),--(MOD(ROW(M$4:M$54)-4,$P$17)<=$P$17-4))} -> 0 | T13: =P13-COUNTIF($A$4:$A$57,"اليوم *")-Q13-R13-S13 -> 0
B14: =MOD(HOUR(([2]المدخلات!$B$4+1*[2]المدخلات!$B$5/1440))-1,12)+1&":"&TEXT(MINUTE(([2]المدخلات!$B$4+1*[2]المدخلات!$B$5/1440)),"00")&"–"&MOD(HOUR(([2]المدخلات!$B$4+1*[2]المدخلات!$B$5/1440+[2]المدخلات!$B$5/1440))-1,12)+1&":"&TEXT(MINUTE(([2]المدخلات!$B$4+1*[2]المدخلات!$B$5/1440+[2]المدخلات!$B$5/1440)),"00")&IF(HOUR(([2]المدخلات!$B$4+1*[2]المدخلات!$B$5/1440))<12," ص"," م") -> 4:15–4:30 م | C14: استراحة (لا توجد مباريات) | F14: استراحة (لا توجد مباريات) | M14: =_xlfn.TEXTJOIN(" ",TRUE,C14:H14) -> استراحة (لا توجد مباريات) استراحة (لا توجد مباريات) | O14: 11 | P14: {=SUMPRODUCT(--ISNUMBER(SEARCH(" "&$O14&" "," "&M$4:M$57&" ")))} -> 25 | Q14: {=SUMPRODUCT(--ISNUMBER(SEARCH(" "&$O14&" "," "&M$4:M$56&" ")),--ISNUMBER(SEARCH(" "&$O14&" "," "&M$5:M$57&" ")),--(MOD(ROW(M$4:M$56)-4,$P$17)<=$P$17-2))} -> 0 | R14: {=SUMPRODUCT(--ISNUMBER(SEARCH(" "&$O14&" "," "&M$4:M$55&" ")),--ISNUMBER(SEARCH(" "&$O14&" "," "&M$6:M$57&" ")),--(MOD(ROW(M$4:M$55)-4,$P$17)<=$P$17-3))} -> 19 | S14: {=SUMPRODUCT(--ISNUMBER(SEARCH(" "&$O14&" "," "&M$4:M$54&" ")),--ISNUMBER(SEARCH(" "&$O14&" "," "&M$7:M$57&" ")),--(MOD(ROW(M$4:M$54)-4,$P$17)<=$P$17-4))} -> 0 | T14: =P14-COUNTIF($A$4:$A$57,"اليوم *")-Q14-R14-S14 -> 0
B15: =MOD(HOUR(([2]المدخلات!$B$4+2*[2]المدخلات!$B$5/1440))-1,12)+1&":"&TEXT(MINUTE(([2]المدخلات!$B$4+2*[2]المدخلات!$B$5/1440)),"00")&"–"&MOD(HOUR(([2]المدخلات!$B$4+2*[2]المدخلات!$B$5/1440+[2]المدخلات!$B$5/1440))-1,12)+1&":"&TEXT(MINUTE(([2]المدخلات!$B$4+2*[2]المدخلات!$B$5/1440+[2]المدخلات!$B$5/1440)),"00")&IF(HOUR(([2]المدخلات!$B$4+2*[2]المدخلات!$B$5/1440))<12," ص"," م") -> 4:30–4:45 م | C15: 1 ضد 6 | D15: 2 ضد 5 | E15: 3 ضد 4 | F15: 7 ضد 12 | G15: 8 ضد 11 | H15: 9 ضد 10 | M15: =_xlfn.TEXTJOIN(" ",TRUE,C15:H15) -> 1 ضد 6 2 ضد 5 3 ضد 4 7 ضد 12 8 ضد 11 9 ضد 10 | O15: 12 | P15: {=SUMPRODUCT(--ISNUMBER(SEARCH(" "&$O15&" "," "&M$4:M$57&" ")))} -> 25 | Q15: {=SUMPRODUCT(--ISNUMBER(SEARCH(" "&$O15&" "," "&M$4:M$56&" ")),--ISNUMBER(SEARCH(" "&$O15&" "," "&M$5:M$57&" ")),--(MOD(ROW(M$4:M$56)-4,$P$17)<=$P$17-2))} -> 0 | R15: {=SUMPRODUCT(--ISNUMBER(SEARCH(" "&$O15&" "," "&M$4:M$55&" ")),--ISNUMBER(SEARCH(" "&$O15&" "," "&M$6:M$57&" ")),--(MOD(ROW(M$4:M$55)-4,$P$17)<=$P$17-3))} -> 19 | S15: {=SUMPRODUCT(--ISNUMBER(SEARCH(" "&$O15&" "," "&M$4:M$54&" ")),--ISNUMBER(SEARCH(" "&$O15&" "," "&M$7:M$57&" ")),--(MOD(ROW(M$4:M$54)-4,$P$17)<=$P$17-4))} -> 0 | T15: =P15-COUNTIF($A$4:$A$57,"اليوم *")-Q15-R15-S15 -> 0
B16: =MOD(HOUR(([2]المدخلات!$B$4+3*[2]المدخلات!$B$5/1440))-1,12)+1&":"&TEXT(MINUTE(([2]المدخلات!$B$4+3*[2]المدخلات!$B$5/1440)),"00")&"–"&MOD(HOUR(([2]المدخلات!$B$4+3*[2]المدخلات!$B$5/1440+[2]المدخلات!$B$5/1440))-1,12)+1&":"&TEXT(MINUTE(([2]المدخلات!$B$4+3*[2]المدخلات!$B$5/1440+[2]المدخلات!$B$5/1440)),"00")&IF(HOUR(([2]المدخلات!$B$4+3*[2]المدخلات!$B$5/1440))<12," ص"," م") -> 4:45–5:00 م | C16: استراحة (لا توجد مباريات) | F16: استراحة (لا توجد مباريات) | M16: =_xlfn.TEXTJOIN(" ",TRUE,C16:H16) -> استراحة (لا توجد مباريات) استراحة (لا توجد مباريات) | O16: المجموع | P16: =SUM(P4:P15) -> 300 | Q16: =SUM(Q4:Q15) -> 0 | R16: =SUM(R4:R15) -> 228 | S16: =SUM(S4:S15) -> 0 | T16: =SUM(T4:T15) -> 0
B17: =MOD(HOUR(([2]المدخلات!$B$4+4*[2]المدخلات!$B$5/1440))-1,12)+1&":"&TEXT(MINUTE(([2]المدخلات!$B$4+4*[2]المدخلات!$B$5/1440)),"00")&"–"&MOD(HOUR(([2]المدخلات!$B$4+4*[2]المدخلات!$B$5/1440+[2]المدخلات!$B$5/1440))-1,12)+1&":"&TEXT(MINUTE(([2]المدخلات!$B$4+4*[2]المدخلات!$B$5/1440+[2]المدخلات!$B$5/1440)),"00")&IF(HOUR(([2]المدخلات!$B$4+4*[2]المدخلات!$B$5/1440))<12," ص"," م") -> 5:00–5:15 م | C17: 1 ضد 5 | D17: 6 ضد 4 | E17: 2 ضد 3 | F17: 7 ضد 11 | G17: 12 ضد 10 | H17: 8 ضد 9 | M17: =_xlfn.TEXTJOIN(" ",TRUE,C17:H17) -> 1 ضد 5 6 ضد 4 2 ضد 3 7 ضد 11 12 ضد 10 8 ضد 9 | O17: فترات اليوم | P17: 9
B18: =MOD(HOUR(([2]المدخلات!$B$4+5*[2]المدخلات!$B$5/1440))-1,12)+1&":"&TEXT(MINUTE(([2]المدخلات!$B$4+5*[2]المدخلات!$B$5/1440)),"00")&"–"&MOD(HOUR(([2]المدخلات!$B$4+5*[2]المدخلات!$B$5/1440+[2]المدخلات!$B$5/1440))-1,12)+1&":"&TEXT(MINUTE(([2]المدخلات!$B$4+5*[2]المدخلات!$B$5/1440+[2]المدخلات!$B$5/1440)),"00")&IF(HOUR(([2]المدخلات!$B$4+5*[2]المدخلات!$B$5/1440))<12," ص"," م") -> 5:15–5:30 م | C18: استراحة (لا توجد مباريات) | F18: استراحة (لا توجد مباريات) | M18: =_xlfn.TEXTJOIN(" ",TRUE,C18:H18) -> استراحة (لا توجد مباريات) استراحة (لا توجد مباريات)
B19: =MOD(HOUR(([2]المدخلات!$B$4+6*[2]المدخلات!$B$5/1440))-1,12)+1&":"&TEXT(MINUTE(([2]المدخلات!$B$4+6*[2]المدخلات!$B$5/1440)),"00")&"–"&MOD(HOUR(([2]المدخلات!$B$4+6*[2]المدخلات!$B$5/1440+[2]المدخلات!$B$5/1440))-1,12)+1&":"&TEXT(MINUTE(([2]المدخلات!$B$4+6*[2]المدخلات!$B$5/1440+[2]المدخلات!$B$5/1440)),"00")&IF(HOUR(([2]المدخلات!$B$4+6*[2]المدخلات!$B$5/1440))<12," ص"," م") -> 5:30–5:45 م | C19: 6 ضد 2 | D19: 5 ضد 3 | E19: 1 ضد 4 | F19: 12 ضد 8 | G19: 11 ضد 9 | H19: 7 ضد 10 | M19: =_xlfn.TEXTJOIN(" ",TRUE,C19:H19) -> 6 ضد 2 5 ضد 3 1 ضد 4 12 ضد 8 11 ضد 9 7 ضد 10
B20: =MOD(HOUR(([2]المدخلات!$B$4+7*[2]المدخلات!$B$5/1440))-1,12)+1&":"&TEXT(MINUTE(([2]المدخلات!$B$4+7*[2]المدخلات!$B$5/1440)),"00")&"–"&MOD(HOUR(([2]المدخلات!$B$4+7*[2]المدخلات!$B$5/1440+[2]المدخلات!$B$5/1440))-1,12)+1&":"&TEXT(MINUTE(([2]المدخلات!$B$4+7*[2]المدخلات!$B$5/1440+[2]المدخلات!$B$5/1440)),"00")&IF(HOUR(([2]المدخلات!$B$4+7*[2]المدخلات!$B$5/1440))<12," ص"," م") -> 5:45–6:00 م | M20: =_xlfn.TEXTJOIN(" ",TRUE,C20:H20)
B21: =MOD(HOUR(([2]المدخلات!$B$4+8*[2]المدخلات!$B$5/1440))-1,12)+1&":"&TEXT(MINUTE(([2]المدخلات!$B$4+8*[2]المدخلات!$B$5/1440)),"00")&"–"&MOD(HOUR(([2]المدخلات!$B$4+8*[2]المدخلات!$B$5/1440+[2]المدخلات!$B$5/1440))-1,12)+1&":"&TEXT(MINUTE(([2]المدخلات!$B$4+8*[2]المدخلات!$B$5/1440+[2]المدخلات!$B$5/1440)),"00")&IF(HOUR(([2]المدخلات!$B$4+8*[2]المدخلات!$B$5/1440))<12," ص"," م") -> 6:00–6:15 م | M21: =_xlfn.TEXTJOIN(" ",TRUE,C21:H21)
A22: اليوم 3 | B22: =MOD(HOUR(([2]المدخلات!$B$4+0*[2]المدخلات!$B$5/1440))-1,12)+1&":"&TEXT(MINUTE(([2]المدخلات!$B$4+0*[2]المدخلات!$B$5/1440)),"00")&"–"&MOD(HOUR(([2]المدخلات!$B$4+0*[2]المدخلات!$B$5/1440+[2]المدخلات!$B$5/1440))-1,12)+1&":"&TEXT(MINUTE(([2]المدخلات!$B$4+0*[2]المدخلات!$B$5/1440+[2]المدخلات!$B$5/1440)),"00")&IF(HOUR(([2]المدخلات!$B$4+0*[2]المدخلات!$B$5/1440))<12," ص"," م") -> 4:00–4:15 م | C22: 4 ضد 2 | D22: 1 ضد 3 | E22: 5 ضد 6 | F22: 10 ضد 8 | G22: 7 ضد 9 | H22: 11 ضد 12 | I22: =COUNTIF(C22:H30,"* ضد *") -> 24 | J22: =COUNTIF(C22:E30,"* ضد *")*2/6 -> 4 | K22: =COUNTIF(F22:H30,"* ضد *")*2/6 -> 4 | M22: =_xlfn.TEXTJOIN(" ",TRUE,C22:H22) -> 4 ضد 2 1 ضد 3 5 ضد 6 10 ضد 8 7 ضد 9 11 ضد 12
B23: =MOD(HOUR(([2]المدخلات!$B$4+1*[2]المدخلات!$B$5/1440))-1,12)+1&":"&TEXT(MINUTE(([2]المدخلات!$B$4+1*[2]المدخلات!$B$5/1440)),"00")&"–"&MOD(HOUR(([2]المدخلات!$B$4+1*[2]المدخلات!$B$5/1440+[2]المدخلات!$B$5/1440))-1,12)+1&":"&TEXT(MINUTE(([2]المدخلات!$B$4+1*[2]المدخلات!$B$5/1440+[2]المدخلات!$B$5/1440)),"00")&IF(HOUR(([2]المدخلات!$B$4+1*[2]المدخلات!$B$5/1440))<12," ص"," م") -> 4:15–4:30 م | C23: استراحة (لا توجد مباريات) | F23: استراحة (لا توجد مباريات) | M23: =_xlfn.TEXTJOIN(" ",TRUE,C23:H23) -> استراحة (لا توجد مباريات) استراحة (لا توجد مباريات)
B24: =MOD(HOUR(([2]المدخلات!$B$4+2*[2]المدخلات!$B$5/1440))-1,12)+1&":"&TEXT(MINUTE(([2]المدخلات!$B$4+2*[2]المدخلات!$B$5/1440)),"00")&"–"&MOD(HOUR(([2]المدخلات!$B$4+2*[2]المدخلات!$B$5/1440+[2]المدخلات!$B$5/1440))-1,12)+1&":"&TEXT(MINUTE(([2]المدخلات!$B$4+2*[2]المدخلات!$B$5/1440+[2]المدخلات!$B$5/1440)),"00")&IF(HOUR(([2]المدخلات!$B$4+2*[2]المدخلات!$B$5/1440))<12," ص"," م") -> 4:30–4:45 م | C24: 3 ضد 6 | D24: 1 ضد 2 | E24: 4 ضد 5 | F24: 9 ضد 12 | G24: 7 ضد 8 | H24: 10 ضد 11 | M24: =_xlfn.TEXTJOIN(" ",TRUE,C24:H24) -> 3 ضد 6 1 ضد 2 4 ضد 5 9 ضد 12 7 ضد 8 10 ضد 11
B25: =MOD(HOUR(([2]المدخلات!$B$4+3*[2]المدخلات!$B$5/1440))-1,12)+1&":"&TEXT(MINUTE(([2]المدخلات!$B$4+3*[2]المدخلات!$B$5/1440)),"00")&"–"&MOD(HOUR(([2]المدخلات!$B$4+3*[2]المدخلات!$B$5/1440+[2]المدخلات!$B$5/1440))-1,12)+1&":"&TEXT(MINUTE(([2]المدخلات!$B$4+3*[2]المدخلات!$B$5/1440+[2]المدخلات!$B$5/1440)),"00")&IF(HOUR(([2]المدخلات!$B$4+3*[2]المدخلات!$B$5/1440))<12," ص"," م") -> 4:45–5:00 م | C25: استراحة (لا توجد مباريات) | F25: استراحة (لا توجد مباريات) | M25: =_xlfn.TEXTJOIN(" ",TRUE,C25:H25) -> استراحة (لا توجد مباريات) استراحة (لا توجد مباريات)
B26: =MOD(HOUR(([2]المدخلات!$B$4+4*[2]المدخلات!$B$5/1440))-1,12)+1&":"&TEXT(MINUTE(([2]المدخلات!$B$4+4*[2]المدخلات!$B$5/1440)),"00")&"–"&MOD(HOUR(([2]المدخلات!$B$4+4*[2]المدخلات!$B$5/1440+[2]المدخلات!$B$5/1440))-1,12)+1&":"&TEXT(MINUTE(([2]المدخلات!$B$4+4*[2]المدخلات!$B$5/1440+[2]المدخلات!$B$5/1440)),"00")&IF(HOUR(([2]المدخلات!$B$4+4*[2]المدخلات!$B$5/1440))<12," ص"," م") -> 5:00–5:15 م | C26: 3 ضد 4 | D26: 2 ضد 5 | E26: 1 ضد 6 | F26: 9 ضد 10 | G26: 8 ضد 11 | H26: 7 ضد 12 | M26: =_xlfn.TEXTJOIN(" ",TRUE,C26:H26) -> 3 ضد 4 2 ضد 5 1 ضد 6 9 ضد 10 8 ضد 11 7 ضد 12
B27: =MOD(HOUR(([2]المدخلات!$B$4+5*[2]المدخلات!$B$5/1440))-1,12)+1&":"&TEXT(MINUTE(([2]المدخلات!$B$4+5*[2]المدخلات!$B$5/1440)),"00")&"–"&MOD(HOUR(([2]المدخلات!$B$4+5*[2]المدخلات!$B$5/1440+[2]المدخلات!$B$5/1440))-1,12)+1&":"&TEXT(MINUTE(([2]المدخلات!$B$4+5*[2]المدخلات!$B$5/1440+[2]المدخلات!$B$5/1440)),"00")&IF(HOUR(([2]المدخلات!$B$4+5*[2]المدخلات!$B$5/1440))<12," ص"," م") -> 5:15–5:30 م | C27: استراحة (لا توجد مباريات) | F27: استراحة (لا توجد مباريات) | M27: =_xlfn.TEXTJOIN(" ",TRUE,C27:H27) -> استراحة (لا توجد مباريات) استراحة (لا توجد مباريات)
B28: =MOD(HOUR(([2]المدخلات!$B$4+6*[2]المدخلات!$B$5/1440))-1,12)+1&":"&TEXT(MINUTE(([2]المدخلات!$B$4+6*[2]المدخلات!$B$5/1440)),"00")&"–"&MOD(HOUR(([2]المدخلات!$B$4+6*[2]المدخلات!$B$5/1440+[2]المدخلات!$B$5/1440))-1,12)+1&":"&TEXT(MINUTE(([2]المدخلات!$B$4+6*[2]المدخلات!$B$5/1440+[2]المدخلات!$B$5/1440)),"00")&IF(HOUR(([2]المدخلات!$B$4+6*[2]المدخلات!$B$5/1440))<12," ص"," م") -> 5:30–5:45 م | C28: 1 ضد 5 | D28: 6 ضد 4 | E28: 2 ضد 3 | F28: 7 ضد 11 | G28: 12 ضد 10 | H28: 8 ضد 9 | M28: =_xlfn.TEXTJOIN(" ",TRUE,C28:H28) -> 1 ضد 5 6 ضد 4 2 ضد 3 7 ضد 11 12 ضد 10 8 ضد 9
B29: =MOD(HOUR(([2]المدخلات!$B$4+7*[2]المدخلات!$B$5/1440))-1,12)+1&":"&TEXT(MINUTE(([2]المدخلات!$B$4+7*[2]المدخلات!$B$5/1440)),"00")&"–"&MOD(HOUR(([2]المدخلات!$B$4+7*[2]المدخلات!$B$5/1440+[2]المدخلات!$B$5/1440))-1,12)+1&":"&TEXT(MINUTE(([2]المدخلات!$B$4+7*[2]المدخلات!$B$5/1440+[2]المدخلات!$B$5/1440)),"00")&IF(HOUR(([2]المدخلات!$B$4+7*[2]المدخلات!$B$5/1440))<12," ص"," م") -> 5:45–6:00 م | M29: =_xlfn.TEXTJOIN(" ",TRUE,C29:H29)
B30: =MOD(HOUR(([2]المدخلات!$B$4+8*[2]المدخلات!$B$5/1440))-1,12)+1&":"&TEXT(MINUTE(([2]المدخلات!$B$4+8*[2]المدخلات!$B$5/1440)),"00")&"–"&MOD(HOUR(([2]المدخلات!$B$4+8*[2]المدخلات!$B$5/1440+[2]المدخلات!$B$5/1440))-1,12)+1&":"&TEXT(MINUTE(([2]المدخلات!$B$4+8*[2]المدخلات!$B$5/1440+[2]المدخلات!$B$5/1440)),"00")&IF(HOUR(([2]المدخلات!$B$4+8*[2]المدخلات!$B$5/1440))<12," ص"," م") -> 6:00–6:15 م | M30: =_xlfn.TEXTJOIN(" ",TRUE,C30:H30)
A31: اليوم 4 | B31: =MOD(HOUR(([2]المدخلات!$B$4+0*[2]المدخلات!$B$5/1440))-1,12)+1&":"&TEXT(MINUTE(([2]المدخلات!$B$4+0*[2]المدخلات!$B$5/1440)),"00")&"–"&MOD(HOUR(([2]المدخلات!$B$4+0*[2]المدخلات!$B$5/1440+[2]المدخلات!$B$5/1440))-1,12)+1&":"&TEXT(MINUTE(([2]المدخلات!$B$4+0*[2]المدخلات!$B$5/1440+[2]المدخلات!$B$5/1440)),"00")&IF(HOUR(([2]المدخلات!$B$4+0*[2]المدخلات!$B$5/1440))<12," ص"," م") -> 4:00–4:15 م | C31: 1 ضد 4 | D31: 5 ضد 3 | E31: 6 ضد 2 | F31: 7 ضد 10 | G31: 11 ضد 9 | H31: 12 ضد 8 | I31: =COUNTIF(C31:H39,"* ضد *") -> 24 | J31: =COUNTIF(C31:E39,"* ضد *")*2/6 -> 4 | K31: =COUNTIF(F31:H39,"* ضد *")*2/6 -> 4 | M31: =_xlfn.TEXTJOIN(" ",TRUE,C31:H31) -> 1 ضد 4 5 ضد 3 6 ضد 2 7 ضد 10 11 ضد 9 12 ضد 8
B32: =MOD(HOUR(([2]المدخلات!$B$4+1*[2]المدخلات!$B$5/1440))-1,12)+1&":"&TEXT(MINUTE(([2]المدخلات!$B$4+1*[2]المدخلات!$B$5/1440)),"00")&"–"&MOD(HOUR(([2]المدخلات!$B$4+1*[2]المدخلات!$B$5/1440+[2]المدخلات!$B$5/1440))-1,12)+1&":"&TEXT(MINUTE(([2]المدخلات!$B$4+1*[2]المدخلات!$B$5/1440+[2]المدخلات!$B$5/1440)),"00")&IF(HOUR(([2]المدخلات!$B$4+1*[2]المدخلات!$B$5/1440))<12," ص"," م") -> 4:15–4:30 م | C32: استراحة (لا توجد مباريات) | F32: استراحة (لا توجد مباريات) | M32: =_xlfn.TEXTJOIN(" ",TRUE,C32:H32) -> استراحة (لا توجد مباريات) استراحة (لا توجد مباريات)
B33: =MOD(HOUR(([2]المدخلات!$B$4+2*[2]المدخلات!$B$5/1440))-1,12)+1&":"&TEXT(MINUTE(([2]المدخلات!$B$4+2*[2]المدخلات!$B$5/1440)),"00")&"–"&MOD(HOUR(([2]المدخلات!$B$4+2*[2]المدخلات!$B$5/1440+[2]المدخلات!$B$5/1440))-1,12)+1&":"&TEXT(MINUTE(([2]المدخلات!$B$4+2*[2]المدخلات!$B$5/1440+[2]المدخلات!$B$5/1440)),"00")&IF(HOUR(([2]المدخلات!$B$4+2*[2]المدخلات!$B$5/1440))<12," ص"," م") -> 4:30–4:45 م | C33: 5 ضد 6 | D33: 4 ضد 2 | E33: 1 ضد 3 | F33: 11 ضد 12 | G33: 10 ضد 8 | H33: 7 ضد 9 | M33: =_xlfn.TEXTJOIN(" ",TRUE,C33:H33) -> 5 ضد 6 4 ضد 2 1 ضد 3 11 ضد 12 10 ضد 8 7 ضد 9
B34: =MOD(HOUR(([2]المدخلات!$B$4+3*[2]المدخلات!$B$5/1440))-1,12)+1&":"&TEXT(MINUTE(([2]المدخلات!$B$4+3*[2]المدخلات!$B$5/1440)),"00")&"–"&MOD(HOUR(([2]المدخلات!$B$4+3*[2]المدخلات!$B$5/1440+[2]المدخلات!$B$5/1440))-1,12)+1&":"&TEXT(MINUTE(([2]المدخلات!$B$4+3*[2]المدخلات!$B$5/1440+[2]المدخلات!$B$5/1440)),"00")&IF(HOUR(([2]المدخلات!$B$4+3*[2]المدخلات!$B$5/1440))<12," ص"," م") -> 4:45–5:00 م | C34: استراحة (لا توجد مباريات) | F34: استراحة (لا توجد مباريات) | M34: =_xlfn.TEXTJOIN(" ",TRUE,C34:H34) -> استراحة (لا توجد مباريات) استراحة (لا توجد مباريات)
B35: =MOD(HOUR(([2]المدخلات!$B$4+4*[2]المدخلات!$B$5/1440))-1,12)+1&":"&TEXT(MINUTE(([2]المدخلات!$B$4+4*[2]المدخلات!$B$5/1440)),"00")&"–"&MOD(HOUR(([2]المدخلات!$B$4+4*[2]المدخلات!$B$5/1440+[2]المدخلات!$B$5/1440))-1,12)+1&":"&TEXT(MINUTE(([2]المدخلات!$B$4+4*[2]المدخلات!$B$5/1440+[2]المدخلات!$B$5/1440)),"00")&IF(HOUR(([2]المدخلات!$B$4+4*[2]المدخلات!$B$5/1440))<12," ص"," م") -> 5:00–5:15 م | C35: 3 ضد 6 | D35: 1 ضد 2 | E35: 4 ضد 5 | F35: 9 ضد 12 | G35: 7 ضد 8 | H35: 10 ضد 11 | M35: =_xlfn.TEXTJOIN(" ",TRUE,C35:H35) -> 3 ضد 6 1 ضد 2 4 ضد 5 9 ضد 12 7 ضد 8 10 ضد 11
B36: =MOD(HOUR(([2]المدخلات!$B$4+5*[2]المدخلات!$B$5/1440))-1,12)+1&":"&TEXT(MINUTE(([2]المدخلات!$B$4+5*[2]المدخلات!$B$5/1440)),"00")&"–"&MOD(HOUR(([2]المدخلات!$B$4+5*[2]المدخلات!$B$5/1440+[2]المدخلات!$B$5/1440))-1,12)+1&":"&TEXT(MINUTE(([2]المدخلات!$B$4+5*[2]المدخلات!$B$5/1440+[2]المدخلات!$B$5/1440)),"00")&IF(HOUR(([2]المدخلات!$B$4+5*[2]المدخلات!$B$5/1440))<12," ص"," م") -> 5:15–5:30 م | C36: استراحة (لا توجد مباريات) | F36: استراحة (لا توجد مباريات) | M36: =_xlfn.TEXTJOIN(" ",TRUE,C36:H36) -> استراحة (لا توجد مباريات) استراحة (لا توجد مباريات)
B37: =MOD(HOUR(([2]المدخلات!$B$4+6*[2]المدخلات!$B$5/1440))-1,12)+1&":"&TEXT(MINUTE(([2]المدخلات!$B$4+6*[2]المدخلات!$B$5/1440)),"00")&"–"&MOD(HOUR(([2]المدخلات!$B$4+6*[2]المدخلات!$B$5/1440+[2]المدخلات!$B$5/1440))-1,12)+1&":"&TEXT(MINUTE(([2]المدخلات!$B$4+6*[2]المدخلات!$B$5/1440+[2]المدخلات!$B$5/1440)),"00")&IF(HOUR(([2]المدخلات!$B$4+6*[2]المدخلات!$B$5/1440))<12," ص"," م") -> 5:30–5:45 م | C37: 2 ضد 5 | D37: 1 ضد 6 | E37: 3 ضد 4 | F37: 8 ضد 11 | G37: 7 ضد 12 | H37: 9 ضد 10 | M37: =_xlfn.TEXTJOIN(" ",TRUE,C37:H37) -> 2 ضد 5 1 ضد 6 3 ضد 4 8 ضد 11 7 ضد 12 9 ضد 10
B38: =MOD(HOUR(([2]المدخلات!$B$4+7*[2]المدخلات!$B$5/1440))-1,12)+1&":"&TEXT(MINUTE(([2]المدخلات!$B$4+7*[2]المدخلات!$B$5/1440)),"00")&"–"&MOD(HOUR(([2]المدخلات!$B$4+7*[2]المدخلات!$B$5/1440+[2]المدخلات!$B$5/1440))-1,12)+1&":"&TEXT(MINUTE(([2]المدخلات!$B$4+7*[2]المدخلات!$B$5/1440+[2]المدخلات!$B$5/1440)),"00")&IF(HOUR(([2]المدخلات!$B$4+7*[2]المدخلات!$B$5/1440))<12," ص"," م") -> 5:45–6:00 م | M38: =_xlfn.TEXTJOIN(" ",TRUE,C38:H38)
B39: =MOD(HOUR(([2]المدخلات!$B$4+8*[2]المدخلات!$B$5/1440))-1,12)+1&":"&TEXT(MINUTE(([2]المدخلات!$B$4+8*[2]المدخلات!$B$5/1440)),"00")&"–"&MOD(HOUR(([2]المدخلات!$B$4+8*[2]المدخلات!$B$5/1440+[2]المدخلات!$B$5/1440))-1,12)+1&":"&TEXT(MINUTE(([2]المدخلات!$B$4+8*[2]المدخلات!$B$5/1440+[2]المدخلات!$B$5/1440)),"00")&IF(HOUR(([2]المدخلات!$B$4+8*[2]المدخلات!$B$5/1440))<12," ص"," م") -> 6:00–6:15 م | M39: =_xlfn.TEXTJOIN(" ",TRUE,C39:H39)
A40: اليوم 5 | B40: =MOD(HOUR(([2]المدخلات!$B$4+0*[2]المدخلات!$B$5/1440))-1,12)+1&":"&TEXT(MINUTE(([2]المدخلات!$B$4+0*[2]المدخلات!$B$5/1440)),"00")&"–"&MOD(HOUR(([2]المدخلات!$B$4+0*[2]المدخلات!$B$5/1440+[2]المدخلات!$B$5/1440))-1,12)+1&":"&TEXT(MINUTE(([2]المدخلات!$B$4+0*[2]المدخلات!$B$5/1440+[2]المدخلات!$B$5/1440)),"00")&IF(HOUR(([2]المدخلات!$B$4+0*[2]المدخلات!$B$5/1440))<12," ص"," م") -> 4:00–4:15 م | C40: 2 ضد 3 | D40: 6 ضد 4 | E40: 1 ضد 5 | F40: 8 ضد 9 | G40: 12 ضد 10 | H40: 7 ضد 11 | I40: =COUNTIF(C40:H48,"* ضد *") -> 24 | J40: =COUNTIF(C40:E48,"* ضد *")*2/6 -> 4 | K40: =COUNTIF(F40:H48,"* ضد *")*2/6 -> 4 | M40: =_xlfn.TEXTJOIN(" ",TRUE,C40:H40) -> 2 ضد 3 6 ضد 4 1 ضد 5 8 ضد 9 12 ضد 10 7 ضد 11
B41: =MOD(HOUR(([2]المدخلات!$B$4+1*[2]المدخلات!$B$5/1440))-1,12)+1&":"&TEXT(MINUTE(([2]المدخلات!$B$4+1*[2]المدخلات!$B$5/1440)),"00")&"–"&MOD(HOUR(([2]المدخلات!$B$4+1*[2]المدخلات!$B$5/1440+[2]المدخلات!$B$5/1440))-1,12)+1&":"&TEXT(MINUTE(([2]المدخلات!$B$4+1*[2]المدخلات!$B$5/1440+[2]المدخلات!$B$5/1440)),"00")&IF(HOUR(([2]المدخلات!$B$4+1*[2]المدخلات!$B$5/1440))<12," ص"," م") -> 4:15–4:30 م | C41: استراحة (لا توجد مباريات) | F41: استراحة (لا توجد مباريات) | M41: =_xlfn.TEXTJOIN(" ",TRUE,C41:H41) -> استراحة (لا توجد مباريات) استراحة (لا توجد مباريات)
...

Sheet Sheet1
B2: تحت 14 | C2: مجموعة نجران | D2: 1 | E2: نجران | F2: 5
B3: تحت 5 | C3: مجموعة طبرجل | D3: 1 | E3: طبرجل | F3: 5
B4: تحت 7 | C4: مجموعة طبرجل | D4: 1 | E4: طبرجل | F4: 5
B5: تحت 9 | C5: مجموعة الخرج | D5: 1 | E5: الخرج | F5: 5
B6: تحت 12 | C6: مجموعة طبرجل | D6: 1 | E6: طبرجل | F6: 5
B7: تحت 14 | C7: مجموعة طبرجل | D7: 1 | E7: طبرجل | F7: 5
B8: تحت 7 | C8: مجموعة شرورة | D8: 1 | E8: شرورة | F8: 5
B9: تحت 9 | C9: مجموعة شرورة | D9: 1 | E9: شرورة | F9: 5
B10: تحت 9 | C10: مجموعة الدوادمي | D10: 1 | E10: الدوادمي | F10: 5
B11: تحت 11 | C11: مجموعة القريات | D11: 1 | E11: القريات | F11: 5
B12: تحت 12 | C12: مجموعة القريات | D12: 1 | E12: القريات | F12: 5
B13: تحت 13 | C13: مجموعة القريات | D13: 1 | E13: القريات | F13: 5
... B185: تحت 12 | C185: مجموعة جدة | D185: 1 | E185: جدة | F185: 56

Sheet المدخلات
A1: صفحة المدخلات – إعدادات جداول البطولات
A3: البند | B3: القيمة
A4: وقت بداية اليوم | B4: 0.66666667
A5: مدة المباراة (دقيقة) | B5: 15
A6: الفاصل بين المباريات (دقيقة) | B6: 0
A7: طول الفترة الكاملة (دقيقة) | B7: =B5+B6 -> 15
A8: عدد المهرجانات في الموسم | B8: 7
A9: ملاعب مصغّرة داخل الملعب القانوني | B9: 4
A10: عدد الحكام لكل ملعب مصغّر | B10: 1

Sheet المبادئ
A1: مبادئ تصميم جداول البطولات
A3: # | B3: المبدأ | C3: الشرح
A4: 1 | B4: عدد المباريات والأدوار | C4: كل مجموعة تلعب أدواراً كاملة: عدد الأدوار = صحيح(28 ÷ (عدد فرق المجموعة − 1))، ومباريات الفريق في الموسم = عدد الأدوار × (عدد فرق المجموعة − 1)، وتتراوح بين 22 و30 مباراة. يلعب كل فريق 4 مباريات في كل مهرجان، ما عدا المهرجان الأخير فيقل أو يزيد بالتساوي بين كل فرق المجموعة بما يكمل المجموع (مثلاً: 3 أو 2 أو 6 مباريات في الأخير). ولا يُشترط عدد مباريات أدنى؛ فالأولوية لاكتمال الأدوار وللتوزيع المعتمد في ورقة ملخص البطولات. وتُستثنى مجموعة الـ11 فريقاً: لإكمال ثلاثة أدوار (30 مباراة) تلعب 4 مباريات في 6 مهرجانات ثم 6 مباريات في المهرجان الأخير، فيطول ذلك اليوم وحده.
A5: 2 | B5: الراحة 15 أو 30 دقيقة | C5: يرتاح الفريق فترة أو فترتين بين مباراتين، أي راحة 15 أو 30 دقيقة فقط. لا يلعب أبداً في فترتين متتاليتين، ولا تزيد راحته على 30 دقيقة.
A6: 3 | B6: المجموعات ذات العدد الفردي | C6: في المجموعة الفردية يجلس فريق أو أكثر في كل فترة، والأصل ألا تتجاوز الراحة 30 دقيقة. وتُستخدم مجموعة من 5 فرق في بطولة الـ5 فرق وحدها؛ ولتفادي أي راحة تفوق 30 دقيقة يمتد يومها إلى 10 فترات (4:00–6:30 م) بمباراة واحدة في كل فترة على ملعب مصغّر واحد (أما 8 أو 9 فترات فلا تكفي). فلا توجد أي راحة تبلغ 45 أو 60 دقيقة في الملف.
A7: 4 | B7: توزيع المجموعات على الفترات | C7: لا تلعب كل المجموعات في كل فترة؛ تتوزّع المجموعات على الفترات بما يناسب عدد الملاعب، فتتشارك نفس الملاعب ويقصُر اليوم.
A8: 5 | B8: عدد الملاعب | C8: عدد الملاعب مُحدّد لكل بطولة (موضح في عنوان كل ورقة)، ويُبنى الجدول بحيث لا يتجاوز عدد مباريات الفترة عدد الملاعب.
A9: 6 | B9: عدالة تكرار الأزواج | C9: داخل المجموعة يلتقي كل زوج العدد نفسه من المرات بلا أي تفاوت (الفارق صفر)، لأن الجدول يُبنى من أدوار كاملة. ويظهر هذا العدد في عمود «لقاءات كل خصم (أدوار كاملة)» في ورقة ملخص البطولات، وفي جدول تكرار الأزواج أسفل كل ورقة. وقد يختلف العدد من مجموعة إلى أخرى داخل البطولة نفسها لاختلاف أحجام المجموعات.
A10: 7 | B10: تقسيم المجموعات | C10: يُعتمد توزيع الفرق المدوّن في عمود «توزيع الفرق في المجموعات» بورقة ملخص البطولات، وتُبنى الجداول عليه مباشرة، وتُفضّل المجموعات المتقاربة في الحجم. ولا تُستخدم مجموعة من 5 فرق إلا في بطولة الـ5 فرق نفسها (لا تدخل في تقسيم أي بطولة أكبر)، ولا من 3 أو 4 فرق لأنّها تفرض لقاء الخصم مرتين في اليوم نفسه. وكلما كبرت المجموعة قلّ عدد الأدوار ومعه عدد المباريات.
A11: 8 | B11: الأوقات | C11: كل الأوقات مشتقّة بصيغ من ورقة المدخلات: وقت البداية ومدة المباراة والفاصل بينها.
A12: 9 | B12: ترتيب مواجهة الخصوم | C12: لا يلتقي الفريق خصماً مرة ثانية قبل أن يلاعب جميع فرق مجموعته مرة، ولا يلتقي الفريقان مرتين في اليوم نفسه، ولا يلعب الفريق مباراتين في الفترة الزمنية نفسها.
A13: 10 | B13: عدالة توزيع الفترات | C13: تتغير فترات الفريق من يوم لآخر؛ فلا يبدأ فريق واحد أول اليوم دائماً ولا يتأخر آخره دائماً. ولا يستريح أي فريق مهرجاناً كاملاً داخل مهرجانات مجموعته؛ أما في البطولة متعددة المجموعات فالمجموعة التي تكمل أدوارها في 6 مهرجانات (مجموعتا الـ7 والـ9) تنتهي قبل المجموعات الأخرى ولا تلعب في المهرجان السابع.
A14: 11 | B14: عدم التنقل بين الملاعب القانونية | C14: الملاعب القانونية غير متجاورة، فلا يستطيع الفريق الانتقال من ملعب قانوني إلى آخر خلال اليوم نفسه. لذلك يُبنى الجدول بحيث تبقى كل مجموعة داخل ملعب قانوني واحد طوال المهرجان (بحد أقصى 4 ملاعب مصغّرة داخله). وإذا استُخدم أكثر من ملعب قانوني وجب أن تنقسم البطولة إلى مجموعات مستقلة تماماً، كل مجموعة في ملعبها، ولا تتقاطع مبارياتها.

Sheet ملخص البطولات
A1: ملخص البطولات – 23 بطولة من 5 إلى 49 فريقاً
A3: عدد الفرق | B3: عدد المجموعات | C3: توزيع الفرق في المجموعات | D3: عدد الأدوار | E3: مباريات كل فريق في الموسم | F3: عدد المهرجانات | G3: توزيع مباريات الفريق على المهرجانات | H3: وقت البداية | I3: وقت النهاية (أطول يوم) | J3: مدة اليوم (أطول يوم) | K3: عدد الملاعب (5 ضد 5) | L3: عدد الملاعب القانونية
A4: 5 | B4: 1 | C4: 5 | D4: 7 | E4: 28 | F4: 7 | G4: 4 مباريات في 7 مهرجانات (المجموع 28) | H4: 4:00 م | I4: 6:30 م | J4: =(10*المدخلات!$B$7)/1440 -> 0.10416667 | K4: 1 | L4: 1
A5: 6 | B5: 1 | C5: 6 | D5: 5 | E5: 25 | F5: 6 | G5: 4 مباريات في 5 مهرجانات، ثم 5 مباريات في المهرجان الأخير (المجموع 25) | H5: 4:00 م | I5: 6:15 م | J5: =(9*المدخلات!$B$7)/1440 -> 0.09375 | K5: 3 | L5: 1
A6: 7 | B6: 1 | C6: 7 | D6: 4 | E6: 24 | F6: 6 | G6: 4 مباريات في 6 مهرجانات (المجموع 24) | H6: 4:00 م | I6: 6:30 م | J6: =(10*المدخلات!$B$7)/1440 -> 0.10416667 | K6: 2 | L6: 1
A7: 8 | B7: 1 | C7: 8 | D7: 4 | E7: 28 | F7: 7 | G7: 4 مباريات في 7 مهرجانات (المجموع 28) | H7: 4:00 م | I7: 5:45 م | J7: =(7*المدخلات!$B$7)/1440 -> 0.072916667 | K7: 4 | L7: 1
A8: 9 | B8: 1 | C8: 9 | D8: 3 | E8: 24 | F8: 6 | G8: 4 مباريات في 6 مهرجانات (المجموع 24) | H8: 4:00 م | I8: 6:30 م | J8: =(10*المدخلات!$B$7)/1440 -> 0.10416667 | K8: 3 | L8: 1
A9: 10 | B9: 1 | C9: 10 | D9: 3 | E9: 27 | F9: 7 | G9: 4 مباريات في 6 مهرجانات، ثم 3 مباريات في المهرجان الأخير (المجموع 27) | H9: 4:00 م | I9: 6:15 م | J9: =(9*المدخلات!$B$7)/1440 -> 0.09375 | K9: 4 | L9: 1
A10: 11 | B10: 1 | C10: 11 | D10: 3 | E10: 30 | F10: 7 | G10: 4 مباريات في 6 مهرجانات، ثم 6 مباريات في المهرجان الأخير (المجموع 30) | H10: 4:00 م | I10: 7:30 م | J10: =(14*المدخلات!$B$7)/1440 -> 0.14583333 | K10: 4 | L10: 1
A11: 12 | B11: 1 | C11: 12 | D11: 2 | E11: 22 | F11: 6 | G11: 4 مباريات في 5 مهرجانات، ثم مباراتان في المهرجان الأخير (المجموع 22) | H11: 4:00 م | I11: 6:15 م | J11: =(9*المدخلات!$B$7)/1440 -> 0.09375 | K11: 4 | L11: 1
A12: 13 | B12: 1 | C12: 13 | D12: 2 | E12: 24 | F12: 6 | G12: 4 مباريات في 6 مهرجانات (المجموع 24) | H12: 4:00 م | I12: 6:15 م | J12: =(9*المدخلات!$B$7)/1440 -> 0.09375 | K12: 4 | L12: 1
A13: 14 | B13: 2 | C13: أ: 7 | ب: 7 | D13: 4 + 4 | E13: 24 + 24 | F13: 6 | G13: كل مجموعة: 4 مباريات في 6 مهرجانات (المجموع 24) | H13: 4:00 م | I13: 6:30 م | J13: =(10*المدخلات!$B$7)/1440 -> 0.10416667 | K13: 4 | L13: 2
A14: 15 | B14: 2 | C14: أ: 7 | ب: 8 | D14: 4 + 4 | E14: 24 + 28 | F14: 7 | G14: أ: 4 مباريات في 6 مهرجانات (المجموع 24) | ب: 4 مباريات في 7 مهرجانات (المجموع 28) | H14: 4:00 م | I14: 6:30 م | J14: =(10*المدخلات!$B$7)/1440 -> 0.10416667 | K14: 6 | L14: 2
A15: 16 | B15: 2 | C15: أ: 8 | ب: 8 | D15: 4 + 4 | E15: 28 + 28 | F15: 7 | G15: كل مجموعة: 4 مباريات في 7 مهرجانات (المجموع 28) | H15: 4:00 م | I15: 5:45 م | J15: =(7*المدخلات!$B$7)/1440 -> 0.072916667 | K15: 8 | L15: 2
A16: 17 | B16: 2 | C16: أ: 8 | ب: 9 | D16: 4 + 3 | E16: 28 + 24 | F16: 7 | G16: أ: 4 مباريات في 7 مهرجانات (المجموع 28) | ب: 4 مباريات في 6 مهرجانات (المجموع 24) | H16: 4:00 م | I16: 6:30 م | J16: =(10*المدخلات!$B$7)/1440 -> 0.10416667 | K16: 7 | L16: 2
A17: 18 | B17: 2 | C17: أ: 8 | ب: 10 | D17: 4 + 3 | E17: 28 + 27 | F17: 7 | G17: أ: 4 مباريات في 7 مهرجانات (المجموع 28) | ب: 4 مباريات في 6 مهرجانات، ثم 3 مباريات في المهرجان الأخير (المجموع 27) | H17: 4:00 م | I17: 6:15 م | J17: =(9*المدخلات!$B$7)/1440 -> 0.09375 | K17: 8 | L17: 2
A18: 19 | B18: 2 | C18: أ: 9 | ب: 10 | D18: 3 + 3 | E18: 24 + 27 | F18: 7 | G18: أ: 4 مباريات في 6 مهرجانات (المجموع 24) | ب: 4 مباريات في 6 مهرجانات، ثم 3 مباريات في المهرجان الأخير (المجموع 27) | H18: 4:00 م | I18: 6:30 م | J18: =(10*المدخلات!$B$7)/1440 -> 0.10416667 | K18: 7 | L18: 2
A19: 21 | B19: 2 | C19: أ: 10 | ب: 11 | D19: 3 + 3 | E19: 27 + 30 | F19: 7 | G19: أ: 4 مباريات في 6 مهرجانات، ثم 3 مباريات في المهرجان الأخير (المجموع 27) | ب: 4 مباريات في 6 مهرجانات، ثم 6 مباريات في المهرجان الأخير (المجموع 30) | H19: 4:00 م | I19: 7:30 م | J19: =(14*المدخلات!$B$7)/1440 -> 0.14583333 | K19: 8 | L19: 2
A20: 25 | B20: 3 | C20: أ: 8 | ب: 8 | ج: 9 | D20: 4 + 4 + 3 | E20: 28 + 28 + 24 | F20: 7 | G20: أ: 4 مباريات في 7 مهرجانات (المجموع 28) | ب: 4 مباريات في 7 مهرجانات (المجموع 28) | ج: 4 مباريات في 6 مهرجانات (المجموع 24) | H20: 4:00 م | I20: 6:30 م | J20: =(10*المدخلات!$B$7)/1440 -> 0.10416667 | K20: 11 | L20: 3
A21: 28 | B21: 3 | C21: أ: 9 | ب: 9 | ج: 10 | D21: 3 + 3 + 3 | E21: 24 + 24 + 27 | F21: 7 | G21: أ: 4 مباريات في 6 مهرجانات (المجموع 24) | ب: 4 مباريات في 6 مهرجانات (المجموع 24) | ج: 4 مباريات في 6 مهرجانات، ثم 3 مباريات في المهرجان الأخير (المجموع 27) | H21: 4:00 م | I21: 6:30 م | J21: =(10*المدخلات!$B$7)/1440 -> 0.10416667 | K21: 10 | L21: 3
A22: 29 | B22: 3 | C22: أ: 9 | ب: 10 | ج: 10 | D22: 3 + 3 + 3 | E22: 24 + 27 + 27 | F22: 7 | G22: أ: 4 مباريات في 6 مهرجانات (المجموع 24) | ب: 4 مباريات في 6 مهرجانات، ثم 3 مباريات في المهرجان الأخير (المجموع 27) | ج: 4 مباريات في 6 مهرجانات، ثم 3 مباريات في المهرجان الأخير (المجموع 27) | H22: 4:00 م | I22: 6:30 م | J22: =(10*المدخلات!$B$7)/1440 -> 0.10416667 | K22: 11 | L22: 3
A23: 30 | B23: 3 | C23: أ: 10 | ب: 10 | ج: 10 | D23: 3 + 3 + 3 | E23: 27 + 27 + 27 | F23: 7 | G23: كل مجموعة: 4 مباريات في 6 مهرجانات، ثم 3 مباريات في المهرجان الأخير (المجموع 27) | H23: 4:00 م | I23: 6:15 م | J23: =(9*المدخلات!$B$7)/1440 -> 0.09375 | K23: 12 | L23: 3
A24: 31 | B24: 3 | C24: أ: 10 | ب: 10 | ج: 11 | D24: 3 + 3 + 3 | E24: 27 + 27 + 30 | F24: 7 | G24: أ: 4 مباريات في 6 مهرجانات، ثم 3 مباريات في المهرجان الأخير (المجموع 27) | ب: 4 مباريات في 6 مهرجانات، ثم 3 مباريات في المهرجان الأخير (المجموع 27) | ج: 4 مباريات في 6 مهرجانات، ثم 6 مباريات في المهرجان الأخير (المجموع 30) | H24: 4:00 م | I24: 7:30 م | J24: =(14*المدخلات!$B$7)/1440 -> 0.14583333 | K24: 12 | L24: 3
A25: 40 | B25: 4 | C25: أ: 10 | ب: 10 | ج: 10 | د: 10 | D25: 3 + 3 + 3 + 3 | E25: 27 + 27 + 27 + 27 | F25: 7 | G25: كل مجموعة: 4 مباريات في 6 مهرجانات، ثم 3 مباريات في المهرجان الأخير (المجموع 27) | H25: 4:00 م | I25: 6:15 م | J25: =(9*المدخلات!$B$7)/1440 -> 0.09375 | K25: 16 | L25: 4
A26: 49 | B26: 4 | C26: أ: 12 | ب: 12 | ج: 12 | د: 13 | D26: 2 + 2 + 2 + 2 | E26: 22 + 22 + 22 + 24 | F26: 6 | G26: أ: 4 مباريات في 5 مهرجانات، ثم مباراتان في المهرجان الأخير (المجموع 22) | ب: 4 مباريات في 5 مهرجانات، ثم مباراتان في المهرجان الأخير (المجموع 22) | ج: 4 مباريات في 5 مهرجانات، ثم مباراتان في المهرجان الأخير (المجموع 22) | د: 4 مباريات في 6 مهرجانات (المجموع 24) | H26: 4:00 م | I26: 6:15 م | J26: =(9*المدخلات!$B$7)/1440 -> 0.09375 | K26: 16 | L26: 4
A29: توزيع فترات الراحة بين مباراتي الفريق في المهرجان الواحد
A30: عدد الفرق | B30: راحة 15 دقيقة | C30: راحة 30 دقيقة | D30: راحة 45 دقيقة | E30: إجمالي فترات الراحة | F30: نسبة الراحة القصيرة
A31: 5 | B31: 56 | C31: 49 | D31: 0 | E31: =B31+C31+D31 -> 105 | F31: =B31/E31 -> 0.53333333
A32: 6 | B32: 114 | C32: 0 | D32: 0 | E32: =B32+C32+D32 -> 114 | F32: =B32/E32 -> 1
A33: 7 | B33: 81 | C33: 45 | D33: 0 | E33: =B33+C33+D33 -> 126 | F33: =B33/E33 -> 0.64285714
A34: 8 | B34: 168 | C34: 0 | D34: 0 | E34: =B34+C34+D34 -> 168 | F34: =B34/E34 -> 1
A35: 9 | B35: 113 | C35: 49 | D35: 0 | E35: =B35+C35+D35 -> 162 | F35: =B35/E35 -> 0.69753086
A36: 10 | B36: 146 | C36: 54 | D36: 0 | E36: =B36+C36+D36 -> 200 | F36: =B36/E36 -> 0.73
A37: 11 | B37: 184 | C37: 69 | D37: 0 | E37: =B37+C37+D37 -> 253 | F37: =B37/E37 -> 0.72727273
A38: 12 | B38: 144 | C38: 48 | D38: 0 | E38: =B38+C38+D38 -> 192 | F38: =B38/E38 -> 0.75
A39: 13 | B39: 164 | C39: 70 | D39: 0 | E39: =B39+C39+D39 -> 234 | F39: =B39/E39 -> 0.7008547
A40: 14 | B40: 162 | C40: 90 | D40: 0 | E40: =B40+C40+D40 -> 252 | F40: =B40/E40 -> 0.64285714
A41: 15 | B41: 249 | C41: 45 | D41: 0 | E41: =B41+C41+D41 -> 294 | F41: =B41/E41 -> 0.84693878
A42: 16 | B42: 336 | C42: 0 | D42: 0 | E42: =B42+C42+D42 -> 336 | F42: =B42/E42 -> 1
... A53: 49 | B53: 596 | C53: 214 | D53: 0 | E53: =B53+C53+D53 -> 810 | F53: =B53/E53 -> 0.73580247
...

Sheet 5 فرق
A1: جدول مباريات بطولة 5 فرق — مجموعة واحدة داخل ملعب قانوني واحد (ملعب مصغّر واحد)
C2: الملعب القانوني 1 — المجموعة أ (الفرق 1–5)
A3: المهرجان | B3: الوقت | C3: ملعب 1 | D3: مجموع مباريات المهرجان
A4: المهرجان 1 | B4: =(MOD(HOUR(المدخلات!$B$4+(1-1)*المدخلات!$B$7/1440)-1,12)+1)&":"&TEXT(MINUTE(المدخلات!$B$4+(1-1)*المدخلات!$B$7/1440),"00")&"–"&(MOD(HOUR(المدخلات!$B$4+(1-1)*المدخلات!$B$7/1440+المدخلات!$B$5/1440)-1,12)+1)&":"&TEXT(MINUTE(المدخلات!$B$4+(1-1)*المدخلات!$B$7/1440+المدخلات!$B$5/1440),"00")&" م" -> 4:00–4:15 م | C4: 4 ضد 5 | D4: =COUNTA(C4:C13) -> 10
B5: =(MOD(HOUR(المدخلات!$B$4+(2-1)*المدخلات!$B$7/1440)-1,12)+1)&":"&TEXT(MINUTE(المدخلات!$B$4+(2-1)*المدخلات!$B$7/1440),"00")&"–"&(MOD(HOUR(المدخلات!$B$4+(2-1)*المدخلات!$B$7/1440+المدخلات!$B$5/1440)-1,12)+1)&":"&TEXT(MINUTE(المدخلات!$B$4+(2-1)*المدخلات!$B$7/1440+المدخلات!$B$5/1440),"00")&" م" -> 4:15–4:30 م | C5: 1 ضد 3
B6: =(MOD(HOUR(المدخلات!$B$4+(3-1)*المدخلات!$B$7/1440)-1,12)+1)&":"&TEXT(MINUTE(المدخلات!$B$4+(3-1)*المدخلات!$B$7/1440),"00")&"–"&(MOD(HOUR(المدخلات!$B$4+(3-1)*المدخلات!$B$7/1440+المدخلات!$B$5/1440)-1,12)+1)&":"&TEXT(MINUTE(المدخلات!$B$4+(3-1)*المدخلات!$B$7/1440+المدخلات!$B$5/1440),"00")&" م" -> 4:30–4:45 م | C6: 2 ضد 4
B7: =(MOD(HOUR(المدخلات!$B$4+(4-1)*المدخلات!$B$7/1440)-1,12)+1)&":"&TEXT(MINUTE(المدخلات!$B$4+(4-1)*المدخلات!$B$7/1440),"00")&"–"&(MOD(HOUR(المدخلات!$B$4+(4-1)*المدخلات!$B$7/1440+المدخلات!$B$5/1440)-1,12)+1)&":"&TEXT(MINUTE(المدخلات!$B$4+(4-1)*المدخلات!$B$7/1440+المدخلات!$B$5/1440),"00")&" م" -> 4:45–5:00 م | C7: 1 ضد 5
B8: =(MOD(HOUR(المدخلات!$B$4+(5-1)*المدخلات!$B$7/1440)-1,12)+1)&":"&TEXT(MINUTE(المدخلات!$B$4+(5-1)*المدخلات!$B$7/1440),"00")&"–"&(MOD(HOUR(المدخلات!$B$4+(5-1)*المدخلات!$B$7/1440+المدخلات!$B$5/1440)-1,12)+1)&":"&TEXT(MINUTE(المدخلات!$B$4+(5-1)*المدخلات!$B$7/1440+المدخلات!$B$5/1440),"00")&" م" -> 5:00–5:15 م | C8: 2 ضد 3
B9: =(MOD(HOUR(المدخلات!$B$4+(6-1)*المدخلات!$B$7/1440)-1,12)+1)&":"&TEXT(MINUTE(المدخلات!$B$4+(6-1)*المدخلات!$B$7/1440),"00")&"–"&(MOD(HOUR(المدخلات!$B$4+(6-1)*المدخلات!$B$7/1440+المدخلات!$B$5/1440)-1,12)+1)&":"&TEXT(MINUTE(المدخلات!$B$4+(6-1)*المدخلات!$B$7/1440+المدخلات!$B$5/1440),"00")&" م" -> 5:15–5:30 م | C9: 1 ضد 4
B10: =(MOD(HOUR(المدخلات!$B$4+(7-1)*المدخلات!$B$7/1440)-1,12)+1)&":"&TEXT(MINUTE(المدخلات!$B$4+(7-1)*المدخلات!$B$7/1440),"00")&"–"&(MOD(HOUR(المدخلات!$B$4+(7-1)*المدخلات!$B$7/1440+المدخلات!$B$5/1440)-1,12)+1)&":"&TEXT(MINUTE(المدخلات!$B$4+(7-1)*المدخلات!$B$7/1440+المدخلات!$B$5/1440),"00")&" م" -> 5:30–5:45 م | C10: 3 ضد 5
B11: =(MOD(HOUR(المدخلات!$B$4+(8-1)*المدخلات!$B$7/1440)-1,12)+1)&":"&TEXT(MINUTE(المدخلات!$B$4+(8-1)*المدخلات!$B$7/1440),"00")&"–"&(MOD(HOUR(المدخلات!$B$4+(8-1)*المدخلات!$B$7/1440+المدخلات!$B$5/1440)-1,12)+1)&":"&TEXT(MINUTE(المدخلات!$B$4+(8-1)*المدخلات!$B$7/1440+المدخلات!$B$5/1440),"00")&" م" -> 5:45–6:00 م | C11: 1 ضد 2
B12: =(MOD(HOUR(المدخلات!$B$4+(9-1)*المدخلات!$B$7/1440)-1,12)+1)&":"&TEXT(MINUTE(المدخلات!$B$4+(9-1)*المدخلات!$B$7/1440),"00")&"–"&(MOD(HOUR(المدخلات!$B$4+(9-1)*المدخلات!$B$7/1440+المدخلات!$B$5/1440)-1,12)+1)&":"&TEXT(MINUTE(المدخلات!$B$4+(9-1)*المدخلات!$B$7/1440+المدخلات!$B$5/1440),"00")&" م" -> 6:00–6:15 م | C12: 3 ضد 4
B13: =(MOD(HOUR(المدخلات!$B$4+(10-1)*المدخلات!$B$7/1440)-1,12)+1)&":"&TEXT(MINUTE(المدخلات!$B$4+(10-1)*المدخلات!$B$7/1440),"00")&"–"&(MOD(HOUR(المدخلات!$B$4+(10-1)*المدخلات!$B$7/1440+المدخلات!$B$5/1440)-1,12)+1)&":"&TEXT(MINUTE(المدخلات!$B$4+(10-1)*المدخلات!$B$7/1440+المدخلات!$B$5/1440),"00")&" م" -> 6:15–6:30 م | C13: 2 ضد 5
A14: المهرجان 2 | B14: =(MOD(HOUR(المدخلات!$B$4+(1-1)*المدخلات!$B$7/1440)-1,12)+1)&":"&TEXT(MINUTE(المدخلات!$B$4+(1-1)*المدخلات!$B$7/1440),"00")&"–"&(MOD(HOUR(المدخلات!$B$4+(1-1)*المدخلات!$B$7/1440+المدخلات!$B$5/1440)-1,12)+1)&":"&TEXT(MINUTE(المدخلات!$B$4+(1-1)*المدخلات!$B$7/1440+المدخلات!$B$5/1440),"00")&" م" -> 4:00–4:15 م | C14: 1 ضد 2 | D14: =COUNTA(C14:C23) -> 10
B15: =(MOD(HOUR(المدخلات!$B$4+(2-1)*المدخلات!$B$7/1440)-1,12)+1)&":"&TEXT(MINUTE(المدخلات!$B$4+(2-1)*المدخلات!$B$7/1440),"00")&"–"&(MOD(HOUR(المدخلات!$B$4+(2-1)*المدخلات!$B$7/1440+المدخلات!$B$5/1440)-1,12)+1)&":"&TEXT(MINUTE(المدخلات!$B$4+(2-1)*المدخلات!$B$7/1440+المدخلات!$B$5/1440),"00")&" م" -> 4:15–4:30 م | C15: 4 ضد 5
B16: =(MOD(HOUR(المدخلات!$B$4+(3-1)*المدخلات!$B$7/1440)-1,12)+1)&":"&TEXT(MINUTE(المدخلات!$B$4+(3-1)*المدخلات!$B$7/1440),"00")&"–"&(MOD(HOUR(المدخلات!$B$4+(3-1)*المدخلات!$B$7/1440+المدخلات!$B$5/1440)-1,12)+1)&":"&TEXT(MINUTE(المدخلات!$B$4+(3-1)*المدخلات!$B$7/1440+المدخلات!$B$5/1440),"00")&" م" -> 4:30–4:45 م | C16: 2 ضد 3
B17: =(MOD(HOUR(المدخلات!$B$4+(4-1)*المدخلات!$B$7/1440)-1,12)+1)&":"&TEXT(MINUTE(المدخلات!$B$4+(4-1)*المدخلات!$B$7/1440),"00")&"–"&(MOD(HOUR(المدخلات!$B$4+(4-1)*المدخلات!$B$7/1440+المدخلات!$B$5/1440)-1,12)+1)&":"&TEXT(MINUTE(المدخلات!$B$4+(4-1)*المدخلات!$B$7/1440+المدخلات!$B$5/1440),"00")&" م" -> 4:45–5:00 م | C17: 1 ضد 5
B18: =(MOD(HOUR(المدخلات!$B$4+(5-1)*المدخلات!$B$7/1440)-1,12)+1)&":"&TEXT(MINUTE(المدخلات!$B$4+(5-1)*المدخلات!$B$7/1440),"00")&"–"&(MOD(HOUR(المدخلات!$B$4+(5-1)*المدخلات!$B$7/1440+المدخلات!$B$5/1440)-1,12)+1)&":"&TEXT(MINUTE(المدخلات!$B$4+(5-1)*المدخلات!$B$7/1440+المدخلات!$B$5/1440),"00")&" م" -> 5:00–5:15 م | C18: 3 ضد 4
B19: =(MOD(HOUR(المدخلات!$B$4+(6-1)*المدخلات!$B$7/1440)-1,12)+1)&":"&TEXT(MINUTE(المدخلات!$B$4+(6-1)*المدخلات!$B$7/1440),"00")&"–"&(MOD(HOUR(المدخلات!$B$4+(6-1)*المدخلات!$B$7/1440+المدخلات!$B$5/1440)-1,12)+1)&":"&TEXT(MINUTE(المدخلات!$B$4+(6-1)*المدخلات!$B$7/1440+المدخلات!$B$5/1440),"00")&" م" -> 5:15–5:30 م | C19: 2 ضد 5
B20: =(MOD(HOUR(المدخلات!$B$4+(7-1)*المدخلات!$B$7/1440)-1,12)+1)&":"&TEXT(MINUTE(المدخلات!$B$4+(7-1)*المدخلات!$B$7/1440),"00")&"–"&(MOD(HOUR(المدخلات!$B$4+(7-1)*المدخلات!$B$7/1440+المدخلات!$B$5/1440)-1,12)+1)&":"&TEXT(MINUTE(المدخلات!$B$4+(7-1)*المدخلات!$B$7/1440+المدخلات!$B$5/1440),"00")&" م" -> 5:30–5:45 م | C20: 1 ضد 3
B21: =(MOD(HOUR(المدخلات!$B$4+(8-1)*المدخلات!$B$7/1440)-1,12)+1)&":"&TEXT(MINUTE(المدخلات!$B$4+(8-1)*المدخلات!$B$7/1440),"00")&"–"&(MOD(HOUR(المدخلات!$B$4+(8-1)*المدخلات!$B$7/1440+المدخلات!$B$5/1440)-1,12)+1)&":"&TEXT(MINUTE(المدخلات!$B$4+(8-1)*المدخلات!$B$7/1440+المدخلات!$B$5/1440),"00")&" م" -> 5:45–6:00 م | C21: 2 ضد 4
B22: =(MOD(HOUR(المدخلات!$B$4+(9-1)*المدخلات!$B$7/1440)-1,12)+1)&":"&TEXT(MINUTE(المدخلات!$B$4+(9-1)*المدخلات!$B$7/1440),"00")&"–"&(MOD(HOUR(المدخلات!$B$4+(9-1)*المدخلات!$B$7/1440+المدخلات!$B$5/1440)-1,12)+1)&":"&TEXT(MINUTE(المدخلات!$B$4+(9-1)*المدخلات!$B$7/1440+المدخلات!$B$5/1440),"00")&" م" -> 6:00–6:15 م | C22: 3 ضد 5
B23: =(MOD(HOUR(المدخلات!$B$4+(10-1)*المدخلات!$B$7/1440)-1,12)+1)&":"&TEXT(MINUTE(المدخلات!$B$4+(10-1)*المدخلات!$B$7/1440),"00")&"–"&(MOD(HOUR(المدخلات!$B$4+(10-1)*المدخلات!$B$7/1440+المدخلات!$B$5/1440)-1,12)+1)&":"&TEXT(MINUTE(المدخلات!$B$4+(10-1)*المدخلات!$B$7/1440+المدخلات!$B$5/1440),"00")&" م" -> 6:15–6:30 م | C23: 1 ضد 4
A24: المهرجان 3 | B24: =(MOD(HOUR(المدخلات!$B$4+(1-1)*المدخلات!$B$7/1440)-1,12)+1)&":"&TEXT(MINUTE(المدخلات!$B$4+(1-1)*المدخلات!$B$7/1440),"00")&"–"&(MOD(HOUR(المدخلات!$B$4+(1-1)*المدخلات!$B$7/1440+المدخلات!$B$5/1440)-1,12)+1)&":"&TEXT(MINUTE(المدخلات!$B$4+(1-1)*المدخلات!$B$7/1440+المدخلات!$B$5/1440),"00")&" م" -> 4:00–4:15 م | C24: 3 ضد 4 | D24: =COUNTA(C24:C33) -> 10
B25: =(MOD(HOUR(المدخلات!$B$4+(2-1)*المدخلات!$B$7/1440)-1,12)+1)&":"&TEXT(MINUTE(المدخلات!$B$4+(2-1)*المدخلات!$B$7/1440),"00")&"–"&(MOD(HOUR(المدخلات!$B$4+(2-1)*المدخلات!$B$7/1440+المدخلات!$B$5/1440)-1,12)+1)&":"&TEXT(MINUTE(المدخلات!$B$4+(2-1)*المدخلات!$B$7/1440+المدخلات!$B$5/1440),"00")&" م" -> 4:15–4:30 م | C25: 2 ضد 5
B26: =(MOD(HOUR(المدخلات!$B$4+(3-1)*المدخلات!$B$7/1440)-1,12)+1)&":"&TEXT(MINUTE(المدخلات!$B$4+(3-1)*المدخلات!$B$7/1440),"00")&"–"&(MOD(HOUR(المدخلات!$B$4+(3-1)*المدخلات!$B$7/1440+المدخلات!$B$5/1440)-1,12)+1)&":"&TEXT(MINUTE(المدخلات!$B$4+(3-1)*المدخلات!$B$7/1440+المدخلات!$B$5/1440),"00")&" م" -> 4:30–4:45 م | C26: 1 ضد 3
B27: =(MOD(HOUR(المدخلات!$B$4+(4-1)*المدخلات!$B$7/1440)-1,12)+1)&":"&TEXT(MINUTE(المدخلات!$B$4+(4-1)*المدخلات!$B$7/1440),"00")&"–"&(MOD(HOUR(المدخلات!$B$4+(4-1)*المدخلات!$B$7/1440+المدخلات!$B$5/1440)-1,12)+1)&":"&TEXT(MINUTE(المدخلات!$B$4+(4-1)*المدخلات!$B$7/1440+المدخلات!$B$5/1440),"00")&" م" -> 4:45–5:00 م | C27: 4 ضد 5
B28: =(MOD(HOUR(المدخلات!$B$4+(5-1)*المدخلات!$B$7/1440)-1,12)+1)&":"&TEXT(MINUTE(المدخلات!$B$4+(5-1)*المدخلات!$B$7/1440),"00")&"–"&(MOD(HOUR(المدخلات!$B$4+(5-1)*المدخلات!$B$7/1440+المدخلات!$B$5/1440)-1,12)+1)&":"&TEXT(MINUTE(المدخلات!$B$4+(5-1)*المدخلات!$B$7/1440+المدخلات!$B$5/1440),"00")&" م" -> 5:00–5:15 م | C28: 1 ضد 2
B29: =(MOD(HOUR(المدخلات!$B$4+(6-1)*المدخلات!$B$7/1440)-1,12)+1)&":"&TEXT(MINUTE(المدخلات!$B$4+(6-1)*المدخلات!$B$7/1440),"00")&"–"&(MOD(HOUR(المدخلات!$B$4+(6-1)*المدخلات!$B$7/1440+المدخلات!$B$5/1440)-1,12)+1)&":"&TEXT(MINUTE(المدخلات!$B$4+(6-1)*المدخلات!$B$7/1440+المدخلات!$B$5/1440),"00")&" م" -> 5:15–5:30 م | C29: 3 ضد 5
B30: =(MOD(HOUR(المدخلات!$B$4+(7-1)*المدخلات!$B$7/1440)-1,12)+1)&":"&TEXT(MINUTE(المدخلات!$B$4+(7-1)*المدخلات!$B$7/1440),"00")&"–"&(MOD(HOUR(المدخلات!$B$4+(7-1)*المدخلات!$B$7/1440+المدخلات!$B$5/1440)-1,12)+1)&":"&TEXT(MINUTE(المدخلات!$B$4+(7-1)*المدخلات!$B$7/1440+المدخلات!$B$5/1440),"00")&" م" -> 5:30–5:45 م | C30: 2 ضد 4
B31: =(MOD(HOUR(المدخلات!$B$4+(8-1)*المدخلات!$B$7/1440)-1,12)+1)&":"&TEXT(MINUTE(المدخلات!$B$4+(8-1)*المدخلات!$B$7/1440),"00")&"–"&(MOD(HOUR(المدخلات!$B$4+(8-1)*المدخلات!$B$7/1440+المدخلات!$B$5/1440)-1,12)+1)&":"&TEXT(MINUTE(المدخلات!$B$4+(8-1)*المدخلات!$B$7/1440+المدخلات!$B$5/1440),"00")&" م" -> 5:45–6:00 م | C31: 1 ضد 5
B32: =(MOD(HOUR(المدخلات!$B$4+(9-1)*المدخلات!$B$7/1440)-1,12)+1)&":"&TEXT(MINUTE(المدخلات!$B$4+(9-1)*المدخلات!$B$7/1440),"00")&"–"&(MOD(HOUR(المدخلات!$B$4+(9-1)*المدخلات!$B$7/1440+المدخلات!$B$5/1440)-1,12)+1)&":"&TEXT(MINUTE(المدخلات!$B$4+(9-1)*المدخلات!$B$7/1440+المدخلات!$B$5/1440),"00")&" م" -> 6:00–6:15 م | C32: 2 ضد 3
B33: =(MOD(HOUR(المدخلات!$B$4+(10-1)*المدخلات!$B$7/1440)-1,12)+1)&":"&TEXT(MINUTE(المدخلات!$B$4+(10-1)*المدخلات!$B$7/1440),"00")&"–"&(MOD(HOUR(المدخلات!$B$4+(10-1)*المدخلات!$B$7/1440+المدخلات!$B$5/1440)-1,12)+1)&":"&TEXT(MINUTE(المدخلات!$B$4+(10-1)*المدخلات!$B$7/1440+المدخلات!$B$5/1440),"00")&" م" -> 6:15–6:30 م | C33: 1 ضد 4
A34: المهرجان 4 | B34: =(MOD(HOUR(المدخلات!$B$4+(1-1)*المدخلات!$B$7/1440)-1,12)+1)&":"&TEXT(MINUTE(المدخلات!$B$4+(1-1)*المدخلات!$B$7/1440),"00")&"–"&(MOD(HOUR(المدخلات!$B$4+(1-1)*المدخلات!$B$7/1440+المدخلات!$B$5/1440)-1,12)+1)&":"&TEXT(MINUTE(المدخلات!$B$4+(1-1)*المدخلات!$B$7/1440+المدخلات!$B$5/1440),"00")&" م" -> 4:00–4:15 م | C34: 1 ضد 5 | D34: =COUNTA(C34:C43) -> 10
B35: =(MOD(HOUR(المدخلات!$B$4+(2-1)*المدخلات!$B$7/1440)-1,12)+1)&":"&TEXT(MINUTE(المدخلات!$B$4+(2-1)*المدخلات!$B$7/1440),"00")&"–"&(MOD(HOUR(المدخلات!$B$4+(2-1)*المدخلات!$B$7/1440+المدخلات!$B$5/1440)-1,12)+1)&":"&TEXT(MINUTE(المدخلات!$B$4+(2-1)*المدخلات!$B$7/1440+المدخلات!$B$5/1440),"00")&" م" -> 4:15–4:30 م | C35: 2 ضد 3
B36: =(MOD(HOUR(المدخلات!$B$4+(3-1)*المدخلات!$B$7/1440)-1,12)+1)&":"&TEXT(MINUTE(المدخلات!$B$4+(3-1)*المدخلات!$B$7/1440),"00")&"–"&(MOD(HOUR(المدخلات!$B$4+(3-1)*المدخلات!$B$7/1440+المدخلات!$B$5/1440)-1,12)+1)&":"&TEXT(MINUTE(المدخلات!$B$4+(3-1)*المدخلات!$B$7/1440+المدخلات!$B$5/1440),"00")&" م" -> 4:30–4:45 م | C36: 1 ضد 4
B37: =(MOD(HOUR(المدخلات!$B$4+(4-1)*المدخلات!$B$7/1440)-1,12)+1)&":"&TEXT(MINUTE(المدخلات!$B$4+(4-1)*المدخلات!$B$7/1440),"00")&"–"&(MOD(HOUR(المدخلات!$B$4+(4-1)*المدخلات!$B$7/1440+المدخلات!$B$5/1440)-1,12)+1)&":"&TEXT(MINUTE(المدخلات!$B$4+(4-1)*المدخلات!$B$7/1440+المدخلات!$B$5/1440),"00")&" م" -> 4:45–5:00 م | C37: 2 ضد 5
B38: =(MOD(HOUR(المدخلات!$B$4+(5-1)*المدخلات!$B$7/1440)-1,12)+1)&":"&TEXT(MINUTE(المدخلات!$B$4+(5-1)*المدخلات!$B$7/1440),"00")&"–"&(MOD(HOUR(المدخلات!$B$4+(5-1)*المدخلات!$B$7/1440+المدخلات!$B$5/1440)-1,12)+1)&":"&TEXT(MINUTE(المدخلات!$B$4+(5-1)*المدخلات!$B$7/1440+المدخلات!$B$5/1440),"00")&" م" -> 5:00–5:15 م | C38: 3 ضد 4
B39: =(MOD(HOUR(المدخلات!$B$4+(6-1)*المدخلات!$B$7/1440)-1,12)+1)&":"&TEXT(MINUTE(المدخلات!$B$4+(6-1)*المدخلات!$B$7/1440),"00")&"–"&(MOD(HOUR(المدخلات!$B$4+(6-1)*المدخلات!$B$7/1440+المدخلات!$B$5/1440)-1,12)+1)&":"&TEXT(MINUTE(المدخلات!$B$4+(6-1)*المدخلات!$B$7/1440+المدخلات!$B$5/1440),"00")&" م" -> 5:15–5:30 م | C39: 1 ضد 2
B40: =(MOD(HOUR(المدخلات!$B$4+(7-1)*المدخلات!$B$7/1440)-1,12)+1)&":"&TEXT(MINUTE(المدخلات!$B$4+(7-1)*المدخلات!$B$7/1440),"00")&"–"&(MOD(HOUR(المدخلات!$B$4+(7-1)*المدخلات!$B$7/1440+المدخلات!$B$5/1440)-1,12)+1)&":"&TEXT(MINUTE(المدخلات!$B$4+(7-1)*المدخلات!$B$7/1440+المدخلات!$B$5/1440),"00")&" م" -> 5:30–5:45 م | C40: 4 ضد 5
...

Sheet 6 فرق
A1: جدول مباريات بطولة 6 فرق — مجموعة واحدة داخل ملعب قانوني واحد (3 ملاعب مصغّرة)
C2: الملعب القانوني 1 — المجموعة أ (الفرق 1–6)
A3: المهرجان | B3: الوقت | C3: ملعب 1 | D3: ملعب 2 | E3: ملعب 3 | F3: مجموع مباريات المهرجان
A4: المهرجان 1 | B4: =(MOD(HOUR(المدخلات!$B$4+(1-1)*المدخلات!$B$7/1440)-1,12)+1)&":"&TEXT(MINUTE(المدخلات!$B$4+(1-1)*المدخلات!$B$7/1440),"00")&"–"&(MOD(HOUR(المدخلات!$B$4+(1-1)*المدخلات!$B$7/1440+المدخلات!$B$5/1440)-1,12)+1)&":"&TEXT(MINUTE(المدخلات!$B$4+(1-1)*المدخلات!$B$7/1440+المدخلات!$B$5/1440),"00")&" م" -> 4:00–4:15 م | C4: 4 ضد 5 | D4: 1 ضد 2 | E4: 3 ضد 6 | F4: =COUNTA(C4:E10) -> 12
B5: =(MOD(HOUR(المدخلات!$B$4+(2-1)*المدخلات!$B$7/1440)-1,12)+1)&":"&TEXT(MINUTE(المدخلات!$B$4+(2-1)*المدخلات!$B$7/1440),"00")&"–"&(MOD(HOUR(المدخلات!$B$4+(2-1)*المدخلات!$B$7/1440+المدخلات!$B$5/1440)-1,12)+1)&":"&TEXT(MINUTE(المدخلات!$B$4+(2-1)*المدخلات!$B$7/1440+المدخلات!$B$5/1440),"00")&" م" -> 4:15–4:30 م
B6: =(MOD(HOUR(المدخلات!$B$4+(3-1)*المدخلات!$B$7/1440)-1,12)+1)&":"&TEXT(MINUTE(المدخلات!$B$4+(3-1)*المدخلات!$B$7/1440),"00")&"–"&(MOD(HOUR(المدخلات!$B$4+(3-1)*المدخلات!$B$7/1440+المدخلات!$B$5/1440)-1,12)+1)&":"&TEXT(MINUTE(المدخلات!$B$4+(3-1)*المدخلات!$B$7/1440+المدخلات!$B$5/1440),"00")&" م" -> 4:30–4:45 م | C6: 2 ضد 5 | D6: 1 ضد 6 | E6: 3 ضد 4
B7: =(MOD(HOUR(المدخلات!$B$4+(4-1)*المدخلات!$B$7/1440)-1,12)+1)&":"&TEXT(MINUTE(المدخلات!$B$4+(4-1)*المدخلات!$B$7/1440),"00")&"–"&(MOD(HOUR(المدخلات!$B$4+(4-1)*المدخلات!$B$7/1440+المدخلات!$B$5/1440)-1,12)+1)&":"&TEXT(MINUTE(المدخلات!$B$4+(4-1)*المدخلات!$B$7/1440+المدخلات!$B$5/1440),"00")&" م" -> 4:45–5:00 م
B8: =(MOD(HOUR(المدخلات!$B$4+(5-1)*المدخلات!$B$7/1440)-1,12)+1)&":"&TEXT(MINUTE(المدخلات!$B$4+(5-1)*المدخلات!$B$7/1440),"00")&"–"&(MOD(HOUR(المدخلات!$B$4+(5-1)*المدخلات!$B$7/1440+المدخلات!$B$5/1440)-1,12)+1)&":"&TEXT(MINUTE(المدخلات!$B$4+(5-1)*المدخلات!$B$7/1440+المدخلات!$B$5/1440),"00")&" م" -> 5:00–5:15 م | C8: 4 ضد 6 | D8: 2 ضد 3 | E8: 1 ضد 5
B9: =(MOD(HOUR(المدخلات!$B$4+(6-1)*المدخلات!$B$7/1440)-1,12)+1)&":"&TEXT(MINUTE(المدخلات!$B$4+(6-1)*المدخلات!$B$7/1440),"00")&"–"&(MOD(HOUR(المدخلات!$B$4+(6-1)*المدخلات!$B$7/1440+المدخلات!$B$5/1440)-1,12)+1)&":"&TEXT(MINUTE(المدخلات!$B$4+(6-1)*المدخلات!$B$7/1440+المدخلات!$B$5/1440),"00")&" م" -> 5:15–5:30 م
B10: =(MOD(HOUR(المدخلات!$B$4+(7-1)*المدخلات!$B$7/1440)-1,12)+1)&":"&TEXT(MINUTE(المدخلات!$B$4+(7-1)*المدخلات!$B$7/1440),"00")&"–"&(MOD(HOUR(المدخلات!$B$4+(7-1)*المدخلات!$B$7/1440+المدخلات!$B$5/1440)-1,12)+1)&":"&TEXT(MINUTE(المدخلات!$B$4+(7-1)*المدخلات!$B$7/1440+المدخلات!$B$5/1440),"00")&" م" -> 5:30–5:45 م | C10: 2 ضد 6 | D10: 3 ضد 5 | E10: 1 ضد 4
A11: المهرجان 2 | B11: =(MOD(HOUR(المدخلات!$B$4+(1-1)*المدخلات!$B$7/1440)-1,12)+1)&":"&TEXT(MINUTE(المدخلات!$B$4+(1-1)*المدخلات!$B$7/1440),"00")&"–"&(MOD(HOUR(المدخلات!$B$4+(1-1)*المدخلات!$B$7/1440+المدخلات!$B$5/1440)-1,12)+1)&":"&TEXT(MINUTE(المدخلات!$B$4+(1-1)*المدخلات!$B$7/1440+المدخلات!$B$5/1440),"00")&" م" -> 4:00–4:15 م | C11: 2 ضد 4 | D11: 1 ضد 3 | E11: 5 ضد 6 | F11: =COUNTA(C11:E17) -> 12
B12: =(MOD(HOUR(المدخلات!$B$4+(2-1)*المدخلات!$B$7/1440)-1,12)+1)&":"&TEXT(MINUTE(المدخلات!$B$4+(2-1)*المدخلات!$B$7/1440),"00")&"–"&(MOD(HOUR(المدخلات!$B$4+(2-1)*المدخلات!$B$7/1440+المدخلات!$B$5/1440)-1,12)+1)&":"&TEXT(MINUTE(المدخلات!$B$4+(2-1)*المدخلات!$B$7/1440+المدخلات!$B$5/1440),"00")&" م" -> 4:15–4:30 م
B13: =(MOD(HOUR(المدخلات!$B$4+(3-1)*المدخلات!$B$7/1440)-1,12)+1)&":"&TEXT(MINUTE(المدخلات!$B$4+(3-1)*المدخلات!$B$7/1440),"00")&"–"&(MOD(HOUR(المدخلات!$B$4+(3-1)*المدخلات!$B$7/1440+المدخلات!$B$5/1440)-1,12)+1)&":"&TEXT(MINUTE(المدخلات!$B$4+(3-1)*المدخلات!$B$7/1440+المدخلات!$B$5/1440),"00")&" م" -> 4:30–4:45 م | C13: 3 ضد 6 | D13: 4 ضد 5 | E13: 1 ضد 2
B14: =(MOD(HOUR(المدخلات!$B$4+(4-1)*المدخلات!$B$7/1440)-1,12)+1)&":"&TEXT(MINUTE(المدخلات!$B$4+(4-1)*المدخلات!$B$7/1440),"00")&"–"&(MOD(HOUR(المدخلات!$B$4+(4-1)*المدخلات!$B$7/1440+المدخلات!$B$5/1440)-1,12)+1)&":"&TEXT(MINUTE(المدخلات!$B$4+(4-1)*المدخلات!$B$7/1440+المدخلات!$B$5/1440),"00")&" م" -> 4:45–5:00 م
B15: =(MOD(HOUR(المدخلات!$B$4+(5-1)*المدخلات!$B$7/1440)-1,12)+1)&":"&TEXT(MINUTE(المدخلات!$B$4+(5-1)*المدخلات!$B$7/1440),"00")&"–"&(MOD(HOUR(المدخلات!$B$4+(5-1)*المدخلات!$B$7/1440+المدخلات!$B$5/1440)-1,12)+1)&":"&TEXT(MINUTE(المدخلات!$B$4+(5-1)*المدخلات!$B$7/1440+المدخلات!$B$5/1440),"00")&" م" -> 5:00–5:15 م | C15: 2 ضد 5 | D15: 1 ضد 6 | E15: 3 ضد 4
B16: =(MOD(HOUR(المدخلات!$B$4+(6-1)*المدخلات!$B$7/1440)-1,12)+1)&":"&TEXT(MINUTE(المدخلات!$B$4+(6-1)*المدخلات!$B$7/1440),"00")&"–"&(MOD(HOUR(المدخلات!$B$4+(6-1)*المدخلات!$B$7/1440+المدخلات!$B$5/1440)-1,12)+1)&":"&TEXT(MINUTE(المدخلات!$B$4+(6-1)*المدخلات!$B$7/1440+المدخلات!$B$5/1440),"00")&" م" -> 5:15–5:30 م
B17: =(MOD(HOUR(المدخلات!$B$4+(7-1)*المدخلات!$B$7/1440)-1,12)+1)&":"&TEXT(MINUTE(المدخلات!$B$4+(7-1)*المدخلات!$B$7/1440),"00")&"–"&(MOD(HOUR(المدخلات!$B$4+(7-1)*المدخلات!$B$7/1440+المدخلات!$B$5/1440)-1,12)+1)&":"&TEXT(MINUTE(المدخلات!$B$4+(7-1)*المدخلات!$B$7/1440+المدخلات!$B$5/1440),"00")&" م" -> 5:30–5:45 م | C17: 4 ضد 6 | D17: 1 ضد 5 | E17: 2 ضد 3
A18: المهرجان 3 | B18: =(MOD(HOUR(المدخلات!$B$4+(1-1)*المدخلات!$B$7/1440)-1,12)+1)&":"&TEXT(MINUTE(المدخلات!$B$4+(1-1)*المدخلات!$B$7/1440),"00")&"–"&(MOD(HOUR(المدخلات!$B$4+(1-1)*المدخلات!$B$7/1440+المدخلات!$B$5/1440)-1,12)+1)&":"&TEXT(MINUTE(المدخلات!$B$4+(1-1)*المدخلات!$B$7/1440+المدخلات!$B$5/1440),"00")&" م" -> 4:00–4:15 م | C18: 3 ضد 5 | D18: 1 ضد 4 | E18: 2 ضد 6 | F18: =COUNTA(C18:E24) -> 12
B19: =(MOD(HOUR(المدخلات!$B$4+(2-1)*المدخلات!$B$7/1440)-1,12)+1)&":"&TEXT(MINUTE(المدخلات!$B$4+(2-1)*المدخلات!$B$7/1440),"00")&"–"&(MOD(HOUR(المدخلات!$B$4+(2-1)*المدخلات!$B$7/1440+المدخلات!$B$5/1440)-1,12)+1)&":"&TEXT(MINUTE(المدخلات!$B$4+(2-1)*المدخلات!$B$7/1440+المدخلات!$B$5/1440),"00")&" م" -> 4:15–4:30 م
B20: =(MOD(HOUR(المدخلات!$B$4+(3-1)*المدخلات!$B$7/1440)-1,12)+1)&":"&TEXT(MINUTE(المدخلات!$B$4+(3-1)*المدخلات!$B$7/1440),"00")&"–"&(MOD(HOUR(المدخلات!$B$4+(3-1)*المدخلات!$B$7/1440+المدخلات!$B$5/1440)-1,12)+1)&":"&TEXT(MINUTE(المدخلات!$B$4+(3-1)*المدخلات!$B$7/1440+المدخلات!$B$5/1440),"00")&" م" -> 4:30–4:45 م | C20: 2 ضد 4 | D20: 1 ضد 3 | E20: 5 ضد 6
