Workbook
Name الحد_الأدنى: [1]المدخلات!$N$3

Sheet Sheet1
G1: عدد الملاعب (تحت 14) | I1: إجمالي الملاعب المطلوبة | J1: =SUM(G2:G185) -> 68
B2: تحت 14 | C2: مجموعة نجران | D2: 1 | E2: نجران | F2: 5 | G2: =IF($B2=$J$4,_xlfn.XLOOKUP($F2,الملخص!$A$4:$A$20,الملخص!$L$4:$L$20,"غير موجود"),"") -> 1 | I2: عدد المجموعات | J2: =COUNTIF(B2:B185,J4) -> 28
B3: تحت 5 | C3: مجموعة طبرجل | D3: 1 | E3: طبرجل | F3: 5 | G3: =IF($B3=$J$4,_xlfn.XLOOKUP($F3,الملخص!$A$4:$A$20,الملخص!$L$4:$L$20,"غير موجود"),"") | I3: أكبر عدد ملاعب لمجموعة واحدة | J3: =MAX(G2:G185) -> 7
B4: تحت 7 | C4: مجموعة طبرجل | D4: 1 | E4: طبرجل | F4: 5 | G4: =IF($B4=$J$4,_xlfn.XLOOKUP($F4,الملخص!$A$4:$A$20,الملخص!$L$4:$L$20,"غير موجود"),"") | I4: الفئة | J4: تحت 14
B5: تحت 9 | C5: مجموعة الخرج | D5: 1 | E5: الخرج | F5: 5 | G5: =IF($B5=$J$4,_xlfn.XLOOKUP($F5,الملخص!$A$4:$A$20,الملخص!$L$4:$L$20,"غير موجود"),"")
B6: تحت 12 | C6: مجموعة طبرجل | D6: 1 | E6: طبرجل | F6: 5 | G6: =IF($B6=$J$4,_xlfn.XLOOKUP($F6,الملخص!$A$4:$A$20,الملخص!$L$4:$L$20,"غير موجود"),"")
B7: تحت 14 | C7: مجموعة طبرجل | D7: 1 | E7: طبرجل | F7: 5 | G7: =IF($B7=$J$4,_xlfn.XLOOKUP($F7,الملخص!$A$4:$A$20,الملخص!$L$4:$L$20,"غير موجود"),"") -> 1
B8: تحت 7 | C8: مجموعة شرورة | D8: 1 | E8: شرورة | F8: 5 | G8: =IF($B8=$J$4,_xlfn.XLOOKUP($F8,الملخص!$A$4:$A$20,الملخص!$L$4:$L$20,"غير موجود"),"")
B9: تحت 9 | C9: مجموعة شرورة | D9: 1 | E9: شرورة | F9: 5 | G9: =IF($B9=$J$4,_xlfn.XLOOKUP($F9,الملخص!$A$4:$A$20,الملخص!$L$4:$L$20,"غير موجود"),"")
B10: تحت 9 | C10: مجموعة الدوادمي | D10: 1 | E10: الدوادمي | F10: 5 | G10: =IF($B10=$J$4,_xlfn.XLOOKUP($F10,الملخص!$A$4:$A$20,الملخص!$L$4:$L$20,"غير موجود"),"")
B11: تحت 11 | C11: مجموعة القريات | D11: 1 | E11: القريات | F11: 5 | G11: =IF($B11=$J$4,_xlfn.XLOOKUP($F11,الملخص!$A$4:$A$20,الملخص!$L$4:$L$20,"غير موجود"),"")
B12: تحت 12 | C12: مجموعة القريات | D12: 1 | E12: القريات | F12: 5 | G12: =IF($B12=$J$4,_xlfn.XLOOKUP($F12,الملخص!$A$4:$A$20,الملخص!$L$4:$L$20,"غير موجود"),"")
B13: تحت 13 | C13: مجموعة القريات | D13: 1 | E13: القريات | F13: 5 | G13: =IF($B13=$J$4,_xlfn.XLOOKUP($F13,الملخص!$A$4:$A$20,الملخص!$L$4:$L$20,"غير موجود"),"")
B14: تحت 14 | C14: مجموعة القريات | D14: 1 | E14: القريات | F14: 5 | G14: =IF($B14=$J$4,_xlfn.XLOOKUP($F14,الملخص!$A$4:$A$20,الملخص!$L$4:$L$20,"غير موجود"),"") -> 1
B15: تحت 12 | C15: مجموعة الباحة | D15: 2 | E15: الباحة، العقيق | F15: 6 | G15: =IF($B15=$J$4,_xlfn.XLOOKUP($F15,الملخص!$A$4:$A$20,الملخص!$L$4:$L$20,"غير موجود"),"")
B16: تحت 13 | C16: مجموعة نجران | D16: 1 | E16: نجران | F16: 6 | G16: =IF($B16=$J$4,_xlfn.XLOOKUP($F16,الملخص!$A$4:$A$20,الملخص!$L$4:$L$20,"غير موجود"),"")
... B185: تحت 12 | C185: مجموعة جدة | D185: 1 | E185: جدة | F185: 56 | G185: =IF($B185=$J$4,_xlfn.XLOOKUP($F185,الملخص!$A$4:$A$20,الملخص!$L$4:$L$20,"غير موجود"),"")

Sheet المدخلات
A1: مدخلات جداول تحت 14 | E1: جدول الفترات
A3: البند | B3: القيمة | C3: ملاحظة | E3: الفترة | F3: التوقيت | H3: الفئة | I3: المجموعة | J3: عدد المدن | K3: المدن | L3: مجموع الفرق
E4: 1 | F4: =MOD(HOUR($B$5+0*$B$8/1440)-1,12)+1&":"&TEXT(MINUTE($B$5+0*$B$8/1440),"00")&"–"&MOD(HOUR($B$5+0*$B$8/1440+$B$6/1440)-1,12)+1&":"&TEXT(MINUTE($B$5+0*$B$8/1440+$B$6/1440),"00")&IF(HOUR($B$5+0*$B$8/1440)<12," ص"," م") -> 4:00–5:30 م | H4: تحت 14 | I4: مجموعة 1 | J4: {=INDEX(_xlfn._xlws.FILTER(Sheet1!$D$2:$D$185,Sheet1!$B$2:$B$185=Sheet1!$J$4),ROWS(J$4:J4))} -> 1 | K4: {=INDEX(_xlfn._xlws.FILTER(Sheet1!$E$2:$E$185,Sheet1!$B$2:$B$185=Sheet1!$J$4),ROWS(K$4:K4))} -> نجران | L4: 5
A5: وقت بداية اليوم | B5: 0.6666667 | C5: قابل للتعديل | E5: 2 | F5: =MOD(HOUR($B$5+1*$B$8/1440)-1,12)+1&":"&TEXT(MINUTE($B$5+1*$B$8/1440),"00")&"–"&MOD(HOUR($B$5+1*$B$8/1440+$B$6/1440)-1,12)+1&":"&TEXT(MINUTE($B$5+1*$B$8/1440+$B$6/1440),"00")&IF(HOUR($B$5+1*$B$8/1440)<12," ص"," م") -> 5:40–7:10 م | H5: تحت 14 | I5: مجموعة 2 | J5: {=INDEX(_xlfn._xlws.FILTER(Sheet1!$D$2:$D$185,Sheet1!$B$2:$B$185=Sheet1!$J$4),ROWS(J$4:J5))} -> 1 | K5: {=INDEX(_xlfn._xlws.FILTER(Sheet1!$E$2:$E$185,Sheet1!$B$2:$B$185=Sheet1!$J$4),ROWS(K$4:K5))} -> طبرجل | L5: 5
A6: مدة المباراة (دقيقة) | B6: 90 | C6: قابل للتعديل | E6: 3 | F6: =MOD(HOUR($B$5+2*$B$8/1440)-1,12)+1&":"&TEXT(MINUTE($B$5+2*$B$8/1440),"00")&"–"&MOD(HOUR($B$5+2*$B$8/1440+$B$6/1440)-1,12)+1&":"&TEXT(MINUTE($B$5+2*$B$8/1440+$B$6/1440),"00")&IF(HOUR($B$5+2*$B$8/1440)<12," ص"," م") -> 7:20–8:50 م | H6: تحت 14 | I6: مجموعة 3 | J6: {=INDEX(_xlfn._xlws.FILTER(Sheet1!$D$2:$D$185,Sheet1!$B$2:$B$185=Sheet1!$J$4),ROWS(J$4:J6))} -> 1 | K6: {=INDEX(_xlfn._xlws.FILTER(Sheet1!$E$2:$E$185,Sheet1!$B$2:$B$185=Sheet1!$J$4),ROWS(K$4:K6))} -> القريات | L6: 5
A7: الفاصل / ترتيب الملعب (دقيقة) | B7: 10 | C7: قابل للتعديل | H7: تحت 14 | I7: مجموعة 4 | J7: {=INDEX(_xlfn._xlws.FILTER(Sheet1!$D$2:$D$185,Sheet1!$B$2:$B$185=Sheet1!$J$4),ROWS(J$4:J7))} -> 1 | K7: {=INDEX(_xlfn._xlws.FILTER(Sheet1!$E$2:$E$185,Sheet1!$B$2:$B$185=Sheet1!$J$4),ROWS(K$4:K7))} -> الباحة | L7: 6
A8: طول الفترة الكاملة (دقيقة) | B8: =B6+B7 -> 100 | C8: محسوبة تلقائياً | H8: تحت 14 | I8: مجموعة 5 | J8: {=INDEX(_xlfn._xlws.FILTER(Sheet1!$D$2:$D$185,Sheet1!$B$2:$B$185=Sheet1!$J$4),ROWS(J$4:J8))} -> 1 | K8: {=INDEX(_xlfn._xlws.FILTER(Sheet1!$E$2:$E$185,Sheet1!$B$2:$B$185=Sheet1!$J$4),ROWS(K$4:K8))} -> حائل | L8: 7
A9: أقصى عدد فترات في اليوم | B9: 3 | C9: قابل للتعديل | H9: تحت 14 | I9: مجموعة 6 | J9: {=INDEX(_xlfn._xlws.FILTER(Sheet1!$D$2:$D$185,Sheet1!$B$2:$B$185=Sheet1!$J$4),ROWS(J$4:J9))} -> 2 | K9: {=INDEX(_xlfn._xlws.FILTER(Sheet1!$E$2:$E$185,Sheet1!$B$2:$B$185=Sheet1!$J$4),ROWS(K$4:K9))} -> الخرج، الدلم | L9: 7
A10: أقل عدد مباريات للفريق | B10: 16 | C10: لا تقل مباريات أي فريق عن هذا العدد (مقدّم على سقف الأيام) | H10: تحت 14 | I10: مجموعة 7 | J10: {=INDEX(_xlfn._xlws.FILTER(Sheet1!$D$2:$D$185,Sheet1!$B$2:$B$185=Sheet1!$J$4),ROWS(J$4:J10))} -> 1 | K10: {=INDEX(_xlfn._xlws.FILTER(Sheet1!$E$2:$E$185,Sheet1!$B$2:$B$185=Sheet1!$J$4),ROWS(K$4:K10))} -> مركز الرفيعة | L10: 8
A11: سقف أيام البطولة | B11: 22 | C11: يشمل أيام الدوري والإقصاء معاً | H11: تحت 14 | I11: مجموعة 8 | J11: {=INDEX(_xlfn._xlws.FILTER(Sheet1!$D$2:$D$185,Sheet1!$B$2:$B$185=Sheet1!$J$4),ROWS(J$4:J11))} -> 4 | K11: {=INDEX(_xlfn._xlws.FILTER(Sheet1!$E$2:$E$185,Sheet1!$B$2:$B$185=Sheet1!$J$4),ROWS(K$4:K11))} -> البكيرية، الرس، رياض الخبراء، البدائع | L11: 8
H12: تحت 14 | I12: مجموعة 9 | J12: {=INDEX(_xlfn._xlws.FILTER(Sheet1!$D$2:$D$185,Sheet1!$B$2:$B$185=Sheet1!$J$4),ROWS(J$4:J12))} -> 1 | K12: {=INDEX(_xlfn._xlws.FILTER(Sheet1!$E$2:$E$185,Sheet1!$B$2:$B$185=Sheet1!$J$4),ROWS(K$4:K12))} -> جيزان | L12: 8
H13: تحت 14 | I13: مجموعة 10 | J13: {=INDEX(_xlfn._xlws.FILTER(Sheet1!$D$2:$D$185,Sheet1!$B$2:$B$185=Sheet1!$J$4),ROWS(J$4:J13))} -> 1 | K13: {=INDEX(_xlfn._xlws.FILTER(Sheet1!$E$2:$E$185,Sheet1!$B$2:$B$185=Sheet1!$J$4),ROWS(K$4:K13))} -> أحد المسارحة | L13: 8
H14: تحت 14 | I14: مجموعة 11 | J14: {=INDEX(_xlfn._xlws.FILTER(Sheet1!$D$2:$D$185,Sheet1!$B$2:$B$185=Sheet1!$J$4),ROWS(J$4:J14))} -> 1 | K14: {=INDEX(_xlfn._xlws.FILTER(Sheet1!$E$2:$E$185,Sheet1!$B$2:$B$185=Sheet1!$J$4),ROWS(K$4:K14))} -> تبوك | L14: 9
H15: تحت 14 | I15: مجموعة 12 | J15: {=INDEX(_xlfn._xlws.FILTER(Sheet1!$D$2:$D$185,Sheet1!$B$2:$B$185=Sheet1!$J$4),ROWS(J$4:J15))} -> 2 | K15: {=INDEX(_xlfn._xlws.FILTER(Sheet1!$E$2:$E$185,Sheet1!$B$2:$B$185=Sheet1!$J$4),ROWS(K$4:K15))} -> القطيف، الجبيل | L15: 10
H16: تحت 14 | I16: مجموعة 13 | J16: {=INDEX(_xlfn._xlws.FILTER(Sheet1!$D$2:$D$185,Sheet1!$B$2:$B$185=Sheet1!$J$4),ROWS(J$4:J16))} -> 1 | K16: {=INDEX(_xlfn._xlws.FILTER(Sheet1!$E$2:$E$185,Sheet1!$B$2:$B$185=Sheet1!$J$4),ROWS(K$4:K16))} -> صامطة | L16: 10
H17: تحت 14 | I17: مجموعة 14 | J17: {=INDEX(_xlfn._xlws.FILTER(Sheet1!$D$2:$D$185,Sheet1!$B$2:$B$185=Sheet1!$J$4),ROWS(J$4:J17))} -> 1 | K17: {=INDEX(_xlfn._xlws.FILTER(Sheet1!$E$2:$E$185,Sheet1!$B$2:$B$185=Sheet1!$J$4),ROWS(K$4:K17))} -> أبو عريش | L17: 10
H18: تحت 14 | I18: مجموعة 15 | J18: {=INDEX(_xlfn._xlws.FILTER(Sheet1!$D$2:$D$185,Sheet1!$B$2:$B$185=Sheet1!$J$4),ROWS(J$4:J18))} -> 2 | K18: {=INDEX(_xlfn._xlws.FILTER(Sheet1!$E$2:$E$185,Sheet1!$B$2:$B$185=Sheet1!$J$4),ROWS(K$4:K18))} -> سكاكا، دومة الجندل | L18: 11
H19: تحت 14 | I19: مجموعة 16 | J19: {=INDEX(_xlfn._xlws.FILTER(Sheet1!$D$2:$D$185,Sheet1!$B$2:$B$185=Sheet1!$J$4),ROWS(J$4:J19))} -> 1 | K19: {=INDEX(_xlfn._xlws.FILTER(Sheet1!$E$2:$E$185,Sheet1!$B$2:$B$185=Sheet1!$J$4),ROWS(K$4:K19))} -> القنفذة | L19: 11
H20: تحت 14 | I20: مجموعة 17 | J20: {=INDEX(_xlfn._xlws.FILTER(Sheet1!$D$2:$D$185,Sheet1!$B$2:$B$185=Sheet1!$J$4),ROWS(J$4:J20))} -> 4 | K20: {=INDEX(_xlfn._xlws.FILTER(Sheet1!$E$2:$E$185,Sheet1!$B$2:$B$185=Sheet1!$J$4),ROWS(K$4:K20))} -> بريدة، عيون الجواء، المذنب، عنيزة | L20: 12
H21: تحت 14 | I21: مجموعة 18 | J21: {=INDEX(_xlfn._xlws.FILTER(Sheet1!$D$2:$D$185,Sheet1!$B$2:$B$185=Sheet1!$J$4),ROWS(J$4:J21))} -> 4 | K21: {=INDEX(_xlfn._xlws.FILTER(Sheet1!$E$2:$E$185,Sheet1!$B$2:$B$185=Sheet1!$J$4),ROWS(K$4:K21))} -> الظهران، الخبر، الدمام، سيهات | L21: 12
H22: تحت 14 | I22: مجموعة 19 | J22: {=INDEX(_xlfn._xlws.FILTER(Sheet1!$D$2:$D$185,Sheet1!$B$2:$B$185=Sheet1!$J$4),ROWS(J$4:J22))} -> 2 | K22: {=INDEX(_xlfn._xlws.FILTER(Sheet1!$E$2:$E$185,Sheet1!$B$2:$B$185=Sheet1!$J$4),ROWS(K$4:K22))} -> صبيا، ضمد | L22: 14
H23: تحت 14 | I23: مجموعة 20 | J23: {=INDEX(_xlfn._xlws.FILTER(Sheet1!$D$2:$D$185,Sheet1!$B$2:$B$185=Sheet1!$J$4),ROWS(J$4:J23))} -> 2 | K23: {=INDEX(_xlfn._xlws.FILTER(Sheet1!$E$2:$E$185,Sheet1!$B$2:$B$185=Sheet1!$J$4),ROWS(K$4:K23))} -> أبها، خميس مشيط | L23: 15
... H31: تحت 14 | I31: مجموعة 28 | J31: {=INDEX(_xlfn._xlws.FILTER(Sheet1!$D$2:$D$185,Sheet1!$B$2:$B$185=Sheet1!$J$4),ROWS(J$4:J31))} -> 1 | K31: {=INDEX(_xlfn._xlws.FILTER(Sheet1!$E$2:$E$185,Sheet1!$B$2:$B$185=Sheet1!$J$4),ROWS(K$4:K31))} -> جدة | L31: 39

Sheet المبادئ
A1: مبادئ بناء جداول تحت 14 (من 5 إلى 39 فريقًا) — وحالة الالتزام الفعلية
A3: # | B3: المبدأ | C3: الشرح | D3: الحالة | E3: الاستثناءات والملاحظات
A4: 1 | B4: لا يلعب الفريق مباراتين ورا بعض | C4: القاعدة الأهم في التصميم: يحصل كل فريق على فترة راحة كاملة (15 دقيقة على الأقل، وفعلياً فترة 100 دقيقة كاملة) بين مباراتيه. ويُحقَّق ذلك إما بحجز فترات استراحة كاملة في الأعداد الصغيرة، أو بتوزيع الفرق على فترات وملاعب أكثر في الأعداد الكبيرة. | D4: ✔ مطبق بالكامل | E4: فحص الـ17 ورقة: صفر حالة تتابع. بل أقوى من ذلك — لا يلعب أي فريق مباراتين في اليوم الواحد إطلاقاً (مباراة واحدة كحد أقصى لكل فريق في اليوم).
A5: 2 | B5: لا يوجد تتابع إطلاقاً | C5: إذا ضاقت الفترات عن عدد المباريات المطلوبة، يُزاد عدد الملاعب أو تُزاد الأيام، ولا يُضحّى براحة اللاعبين بأي حال. | D5: ✔ مطبق بالكامل | E5: لم يُسجَّل أي تتابع في أي ورقة. عند ضيق الفترات زيد عدد الملاعب (حتى 7 ملاعب في 39 فريقًا) أو عدد الأيام، ولم تُضغط راحة أي فريق.
A6: 3 | B6: عدالة عدد المباريات | C6: كل الفرق تلعب العدد نفسه في اليوم الواحد وفي البطولة ككل — لا فريق يلعب أكثر من آخر. | D6: ✔ مطبق بالكامل | E6: داخل كل مجموعة تفاوت صفر: 5→16، 6→20، 7→18، 8→21، 9→16، 10→18، 11→20، 12→22، 14→18/18، 15→18/21، 16→21/21، 17→16، 19→18، 26→20/20/18/18، 28→18/18/18/18، 38→18/18، 39→18/19. ولا تقل عن 16 (المدخلات B10).
A7: 4 | B7: عدالة المواجهات | C7: تُوزَّع فرص اللقاء على الجميع بدل أن تتكرر بين فرق معيّنة: يُقسم إجمالي المباريات على عدد الأزواج الممكنة، ويُسمح بمستويين فقط فرقهما مباراة واحدة. | D7: ✔ مطبق بالكامل | E7: كل زوج داخل المجموعة يلتقي العدد نفسه بالضبط (تفاوت صفر)، ولا تبدأ دورة جديدة إلا بعد اكتمال كل مواجهات الدورة السابقة — في كل الأوراق. عدد الدورات (1–4) صحيح لكل مجموعة فرعية.
A8: 5 | B8: تقسيم المجموعات عند الأعداد الكبيرة | C8: إذا كبر عدد الفرق حتى لم تكفِ مباريات الموسم للقاء الجميع، يُقسم العدد إلى مجموعات متساوية تلعب كل منها على ملاعبها الخاصة في نفس الوقت. | D8: ✔ مطبق بالكامل | E8: التقسيم الفعلي: 14→7+7، 15→7+8، 16→8+8، 26→6+6+7+7، 28→7+7+7+7، 38→19+19، 39→19+20. والأعداد 5، 6، 7، 8، 9، 10، 11، 12، 17، 19 مجموعة واحدة.
A9: 6 | B9: أقصى 3 فترات في اليوم | C9: اليوم يبدأ 4:00 م وينتهي 8:50 م بثلاث فترات فقط (مباراة 90 دقيقة + 10 دقائق ترتيب الملعب)، ولا يُطال اليوم أكثر من ذلك. | D9: ✔ مطبق بالكامل | E9: كل الأوراق تستخدم ثلاث فترات فقط (4:00 / 5:40 / 7:20) وينتهي اليوم 8:50 م — لا استثناء.
A10: 7 | B10: الحد الأقصى لأيام الدوري = 21 يوماً | C10: ميزانية أيام الدوري = 22 ناقص أيام الإقصاء (22 لمجموعة واحدة، 21 لمجموعتين، 20 لثلاث/أربع، 19 لخمس فأكثر). | D10: ⚠ مطبق باستثناءين | E10: كل الأعداد ≤ 21 يوم دوري، ما عدا 11 و12 فريقًا = 22 يوم دوري (مجموعة واحدة بلا إقصاء، ضمن ميزانية الـ22). أقلها 17 يومًا (17 فريقًا) و18 يومًا (9 و10 فرق).
A11: 8 | B11: إجمالي أيام البطولة لا يتجاوز 22 يوماً | C11: أيام الدوري + الإقصاء في سقف واحد، إلا إذا تعارض السقف مع شرط الحد الأدنى 16 مباراة فيُقدّم الشرط. | D11: ⚠ مطبق باستثناءين | E11: إجمالي الأيام 17–22 لكل الأعداد، ما عدا 26 و28 فريقًا = 23 يومًا؛ لا يوجد تقسيم إلى مجموعات متساوية بأدوار كاملة موحّدة يحقق حد الـ16 مباراة داخل 22 يومًا. عمودا التحقق M وN في الملخص يُظهران التجاوز.
A12: 9 | B12: الإقصاء فقط عند تعدد المجموعات | C12: المجموعة الواحدة تحسم بالدوري بدون إقصاء، وعند تعدد المجموعات يتأهل متصدر كل مجموعة لدور إقصائي بحجم عدد المجموعات. | D12: ✔ مطبق بالكامل | E12: بدون إقصاء (مجموعة واحدة): 5، 6، 7، 8، 9، 10، 11، 12، 17، 19. نهائي مباشر (يوم واحد): 14، 15، 16، 38، 39. نصف + نهائي (يومان): 26، 28.
A13: 10 | B13: أقل عدد ممكن من الملاعب | C13: لا يُفتح ملعب إضافي إلا إذا لم تكفِ الفترات الثلاث وأيام السقف 21 يوماً لتغطية المباريات. | D13: ✔ مطبق بالكامل | E13: ملعب واحد: 5، 6، 7. ملعبان: 8، 9، 10، 11، 12، 14. ثلاثة: 15، 16، 17، 19. أربعة: 26، 28. ستة: 38. سبعة: 39.
A14: 11 | B14: كل المجموعات تلعب في نفس الوقت | C14: المجموعات لا تتناوب على الأيام؛ كل المجموعات تلعب في نفس المهرجان ونفس الأيام، وتُوزَّع مبارياتها على الملاعب والفترات المتاحة في اليوم نفسه. | D14: ✔ مطبق بالكامل | E14: متحقق في جميع الأوراق متعددة المجموعات: كل المجموعات تلعب في نفس الأيام. الملاعب غير مثبّتة لكل مجموعة بل تُوزَّع بالتناوب لتحقيق عدالة الفترات (مبدأ 13).
A15: 12 | B15: وقت موحد لكل البطولات | C15: كل جداول تحت 14 تبدأ 4:00 م وتستخدم نفس الفترات المعرفة في ورقة المدخلات، وأي تعديل في المدخلات ينعكس تلقائياً على كل الأوراق. | D15: ✔ مطبق بالكامل | E15: كل الأوراق تبدأ 4:00 م وتستخدم الفترات المعرفة في ورقة المدخلات نفسها، وأي تعديل في المدخلات ينعكس على الجميع.
A16: 13 | B16: عدالة توزيع الفترات | C16: لا يُثبَّت فريق أو مجموعة على فترة واحدة طول الموسم؛ تتدوّر فترات المباريات (4:00 / 5:40 / 7:20) بين كل الفرق بالتساوي داخل كل مجموعة. | D16: ✔ مطبق بالكامل | E16: لا يوجد فريق مثبّت على فترة واحدة ولا فريق يبدأ أول مباراة كل يوم. الفرق بين أكثر وأقل فريق في عدد مرات الفترة الأولى داخل المجموعة الواحدة لا يتجاوز 3 مباريات (الأغلب 1–2).

Sheet الملخص
A1: ملخص بطولات تحت 14 — الأعداد المطلوبة
A3: عدد الفرق | B3: عدد المجموعات | C3: توزيع الفرق في المجموعات | D3: عدد الأدوار | E3: مباريات كل فريق في الموسم | F3: نظام الإقصاء | G3: أيام الدوري | H3: أيام الإقصاء | I3: إجمالي الأيام | J3: وقت البداية | K3: وقت النهاية | L3: عدد الملاعب القانونية | M3: أقل مباريات للفريق (تحقق ≥ 16) | N3: تحقق سقف الأيام (≤ 22) | O3: عدد مباريات البطولة الواحدة
A4: 5 | B4: {=ROUND(SUMPRODUCT(1/COUNTIF('بيانات الفرق'!$B$3:$B$7,'بيانات الفرق'!$B$3:$B$7)),0)} -> 1 | C4: {=_xlfn.TEXTJOIN(" + ",TRUE,_xlfn._xlws.SORT(COUNTIF('بيانات الفرق'!$B$3:$B$7,"المجموعة "&_xlfn.SEQUENCE(B4))))} -> 5 | D4: {=_xlfn.LET(_xlpm.gs,_xlfn.SEQUENCE(B4),_xlpm.ln,_xlfn.MAXIFS('بيانات الفرق'!$D$3:$D$7,'بيانات الفرق'!$B$3:$B$7,"المجموعة "&_xlpm.gs),_xlpm.mn,_xlfn.MINIFS('بيانات الفرق'!$C$3:$C$7,'بيانات الفرق'!$B$3:$B$7,"المجموعة "&_xlpm.gs),_xlpm.mx,_xlfn.MAXIFS('بيانات الفرق'!$C$3:$C$7,'بيانات الفرق'!$B$3:$B$7,"المجموعة "&_xlpm.gs),_xlpm.lo,FLOOR(_xlpm.mn/_xlpm.ln,1),_xlpm.hi,CEILING(_xlpm.mx/_xlpm.ln,1),_xlpm.t,IF(_xlpm.lo=_xlpm.hi,_xlpm.lo&"",_xlpm.lo&"–"&_xlpm.hi),_xlfn.TEXTJOIN(" + ",TRUE,_xlfn.SORTBY(_xlpm.t,_xlpm.ln,1)))} -> 4 | E4: {=_xlfn.LET(_xlpm.gs,_xlfn.SEQUENCE(B4),_xlpm.ln,_xlfn.MAXIFS('بيانات الفرق'!$D$3:$D$7,'بيانات الفرق'!$B$3:$B$7,"المجموعة "&_xlpm.gs),_xlpm.mn,_xlfn.MINIFS('بيانات الفرق'!$C$3:$C$7,'بيانات الفرق'!$B$3:$B$7,"المجموعة "&_xlpm.gs),_xlpm.mx,_xlfn.MAXIFS('بيانات الفرق'!$C$3:$C$7,'بيانات الفرق'!$B$3:$B$7,"المجموعة "&_xlpm.gs),_xlpm.t,IF(_xlpm.mn=_xlpm.mx,_xlpm.mn&"",_xlpm.mn&"–"&_xlpm.mx),_xlfn.TEXTJOIN(" + ",TRUE,_xlfn.SORTBY(_xlpm.t,_xlpm.ln,1)))} -> 16 | F4: ="—" -> — | G4: =MAX('5 فرق'!$A$4:$A$600) -> 20 | H4: =MAX('5 فرق'!$A$4:$A$600)-G4 -> 0 | I4: =MAX('5 فرق'!$A$4:$A$600) -> 20 | J4: =MOD(HOUR(المدخلات!$B$5)-1,12)+1&":"&TEXT(MINUTE(المدخلات!$B$5),"00")&IF(HOUR(المدخلات!$B$5)<12," ص"," م") -> 4:00 م | K4: {=MOD(HOUR(المدخلات!$B$5+((SUMPRODUCT(--(COUNTIF('5 فرق'!$B$4:$B$600,المدخلات!$F$4:$F$6)>0))-1)*المدخلات!$B$8+المدخلات!$B$6)/1440)-1,12)+1&":"&TEXT(MINUTE(المدخلات!$B$5+((SUMPRODUCT(--(COUNTIF('5 فرق'!$B$4:$B$600,المدخلات!$F$4:$F$6)>0))-1)*المدخلات!$B$8+المدخلات!$B$6)/1440),"00")&IF(HOUR(المدخلات!$B$5+((SUMPRODUCT(--(COUNTIF('5 فرق'!$B$4:$B$600,المدخلات!$F$4:$F$6)>0))-1)*المدخلات!$B$8+المدخلات!$B$6)/1440)<12," ص"," م")} -> 8:50 م | L4: =MAX('5 فرق'!$C$4:$C$600) -> 1 | M4: =IF(MIN('بيانات الفرق'!$C$3:$C$7)>=المدخلات!$B$10,"✔ "&MIN('بيانات الفرق'!$C$3:$C$7),"⚠ "&MIN('بيانات الفرق'!$C$3:$C$7)) -> ✔ 16 | N4: =IF(I4<=المدخلات!$B$11,"✔ "&I4,"⚠ تجاوز "&(I4-المدخلات!$B$11)&" يوم") -> ✔ 20 | O4: =COUNT('5 فرق'!$A$4:$A$600) -> 55
A5: 6 | B5: {=ROUND(SUMPRODUCT(1/COUNTIF('بيانات الفرق'!$G$3:$G$8,'بيانات الفرق'!$G$3:$G$8)),0)} -> 1 | C5: {=_xlfn.TEXTJOIN(" + ",TRUE,_xlfn._xlws.SORT(COUNTIF('بيانات الفرق'!$G$3:$G$8,"المجموعة "&_xlfn.SEQUENCE(B5))))} -> 6 | D5: {=_xlfn.LET(_xlpm.gs,_xlfn.SEQUENCE(B5),_xlpm.ln,_xlfn.MAXIFS('بيانات الفرق'!$I$3:$I$8,'بيانات الفرق'!$G$3:$G$8,"المجموعة "&_xlpm.gs),_xlpm.mn,_xlfn.MINIFS('بيانات الفرق'!$H$3:$H$8,'بيانات الفرق'!$G$3:$G$8,"المجموعة "&_xlpm.gs),_xlpm.mx,_xlfn.MAXIFS('بيانات الفرق'!$H$3:$H$8,'بيانات الفرق'!$G$3:$G$8,"المجموعة "&_xlpm.gs),_xlpm.lo,FLOOR(_xlpm.mn/_xlpm.ln,1),_xlpm.hi,CEILING(_xlpm.mx/_xlpm.ln,1),_xlpm.t,IF(_xlpm.lo=_xlpm.hi,_xlpm.lo&"",_xlpm.lo&"–"&_xlpm.hi),_xlfn.TEXTJOIN(" + ",TRUE,_xlfn.SORTBY(_xlpm.t,_xlpm.ln,1)))} -> 4 | E5: {=_xlfn.LET(_xlpm.gs,_xlfn.SEQUENCE(B5),_xlpm.ln,_xlfn.MAXIFS('بيانات الفرق'!$I$3:$I$8,'بيانات الفرق'!$G$3:$G$8,"المجموعة "&_xlpm.gs),_xlpm.mn,_xlfn.MINIFS('بيانات الفرق'!$H$3:$H$8,'بيانات الفرق'!$G$3:$G$8,"المجموعة "&_xlpm.gs),_xlpm.mx,_xlfn.MAXIFS('بيانات الفرق'!$H$3:$H$8,'بيانات الفرق'!$G$3:$G$8,"المجموعة "&_xlpm.gs),_xlpm.t,IF(_xlpm.mn=_xlpm.mx,_xlpm.mn&"",_xlpm.mn&"–"&_xlpm.mx),_xlfn.TEXTJOIN(" + ",TRUE,_xlfn.SORTBY(_xlpm.t,_xlpm.ln,1)))} -> 20 | F5: ="—" -> — | G5: =MAX('6 فرق'!$A$4:$A$600) -> 20 | H5: =MAX('6 فرق'!$A$4:$A$600)-G5 -> 0 | I5: =MAX('6 فرق'!$A$4:$A$600) -> 20 | J5: =MOD(HOUR(المدخلات!$B$5)-1,12)+1&":"&TEXT(MINUTE(المدخلات!$B$5),"00")&IF(HOUR(المدخلات!$B$5)<12," ص"," م") -> 4:00 م | K5: {=MOD(HOUR(المدخلات!$B$5+((SUMPRODUCT(--(COUNTIF('6 فرق'!$B$4:$B$600,المدخلات!$F$4:$F$6)>0))-1)*المدخلات!$B$8+المدخلات!$B$6)/1440)-1,12)+1&":"&TEXT(MINUTE(المدخلات!$B$5+((SUMPRODUCT(--(COUNTIF('6 فرق'!$B$4:$B$600,المدخلات!$F$4:$F$6)>0))-1)*المدخلات!$B$8+المدخلات!$B$6)/1440),"00")&IF(HOUR(المدخلات!$B$5+((SUMPRODUCT(--(COUNTIF('6 فرق'!$B$4:$B$600,المدخلات!$F$4:$F$6)>0))-1)*المدخلات!$B$8+المدخلات!$B$6)/1440)<12," ص"," م")} -> 8:50 م | L5: =MAX('6 فرق'!$C$4:$C$600) -> 1 | M5: =IF(MIN('بيانات الفرق'!$H$3:$H$8)>=المدخلات!$B$10,"✔ "&MIN('بيانات الفرق'!$H$3:$H$8),"⚠ "&MIN('بيانات الفرق'!$H$3:$H$8)) -> ✔ 20 | N5: =IF(I5<=المدخلات!$B$11,"✔ "&I5,"⚠ تجاوز "&(I5-المدخلات!$B$11)&" يوم") -> ✔ 20 | O5: =COUNT('6 فرق'!$A$4:$A$600) -> 66
A6: 7 | B6: {=ROUND(SUMPRODUCT(1/COUNTIF('بيانات الفرق'!$L$3:$L$9,'بيانات الفرق'!$L$3:$L$9)),0)} -> 1 | C6: {=_xlfn.TEXTJOIN(" + ",TRUE,_xlfn._xlws.SORT(COUNTIF('بيانات الفرق'!$L$3:$L$9,"المجموعة "&_xlfn.SEQUENCE(B6))))} -> 7 | D6: {=_xlfn.LET(_xlpm.gs,_xlfn.SEQUENCE(B6),_xlpm.ln,_xlfn.MAXIFS('بيانات الفرق'!$N$3:$N$9,'بيانات الفرق'!$L$3:$L$9,"المجموعة "&_xlpm.gs),_xlpm.mn,_xlfn.MINIFS('بيانات الفرق'!$M$3:$M$9,'بيانات الفرق'!$L$3:$L$9,"المجموعة "&_xlpm.gs),_xlpm.mx,_xlfn.MAXIFS('بيانات الفرق'!$M$3:$M$9,'بيانات الفرق'!$L$3:$L$9,"المجموعة "&_xlpm.gs),_xlpm.lo,FLOOR(_xlpm.mn/_xlpm.ln,1),_xlpm.hi,CEILING(_xlpm.mx/_xlpm.ln,1),_xlpm.t,IF(_xlpm.lo=_xlpm.hi,_xlpm.lo&"",_xlpm.lo&"–"&_xlpm.hi),_xlfn.TEXTJOIN(" + ",TRUE,_xlfn.SORTBY(_xlpm.t,_xlpm.ln,1)))} -> 3 | E6: {=_xlfn.LET(_xlpm.gs,_xlfn.SEQUENCE(B6),_xlpm.ln,_xlfn.MAXIFS('بيانات الفرق'!$N$3:$N$9,'بيانات الفرق'!$L$3:$L$9,"المجموعة "&_xlpm.gs),_xlpm.mn,_xlfn.MINIFS('بيانات الفرق'!$M$3:$M$9,'بيانات الفرق'!$L$3:$L$9,"المجموعة "&_xlpm.gs),_xlpm.mx,_xlfn.MAXIFS('بيانات الفرق'!$M$3:$M$9,'بيانات الفرق'!$L$3:$L$9,"المجموعة "&_xlpm.gs),_xlpm.t,IF(_xlpm.mn=_xlpm.mx,_xlpm.mn&"",_xlpm.mn&"–"&_xlpm.mx),_xlfn.TEXTJOIN(" + ",TRUE,_xlfn.SORTBY(_xlpm.t,_xlpm.ln,1)))} -> 18 | F6: ="—" -> — | G6: =MAX('7 فرق'!$A$4:$A$600) -> 21 | H6: =MAX('7 فرق'!$A$4:$A$600)-G6 -> 0 | I6: =MAX('7 فرق'!$A$4:$A$600) -> 21 | J6: =MOD(HOUR(المدخلات!$B$5)-1,12)+1&":"&TEXT(MINUTE(المدخلات!$B$5),"00")&IF(HOUR(المدخلات!$B$5)<12," ص"," م") -> 4:00 م | K6: {=MOD(HOUR(المدخلات!$B$5+((SUMPRODUCT(--(COUNTIF('7 فرق'!$B$4:$B$600,المدخلات!$F$4:$F$6)>0))-1)*المدخلات!$B$8+المدخلات!$B$6)/1440)-1,12)+1&":"&TEXT(MINUTE(المدخلات!$B$5+((SUMPRODUCT(--(COUNTIF('7 فرق'!$B$4:$B$600,المدخلات!$F$4:$F$6)>0))-1)*المدخلات!$B$8+المدخلات!$B$6)/1440),"00")&IF(HOUR(المدخلات!$B$5+((SUMPRODUCT(--(COUNTIF('7 فرق'!$B$4:$B$600,المدخلات!$F$4:$F$6)>0))-1)*المدخلات!$B$8+المدخلات!$B$6)/1440)<12," ص"," م")} -> 8:50 م | L6: =MAX('7 فرق'!$C$4:$C$600) -> 1 | M6: =IF(MIN('بيانات الفرق'!$M$3:$M$9)>=المدخلات!$B$10,"✔ "&MIN('بيانات الفرق'!$M$3:$M$9),"⚠ "&MIN('بيانات الفرق'!$M$3:$M$9)) -> ✔ 18 | N6: =IF(I6<=المدخلات!$B$11,"✔ "&I6,"⚠ تجاوز "&(I6-المدخلات!$B$11)&" يوم") -> ✔ 21 | O6: =COUNT('7 فرق'!$A$4:$A$600) -> 77
A7: 8 | B7: {=ROUND(SUMPRODUCT(1/COUNTIF('بيانات الفرق'!$Q$3:$Q$10,'بيانات الفرق'!$Q$3:$Q$10)),0)} -> 1 | C7: {=_xlfn.TEXTJOIN(" + ",TRUE,_xlfn._xlws.SORT(COUNTIF('بيانات الفرق'!$Q$3:$Q$10,"المجموعة "&_xlfn.SEQUENCE(B7))))} -> 8 | D7: {=_xlfn.LET(_xlpm.gs,_xlfn.SEQUENCE(B7),_xlpm.ln,_xlfn.MAXIFS('بيانات الفرق'!$S$3:$S$10,'بيانات الفرق'!$Q$3:$Q$10,"المجموعة "&_xlpm.gs),_xlpm.mn,_xlfn.MINIFS('بيانات الفرق'!$R$3:$R$10,'بيانات الفرق'!$Q$3:$Q$10,"المجموعة "&_xlpm.gs),_xlpm.mx,_xlfn.MAXIFS('بيانات الفرق'!$R$3:$R$10,'بيانات الفرق'!$Q$3:$Q$10,"المجموعة "&_xlpm.gs),_xlpm.lo,FLOOR(_xlpm.mn/_xlpm.ln,1),_xlpm.hi,CEILING(_xlpm.mx/_xlpm.ln,1),_xlpm.t,IF(_xlpm.lo=_xlpm.hi,_xlpm.lo&"",_xlpm.lo&"–"&_xlpm.hi),_xlfn.TEXTJOIN(" + ",TRUE,_xlfn.SORTBY(_xlpm.t,_xlpm.ln,1)))} -> 3 | E7: {=_xlfn.LET(_xlpm.gs,_xlfn.SEQUENCE(B7),_xlpm.ln,_xlfn.MAXIFS('بيانات الفرق'!$S$3:$S$10,'بيانات الفرق'!$Q$3:$Q$10,"المجموعة "&_xlpm.gs),_xlpm.mn,_xlfn.MINIFS('بيانات الفرق'!$R$3:$R$10,'بيانات الفرق'!$Q$3:$Q$10,"المجموعة "&_xlpm.gs),_xlpm.mx,_xlfn.MAXIFS('بيانات الفرق'!$R$3:$R$10,'بيانات الفرق'!$Q$3:$Q$10,"المجموعة "&_xlpm.gs),_xlpm.t,IF(_xlpm.mn=_xlpm.mx,_xlpm.mn&"",_xlpm.mn&"–"&_xlpm.mx),_xlfn.TEXTJOIN(" + ",TRUE,_xlfn.SORTBY(_xlpm.t,_xlpm.ln,1)))} -> 21 | F7: ="—" -> — | G7: =MAX('8 فرق'!$A$4:$A$600) -> 21 | H7: =MAX('8 فرق'!$A$4:$A$600)-G7 -> 0 | I7: =MAX('8 فرق'!$A$4:$A$600) -> 21 | J7: =MOD(HOUR(المدخلات!$B$5)-1,12)+1&":"&TEXT(MINUTE(المدخلات!$B$5),"00")&IF(HOUR(المدخلات!$B$5)<12," ص"," م") -> 4:00 م | K7: {=MOD(HOUR(المدخلات!$B$5+((SUMPRODUCT(--(COUNTIF('8 فرق'!$B$4:$B$600,المدخلات!$F$4:$F$6)>0))-1)*المدخلات!$B$8+المدخلات!$B$6)/1440)-1,12)+1&":"&TEXT(MINUTE(المدخلات!$B$5+((SUMPRODUCT(--(COUNTIF('8 فرق'!$B$4:$B$600,المدخلات!$F$4:$F$6)>0))-1)*المدخلات!$B$8+المدخلات!$B$6)/1440),"00")&IF(HOUR(المدخلات!$B$5+((SUMPRODUCT(--(COUNTIF('8 فرق'!$B$4:$B$600,المدخلات!$F$4:$F$6)>0))-1)*المدخلات!$B$8+المدخلات!$B$6)/1440)<12," ص"," م")} -> 8:50 م | L7: =MAX('8 فرق'!$C$4:$C$600) -> 2 | M7: =IF(MIN('بيانات الفرق'!$R$3:$R$10)>=المدخلات!$B$10,"✔ "&MIN('بيانات الفرق'!$R$3:$R$10),"⚠ "&MIN('بيانات الفرق'!$R$3:$R$10)) -> ✔ 21 | N7: =IF(I7<=المدخلات!$B$11,"✔ "&I7,"⚠ تجاوز "&(I7-المدخلات!$B$11)&" يوم") -> ✔ 21 | O7: =COUNT('8 فرق'!$A$4:$A$600) -> 116
A8: 9 | B8: {=ROUND(SUMPRODUCT(1/COUNTIF('بيانات الفرق'!$V$3:$V$11,'بيانات الفرق'!$V$3:$V$11)),0)} -> 1 | C8: {=_xlfn.TEXTJOIN(" + ",TRUE,_xlfn._xlws.SORT(COUNTIF('بيانات الفرق'!$V$3:$V$11,"المجموعة "&_xlfn.SEQUENCE(B8))))} -> 9 | D8: {=_xlfn.LET(_xlpm.gs,_xlfn.SEQUENCE(B8),_xlpm.ln,_xlfn.MAXIFS('بيانات الفرق'!$X$3:$X$11,'بيانات الفرق'!$V$3:$V$11,"المجموعة "&_xlpm.gs),_xlpm.mn,_xlfn.MINIFS('بيانات الفرق'!$W$3:$W$11,'بيانات الفرق'!$V$3:$V$11,"المجموعة "&_xlpm.gs),_xlpm.mx,_xlfn.MAXIFS('بيانات الفرق'!$W$3:$W$11,'بيانات الفرق'!$V$3:$V$11,"المجموعة "&_xlpm.gs),_xlpm.lo,FLOOR(_xlpm.mn/_xlpm.ln,1),_xlpm.hi,CEILING(_xlpm.mx/_xlpm.ln,1),_xlpm.t,IF(_xlpm.lo=_xlpm.hi,_xlpm.lo&"",_xlpm.lo&"–"&_xlpm.hi),_xlfn.TEXTJOIN(" + ",TRUE,_xlfn.SORTBY(_xlpm.t,_xlpm.ln,1)))} -> 2 | E8: {=_xlfn.LET(_xlpm.gs,_xlfn.SEQUENCE(B8),_xlpm.ln,_xlfn.MAXIFS('بيانات الفرق'!$X$3:$X$11,'بيانات الفرق'!$V$3:$V$11,"المجموعة "&_xlpm.gs),_xlpm.mn,_xlfn.MINIFS('بيانات الفرق'!$W$3:$W$11,'بيانات الفرق'!$V$3:$V$11,"المجموعة "&_xlpm.gs),_xlpm.mx,_xlfn.MAXIFS('بيانات الفرق'!$W$3:$W$11,'بيانات الفرق'!$V$3:$V$11,"المجموعة "&_xlpm.gs),_xlpm.t,IF(_xlpm.mn=_xlpm.mx,_xlpm.mn&"",_xlpm.mn&"–"&_xlpm.mx),_xlfn.TEXTJOIN(" + ",TRUE,_xlfn.SORTBY(_xlpm.t,_xlpm.ln,1)))} -> 16 | F8: ="—" -> — | G8: =MAX('9 فرق'!$A$4:$A$600) -> 18 | H8: =MAX('9 فرق'!$A$4:$A$600)-G8 -> 0 | I8: =MAX('9 فرق'!$A$4:$A$600) -> 18 | J8: =MOD(HOUR(المدخلات!$B$5)-1,12)+1&":"&TEXT(MINUTE(المدخلات!$B$5),"00")&IF(HOUR(المدخلات!$B$5)<12," ص"," م") -> 4:00 م | K8: {=MOD(HOUR(المدخلات!$B$5+((SUMPRODUCT(--(COUNTIF('9 فرق'!$B$4:$B$600,المدخلات!$F$4:$F$6)>0))-1)*المدخلات!$B$8+المدخلات!$B$6)/1440)-1,12)+1&":"&TEXT(MINUTE(المدخلات!$B$5+((SUMPRODUCT(--(COUNTIF('9 فرق'!$B$4:$B$600,المدخلات!$F$4:$F$6)>0))-1)*المدخلات!$B$8+المدخلات!$B$6)/1440),"00")&IF(HOUR(المدخلات!$B$5+((SUMPRODUCT(--(COUNTIF('9 فرق'!$B$4:$B$600,المدخلات!$F$4:$F$6)>0))-1)*المدخلات!$B$8+المدخلات!$B$6)/1440)<12," ص"," م")} -> 8:50 م | L8: =MAX('9 فرق'!$C$4:$C$600) -> 2 | M8: =IF(MIN('بيانات الفرق'!$W$3:$W$11)>=المدخلات!$B$10,"✔ "&MIN('بيانات الفرق'!$W$3:$W$11),"⚠ "&MIN('بيانات الفرق'!$W$3:$W$11)) -> ✔ 16 | N8: =IF(I8<=المدخلات!$B$11,"✔ "&I8,"⚠ تجاوز "&(I8-المدخلات!$B$11)&" يوم") -> ✔ 18 | O8: =COUNT('9 فرق'!$A$4:$A$600) -> 81
A9: 10 | B9: {=ROUND(SUMPRODUCT(1/COUNTIF('بيانات الفرق'!$AA$3:$AA$12,'بيانات الفرق'!$AA$3:$AA$12)),0)} -> 1 | C9: {=_xlfn.TEXTJOIN(" + ",TRUE,_xlfn._xlws.SORT(COUNTIF('بيانات الفرق'!$AA$3:$AA$12,"المجموعة "&_xlfn.SEQUENCE(B9))))} -> 10 | D9: {=_xlfn.LET(_xlpm.gs,_xlfn.SEQUENCE(B9),_xlpm.ln,_xlfn.MAXIFS('بيانات الفرق'!$AC$3:$AC$12,'بيانات الفرق'!$AA$3:$AA$12,"المجموعة "&_xlpm.gs),_xlpm.mn,_xlfn.MINIFS('بيانات الفرق'!$AB$3:$AB$12,'بيانات الفرق'!$AA$3:$AA$12,"المجموعة "&_xlpm.gs),_xlpm.mx,_xlfn.MAXIFS('بيانات الفرق'!$AB$3:$AB$12,'بيانات الفرق'!$AA$3:$AA$12,"المجموعة "&_xlpm.gs),_xlpm.lo,FLOOR(_xlpm.mn/_xlpm.ln,1),_xlpm.hi,CEILING(_xlpm.mx/_xlpm.ln,1),_xlpm.t,IF(_xlpm.lo=_xlpm.hi,_xlpm.lo&"",_xlpm.lo&"–"&_xlpm.hi),_xlfn.TEXTJOIN(" + ",TRUE,_xlfn.SORTBY(_xlpm.t,_xlpm.ln,1)))} -> 2 | E9: {=_xlfn.LET(_xlpm.gs,_xlfn.SEQUENCE(B9),_xlpm.ln,_xlfn.MAXIFS('بيانات الفرق'!$AC$3:$AC$12,'بيانات الفرق'!$AA$3:$AA$12,"المجموعة "&_xlpm.gs),_xlpm.mn,_xlfn.MINIFS('بيانات الفرق'!$AB$3:$AB$12,'بيانات الفرق'!$AA$3:$AA$12,"المجموعة "&_xlpm.gs),_xlpm.mx,_xlfn.MAXIFS('بيانات الفرق'!$AB$3:$AB$12,'بيانات الفرق'!$AA$3:$AA$12,"المجموعة "&_xlpm.gs),_xlpm.t,IF(_xlpm.mn=_xlpm.mx,_xlpm.mn&"",_xlpm.mn&"–"&_xlpm.mx),_xlfn.TEXTJOIN(" + ",TRUE,_xlfn.SORTBY(_xlpm.t,_xlpm.ln,1)))} -> 18 | F9: ="—" -> — | G9: =MAX('10 فرق'!$A$4:$A$600) -> 18 | H9: =MAX('10 فرق'!$A$4:$A$600)-G9 -> 0 | I9: =MAX('10 فرق'!$A$4:$A$600) -> 18 | J9: =MOD(HOUR(المدخلات!$B$5)-1,12)+1&":"&TEXT(MINUTE(المدخلات!$B$5),"00")&IF(HOUR(المدخلات!$B$5)<12," ص"," م") -> 4:00 م | K9: {=MOD(HOUR(المدخلات!$B$5+((SUMPRODUCT(--(COUNTIF('10 فرق'!$B$4:$B$600,المدخلات!$F$4:$F$6)>0))-1)*المدخلات!$B$8+المدخلات!$B$6)/1440)-1,12)+1&":"&TEXT(MINUTE(المدخلات!$B$5+((SUMPRODUCT(--(COUNTIF('10 فرق'!$B$4:$B$600,المدخلات!$F$4:$F$6)>0))-1)*المدخلات!$B$8+المدخلات!$B$6)/1440),"00")&IF(HOUR(المدخلات!$B$5+((SUMPRODUCT(--(COUNTIF('10 فرق'!$B$4:$B$600,المدخلات!$F$4:$F$6)>0))-1)*المدخلات!$B$8+المدخلات!$B$6)/1440)<12," ص"," م")} -> 8:50 م | L9: =MAX('10 فرق'!$C$4:$C$600) -> 2 | M9: =IF(MIN('بيانات الفرق'!$AB$3:$AB$12)>=المدخلات!$B$10,"✔ "&MIN('بيانات الفرق'!$AB$3:$AB$12),"⚠ "&MIN('بيانات الفرق'!$AB$3:$AB$12)) -> ✔ 18 | N9: =IF(I9<=المدخلات!$B$11,"✔ "&I9,"⚠ تجاوز "&(I9-المدخلات!$B$11)&" يوم") -> ✔ 18 | O9: =COUNT('10 فرق'!$A$4:$A$600) -> 120
A10: 11 | B10: {=ROUND(SUMPRODUCT(1/COUNTIF('بيانات الفرق'!$AF$3:$AF$13,'بيانات الفرق'!$AF$3:$AF$13)),0)} -> 1 | C10: {=_xlfn.TEXTJOIN(" + ",TRUE,_xlfn._xlws.SORT(COUNTIF('بيانات الفرق'!$AF$3:$AF$13,"المجموعة "&_xlfn.SEQUENCE(B10))))} -> 11 | D10: {=_xlfn.LET(_xlpm.gs,_xlfn.SEQUENCE(B10),_xlpm.ln,_xlfn.MAXIFS('بيانات الفرق'!$AH$3:$AH$13,'بيانات الفرق'!$AF$3:$AF$13,"المجموعة "&_xlpm.gs),_xlpm.mn,_xlfn.MINIFS('بيانات الفرق'!$AG$3:$AG$13,'بيانات الفرق'!$AF$3:$AF$13,"المجموعة "&_xlpm.gs),_xlpm.mx,_xlfn.MAXIFS('بيانات الفرق'!$AG$3:$AG$13,'بيانات الفرق'!$AF$3:$AF$13,"المجموعة "&_xlpm.gs),_xlpm.lo,FLOOR(_xlpm.mn/_xlpm.ln,1),_xlpm.hi,CEILING(_xlpm.mx/_xlpm.ln,1),_xlpm.t,IF(_xlpm.lo=_xlpm.hi,_xlpm.lo&"",_xlpm.lo&"–"&_xlpm.hi),_xlfn.TEXTJOIN(" + ",TRUE,_xlfn.SORTBY(_xlpm.t,_xlpm.ln,1)))} -> 2 | E10: {=_xlfn.LET(_xlpm.gs,_xlfn.SEQUENCE(B10),_xlpm.ln,_xlfn.MAXIFS('بيانات الفرق'!$AH$3:$AH$13,'بيانات الفرق'!$AF$3:$AF$13,"المجموعة "&_xlpm.gs),_xlpm.mn,_xlfn.MINIFS('بيانات الفرق'!$AG$3:$AG$13,'بيانات الفرق'!$AF$3:$AF$13,"المجموعة "&_xlpm.gs),_xlpm.mx,_xlfn.MAXIFS('بيانات الفرق'!$AG$3:$AG$13,'بيانات الفرق'!$AF$3:$AF$13,"المجموعة "&_xlpm.gs),_xlpm.t,IF(_xlpm.mn=_xlpm.mx,_xlpm.mn&"",_xlpm.mn&"–"&_xlpm.mx),_xlfn.TEXTJOIN(" + ",TRUE,_xlfn.SORTBY(_xlpm.t,_xlpm.ln,1)))} -> 20 | F10: =IF(COUNTIF('11 فريقًا'!$D$4:$D$600,"نهائي")=0,"—",IF(COUNTIF('11 فريقًا'!$D$4:$D$600,"ربع نهائي")>0,"ربع نهائي ثم نصف نهائي ثم نهائي",IF(COUNTIF('11 فريقًا'!$D$4:$D$600,"نصف نهائي")>0,"نصف نهائي ثم نهائي","نهائي مباشر"))) -> — | G10: =_xlfn.MAXIFS('11 فريقًا'!$A$4:$A$600,'11 فريقًا'!$D$4:$D$600,"المجموعة*") -> 22 | H10: =MAX('11 فريقًا'!$A$4:$A$600)-G10 -> 0 | I10: =MAX('11 فريقًا'!$A$4:$A$600) -> 22 | J10: =MOD(HOUR(المدخلات!$B$5)-1,12)+1&":"&TEXT(MINUTE(المدخلات!$B$5),"00")&IF(HOUR(المدخلات!$B$5)<12," ص"," م") -> 4:00 م | K10: {=MOD(HOUR(المدخلات!$B$5+((SUMPRODUCT(--(COUNTIF('11 فريقًا'!$B$4:$B$600,المدخلات!$F$4:$F$6)>0))-1)*المدخلات!$B$8+المدخلات!$B$6)/1440)-1,12)+1&":"&TEXT(MINUTE(المدخلات!$B$5+((SUMPRODUCT(--(COUNTIF('11 فريقًا'!$B$4:$B$600,المدخلات!$F$4:$F$6)>0))-1)*المدخلات!$B$8+المدخلات!$B$6)/1440),"00")&IF(HOUR(المدخلات!$B$5+((SUMPRODUCT(--(COUNTIF('11 فريقًا'!$B$4:$B$600,المدخلات!$F$4:$F$6)>0))-1)*المدخلات!$B$8+المدخلات!$B$6)/1440)<12," ص"," م")} -> 8:50 م | L10: =MAX('11 فريقًا'!$C$4:$C$600) -> 2 | M10: =IF(MIN('بيانات الفرق'!$AG$3:$AG$13)>=المدخلات!$B$10,"✔ "&MIN('بيانات الفرق'!$AG$3:$AG$13),"⚠ "&MIN('بيانات الفرق'!$AG$3:$AG$13)) -> ✔ 20 | N10: =IF(I10<=المدخلات!$B$11,"✔ "&I10,"⚠ تجاوز "&(I10-المدخلات!$B$11)&" يوم") -> ✔ 22 | O10: =COUNT('11 فريقًا'!$A$4:$A$600) -> 132
A11: 12 | B11: {=ROUND(SUMPRODUCT(1/COUNTIF('بيانات الفرق'!$AK$3:$AK$14,'بيانات الفرق'!$AK$3:$AK$14)),0)} -> 1 | C11: {=_xlfn.TEXTJOIN(" + ",TRUE,_xlfn._xlws.SORT(COUNTIF('بيانات الفرق'!$AK$3:$AK$14,"المجموعة "&_xlfn.SEQUENCE(B11))))} -> 12 | D11: {=_xlfn.LET(_xlpm.gs,_xlfn.SEQUENCE(B11),_xlpm.ln,_xlfn.MAXIFS('بيانات الفرق'!$AM$3:$AM$14,'بيانات الفرق'!$AK$3:$AK$14,"المجموعة "&_xlpm.gs),_xlpm.mn,_xlfn.MINIFS('بيانات الفرق'!$AL$3:$AL$14,'بيانات الفرق'!$AK$3:$AK$14,"المجموعة "&_xlpm.gs),_xlpm.mx,_xlfn.MAXIFS('بيانات الفرق'!$AL$3:$AL$14,'بيانات الفرق'!$AK$3:$AK$14,"المجموعة "&_xlpm.gs),_xlpm.lo,FLOOR(_xlpm.mn/_xlpm.ln,1),_xlpm.hi,CEILING(_xlpm.mx/_xlpm.ln,1),_xlpm.t,IF(_xlpm.lo=_xlpm.hi,_xlpm.lo&"",_xlpm.lo&"–"&_xlpm.hi),_xlfn.TEXTJOIN(" + ",TRUE,_xlfn.SORTBY(_xlpm.t,_xlpm.ln,1)))} -> 2 | E11: {=_xlfn.LET(_xlpm.gs,_xlfn.SEQUENCE(B11),_xlpm.ln,_xlfn.MAXIFS('بيانات الفرق'!$AM$3:$AM$14,'بيانات الفرق'!$AK$3:$AK$14,"المجموعة "&_xlpm.gs),_xlpm.mn,_xlfn.MINIFS('بيانات الفرق'!$AL$3:$AL$14,'بيانات الفرق'!$AK$3:$AK$14,"المجموعة "&_xlpm.gs),_xlpm.mx,_xlfn.MAXIFS('بيانات الفرق'!$AL$3:$AL$14,'بيانات الفرق'!$AK$3:$AK$14,"المجموعة "&_xlpm.gs),_xlpm.t,IF(_xlpm.mn=_xlpm.mx,_xlpm.mn&"",_xlpm.mn&"–"&_xlpm.mx),_xlfn.TEXTJOIN(" + ",TRUE,_xlfn.SORTBY(_xlpm.t,_xlpm.ln,1)))} -> 22 | F11: =IF(COUNTIF('12 فريقًا'!$D$4:$D$600,"نهائي")=0,"—",IF(COUNTIF('12 فريقًا'!$D$4:$D$600,"ربع نهائي")>0,"ربع نهائي ثم نصف نهائي ثم نهائي",IF(COUNTIF('12 فريقًا'!$D$4:$D$600,"نصف نهائي")>0,"نصف نهائي ثم نهائي","نهائي مباشر"))) -> — | G11: =_xlfn.MAXIFS('12 فريقًا'!$A$4:$A$600,'12 فريقًا'!$D$4:$D$600,"المجموعة*") -> 22 | H11: =MAX('12 فريقًا'!$A$4:$A$600)-G11 -> 0 | I11: =MAX('12 فريقًا'!$A$4:$A$600) -> 22 | J11: =MOD(HOUR(المدخلات!$B$5)-1,12)+1&":"&TEXT(MINUTE(المدخلات!$B$5),"00")&IF(HOUR(المدخلات!$B$5)<12," ص"," م") -> 4:00 م | K11: {=MOD(HOUR(المدخلات!$B$5+((SUMPRODUCT(--(COUNTIF('12 فريقًا'!$B$4:$B$600,المدخلات!$F$4:$F$6)>0))-1)*المدخلات!$B$8+المدخلات!$B$6)/1440)-1,12)+1&":"&TEXT(MINUTE(المدخلات!$B$5+((SUMPRODUCT(--(COUNTIF('12 فريقًا'!$B$4:$B$600,المدخلات!$F$4:$F$6)>0))-1)*المدخلات!$B$8+المدخلات!$B$6)/1440),"00")&IF(HOUR(المدخلات!$B$5+((SUMPRODUCT(--(COUNTIF('12 فريقًا'!$B$4:$B$600,المدخلات!$F$4:$F$6)>0))-1)*المدخلات!$B$8+المدخلات!$B$6)/1440)<12," ص"," م")} -> 8:50 م | L11: =MAX('12 فريقًا'!$C$4:$C$600) -> 2 | M11: =IF(MIN('بيانات الفرق'!$AL$3:$AL$14)>=المدخلات!$B$10,"✔ "&MIN('بيانات الفرق'!$AL$3:$AL$14),"⚠ "&MIN('بيانات الفرق'!$AL$3:$AL$14)) -> ✔ 22 | N11: =IF(I11<=المدخلات!$B$11,"✔ "&I11,"⚠ تجاوز "&(I11-المدخلات!$B$11)&" يوم") -> ✔ 22 | O11: =COUNT('12 فريقًا'!$A$4:$A$600) -> 156
A12: 14 | B12: {=ROUND(SUMPRODUCT(1/COUNTIF('بيانات الفرق'!$AP$3:$AP$16,'بيانات الفرق'!$AP$3:$AP$16)),0)} -> 2 | C12: {=_xlfn.TEXTJOIN(" + ",TRUE,_xlfn._xlws.SORT(COUNTIF('بيانات الفرق'!$AP$3:$AP$16,"المجموعة "&_xlfn.SEQUENCE(B12))))} -> 7 + 7 | D12: {=_xlfn.LET(_xlpm.gs,_xlfn.SEQUENCE(B12),_xlpm.ln,_xlfn.MAXIFS('بيانات الفرق'!$AR$3:$AR$16,'بيانات الفرق'!$AP$3:$AP$16,"المجموعة "&_xlpm.gs),_xlpm.mn,_xlfn.MINIFS('بيانات الفرق'!$AQ$3:$AQ$16,'بيانات الفرق'!$AP$3:$AP$16,"المجموعة "&_xlpm.gs),_xlpm.mx,_xlfn.MAXIFS('بيانات الفرق'!$AQ$3:$AQ$16,'بيانات الفرق'!$AP$3:$AP$16,"المجموعة "&_xlpm.gs),_xlpm.lo,FLOOR(_xlpm.mn/_xlpm.ln,1),_xlpm.hi,CEILING(_xlpm.mx/_xlpm.ln,1),_xlpm.t,IF(_xlpm.lo=_xlpm.hi,_xlpm.lo&"",_xlpm.lo&"–"&_xlpm.hi),_xlfn.TEXTJOIN(" + ",TRUE,_xlfn.SORTBY(_xlpm.t,_xlpm.ln,1)))} -> 3 + 3 | E12: {=_xlfn.LET(_xlpm.gs,_xlfn.SEQUENCE(B12),_xlpm.ln,_xlfn.MAXIFS('بيانات الفرق'!$AR$3:$AR$16,'بيانات الفرق'!$AP$3:$AP$16,"المجموعة "&_xlpm.gs),_xlpm.mn,_xlfn.MINIFS('بيانات الفرق'!$AQ$3:$AQ$16,'بيانات الفرق'!$AP$3:$AP$16,"المجموعة "&_xlpm.gs),_xlpm.mx,_xlfn.MAXIFS('بيانات الفرق'!$AQ$3:$AQ$16,'بيانات الفرق'!$AP$3:$AP$16,"المجموعة "&_xlpm.gs),_xlpm.t,IF(_xlpm.mn=_xlpm.mx,_xlpm.mn&"",_xlpm.mn&"–"&_xlpm.mx),_xlfn.TEXTJOIN(" + ",TRUE,_xlfn.SORTBY(_xlpm.t,_xlpm.ln,1)))} -> 18 + 18 | F12: =IF(COUNTIF('14 فريقًا'!$D$4:$D$600,"نهائي")=0,"—",IF(COUNTIF('14 فريقًا'!$D$4:$D$600,"ربع نهائي")>0,"ربع نهائي ثم نصف نهائي ثم نهائي",IF(COUNTIF('14 فريقًا'!$D$4:$D$600,"نصف نهائي")>0,"نصف نهائي ثم نهائي","نهائي مباشر"))) -> نهائي مباشر | G12: =_xlfn.MAXIFS('14 فريقًا'!$A$4:$A$600,'14 فريقًا'!$D$4:$D$600,"المجموعة*") -> 21 | H12: =MAX('14 فريقًا'!$A$4:$A$600)-G12 -> 1 | I12: =MAX('14 فريقًا'!$A$4:$A$600) -> 22 | J12: =MOD(HOUR(المدخلات!$B$5)-1,12)+1&":"&TEXT(MINUTE(المدخلات!$B$5),"00")&IF(HOUR(المدخلات!$B$5)<12," ص"," م") -> 4:00 م | K12: {=MOD(HOUR(المدخلات!$B$5+((SUMPRODUCT(--(COUNTIF('14 فريقًا'!$B$4:$B$600,المدخلات!$F$4:$F$6)>0))-1)*المدخلات!$B$8+المدخلات!$B$6)/1440)-1,12)+1&":"&TEXT(MINUTE(المدخلات!$B$5+((SUMPRODUCT(--(COUNTIF('14 فريقًا'!$B$4:$B$600,المدخلات!$F$4:$F$6)>0))-1)*المدخلات!$B$8+المدخلات!$B$6)/1440),"00")&IF(HOUR(المدخلات!$B$5+((SUMPRODUCT(--(COUNTIF('14 فريقًا'!$B$4:$B$600,المدخلات!$F$4:$F$6)>0))-1)*المدخلات!$B$8+المدخلات!$B$6)/1440)<12," ص"," م")} -> 8:50 م | L12: =MAX('14 فريقًا'!$C$4:$C$600) -> 2 | M12: =IF(MIN('بيانات الفرق'!$AQ$3:$AQ$16)>=المدخلات!$B$10,"✔ "&MIN('بيانات الفرق'!$AQ$3:$AQ$16),"⚠ "&MIN('بيانات الفرق'!$AQ$3:$AQ$16)) -> ✔ 18 | N12: =IF(I12<=المدخلات!$B$11,"✔ "&I12,"⚠ تجاوز "&(I12-المدخلات!$B$11)&" يوم") -> ✔ 22 | O12: =COUNT('14 فريقًا'!$A$4:$A$600) -> 141
A13: 15 | B13: {=ROUND(SUMPRODUCT(1/COUNTIF('بيانات الفرق'!$AU$3:$AU$17,'بيانات الفرق'!$AU$3:$AU$17)),0)} -> 2 | C13: {=_xlfn.TEXTJOIN(" + ",TRUE,_xlfn._xlws.SORT(COUNTIF('بيانات الفرق'!$AU$3:$AU$17,"المجموعة "&_xlfn.SEQUENCE(B13))))} -> 7 + 8 | D13: {=_xlfn.LET(_xlpm.gs,_xlfn.SEQUENCE(B13),_xlpm.ln,_xlfn.MAXIFS('بيانات الفرق'!$AW$3:$AW$17,'بيانات الفرق'!$AU$3:$AU$17,"المجموعة "&_xlpm.gs),_xlpm.mn,_xlfn.MINIFS('بيانات الفرق'!$AV$3:$AV$17,'بيانات الفرق'!$AU$3:$AU$17,"المجموعة "&_xlpm.gs),_xlpm.mx,_xlfn.MAXIFS('بيانات الفرق'!$AV$3:$AV$17,'بيانات الفرق'!$AU$3:$AU$17,"المجموعة "&_xlpm.gs),_xlpm.lo,FLOOR(_xlpm.mn/_xlpm.ln,1),_xlpm.hi,CEILING(_xlpm.mx/_xlpm.ln,1),_xlpm.t,IF(_xlpm.lo=_xlpm.hi,_xlpm.lo&"",_xlpm.lo&"–"&_xlpm.hi),_xlfn.TEXTJOIN(" + ",TRUE,_xlfn.SORTBY(_xlpm.t,_xlpm.ln,1)))} -> 3 + 3 | E13: {=_xlfn.LET(_xlpm.gs,_xlfn.SEQUENCE(B13),_xlpm.ln,_xlfn.MAXIFS('بيانات الفرق'!$AW$3:$AW$17,'بيانات الفرق'!$AU$3:$AU$17,"المجموعة "&_xlpm.gs),_xlpm.mn,_xlfn.MINIFS('بيانات الفرق'!$AV$3:$AV$17,'بيانات الفرق'!$AU$3:$AU$17,"المجموعة "&_xlpm.gs),_xlpm.mx,_xlfn.MAXIFS('بيانات الفرق'!$AV$3:$AV$17,'بيانات الفرق'!$AU$3:$AU$17,"المجموعة "&_xlpm.gs),_xlpm.t,IF(_xlpm.mn=_xlpm.mx,_xlpm.mn&"",_xlpm.mn&"–"&_xlpm.mx),_xlfn.TEXTJOIN(" + ",TRUE,_xlfn.SORTBY(_xlpm.t,_xlpm.ln,1)))} -> 18 + 21 | F13: =IF(COUNTIF('15 فريقًا'!$D$4:$D$600,"نهائي")=0,"—",IF(COUNTIF('15 فريقًا'!$D$4:$D$600,"ربع نهائي")>0,"ربع نهائي ثم نصف نهائي ثم نهائي",IF(COUNTIF('15 فريقًا'!$D$4:$D$600,"نصف نهائي")>0,"نصف نهائي ثم نهائي","نهائي مباشر"))) -> نهائي مباشر | G13: =_xlfn.MAXIFS('15 فريقًا'!$A$4:$A$600,'15 فريقًا'!$D$4:$D$600,"المجموعة*") -> 21 | H13: =MAX('15 فريقًا'!$A$4:$A$600)-G13 -> 1 | I13: =MAX('15 فريقًا'!$A$4:$A$600) -> 22 | J13: =MOD(HOUR(المدخلات!$B$5)-1,12)+1&":"&TEXT(MINUTE(المدخلات!$B$5),"00")&IF(HOUR(المدخلات!$B$5)<12," ص"," م") -> 4:00 م | K13: {=MOD(HOUR(المدخلات!$B$5+((SUMPRODUCT(--(COUNTIF('15 فريقًا'!$B$4:$B$600,المدخلات!$F$4:$F$6)>0))-1)*المدخلات!$B$8+المدخلات!$B$6)/1440)-1,12)+1&":"&TEXT(MINUTE(المدخلات!$B$5+((SUMPRODUCT(--(COUNTIF('15 فريقًا'!$B$4:$B$600,المدخلات!$F$4:$F$6)>0))-1)*المدخلات!$B$8+المدخلات!$B$6)/1440),"00")&IF(HOUR(المدخلات!$B$5+((SUMPRODUCT(--(COUNTIF('15 فريقًا'!$B$4:$B$600,المدخلات!$F$4:$F$6)>0))-1)*المدخلات!$B$8+المدخلات!$B$6)/1440)<12," ص"," م")} -> 8:50 م | L13: =MAX('15 فريقًا'!$C$4:$C$600) -> 3 | M13: =IF(MIN('بيانات الفرق'!$AV$3:$AV$17)>=المدخلات!$B$10,"✔ "&MIN('بيانات الفرق'!$AV$3:$AV$17),"⚠ "&MIN('بيانات الفرق'!$AV$3:$AV$17)) -> ✔ 18 | N13: =IF(I13<=المدخلات!$B$11,"✔ "&I13,"⚠ تجاوز "&(I13-المدخلات!$B$11)&" يوم") -> ✔ 22 | O13: =COUNT('15 فريقًا'!$A$4:$A$600) -> 178
A14: 16 | B14: {=ROUND(SUMPRODUCT(1/COUNTIF('بيانات الفرق'!$AZ$3:$AZ$18,'بيانات الفرق'!$AZ$3:$AZ$18)),0)} -> 2 | C14: {=_xlfn.TEXTJOIN(" + ",TRUE,_xlfn._xlws.SORT(COUNTIF('بيانات الفرق'!$AZ$3:$AZ$18,"المجموعة "&_xlfn.SEQUENCE(B14))))} -> 8 + 8 | D14: {=_xlfn.LET(_xlpm.gs,_xlfn.SEQUENCE(B14),_xlpm.ln,_xlfn.MAXIFS('بيانات الفرق'!$BB$3:$BB$18,'بيانات الفرق'!$AZ$3:$AZ$18,"المجموعة "&_xlpm.gs),_xlpm.mn,_xlfn.MINIFS('بيانات الفرق'!$BA$3:$BA$18,'بيانات الفرق'!$AZ$3:$AZ$18,"المجموعة "&_xlpm.gs),_xlpm.mx,_xlfn.MAXIFS('بيانات الفرق'!$BA$3:$BA$18,'بيانات الفرق'!$AZ$3:$AZ$18,"المجموعة "&_xlpm.gs),_xlpm.lo,FLOOR(_xlpm.mn/_xlpm.ln,1),_xlpm.hi,CEILING(_xlpm.mx/_xlpm.ln,1),_xlpm.t,IF(_xlpm.lo=_xlpm.hi,_xlpm.lo&"",_xlpm.lo&"–"&_xlpm.hi),_xlfn.TEXTJOIN(" + ",TRUE,_xlfn.SORTBY(_xlpm.t,_xlpm.ln,1)))} -> 3 + 3 | E14: {=_xlfn.LET(_xlpm.gs,_xlfn.SEQUENCE(B14),_xlpm.ln,_xlfn.MAXIFS('بيانات الفرق'!$BB$3:$BB$18,'بيانات الفرق'!$AZ$3:$AZ$18,"المجموعة "&_xlpm.gs),_xlpm.mn,_xlfn.MINIFS('بيانات الفرق'!$BA$3:$BA$18,'بيانات الفرق'!$AZ$3:$AZ$18,"المجموعة "&_xlpm.gs),_xlpm.mx,_xlfn.MAXIFS('بيانات الفرق'!$BA$3:$BA$18,'بيانات الفرق'!$AZ$3:$AZ$18,"المجموعة "&_xlpm.gs),_xlpm.t,IF(_xlpm.mn=_xlpm.mx,_xlpm.mn&"",_xlpm.mn&"–"&_xlpm.mx),_xlfn.TEXTJOIN(" + ",TRUE,_xlfn.SORTBY(_xlpm.t,_xlpm.ln,1)))} -> 21 + 21 | F14: =IF(COUNTIF('16 فريقًا'!$D$4:$D$600,"نهائي")=0,"—",IF(COUNTIF('16 فريقًا'!$D$4:$D$600,"ربع نهائي")>0,"ربع نهائي ثم نصف نهائي ثم نهائي",IF(COUNTIF('16 فريقًا'!$D$4:$D$600,"نصف نهائي")>0,"نصف نهائي ثم نهائي","نهائي مباشر"))) -> نهائي مباشر | G14: =_xlfn.MAXIFS('16 فريقًا'!$A$4:$A$600,'16 فريقًا'!$D$4:$D$600,"المجموعة*") -> 21 | H14: =MAX('16 فريقًا'!$A$4:$A$600)-G14 -> 1 | I14: =MAX('16 فريقًا'!$A$4:$A$600) -> 22 | J14: =MOD(HOUR(المدخلات!$B$5)-1,12)+1&":"&TEXT(MINUTE(المدخلات!$B$5),"00")&IF(HOUR(المدخلات!$B$5)<12," ص"," م") -> 4:00 م | K14: {=MOD(HOUR(المدخلات!$B$5+((SUMPRODUCT(--(COUNTIF('16 فريقًا'!$B$4:$B$600,المدخلات!$F$4:$F$6)>0))-1)*المدخلات!$B$8+المدخلات!$B$6)/1440)-1,12)+1&":"&TEXT(MINUTE(المدخلات!$B$5+((SUMPRODUCT(--(COUNTIF('16 فريقًا'!$B$4:$B$600,المدخلات!$F$4:$F$6)>0))-1)*المدخلات!$B$8+المدخلات!$B$6)/1440),"00")&IF(HOUR(المدخلات!$B$5+((SUMPRODUCT(--(COUNTIF('16 فريقًا'!$B$4:$B$600,المدخلات!$F$4:$F$6)>0))-1)*المدخلات!$B$8+المدخلات!$B$6)/1440)<12," ص"," م")} -> 8:50 م | L14: =MAX('16 فريقًا'!$C$4:$C$600) -> 3 | M14: =IF(MIN('بيانات الفرق'!$BA$3:$BA$18)>=المدخلات!$B$10,"✔ "&MIN('بيانات الفرق'!$BA$3:$BA$18),"⚠ "&MIN('بيانات الفرق'!$BA$3:$BA$18)) -> ✔ 21 | N14: =IF(I14<=المدخلات!$B$11,"✔ "&I14,"⚠ تجاوز "&(I14-المدخلات!$B$11)&" يوم") -> ✔ 22 | O14: =COUNT('16 فريقًا'!$A$4:$A$600) -> 185
A15: 17 | B15: {=ROUND(SUMPRODUCT(1/COUNTIF('بيانات الفرق'!$BE$3:$BE$19,'بيانات الفرق'!$BE$3:$BE$19)),0)} -> 1 | C15: {=_xlfn.TEXTJOIN(" + ",TRUE,_xlfn._xlws.SORT(COUNTIF('بيانات الفرق'!$BE$3:$BE$19,"المجموعة "&_xlfn.SEQUENCE(B15))))} -> 17 | D15: {=_xlfn.LET(_xlpm.gs,_xlfn.SEQUENCE(B15),_xlpm.ln,_xlfn.MAXIFS('بيانات الفرق'!$BG$3:$BG$19,'بيانات الفرق'!$BE$3:$BE$19,"المجموعة "&_xlpm.gs),_xlpm.mn,_xlfn.MINIFS('بيانات الفرق'!$BF$3:$BF$19,'بيانات الفرق'!$BE$3:$BE$19,"المجموعة "&_xlpm.gs),_xlpm.mx,_xlfn.MAXIFS('بيانات الفرق'!$BF$3:$BF$19,'بيانات الفرق'!$BE$3:$BE$19,"المجموعة "&_xlpm.gs),_xlpm.lo,FLOOR(_xlpm.mn/_xlpm.ln,1),_xlpm.hi,CEILING(_xlpm.mx/_xlpm.ln,1),_xlpm.t,IF(_xlpm.lo=_xlpm.hi,_xlpm.lo&"",_xlpm.lo&"–"&_xlpm.hi),_xlfn.TEXTJOIN(" + ",TRUE,_xlfn.SORTBY(_xlpm.t,_xlpm.ln,1)))} -> 1 | E15: {=_xlfn.LET(_xlpm.gs,_xlfn.SEQUENCE(B15),_xlpm.ln,_xlfn.MAXIFS('بيانات الفرق'!$BG$3:$BG$19,'بيانات الفرق'!$BE$3:$BE$19,"المجموعة "&_xlpm.gs),_xlpm.mn,_xlfn.MINIFS('بيانات الفرق'!$BF$3:$BF$19,'بيانات الفرق'!$BE$3:$BE$19,"المجموعة "&_xlpm.gs),_xlpm.mx,_xlfn.MAXIFS('بيانات الفرق'!$BF$3:$BF$19,'بيانات الفرق'!$BE$3:$BE$19,"المجموعة "&_xlpm.gs),_xlpm.t,IF(_xlpm.mn=_xlpm.mx,_xlpm.mn&"",_xlpm.mn&"–"&_xlpm.mx),_xlfn.TEXTJOIN(" + ",TRUE,_xlfn.SORTBY(_xlpm.t,_xlpm.ln,1)))} -> 16 | F15: =IF(COUNTIF('17 فريقًا'!$D$4:$D$600,"نهائي")=0,"—",IF(COUNTIF('17 فريقًا'!$D$4:$D$600,"ربع نهائي")>0,"ربع نهائي ثم نصف نهائي ثم نهائي",IF(COUNTIF('17 فريقًا'!$D$4:$D$600,"نصف نهائي")>0,"نصف نهائي ثم نهائي","نهائي مباشر"))) -> — | G15: =_xlfn.MAXIFS('17 فريقًا'!$A$4:$A$600,'17 فريقًا'!$D$4:$D$600,"المجموعة*") -> 17 | H15: =MAX('17 فريقًا'!$A$4:$A$600)-G15 -> 0 | I15: =MAX('17 فريقًا'!$A$4:$A$600) -> 17 | J15: =MOD(HOUR(المدخلات!$B$5)-1,12)+1&":"&TEXT(MINUTE(المدخلات!$B$5),"00")&IF(HOUR(المدخلات!$B$5)<12," ص"," م") -> 4:00 م | K15: {=MOD(HOUR(المدخلات!$B$5+((SUMPRODUCT(--(COUNTIF('17 فريقًا'!$B$4:$B$600,المدخلات!$F$4:$F$6)>0))-1)*المدخلات!$B$8+المدخلات!$B$6)/1440)-1,12)+1&":"&TEXT(MINUTE(المدخلات!$B$5+((SUMPRODUCT(--(COUNTIF('17 فريقًا'!$B$4:$B$600,المدخلات!$F$4:$F$6)>0))-1)*المدخلات!$B$8+المدخلات!$B$6)/1440),"00")&IF(HOUR(المدخلات!$B$5+((SUMPRODUCT(--(COUNTIF('17 فريقًا'!$B$4:$B$600,المدخلات!$F$4:$F$6)>0))-1)*المدخلات!$B$8+المدخلات!$B$6)/1440)<12," ص"," م")} -> 8:50 م | L15: =MAX('17 فريقًا'!$C$4:$C$600) -> 3 | M15: =IF(MIN('بيانات الفرق'!$BF$3:$BF$19)>=المدخلات!$B$10,"✔ "&MIN('بيانات الفرق'!$BF$3:$BF$19),"⚠ "&MIN('بيانات الفرق'!$BF$3:$BF$19)) -> ✔ 16 | N15: =IF(I15<=المدخلات!$B$11,"✔ "&I15,"⚠ تجاوز "&(I15-المدخلات!$B$11)&" يوم") -> ✔ 17 | O15: =COUNT('17 فريقًا'!$A$4:$A$600) -> 153
A16: 19 | B16: {=ROUND(SUMPRODUCT(1/COUNTIF('بيانات الفرق'!$BJ$3:$BJ$21,'بيانات الفرق'!$BJ$3:$BJ$21)),0)} -> 1 | C16: {=_xlfn.TEXTJOIN(" + ",TRUE,_xlfn._xlws.SORT(COUNTIF('بيانات الفرق'!$BJ$3:$BJ$21,"المجموعة "&_xlfn.SEQUENCE(B16))))} -> 19 | D16: {=_xlfn.LET(_xlpm.gs,_xlfn.SEQUENCE(B16),_xlpm.ln,_xlfn.MAXIFS('بيانات الفرق'!$BL$3:$BL$21,'بيانات الفرق'!$BJ$3:$BJ$21,"المجموعة "&_xlpm.gs),_xlpm.mn,_xlfn.MINIFS('بيانات الفرق'!$BK$3:$BK$21,'بيانات الفرق'!$BJ$3:$BJ$21,"المجموعة "&_xlpm.gs),_xlpm.mx,_xlfn.MAXIFS('بيانات الفرق'!$BK$3:$BK$21,'بيانات الفرق'!$BJ$3:$BJ$21,"المجموعة "&_xlpm.gs),_xlpm.lo,FLOOR(_xlpm.mn/_xlpm.ln,1),_xlpm.hi,CEILING(_xlpm.mx/_xlpm.ln,1),_xlpm.t,IF(_xlpm.lo=_xlpm.hi,_xlpm.lo&"",_xlpm.lo&"–"&_xlpm.hi),_xlfn.TEXTJOIN(" + ",TRUE,_xlfn.SORTBY(_xlpm.t,_xlpm.ln,1)))} -> 1 | E16: {=_xlfn.LET(_xlpm.gs,_xlfn.SEQUENCE(B16),_xlpm.ln,_xlfn.MAXIFS('بيانات الفرق'!$BL$3:$BL$21,'بيانات الفرق'!$BJ$3:$BJ$21,"المجموعة "&_xlpm.gs),_xlpm.mn,_xlfn.MINIFS('بيانات الفرق'!$BK$3:$BK$21,'بيانات الفرق'!$BJ$3:$BJ$21,"المجموعة "&_xlpm.gs),_xlpm.mx,_xlfn.MAXIFS('بيانات الفرق'!$BK$3:$BK$21,'بيانات الفرق'!$BJ$3:$BJ$21,"المجموعة "&_xlpm.gs),_xlpm.t,IF(_xlpm.mn=_xlpm.mx,_xlpm.mn&"",_xlpm.mn&"–"&_xlpm.mx),_xlfn.TEXTJOIN(" + ",TRUE,_xlfn.SORTBY(_xlpm.t,_xlpm.ln,1)))} -> 18 | F16: =IF(COUNTIF('19 فريقًا'!$D$4:$D$600,"نهائي")=0,"—",IF(COUNTIF('19 فريقًا'!$D$4:$D$600,"ربع نهائي")>0,"ربع نهائي ثم نصف نهائي ثم نهائي",IF(COUNTIF('19 فريقًا'!$D$4:$D$600,"نصف نهائي")>0,"نصف نهائي ثم نهائي","نهائي مباشر"))) -> — | G16: =_xlfn.MAXIFS('19 فريقًا'!$A$4:$A$600,'19 فريقًا'!$D$4:$D$600,"المجموعة*") -> 19 | H16: =MAX('19 فريقًا'!$A$4:$A$600)-G16 -> 0 | I16: =MAX('19 فريقًا'!$A$4:$A$600) -> 19 | J16: =MOD(HOUR(المدخلات!$B$5)-1,12)+1&":"&TEXT(MINUTE(المدخلات!$B$5),"00")&IF(HOUR(المدخلات!$B$5)<12," ص"," م") -> 4:00 م | K16: {=MOD(HOUR(المدخلات!$B$5+((SUMPRODUCT(--(COUNTIF('19 فريقًا'!$B$4:$B$600,المدخلات!$F$4:$F$6)>0))-1)*المدخلات!$B$8+المدخلات!$B$6)/1440)-1,12)+1&":"&TEXT(MINUTE(المدخلات!$B$5+((SUMPRODUCT(--(COUNTIF('19 فريقًا'!$B$4:$B$600,المدخلات!$F$4:$F$6)>0))-1)*المدخلات!$B$8+المدخلات!$B$6)/1440),"00")&IF(HOUR(المدخلات!$B$5+((SUMPRODUCT(--(COUNTIF('19 فريقًا'!$B$4:$B$600,المدخلات!$F$4:$F$6)>0))-1)*المدخلات!$B$8+المدخلات!$B$6)/1440)<12," ص"," م")} -> 8:50 م | L16: =MAX('19 فريقًا'!$C$4:$C$600) -> 3 | M16: =IF(MIN('بيانات الفرق'!$BK$3:$BK$21)>=المدخلات!$B$10,"✔ "&MIN('بيانات الفرق'!$BK$3:$BK$21),"⚠ "&MIN('بيانات الفرق'!$BK$3:$BK$21)) -> ✔ 18 | N16: =IF(I16<=المدخلات!$B$11,"✔ "&I16,"⚠ تجاوز "&(I16-المدخلات!$B$11)&" يوم") -> ✔ 19 | O16: =COUNT('19 فريقًا'!$A$4:$A$600) -> 190
A17: 26 | B17: {=ROUND(SUMPRODUCT(1/COUNTIF('بيانات الفرق'!$BO$3:$BO$28,'بيانات الفرق'!$BO$3:$BO$28)),0)} -> 4 | C17: {=_xlfn.TEXTJOIN(" + ",TRUE,_xlfn._xlws.SORT(COUNTIF('بيانات الفرق'!$BO$3:$BO$28,"المجموعة "&_xlfn.SEQUENCE(B17))))} -> 6 + 6 + 7 + 7 | D17: {=_xlfn.LET(_xlpm.gs,_xlfn.SEQUENCE(B17),_xlpm.ln,_xlfn.MAXIFS('بيانات الفرق'!$BQ$3:$BQ$28,'بيانات الفرق'!$BO$3:$BO$28,"المجموعة "&_xlpm.gs),_xlpm.mn,_xlfn.MINIFS('بيانات الفرق'!$BP$3:$BP$28,'بيانات الفرق'!$BO$3:$BO$28,"المجموعة "&_xlpm.gs),_xlpm.mx,_xlfn.MAXIFS('بيانات الفرق'!$BP$3:$BP$28,'بيانات الفرق'!$BO$3:$BO$28,"المجموعة "&_xlpm.gs),_xlpm.lo,FLOOR(_xlpm.mn/_xlpm.ln,1),_xlpm.hi,CEILING(_xlpm.mx/_xlpm.ln,1),_xlpm.t,IF(_xlpm.lo=_xlpm.hi,_xlpm.lo&"",_xlpm.lo&"–"&_xlpm.hi),_xlfn.TEXTJOIN(" + ",TRUE,_xlfn.SORTBY(_xlpm.t,_xlpm.ln,1)))} -> 4 + 4 + 3 + 3 | E17: {=_xlfn.LET(_xlpm.gs,_xlfn.SEQUENCE(B17),_xlpm.ln,_xlfn.MAXIFS('بيانات الفرق'!$BQ$3:$BQ$28,'بيانات الفرق'!$BO$3:$BO$28,"المجموعة "&_xlpm.gs),_xlpm.mn,_xlfn.MINIFS('بيانات الفرق'!$BP$3:$BP$28,'بيانات الفرق'!$BO$3:$BO$28,"المجموعة "&_xlpm.gs),_xlpm.mx,_xlfn.MAXIFS('بيانات الفرق'!$BP$3:$BP$28,'بيانات الفرق'!$BO$3:$BO$28,"المجموعة "&_xlpm.gs),_xlpm.t,IF(_xlpm.mn=_xlpm.mx,_xlpm.mn&"",_xlpm.mn&"–"&_xlpm.mx),_xlfn.TEXTJOIN(" + ",TRUE,_xlfn.SORTBY(_xlpm.t,_xlpm.ln,1)))} -> 20 + 20 + 18 + 18 | F17: =IF(COUNTIF('26 فريقًا'!$D$4:$D$600,"نهائي")=0,"—",IF(COUNTIF('26 فريقًا'!$D$4:$D$600,"ربع نهائي")>0,"ربع نهائي ثم نصف نهائي ثم نهائي",IF(COUNTIF('26 فريقًا'!$D$4:$D$600,"نصف نهائي")>0,"نصف نهائي ثم نهائي","نهائي مباشر"))) -> نصف نهائي ثم نهائي | G17: =_xlfn.MAXIFS('26 فريقًا'!$A$4:$A$600,'26 فريقًا'!$D$4:$D$600,"المجموعة*") -> 21 | H17: =MAX('26 فريقًا'!$A$4:$A$600)-G17 -> 5 | I17: =MAX('26 فريقًا'!$A$4:$A$600) -> 26 | J17: =MOD(HOUR(المدخلات!$B$5)-1,12)+1&":"&TEXT(MINUTE(المدخلات!$B$5),"00")&IF(HOUR(المدخلات!$B$5)<12," ص"," م") -> 4:00 م | K17: {=MOD(HOUR(المدخلات!$B$5+((SUMPRODUCT(--(COUNTIF('26 فريقًا'!$B$4:$B$600,المدخلات!$F$4:$F$6)>0))-1)*المدخلات!$B$8+المدخلات!$B$6)/1440)-1,12)+1&":"&TEXT(MINUTE(المدخلات!$B$5+((SUMPRODUCT(--(COUNTIF('26 فريقًا'!$B$4:$B$600,المدخلات!$F$4:$F$6)>0))-1)*المدخلات!$B$8+المدخلات!$B$6)/1440),"00")&IF(HOUR(المدخلات!$B$5+((SUMPRODUCT(--(COUNTIF('26 فريقًا'!$B$4:$B$600,المدخلات!$F$4:$F$6)>0))-1)*المدخلات!$B$8+المدخلات!$B$6)/1440)<12," ص"," م")} -> 8:50 م | L17: =MAX('26 فريقًا'!$C$4:$C$600) -> 4 | M17: =IF(MIN('بيانات الفرق'!$BP$3:$BP$28)>=المدخلات!$B$10,"✔ "&MIN('بيانات الفرق'!$BP$3:$BP$28),"⚠ "&MIN('بيانات الفرق'!$BP$3:$BP$28)) -> ✔ 18 | N17: =IF(I17<=المدخلات!$B$11,"✔ "&I17,"⚠ تجاوز "&(I17-المدخلات!$B$11)&" يوم") -> ⚠ تجاوز 4 يوم | O17: =COUNT('26 فريقًا'!$A$4:$A$600) -> 275
A18: 28 | B18: {=ROUND(SUMPRODUCT(1/COUNTIF('بيانات الفرق'!$BT$3:$BT$30,'بيانات الفرق'!$BT$3:$BT$30)),0)} -> 4 | C18: {=_xlfn.TEXTJOIN(" + ",TRUE,_xlfn._xlws.SORT(COUNTIF('بيانات الفرق'!$BT$3:$BT$30,"المجموعة "&_xlfn.SEQUENCE(B18))))} -> 7 + 7 + 7 + 7 | D18: {=_xlfn.LET(_xlpm.gs,_xlfn.SEQUENCE(B18),_xlpm.ln,_xlfn.MAXIFS('بيانات الفرق'!$BV$3:$BV$30,'بيانات الفرق'!$BT$3:$BT$30,"المجموعة "&_xlpm.gs),_xlpm.mn,_xlfn.MINIFS('بيانات الفرق'!$BU$3:$BU$30,'بيانات الفرق'!$BT$3:$BT$30,"المجموعة "&_xlpm.gs),_xlpm.mx,_xlfn.MAXIFS('بيانات الفرق'!$BU$3:$BU$30,'بيانات الفرق'!$BT$3:$BT$30,"المجموعة "&_xlpm.gs),_xlpm.lo,FLOOR(_xlpm.mn/_xlpm.ln,1),_xlpm.hi,CEILING(_xlpm.mx/_xlpm.ln,1),_xlpm.t,IF(_xlpm.lo=_xlpm.hi,_xlpm.lo&"",_xlpm.lo&"–"&_xlpm.hi),_xlfn.TEXTJOIN(" + ",TRUE,_xlfn.SORTBY(_xlpm.t,_xlpm.ln,1)))} -> 3 + 3 + 3 + 3 | E18: {=_xlfn.LET(_xlpm.gs,_xlfn.SEQUENCE(B18),_xlpm.ln,_xlfn.MAXIFS('بيانات الفرق'!$BV$3:$BV$30,'بيانات الفرق'!$BT$3:$BT$30,"المجموعة "&_xlpm.gs),_xlpm.mn,_xlfn.MINIFS('بيانات الفرق'!$BU$3:$BU$30,'بيانات الفرق'!$BT$3:$BT$30,"المجموعة "&_xlpm.gs),_xlpm.mx,_xlfn.MAXIFS('بيانات الفرق'!$BU$3:$BU$30,'بيانات الفرق'!$BT$3:$BT$30,"المجموعة "&_xlpm.gs),_xlpm.t,IF(_xlpm.mn=_xlpm.mx,_xlpm.mn&"",_xlpm.mn&"–"&_xlpm.mx),_xlfn.TEXTJOIN(" + ",TRUE,_xlfn.SORTBY(_xlpm.t,_xlpm.ln,1)))} -> 18 + 18 + 18 + 18 | F18: =IF(COUNTIF('28 فريقًا'!$D$4:$D$600,"نهائي")=0,"—",IF(COUNTIF('28 فريقًا'!$D$4:$D$600,"ربع نهائي")>0,"ربع نهائي ثم نصف نهائي ثم نهائي",IF(COUNTIF('28 فريقًا'!$D$4:$D$600,"نصف نهائي")>0,"نصف نهائي ثم نهائي","نهائي مباشر"))) -> نصف نهائي ثم نهائي | G18: =_xlfn.MAXIFS('28 فريقًا'!$A$4:$A$600,'28 فريقًا'!$D$4:$D$600,"المجموعة*") -> 21 | H18: =MAX('28 فريقًا'!$A$4:$A$600)-G18 -> 7 | I18: =MAX('28 فريقًا'!$A$4:$A$600) -> 28 | J18: =MOD(HOUR(المدخلات!$B$5)-1,12)+1&":"&TEXT(MINUTE(المدخلات!$B$5),"00")&IF(HOUR(المدخلات!$B$5)<12," ص"," م") -> 4:00 م | K18: {=MOD(HOUR(المدخلات!$B$5+((SUMPRODUCT(--(COUNTIF('28 فريقًا'!$B$4:$B$600,المدخلات!$F$4:$F$6)>0))-1)*المدخلات!$B$8+المدخلات!$B$6)/1440)-1,12)+1&":"&TEXT(MINUTE(المدخلات!$B$5+((SUMPRODUCT(--(COUNTIF('28 فريقًا'!$B$4:$B$600,المدخلات!$F$4:$F$6)>0))-1)*المدخلات!$B$8+المدخلات!$B$6)/1440),"00")&IF(HOUR(المدخلات!$B$5+((SUMPRODUCT(--(COUNTIF('28 فريقًا'!$B$4:$B$600,المدخلات!$F$4:$F$6)>0))-1)*المدخلات!$B$8+المدخلات!$B$6)/1440)<12," ص"," م")} -> 8:50 م | L18: =MAX('28 فريقًا'!$C$4:$C$600) -> 4 | M18: =IF(MIN('بيانات الفرق'!$BU$3:$BU$30)>=المدخلات!$B$10,"✔ "&MIN('بيانات الفرق'!$BU$3:$BU$30),"⚠ "&MIN('بيانات الفرق'!$BU$3:$BU$30)) -> ✔ 18 | N18: =IF(I18<=المدخلات!$B$11,"✔ "&I18,"⚠ تجاوز "&(I18-المدخلات!$B$11)&" يوم") -> ⚠ تجاوز 6 يوم | O18: =COUNT('28 فريقًا'!$A$4:$A$600) -> 283
A19: 38 | B19: {=ROUND(SUMPRODUCT(1/COUNTIF('بيانات الفرق'!$BY$3:$BY$40,'بيانات الفرق'!$BY$3:$BY$40)),0)} -> 2 | C19: {=_xlfn.TEXTJOIN(" + ",TRUE,_xlfn._xlws.SORT(COUNTIF('بيانات الفرق'!$BY$3:$BY$40,"المجموعة "&_xlfn.SEQUENCE(B19))))} -> 19 + 19 | D19: {=_xlfn.LET(_xlpm.gs,_xlfn.SEQUENCE(B19),_xlpm.ln,_xlfn.MAXIFS('بيانات الفرق'!$CA$3:$CA$40,'بيانات الفرق'!$BY$3:$BY$40,"المجموعة "&_xlpm.gs),_xlpm.mn,_xlfn.MINIFS('بيانات الفرق'!$BZ$3:$BZ$40,'بيانات الفرق'!$BY$3:$BY$40,"المجموعة "&_xlpm.gs),_xlpm.mx,_xlfn.MAXIFS('بيانات الفرق'!$BZ$3:$BZ$40,'بيانات الفرق'!$BY$3:$BY$40,"المجموعة "&_xlpm.gs),_xlpm.lo,FLOOR(_xlpm.mn/_xlpm.ln,1),_xlpm.hi,CEILING(_xlpm.mx/_xlpm.ln,1),_xlpm.t,IF(_xlpm.lo=_xlpm.hi,_xlpm.lo&"",_xlpm.lo&"–"&_xlpm.hi),_xlfn.TEXTJOIN(" + ",TRUE,_xlfn.SORTBY(_xlpm.t,_xlpm.ln,1)))} -> 1 + 1 | E19: {=_xlfn.LET(_xlpm.gs,_xlfn.SEQUENCE(B19),_xlpm.ln,_xlfn.MAXIFS('بيانات الفرق'!$CA$3:$CA$40,'بيانات الفرق'!$BY$3:$BY$40,"المجموعة "&_xlpm.gs),_xlpm.mn,_xlfn.MINIFS('بيانات الفرق'!$BZ$3:$BZ$40,'بيانات الفرق'!$BY$3:$BY$40,"المجموعة "&_xlpm.gs),_xlpm.mx,_xlfn.MAXIFS('بيانات الفرق'!$BZ$3:$BZ$40,'بيانات الفرق'!$BY$3:$BY$40,"المجموعة "&_xlpm.gs),_xlpm.t,IF(_xlpm.mn=_xlpm.mx,_xlpm.mn&"",_xlpm.mn&"–"&_xlpm.mx),_xlfn.TEXTJOIN(" + ",TRUE,_xlfn.SORTBY(_xlpm.t,_xlpm.ln,1)))} -> 18 + 18 | F19: =IF(COUNTIF('38 فريقًا'!$D$4:$D$600,"نهائي")=0,"—",IF(COUNTIF('38 فريقًا'!$D$4:$D$600,"ربع نهائي")>0,"ربع نهائي ثم نصف نهائي ثم نهائي",IF(COUNTIF('38 فريقًا'!$D$4:$D$600,"نصف نهائي")>0,"نصف نهائي ثم نهائي","نهائي مباشر"))) -> نهائي مباشر | G19: =_xlfn.MAXIFS('38 فريقًا'!$A$4:$A$600,'38 فريقًا'!$D$4:$D$600,"المجموعة*") -> 19 | H19: =MAX('38 فريقًا'!$A$4:$A$600)-G19 -> 19 | I19: =MAX('38 فريقًا'!$A$4:$A$600) -> 38 | J19: =MOD(HOUR(المدخلات!$B$5)-1,12)+1&":"&TEXT(MINUTE(المدخلات!$B$5),"00")&IF(HOUR(المدخلات!$B$5)<12," ص"," م") -> 4:00 م | K19: {=MOD(HOUR(المدخلات!$B$5+((SUMPRODUCT(--(COUNTIF('38 فريقًا'!$B$4:$B$600,المدخلات!$F$4:$F$6)>0))-1)*المدخلات!$B$8+المدخلات!$B$6)/1440)-1,12)+1&":"&TEXT(MINUTE(المدخلات!$B$5+((SUMPRODUCT(--(COUNTIF('38 فريقًا'!$B$4:$B$600,المدخلات!$F$4:$F$6)>0))-1)*المدخلات!$B$8+المدخلات!$B$6)/1440),"00")&IF(HOUR(المدخلات!$B$5+((SUMPRODUCT(--(COUNTIF('38 فريقًا'!$B$4:$B$600,المدخلات!$F$4:$F$6)>0))-1)*المدخلات!$B$8+المدخلات!$B$6)/1440)<12," ص"," م")} -> 8:50 م | L19: =MAX('38 فريقًا'!$C$4:$C$600) -> 6 | M19: =IF(MIN('بيانات الفرق'!$BZ$3:$BZ$40)>=المدخلات!$B$10,"✔ "&MIN('بيانات الفرق'!$BZ$3:$BZ$40),"⚠ "&MIN('بيانات الفرق'!$BZ$3:$BZ$40)) -> ✔ 18 | N19: =IF(I19<=المدخلات!$B$11,"✔ "&I19,"⚠ تجاوز "&(I19-المدخلات!$B$11)&" يوم") -> ⚠ تجاوز 16 يوم | O19: =COUNT('38 فريقًا'!$A$4:$A$600) -> 381
A20: 39 | B20: {=ROUND(SUMPRODUCT(1/COUNTIF('بيانات الفرق'!$CD$3:$CD$41,'بيانات الفرق'!$CD$3:$CD$41)),0)} -> 2 | C20: {=_xlfn.TEXTJOIN(" + ",TRUE,_xlfn._xlws.SORT(COUNTIF('بيانات الفرق'!$CD$3:$CD$41,"المجموعة "&_xlfn.SEQUENCE(B20))))} -> 19 + 20 | D20: {=_xlfn.LET(_xlpm.gs,_xlfn.SEQUENCE(B20),_xlpm.ln,_xlfn.MAXIFS('بيانات الفرق'!$CF$3:$CF$41,'بيانات الفرق'!$CD$3:$CD$41,"المجموعة "&_xlpm.gs),_xlpm.mn,_xlfn.MINIFS('بيانات الفرق'!$CE$3:$CE$41,'بيانات الفرق'!$CD$3:$CD$41,"المجموعة "&_xlpm.gs),_xlpm.mx,_xlfn.MAXIFS('بيانات الفرق'!$CE$3:$CE$41,'بيانات الفرق'!$CD$3:$CD$41,"المجموعة "&_xlpm.gs),_xlpm.lo,FLOOR(_xlpm.mn/_xlpm.ln,1),_xlpm.hi,CEILING(_xlpm.mx/_xlpm.ln,1),_xlpm.t,IF(_xlpm.lo=_xlpm.hi,_xlpm.lo&"",_xlpm.lo&"–"&_xlpm.hi),_xlfn.TEXTJOIN(" + ",TRUE,_xlfn.SORTBY(_xlpm.t,_xlpm.ln,1)))} -> 1 + 1 | E20: {=_xlfn.LET(_xlpm.gs,_xlfn.SEQUENCE(B20),_xlpm.ln,_xlfn.MAXIFS('بيانات الفرق'!$CF$3:$CF$41,'بيانات الفرق'!$CD$3:$CD$41,"المجموعة "&_xlpm.gs),_xlpm.mn,_xlfn.MINIFS('بيانات الفرق'!$CE$3:$CE$41,'بيانات الفرق'!$CD$3:$CD$41,"المجموعة "&_xlpm.gs),_xlpm.mx,_xlfn.MAXIFS('بيانات الفرق'!$CE$3:$CE$41,'بيانات الفرق'!$CD$3:$CD$41,"المجموعة "&_xlpm.gs),_xlpm.t,IF(_xlpm.mn=_xlpm.mx,_xlpm.mn&"",_xlpm.mn&"–"&_xlpm.mx),_xlfn.TEXTJOIN(" + ",TRUE,_xlfn.SORTBY(_xlpm.t,_xlpm.ln,1)))} -> 18 + 19 | F20: =IF(COUNTIF('39 فريقًا'!$D$4:$D$600,"نهائي")=0,"—",IF(COUNTIF('39 فريقًا'!$D$4:$D$600,"ربع نهائي")>0,"ربع نهائي ثم نصف نهائي ثم نهائي",IF(COUNTIF('39 فريقًا'!$D$4:$D$600,"نصف نهائي")>0,"نصف نهائي ثم نهائي","نهائي مباشر"))) -> نهائي مباشر | G20: =_xlfn.MAXIFS('39 فريقًا'!$A$4:$A$600,'39 فريقًا'!$D$4:$D$600,"المجموعة*") -> 19 | H20: =MAX('39 فريقًا'!$A$4:$A$600)-G20 -> 20 | I20: =MAX('39 فريقًا'!$A$4:$A$600) -> 39 | J20: =MOD(HOUR(المدخلات!$B$5)-1,12)+1&":"&TEXT(MINUTE(المدخلات!$B$5),"00")&IF(HOUR(المدخلات!$B$5)<12," ص"," م") -> 4:00 م | K20: {=MOD(HOUR(المدخلات!$B$5+((SUMPRODUCT(--(COUNTIF('39 فريقًا'!$B$4:$B$600,المدخلات!$F$4:$F$6)>0))-1)*المدخلات!$B$8+المدخلات!$B$6)/1440)-1,12)+1&":"&TEXT(MINUTE(المدخلات!$B$5+((SUMPRODUCT(--(COUNTIF('39 فريقًا'!$B$4:$B$600,المدخلات!$F$4:$F$6)>0))-1)*المدخلات!$B$8+المدخلات!$B$6)/1440),"00")&IF(HOUR(المدخلات!$B$5+((SUMPRODUCT(--(COUNTIF('39 فريقًا'!$B$4:$B$600,المدخلات!$F$4:$F$6)>0))-1)*المدخلات!$B$8+المدخلات!$B$6)/1440)<12," ص"," م")} -> 8:50 م | L20: =MAX('39 فريقًا'!$C$4:$C$600) -> 7 | M20: =IF(MIN('بيانات الفرق'!$CE$3:$CE$41)>=المدخلات!$B$10,"✔ "&MIN('بيانات الفرق'!$CE$3:$CE$41),"⚠ "&MIN('بيانات الفرق'!$CE$3:$CE$41)) -> ✔ 18 | N20: =IF(I20<=المدخلات!$B$11,"✔ "&I20,"⚠ تجاوز "&(I20-المدخلات!$B$11)&" يوم") -> ⚠ تجاوز 17 يوم | O20: =COUNT('39 فريقًا'!$A$4:$A$600) -> 401
A22: إجمالي عدد المباريات (جميع المجموعات) | B22: {=SUMPRODUCT(COUNTIF(المدخلات!$L$4:$L$33,$A$4:$A$20),$O$4:$O$20)} -> 4231

Sheet 5 فرق
A1: بطولة 5 فرق – تحت 14
A3: اليوم | B3: الوقت | C3: الملعب | D3: المباراة
A4: 1 | B4: =المدخلات!$F$4 -> 4:00–5:30 م | C4: 1 | D4: 5 ضد 2
A5: 1 | B5: =المدخلات!$F$5 -> 5:40–7:10 م | C5: 1 | D5: 3 ضد 4
A6: 2 | B6: =المدخلات!$F$4 -> 4:00–5:30 م | C6: 1 | D6: 3 ضد 2
A7: 2 | B7: =المدخلات!$F$6 -> 7:20–8:50 م | C7: 1 | D7: 5 ضد 1
A8: 3 | B8: =المدخلات!$F$4 -> 4:00–5:30 م | C8: 1 | D8: 1 ضد 4
A9: 3 | B9: =المدخلات!$F$5 -> 5:40–7:10 م | C9: 1 | D9: 3 ضد 5
A10: 4 | B10: =المدخلات!$F$5 -> 5:40–7:10 م | C10: 1 | D10: 4 ضد 2
A11: 4 | B11: =المدخلات!$F$6 -> 7:20–8:50 م | C11: 1 | D11: 3 ضد 1
A12: 5 | B12: =المدخلات!$F$5 -> 5:40–7:10 م | C12: 1 | D12: 1 ضد 2
A13: 5 | B13: =المدخلات!$F$6 -> 7:20–8:50 م | C13: 1 | D13: 4 ضد 5
A14: 6 | B14: =المدخلات!$F$4 -> 4:00–5:30 م | C14: 1 | D14: 3 ضد 1
A15: 6 | B15: =المدخلات!$F$6 -> 7:20–8:50 م | C15: 1 | D15: 4 ضد 2
A16: 7 | B16: =المدخلات!$F$4 -> 4:00–5:30 م | C16: 1 | D16: 4 ضد 5
A17: 7 | B17: =المدخلات!$F$5 -> 5:40–7:10 م | C17: 1 | D17: 1 ضد 2
A18: 8 | B18: =المدخلات!$F$5 -> 5:40–7:10 م | C18: 1 | D18: 3 ضد 4
A19: 8 | B19: =المدخلات!$F$6 -> 7:20–8:50 م | C19: 1 | D19: 5 ضد 2
A20: 9 | B20: =المدخلات!$F$5 -> 5:40–7:10 م | C20: 1 | D20: 5 ضد 1
A21: 9 | B21: =المدخلات!$F$6 -> 7:20–8:50 م | C21: 1 | D21: 3 ضد 2
A22: 10 | B22: =المدخلات!$F$4 -> 4:00–5:30 م | C22: 1 | D22: 1 ضد 4
A23: 10 | B23: =المدخلات!$F$5 -> 5:40–7:10 م | C23: 1 | D23: 3 ضد 5
A24: 11 | B24: =المدخلات!$F$4 -> 4:00–5:30 م | C24: 1 | D24: 3 ضد 2
A25: 11 | B25: =المدخلات!$F$6 -> 7:20–8:50 م | C25: 1 | D25: 5 ضد 1
A26: 12 | B26: =المدخلات!$F$4 -> 4:00–5:30 م | C26: 1 | D26: 3 ضد 5
A27: 12 | B27: =المدخلات!$F$6 -> 7:20–8:50 م | C27: 1 | D27: 1 ضد 4
A28: 13 | B28: =المدخلات!$F$4 -> 4:00–5:30 م | C28: 1 | D28: 4 ضد 2
A29: 13 | B29: =المدخلات!$F$6 -> 7:20–8:50 م | C29: 1 | D29: 3 ضد 1
A30: 14 | B30: =المدخلات!$F$4 -> 4:00–5:30 م | C30: 1 | D30: 1 ضد 2
A31: 14 | B31: =المدخلات!$F$5 -> 5:40–7:10 م | C31: 1 | D31: 4 ضد 5
A32: 15 | B32: =المدخلات!$F$5 -> 5:40–7:10 م | C32: 1 | D32: 3 ضد 4
A33: 15 | B33: =المدخلات!$F$6 -> 7:20–8:50 م | C33: 1 | D33: 5 ضد 2
A34: 16 | B34: =المدخلات!$F$4 -> 4:00–5:30 م | C34: 1 | D34: 4 ضد 5
A35: 16 | B35: =المدخلات!$F$5 -> 5:40–7:10 م | C35: 1 | D35: 1 ضد 2
A36: 17 | B36: =المدخلات!$F$5 -> 5:40–7:10 م | C36: 1 | D36: 5 ضد 2
A37: 17 | B37: =المدخلات!$F$6 -> 7:20–8:50 م | C37: 1 | D37: 3 ضد 4
A38: 18 | B38: =المدخلات!$F$4 -> 4:00–5:30 م | C38: 1 | D38: 5 ضد 1
A39: 18 | B39: =المدخلات!$F$6 -> 7:20–8:50 م | C39: 1 | D39: 3 ضد 2
A40: 19 | B40: =المدخلات!$F$4 -> 4:00–5:30 م | C40: 1 | D40: 3 ضد 5
A41: 19 | B41: =المدخلات!$F$6 -> 7:20–8:50 م | C41: 1 | D41: 1 ضد 4
...

Sheet 6 فرق
A1: بطولة 6 فرق – تحت 14
A3: اليوم | B3: الوقت | C3: الملعب | D3: المباراة
A4: 1 | B4: =المدخلات!$F$4 -> 4:00–5:30 م | C4: 1 | D4: 1 ضد 6
A5: 1 | B5: =المدخلات!$F$5 -> 5:40–7:10 م | C5: 1 | D5: 2 ضد 5
A6: 1 | B6: =المدخلات!$F$6 -> 7:20–8:50 م | C6: 1 | D6: 3 ضد 4
A7: 2 | B7: =المدخلات!$F$4 -> 4:00–5:30 م | C7: 1 | D7: 2 ضد 3
A8: 2 | B8: =المدخلات!$F$5 -> 5:40–7:10 م | C8: 1 | D8: 6 ضد 4
